{
    "registryname": "g_co",
    "localizedname": "§B巨型共价超载器",
    "failure-action": "still",
    "requires-blueprint": false,
    "has-factory": true,
    "factory-only": true,
    "color": "4E4A4A",
    "parts": [
        {
            "x": 0,
            "y": 0,
            "z": 0,
            "elements": [
                "modularmachinery:g_co_factory_controller"
            ]
        },
        {
            "x": -3,
            "y": -2,
            "z": 5,
            
            "elements": [
                "modularmachinery:blockcasing@0"
            ]
        },
        {
            "x": 3,
            "y": 3,
            "z": 2,
            
            "elements": [
                "modularmachinery:blockcasing@0"
            ]
        },
        {
            "x": -4,
            "y": 3,
            "z": 5,
            
            "elements": [
                "modularmachinery:blockcasing@0"
            ]
        },
        {
            "x": -1,
            "y": 2,
            "z": 0,
            "elements": [
                "avaritiaddons:infinity_glass@6"
            ]
        },
        {
            "x": -3,
            "y": 6,
            "z": 7,
            "elements": [
                "actuallyadditions:block_crystal_empowered@1"
            ]
        },
        {
            "x": -2,
            "y": 4,
            "z": 0,
            "elements": [
                "ic2:glass@0"
            ]
        },
        {
            "x": 0,
            "y": 6,
            "z": 2,
            
            "elements": [
                "modularmachinery:blockcasing@0"
            ]
        },
        {
            "x": -1,
            "y": 2,
            "z": 7,
            "elements": [
                "avaritiaddons:infinity_glass@2"
            ]
        },
        {
            "x": -2,
            "y": -3,
            "z": 3,
            "elements": [
                "contenttweaker:neutronforcefieldcontrolblock@0"
            ]
        },
        {
            "x": -1,
            "y": 3,
            "z": 7,
            "elements": [
                "avaritiaddons:infinity_glass@0"
            ]
        },
        {
            "x": -4,
            "y": 4,
            "z": 5,
            
            "elements": [
                "modularmachinery:blockcasing@0"
            ]
        },
        {
            "x": -3,
            "y": 6,
            "z": 0,
            "elements": [
                "actuallyadditions:block_crystal_empowered@1"
            ]
        },
        {
            "x": -1,
            "y": 1,
            "z": 0,
            "elements": [
                "ic2:glass@0"
            ]
        },
        {
            "x": 0,
            "y": -1,
            "z": 0,
            
            "elements": [
                "modularmachinery:blockmepatternprovider@0",
                "modularmachinery:blockoutputbus",
                "modularmachinery:blockmeitemoutputbus"
            ]
        },
        {
            "x": -2,
            "y": -3,
            "z": 5,
            "elements": [
                "contenttweaker:neutronforcefieldcontrolblock@0"
            ]
        },
        {
            "x": -1,
            "y": 6,
            "z": 6,
            
            "elements": [
                "modularmachinery:blockcasing@0"
            ]
        },
        {
            "x": 3,
            "y": 2,
            "z": 2,
            
            "elements": [
                "modularmachinery:blockcasing@0"
            ]
        },
        {
            "x": -3,
            "y": -1,
            "z": 5,
            
            "elements": [
                "modularmachinery:blockcasing@0"
            ]
        },
        {
            "x": -2,
            "y": 3,
            "z": 0,
            "elements": [
                "ic2:glass@0"
            ]
        },
        {
            "x": -4,
            "y": -1,
            "z": 2,
            
            "elements": [
                "modularmachinery:blockcasing@0"
            ]
        },
        {
            "x": -2,
            "y": -2,
            "z": 3,
            "elements": [
                "contenttweaker:universalforcefieldcontrolblock@0"
            ]
        },
        {
            "x": -4,
            "y": 0,
            "z": 3,
            
            "elements": [
                "modularmachinery:blockcasing@0"
            ]
        },
        {
            "x": -3,
            "y": 5,
            "z": 0,
            
            "elements": [
                "modularmachinery:blockcasing@0"
            ]
        },
        {
            "x": 2,
            "y": 6,
            "z": 1,
            
            "elements": [
                "modularmachinery:blockcasing@0"
            ]
        },
        {
            "x": 1,
            "y": 0,
            "z": 0,
            "elements": [
                "modularmachinery:blockmepatternprovider@0",
                "modularmachinery:blockoutputbus",
                "modularmachinery:blockmeitemoutputbus"
            ]
        },
        {
            "x": -2,
            "y": 2,
            "z": 0,
            "elements": [
                "ic2:glass@0"
            ]
        },
        {
            "x": -4,
            "y": 1,
            "z": 3,
            
            "elements": [
                "modularmachinery:blockcasing@0"
            ]
        },
        {
            "x": -4,
            "y": 6,
            "z": 7,
            "elements": [
                "actuallyadditions:block_crystal_empowered@1"
            ]
        },
        {
            "x": -4,
            "y": 6,
            "z": 5,
            
            "elements": [
                "modularmachinery:blockcasing@0"
            ]
        },
        {
            "x": 1,
            "y": -3,
            "z": 3,
            "elements": [
                "contenttweaker:neutronforcefieldcontrolblock@0"
            ]
        },
        {
            "x": -1,
            "y": 4,
            "z": 0,
            "elements": [
                "ic2:glass@0"
            ]
        },
        {
            "x": 3,
            "y": 1,
            "z": 2,
            
            "elements": [
                "modularmachinery:blockcasing@0"
            ]
        },
        {
            "x": 3,
            "y": -1,
            "z": 4,
            
            "elements": [
                "modularmachinery:blockcasing@0"
            ]
        },
        {
            "x": -4,
            "y": 6,
            "z": 0,
            "elements": [
                "actuallyadditions:block_crystal_empowered@1"
            ]
        },
        {
            "x": -1,
            "y": 4,
            "z": 7,
            "elements": [
                "ic2:glass@0"
            ]
        },
        {
            "x": 1,
            "y": 6,
            "z": 4,
            
            "elements": [
                "modularmachinery:blockcasing@0"
            ]
        },
        {
            "x": -2,
            "y": 1,
            "z": 0,
            "elements": [
                "ic2:glass@0"
            ]
        },
        {
            "x": 1,
            "y": -1,
            "z": 0,
            "elements": [
                "modularmachinery:blockenergyinputhatch@7"
            ]
        },
        {
            "x": -1,
            "y": -3,
            "z": 5,
            "elements": [
                "contenttweaker:neutronforcefieldcontrolblock@0"
            ]
        },
        {
            "x": -1,
            "y": 5,
            "z": 7,
            
            "elements": [
                "modularmachinery:blockcasing@0"
            ]
        },
        {
            "x": 2,
            "y": 0,
            "z": 7,
            
            "elements": [
                "modularmachinery:blockcasing@0"
            ]
        },
        {
            "x": -4,
            "y": -1,
            "z": 5,
            
            "elements": [
                "modularmachinery:blockcasing@0"
            ]
        },
        {
            "x": -4,
            "y": 2,
            "z": 3,
            "elements": [
                "contenttweaker:universalforcefieldcontrolblock@0"
            ]
        },
        {
            "x": -1,
            "y": 3,
            "z": 0,
            "elements": [
                "avaritiaddons:infinity_glass@4"
            ]
        },
        {
            "x": -4,
            "y": 5,
            "z": 5,
            
            "elements": [
                "modularmachinery:blockcasing@0"
            ]
        },
        {
            "x": 3,
            "y": 6,
            "z": 7,
            "elements": [
                "actuallyadditions:block_crystal_empowered@1"
            ]
        },
        {
            "x": -1,
            "y": 1,
            "z": 7,
            "elements": [
                "ic2:glass@0"
            ]
        },
        {
            "x": -4,
            "y": 5,
            "z": 0,
            "elements": [
                "actuallyadditions:block_crystal_empowered@1"
            ]
        },
        {
            "x": 2,
            "y": 6,
            "z": 6,
            
            "elements": [
                "modularmachinery:blockcasing@0"
            ]
        },
        {
            "x": -3,
            "y": 6,
            "z": 5,
            
            "elements": [
                "modularmachinery:blockcasing@0"
            ]
        },
        {
            "x": 1,
            "y": -2,
            "z": 3,
            "elements": [
                "contenttweaker:universalforcefieldcontrolblock@0"
            ]
        },
        {
            "x": 3,
            "y": 0,
            "z": 2,
            
            "elements": [
                "modularmachinery:blockcasing@0"
            ]
        },
        {
            "x": 3,
            "y": 3,
            "z": 4,
            "elements": [
                "contenttweaker:universalforcefieldcontrolblock@0"
            ]
        },
        {
            "x": 2,
            "y": 0,
            "z": 0,
            
            "elements": [
                "modularmachinery:blockcasing@0"
            ]
        },
        {
            "x": 2,
            "y": -2,
            "z": 2,
            
            "elements": [
                "modularmachinery:blockcasing@0"
            ]
        },
        {
            "x": 3,
            "y": 1,
            "z": 3,
            
            "elements": [
                "modularmachinery:blockcasing@0"
            ]
        },
        {
            "x": 0,
            "y": 6,
            "z": 3,
            "elements": [
                "contenttweaker:arkforcefieldcontrolblock@0"
            ]
        },
        {
            "x": 1,
            "y": 2,
            "z": 0,
            "elements": [
                "ic2:glass@0"
            ]
        },
        {
            "x": -4,
            "y": 4,
            "z": 0,
            
            "elements": [
                "modularmachinery:blockcasing@0"
            ]
        },
        {
            "x": -1,
            "y": -2,
            "z": 5,
            "elements": [
                "contenttweaker:universalforcefieldcontrolblock@0"
            ]
        },
        {
            "x": -4,
            "y": 4,
            "z": 7,
            
            "elements": [
                "modularmachinery:blockcasing@0"
            ]
        },
        {
            "x": 3,
            "y": 4,
            "z": 4,
            
            "elements": [
                "modularmachinery:blockcasing@0"
            ]
        },
        {
            "x": 2,
            "y": -1,
            "z": 2,
            
            "elements": [
                "modularmachinery:blockcasing@0"
            ]
        },
        {
            "x": 0,
            "y": -3,
            "z": 5,
            "elements": [
                "contenttweaker:neutronforcefieldcontrolblock@0"
            ]
        },
        {
            "x": -1,
            "y": 0,
            "z": 7,
            
            "elements": [
                "modularmachinery:blockcasing@0"
            ]
        },
        {
            "x": 1,
            "y": 1,
            "z": 0,
            "elements": [
                "ic2:glass@0"
            ]
        },
        {
            "x": -2,
            "y": -1,
            "z": 0,
            "elements": [
                "modularmachinery:blockenergyinputhatch@7"
            ]
        },
        {
            "x": -4,
            "y": 3,
            "z": 0,
            
            "elements": [
                "modularmachinery:blockcasing@0"
            ]
        },
        {
            "x": 1,
            "y": -2,
            "z": 6,
            
            "elements": [
                "modularmachinery:blockcasing@0"
            ]
        },
        {
            "x": 2,
            "y": 1,
            "z": 7,
            
            "elements": [
                "modularmachinery:blockcasing@0"
            ]
        },
        {
            "x": 1,
            "y": -1,
            "z": 6,
            
            "elements": [
                "modularmachinery:blockcasing@0"
            ]
        },
        {
            "x": -4,
            "y": 5,
            "z": 7,
            "elements": [
                "actuallyadditions:block_crystal_empowered@1"
            ]
        },
        {
            "x": -1,
            "y": 3,
            "z": 3,
            "elements": [
                "avaritia:block_resource@0"
            ]
        },
        {
            "x": -1,
            "y": 0,
            "z": 0,
            "elements": [
                "modularmachinery:blockmepatternprovider"
            ]
        },
        {
            "x": -4,
            "y": 2,
            "z": 0,
            
            "elements": [
                "modularmachinery:blockcasing@0"
            ]
        },
        {
            "x": -4,
            "y": 1,
            "z": 7,
            
            "elements": [
                "modularmachinery:blockcasing@0"
            ]
        },
        {
            "x": 2,
            "y": -1,
            "z": 3,
            
            "elements": [
                "modularmachinery:blockcasing@0"
            ]
        },
        {
            "x": -1,
            "y": 6,
            "z": 3,
            "elements": [
                "contenttweaker:arkforcefieldcontrolblock@0"
            ]
        },
        {
            "x": 3,
            "y": 6,
            "z": 4,
            
            "elements": [
                "modularmachinery:blockcasing@0"
            ]
        },
        {
            "x": 1,
            "y": 4,
            "z": 0,
            "elements": [
                "ic2:glass@0"
            ]
        },
        {
            "x": -2,
            "y": 6,
            "z": 0,
            
            "elements": [
                "modularmachinery:blockcasing@0"
            ]
        },
        {
            "x": -2,
            "y": -1,
            "z": 7,
            
            "elements": [
                "modularmachinery:blockcasing@0"
            ]
        },
        {
            "x": 3,
            "y": 0,
            "z": 3,
            
            "elements": [
                "modularmachinery:blockcasing@0"
            ]
        },
        {
            "x": -4,
            "y": 3,
            "z": 7,
            
            "elements": [
                "modularmachinery:blockcasing@0"
            ]
        },
        {
            "x": 0,
            "y": -2,
            "z": 6,
            
            "elements": [
                "modularmachinery:blockcasing@0"
            ]
        },
        {
            "x": 0,
            "y": -1,
            "z": 6,
            
            "elements": [
                "modularmachinery:blockcasing@0"
            ]
        },
        {
            "x": 3,
            "y": 5,
            "z": 4,
            
            "elements": [
                "modularmachinery:blockcasing@0"
            ]
        },
        {
            "x": 1,
            "y": 3,
            "z": 0,
            "elements": [
                "ic2:glass@0"
            ]
        },
        {
            "x": -4,
            "y": 6,
            "z": 6,
            "elements": [
                "actuallyadditions:block_crystal_empowered@1"
            ]
        },
        {
            "x": 2,
            "y": 4,
            "z": 7,
            
            "elements": [
                "modularmachinery:blockcasing@0"
            ]
        },
        {
            "x": -2,
            "y": 5,
            "z": 0,
            
            "elements": [
                "modularmachinery:blockcasing@0"
            ]
        },
        {
            "x": -4,
            "y": 0,
            "z": 7,
            "elements": [
                "actuallyadditions:block_crystal_empowered@1"
            ]
        },
        {
            "x": 0,
            "y": 3,
            "z": 3,
            "elements": [
                "avaritia:block_resource@0"
            ]
        },
        {
            "x": 0,
            "y": -2,
            "z": 2,
            "elements": [
                "contenttweaker:universalforcefieldcontrolblock@0"
            ]
        },
        {
            "x": -4,
            "y": 5,
            "z": 2,
            
            "elements": [
                "modularmachinery:blockcasing@0"
            ]
        },
        {
            "x": 2,
            "y": 6,
            "z": 3,
            
            "elements": [
                "modularmachinery:blockcasing@0"
            ]
        },
        {
            "x": 1,
            "y": 6,
            "z": 7,
            
            "elements": [
                "modularmachinery:blockcasing@0"
            ]
        },
        {
            "x": 1,
            "y": -2,
            "z": 5,
            "elements": [
                "contenttweaker:universalforcefieldcontrolblock@0"
            ]
        },
        {
            "x": -1,
            "y": 6,
            "z": 5,
            
            "elements": [
                "modularmachinery:blockcasing@0"
            ]
        },
        {
            "x": 2,
            "y": -2,
            "z": 4,
            
            "elements": [
                "modularmachinery:blockcasing@0"
            ]
        },
        {
            "x": 2,
            "y": -1,
            "z": 4,
            
            "elements": [
                "modularmachinery:blockcasing@0"
            ]
        },
        {
            "x": 3,
            "y": 2,
            "z": 7,
            
            "elements": [
                "modularmachinery:blockcasing@0"
            ]
        },
        {
            "x": 2,
            "y": 4,
            "z": 0,
            
            "elements": [
                "modularmachinery:blockcasing@0"
            ]
        },
        {
            "x": -4,
            "y": 1,
            "z": 0,
            
            "elements": [
                "modularmachinery:blockcasing@0"
            ]
        },
        {
            "x": 3,
            "y": -1,
            "z": 0,
            "elements": [
                "actuallyadditions:block_crystal_empowered@1"
            ]
        },
        {
            "x": 2,
            "y": 5,
            "z": 7,
            
            "elements": [
                "modularmachinery:blockcasing@0"
            ]
        },
        {
            "x": -4,
            "y": 4,
            "z": 2,
            
            "elements": [
                "modularmachinery:blockcasing@0"
            ]
        },
        {
            "x": -2,
            "y": 6,
            "z": 1,
            
            "elements": [
                "modularmachinery:blockcasing@0"
            ]
        },
        {
            "x": -1,
            "y": -3,
            "z": 2,
            "elements": [
                "contenttweaker:neutronforcefieldcontrolblock@0"
            ]
        },
        {
            "x": -3,
            "y": 6,
            "z": 2,
            
            "elements": [
                "modularmachinery:blockcasing@0"
            ]
        },
        {
            "x": 3,
            "y": 6,
            "z": 6,
            "elements": [
                "actuallyadditions:block_crystal_empowered@1"
            ]
        },
        {
            "x": 2,
            "y": 3,
            "z": 0,
            
            "elements": [
                "modularmachinery:blockcasing@0"
            ]
        },
        {
            "x": 3,
            "y": -1,
            "z": 6,
            "elements": [
                "actuallyadditions:block_crystal_empowered@1"
            ]
        },
        {
            "x": 0,
            "y": 2,
            "z": 4,
            "elements": [
                "avaritia:block_resource@0"
            ]
        },
        {
            "x": 3,
            "y": 0,
            "z": 4,
            
            "elements": [
                "modularmachinery:blockcasing@0"
            ]
        },
        {
            "x": 3,
            "y": 3,
            "z": 7,
            
            "elements": [
                "modularmachinery:blockcasing@0"
            ]
        },
        {
            "x": 3,
            "y": 4,
            "z": 7,
            
            "elements": [
                "modularmachinery:blockcasing@0"
            ]
        },
        {
            "x": 0,
            "y": 6,
            "z": 7,
            
            "elements": [
                "modularmachinery:blockcasing@0"
            ]
        },
        {
            "x": 0,
            "y": 6,
            "z": 5,
            
            "elements": [
                "modularmachinery:blockcasing@0"
            ]
        },
        {
            "x": 2,
            "y": 2,
            "z": 0,
            
            "elements": [
                "modularmachinery:blockcasing@0"
            ]
        },
        {
            "x": -1,
            "y": -2,
            "z": 2,
            "elements": [
                "contenttweaker:universalforcefieldcontrolblock@0"
            ]
        },
        {
            "x": 2,
            "y": 2,
            "z": 7,
            
            "elements": [
                "modularmachinery:blockcasing@0"
            ]
        },
        {
            "x": -3,
            "y": 6,
            "z": 4,
            
            "elements": [
                "modularmachinery:blockcasing@0"
            ]
        },
        {
            "x": 3,
            "y": 1,
            "z": 4,
            
            "elements": [
                "modularmachinery:blockcasing@0"
            ]
        },
        {
            "x": 3,
            "y": 5,
            "z": 7,
            "elements": [
                "actuallyadditions:block_crystal_empowered@1"
            ]
        },
        {
            "x": 3,
            "y": 2,
            "z": 3,
            "elements": [
                "contenttweaker:universalforcefieldcontrolblock@0"
            ]
        },
        {
            "x": 3,
            "y": 2,
            "z": 4,
            "elements": [
                "contenttweaker:universalforcefieldcontrolblock@0"
            ]
        },
        {
            "x": 2,
            "y": 1,
            "z": 0,
            
            "elements": [
                "modularmachinery:blockcasing@0"
            ]
        },
        {
            "x": -3,
            "y": -1,
            "z": 0,
            "elements": [
                "actuallyadditions:block_crystal_empowered@1"
            ]
        },
        {
            "x": -4,
            "y": 6,
            "z": 2,
            
            "elements": [
                "modularmachinery:blockcasing@0"
            ]
        },
        {
            "x": -4,
            "y": -1,
            "z": 4,
            
            "elements": [
                "modularmachinery:blockcasing@0"
            ]
        },
        {
            "x": 0,
            "y": -3,
            "z": 2,
            "elements": [
                "contenttweaker:neutronforcefieldcontrolblock@0"
            ]
        },
        {
            "x": -2,
            "y": 6,
            "z": 6,
            
            "elements": [
                "modularmachinery:blockcasing@0"
            ]
        },
        {
            "x": -2,
            "y": 0,
            "z": 0,
 
            "elements": [
                "modularmachinery:blockmepatternprovider@0",
                "modularmachinery:blockoutputbus",
                "modularmachinery:blockmeitemoutputbus"
            ]
        },
        {
            "x": 2,
            "y": 3,
            "z": 7,
            
            "elements": [
                "modularmachinery:blockcasing@0"
            ]
        },
        {
            "x": -4,
            "y": 0,
            "z": 2,
            
            "elements": [
                "modularmachinery:blockcasing@0"
            ]
        },
        {
            "x": -1,
            "y": 6,
            "z": 7,
            
            "elements": [
                "modularmachinery:blockcasing@0"
            ]
        },
        {
            "x": -2,
            "y": -2,
            "z": 2,
            "elements": [
                "contenttweaker:universalforcefieldcontrolblock@0"
            ]
        },
        {
            "x": 0,
            "y": 6,
            "z": 4,
            "elements": [
                "contenttweaker:arkforcefieldcontrolblock@0"
            ]
        },
        {
            "x": -2,
            "y": 6,
            "z": 2,
            
            "elements": [
                "modularmachinery:blockcasing@0"
            ]
        },
        {
            "x": 3,
            "y": 4,
            "z": 3,
            
            "elements": [
                "modularmachinery:blockcasing@0"
            ]
        },
        {
            "x": 0,
            "y": 4,
            "z": 7,
            "elements": [
                "ic2:glass@0"
            ]
        },
        {
            "x": -1,
            "y": 6,
            "z": 0,
            
            "elements": [
                "modularmachinery:blockcasing@0"
            ]
        },
        {
            "x": -4,
            "y": 1,
            "z": 2,
            
            "elements": [
                "modularmachinery:blockcasing@0"
            ]
        },
        {
            "x": 3,
            "y": 0,
            "z": 7,
            "elements": [
                "actuallyadditions:block_crystal_empowered@1"
            ]
        },
        {
            "x": 1,
            "y": -3,
            "z": 2,
            "elements": [
                "contenttweaker:neutronforcefieldcontrolblock@0"
            ]
        },
        {
            "x": 0,
            "y": 5,
            "z": 7,
            
            "elements": [
                "modularmachinery:blockcasing@0"
            ]
        },
        {
            "x": 3,
            "y": 3,
            "z": 3,
            "elements": [
                "contenttweaker:universalforcefieldcontrolblock@0"
            ]
        },
        {
            "x": 2,
            "y": 6,
            "z": 7,
            "elements": [
                "actuallyadditions:block_crystal_empowered@1"
            ]
        },
        {
            "x": 2,
            "y": -1,
            "z": 7,
            "elements": [
                "actuallyadditions:block_crystal_empowered@1"
            ]
        },
        {
            "x": 1,
            "y": 6,
            "z": 6,
            
            "elements": [
                "modularmachinery:blockcasing@0"
            ]
        },
        {
            "x": -1,
            "y": 5,
            "z": 0,
            
            "elements": [
                "modularmachinery:blockcasing@0"
            ]
        },
        {
            "x": -2,
            "y": -2,
            "z": 5,
            "elements": [
                "contenttweaker:universalforcefieldcontrolblock@0"
            ]
        },
        {
            "x": 0,
            "y": 3,
            "z": 4,
            "elements": [
                "avaritia:block_resource@0"
            ]
        },
        {
            "x": 3,
            "y": -1,
            "z": 1,
            "elements": [
                "actuallyadditions:block_crystal_empowered@1"
            ]
        },
        {
            "x": 2,
            "y": 5,
            "z": 0,
            
            "elements": [
                "modularmachinery:blockcasing@0"
            ]
        },
        {
            "x": 1,
            "y": -2,
            "z": 2,
            "elements": [
                "contenttweaker:universalforcefieldcontrolblock@0"
            ]
        },
        {
            "x": 3,
            "y": 2,
            "z": 6,
            
            "elements": [
                "modularmachinery:blockcasing@0"
            ]
        },
        {
            "x": 3,
            "y": 6,
            "z": 3,
            
            "elements": [
                "modularmachinery:blockcasing@0"
            ]
        },
        {
            "x": -4,
            "y": 0,
            "z": 5,
            
            "elements": [
                "modularmachinery:blockcasing@0"
            ]
        },
        {
            "x": 0,
            "y": 2,
            "z": 7,
            "elements": [
                "avaritiaddons:infinity_glass@3"
            ]
        },
        {
            "x": -4,
            "y": 3,
            "z": 2,
            
            "elements": [
                "modularmachinery:blockcasing@0"
            ]
        },
        {
            "x": 3,
            "y": 5,
            "z": 6,
            
            "elements": [
                "modularmachinery:blockcasing@0"
            ]
        },
        {
            "x": -4,
            "y": 2,
            "z": 5,
            
            "elements": [
                "modularmachinery:blockcasing@0"
            ]
        },
        {
            "x": 2,
            "y": 6,
            "z": 0,
            "elements": [
                "actuallyadditions:block_crystal_empowered@1"
            ]
        },
        {
            "x": -4,
            "y": -1,
            "z": 1,
            "elements": [
                "actuallyadditions:block_crystal_empowered@1"
            ]
        },
        {
            "x": 3,
            "y": 5,
            "z": 3,
            
            "elements": [
                "modularmachinery:blockcasing@0"
            ]
        },
        {
            "x": 3,
            "y": 3,
            "z": 6,
            
            "elements": [
                "modularmachinery:blockcasing@0"
            ]
        },
        {
            "x": 1,
            "y": -3,
            "z": 5,
            "elements": [
                "contenttweaker:neutronforcefieldcontrolblock@0"
            ]
        },
        {
            "x": 3,
            "y": 1,
            "z": 7,
            
            "elements": [
                "modularmachinery:blockcasing@0"
            ]
        },
        {
            "x": 3,
            "y": 4,
            "z": 6,
            
            "elements": [
                "modularmachinery:blockcasing@0"
            ]
        },
        {
            "x": -4,
            "y": 1,
            "z": 5,
            
            "elements": [
                "modularmachinery:blockcasing@0"
            ]
        },
        {
            "x": -2,
            "y": -3,
            "z": 2,
            "elements": [
                "contenttweaker:neutronforcefieldcontrolblock@0"
            ]
        },
        {
            "x": 0,
            "y": 3,
            "z": 7,
            "elements": [
                "avaritiaddons:infinity_glass@1"
            ]
        },
        {
            "x": 0,
            "y": 6,
            "z": 6,
            
            "elements": [
                "modularmachinery:blockcasing@0"
            ]
        },
        {
            "x": 1,
            "y": 6,
            "z": 1,
            
            "elements": [
                "modularmachinery:blockcasing@0"
            ]
        },
        {
            "x": -4,
            "y": 2,
            "z": 2,
            
            "elements": [
                "modularmachinery:blockcasing@0"
            ]
        },
        {
            "x": 1,
            "y": 1,
            "z": 7,
            "elements": [
                "ic2:glass@0"
            ]
        },
        {
            "x": 3,
            "y": 6,
            "z": 5,
            
            "elements": [
                "modularmachinery:blockcasing@0"
            ]
        },
        {
            "x": -2,
            "y": -2,
            "z": 4,
            "elements": [
                "contenttweaker:universalforcefieldcontrolblock@0"
            ]
        },
        {
            "x": 3,
            "y": -1,
            "z": 3,
            
            "elements": [
                "modularmachinery:blockcasing@0"
            ]
        },
        {
            "x": -2,
            "y": 6,
            "z": 3,
            
            "elements": [
                "modularmachinery:blockcasing@0"
            ]
        },
        {
            "x": -4,
            "y": 0,
            "z": 4,
            
            "elements": [
                "modularmachinery:blockcasing@0"
            ]
        },
        {
            "x": -3,
            "y": -2,
            "z": 1,
            
            "elements": [
                "modularmachinery:blockcasing@0"
            ]
        },
        {
            "x": -4,
            "y": 1,
            "z": 4,
            
            "elements": [
                "modularmachinery:blockcasing@0"
            ]
        },
        {
            "x": -2,
            "y": 6,
            "z": 4,
            
            "elements": [
                "modularmachinery:blockcasing@0"
            ]
        },
        {
            "x": -2,
            "y": 4,
            "z": 7,
            "elements": [
                "ic2:glass@0"
            ]
        },
        {
            "x": 3,
            "y": 0,
            "z": 6,
            
            "elements": [
                "modularmachinery:blockcasing@0"
            ]
        },
        {
            "x": -2,
            "y": -3,
            "z": 4,
            "elements": [
                "contenttweaker:neutronforcefieldcontrolblock@0"
            ]
        },
        {
            "x": 3,
            "y": 1,
            "z": 6,
            
            "elements": [
                "modularmachinery:blockcasing@0"
            ]
        },
        {
            "x": 1,
            "y": 0,
            "z": 7,
            
            "elements": [
                "modularmachinery:blockcasing@0"
            ]
        },
        {
            "x": -1,
            "y": -2,
            "z": 6,
            
            "elements": [
                "modularmachinery:blockcasing@0"
            ]
        },
        {
            "x": -3,
            "y": -1,
            "z": 1,
            
            "elements": [
                "modularmachinery:blockcasing@0"
            ]
        },
        {
            "x": -1,
            "y": -1,
            "z": 6,
            
            "elements": [
                "modularmachinery:blockcasing@0"
            ]
        },
        {
            "x": 3,
            "y": 5,
            "z": 5,
            
            "elements": [
                "modularmachinery:blockcasing@0"
            ]
        },
        {
            "x": -4,
            "y": 2,
            "z": 4,
            "elements": [
                "contenttweaker:universalforcefieldcontrolblock@0"
            ]
        },
        {
            "x": -2,
            "y": 5,
            "z": 7,
            
            "elements": [
                "modularmachinery:blockcasing@0"
            ]
        },
        {
            "x": 0,
            "y": -1,
            "z": 7,
            
            "elements": [
                "modularmachinery:blockcasing@0"
            ]
        },
        {
            "x": 2,
            "y": -2,
            "z": 1,
            
            "elements": [
                "modularmachinery:blockcasing@0"
            ]
        },
        {
            "x": 3,
            "y": 4,
            "z": 5,
            
            "elements": [
                "modularmachinery:blockcasing@0"
            ]
        },
        {
            "x": 1,
            "y": 6,
            "z": 3,
            
            "elements": [
                "modularmachinery:blockcasing@0"
            ]
        },
        {
            "x": 1,
            "y": -2,
            "z": 4,
            "elements": [
                "contenttweaker:universalforcefieldcontrolblock@0"
            ]
        },
        {
            "x": 2,
            "y": -2,
            "z": 6,
            
            "elements": [
                "modularmachinery:blockcasing@0"
            ]
        },
        {
            "x": -1,
            "y": 6,
            "z": 2,
            
            "elements": [
                "modularmachinery:blockcasing@0"
            ]
        },
        {
            "x": 3,
            "y": -1,
            "z": 2,
            
            "elements": [
                "modularmachinery:blockcasing@0"
            ]
        },
        {
            "x": 1,
            "y": -3,
            "z": 4,
            "elements": [
                "contenttweaker:neutronforcefieldcontrolblock@0"
            ]
        },
        {
            "x": -2,
            "y": 3,
            "z": 7,
            "elements": [
                "ic2:glass@0"
            ]
        },
        {
            "x": 2,
            "y": -1,
            "z": 6,
            
            "elements": [
                "modularmachinery:blockcasing@0"
            ]
        },
        {
            "x": 3,
            "y": 3,
            "z": 5,
            
            "elements": [
                "modularmachinery:blockcasing@0"
            ]
        },
        {
            "x": -1,
            "y": 6,
            "z": 1,
            
            "elements": [
                "modularmachinery:blockcasing@0"
            ]
        },
        {
            "x": -1,
            "y": 2,
            "z": 4,
            "elements": [
                "avaritia:block_resource@0"
            ]
        },
        {
            "x": 2,
            "y": -1,
            "z": 1,
            
            "elements": [
                "modularmachinery:blockcasing@0"
            ]
        },
        {
            "x": 3,
            "y": 5,
            "z": 0,
            "elements": [
                "actuallyadditions:block_crystal_empowered@1"
            ]
        },
        {
            "x": 3,
            "y": 1,
            "z": 5,
            
            "elements": [
                "modularmachinery:blockcasing@0"
            ]
        },
        {
            "x": 3,
            "y": -1,
            "z": 7,
            "elements": [
                "actuallyadditions:block_crystal_empowered@1"
            ]
        },
        {
            "x": -1,
            "y": -2,
            "z": 1,
            
            "elements": [
                "modularmachinery:blockcasing@0"
            ]
        },
        {
            "x": -4,
            "y": 5,
            "z": 4,
            
            "elements": [
                "modularmachinery:blockcasing@0"
            ]
        },
        {
            "x": 1,
            "y": 2,
            "z": 7,
            "elements": [
                "ic2:glass@0"
            ]
        },
        {
            "x": 3,
            "y": 2,
            "z": 5,
            
            "elements": [
                "modularmachinery:blockcasing@0"
            ]
        },
        {
            "x": 3,
            "y": 0,
            "z": 5,
            
            "elements": [
                "modularmachinery:blockcasing@0"
            ]
        },
        {
            "x": 2,
            "y": 6,
            "z": 2,
            
            "elements": [
                "modularmachinery:blockcasing@0"
            ]
        },
        {
            "x": -1,
            "y": -4,
            "z": 4,
            "elements": [
                "contenttweaker:fallenstarforcefieldcontrolblock@0"
            ]
        },
        {
            "x": 3,
            "y": 6,
            "z": 0,
            "elements": [
                "actuallyadditions:block_crystal_empowered@1"
            ]
        },
        {
            "x": -4,
            "y": 6,
            "z": 1,
            "elements": [
                "actuallyadditions:block_crystal_empowered@1"
            ]
        },
        {
            "x": 0,
            "y": -3,
            "z": 4,
            "elements": [
                "contenttweaker:arkforcefieldcontrolblock@0"
            ]
        },
        {
            "x": -1,
            "y": -1,
            "z": 1,
            
            "elements": [
                "modularmachinery:blockcasing@0"
            ]
        },
        {
            "x": -4,
            "y": 6,
            "z": 4,
            
            "elements": [
                "modularmachinery:blockcasing@0"
            ]
        },
        {
            "x": -3,
            "y": -1,
            "z": 4,
            
            "elements": [
                "modularmachinery:blockcasing@0"
            ]
        },
        {
            "x": -2,
            "y": 2,
            "z": 7,
            "elements": [
                "ic2:glass@0"
            ]
        },
        {
            "x": -1,
            "y": -5,
            "z": 4,
            "elements": [
                "contenttweaker:fallenstarforcefieldcontrolblock@0"
            ]
        },
        {
            "x": -3,
            "y": 6,
            "z": 6,
            
            "elements": [
                "modularmachinery:blockcasing@0"
            ]
        },
        {
            "x": 1,
            "y": 3,
            "z": 7,
            "elements": [
                "ic2:glass@0"
            ]
        },
        {
            "x": 2,
            "y": 6,
            "z": 5,
            
            "elements": [
                "modularmachinery:blockcasing@0"
            ]
        },
        {
            "x": -2,
            "y": 6,
            "z": 7,
            
            "elements": [
                "modularmachinery:blockcasing@0"
            ]
        },
        {
            "x": 2,
            "y": -2,
            "z": 5,
            
            "elements": [
                "modularmachinery:blockcasing@0"
            ]
        },
        {
            "x": 0,
            "y": -2,
            "z": 1,
            
            "elements": [
                "modularmachinery:blockcasing@0"
            ]
        },
        {
            "x": -3,
            "y": -2,
            "z": 2,
            
            "elements": [
                "modularmachinery:blockcasing@0"
            ]
        },
        {
            "x": -4,
            "y": 5,
            "z": 1,
            
            "elements": [
                "modularmachinery:blockcasing@0"
            ]
        },
        {
            "x": -4,
            "y": 4,
            "z": 1,
            
            "elements": [
                "modularmachinery:blockcasing@0"
            ]
        },
        {
            "x": 1,
            "y": 4,
            "z": 7,
            "elements": [
                "ic2:glass@0"
            ]
        },
        {
            "x": -4,
            "y": 3,
            "z": 4,
            "elements": [
                "contenttweaker:universalforcefieldcontrolblock@0"
            ]
        },
        {
            "x": 0,
            "y": -4,
            "z": 4,
            "elements": [
                "contenttweaker:fallenstarforcefieldcontrolblock@0"
            ]
        },
        {
            "x": 0,
            "y": -1,
            "z": 1,
            
            "elements": [
                "modularmachinery:blockcasing@0"
            ]
        },
        {
            "x": -3,
            "y": -1,
            "z": 2,
            
            "elements": [
                "modularmachinery:blockcasing@0"
            ]
        },
        {
            "x": -1,
            "y": -3,
            "z": 4,
            "elements": [
                "contenttweaker:arkforcefieldcontrolblock@0"
            ]
        },
        {
            "x": -3,
            "y": 6,
            "z": 1,
            
            "elements": [
                "modularmachinery:blockcasing@0"
            ]
        },
        {
            "x": -4,
            "y": 4,
            "z": 4,
            
            "elements": [
                "modularmachinery:blockcasing@0"
            ]
        },
        {
            "x": 1,
            "y": 5,
            "z": 7,
            
            "elements": [
                "modularmachinery:blockcasing@0"
            ]
        },
        {
            "x": 2,
            "y": -1,
            "z": 5,
            
            "elements": [
                "modularmachinery:blockcasing@0"
            ]
        },
        {
            "x": -4,
            "y": 0,
            "z": 0,
            "elements": [
                "actuallyadditions:block_crystal_empowered@1"
            ]
        },
        {
            "x": 0,
            "y": -5,
            "z": 4,
            "elements": [
                "contenttweaker:fallenstarforcefieldcontrolblock@0"
            ]
        },
        {
            "x": -3,
            "y": 1,
            "z": 7,
            
            "elements": [
                "modularmachinery:blockcasing@0"
            ]
        },
        {
            "x": 1,
            "y": -2,
            "z": 1,
            
            "elements": [
                "modularmachinery:blockcasing@0"
            ]
        },
        {
            "x": 3,
            "y": 2,
            "z": 0,
            
            "elements": [
                "modularmachinery:blockcasing@0"
            ]
        },
        {
            "x": -3,
            "y": 0,
            "z": 7,
            
            "elements": [
                "modularmachinery:blockcasing@0"
            ]
        },
        {
            "x": -3,
            "y": -1,
            "z": 7,
            "elements": [
                "actuallyadditions:block_crystal_empowered@1"
            ]
        },
        {
            "x": 3,
            "y": 5,
            "z": 1,
            
            "elements": [
                "modularmachinery:blockcasing@0"
            ]
        },
        {
            "x": 2,
            "y": 6,
            "z": 4,
            
            "elements": [
                "modularmachinery:blockcasing@0"
            ]
        },
        {
            "x": -4,
            "y": 2,
            "z": 1,
            
            "elements": [
                "modularmachinery:blockcasing@0"
            ]
        },
        {
            "x": 1,
            "y": 6,
            "z": 0,
            
            "elements": [
                "modularmachinery:blockcasing@0"
            ]
        },
        {
            "x": 1,
            "y": -1,
            "z": 1,
            
            "elements": [
                "modularmachinery:blockcasing@0"
            ]
        },
        {
            "x": -4,
            "y": 2,
            "z": 7,
            
            "elements": [
                "modularmachinery:blockcasing@0"
            ]
        },
        {
            "x": 3,
            "y": 4,
            "z": 1,
            
            "elements": [
                "modularmachinery:blockcasing@0"
            ]
        },
        {
            "x": 3,
            "y": 1,
            "z": 0,
            
            "elements": [
                "modularmachinery:blockcasing@0"
            ]
        },
        {
            "x": -4,
            "y": -1,
            "z": 0,
            "elements": [
                "actuallyadditions:block_crystal_empowered@1"
            ]
        },
        {
            "x": -4,
            "y": 3,
            "z": 1,
            
            "elements": [
                "modularmachinery:blockcasing@0"
            ]
        },
        {
            "x": 3,
            "y": 5,
            "z": 2,
            
            "elements": [
                "modularmachinery:blockcasing@0"
            ]
        },
        {
            "x": -3,
            "y": 0,
            "z": 0,
            
            "elements": [
                "modularmachinery:blockcasing@0"
            ]
        },
        {
            "x": 2,
            "y": -2,
            "z": 3,
            
            "elements": [
                "modularmachinery:blockcasing@0"
            ]
        },
        {
            "x": 1,
            "y": 5,
            "z": 0,
            
            "elements": [
                "modularmachinery:blockcasing@0"
            ]
        },
        {
            "x": -4,
            "y": 0,
            "z": 1,
            
            "elements": [
                "modularmachinery:blockcasing@0"
            ]
        },
        {
            "x": -3,
            "y": -2,
            "z": 4,
            
            "elements": [
                "modularmachinery:blockcasing@0"
            ]
        },
        {
            "x": -2,
            "y": 1,
            "z": 7,
            "elements": [
                "ic2:glass@0"
            ]
        },
        {
            "x": 0,
            "y": -2,
            "z": 5,
            "elements": [
                "contenttweaker:universalforcefieldcontrolblock@0"
            ]
        },
        {
            "x": -2,
            "y": -2,
            "z": 1,
            
            "elements": [
                "modularmachinery:blockcasing@0"
            ]
        },
        {
            "x": -2,
            "y": -1,
            "z": 6,
            
            "elements": [
                "modularmachinery:blockcasing@0"
            ]
        },
        {
            "x": -3,
            "y": 6,
            "z": 3,
            
            "elements": [
                "modularmachinery:blockcasing@0"
            ]
        },
        {
            "x": -2,
            "y": 0,
            "z": 7,
            
            "elements": [
                "modularmachinery:blockcasing@0"
            ]
        },
        {
            "x": -4,
            "y": -1,
            "z": 7,
            "elements": [
                "actuallyadditions:block_crystal_empowered@1"
            ]
        },
        {
            "x": -2,
            "y": -1,
            "z": 1,
            
            "elements": [
                "modularmachinery:blockcasing@0"
            ]
        },
        {
            "x": 3,
            "y": 4,
            "z": 0,
            
            "elements": [
                "modularmachinery:blockcasing@0"
            ]
        },
        {
            "x": 3,
            "y": 6,
            "z": 2,
            
            "elements": [
                "modularmachinery:blockcasing@0"
            ]
        },
        {
            "x": -4,
            "y": -1,
            "z": 3,
            
            "elements": [
                "modularmachinery:blockcasing@0"
            ]
        },
        {
            "x": 0,
            "y": 6,
            "z": 0,
            
            "elements": [
                "modularmachinery:blockcasing@0"
            ]
        },
        {
            "x": -4,
            "y": 1,
            "z": 1,
            
            "elements": [
                "modularmachinery:blockcasing@0"
            ]
        },
        {
            "x": 0,
            "y": 2,
            "z": 3,
            "elements": [
                "avaritia:block_resource@0"
            ]
        },
        {
            "x": -2,
            "y": -2,
            "z": 6,
            
            "elements": [
                "modularmachinery:blockcasing@0"
            ]
        },
        {
            "x": -4,
            "y": 0,
            "z": 6,
            
            "elements": [
                "modularmachinery:blockcasing@0"
            ]
        },
        {
            "x": 3,
            "y": 6,
            "z": 1,
            "elements": [
                "actuallyadditions:block_crystal_empowered@1"
            ]
        },
        {
            "x": -4,
            "y": 1,
            "z": 6,
            
            "elements": [
                "modularmachinery:blockcasing@0"
            ]
        },
        {
            "x": -3,
            "y": -2,
            "z": 3,
            
            "elements": [
                "modularmachinery:blockcasing@0"
            ]
        },
        {
            "x": 3,
            "y": 3,
            "z": 0,
            
            "elements": [
                "modularmachinery:blockcasing@0"
            ]
        },
        {
            "x": -1,
            "y": -1,
            "z": 7,
            
            "elements": [
                "modularmachinery:blockcasing@0"
            ]
        },
        {
            "x": 0,
            "y": 5,
            "z": 0,
            
            "elements": [
                "modularmachinery:blockcasing@0"
            ]
        },
        {
            "x": 1,
            "y": 6,
            "z": 5,
            
            "elements": [
                "modularmachinery:blockcasing@0"
            ]
        },
        {
            "x": -1,
            "y": 3,
            "z": 4,
            "elements": [
                "avaritia:block_resource@0"
            ]
        },
        {
            "x": -3,
            "y": 2,
            "z": 0,
            
            "elements": [
                "modularmachinery:blockcasing@0"
            ]
        },
        {
            "x": -4,
            "y": 3,
            "z": 3,
            "elements": [
                "contenttweaker:universalforcefieldcontrolblock@0"
            ]
        },
        {
            "x": -1,
            "y": -4,
            "z": 3,
            "elements": [
                "contenttweaker:fallenstarforcefieldcontrolblock@0"
            ]
        },
        {
            "x": -3,
            "y": -1,
            "z": 6,
            
            "elements": [
                "modularmachinery:blockcasing@0"
            ]
        },
        {
            "x": -3,
            "y": -1,
            "z": 3,
            
            "elements": [
                "modularmachinery:blockcasing@0"
            ]
        },
        {
            "x": -4,
            "y": 6,
            "z": 3,
            
            "elements": [
                "modularmachinery:blockcasing@0"
            ]
        },
        {
            "x": 0,
            "y": -3,
            "z": 3,
            "elements": [
                "contenttweaker:arkforcefieldcontrolblock@0"
            ]
        },
        {
            "x": 0,
            "y": 4,
            "z": 0,
            "elements": [
                "ic2:glass@0"
            ]
        },
        {
            "x": -4,
            "y": 2,
            "z": 6,
            
            "elements": [
                "modularmachinery:blockcasing@0"
            ]
        },
        {
            "x": 3,
            "y": 0,
            "z": 1,
            
            "elements": [
                "modularmachinery:blockcasing@0"
            ]
        },
        {
            "x": -1,
            "y": -5,
            "z": 3,
            "elements": [
                "contenttweaker:fallenstarforcefieldcontrolblock@0"
            ]
        },
        {
            "x": -3,
            "y": -2,
            "z": 6,
            
            "elements": [
                "modularmachinery:blockcasing@0"
            ]
        },
        {
            "x": -1,
            "y": 2,
            "z": 3,
            "elements": [
                "avaritia:block_resource@0"
            ]
        },
        {
            "x": -3,
            "y": 3,
            "z": 7,
            
            "elements": [
                "modularmachinery:blockcasing@0"
            ]
        },
        {
            "x": 3,
            "y": 1,
            "z": 1,
            
            "elements": [
                "modularmachinery:blockcasing@0"
            ]
        },
        {
            "x": 0,
            "y": 3,
            "z": 0,
            "elements": [
                "avaritiaddons:infinity_glass@5"
            ]
        },
        {
            "x": 3,
            "y": -1,
            "z": 5,
            
            "elements": [
                "modularmachinery:blockcasing@0"
            ]
        },
        {
            "x": 0,
            "y": 6,
            "z": 1,
            
            "elements": [
                "modularmachinery:blockcasing@0"
            ]
        },
        {
            "x": -4,
            "y": 5,
            "z": 3,
            
            "elements": [
                "modularmachinery:blockcasing@0"
            ]
        },
        {
            "x": -4,
            "y": 3,
            "z": 6,
            
            "elements": [
                "modularmachinery:blockcasing@0"
            ]
        },
        {
            "x": 0,
            "y": 1,
            "z": 7,
            "elements": [
                "ic2:glass@0"
            ]
        },
        {
            "x": -4,
            "y": 4,
            "z": 6,
            
            "elements": [
                "modularmachinery:blockcasing@0"
            ]
        },
        {
            "x": -4,
            "y": -1,
            "z": 6,
            "elements": [
                "actuallyadditions:block_crystal_empowered@1"
            ]
        },
        {
            "x": 3,
            "y": 0,
            "z": 0,
            "elements": [
                "actuallyadditions:block_crystal_empowered@1"
            ]
        },
        {
            "x": -2,
            "y": 6,
            "z": 5,
            
            "elements": [
                "modularmachinery:blockcasing@0"
            ]
        },
        {
            "x": 0,
            "y": -4,
            "z": 3,
            "elements": [
                "contenttweaker:fallenstarforcefieldcontrolblock@0"
            ]
        },
        {
            "x": 0,
            "y": 2,
            "z": 0,
            "elements": [
                "avaritiaddons:infinity_glass@7"
            ]
        },
        {
            "x": 3,
            "y": 3,
            "z": 1,
            
            "elements": [
                "modularmachinery:blockcasing@0"
            ]
        },
        {
            "x": -1,
            "y": 6,
            "z": 4,
            "elements": [
                "contenttweaker:arkforcefieldcontrolblock@0"
            ]
        },
        {
            "x": -3,
            "y": 4,
            "z": 0,
            
            "elements": [
                "modularmachinery:blockcasing@0"
            ]
        },
        {
            "x": 1,
            "y": 6,
            "z": 2,
            
            "elements": [
                "modularmachinery:blockcasing@0"
            ]
        },
        {
            "x": -1,
            "y": -3,
            "z": 3,
            "elements": [
                "contenttweaker:arkforcefieldcontrolblock@0"
            ]
        },
        {
            "x": -3,
            "y": 4,
            "z": 7,
            
            "elements": [
                "modularmachinery:blockcasing@0"
            ]
        },
        {
            "x": -4,
            "y": 4,
            "z": 3,
            
            "elements": [
                "modularmachinery:blockcasing@0"
            ]
        },
        {
            "x": -3,
            "y": 2,
            "z": 7,
            
            "elements": [
                "modularmachinery:blockcasing@0"
            ]
        },
        {
            "x": -3,
            "y": 1,
            "z": 0,
            
            "elements": [
                "modularmachinery:blockcasing@0"
            ]
        },
        {
            "x": 2,
            "y": -1,
            "z": 0,
            "elements": [
                "actuallyadditions:block_crystal_empowered@1"
            ]
        },
        {
            "x": 0,
            "y": 0,
            "z": 7,
            
            "elements": [
                "modularmachinery:blockcasing@0"
            ]
        },
        {
            "x": 0,
            "y": 1,
            "z": 0,
            "elements": [
                "ic2:glass@0"
            ]
        },
        {
            "x": -1,
            "y": -1,
            "z": 0,
            
            "elements": [
                "modularmachinery:blockmepatternprovider@0",
                "modularmachinery:blockoutputbus",
                "modularmachinery:blockmeitemoutputbus"
            ]
        },
        {
            "x": -3,
            "y": 3,
            "z": 0,
            
            "elements": [
                "modularmachinery:blockcasing@0"
            ]
        },
        {
            "x": 3,
            "y": 2,
            "z": 1,
            
            "elements": [
                "modularmachinery:blockcasing@0"
            ]
        },
        {
            "x": 3,
            "y": 4,
            "z": 2,
            
            "elements": [
                "modularmachinery:blockcasing@0"
            ]
        },
        {
            "x": 0,
            "y": -5,
            "z": 3,
            "elements": [
                "contenttweaker:fallenstarforcefieldcontrolblock@0"
            ]
        },
        {
            "x": -4,
            "y": 5,
            "z": 6,
            
            "elements": [
                "modularmachinery:blockcasing@0"
            ]
        },
        {
            "x": -3,
            "y": 5,
            "z": 7,
            
            "elements": [
                "modularmachinery:blockcasing@0"
            ]
        },
        {
            "x": 1,
            "y": -1,
            "z": 7,
            
            "elements": [
                "modularmachinery:blockcasing@0"
            ]
        }
    ]}