{
    "registryname": "TSL",
    "localizedname": "§6三级奇点",
    "failure-action": "still",
    "requires-blueprint": false,
    "color": "11131A",
    "parts": [
        {
            "x": -5,
            "y": 14,
            "z": 9,
            "elements": [
                "mekanism:plasticfence@0"
            ]
        },
        {
            "x": 1,
            "y": -5,
            "z": -5,
            "elements": [
                "chisel:antiblock@0"
            ]
        },
        {
            "x": 1,
            "y": -5,
            "z": -16,
            "elements": [
                "chisel:antiblock@0"
            ]
        },
        {
            "x": 1,
            "y": -5,
            "z": -15,
            "elements": [
                "minecraft:stained_glass_pane@1"
            ]
        },
        {
            "x": 1,
            "y": -5,
            "z": -14,
            "elements": [
                "chisel:antiblock@0"
            ]
        },
        {
            "x": 1,
            "y": -5,
            "z": -19,
            "elements": [
                "chisel:antiblock@0"
            ]
        },
        {
            "x": 15,
            "y": 13,
            "z": 6,
            "elements": [
                "chisel:antiblock@0"
            ]
        },
        {
            "x": 15,
            "y": 13,
            "z": 8,
            "elements": [
                "chisel:antiblock@0"
            ]
        },
        {
            "x": 15,
            "y": 13,
            "z": 7,
            "elements": [
                "minecraft:stained_glass_pane@1"
            ]
        },
        {
            "x": 1,
            "y": -5,
            "z": 28,
            "elements": [
                "chisel:antiblock@0"
            ]
        },
        {
            "x": 1,
            "y": -5,
            "z": 29,
            "elements": [
                "minecraft:stained_glass_pane@1"
            ]
        },
        {
            "x": 1,
            "y": -5,
            "z": 30,
            "elements": [
                "chisel:antiblock@0"
            ]
        },
        {
            "x": 7,
            "y": 55,
            "z": 6,
            "elements": [
                "botania:quartzstairsdark@4"
            ]
        },
        {
            "x": 7,
            "y": 55,
            "z": 8,
            "elements": [
                "botania:quartzstairsdark@4"
            ]
        },
        {
            "x": 1,
            "y": -5,
            "z": 19,
            "elements": [
                "chisel:antiblock@0"
            ]
        },
        {
            "x": -14,
            "y": 3,
            "z": 6,
            "elements": [
                "futuremc:red_sandstone_wall@0"
            ]
        },
        {
            "x": -14,
            "y": 3,
            "z": 8,
            "elements": [
                "futuremc:red_sandstone_wall@0"
            ]
        },
        {
            "x": -3,
            "y": -9,
            "z": -16,
            "elements": [
                "chisel:antiblock@0"
            ]
        },
        {
            "x": -3,
            "y": -9,
            "z": -17,
            "elements": [
                "chisel:antiblock@0"
            ]
        },
        {
            "x": -3,
            "y": -9,
            "z": -14,
            "elements": [
                "chisel:antiblock@0"
            ]
        },
        {
            "x": -3,
            "y": -9,
            "z": -15,
            "elements": [
                "chisel:antiblock@0"
            ]
        },
        {
            "x": -3,
            "y": -9,
            "z": -20,
            "elements": [
                "chisel:antiblock@0"
            ]
        },
        {
            "x": -3,
            "y": -9,
            "z": -18,
            "elements": [
                "chisel:antiblock@0"
            ]
        },
        {
            "x": -3,
            "y": -9,
            "z": -19,
            "elements": [
                "chisel:antiblock@0"
            ]
        },
        {
            "x": -1,
            "y": 18,
            "z": 19,
            "elements": [
                "minecraft:stained_glass_pane@1"
            ]
        },
        {
            "x": -1,
            "y": 18,
            "z": 18,
            "elements": [
                "chisel:antiblock@0"
            ]
        },
        {
            "x": -1,
            "y": 18,
            "z": 20,
            "elements": [
                "chisel:antiblock@0"
            ]
        },
        {
            "x": -1,
            "y": 18,
            "z": 11,
            "elements": [
                "minecraft:end_rod@5"
            ]
        },
        {
            "x": 5,
            "y": -1,
            "z": 13,
            "elements": [
                "chisel:antiblock@0"
            ]
        },
        {
            "x": -1,
            "y": 18,
            "z": 3,
            "elements": [
                "minecraft:end_rod@5"
            ]
        },
        {
            "x": -24,
            "y": -11,
            "z": 2,
            "elements": [
                "chisel:antiblock@0"
            ]
        },
        {
            "x": 21,
            "y": -6,
            "z": 5,
            "elements": [
                "minecraft:stone_slab2@0"
            ]
        },
        {
            "x": -24,
            "y": -11,
            "z": 12,
            "elements": [
                "chisel:antiblock@0"
            ]
        },
        {
            "x": 21,
            "y": -6,
            "z": 9,
            "elements": [
                "minecraft:stone_slab2@0"
            ]
        },
        {
            "x": 5,
            "y": -1,
            "z": 1,
            "elements": [
                "chisel:antiblock@0"
            ]
        },
        {
            "x": -5,
            "y": 14,
            "z": 5,
            "elements": [
                "mekanism:plasticfence@0"
            ]
        },
        {
            "x": -4,
            "y": 17,
            "z": 5,
            "elements": [
                "chisel:antiblock@0"
            ]
        },
        {
            "x": -4,
            "y": 17,
            "z": 6,
            "elements": [
                "minecraft:end_rod@3"
            ]
        },
        {
            "x": -4,
            "y": 17,
            "z": 8,
            "elements": [
                "minecraft:end_rod@2"
            ]
        },
        {
            "x": -4,
            "y": 17,
            "z": 9,
            "elements": [
                "chisel:antiblock@0"
            ]
        },
        {
            "x": 0,
            "y": -8,
            "z": -9,
            "elements": [
                "mekanism:plasticfence@0"
            ]
        },
        {
            "x": 0,
            "y": -8,
            "z": -8,
            "elements": [
                "chisel:antiblock@0"
            ]
        },
        {
            "x": 0,
            "y": -8,
            "z": -11,
            "elements": [
                "chisel:antiblock@0"
            ]
        },
        {
            "x": 0,
            "y": -8,
            "z": -10,
            "elements": [
                "chisel:antiblock@0"
            ]
        },
        {
            "x": 0,
            "y": -8,
            "z": -12,
            "elements": [
                "chisel:antiblock@0"
            ]
        },
        {
            "x": 0,
            "y": -8,
            "z": -15,
            "elements": [
                "chisel:antiblock@0"
            ]
        },
        {
            "x": 0,
            "y": -8,
            "z": -17,
            "elements": [
                "chisel:antiblock@0"
            ]
        },
        {
            "x": 0,
            "y": -8,
            "z": -16,
            "elements": [
                "chisel:antiblock@0"
            ]
        },
        {
            "x": -1,
            "y": 18,
            "z": -5,
            "elements": [
                "minecraft:stained_glass_pane@1"
            ]
        },
        {
            "x": -1,
            "y": 18,
            "z": -6,
            "elements": [
                "chisel:antiblock@0"
            ]
        },
        {
            "x": -1,
            "y": 18,
            "z": -4,
            "elements": [
                "chisel:antiblock@0"
            ]
        },
        {
            "x": 0,
            "y": -8,
            "z": 31,
            "elements": [
                "chisel:antiblock@0"
            ]
        },
        {
            "x": 0,
            "y": -8,
            "z": 29,
            "elements": [
                "chisel:antiblock@0"
            ]
        },
        {
            "x": 0,
            "y": -8,
            "z": 30,
            "elements": [
                "chisel:antiblock@0"
            ]
        },
        {
            "x": 0,
            "y": -8,
            "z": 28,
            "elements": [
                "chisel:antiblock@0"
            ]
        },
        {
            "x": 0,
            "y": -8,
            "z": 25,
            "elements": [
                "chisel:antiblock@0"
            ]
        },
        {
            "x": 0,
            "y": -8,
            "z": 26,
            "elements": [
                "chisel:antiblock@0"
            ]
        },
        {
            "x": 0,
            "y": -8,
            "z": 23,
            "elements": [
                "mekanism:plasticfence@0"
            ]
        },
        {
            "x": 0,
            "y": -8,
            "z": 24,
            "elements": [
                "chisel:antiblock@0"
            ]
        },
        {
            "x": 0,
            "y": -8,
            "z": 22,
            "elements": [
                "chisel:antiblock@0"
            ]
        },
        {
            "x": -2,
            "y": -6,
            "z": -18,
            "elements": [
                "chisel:antiblock@0"
            ]
        },
        {
            "x": -2,
            "y": -6,
            "z": -19,
            "elements": [
                "minecraft:end_rod@1"
            ]
        },
        {
            "x": -3,
            "y": -9,
            "z": -8,
            "elements": [
                "chisel:antiblock@0"
            ]
        },
        {
            "x": -3,
            "y": -9,
            "z": -9,
            "elements": [
                "thermalfoundation:storage_alloy@6"
            ]
        },
        {
            "x": -3,
            "y": -9,
            "z": -13,
            "elements": [
                "chisel:antiblock@0"
            ]
        },
        {
            "x": -3,
            "y": -9,
            "z": -10,
            "elements": [
                "chisel:antiblock@0"
            ]
        },
        {
            "x": -2,
            "y": 15,
            "z": 12,
            "elements": [
                "mekanism:plasticfence@0"
            ]
        },
        {
            "x": -2,
            "y": 15,
            "z": 11,
            "elements": [
                "chisel:antiblock@0"
            ]
        },
        {
            "x": 24,
            "y": -5,
            "z": 5,
            "elements": [
                "chisel:antiblock@0"
            ]
        },
        {
            "x": -2,
            "y": 15,
            "z": 10,
            "elements": [
                "chisel:glasspanedyedorange@5"
            ]
        },
        {
            "x": 24,
            "y": -5,
            "z": 9,
            "elements": [
                "chisel:antiblock@0"
            ]
        },
        {
            "x": -2,
            "y": 15,
            "z": 4,
            "elements": [
                "chisel:glasspanedyedorange@5"
            ]
        },
        {
            "x": -2,
            "y": 15,
            "z": 3,
            "elements": [
                "chisel:antiblock@0"
            ]
        },
        {
            "x": -2,
            "y": 15,
            "z": 2,
            "elements": [
                "mekanism:plasticfence@0"
            ]
        },
        {
            "x": 0,
            "y": -8,
            "z": -19,
            "elements": [
                "chisel:antiblock@0"
            ]
        },
        {
            "x": -3,
            "y": -9,
            "z": 24,
            "elements": [
                "chisel:antiblock@0"
            ]
        },
        {
            "x": -3,
            "y": -9,
            "z": 23,
            "elements": [
                "thermalfoundation:storage_alloy@6"
            ]
        },
        {
            "x": 0,
            "y": -8,
            "z": -18,
            "elements": [
                "chisel:antiblock@0"
            ]
        },
        {
            "x": 0,
            "y": -8,
            "z": -20,
            "elements": [
                "chisel:antiblock@14"
            ]
        },
        {
            "x": -3,
            "y": -9,
            "z": 22,
            "elements": [
                "chisel:antiblock@0"
            ]
        },
        {
            "x": -3,
            "y": -9,
            "z": 31,
            "elements": [
                "chisel:antiblock@0"
            ]
        },
        {
            "x": -3,
            "y": -9,
            "z": 28,
            "elements": [
                "chisel:antiblock@0"
            ]
        },
        {
            "x": -3,
            "y": -9,
            "z": 27,
            "elements": [
                "chisel:antiblock@0"
            ]
        },
        {
            "x": -3,
            "y": -9,
            "z": 30,
            "elements": [
                "chisel:antiblock@0"
            ]
        },
        {
            "x": -3,
            "y": -9,
            "z": 29,
            "elements": [
                "chisel:antiblock@0"
            ]
        },
        {
            "x": 22,
            "y": -3,
            "z": 8,
            "elements": [
                "chisel:antiblock@0"
            ]
        },
        {
            "x": 22,
            "y": -3,
            "z": 7,
            "elements": [
                "minecraft:stained_glass_pane@1"
            ]
        },
        {
            "x": 22,
            "y": -3,
            "z": 6,
            "elements": [
                "chisel:antiblock@0"
            ]
        },
        {
            "x": -26,
            "y": -9,
            "z": 8,
            "elements": [
                "chisel:antiblock@0"
            ]
        },
        {
            "x": -26,
            "y": -9,
            "z": 9,
            "elements": [
                "chisel:antiblock@0"
            ]
        },
        {
            "x": -26,
            "y": -9,
            "z": 6,
            "elements": [
                "chisel:antiblock@0"
            ]
        },
        {
            "x": -26,
            "y": -9,
            "z": 7,
            "elements": [
                "chisel:antiblock@0"
            ]
        },
        {
            "x": -26,
            "y": -9,
            "z": 4,
            "elements": [
                "chisel:antiblock@0"
            ]
        },
        {
            "x": -26,
            "y": -9,
            "z": 5,
            "elements": [
                "chisel:antiblock@0"
            ]
        },
        {
            "x": -26,
            "y": -9,
            "z": 3,
            "elements": [
                "minecraft:red_sandstone_stairs@0"
            ]
        },
        {
            "x": 0,
            "y": 50,
            "z": 15,
            "elements": [
                "minecraft:end_rod@4"
            ]
        },
        {
            "x": 3,
            "y": 1,
            "z": 1,
            "elements": [
                "appliedenergistics2:fluix_stairs@3"
            ]
        },
        {
            "x": 3,
            "y": 1,
            "z": 2,
            "elements": [
                "appliedenergistics2:fluix_stairs@0"
            ]
        },
        {
            "x": 3,
            "y": 1,
            "z": 0,
            "elements": [
                "chisel:antiblock@0"
            ]
        },
        {
            "x": -26,
            "y": -9,
            "z": 10,
            "elements": [
                "chisel:antiblock@0"
            ]
        },
        {
            "x": -26,
            "y": -9,
            "z": 11,
            "elements": [
                "minecraft:red_sandstone_stairs@0"
            ]
        },
        {
            "x": 1,
            "y": 45,
            "z": -3,
            "elements": [
                "chisel:antiblock@0"
            ]
        },
        {
            "x": 1,
            "y": 45,
            "z": -2,
            "elements": [
                "minecraft:stained_glass_pane@1"
            ]
        },
        {
            "x": 1,
            "y": 45,
            "z": -1,
            "elements": [
                "chisel:antiblock@0"
            ]
        },
        {
            "x": 1,
            "y": 45,
            "z": 0,
            "elements": [
                "botania:quartzstairsdark@7"
            ]
        },
        {
            "x": -13,
            "y": 27,
            "z": 8,
            "elements": [
                "futuremc:red_sandstone_wall@0"
            ]
        },
        {
            "x": 3,
            "y": 1,
            "z": 9,
            "elements": [
                "chisel:antiblock@0"
            ]
        },
        {
            "x": 3,
            "y": 1,
            "z": 10,
            "elements": [
                "chisel:antiblock@0"
            ]
        },
        {
            "x": 3,
            "y": 1,
            "z": 7,
            "elements": [
                "chisel:antiblock@0"
            ]
        },
        {
            "x": -13,
            "y": 27,
            "z": 6,
            "elements": [
                "futuremc:red_sandstone_wall@0"
            ]
        },
        {
            "x": 3,
            "y": 1,
            "z": 8,
            "elements": [
                "chisel:antiblock@0"
            ]
        },
        {
            "x": 3,
            "y": 1,
            "z": 5,
            "elements": [
                "chisel:antiblock@0"
            ]
        },
        {
            "x": 3,
            "y": 1,
            "z": 6,
            "elements": [
                "chisel:antiblock@0"
            ]
        },
        {
            "x": 3,
            "y": 1,
            "z": 3,
            "elements": [
                "appliedenergistics2:fluix_stairs@2"
            ]
        },
        {
            "x": 3,
            "y": 1,
            "z": 4,
            "elements": [
                "chisel:antiblock@0"
            ]
        },
        {
            "x": 3,
            "y": 1,
            "z": 13,
            "elements": [
                "appliedenergistics2:fluix_stairs@2"
            ]
        },
        {
            "x": 3,
            "y": 1,
            "z": 14,
            "elements": [
                "chisel:antiblock@0"
            ]
        },
        {
            "x": 3,
            "y": 1,
            "z": 11,
            "elements": [
                "appliedenergistics2:fluix_stairs@3"
            ]
        },
        {
            "x": 3,
            "y": 1,
            "z": 12,
            "elements": [
                "appliedenergistics2:fluix_stairs@0"
            ]
        },
        {
            "x": -2,
            "y": -6,
            "z": -14,
            "elements": [
                "minecraft:stone_slab2@0"
            ]
        },
        {
            "x": -2,
            "y": -6,
            "z": -17,
            "elements": [
                "chisel:antiblock@0"
            ]
        },
        {
            "x": 3,
            "y": -7,
            "z": 28,
            "elements": [
                "chisel:antiblock@0"
            ]
        },
        {
            "x": -2,
            "y": -6,
            "z": -12,
            "elements": [
                "minecraft:stone_slab2@0"
            ]
        },
        {
            "x": -2,
            "y": -6,
            "z": -13,
            "elements": [
                "minecraft:stone_slab2@0"
            ]
        },
        {
            "x": 3,
            "y": -7,
            "z": 27,
            "elements": [
                "chisel:antiblock@0"
            ]
        },
        {
            "x": -2,
            "y": -6,
            "z": -5,
            "elements": [
                "thermalfoundation:glass_alloy@6"
            ]
        },
        {
            "x": -20,
            "y": -7,
            "z": 4,
            "elements": [
                "chisel:antiblock@0"
            ]
        },
        {
            "x": -20,
            "y": -7,
            "z": 5,
            "elements": [
                "chisel:antiblock@0"
            ]
        },
        {
            "x": -20,
            "y": -7,
            "z": 6,
            "elements": [
                "chisel:antiblock@0"
            ]
        },
        {
            "x": -20,
            "y": -7,
            "z": 7,
            "elements": [
                "chisel:antiblock@0"
            ]
        },
        {
            "x": -20,
            "y": -7,
            "z": 8,
            "elements": [
                "chisel:antiblock@0"
            ]
        },
        {
            "x": -20,
            "y": -7,
            "z": 9,
            "elements": [
                "chisel:antiblock@0"
            ]
        },
        {
            "x": 3,
            "y": -7,
            "z": 26,
            "elements": [
                "chisel:antiblock@0"
            ]
        },
        {
            "x": 10,
            "y": 35,
            "z": 6,
            "elements": [
                "chisel:antiblock@0"
            ]
        },
        {
            "x": 10,
            "y": 35,
            "z": 8,
            "elements": [
                "chisel:antiblock@0"
            ]
        },
        {
            "x": 3,
            "y": -7,
            "z": 22,
            "elements": [
                "botania:quartzstairsdark@2"
            ]
        },
        {
            "x": -3,
            "y": 12,
            "z": 9,
            "elements": [
                "chisel:glasspanedyedorange@5"
            ]
        },
        {
            "x": 3,
            "y": -7,
            "z": 21,
            "elements": [
                "thermalfoundation:glass_alloy@6"
            ]
        },
        {
            "x": 3,
            "y": -7,
            "z": 20,
            "elements": [
                "thermalfoundation:glass_alloy@6"
            ]
        },
        {
            "x": 3,
            "y": -7,
            "z": 19,
            "elements": [
                "chisel:antiblock@0"
            ]
        },
        {
            "x": -2,
            "y": -6,
            "z": 19,
            "elements": [
                "thermalfoundation:glass_alloy@6"
            ]
        },
        {
            "x": 3,
            "y": -7,
            "z": -5,
            "elements": [
                "chisel:antiblock@0"
            ]
        },
        {
            "x": -2,
            "y": -6,
            "z": 26,
            "elements": [
                "minecraft:stone_slab2@0"
            ]
        },
        {
            "x": -20,
            "y": -7,
            "z": 10,
            "elements": [
                "chisel:antiblock@0"
            ]
        },
        {
            "x": 0,
            "y": 42,
            "z": 15,
            "elements": [
                "minecraft:end_rod@4"
            ]
        },
        {
            "x": -2,
            "y": -6,
            "z": 28,
            "elements": [
                "minecraft:stone_slab2@0"
            ]
        },
        {
            "x": -2,
            "y": -6,
            "z": 27,
            "elements": [
                "minecraft:stone_slab2@0"
            ]
        },
        {
            "x": -22,
            "y": -5,
            "z": 6,
            "elements": [
                "minecraft:stained_glass_pane@1"
            ]
        },
        {
            "x": 3,
            "y": -7,
            "z": -14,
            "elements": [
                "chisel:antiblock@0"
            ]
        },
        {
            "x": -22,
            "y": -5,
            "z": 7,
            "elements": [
                "thermalfoundation:storage_alloy@6"
            ]
        },
        {
            "x": -22,
            "y": -5,
            "z": 8,
            "elements": [
                "minecraft:stained_glass_pane@1"
            ]
        },
        {
            "x": -2,
            "y": -6,
            "z": 31,
            "elements": [
                "chisel:antiblock@0"
            ]
        },
        {
            "x": 0,
            "y": 50,
            "z": -1,
            "elements": [
                "minecraft:end_rod@4"
            ]
        },
        {
            "x": 3,
            "y": -7,
            "z": -6,
            "elements": [
                "thermalfoundation:glass_alloy@6"
            ]
        },
        {
            "x": 3,
            "y": -7,
            "z": -7,
            "elements": [
                "thermalfoundation:glass_alloy@6"
            ]
        },
        {
            "x": 3,
            "y": -7,
            "z": -8,
            "elements": [
                "botania:quartzstairsdark@3"
            ]
        },
        {
            "x": 3,
            "y": -7,
            "z": -12,
            "elements": [
                "chisel:antiblock@0"
            ]
        },
        {
            "x": 3,
            "y": -7,
            "z": -13,
            "elements": [
                "chisel:antiblock@0"
            ]
        },
        {
            "x": 2,
            "y": -2,
            "z": -1,
            "elements": [
                "chisel:antiblock@0"
            ]
        },
        {
            "x": -25,
            "y": -6,
            "z": 5,
            "elements": [
                "chisel:antiblock@0"
            ]
        },
        {
            "x": 2,
            "y": -2,
            "z": 4,
            "elements": [
                "enderio:block_alloy_endergy@2"
            ]
        },
        {
            "x": 7,
            "y": 34,
            "z": 6,
            "elements": [
                "botania:quartzstairsdark@4"
            ]
        },
        {
            "x": 7,
            "y": 34,
            "z": 8,
            "elements": [
                "botania:quartzstairsdark@4"
            ]
        },
        {
            "x": 2,
            "y": -2,
            "z": 6,
            "elements": [
                "enderio:block_alloy_endergy@2"
            ]
        },
        {
            "x": 2,
            "y": -2,
            "z": 5,
            "elements": [
                "enderio:block_alloy_endergy@2"
            ]
        },
        {
            "x": -25,
            "y": -6,
            "z": 9,
            "elements": [
                "chisel:antiblock@0"
            ]
        },
        {
            "x": -1,
            "y": 47,
            "z": 10,
            "elements": [
                "minecraft:stained_glass@1"
            ]
        },
        {
            "x": 2,
            "y": -2,
            "z": -17,
            "elements": [
                "chisel:antiblock@0"
            ]
        },
        {
            "x": -1,
            "y": 47,
            "z": 14,
            "elements": [
                "botania:quartzstairsdark@6"
            ]
        },
        {
            "x": -1,
            "y": 47,
            "z": 15,
            "elements": [
                "chisel:antiblock@0"
            ]
        },
        {
            "x": -1,
            "y": 47,
            "z": 16,
            "elements": [
                "minecraft:stained_glass_pane@1"
            ]
        },
        {
            "x": -1,
            "y": 47,
            "z": 17,
            "elements": [
                "chisel:antiblock@0"
            ]
        },
        {
            "x": 8,
            "y": 29,
            "z": 8,
            "elements": [
                "chisel:antiblock@0"
            ]
        },
        {
            "x": 8,
            "y": 29,
            "z": 6,
            "elements": [
                "chisel:antiblock@0"
            ]
        },
        {
            "x": 2,
            "y": -2,
            "z": -18,
            "elements": [
                "chisel:antiblock@0"
            ]
        },
        {
            "x": 2,
            "y": -2,
            "z": -19,
            "elements": [
                "mekanism:plasticfence@0"
            ]
        },
        {
            "x": 8,
            "y": 29,
            "z": 7,
            "elements": [
                "minecraft:end_rod@3"
            ]
        },
        {
            "x": 2,
            "y": -2,
            "z": 31,
            "elements": [
                "chisel:antiblock@0"
            ]
        },
        {
            "x": -3,
            "y": 12,
            "z": 5,
            "elements": [
                "chisel:glasspanedyedorange@5"
            ]
        },
        {
            "x": 2,
            "y": -2,
            "z": 15,
            "elements": [
                "chisel:antiblock@0"
            ]
        },
        {
            "x": 2,
            "y": -2,
            "z": 8,
            "elements": [
                "enderio:block_alloy_endergy@2"
            ]
        },
        {
            "x": 2,
            "y": -2,
            "z": 7,
            "elements": [
                "enderio:block_alloy_endergy@2"
            ]
        },
        {
            "x": 2,
            "y": -2,
            "z": 10,
            "elements": [
                "enderio:block_alloy_endergy@2"
            ]
        },
        {
            "x": 2,
            "y": -2,
            "z": 9,
            "elements": [
                "enderio:block_alloy_endergy@2"
            ]
        },
        {
            "x": -1,
            "y": -3,
            "z": -19,
            "elements": [
                "chisel:antiblock@0"
            ]
        },
        {
            "x": -1,
            "y": -3,
            "z": -15,
            "elements": [
                "chisel:antiblock@0"
            ]
        },
        {
            "x": -1,
            "y": -3,
            "z": -14,
            "elements": [
                "minecraft:stained_glass_pane@1"
            ]
        },
        {
            "x": -1,
            "y": -3,
            "z": -13,
            "elements": [
                "chisel:antiblock@0"
            ]
        },
        {
            "x": 24,
            "y": 3,
            "z": 5,
            "elements": [
                "chisel:antiblock@0"
            ]
        },
        {
            "x": 24,
            "y": 3,
            "z": 7,
            "elements": [
                "chisel:antiblock@0"
            ]
        },
        {
            "x": 24,
            "y": 3,
            "z": 6,
            "elements": [
                "chisel:antiblock@0"
            ]
        },
        {
            "x": 24,
            "y": 3,
            "z": 9,
            "elements": [
                "chisel:antiblock@0"
            ]
        },
        {
            "x": 24,
            "y": 3,
            "z": 8,
            "elements": [
                "chisel:antiblock@0"
            ]
        },
        {
            "x": 4,
            "y": -4,
            "z": 12,
            "elements": [
                "enderio:block_alloy_endergy@2"
            ]
        },
        {
            "x": 4,
            "y": -4,
            "z": 11,
            "elements": [
                "enderio:block_alloy_endergy@2"
            ]
        },
        {
            "x": -1,
            "y": -3,
            "z": -4,
            "elements": [
                "chisel:antiblock@0"
            ]
        },
        {
            "x": -1,
            "y": -3,
            "z": -3,
            "elements": [
                "chisel:antiblock@0"
            ]
        },
        {
            "x": -1,
            "y": -3,
            "z": -2,
            "elements": [
                "appliedenergistics2:fluix_stairs@3"
            ]
        },
        {
            "x": -21,
            "y": -10,
            "z": 13,
            "elements": [
                "mekanism:plasticfence@0"
            ]
        },
        {
            "x": -1,
            "y": -3,
            "z": -1,
            "elements": [
                "thermalfoundation:glass_alloy@6"
            ]
        },
        {
            "x": 4,
            "y": -4,
            "z": 8,
            "elements": [
                "enderio:block_alloy_endergy@2"
            ]
        },
        {
            "x": -1,
            "y": -3,
            "z": 0,
            "elements": [
                "thermalfoundation:storage_alloy@6"
            ]
        },
        {
            "x": -21,
            "y": -10,
            "z": 12,
            "elements": [
                "chisel:antiblock@0"
            ]
        },
        {
            "x": 4,
            "y": -4,
            "z": 7,
            "elements": [
                "enderio:block_alloy_endergy@2"
            ]
        },
        {
            "x": 4,
            "y": -4,
            "z": 10,
            "elements": [
                "enderio:block_alloy_endergy@2"
            ]
        },
        {
            "x": 4,
            "y": -4,
            "z": 9,
            "elements": [
                "enderio:block_alloy_endergy@2"
            ]
        },
        {
            "x": -1,
            "y": -3,
            "z": 3,
            "elements": [
                "enderio:block_alloy_endergy@2"
            ]
        },
        {
            "x": -21,
            "y": -10,
            "z": 1,
            "elements": [
                "mekanism:plasticfence@0"
            ]
        },
        {
            "x": -1,
            "y": -3,
            "z": 4,
            "elements": [
                "enderio:block_alloy_endergy@2"
            ]
        },
        {
            "x": -1,
            "y": -3,
            "z": 5,
            "elements": [
                "enderio:block_alloy_endergy@2"
            ]
        },
        {
            "x": -1,
            "y": -3,
            "z": 6,
            "elements": [
                "enderio:block_alloy_endergy@2"
            ]
        },
        {
            "x": -1,
            "y": -3,
            "z": 7,
            "elements": [
                "enderio:block_alloy_endergy@2"
            ]
        },
        {
            "x": -1,
            "y": -3,
            "z": 8,
            "elements": [
                "enderio:block_alloy_endergy@2"
            ]
        },
        {
            "x": 9,
            "y": 32,
            "z": 8,
            "elements": [
                "minecraft:stained_glass_pane@1"
            ]
        },
        {
            "x": 4,
            "y": -4,
            "z": 18,
            "elements": [
                "chisel:antiblock@0"
            ]
        },
        {
            "x": -1,
            "y": -3,
            "z": 9,
            "elements": [
                "enderio:block_alloy_endergy@2"
            ]
        },
        {
            "x": 9,
            "y": 32,
            "z": 6,
            "elements": [
                "minecraft:stained_glass_pane@1"
            ]
        },
        {
            "x": -1,
            "y": -3,
            "z": 10,
            "elements": [
                "enderio:block_alloy_endergy@2"
            ]
        },
        {
            "x": -21,
            "y": -10,
            "z": 2,
            "elements": [
                "chisel:antiblock@0"
            ]
        },
        {
            "x": 4,
            "y": -4,
            "z": -4,
            "elements": [
                "chisel:antiblock@0"
            ]
        },
        {
            "x": -1,
            "y": -3,
            "z": 11,
            "elements": [
                "enderio:block_alloy_endergy@2"
            ]
        },
        {
            "x": -1,
            "y": -3,
            "z": 14,
            "elements": [
                "thermalfoundation:storage_alloy@6"
            ]
        },
        {
            "x": -1,
            "y": -3,
            "z": 15,
            "elements": [
                "thermalfoundation:glass_alloy@6"
            ]
        },
        {
            "x": -1,
            "y": 47,
            "z": -3,
            "elements": [
                "chisel:antiblock@0"
            ]
        },
        {
            "x": 1,
            "y": 45,
            "z": 17,
            "elements": [
                "chisel:antiblock@0"
            ]
        },
        {
            "x": -1,
            "y": -3,
            "z": 16,
            "elements": [
                "appliedenergistics2:fluix_stairs@2"
            ]
        },
        {
            "x": -1,
            "y": 47,
            "z": -2,
            "elements": [
                "minecraft:stained_glass_pane@1"
            ]
        },
        {
            "x": -1,
            "y": 47,
            "z": -1,
            "elements": [
                "chisel:antiblock@0"
            ]
        },
        {
            "x": -1,
            "y": -3,
            "z": 17,
            "elements": [
                "chisel:antiblock@0"
            ]
        },
        {
            "x": -1,
            "y": -3,
            "z": 18,
            "elements": [
                "chisel:antiblock@0"
            ]
        },
        {
            "x": -1,
            "y": 47,
            "z": 0,
            "elements": [
                "botania:quartzstairsdark@7"
            ]
        },
        {
            "x": 4,
            "y": -4,
            "z": 4,
            "elements": [
                "enderio:block_alloy_endergy@2"
            ]
        },
        {
            "x": 1,
            "y": 45,
            "z": 14,
            "elements": [
                "botania:quartzstairsdark@6"
            ]
        },
        {
            "x": 4,
            "y": -4,
            "z": 3,
            "elements": [
                "enderio:block_alloy_endergy@2"
            ]
        },
        {
            "x": 1,
            "y": 45,
            "z": 15,
            "elements": [
                "chisel:antiblock@0"
            ]
        },
        {
            "x": 4,
            "y": -4,
            "z": 6,
            "elements": [
                "enderio:block_alloy_endergy@2"
            ]
        },
        {
            "x": 4,
            "y": -4,
            "z": 5,
            "elements": [
                "enderio:block_alloy_endergy@2"
            ]
        },
        {
            "x": 1,
            "y": 45,
            "z": 16,
            "elements": [
                "minecraft:stained_glass_pane@1"
            ]
        },
        {
            "x": -1,
            "y": 47,
            "z": 4,
            "elements": [
                "minecraft:stained_glass@1"
            ]
        },
        {
            "x": 4,
            "y": -4,
            "z": 2,
            "elements": [
                "enderio:block_alloy_endergy@2"
            ]
        },
        {
            "x": -1,
            "y": -3,
            "z": 27,
            "elements": [
                "chisel:antiblock@0"
            ]
        },
        {
            "x": -1,
            "y": -3,
            "z": 28,
            "elements": [
                "minecraft:stained_glass_pane@1"
            ]
        },
        {
            "x": -1,
            "y": -3,
            "z": 29,
            "elements": [
                "chisel:antiblock@0"
            ]
        },
        {
            "x": -23,
            "y": -8,
            "z": 11,
            "elements": [
                "minecraft:stone_slab2@0"
            ]
        },
        {
            "x": -23,
            "y": -8,
            "z": 10,
            "elements": [
                "botania:quartzstairsdark@3"
            ]
        },
        {
            "x": -23,
            "y": -8,
            "z": 9,
            "elements": [
                "chisel:antiblock@0"
            ]
        },
        {
            "x": -23,
            "y": -8,
            "z": 8,
            "elements": [
                "chisel:antiblock@0"
            ]
        },
        {
            "x": -23,
            "y": -8,
            "z": 7,
            "elements": [
                "chisel:antiblock@0"
            ]
        },
        {
            "x": -23,
            "y": -8,
            "z": 6,
            "elements": [
                "chisel:antiblock@0"
            ]
        },
        {
            "x": -23,
            "y": -8,
            "z": 5,
            "elements": [
                "chisel:antiblock@0"
            ]
        },
        {
            "x": -23,
            "y": -8,
            "z": 4,
            "elements": [
                "botania:quartzstairsdark@2"
            ]
        },
        {
            "x": -23,
            "y": -8,
            "z": 3,
            "elements": [
                "minecraft:stone_slab2@0"
            ]
        },
        {
            "x": 11,
            "y": 1,
            "z": -4,
            "elements": [
                "botania:quartzslabdarkhalf@8"
            ]
        },
        {
            "x": 11,
            "y": 1,
            "z": -3,
            "elements": [
                "botania:quartzslabdarkhalf@0"
            ]
        },
        {
            "x": -15,
            "y": 8,
            "z": 8,
            "elements": [
                "chisel:antiblock@0"
            ]
        },
        {
            "x": 20,
            "y": -1,
            "z": 7,
            "elements": [
                "thermalfoundation:storage_alloy@6"
            ]
        },
        {
            "x": 0,
            "y": 0,
            "z": 28,
            "elements": [
                "minecraft:stained_glass_pane@1"
            ]
        },
        {
            "x": 20,
            "y": -1,
            "z": 6,
            "elements": [
                "minecraft:stained_glass_pane@1"
            ]
        },
        {
            "x": 0,
            "y": 0,
            "z": 27,
            "elements": [
                "thermalfoundation:storage_alloy@6"
            ]
        },
        {
            "x": -15,
            "y": 8,
            "z": 6,
            "elements": [
                "chisel:antiblock@0"
            ]
        },
        {
            "x": -24,
            "y": -3,
            "z": 5,
            "elements": [
                "chisel:antiblock@0"
            ]
        },
        {
            "x": -15,
            "y": 8,
            "z": 7,
            "elements": [
                "minecraft:stained_glass_pane@1"
            ]
        },
        {
            "x": -1,
            "y": 39,
            "z": 14,
            "elements": [
                "botania:quartzstairsdark@6"
            ]
        },
        {
            "x": -24,
            "y": -3,
            "z": 9,
            "elements": [
                "chisel:antiblock@0"
            ]
        },
        {
            "x": -1,
            "y": 39,
            "z": 16,
            "elements": [
                "minecraft:stained_glass_pane@1"
            ]
        },
        {
            "x": 0,
            "y": 0,
            "z": 26,
            "elements": [
                "minecraft:stained_glass_pane@1"
            ]
        },
        {
            "x": 20,
            "y": -1,
            "z": 8,
            "elements": [
                "minecraft:stained_glass_pane@1"
            ]
        },
        {
            "x": -1,
            "y": 39,
            "z": 15,
            "elements": [
                "chisel:antiblock@0"
            ]
        },
        {
            "x": 11,
            "y": 1,
            "z": 17,
            "elements": [
                "botania:quartzslabdarkhalf@0"
            ]
        },
        {
            "x": 11,
            "y": 1,
            "z": 18,
            "elements": [
                "botania:quartzslabdarkhalf@8"
            ]
        },
        {
            "x": 0,
            "y": 0,
            "z": 14,
            "elements": [
                "modularmachinery:blockenergyoutputhatch"
            ]
        },
        {
            "x": -4,
            "y": 9,
            "z": 5,
            "elements": [
                "chisel:antiblock@0"
            ]
        },
        {
            "x": -1,
            "y": 39,
            "z": -2,
            "elements": [
                "minecraft:stained_glass_pane@1"
            ]
        },
        {
            "x": 0,
            "y": 0,
            "z": 7,
            "elements": [
                "minecraft:beacon@0"
            ]
        },
        {
            "x": -1,
            "y": 39,
            "z": -3,
            "elements": [
                "chisel:antiblock@0"
            ]
        },
        {
            "x": -4,
            "y": 9,
            "z": 6,
            "elements": [
                "minecraft:end_rod@3"
            ]
        },
        {
            "x": -4,
            "y": 9,
            "z": 9,
            "elements": [
                "chisel:antiblock@0"
            ]
        },
        {
            "x": -1,
            "y": 39,
            "z": 0,
            "elements": [
                "botania:quartzstairsdark@7"
            ]
        },
        {
            "x": -1,
            "y": 39,
            "z": -1,
            "elements": [
                "chisel:antiblock@0"
            ]
        },
        {
            "x": -4,
            "y": 9,
            "z": 8,
            "elements": [
                "minecraft:end_rod@2"
            ]
        },
        {
            "x": 0,
            "y": 13,
            "z": 22,
            "elements": [
                "minecraft:stained_glass_pane@1"
            ]
        },
        {
            "x": 0,
            "y": 13,
            "z": 21,
            "elements": [
                "thermalfoundation:storage_alloy@6"
            ]
        },
        {
            "x": 0,
            "y": 13,
            "z": 20,
            "elements": [
                "minecraft:stained_glass_pane@1"
            ]
        },
        {
            "x": -10,
            "y": 28,
            "z": 6,
            "elements": [
                "chisel:antiblock@0"
            ]
        },
        {
            "x": -10,
            "y": 28,
            "z": 8,
            "elements": [
                "chisel:antiblock@0"
            ]
        },
        {
            "x": 0,
            "y": 0,
            "z": -12,
            "elements": [
                "minecraft:stained_glass_pane@1"
            ]
        },
        {
            "x": 0,
            "y": 0,
            "z": -13,
            "elements": [
                "thermalfoundation:storage_alloy@6"
            ]
        },
        {
            "x": 0,
            "y": 0,
            "z": -14,
            "elements": [
                "minecraft:stained_glass_pane@1"
            ]
        },
        {
            "x": 0,
            "y": 0,
            "z": -19,
            "elements": [
                "chisel:antiblock@0"
            ]
        },
        {
            "x": 10,
            "y": 27,
            "z": 8,
            "elements": [
                "chisel:antiblock@0"
            ]
        },
        {
            "x": 0,
            "y": 13,
            "z": -7,
            "elements": [
                "thermalfoundation:storage_alloy@6"
            ]
        },
        {
            "x": 0,
            "y": 13,
            "z": -8,
            "elements": [
                "minecraft:stained_glass_pane@1"
            ]
        },
        {
            "x": 10,
            "y": 27,
            "z": 6,
            "elements": [
                "chisel:antiblock@0"
            ]
        },
        {
            "x": -4,
            "y": -4,
            "z": 18,
            "elements": [
                "chisel:antiblock@0"
            ]
        },
        {
            "x": 0,
            "y": 13,
            "z": -6,
            "elements": [
                "minecraft:stained_glass_pane@1"
            ]
        },
        {
            "x": -1,
            "y": 26,
            "z": 20,
            "elements": [
                "minecraft:anvil@0"
            ]
        },
        {
            "x": -4,
            "y": -4,
            "z": -4,
            "elements": [
                "chisel:antiblock@0"
            ]
        },
        {
            "x": -1,
            "y": 26,
            "z": 17,
            "elements": [
                "chisel:antiblock@0"
            ]
        },
        {
            "x": -1,
            "y": 26,
            "z": 16,
            "elements": [
                "chisel:antiblock@0"
            ]
        },
        {
            "x": -1,
            "y": 26,
            "z": 15,
            "elements": [
                "chisel:antiblock@0"
            ]
        },
        {
            "x": -1,
            "y": 26,
            "z": -3,
            "elements": [
                "chisel:antiblock@0"
            ]
        },
        {
            "x": -4,
            "y": -4,
            "z": 6,
            "elements": [
                "enderio:block_alloy_endergy@2"
            ]
        },
        {
            "x": -4,
            "y": -4,
            "z": 5,
            "elements": [
                "enderio:block_alloy_endergy@2"
            ]
        },
        {
            "x": -4,
            "y": -4,
            "z": 4,
            "elements": [
                "enderio:block_alloy_endergy@2"
            ]
        },
        {
            "x": -1,
            "y": 26,
            "z": -6,
            "elements": [
                "minecraft:anvil@0"
            ]
        },
        {
            "x": -4,
            "y": -4,
            "z": 3,
            "elements": [
                "enderio:block_alloy_endergy@2"
            ]
        },
        {
            "x": -4,
            "y": -4,
            "z": 2,
            "elements": [
                "enderio:block_alloy_endergy@2"
            ]
        },
        {
            "x": -4,
            "y": -4,
            "z": 12,
            "elements": [
                "enderio:block_alloy_endergy@2"
            ]
        },
        {
            "x": -4,
            "y": -4,
            "z": 11,
            "elements": [
                "enderio:block_alloy_endergy@2"
            ]
        },
        {
            "x": -4,
            "y": -4,
            "z": 10,
            "elements": [
                "enderio:block_alloy_endergy@2"
            ]
        },
        {
            "x": -4,
            "y": -4,
            "z": 9,
            "elements": [
                "enderio:block_alloy_endergy@2"
            ]
        },
        {
            "x": -1,
            "y": 26,
            "z": -1,
            "elements": [
                "chisel:antiblock@0"
            ]
        },
        {
            "x": -4,
            "y": -4,
            "z": 8,
            "elements": [
                "enderio:block_alloy_endergy@2"
            ]
        },
        {
            "x": -1,
            "y": 26,
            "z": -2,
            "elements": [
                "chisel:antiblock@0"
            ]
        },
        {
            "x": -4,
            "y": -4,
            "z": 7,
            "elements": [
                "enderio:block_alloy_endergy@2"
            ]
        },
        {
            "x": 1,
            "y": 3,
            "z": 30,
            "elements": [
                "chisel:antiblock@0"
            ]
        },
        {
            "x": 1,
            "y": 3,
            "z": 27,
            "elements": [
                "chisel:antiblock@0"
            ]
        },
        {
            "x": 1,
            "y": 53,
            "z": 16,
            "elements": [
                "minecraft:stained_glass_pane@1"
            ]
        },
        {
            "x": 1,
            "y": 53,
            "z": 15,
            "elements": [
                "chisel:antiblock@0"
            ]
        },
        {
            "x": 1,
            "y": 53,
            "z": 14,
            "elements": [
                "botania:quartzstairsdark@6"
            ]
        },
        {
            "x": 1,
            "y": 3,
            "z": 31,
            "elements": [
                "chisel:antiblock@0"
            ]
        },
        {
            "x": 10,
            "y": -2,
            "z": -1,
            "elements": [
                "chisel:antiblock@0"
            ]
        },
        {
            "x": 1,
            "y": 3,
            "z": 21,
            "elements": [
                "futuremc:red_sandstone_wall@0"
            ]
        },
        {
            "x": 10,
            "y": -2,
            "z": 14,
            "elements": [
                "mekanism:plasticfence@0"
            ]
        },
        {
            "x": 1,
            "y": 3,
            "z": 19,
            "elements": [
                "futuremc:red_sandstone_wall@0"
            ]
        },
        {
            "x": 1,
            "y": 3,
            "z": 20,
            "elements": [
                "chisel:antiblock@0"
            ]
        },
        {
            "x": -14,
            "y": 11,
            "z": 6,
            "elements": [
                "chisel:antiblock@0"
            ]
        },
        {
            "x": 1,
            "y": 3,
            "z": 25,
            "elements": [
                "chisel:antiblock@0"
            ]
        },
        {
            "x": 1,
            "y": 3,
            "z": 26,
            "elements": [
                "minecraft:stained_glass_pane@1"
            ]
        },
        {
            "x": -14,
            "y": 11,
            "z": 7,
            "elements": [
                "minecraft:stained_glass_pane@1"
            ]
        },
        {
            "x": -14,
            "y": 11,
            "z": 8,
            "elements": [
                "chisel:antiblock@0"
            ]
        },
        {
            "x": 0,
            "y": 42,
            "z": 10,
            "elements": [
                "minecraft:stained_glass@1"
            ]
        },
        {
            "x": 1,
            "y": 3,
            "z": 11,
            "elements": [
                "minecraft:end_rod@4"
            ]
        },
        {
            "x": -5,
            "y": 6,
            "z": 5,
            "elements": [
                "mekanism:plasticfence@0"
            ]
        },
        {
            "x": 10,
            "y": -2,
            "z": 15,
            "elements": [
                "chisel:antiblock@0"
            ]
        },
        {
            "x": 12,
            "y": -9,
            "z": -5,
            "elements": [
                "chisel:antiblock@14"
            ]
        },
        {
            "x": 0,
            "y": 42,
            "z": 4,
            "elements": [
                "minecraft:stained_glass@1"
            ]
        },
        {
            "x": 12,
            "y": -9,
            "z": -6,
            "elements": [
                "chisel:antiblock@14"
            ]
        },
        {
            "x": 12,
            "y": -9,
            "z": -7,
            "elements": [
                "chisel:antiblock@0"
            ]
        },
        {
            "x": 1,
            "y": 3,
            "z": 3,
            "elements": [
                "minecraft:end_rod@4"
            ]
        },
        {
            "x": 12,
            "y": -9,
            "z": -8,
            "elements": [
                "chisel:antiblock@0"
            ]
        },
        {
            "x": 1,
            "y": 53,
            "z": 17,
            "elements": [
                "chisel:antiblock@0"
            ]
        },
        {
            "x": 12,
            "y": -9,
            "z": -9,
            "elements": [
                "chisel:antiblock@0"
            ]
        },
        {
            "x": 0,
            "y": 42,
            "z": -1,
            "elements": [
                "minecraft:end_rod@4"
            ]
        },
        {
            "x": -5,
            "y": 6,
            "z": 9,
            "elements": [
                "mekanism:plasticfence@0"
            ]
        },
        {
            "x": -9,
            "y": 31,
            "z": 6,
            "elements": [
                "minecraft:stained_glass_pane@1"
            ]
        },
        {
            "x": 1,
            "y": 16,
            "z": 19,
            "elements": [
                "chisel:antiblock@0"
            ]
        },
        {
            "x": 1,
            "y": 16,
            "z": 20,
            "elements": [
                "minecraft:stained_glass_pane@1"
            ]
        },
        {
            "x": 1,
            "y": 3,
            "z": -5,
            "elements": [
                "futuremc:red_sandstone_wall@0"
            ]
        },
        {
            "x": -9,
            "y": 31,
            "z": 8,
            "elements": [
                "minecraft:stained_glass_pane@1"
            ]
        },
        {
            "x": 1,
            "y": 16,
            "z": 21,
            "elements": [
                "chisel:antiblock@0"
            ]
        },
        {
            "x": 1,
            "y": 3,
            "z": -11,
            "elements": [
                "chisel:antiblock@0"
            ]
        },
        {
            "x": 1,
            "y": 3,
            "z": -13,
            "elements": [
                "chisel:antiblock@0"
            ]
        },
        {
            "x": 1,
            "y": 3,
            "z": -12,
            "elements": [
                "minecraft:stained_glass_pane@1"
            ]
        },
        {
            "x": 1,
            "y": 3,
            "z": -7,
            "elements": [
                "futuremc:red_sandstone_wall@0"
            ]
        },
        {
            "x": 1,
            "y": 3,
            "z": -6,
            "elements": [
                "chisel:antiblock@0"
            ]
        },
        {
            "x": 1,
            "y": 16,
            "z": 3,
            "elements": [
                "minecraft:end_rod@4"
            ]
        },
        {
            "x": 1,
            "y": 3,
            "z": -18,
            "elements": [
                "mekanism:plasticfence@14"
            ]
        },
        {
            "x": 1,
            "y": 3,
            "z": -17,
            "elements": [
                "chisel:antiblock@0"
            ]
        },
        {
            "x": 1,
            "y": 3,
            "z": -16,
            "elements": [
                "chisel:antiblock@0"
            ]
        },
        {
            "x": 1,
            "y": 16,
            "z": 11,
            "elements": [
                "minecraft:end_rod@4"
            ]
        },
        {
            "x": 1,
            "y": 16,
            "z": -6,
            "elements": [
                "minecraft:stained_glass_pane@1"
            ]
        },
        {
            "x": -5,
            "y": -7,
            "z": 21,
            "elements": [
                "chisel:antiblock@0"
            ]
        },
        {
            "x": 1,
            "y": 16,
            "z": -5,
            "elements": [
                "chisel:antiblock@0"
            ]
        },
        {
            "x": -5,
            "y": -7,
            "z": 22,
            "elements": [
                "chisel:antiblock@0"
            ]
        },
        {
            "x": -5,
            "y": -7,
            "z": 19,
            "elements": [
                "chisel:antiblock@0"
            ]
        },
        {
            "x": -5,
            "y": -7,
            "z": 20,
            "elements": [
                "chisel:antiblock@0"
            ]
        },
        {
            "x": 1,
            "y": 16,
            "z": -7,
            "elements": [
                "chisel:antiblock@0"
            ]
        },
        {
            "x": -14,
            "y": -5,
            "z": 17,
            "elements": [
                "botania:quartzslabdarkhalf@0"
            ]
        },
        {
            "x": -14,
            "y": -5,
            "z": -3,
            "elements": [
                "botania:quartzslabdarkhalf@0"
            ]
        },
        {
            "x": -6,
            "y": 3,
            "z": 20,
            "elements": [
                "chisel:antiblock@0"
            ]
        },
        {
            "x": 0,
            "y": 29,
            "z": 15,
            "elements": [
                "minecraft:end_rod@5"
            ]
        },
        {
            "x": -5,
            "y": -7,
            "z": -7,
            "elements": [
                "chisel:antiblock@0"
            ]
        },
        {
            "x": -5,
            "y": -7,
            "z": -6,
            "elements": [
                "chisel:antiblock@0"
            ]
        },
        {
            "x": -5,
            "y": -7,
            "z": -8,
            "elements": [
                "chisel:antiblock@0"
            ]
        },
        {
            "x": -1,
            "y": 39,
            "z": 17,
            "elements": [
                "chisel:antiblock@0"
            ]
        },
        {
            "x": 1,
            "y": 53,
            "z": 0,
            "elements": [
                "botania:quartzstairsdark@7"
            ]
        },
        {
            "x": -10,
            "y": 44,
            "z": 6,
            "elements": [
                "chisel:antiblock@0"
            ]
        },
        {
            "x": 1,
            "y": 53,
            "z": -1,
            "elements": [
                "chisel:antiblock@0"
            ]
        },
        {
            "x": 1,
            "y": 53,
            "z": -2,
            "elements": [
                "minecraft:stained_glass_pane@1"
            ]
        },
        {
            "x": -10,
            "y": 44,
            "z": 8,
            "elements": [
                "chisel:antiblock@0"
            ]
        },
        {
            "x": 1,
            "y": 53,
            "z": -3,
            "elements": [
                "chisel:antiblock@0"
            ]
        },
        {
            "x": 9,
            "y": 24,
            "z": 7,
            "elements": [
                "thermalfoundation:storage_alloy@6"
            ]
        },
        {
            "x": 0,
            "y": 29,
            "z": -1,
            "elements": [
                "minecraft:end_rod@5"
            ]
        },
        {
            "x": 9,
            "y": 24,
            "z": 6,
            "elements": [
                "minecraft:stained_glass_pane@1"
            ]
        },
        {
            "x": 9,
            "y": 24,
            "z": 8,
            "elements": [
                "minecraft:stained_glass_pane@1"
            ]
        },
        {
            "x": -1,
            "y": -11,
            "z": 22,
            "elements": [
                "chisel:antiblock@0"
            ]
        },
        {
            "x": -1,
            "y": -11,
            "z": 24,
            "elements": [
                "chisel:antiblock@0"
            ]
        },
        {
            "x": 2,
            "y": 6,
            "z": 30,
            "elements": [
                "botania:quartzstairsdark@3"
            ]
        },
        {
            "x": 18,
            "y": -7,
            "z": 5,
            "elements": [
                "minecraft:red_sandstone_stairs@0"
            ]
        },
        {
            "x": 18,
            "y": -7,
            "z": 9,
            "elements": [
                "minecraft:red_sandstone_stairs@0"
            ]
        },
        {
            "x": -6,
            "y": 3,
            "z": -6,
            "elements": [
                "chisel:antiblock@0"
            ]
        },
        {
            "x": -6,
            "y": -10,
            "z": -13,
            "elements": [
                "mekanism:plasticfence@0"
            ]
        },
        {
            "x": -6,
            "y": -10,
            "z": -12,
            "elements": [
                "chisel:antiblock@0"
            ]
        },
        {
            "x": -6,
            "y": -10,
            "z": -10,
            "elements": [
                "chisel:antiblock@0"
            ]
        },
        {
            "x": 2,
            "y": 6,
            "z": 10,
            "elements": [
                "chisel:glasspanedyedorange@5"
            ]
        },
        {
            "x": 2,
            "y": 6,
            "z": 11,
            "elements": [
                "chisel:antiblock@0"
            ]
        },
        {
            "x": 2,
            "y": 6,
            "z": 12,
            "elements": [
                "mekanism:plasticfence@0"
            ]
        },
        {
            "x": -6,
            "y": -10,
            "z": -14,
            "elements": [
                "mekanism:plasticfence@0"
            ]
        },
        {
            "x": 2,
            "y": 6,
            "z": 2,
            "elements": [
                "mekanism:plasticfence@0"
            ]
        },
        {
            "x": 2,
            "y": 6,
            "z": 3,
            "elements": [
                "chisel:antiblock@0"
            ]
        },
        {
            "x": 2,
            "y": 6,
            "z": 4,
            "elements": [
                "chisel:glasspanedyedorange@5"
            ]
        },
        {
            "x": 2,
            "y": 19,
            "z": 12,
            "elements": [
                "mekanism:plasticfence@0"
            ]
        },
        {
            "x": -1,
            "y": -11,
            "z": -10,
            "elements": [
                "chisel:antiblock@0"
            ]
        },
        {
            "x": 2,
            "y": 19,
            "z": 10,
            "elements": [
                "chisel:glasspanedyedorange@5"
            ]
        },
        {
            "x": 2,
            "y": 19,
            "z": 11,
            "elements": [
                "chisel:antiblock@0"
            ]
        },
        {
            "x": -1,
            "y": -11,
            "z": -8,
            "elements": [
                "chisel:antiblock@0"
            ]
        },
        {
            "x": -22,
            "y": 3,
            "z": 5,
            "elements": [
                "minecraft:stained_glass_pane@1"
            ]
        },
        {
            "x": -8,
            "y": 34,
            "z": 7,
            "elements": [
                "minecraft:end_rod@3"
            ]
        },
        {
            "x": -8,
            "y": 34,
            "z": 8,
            "elements": [
                "chisel:antiblock@0"
            ]
        },
        {
            "x": 2,
            "y": 6,
            "z": -16,
            "elements": [
                "botania:quartzstairsdark@2"
            ]
        },
        {
            "x": -8,
            "y": 34,
            "z": 6,
            "elements": [
                "chisel:antiblock@0"
            ]
        },
        {
            "x": -22,
            "y": 3,
            "z": 9,
            "elements": [
                "minecraft:stained_glass_pane@1"
            ]
        },
        {
            "x": 2,
            "y": 19,
            "z": 4,
            "elements": [
                "chisel:glasspanedyedorange@5"
            ]
        },
        {
            "x": 2,
            "y": 19,
            "z": 2,
            "elements": [
                "mekanism:plasticfence@0"
            ]
        },
        {
            "x": 2,
            "y": 19,
            "z": 3,
            "elements": [
                "chisel:antiblock@0"
            ]
        },
        {
            "x": -6,
            "y": -10,
            "z": 27,
            "elements": [
                "mekanism:plasticfence@0"
            ]
        },
        {
            "x": -11,
            "y": 4,
            "z": 16,
            "elements": [
                "mekanism:plasticfence@0"
            ]
        },
        {
            "x": -6,
            "y": -10,
            "z": 28,
            "elements": [
                "mekanism:plasticfence@0"
            ]
        },
        {
            "x": -11,
            "y": 4,
            "z": 17,
            "elements": [
                "minecraft:end_rod@5"
            ]
        },
        {
            "x": -11,
            "y": 4,
            "z": 15,
            "elements": [
                "minecraft:stained_glass_pane@1"
            ]
        },
        {
            "x": -6,
            "y": -10,
            "z": 23,
            "elements": [
                "mekanism:plasticfence@0"
            ]
        },
        {
            "x": -6,
            "y": -10,
            "z": 24,
            "elements": [
                "chisel:antiblock@0"
            ]
        },
        {
            "x": -11,
            "y": 4,
            "z": 18,
            "elements": [
                "thermalfoundation:glass_alloy@6"
            ]
        },
        {
            "x": -6,
            "y": -10,
            "z": 26,
            "elements": [
                "chisel:antiblock@0"
            ]
        },
        {
            "x": -11,
            "y": 4,
            "z": -4,
            "elements": [
                "thermalfoundation:glass_alloy@6"
            ]
        },
        {
            "x": 23,
            "y": -8,
            "z": 9,
            "elements": [
                "chisel:antiblock@0"
            ]
        },
        {
            "x": -11,
            "y": 4,
            "z": -3,
            "elements": [
                "minecraft:end_rod@5"
            ]
        },
        {
            "x": 23,
            "y": -8,
            "z": 8,
            "elements": [
                "chisel:antiblock@0"
            ]
        },
        {
            "x": 23,
            "y": -8,
            "z": 11,
            "elements": [
                "minecraft:stone_slab2@0"
            ]
        },
        {
            "x": 23,
            "y": -8,
            "z": 10,
            "elements": [
                "botania:quartzstairsdark@3"
            ]
        },
        {
            "x": 23,
            "y": -8,
            "z": 5,
            "elements": [
                "chisel:antiblock@0"
            ]
        },
        {
            "x": 23,
            "y": -8,
            "z": 4,
            "elements": [
                "botania:quartzstairsdark@2"
            ]
        },
        {
            "x": 23,
            "y": -8,
            "z": 7,
            "elements": [
                "chisel:antiblock@0"
            ]
        },
        {
            "x": -11,
            "y": 4,
            "z": -2,
            "elements": [
                "mekanism:plasticfence@0"
            ]
        },
        {
            "x": 23,
            "y": -8,
            "z": 6,
            "elements": [
                "chisel:antiblock@0"
            ]
        },
        {
            "x": -11,
            "y": 4,
            "z": -1,
            "elements": [
                "minecraft:stained_glass_pane@1"
            ]
        },
        {
            "x": 23,
            "y": -8,
            "z": 3,
            "elements": [
                "minecraft:stone_slab2@0"
            ]
        },
        {
            "x": 18,
            "y": 6,
            "z": 6,
            "elements": [
                "chisel:antiblock@0"
            ]
        },
        {
            "x": 12,
            "y": -9,
            "z": -3,
            "elements": [
                "chisel:antiblock@0"
            ]
        },
        {
            "x": 18,
            "y": 6,
            "z": 8,
            "elements": [
                "chisel:antiblock@0"
            ]
        },
        {
            "x": 18,
            "y": 6,
            "z": 7,
            "elements": [
                "minecraft:stained_glass_pane@1"
            ]
        },
        {
            "x": -6,
            "y": -10,
            "z": -9,
            "elements": [
                "mekanism:plasticfence@0"
            ]
        },
        {
            "x": -6,
            "y": -10,
            "z": -8,
            "elements": [
                "chisel:antiblock@0"
            ]
        },
        {
            "x": 12,
            "y": -9,
            "z": 19,
            "elements": [
                "chisel:antiblock@14"
            ]
        },
        {
            "x": -6,
            "y": -10,
            "z": 22,
            "elements": [
                "chisel:antiblock@0"
            ]
        },
        {
            "x": -3,
            "y": 20,
            "z": 9,
            "elements": [
                "chisel:glasspanedyedorange@5"
            ]
        },
        {
            "x": -3,
            "y": 20,
            "z": 5,
            "elements": [
                "chisel:glasspanedyedorange@5"
            ]
        },
        {
            "x": 12,
            "y": -9,
            "z": 23,
            "elements": [
                "chisel:antiblock@0"
            ]
        },
        {
            "x": 12,
            "y": -9,
            "z": 22,
            "elements": [
                "chisel:antiblock@0"
            ]
        },
        {
            "x": 12,
            "y": -9,
            "z": 21,
            "elements": [
                "chisel:antiblock@0"
            ]
        },
        {
            "x": 12,
            "y": -9,
            "z": 20,
            "elements": [
                "chisel:antiblock@14"
            ]
        },
        {
            "x": -7,
            "y": 0,
            "z": 5,
            "elements": [
                "modularmachinery:blockenergyoutputhatch"
            ]
        },
        {
            "x": 12,
            "y": 4,
            "z": -2,
            "elements": [
                "futuremc:red_sandstone_wall@0"
            ]
        },
        {
            "x": 12,
            "y": 4,
            "z": -3,
            "elements": [
                "chisel:antiblock@0"
            ]
        },
        {
            "x": -7,
            "y": 0,
            "z": 4,
            "elements": [
                "chisel:antiblock@0"
            ]
        },
        {
            "x": 17,
            "y": -10,
            "z": 12,
            "elements": [
                "chisel:antiblock@0"
            ]
        },
        {
            "x": 17,
            "y": -10,
            "z": 13,
            "elements": [
                "chisel:antiblock@0"
            ]
        },
        {
            "x": 17,
            "y": -10,
            "z": 14,
            "elements": [
                "chisel:antiblock@0"
            ]
        },
        {
            "x": 17,
            "y": -10,
            "z": 8,
            "elements": [
                "chisel:antiblock@0"
            ]
        },
        {
            "x": 17,
            "y": -10,
            "z": 9,
            "elements": [
                "chisel:antiblock@0"
            ]
        },
        {
            "x": 17,
            "y": -10,
            "z": 10,
            "elements": [
                "chisel:antiblock@0"
            ]
        },
        {
            "x": 17,
            "y": -10,
            "z": 11,
            "elements": [
                "chisel:antiblock@0"
            ]
        },
        {
            "x": 17,
            "y": -10,
            "z": 4,
            "elements": [
                "chisel:antiblock@0"
            ]
        },
        {
            "x": 17,
            "y": -10,
            "z": 5,
            "elements": [
                "chisel:antiblock@0"
            ]
        },
        {
            "x": 17,
            "y": -10,
            "z": 6,
            "elements": [
                "chisel:antiblock@0"
            ]
        },
        {
            "x": 17,
            "y": -10,
            "z": 7,
            "elements": [
                "chisel:antiblock@0"
            ]
        },
        {
            "x": 17,
            "y": -10,
            "z": 0,
            "elements": [
                "chisel:antiblock@0"
            ]
        },
        {
            "x": 17,
            "y": -10,
            "z": 1,
            "elements": [
                "chisel:antiblock@0"
            ]
        },
        {
            "x": 17,
            "y": -10,
            "z": 2,
            "elements": [
                "chisel:antiblock@0"
            ]
        },
        {
            "x": 17,
            "y": -10,
            "z": 3,
            "elements": [
                "chisel:antiblock@0"
            ]
        },
        {
            "x": -7,
            "y": 0,
            "z": 7,
            "elements": [
                "modularmachinery:blockenergyoutputhatch"
            ]
        },
        {
            "x": 12,
            "y": 4,
            "z": 16,
            "elements": [
                "futuremc:red_sandstone_wall@0"
            ]
        },
        {
            "x": -7,
            "y": 0,
            "z": 6,
            "elements": [
                "modularmachinery:blockenergyoutputhatch"
            ]
        },
        {
            "x": -7,
            "y": 0,
            "z": 9,
            "elements": [
                "modularmachinery:blockenergyoutputhatch"
            ]
        },
        {
            "x": -7,
            "y": 0,
            "z": 8,
            "elements": [
                "modularmachinery:blockenergyoutputhatch"
            ]
        },
        {
            "x": 3,
            "y": 9,
            "z": 9,
            "elements": [
                "chisel:glasspanedyedorange@5"
            ]
        },
        {
            "x": 12,
            "y": 4,
            "z": 17,
            "elements": [
                "chisel:antiblock@0"
            ]
        },
        {
            "x": -7,
            "y": 0,
            "z": 10,
            "elements": [
                "chisel:antiblock@0"
            ]
        },
        {
            "x": 3,
            "y": 9,
            "z": 5,
            "elements": [
                "chisel:glasspanedyedorange@5"
            ]
        },
        {
            "x": -11,
            "y": -9,
            "z": 20,
            "elements": [
                "chisel:antiblock@14"
            ]
        },
        {
            "x": -11,
            "y": -9,
            "z": 21,
            "elements": [
                "chisel:antiblock@14"
            ]
        },
        {
            "x": -11,
            "y": -9,
            "z": 22,
            "elements": [
                "chisel:antiblock@0"
            ]
        },
        {
            "x": 8,
            "y": 58,
            "z": 8,
            "elements": [
                "botania:quartztypedark@0"
            ]
        },
        {
            "x": 8,
            "y": 58,
            "z": 6,
            "elements": [
                "botania:quartztypedark@0"
            ]
        },
        {
            "x": -7,
            "y": 37,
            "z": 6,
            "elements": [
                "botania:quartzstairsdark@5"
            ]
        },
        {
            "x": -11,
            "y": -9,
            "z": 18,
            "elements": [
                "chisel:antiblock@0"
            ]
        },
        {
            "x": -7,
            "y": 37,
            "z": 8,
            "elements": [
                "botania:quartzstairsdark@5"
            ]
        },
        {
            "x": -11,
            "y": -9,
            "z": -4,
            "elements": [
                "chisel:antiblock@0"
            ]
        },
        {
            "x": -7,
            "y": 24,
            "z": 5,
            "elements": [
                "chisel:antiblock@0"
            ]
        },
        {
            "x": -12,
            "y": 1,
            "z": 17,
            "elements": [
                "botania:quartzslabdarkhalf@8"
            ]
        },
        {
            "x": -12,
            "y": 1,
            "z": 16,
            "elements": [
                "botania:quartzstairsdark@4"
            ]
        },
        {
            "x": -11,
            "y": -9,
            "z": -8,
            "elements": [
                "chisel:antiblock@0"
            ]
        },
        {
            "x": -11,
            "y": -9,
            "z": -7,
            "elements": [
                "chisel:antiblock@14"
            ]
        },
        {
            "x": -11,
            "y": -9,
            "z": -6,
            "elements": [
                "chisel:antiblock@14"
            ]
        },
        {
            "x": 22,
            "y": -11,
            "z": 12,
            "elements": [
                "chisel:antiblock@0"
            ]
        },
        {
            "x": -7,
            "y": 24,
            "z": 8,
            "elements": [
                "minecraft:end_rod@2"
            ]
        },
        {
            "x": -7,
            "y": 24,
            "z": 9,
            "elements": [
                "chisel:antiblock@0"
            ]
        },
        {
            "x": -7,
            "y": 24,
            "z": 6,
            "elements": [
                "minecraft:end_rod@3"
            ]
        },
        {
            "x": -12,
            "y": 1,
            "z": -2,
            "elements": [
                "botania:quartzstairsdark@4"
            ]
        },
        {
            "x": -12,
            "y": 1,
            "z": -3,
            "elements": [
                "botania:quartzslabdarkhalf@8"
            ]
        },
        {
            "x": 22,
            "y": -11,
            "z": 2,
            "elements": [
                "chisel:antiblock@0"
            ]
        },
        {
            "x": 13,
            "y": -6,
            "z": -2,
            "elements": [
                "chisel:antiblock@0"
            ]
        },
        {
            "x": -2,
            "y": 23,
            "z": 12,
            "elements": [
                "appliedenergistics2:fluix_slab@0"
            ]
        },
        {
            "x": -2,
            "y": 23,
            "z": 13,
            "elements": [
                "chisel:antiblock@0"
            ]
        },
        {
            "x": -2,
            "y": 23,
            "z": 14,
            "elements": [
                "mekanism:plasticfence@0"
            ]
        },
        {
            "x": -2,
            "y": 23,
            "z": 2,
            "elements": [
                "appliedenergistics2:fluix_slab@0"
            ]
        },
        {
            "x": -2,
            "y": 23,
            "z": 0,
            "elements": [
                "mekanism:plasticfence@0"
            ]
        },
        {
            "x": 13,
            "y": -6,
            "z": 16,
            "elements": [
                "chisel:antiblock@0"
            ]
        },
        {
            "x": -2,
            "y": 23,
            "z": 1,
            "elements": [
                "chisel:antiblock@0"
            ]
        },
        {
            "x": -14,
            "y": 16,
            "z": 8,
            "elements": [
                "chisel:antiblock@0"
            ]
        },
        {
            "x": -8,
            "y": -3,
            "z": 6,
            "elements": [
                "thermalfoundation:glass_alloy@6"
            ]
        },
        {
            "x": -14,
            "y": 16,
            "z": 7,
            "elements": [
                "minecraft:stained_glass_pane@1"
            ]
        },
        {
            "x": -8,
            "y": -3,
            "z": 7,
            "elements": [
                "thermalfoundation:glass_alloy@6"
            ]
        },
        {
            "x": -8,
            "y": -3,
            "z": 8,
            "elements": [
                "thermalfoundation:glass_alloy@6"
            ]
        },
        {
            "x": -14,
            "y": 16,
            "z": 6,
            "elements": [
                "chisel:antiblock@0"
            ]
        },
        {
            "x": -8,
            "y": -3,
            "z": 9,
            "elements": [
                "thermalfoundation:glass_alloy@6"
            ]
        },
        {
            "x": -8,
            "y": -3,
            "z": 2,
            "elements": [
                "appliedenergistics2:fluix_stairs@3"
            ]
        },
        {
            "x": -8,
            "y": -3,
            "z": 3,
            "elements": [
                "appliedenergistics2:fluix_stairs@1"
            ]
        },
        {
            "x": -8,
            "y": -3,
            "z": 4,
            "elements": [
                "thermalfoundation:glass_alloy@6"
            ]
        },
        {
            "x": -8,
            "y": -3,
            "z": 5,
            "elements": [
                "thermalfoundation:glass_alloy@6"
            ]
        },
        {
            "x": -8,
            "y": -3,
            "z": -2,
            "elements": [
                "botania:quartzstairsdark@4"
            ]
        },
        {
            "x": -8,
            "y": -3,
            "z": -1,
            "elements": [
                "chisel:antiblock@0"
            ]
        },
        {
            "x": -8,
            "y": -3,
            "z": 0,
            "elements": [
                "chisel:antiblock@0"
            ]
        },
        {
            "x": -8,
            "y": -3,
            "z": 1,
            "elements": [
                "chisel:antiblock@0"
            ]
        },
        {
            "x": -8,
            "y": -3,
            "z": -3,
            "elements": [
                "botania:quartzstairsdark@4"
            ]
        },
        {
            "x": -5,
            "y": 1,
            "z": 3,
            "elements": [
                "chisel:antiblock@0"
            ]
        },
        {
            "x": -5,
            "y": 1,
            "z": 4,
            "elements": [
                "appliedenergistics2:fluix_stairs@3"
            ]
        },
        {
            "x": -5,
            "y": 1,
            "z": 5,
            "elements": [
                "chisel:antiblock@0"
            ]
        },
        {
            "x": -5,
            "y": 1,
            "z": 6,
            "elements": [
                "chisel:antiblock@0"
            ]
        },
        {
            "x": -23,
            "y": 5,
            "z": 6,
            "elements": [
                "chisel:antiblock@0"
            ]
        },
        {
            "x": -5,
            "y": 1,
            "z": 7,
            "elements": [
                "chisel:antiblock@0"
            ]
        },
        {
            "x": -5,
            "y": 1,
            "z": 8,
            "elements": [
                "chisel:antiblock@0"
            ]
        },
        {
            "x": -23,
            "y": 5,
            "z": 5,
            "elements": [
                "chisel:antiblock@0"
            ]
        },
        {
            "x": -5,
            "y": 1,
            "z": 9,
            "elements": [
                "chisel:antiblock@0"
            ]
        },
        {
            "x": -23,
            "y": 5,
            "z": 8,
            "elements": [
                "chisel:antiblock@0"
            ]
        },
        {
            "x": -23,
            "y": 5,
            "z": 7,
            "elements": [
                "chisel:antiblock@0"
            ]
        },
        {
            "x": -5,
            "y": 1,
            "z": 10,
            "elements": [
                "appliedenergistics2:fluix_stairs@2"
            ]
        },
        {
            "x": -8,
            "y": -3,
            "z": 14,
            "elements": [
                "chisel:antiblock@0"
            ]
        },
        {
            "x": -8,
            "y": -3,
            "z": 15,
            "elements": [
                "chisel:antiblock@0"
            ]
        },
        {
            "x": -8,
            "y": -3,
            "z": 16,
            "elements": [
                "botania:quartzstairsdark@7"
            ]
        },
        {
            "x": -8,
            "y": -3,
            "z": 17,
            "elements": [
                "botania:quartzstairsdark@4"
            ]
        },
        {
            "x": -8,
            "y": -3,
            "z": 10,
            "elements": [
                "thermalfoundation:glass_alloy@6"
            ]
        },
        {
            "x": -8,
            "y": -3,
            "z": 11,
            "elements": [
                "appliedenergistics2:fluix_stairs@1"
            ]
        },
        {
            "x": 12,
            "y": -4,
            "z": -2,
            "elements": [
                "chisel:antiblock@0"
            ]
        },
        {
            "x": -8,
            "y": -3,
            "z": 12,
            "elements": [
                "appliedenergistics2:fluix_stairs@2"
            ]
        },
        {
            "x": -8,
            "y": -3,
            "z": 13,
            "elements": [
                "chisel:antiblock@0"
            ]
        },
        {
            "x": -5,
            "y": 1,
            "z": 2,
            "elements": [
                "chisel:antiblock@0"
            ]
        },
        {
            "x": -14,
            "y": -10,
            "z": -3,
            "elements": [
                "chisel:antiblock@0"
            ]
        },
        {
            "x": -10,
            "y": -6,
            "z": 14,
            "elements": [
                "chisel:antiblock@0"
            ]
        },
        {
            "x": 12,
            "y": -4,
            "z": -1,
            "elements": [
                "chisel:antiblock@0"
            ]
        },
        {
            "x": -14,
            "y": -10,
            "z": -7,
            "elements": [
                "chisel:antiblock@0"
            ]
        },
        {
            "x": -5,
            "y": 1,
            "z": 11,
            "elements": [
                "chisel:antiblock@0"
            ]
        },
        {
            "x": -5,
            "y": 1,
            "z": 12,
            "elements": [
                "chisel:antiblock@0"
            ]
        },
        {
            "x": -10,
            "y": -6,
            "z": 21,
            "elements": [
                "chisel:antiblock@0"
            ]
        },
        {
            "x": -10,
            "y": -6,
            "z": 16,
            "elements": [
                "mekanism:plasticfence@0"
            ]
        },
        {
            "x": -10,
            "y": -6,
            "z": 15,
            "elements": [
                "minecraft:end_rod@1"
            ]
        },
        {
            "x": 12,
            "y": -4,
            "z": 15,
            "elements": [
                "chisel:antiblock@0"
            ]
        },
        {
            "x": -10,
            "y": -6,
            "z": -2,
            "elements": [
                "mekanism:plasticfence@0"
            ]
        },
        {
            "x": 12,
            "y": -4,
            "z": 16,
            "elements": [
                "chisel:antiblock@0"
            ]
        },
        {
            "x": -10,
            "y": -6,
            "z": -7,
            "elements": [
                "chisel:antiblock@0"
            ]
        },
        {
            "x": -10,
            "y": -6,
            "z": 0,
            "elements": [
                "chisel:antiblock@0"
            ]
        },
        {
            "x": -10,
            "y": -6,
            "z": -1,
            "elements": [
                "minecraft:end_rod@1"
            ]
        },
        {
            "x": -13,
            "y": -10,
            "z": -2,
            "elements": [
                "chisel:antiblock@0"
            ]
        },
        {
            "x": -13,
            "y": -10,
            "z": -8,
            "elements": [
                "chisel:antiblock@0"
            ]
        },
        {
            "x": -7,
            "y": 50,
            "z": 6,
            "elements": [
                "botania:quartzstairsdark@5"
            ]
        },
        {
            "x": -23,
            "y": 5,
            "z": 9,
            "elements": [
                "chisel:antiblock@0"
            ]
        },
        {
            "x": 7,
            "y": 42,
            "z": 8,
            "elements": [
                "botania:quartzstairsdark@4"
            ]
        },
        {
            "x": -13,
            "y": -10,
            "z": 22,
            "elements": [
                "chisel:antiblock@0"
            ]
        },
        {
            "x": 7,
            "y": 42,
            "z": 6,
            "elements": [
                "botania:quartzstairsdark@0"
            ]
        },
        {
            "x": -7,
            "y": 50,
            "z": 8,
            "elements": [
                "botania:quartzstairsdark@5"
            ]
        },
        {
            "x": -10,
            "y": 20,
            "z": 6,
            "elements": [
                "chisel:antiblock@0"
            ]
        },
        {
            "x": -10,
            "y": 20,
            "z": 8,
            "elements": [
                "chisel:antiblock@0"
            ]
        },
        {
            "x": -13,
            "y": -10,
            "z": 16,
            "elements": [
                "chisel:antiblock@0"
            ]
        },
        {
            "x": -10,
            "y": 20,
            "z": 7,
            "elements": [
                "minecraft:stained_glass_pane@1"
            ]
        },
        {
            "x": -13,
            "y": -10,
            "z": 21,
            "elements": [
                "chisel:antiblock@0"
            ]
        },
        {
            "x": 2,
            "y": 11,
            "z": 4,
            "elements": [
                "chisel:glasspanedyedorange@5"
            ]
        },
        {
            "x": 2,
            "y": 11,
            "z": 3,
            "elements": [
                "chisel:antiblock@0"
            ]
        },
        {
            "x": 2,
            "y": 11,
            "z": 2,
            "elements": [
                "mekanism:plasticfence@0"
            ]
        },
        {
            "x": 5,
            "y": 15,
            "z": 9,
            "elements": [
                "mekanism:plasticfence@0"
            ]
        },
        {
            "x": 2,
            "y": 11,
            "z": 12,
            "elements": [
                "mekanism:plasticfence@0"
            ]
        },
        {
            "x": 9,
            "y": -10,
            "z": 20,
            "elements": [
                "chisel:antiblock@0"
            ]
        },
        {
            "x": 2,
            "y": 11,
            "z": 11,
            "elements": [
                "chisel:antiblock@0"
            ]
        },
        {
            "x": 2,
            "y": 11,
            "z": 10,
            "elements": [
                "chisel:glasspanedyedorange@5"
            ]
        },
        {
            "x": 5,
            "y": 15,
            "z": 5,
            "elements": [
                "mekanism:plasticfence@0"
            ]
        },
        {
            "x": 1,
            "y": 37,
            "z": -2,
            "elements": [
                "minecraft:stained_glass_pane@1"
            ]
        },
        {
            "x": 1,
            "y": 37,
            "z": -3,
            "elements": [
                "chisel:antiblock@0"
            ]
        },
        {
            "x": 1,
            "y": 37,
            "z": 0,
            "elements": [
                "botania:quartzstairsdark@7"
            ]
        },
        {
            "x": 1,
            "y": 37,
            "z": -1,
            "elements": [
                "chisel:antiblock@0"
            ]
        },
        {
            "x": 11,
            "y": 22,
            "z": 6,
            "elements": [
                "chisel:antiblock@0"
            ]
        },
        {
            "x": 11,
            "y": 22,
            "z": 7,
            "elements": [
                "minecraft:stained_glass_pane@1"
            ]
        },
        {
            "x": 11,
            "y": 22,
            "z": 8,
            "elements": [
                "chisel:antiblock@0"
            ]
        },
        {
            "x": -26,
            "y": -1,
            "z": 7,
            "elements": [
                "chisel:antiblock@0"
            ]
        },
        {
            "x": -26,
            "y": -1,
            "z": 6,
            "elements": [
                "chisel:antiblock@0"
            ]
        },
        {
            "x": -26,
            "y": -1,
            "z": 9,
            "elements": [
                "mekanism:plasticfence@0"
            ]
        },
        {
            "x": -26,
            "y": -1,
            "z": 8,
            "elements": [
                "chisel:antiblock@0"
            ]
        },
        {
            "x": -4,
            "y": 1,
            "z": 1,
            "elements": [
                "chisel:antiblock@0"
            ]
        },
        {
            "x": -26,
            "y": -1,
            "z": 5,
            "elements": [
                "mekanism:plasticfence@0"
            ]
        },
        {
            "x": -4,
            "y": 1,
            "z": 4,
            "elements": [
                "appliedenergistics2:fluix_stairs@0"
            ]
        },
        {
            "x": 1,
            "y": 37,
            "z": 14,
            "elements": [
                "botania:quartzstairsdark@6"
            ]
        },
        {
            "x": -4,
            "y": 1,
            "z": 5,
            "elements": [
                "chisel:antiblock@0"
            ]
        },
        {
            "x": 1,
            "y": 37,
            "z": 16,
            "elements": [
                "minecraft:stained_glass_pane@1"
            ]
        },
        {
            "x": -4,
            "y": 1,
            "z": 2,
            "elements": [
                "chisel:antiblock@0"
            ]
        },
        {
            "x": 1,
            "y": 37,
            "z": 15,
            "elements": [
                "chisel:antiblock@0"
            ]
        },
        {
            "x": -4,
            "y": 1,
            "z": 3,
            "elements": [
                "chisel:antiblock@0"
            ]
        },
        {
            "x": -4,
