{
    "registryname": "g_ma",
    "localizedname": "§B魔力聚合机ProMax+",
    "failure-action": "still",
    "requires-blueprint": false,
    "has-factory": true,
    "factory-only": true,
    "color": "4E4A4A",
    "parts": [
        {
            "x": 0,
            "y": 0,
            "z": 0,
            "elements": [
                "modularmachinery:g_ma_factory_controller"
            ]
        },
        {
            "x": 3,
            "y": 3,
            "z": 2,
            "elements": [
                "contenttweaker:fallenstarforcefieldcontrolblock@0"
            ]
        },
        {
            "x": -2,
            "y": 0,
            "z": 2,
            "elements": [
                "contenttweaker:neutronforcefieldcontrolblock@0"
            ]
        },
        {
            "x": -3,
            "y": 0,
            "z": 1,
            "elements": [
                "contenttweaker:fallenstarforcefieldcontrolblock@0"
            ]
        },
        {
            "x": -3,
            "y": 1,
            "z": 3,
            "elements": [
                "mekanism:plasticfence@15"
            ]
        },
        {
            "x": 1,
            "y": 0,
            "z": 5,
            "elements": [
                "contenttweaker:fallenstarforcefieldcontrolblock@0"
            ]
        },
        {
            "x": 1,
            "y": 2,
            "z": 5,
            "elements": [
                "mekanism:plasticfence@15"
            ]
        },
        {
            "x": 0,
            "y": 1,
            "z": 4,
            "elements": [
                "botania:runealtar@0"
            ]
        },
        {
            "x": 1,
            "y": 0,
            "z": 1,
            "elements": [
                "contenttweaker:crystalmatrixforcefieldcontrolblock@0"
            ]
        },
        {
            "x": -3,
            "y": 2,
            "z": 3,
            "elements": [
                "mekanism:plasticfence@15"
            ]
        },
        {
            "x": 3,
            "y": 2,
            "z": 2,
            "elements": [
                "mekanism:plasticfence@15"
            ]
        },
        {
            "x": 0,
            "y": 0,
            "z": 3,
            "elements": [
                "contenttweaker:universalforcefieldcontrolblock@0"
            ]
        },
        {
            "x": -1,
            "y": 0,
            "z": 4,
            "elements": [
                "contenttweaker:neutronforcefieldcontrolblock@0"
            ]
        },
        {
            "x": 1,
            "y": 1,
            "z": 5,
            "elements": [
                "mekanism:plasticfence@15"
            ]
        },
        {
            "x": -3,
            "y": 1,
            "z": 1,
            "elements": [
                "mekanism:plasticfence@15"
            ]
        },
        {
            "x": 0,
            "y": 3,
            "z": 5,
            "elements": [
                "contenttweaker:fallenstarforcefieldcontrolblock@0"
            ]
        },
        {
            "x": 2,
            "y": 0,
            "z": 2,
            "elements": [
                "contenttweaker:neutronforcefieldcontrolblock@0"
            ]
        },
        {
            "x": 1,
            "y": 0,
            "z": 0,
            "elements": [
                "contenttweaker:universalforcefieldcontrolblock@0"
            ]
        },
        {
            "x": -2,
            "y": 3,
            "z": 4,
            "elements": [
                "contenttweaker:fallenstarforcefieldcontrolblock@0"
            ]
        },
        {
            "x": 2,
            "y": 3,
            "z": 4,
            "elements": [
                "contenttweaker:fallenstarforcefieldcontrolblock@0"
            ]
        },
        {
            "x": 3,
            "y": 1,
            "z": 2,
            "elements": [
                "mekanism:plasticfence@15"
            ]
        },
        {
            "x": 0,
            "y": 0,
            "z": 1,
            "elements": [
                "contenttweaker:universalforcefieldcontrolblock@0"
            ]
        },
        {
            "x": -3,
            "y": 2,
            "z": 1,
            "elements": [
                "mekanism:plasticfence@15"
            ]
        },
        {
            "x": 3,
            "y": 2,
            "z": 3,
            "elements": [
                "mekanism:plasticfence@15"
            ]
        },
        {
            "x": 1,
            "y": 0,
            "z": -1,
            "elements": [
                "modularmachinery:blockmefluidinputbus@0"
            ]
        },
        {
            "x": 1,
            "y": 0,
            "z": 3,
            "elements": [
                "contenttweaker:crystalmatrixforcefieldcontrolblock@0"
            ]
        },
        {
            "x": 0,
            "y": 0,
            "z": 4,
            "elements": [
                "contenttweaker:neutronforcefieldcontrolblock@0"
            ]
        },
        {
            "x": -3,
            "y": 0,
            "z": 3,
            "elements": [
                "contenttweaker:fallenstarforcefieldcontrolblock@0"
            ]
        },
        {
            "x": -3,
            "y": 3,
            "z": 1,
            "elements": [
                "contenttweaker:fallenstarforcefieldcontrolblock@0"
            ]
        },
        {
            "x": -1,
            "y": 0,
            "z": 2,
            "elements": [
                "contenttweaker:universalforcefieldcontrolblock@0"
            ]
        },
        {
            "x": -2,
            "y": 0,
            "z": 0,
            "elements": [
                "modularmachinery:blockmeitemoutputbus@0"
            ]
        },
        {
            "x": -1,
            "y": 3,
            "z": 5,
            "elements": [
                "contenttweaker:fallenstarforcefieldcontrolblock@0"
            ]
        },
        {
            "x": 3,
            "y": 0,
            "z": 2,
            "elements": [
                "contenttweaker:fallenstarforcefieldcontrolblock@0"
            ]
        },
        {
            "x": -1,
            "y": 0,
            "z": 1,
            "elements": [
                "contenttweaker:crystalmatrixforcefieldcontrolblock@0"
            ]
        },
        {
            "x": 2,
            "y": 0,
            "z": 0,

            "elements": [
                "modularmachinery:blockmepatternprovider@0"
            ]
        },
        {
            "x": 3,
            "y": 1,
            "z": 3,
            "elements": [
                "mekanism:plasticfence@15"
            ]
        },
        {
            "x": -1,
            "y": 0,
            "z": 5,
            "elements": [
                "contenttweaker:fallenstarforcefieldcontrolblock@0"
            ]
        },
        {
            "x": -3,
            "y": 3,
            "z": 2,
            "elements": [
                "contenttweaker:fallenstarforcefieldcontrolblock@0"
            ]
        },
        {
            "x": 3,
            "y": 0,
            "z": 1,
            "elements": [
                "contenttweaker:fallenstarforcefieldcontrolblock@0"
            ]
        },
        {
            "x": 0,
            "y": 1,
            "z": 2,
            "elements": [
                "botania:terraplate@0"
            ]
        },
        {
            "x": 0,
            "y": 0,
            "z": -1,
            "elements": [
                "modularmachinery:blockenergyinputhatch"
            ]
        },
        {
            "x": -1,
            "y": 2,
            "z": 5,
            "elements": [
                "mekanism:plasticfence@15"
            ]
        },
        {
            "x": 2,
            "y": 0,
            "z": 3,
            "elements": [
                "contenttweaker:neutronforcefieldcontrolblock@0"
            ]
        },
        {
            "x": 3,
            "y": 3,
            "z": 3,
            "elements": [
                "contenttweaker:fallenstarforcefieldcontrolblock@0"
            ]
        },
        {
            "x": 3,
            "y": 1,
            "z": 1,
            "elements": [
                "mekanism:plasticfence@15"
            ]
        },
        {
            "x": 1,
            "y": 0,
            "z": 4,
            "elements": [
                "contenttweaker:neutronforcefieldcontrolblock@0"
            ]
        },
        {
            "x": -2,
            "y": 0,
            "z": 3,
            "elements": [
                "contenttweaker:neutronforcefieldcontrolblock@0"
            ]
        },
        {
            "x": -3,
            "y": 2,
            "z": 2,
            "elements": [
                "mekanism:plasticfence@15"
            ]
        },
        {
            "x": 0,
            "y": 0,
            "z": 2,
            "elements": [
                "contenttweaker:arkforcefieldcontrolblock@0"
            ]
        },
        {
            "x": -1,
            "y": 1,
            "z": 5,
            "elements": [
                "mekanism:plasticfence@15"
            ]
        },
        {
            "x": -1,
            "y": 0,
            "z": 0,
            "elements": [
                "contenttweaker:universalforcefieldcontrolblock@0"
            ]
        },
        {
            "x": -2,
            "y": 0,
            "z": 1,
            "elements": [
                "contenttweaker:neutronforcefieldcontrolblock@0"
            ]
        },
        {
            "x": -3,
            "y": 3,
            "z": 3,
            "elements": [
                "contenttweaker:fallenstarforcefieldcontrolblock@0"
            ]
        },
        {
            "x": -3,
            "y": 0,
            "z": 2,
            "elements": [
                "contenttweaker:fallenstarforcefieldcontrolblock@0"
            ]
        },
        {
            "x": 3,
            "y": 3,
            "z": 1,
            "elements": [
                "contenttweaker:fallenstarforcefieldcontrolblock@0"
            ]
        },
        {
            "x": 0,
            "y": 0,
            "z": 5,
            "elements": [
                "contenttweaker:fallenstarforcefieldcontrolblock@0"
            ]
        },
        {
            "x": 0,
            "y": 2,
            "z": 5,
            "elements": [
                "mekanism:plasticfence@15"
            ]
        },
        {
            "x": 2,
            "y": 0,
            "z": 1,
            "elements": [
                "contenttweaker:neutronforcefieldcontrolblock@0"
            ]
        },
        {
            "x": -3,
            "y": 1,
            "z": 2,
            "elements": [
                "mekanism:plasticfence@15"
            ]
        },
        {
            "x": 3,
            "y": 0,
            "z": 3,
            "elements": [
                "contenttweaker:fallenstarforcefieldcontrolblock@0"
            ]
        },
        {
            "x": -1,
            "y": 0,
            "z": -1,
            "elements": [
                "modularmachinery:blockmefluidinputbus@0"
            ]
        },
        {
            "x": -1,
            "y": 0,
            "z": 3,
            "elements": [
                "contenttweaker:crystalmatrixforcefieldcontrolblock@0"
            ]
        },
        {
            "x": 3,
            "y": 2,
            "z": 1,
            "elements": [
                "mekanism:plasticfence@15"
            ]
        },
        {
            "x": -2,
            "y": 0,
            "z": 4,
            "elements": [
                "contenttweaker:fallenstarforcefieldcontrolblock@0"
            ]
        },
        {
            "x": 1,
            "y": 3,
            "z": 5,
            "elements": [
                "contenttweaker:fallenstarforcefieldcontrolblock@0"
            ]
        },
        {
            "x": 2,
            "y": 0,
            "z": 4,
            "elements": [
                "contenttweaker:fallenstarforcefieldcontrolblock@0"
            ]
        },
        {
            "x": 1,
            "y": 0,
            "z": 2,
            "elements": [
                "contenttweaker:universalforcefieldcontrolblock@0"
            ]
        },
        {
            "x": 0,
            "y": 1,
            "z": 5,
            "elements": [
                "mekanism:plasticfence@15"
            ]
        }
    ]}