{
    "registryname": "GSHAG",
    "localizedname": "§e巨型平流层高空发电机",
    "requires-blueprint": false,
    "failure-action": "decrease",
    "has-factory": true,
    "factory-only": false,
    "parts": [
        {
            "x": 0,
            "y": 0,
            "z": 0,
            "elements": [
                "modularmachinery:gshag_controller@2"
            ]
        },
        {
            "x": 1,
            "y": 51,
            "z": 5,
            "elements": [
                "chisel:laboratory@9"
            ]
        },
        {
            "x": 1,
            "y": 86,
            "z": -2,
            "elements": [
                "actuallyadditions:block_testifi_bucks_white_stairs@0"
            ]
        },
        {
            "x": -3,
            "y": 13,
            "z": 4,
            "elements": [
                "chisel:laboratory@9"
            ]
        },
        {
            "x": -1,
            "y": 2,
            "z": 0,
            "elements": [
                "chisel:laboratory@9"
            ]
        },
        {
            "x": 0,
            "y": 19,
            "z": 6,
            "elements": [
                "chisel:laboratory@9"
            ]
        },
        {
            "x": -3,
            "y": 12,
            "z": 3,
            "elements": [
                "chisel:laboratory@9"
            ]
        },
        {
            "x": -2,
            "y": 46,
            "z": 4,
            "elements": [
                "chisel:laboratory@9"
            ]
        },
        {
            "x": 2,
            "y": 70,
            "z": 2,
            "elements": [
                "chisel:laboratory@9"
            ]
        },
        {
            "x": 2,
            "y": 69,
            "z": 2,
            "elements": [
                "chisel:laboratory@9"
            ]
        },
        {
            "x": -2,
            "y": 64,
            "z": 4,
            "elements": [
                "chisel:laboratory@9"
            ]
        },
        {
            "x": -1,
            "y": 74,
            "z": 2,
            "elements": [
                "chisel:laboratory@9"
            ]
        },
        {
            "x": 1,
            "y": 49,
            "z": 5,
            "elements": [
                "chisel:laboratory@9"
            ]
        },
        {
            "x": -2,
            "y": 44,
            "z": 4,
            "elements": [
                "chisel:laboratory@9"
            ]
        },
        {
            "x": 0,
            "y": 18,
            "z": 6,
            "elements": [
                "chisel:laboratory@9"
            ]
        },
        {
            "x": -3,
            "y": 11,
            "z": 4,
            "elements": [
                "chisel:laboratory@9"
            ]
        },
        {
            "x": -2,
            "y": 78,
            "z": 6,
            "elements": [
                "chisel:laboratory@4"
            ]
        },
        {
            "x": 3,
            "y": 8,
            "z": 3,
            "elements": [
                "chisel:laboratory@9"
            ]
        },
        {
            "x": 3,
            "y": 7,
            "z": 4,
            "elements": [
                "chisel:laboratory@9"
            ]
        },
        {
            "x": -2,
            "y": 65,
            "z": 3,
            "elements": [
                "chisel:laboratory@9"
            ]
        },
        {
            "x": 2,
            "y": 38,
            "z": 4,
            "elements": [
                "chisel:laboratory@9"
            ]
        },
        {
            "x": 1,
            "y": 0,
            "z": 0,
            "elements": [
                "modularmachinery:blockenergyoutputhatch"
            ]
        },
        {
            "x": 0,
            "y": 21,
            "z": 6,
            "elements": [
                "chisel:laboratory@9"
            ]
        },
        {
            "x": -1,
            "y": 53,
            "z": 5,
            "elements": [
                "chisel:laboratory@9"
            ]
        },
        {
            "x": 2,
            "y": 39,
            "z": 3,
            "elements": [
                "chisel:laboratory@9"
            ]
        },
        {
            "x": -2,
            "y": 0,
            "z": 5,
            "elements": [
                "chisel:laboratory@9"
            ]
        },
        {
            "x": -2,
            "y": 67,
            "z": 3,
            "elements": [
                "chisel:laboratory@9"
            ]
        },
        {
            "x": 1,
            "y": 75,
            "z": 6,
            "elements": [
                "chisel:laboratory@4"
            ]
        },
        {
            "x": -2,
            "y": 77,
            "z": 6,
            "elements": [
                "chisel:laboratory@4"
            ]
        },
        {
            "x": -1,
            "y": 4,
            "z": 0,
            "elements": [
                "chisel:laboratory@9"
            ]
        },
        {
            "x": 2,
            "y": 72,
            "z": 2,
            "elements": [
                "chisel:laboratory@9"
            ]
        },
        {
            "x": -3,
            "y": 14,
            "z": 3,
            "elements": [
                "chisel:laboratory@9"
            ]
        },
        {
            "x": 0,
            "y": 22,
            "z": 6,
            "elements": [
                "chisel:laboratory@9"
            ]
        },
        {
            "x": -2,
            "y": 2,
            "z": 5,
            "elements": [
                "chisel:laboratory@9"
            ]
        },
        {
            "x": 1,
            "y": 47,
            "z": 5,
            "elements": [
                "chisel:laboratory@9"
            ]
        },
        {
            "x": 0,
            "y": 20,
            "z": 6,
            "elements": [
                "chisel:laboratory@9"
            ]
        },
        {
            "x": -2,
            "y": 76,
            "z": 6,
            "elements": [
                "chisel:laboratory@4"
            ]
        },
        {
            "x": 3,
            "y": 10,
            "z": 3,
            "elements": [
                "chisel:laboratory@9"
            ]
        },
        {
            "x": 2,
            "y": 71,
            "z": 2,
            "elements": [
                "chisel:laboratory@9"
            ]
        },
        {
            "x": -1,
            "y": 55,
            "z": 5,
            "elements": [
                "chisel:laboratory@9"
            ]
        },
        {
            "x": 3,
            "y": 9,
            "z": 4,
            "elements": [
                "chisel:laboratory@9"
            ]
        },
        {
            "x": -2,
            "y": 66,
            "z": 4,
            "elements": [
                "chisel:laboratory@9"
            ]
        },
        {
            "x": -2,
            "y": 70,
            "z": 4,
            "elements": [
                "chisel:laboratory@9"
            ]
        },
        {
            "x": -3,
            "y": 8,
            "z": 3,
            "elements": [
                "chisel:laboratory@9"
            ]
        },
        {
            "x": 3,
            "y": 3,
            "z": 4,
            "elements": [
                "chisel:laboratory@9"
            ]
        },
        {
            "x": 1,
            "y": 40,
            "z": 1,
            "elements": [
                "chisel:laboratory@9"
            ]
        },
        {
            "x": 2,
            "y": 41,
            "z": 3,
            "elements": [
                "chisel:laboratory@9"
            ]
        },
        {
            "x": -2,
            "y": 75,
            "z": 6,
            "elements": [
                "chisel:laboratory@4"
            ]
        },
        {
            "x": 4,
            "y": 89,
            "z": -2,
            "elements": [
                "chisel:quartz@7"
            ]
        },
        {
            "x": 1,
            "y": 2,
            "z": 0,
            "elements": [
                "chisel:laboratory@9"
            ]
        },
        {
            "x": -1,
            "y": 51,
            "z": 5,
            "elements": [
                "chisel:laboratory@9"
            ]
        },
        {
            "x": 4,
            "y": 88,
            "z": -2,
            "elements": [
                "thermalfoundation:storage_alloy@0"
            ]
        },
        {
            "x": -3,
            "y": 17,
            "z": 4,
            "elements": [
                "chisel:laboratory@9"
            ]
        },
        {
            "x": 0,
            "y": 30,
            "z": 6,
            "elements": [
                "chisel:laboratory@9"
            ]
        },
        {
            "x": 2,
            "y": 65,
            "z": 2,
            "elements": [
                "chisel:laboratory@9"
            ]
        },
        {
            "x": 3,
            "y": 12,
            "z": 3,
            "elements": [
                "chisel:laboratory@9"
            ]
        },
        {
            "x": 1,
            "y": 39,
            "z": 1,
            "elements": [
                "chisel:laboratory@9"
            ]
        },
        {
            "x": -2,
            "y": 61,
            "z": 3,
            "elements": [
                "chisel:laboratory@9"
            ]
        },
        {
            "x": 3,
            "y": 14,
            "z": 3,
            "elements": [
                "chisel:laboratory@9"
            ]
        },
        {
            "x": -1,
            "y": 49,
            "z": 5,
            "elements": [
                "chisel:laboratory@9"
            ]
        },
        {
            "x": 0,
            "y": 29,
            "z": 6,
            "elements": [
                "chisel:laboratory@9"
            ]
        },
        {
            "x": 2,
            "y": 66,
            "z": 2,
            "elements": [
                "chisel:laboratory@9"
            ]
        },
        {
            "x": 1,
            "y": 53,
            "z": 5,
            "elements": [
                "chisel:laboratory@9"
            ]
        },
        {
            "x": -1,
            "y": 0,
            "z": 0,
            "elements": [
                "modularmachinery:blockenergyoutputhatch"
            ]
        },
        {
            "x": -2,
            "y": 40,
            "z": 4,
            "elements": [
                "chisel:laboratory@9"
            ]
        },
        {
            "x": 0,
            "y": 28,
            "z": 6,
            "elements": [
                "chisel:laboratory@9"
            ]
        },
        {
            "x": -2,
            "y": 68,
            "z": 4,
            "elements": [
                "chisel:laboratory@9"
            ]
        },
        {
            "x": 2,
            "y": 68,
            "z": 2,
            "elements": [
                "chisel:laboratory@9"
            ]
        },
        {
            "x": 0,
            "y": 14,
            "z": 6,
            "elements": [
                "chisel:laboratory@9"
            ]
        },
        {
            "x": 1,
            "y": 38,
            "z": 1,
            "elements": [
                "chisel:laboratory@9"
            ]
        },
        {
            "x": 0,
            "y": 17,
            "z": 6,
            "elements": [
                "chisel:laboratory@9"
            ]
        },
        {
            "x": -1,
            "y": 47,
            "z": 5,
            "elements": [
                "chisel:laboratory@9"
            ]
        },
        {
            "x": 1,
            "y": 4,
            "z": 0,
            "elements": [
                "chisel:laboratory@9"
            ]
        },
        {
            "x": -3,
            "y": 15,
            "z": 4,
            "elements": [
                "chisel:laboratory@9"
            ]
        },
        {
            "x": 0,
            "y": 15,
            "z": 6,
            "elements": [
                "chisel:laboratory@9"
            ]
        },
        {
            "x": 3,
            "y": 0,
            "z": 3,
            "elements": [
                "chisel:laboratory@9"
            ]
        },
        {
            "x": 2,
            "y": 67,
            "z": 2,
            "elements": [
                "chisel:laboratory@9"
            ]
        },
        {
            "x": 3,
            "y": 5,
            "z": 4,
            "elements": [
                "chisel:laboratory@9"
            ]
        },
        {
            "x": 4,
            "y": 87,
            "z": -2,
            "elements": [
                "thermalfoundation:storage_alloy@0"
            ]
        },
        {
            "x": -2,
            "y": 42,
            "z": 4,
            "elements": [
                "chisel:laboratory@9"
            ]
        },
        {
            "x": 1,
            "y": 55,
            "z": 5,
            "elements": [
                "chisel:laboratory@9"
            ]
        },
        {
            "x": -2,
            "y": 63,
            "z": 3,
            "elements": [
                "chisel:laboratory@9"
            ]
        },
        {
            "x": -3,
            "y": 10,
            "z": 3,
            "elements": [
                "chisel:laboratory@9"
            ]
        },
        {
            "x": 0,
            "y": 76,
            "z": -3,
            "elements": [
                "contenttweaker:crystalmatrixforcefieldcontrolblock@0"
            ]
        },
        {
            "x": 0,
            "y": 16,
            "z": 6,
            "elements": [
                "chisel:laboratory@9"
            ]
        },
        {
            "x": 2,
            "y": 43,
            "z": 3,
            "elements": [
                "chisel:laboratory@9"
            ]
        },
        {
            "x": 0,
            "y": 33,
            "z": 6,
            "elements": [
                "chisel:laboratory@9"
            ]
        },
        {
            "x": 0,
            "y": 43,
            "z": 5,
            "elements": [
                "chisel:laboratory@9"
            ]
        },
        {
            "x": -3,
            "y": 22,
            "z": 3,
            "elements": [
                "chisel:laboratory@9"
            ]
        },
        {
            "x": 2,
            "y": -1,
            "z": 4,
            "elements": [
                "thermalfoundation:storage_alloy@0"
            ]
        },
        {
            "x": 0,
            "y": 12,
            "z": 6,
            "elements": [
                "chisel:laboratory@9"
            ]
        },
        {
            "x": -1,
            "y": 45,
            "z": 5,
            "elements": [
                "chisel:laboratory@9"
            ]
        },
        {
            "x": -3,
            "y": 3,
            "z": 4,
            "elements": [
                "chisel:laboratory@9"
            ]
        },
        {
            "x": 0,
            "y": 59,
            "z": 5,
            "elements": [
                "chisel:laboratory@9"
            ]
        },
        {
            "x": 1,
            "y": 57,
            "z": 5,
            "elements": [
                "chisel:laboratory@9"
            ]
        },
        {
            "x": -2,
            "y": 54,
            "z": 4,
            "elements": [
                "chisel:laboratory@9"
            ]
        },
        {
            "x": 0,
            "y": 34,
            "z": 6,
            "elements": [
                "chisel:laboratory@9"
            ]
        },
        {
            "x": 0,
            "y": 13,
            "z": 6,
            "elements": [
                "chisel:laboratory@9"
            ]
        },
        {
            "x": 1,
            "y": 42,
            "z": 1,
            "elements": [
                "chisel:laboratory@9"
            ]
        },
        {
            "x": -1,
            "y": -1,
            "z": 4,
            "elements": [
                "thermalfoundation:storage_alloy@0"
            ]
        },
        {
            "x": -1,
            "y": 10,
            "z": 0,
            "elements": [
                "chisel:laboratory@9"
            ]
        },
        {
            "x": -2,
            "y": 75,
            "z": 3,
            "elements": [
                "chisel:laboratory@4"
            ]
        },
        {
            "x": -2,
            "y": 58,
            "z": 4,
            "elements": [
                "chisel:laboratory@9"
            ]
        },
        {
            "x": 0,
            "y": 45,
            "z": 5,
            "elements": [
                "chisel:laboratory@9"
            ]
        },
        {
            "x": 2,
            "y": 78,
            "z": 2,
            "elements": [
                "chisel:laboratory@13"
            ]
        },
        {
            "x": -1,
            "y": 43,
            "z": 5,
            "elements": [
                "chisel:laboratory@9"
            ]
        },
        {
            "x": 2,
            "y": 77,
            "z": 2,
            "elements": [
                "chisel:laboratory@13"
            ]
        },
        {
            "x": 2,
            "y": 0,
            "z": 5,
            "elements": [
                "chisel:laboratory@9"
            ]
        },
        {
            "x": 4,
            "y": 76,
            "z": -2,
            "elements": [
                "thermalfoundation:storage_alloy@0"
            ]
        },
        {
            "x": -3,
            "y": 5,
            "z": 4,
            "elements": [
                "chisel:laboratory@9"
            ]
        },
        {
            "x": 2,
            "y": 2,
            "z": 5,
            "elements": [
                "chisel:laboratory@9"
            ]
        },
        {
            "x": 1,
            "y": 83,
            "z": -2,
            "elements": [
                "chisel:quartz@7"
            ]
        },
        {
            "x": 1,
            "y": 43,
            "z": 1,
            "elements": [
                "chisel:laboratory@9"
            ]
        },
        {
            "x": 4,
            "y": 77,
            "z": -2,
            "elements": [
                "chisel:quartz@7"
            ]
        },
        {
            "x": 3,
            "y": 1,
            "z": 4,
            "elements": [
                "chisel:laboratory@9"
            ]
        },
        {
            "x": 1,
            "y": 59,
            "z": 5,
            "elements": [
                "chisel:laboratory@9"
            ]
        },
        {
            "x": 0,
            "y": 32,
            "z": 6,
            "elements": [
                "chisel:laboratory@9"
            ]
        },
        {
            "x": 3,
            "y": 2,
            "z": 3,
            "elements": [
                "chisel:laboratory@9"
            ]
        },
        {
            "x": 0,
            "y": 57,
            "z": 5,
            "elements": [
                "chisel:laboratory@9"
            ]
        },
        {
            "x": -4,
            "y": -1,
            "z": 4,
            "elements": [
                "immersiveengineering:steel_scaffolding_stairs1@0"
            ]
        },
        {
            "x": 0,
            "y": 10,
            "z": 6,
            "elements": [
                "chisel:laboratory@9"
            ]
        },
        {
            "x": 1,
            "y": 41,
            "z": 1,
            "elements": [
                "chisel:laboratory@9"
            ]
        },
        {
            "x": 0,
            "y": 31,
            "z": 6,
            "elements": [
                "chisel:laboratory@9"
            ]
        },
        {
            "x": -2,
            "y": 52,
            "z": 4,
            "elements": [
                "chisel:laboratory@9"
            ]
        },
        {
            "x": 1,
            "y": 44,
            "z": 1,
            "elements": [
                "chisel:laboratory@9"
            ]
        },
        {
            "x": -3,
            "y": 20,
            "z": 3,
            "elements": [
                "chisel:laboratory@9"
            ]
        },
        {
            "x": 1,
            "y": 82,
            "z": -2,
            "elements": [
                "thermalfoundation:storage_alloy@0"
            ]
        },
        {
            "x": 0,
            "y": 11,
            "z": 6,
            "elements": [
                "chisel:laboratory@9"
            ]
        },
        {
            "x": 2,
            "y": 75,
            "z": 2,
            "elements": [
                "chisel:laboratory@4"
            ]
        },
        {
            "x": 1,
            "y": 81,
            "z": -2,
            "elements": [
                "thermalfoundation:storage_alloy@0"
            ]
        },
        {
            "x": -1,
            "y": 12,
            "z": 0,
            "elements": [
                "chisel:laboratory@9"
            ]
        },
        {
            "x": -2,
            "y": 50,
            "z": 4,
            "elements": [
                "chisel:laboratory@9"
            ]
        },
        {
            "x": -2,
            "y": 37,
            "z": 1,
            "elements": [
                "chisel:laboratory@9"
            ]
        },
        {
            "x": 7,
            "y": 77,
            "z": -2,
            "elements": [
                "actuallyadditions:block_testifi_bucks_white_stairs@1"
            ]
        },
        {
            "x": 1,
            "y": 61,
            "z": 5,
            "elements": [
                "chisel:laboratory@9"
            ]
        },
        {
            "x": 0,
            "y": 9,
            "z": 6,
            "elements": [
                "chisel:laboratory@9"
            ]
        },
        {
            "x": -2,
            "y": 69,
            "z": 3,
            "elements": [
                "chisel:laboratory@9"
            ]
        },
        {
            "x": 0,
            "y": 37,
            "z": 6,
            "elements": [
                "chisel:laboratory@9"
            ]
        },
        {
            "x": 3,
            "y": 4,
            "z": 3,
            "elements": [
                "chisel:laboratory@9"
            ]
        },
        {
            "x": 0,
            "y": 47,
            "z": 5,
            "elements": [
                "chisel:laboratory@9"
            ]
        },
        {
            "x": -2,
            "y": 60,
            "z": 4,
            "elements": [
                "chisel:laboratory@9"
            ]
        },
        {
            "x": 1,
            "y": 45,
            "z": 1,
            "elements": [
                "chisel:laboratory@9"
            ]
        },
        {
            "x": 0,
            "y": 8,
            "z": 6,
            "elements": [
                "chisel:laboratory@9"
            ]
        },
        {
            "x": 0,
            "y": 74,
            "z": 4,
            "elements": [
                "chisel:laboratory@9"
            ]
        },
        {
            "x": -1,
            "y": 6,
            "z": 0,
            "elements": [
                "chisel:laboratory@9"
            ]
        },
        {
            "x": 2,
            "y": 37,
            "z": 5,
            "elements": [
                "chisel:laboratory@9"
            ]
        },
        {
            "x": -2,
            "y": 71,
            "z": 3,
            "elements": [
                "chisel:laboratory@9"
            ]
        },
        {
            "x": -3,
            "y": 7,
            "z": 4,
            "elements": [
                "chisel:laboratory@9"
            ]
        },
        {
            "x": 0,
            "y": 55,
            "z": 5,
            "elements": [
                "chisel:laboratory@9"
            ]
        },
        {
            "x": 4,
            "y": 78,
            "z": -2,
            "elements": [
                "chisel:quartz@7"
            ]
        },
        {
            "x": 7,
            "y": 76,
            "z": -2,
            "elements": [
                "chisel:quartz@7"
            ]
        },
        {
            "x": -3,
            "y": 18,
            "z": 3,
            "elements": [
                "chisel:laboratory@9"
            ]
        },
        {
            "x": 1,
            "y": 46,
            "z": 1,
            "elements": [
                "chisel:laboratory@9"
            ]
        },
        {
            "x": 0,
            "y": 51,
            "z": 5,
            "elements": [
                "chisel:laboratory@9"
            ]
        },
        {
            "x": 0,
            "y": 35,
            "z": 6,
            "elements": [
                "chisel:laboratory@9"
            ]
        },
        {
            "x": 2,
            "y": 76,
            "z": 2,
            "elements": [
                "chisel:laboratory@13"
            ]
        },
        {
            "x": -2,
            "y": 48,
            "z": 4,
            "elements": [
                "chisel:laboratory@9"
            ]
        },
        {
            "x": 2,
            "y": -1,
            "z": 7,
            "elements": [
                "immersiveengineering:steel_scaffolding_stairs1@1"
            ]
        },
        {
            "x": 3,
            "y": 6,
            "z": 3,
            "elements": [
                "chisel:laboratory@9"
            ]
        },
        {
            "x": 1,
            "y": 78,
            "z": -2,
            "elements": [
                "thermalfoundation:storage_alloy@0"
            ]
        },
        {
            "x": 1,
            "y": 84,
            "z": -2,
            "elements": [
                "chisel:quartz@7"
            ]
        },
        {
            "x": -2,
            "y": 62,
            "z": 4,
            "elements": [
                "chisel:laboratory@9"
            ]
        },
        {
            "x": 1,
            "y": 48,
            "z": 1,
            "elements": [
                "chisel:laboratory@9"
            ]
        },
        {
            "x": 1,
            "y": 63,
            "z": 5,
            "elements": [
                "chisel:laboratory@9"
            ]
        },
        {
            "x": 2,
            "y": 35,
            "z": 5,
            "elements": [
                "chisel:laboratory@9"
            ]
        },
        {
            "x": 1,
            "y": 47,
            "z": 1,
            "elements": [
                "chisel:laboratory@9"
            ]
        },
        {
            "x": 0,
            "y": 7,
            "z": 6,
            "elements": [
                "chisel:laboratory@9"
            ]
        },
        {
            "x": 0,
            "y": 49,
            "z": 5,
            "elements": [
                "chisel:laboratory@9"
            ]
        },
        {
            "x": 2,
            "y": 74,
            "z": 2,
            "elements": [
                "chisel:laboratory@9"
            ]
        },
        {
            "x": -1,
            "y": 79,
            "z": 2,
            "elements": [
                "chisel:laboratory@4"
            ]
        },
        {
            "x": -3,
            "y": 16,
            "z": 3,
            "elements": [
                "chisel:laboratory@9"
            ]
        },
        {
            "x": -4,
            "y": -1,
            "z": 1,
            "elements": [
                "immersiveengineering:steel_scaffolding_stairs1@2"
            ]
        },
        {
            "x": 7,
            "y": 75,
            "z": -2,
            "elements": [
                "thermalfoundation:storage_alloy@0"
            ]
        },
        {
            "x": 1,
            "y": 85,
            "z": -2,
            "elements": [
                "chisel:quartz@7"
            ]
        },
        {
            "x": -1,
            "y": 8,
            "z": 0,
            "elements": [
                "chisel:laboratory@9"
            ]
        },
        {
            "x": 0,
            "y": 53,
            "z": 5,
            "elements": [
                "chisel:laboratory@9"
            ]
        },
        {
            "x": 0,
            "y": 36,
            "z": 6,
            "elements": [
                "chisel:laboratory@9"
            ]
        },
        {
            "x": -3,
            "y": 9,
            "z": 4,
            "elements": [
                "chisel:laboratory@9"
            ]
        },
        {
            "x": 0,
            "y": 6,
            "z": 6,
            "elements": [
                "chisel:laboratory@9"
            ]
        },
        {
            "x": 1,
            "y": 12,
            "z": 0,
            "elements": [
                "chisel:laboratory@9"
            ]
        },
        {
            "x": 1,
            "y": 76,
            "z": -2,
            "elements": [
                "thermalfoundation:storage_alloy@0"
            ]
        },
        {
            "x": 2,
            "y": 33,
            "z": 5,
            "elements": [
                "chisel:laboratory@9"
            ]
        },
        {
            "x": -2,
            "y": 39,
            "z": 2,
            "elements": [
                "chisel:laboratory@9"
            ]
        },
        {
            "x": -2,
            "y": 69,
            "z": -2,
            "elements": [
                "chisel:quartz@7"
            ]
        },
        {
            "x": -2,
            "y": 33,
            "z": 1,
            "elements": [
                "chisel:laboratory@9"
            ]
        },
        {
            "x": -2,
            "y": 79,
            "z": -2,
            "elements": [
                "chisel:quartz@7"
            ]
        },
        {
            "x": 1,
            "y": 77,
            "z": -2,
            "elements": [
                "thermalfoundation:storage_alloy@0"
            ]
        },
        {
            "x": 2,
            "y": 54,
            "z": 4,
            "elements": [
                "chisel:laboratory@9"
            ]
        },
        {
            "x": 2,
            "y": 55,
            "z": 3,
            "elements": [
                "chisel:laboratory@9"
            ]
        },
        {
            "x": -2,
            "y": 38,
            "z": 2,
            "elements": [
                "chisel:laboratory@9"
            ]
        },
        {
            "x": 0,
            "y": 65,
            "z": 5,
            "elements": [
                "chisel:laboratory@9"
            ]
        },
        {
            "x": -2,
            "y": 45,
            "z": 3,
            "elements": [
                "chisel:laboratory@9"
            ]
        },
        {
            "x": -2,
            "y": 34,
            "z": 1,
            "elements": [
                "chisel:laboratory@9"
            ]
        },
        {
            "x": -2,
            "y": 68,
            "z": -2,
            "elements": [
                "chisel:quartz@7"
            ]
        },
        {
            "x": 2,
            "y": 31,
            "z": 5,
            "elements": [
                "chisel:laboratory@9"
            ]
        },
        {
            "x": -2,
            "y": 35,
            "z": 1,
            "elements": [
                "chisel:laboratory@9"
            ]
        },
        {
            "x": -2,
            "y": 66,
            "z": -2,
            "elements": [
                "actuallyadditions:block_testifi_bucks_white_stairs@5"
            ]
        },
        {
            "x": -20,
            "y": 84,
            "z": -2,
            "elements": [
                "chisel:quartz@7"
            ]
        },
        {
            "x": 1,
            "y": 74,
            "z": -2,
            "elements": [
                "chisel:quartz@7"
            ]
        },
        {
            "x": 2,
            "y": 59,
            "z": 3,
            "elements": [
                "chisel:laboratory@9"
            ]
        },
        {
            "x": 0,
            "y": 67,
            "z": 5,
            "elements": [
                "chisel:laboratory@9"
            ]
        },
        {
            "x": 10,
            "y": 73,
            "z": -2,
            "elements": [
                "thermalfoundation:storage_alloy@0"
            ]
        },
        {
            "x": -2,
            "y": 67,
            "z": -2,
            "elements": [
                "chisel:quartz@7"
            ]
        },
        {
            "x": -2,
            "y": 36,
            "z": 1,
            "elements": [
                "chisel:laboratory@9"
            ]
        },
        {
            "x": -2,
            "y": 47,
            "z": 3,
            "elements": [
                "chisel:laboratory@9"
            ]
        },
        {
            "x": -2,
            "y": 80,
            "z": -2,
            "elements": [
                "actuallyadditions:block_testifi_bucks_white_stairs@0"
            ]
        },
        {
            "x": 2,
            "y": 53,
            "z": 3,
            "elements": [
                "chisel:laboratory@9"
            ]
        },
        {
            "x": 2,
            "y": 52,
            "z": 4,
            "elements": [
                "chisel:laboratory@9"
            ]
        },
        {
            "x": 1,
            "y": 75,
            "z": -2,
            "elements": [
                "chisel:quartz@7"
            ]
        },
        {
            "x": -11,
            "y": 80,
            "z": -2,
            "elements": [
                "chisel:quartz@7"
            ]
        },
        {
            "x": 0,
            "y": 63,
            "z": 5,
            "elements": [
                "chisel:laboratory@9"
            ]
        },
        {
            "x": -2,
            "y": 51,
            "z": 3,
            "elements": [
                "chisel:laboratory@9"
            ]
        },
        {
            "x": 2,
            "y": 4,
            "z": 5,
            "elements": [
                "chisel:laboratory@9"
            ]
        },
        {
            "x": -14,
            "y": 82,
            "z": -2,
            "elements": [
                "chisel:quartz@7"
            ]
        },
        {
            "x": -17,
            "y": 84,
            "z": -2,
            "elements": [
                "thermalfoundation:storage_alloy@0"
            ]
        },
        {
            "x": 2,
            "y": 78,
            "z": 1,
            "elements": [
                "chisel:laboratory@13"
            ]
        },
        {
            "x": -8,
            "y": 78,
            "z": -2,
            "elements": [
                "chisel:quartz@7"
            ]
        },
        {
            "x": -5,
            "y": 76,
            "z": -2,
            "elements": [
                "actuallyadditions:block_testifi_bucks_white_stairs@4"
            ]
        },
        {
            "x": -8,
            "y": 79,
            "z": -2,
            "elements": [
                "chisel:quartz@7"
            ]
        },
        {
            "x": -2,
            "y": 31,
            "z": 1,
            "elements": [
                "chisel:laboratory@9"
            ]
        },
        {
            "x": -5,
            "y": 77,
            "z": -2,
            "elements": [
                "chisel:quartz@7"
            ]
        },
        {
            "x": 2,
            "y": 10,
            "z": 5,
            "elements": [
                "chisel:laboratory@9"
            ]
        },
        {
            "x": -3,
            "y": -1,
            "z": 4,
            "elements": [
                "thermalfoundation:storage_alloy@0"
            ]
        },
        {
            "x": -11,
            "y": 81,
            "z": -2,
            "elements": [
                "thermalfoundation:storage_alloy@0"
            ]
        },
        {
            "x": -2,
            "y": 37,
            "z": 5,
            "elements": [
                "chisel:laboratory@9"
            ]
        },
        {
            "x": -14,
            "y": 83,
            "z": -2,
            "elements": [
                "thermalfoundation:storage_alloy@0"
            ]
        },
        {
            "x": 1,
            "y": 73,
            "z": -2,
            "elements": [
                "chisel:quartz@7"
            ]
        },
        {
            "x": 2,
            "y": 50,
            "z": 4,
            "elements": [
                "chisel:laboratory@9"
            ]
        },
        {
            "x": -1,
            "y": 75,
            "z": 0,
            "elements": [
                "chisel:laboratory@4"
            ]
        },
        {
            "x": -2,
            "y": 75,
            "z": -2,
            "elements": [
                "chisel:quartz@7"
            ]
        },
        {
            "x": -2,
            "y": 71,
            "z": -2,
            "elements": [
                "thermalfoundation:storage_alloy@0"
            ]
        },
        {
            "x": 2,
            "y": 6,
            "z": 5,
            "elements": [
                "chisel:laboratory@9"
            ]
        },
        {
            "x": 2,
            "y": 48,
            "z": 4,
            "elements": [
                "chisel:laboratory@9"
            ]
        },
        {
            "x": -8,
            "y": 80,
            "z": -2,
            "elements": [
                "thermalfoundation:storage_alloy@0"
            ]
        },
        {
            "x": -2,
            "y": 30,
            "z": 1,
            "elements": [
                "chisel:laboratory@9"
            ]
        },
        {
            "x": -17,
            "y": 82,
            "z": -2,
            "elements": [
                "actuallyadditions:block_testifi_bucks_white_stairs@4"
            ]
        },
        {
            "x": 0,
            "y": 61,
            "z": 5,
            "elements": [
                "chisel:laboratory@9"
            ]
        },
        {
            "x": -3,
            "y": 1,
            "z": 4,
            "elements": [
                "chisel:laboratory@9"
            ]
        },
        {
            "x": -2,
            "y": 35,
            "z": 5,
            "elements": [
                "chisel:laboratory@9"
            ]
        },
        {
            "x": -2,
            "y": 76,
            "z": -2,
            "elements": [
                "chisel:quartz@7"
            ]
        },
        {
            "x": -2,
            "y": 49,
            "z": 3,
            "elements": [
                "chisel:laboratory@9"
            ]
        },
        {
            "x": -2,
            "y": 77,
            "z": -2,
            "elements": [
                "thermalfoundation:storage_alloy@0"
            ]
        },
        {
            "x": 2,
            "y": 57,
            "z": 3,
            "elements": [
                "chisel:laboratory@9"
            ]
        },
        {
            "x": -2,
            "y": 29,
            "z": 1,
            "elements": [
                "chisel:laboratory@9"
            ]
        },
        {
            "x": 1,
            "y": 79,
            "z": 1,
            "elements": [
                "chisel:laboratory@4"
            ]
        },
        {
            "x": -2,
            "y": -1,
            "z": 4,
            "elements": [
                "thermalfoundation:storage_alloy@0"
            ]
        },
        {
            "x": 1,
            "y": 72,
            "z": -2,
            "elements": [
                "actuallyadditions:block_testifi_bucks_white_stairs@5"
            ]
        },
        {
            "x": -17,
            "y": 83,
            "z": -2,
            "elements": [
                "chisel:quartz@7"
            ]
        },
        {
            "x": 2,
            "y": 8,
            "z": 5,
            "elements": [
                "chisel:laboratory@9"
            ]
        },
        {
            "x": -2,
            "y": 56,
            "z": 4,
            "elements": [
                "chisel:laboratory@9"
            ]
        },
        {
            "x": -11,
            "y": 79,
            "z": -2,
            "elements": [
                "actuallyadditions:block_testifi_bucks_white_stairs@4"
            ]
        },
        {
            "x": -2,
            "y": 32,
            "z": 1,
            "elements": [
                "chisel:laboratory@9"
            ]
        },
        {
            "x": -2,
            "y": 40,
            "z": 2,
            "elements": [
                "chisel:laboratory@9"
            ]
        },
        {
            "x": -2,
            "y": 70,
            "z": -2,
            "elements": [
                "thermalfoundation:storage_alloy@0"
            ]
        },
        {
            "x": 1,
            "y": 76,
            "z": 7,
            "elements": [
                "chisel:technical@4"
            ]
        },
        {
            "x": -2,
            "y": 28,
            "z": 1,
            "elements": [
                "chisel:laboratory@9"
            ]
        },
        {
            "x": 0,
            "y": 27,
            "z": 6,
            "elements": [
                "chisel:laboratory@9"
            ]
        },
        {
            "x": 2,
            "y": 14,
            "z": 5,
            "elements": [
                "chisel:laboratory@9"
            ]
        },
        {
            "x": 2,
            "y": 47,
            "z": 3,
            "elements": [
                "chisel:laboratory@9"
            ]
        },
        {
            "x": -3,
            "y": 4,
            "z": 3,
            "elements": [
                "chisel:laboratory@9"
            ]
        },
        {
            "x": -2,
            "y": 41,
            "z": 2,
            "elements": [
                "chisel:laboratory@9"
            ]
        },
        {
            "x": 2,
            "y": 46,
            "z": 4,
            "elements": [
                "chisel:laboratory@9"
            ]
        },
        {
            "x": 2,
            "y": 45,
            "z": 3,
            "elements": [
                "chisel:laboratory@9"
            ]
        },
        {
            "x": 1,
            "y": 6,
            "z": 0,
            "elements": [
                "chisel:laboratory@9"
            ]
        },
        {
            "x": -3,
            "y": 2,
            "z": 3,
            "elements": [
                "chisel:laboratory@9"
            ]
        },
        {
            "x": 1,
            "y": 78,
            "z": -1,
            "elements": [
                "avaritia:block_resource@0"
            ]
        },
        {
            "x": -1,
            "y": 74,
            "z": 1,
            "elements": [
                "chisel:laboratory@9"
            ]
        },
        {
            "x": -2,
            "y": 42,
            "z": 2,
            "elements": [
                "chisel:laboratory@9"
            ]
        },
        {
            "x": -2,
            "y": 55,
            "z": 3,
            "elements": [
                "chisel:laboratory@9"
            ]
        },
        {
            "x": -2,
            "y": 27,
            "z": 1,
            "elements": [
                "chisel:laboratory@9"
            ]
        },
        {
            "x": 1,
            "y": 20,
            "z": 0,
            "elements": [
                "chisel:laboratory@9"
            ]
        },
        {
            "x": -2,
            "y": 53,
            "z": 3,
            "elements": [
                "chisel:laboratory@9"
            ]
        },
        {
            "x": -5,
            "y": 78,
            "z": -2,
            "elements": [
                "thermalfoundation:storage_alloy@0"
            ]
        },
        {
            "x": 2,
            "y": 75,
            "z": 1,
            "elements": [
                "chisel:laboratory@4"
            ]
        },
        {
            "x": -2,
            "y": 25,
            "z": 1,
            "elements": [
                "chisel:laboratory@9"
            ]
        },
        {
            "x": -2,
            "y": 43,
            "z": 2,
            "elements": [
                "chisel:laboratory@9"
            ]
        },
        {
            "x": 0,
            "y": 33,
            "z": 0,
            "elements": [
                "chisel:laboratory@9"
            ]
        },
        {
            "x": -3,
            "y": 6,
            "z": 3,
            "elements": [
                "chisel:laboratory@9"
            ]
        },
        {
            "x": 2,
            "y": 44,
            "z": 4,
            "elements": [
                "chisel:laboratory@9"
            ]
        },
        {
            "x": -2,
            "y": 26,
            "z": 1,
            "elements": [
                "chisel:laboratory@9"
            ]
        },
        {
            "x": 1,
            "y": 78,
            "z": 7,
            "elements": [
                "chisel:technical@4"
            ]
        },
        {
            "x": 2,
            "y": 76,
            "z": 1,
            "elements": [
                "chisel:laboratory@13"
            ]
        },
        {
            "x": 2,
            "y": 12,
            "z": 5,
            "elements": [
                "chisel:laboratory@9"
            ]
        },
        {
            "x": 1,
            "y": 18,
            "z": 0,
            "elements": [
                "chisel:laboratory@9"
            ]
        },
        {
            "x": -2,
            "y": 44,
            "z": 2,
            "elements": [
                "chisel:laboratory@9"
            ]
        },
        {
            "x": 1,
            "y": 8,
            "z": 0,
            "elements": [
                "chisel:laboratory@9"
            ]
        },
        {
            "x": 1,
            "y": 77,
            "z": 7,
            "elements": [
                "chisel:technical@4"
            ]
        },
        {
            "x": 13,
            "y": 74,
            "z": -2,
            "elements": [
                "actuallyadditions:block_testifi_bucks_white_stairs@1"
            ]
        },
        {
            "x": 0,
            "y": 35,
            "z": 0,
            "elements": [
                "chisel:laboratory@9"
            ]
        },
        {
            "x": 2,
            "y": 77,
            "z": 1,
            "elements": [
                "chisel:laboratory@13"
            ]
        },
        {
            "x": -3,
            "y": 0,
            "z": 3,
            "elements": [
                "chisel:laboratory@9"
            ]
        },
        {
            "x": -1,
            "y": 79,
            "z": 1,
            "elements": [
                "chisel:laboratory@4"
            ]
        },
        {
            "x": 2,
            "y": 51,
            "z": 3,
            "elements": [
                "chisel:laboratory@9"
            ]
        },
        {
            "x": -2,
            "y": 45,
            "z": 2,
            "elements": [
                "chisel:laboratory@9"
            ]
        },
        {
            "x": 0,
            "y": -1,
            "z": 4,
            "elements": [
                "thermalfoundation:storage_alloy@0"
            ]
        },
        {
            "x": 13,
            "y": 72,
            "z": -2,
            "elements": [
                "thermalfoundation:storage_alloy@0"
            ]
        },
        {
            "x": 0,
            "y": 23,
            "z": 6,
            "elements": [
                "chisel:laboratory@9"
            ]
        },
        {
            "x": 10,
            "y": 74,
            "z": -2,
            "elements": [
                "chisel:quartz@7"
            ]
        },
        {
            "x": 2,
            "y": 18,
            "z": 5,
            "elements": [
                "chisel:laboratory@9"
            ]
        },
        {
            "x": 1,
            "y": 45,
            "z": 5,
            "elements": [
                "chisel:laboratory@9"
            ]
        },
        {
            "x": 10,
            "y": 75,
            "z": -2,
            "elements": [
                "chisel:quartz@7"
            ]
        },
        {
            "x": -2,
            "y": 23,
            "z": 1,
            "elements": [
                "chisel:laboratory@9"
            ]
        },
        {
            "x": 1,
            "y": 16,
            "z": 0,
            "elements": [
                "chisel:laboratory@9"
            ]
        },
        {
            "x": -2,
            "y": 46,
            "z": 2,
            "elements": [
                "chisel:laboratory@9"
            ]
        },
        {
            "x": 16,
            "y": 70,
            "z": -2,
            "elements": [
                "thermalfoundation:storage_alloy@0"
            ]
        },
        {
            "x": 13,
            "y": 73,
            "z": -2,
            "elements": [
                "chisel:quartz@7"
            ]
        },
        {
            "x": -2,
            "y": 59,
            "z": 3,
            "elements": [
                "chisel:laboratory@9"
            ]
        },
        {
            "x": 0,
            "y": 37,
            "z": 0,
            "elements": [
                "chisel:laboratory@9"
            ]
        },
        {
            "x": 16,
            "y": 71,
            "z": -2,
            "elements": [
                "chisel:quartz@7"
            ]
        },
        {
            "x": -2,
            "y": 24,
            "z": 1,
            "elements": [
                "chisel:laboratory@9"
            ]
        },
        {
            "x": 0,
            "y": 69,
            "z": 5,
            "elements": [
                "chisel:laboratory@9"
            ]
        },
        {
            "x": 0,
            "y": 24,
            "z": 6,
            "elements": [
                "chisel:laboratory@9"
            ]
        },
        {
            "x": 2,
            "y": 40,
            "z": 4,
            "elements": [
                "chisel:laboratory@9"
            ]
        },
        {
            "x": 1,
            "y": 39,
            "z": 5,
            "elements": [
                "chisel:laboratory@9"
            ]
        },
        {
            "x": 1,
            "y": 10,
            "z": 0,
            "elements": [
                "chisel:laboratory@9"
            ]
        },
        {
            "x": 2,
            "y": 16,
            "z": 5,
            "elements": [
                "chisel:laboratory@9"
            ]
        },
        {
            "x": 1,
            "y": 76,
            "z": -1,
            "elements": [
                "avaritia:block_resource@0"
            ]
        },
        {
            "x": 16,
            "y": 72,
            "z": -2,
            "elements": [
                "chisel:quartz@7"
            ]
        },
        {
            "x": 1,
            "y": 43,
            "z": 5,
            "elements": [
                "chisel:laboratory@9"
            ]
        },
        {
            "x": -2,
            "y": 48,
            "z": 2,
            "elements": [
                "chisel:laboratory@9"
            ]
        },
        {
            "x": 0,
            "y": 25,
            "z": 6,
            "elements": [
                "chisel:laboratory@9"
            ]
        },
        {
            "x": 0,
            "y": 71,
            "z": 5,
            "elements": [
                "chisel:laboratory@9"
            ]
        },
        {
            "x": 1,
            "y": -1,
            "z": 4,
            "elements": [
                "thermalfoundation:storage_alloy@0"
            ]
        },
        {
            "x": 2,
            "y": 49,
            "z": 3,
            "elements": [
                "chisel:laboratory@9"
            ]
        },
        {
            "x": 1,
            "y": 77,
            "z": -1,
            "elements": [
                "avaritia:block_resource@0"
            ]
        },
        {
            "x": 1,
            "y": 14,
            "z": 0,
            "elements": [
                "chisel:laboratory@9"
            ]
        },
        {
            "x": -2,
            "y": 21,
            "z": 1,
            "elements": [
                "chisel:laboratory@9"
            ]
        },
        {
            "x": 1,
            "y": 79,
            "z": 6,
            "elements": [
                "chisel:laboratory@4"
            ]
        },
        {
            "x": 2,
            "y": 42,
            "z": 4,
            "elements": [
                "chisel:laboratory@9"
            ]
        },
        {
            "x": -2,
            "y": 57,
            "z": 3,
            "elements": [
                "chisel:laboratory@9"
            ]
        },
        {
            "x": -2,
            "y": 47,
            "z": 2,
            "elements": [
                "chisel:laboratory@9"
            ]
        },
        {
            "x": -1,
            "y": 73,
            "z": 2,
            "elements": [
                "chisel:laboratory@9"
            ]
        },
        {
            "x": -2,
            "y": 22,
            "z": 1,
            "elements": [
                "chisel:laboratory@9"
            ]
        },
        {
            "x": 0,
            "y": 26,
            "z": 6,
            "elements": [
                "chisel:laboratory@9"
            ]
        },
        {
            "x": -2,
            "y": 50,
            "z": 2,
            "elements": [
                "chisel:laboratory@9"
            ]
        },
        {
            "x": 1,
            "y": 41,
            "z": 5,
            "elements": [
                "chisel:laboratory@9"
            ]
        },
        {
            "x": 18,
            "y": 70,
            "z": -2,
            "elements": [
                "chisel:quartz@7"
            ]
        },
        {
            "x": -1,
            "y": 45,
            "z": 1,
            "elements": [
                "chisel:laboratory@9"
            ]
        },
        {
            "x": 3,
            "y": 3,
            "z": 2,
            "elements": [
                "chisel:laboratory@9"
            ]
        },
        {
            "x": 1,
            "y": -1,
            "z": 7,
            "elements": [
                "immersiveengineering:steel_scaffolding_stairs1@3"
            ]
        },
        {
            "x": 2,
            "y": 75,
            "z": 3,
            "elements": [
                "chisel:laboratory@4"
            ]
        },
        {
            "x": -5,
            "y": 61,
            "z": -2,
            "elements": [
                "chisel:quartz@7"
            ]
        },
        {
            "x": 2,
            "y": 60,
            "z": 2,
            "elements": [
                "chisel:laboratory@9"
            ]
        },
        {
            "x": 2,
            "y": 19,
            "z": 5,
            "elements": [
                "chisel:laboratory@9"
            ]
        },
        {
            "x": 2,
            "y": 56,
            "z": 4,
            "elements": [
                "chisel:laboratory@9"
            ]
        },
        {
            "x": -1,
            "y": 29,
            "z": 0,
            "elements": [
                "chisel:laboratory@9"
            ]
        },
        {
            "x": 0,
            "y": 43,
            "z": 1,
            "elements": [
                "chisel:laboratory@9"
            ]
        },
        {
            "x": -2,
            "y": 12,
            "z": 1,
            "elements": [
                "chisel:laboratory@9"
            ]
        },
        {
            "x": 1,
            "y": 71,
            "z": 1,
            "elements": [
                "chisel:laboratory@9"
            ]
        },
        {
            "x": -2,
            "y": 28,
            "z": 5,
            "elements": [
                "chisel:laboratory@9"
            ]
        },
        {
            "x": -2,
            "y": 27,
            "z": 5,
            "elements": [
                "chisel:laboratory@9"
            ]
        },
        {
            "x": 2,
            "y": 57,
            "z": 4,
            "elements": [
                "chisel:laboratory@9"
            ]
        },
        {
            "x": -10,
            "y": 79,
            "z": -2,
            "elements": [
                "chisel:quartz@7"
            ]
        },
        {
            "x": 2,
            "y": 75,
            "z": 5,
            "elements": [
                "chisel:laboratory@4"
            ]
        },
        {
            "x": 2,
            "y": 76,
            "z": 3,
            "elements": [
                "chisel:laboratory@13"
            ]
        },
        {
            "x": -4,
            "y": -1,
            "z": 2,
            "elements": [
                "immersiveengineering:steel_scaffolding_stairs1@0"
            ]
        },
        {
            "x": -2,
            "y": 52,
            "z": 2,
            "elements": [
                "chisel:laboratory@9"
            ]
        },
        {
            "x": -1,
            "y": 6,
            "z": 6,
            "elements": [
                "chisel:laboratory@9"
            ]
        },
        {
            "x": -3,
            "y": 9,
            "z": 2,
            "elements": [
                "chisel:laboratory@9"
            ]
        },
        {
            "x": 2,
            "y": 20,
            "z": 5,
            "elements": [
                "chisel:laboratory@9"
            ]
        },
        {
            "x": -1,
            "y": 30,
            "z": 0,
            "elements": [
                "chisel:laboratory@9"
            ]
        },
        {
            "x": -7,
            "y": 77,
            "z": -2,
            "elements": [
                "actuallyadditions:block_testifi_bucks_white_stairs@4"
            ]
        },
        {
            "x": 0,
            "y": 79,
            "z": 5,
            "elements": [
                "chisel:laboratory@4"
            ]
        },
        {
            "x": 1,
            "y": 31,
            "z": 6,
            "elements": [
                "chisel:laboratory@9"
            ]
        },
        {
            "x": 5,
            "y": 94,
            "z": -2,
            "elements": [
                "actuallyadditions:block_testifi_bucks_white_stairs@0"
            ]
        },
        {
            "x": 1,
            "y": 33,
            "z": 6,
            "elements": [
                "chisel:laboratory@9"
            ]
        },
        {
            "x": 19,
            "y": 70,
            "z": -2,
            "elements": [
                "chisel:quartz@7"
            ]
        },
        {
            "x": 2,
            "y": 21,
            "z": 5,
            "elements": [
                "chisel:laboratory@9"
            ]
        },
        {
            "x": -1,
            "y": 67,
            "z": 1,
            "elements": [
                "chisel:laboratory@9"
            ]
        },
        {
            "x": 3,
            "y": 1,
            "z": 2,
            "elements": [
                "chisel:laboratory@9"
            ]
        },
        {
            "x": -2,
            "y": 75,
            "z": 1,
            "elements": [
                "chisel:laboratory@4"
            ]
        },
        {
            "x": 3,
            "y": -1,
            "z": 4,
            "elements": [
                "thermalfoundation:storage_alloy@0"
            ]
        },
        {
            "x": 2,
            "y": 74,
            "z": 3,
            "elements": [
                "chisel:laboratory@9"
            ]
        },
        {
            "x": -2,
            "y": 30,
            "z": 5,
            "elements": [
                "chisel:laboratory@9"
            ]
        },
        {
            "x": -1,
            "y": 31,
            "z": 0,
            "elements": [
                "chisel:laboratory@9"
            ]
        },
        {
            "x": -1,
            "y": 47,
            "z": 1,
            "elements": [
                "chisel:laboratory@9"
            ]
        },
        {
            "x": 2,
            "y": 58,
            "z": 4,
            "elements": [
                "chisel:laboratory@9"
            ]
        },
        {
            "x": 2,
            "y": 58,
            "z": 2,
            "elements": [
                "chisel:laboratory@9"
            ]
        },
        {
            "x": -1,
            "y": 79,
            "z": 3,
            "elements": [
                "chisel:laboratory@4"
            ]
        },
        {
            "x": -2,
            "y": 14,
            "z": 1,
            "elements": [
                "chisel:laboratory@9"
            ]
        },
        {
            "x": -1,
            "y": 8,
            "z": 6,
            "elements": [
                "chisel:laboratory@9"
            ]
        },
        {
            "x": 2,
            "y": 22,
            "z": 5,
            "elements": [
                "chisel:laboratory@9"
            ]
        },
        {
            "x": -1,
            "y": 32,
            "z": 0,
            "elements": [
                "chisel:laboratory@9"
            ]
        },
        {
            "x": -9,
            "y": 79,
            "z": -2,
            "elements": [
                "chisel:quartz@7"
            ]
        },
        {
            "x": -1,
            "y": 69,
            "z": 1,
            "elements": [
                "chisel:laboratory@9"
            ]
        },
        {
            "x": -3,
            "y": 11,
            "z": 2,
            "elements": [
                "chisel:laboratory@9"
            ]
        },
        {
            "x": -10,
            "y": 81,
            "z": -2,
            "elements": [
                "thermalfoundation:storage_alloy@0"
            ]
        },
        {
            "x": 7,
            "y": 92,
            "z": -2,
            "elements": [
                "thermalfoundation:storage_alloy@0"
            ]
        },
        {
            "x": -2,
            "y": 29,
            "z": 5,
            "elements": [
                "chisel:laboratory@9"
            ]
        },
        {
            "x": 2,
            "y": 59,
            "z": 4,
            "elements": [
                "chisel:laboratory@9"
            ]
        },
        {
            "x": -2,
            "y": 64,
            "z": 2,
            "elements": [
                "chisel:laboratory@9"
            ]
        },
        {
            "x": -1,
            "y": 65,
            "z": 1,
            "elements": [
                "chisel:laboratory@9"
            ]
        },
        {
            "x": -2,
            "y": 77,
            "z": 1,
            "elements": [
                "chisel:laboratory@13"
            ]
        },
        {
            "x": 0,
            "y": 39,
            "z": 1,
            "elements": [
                "chisel:laboratory@9"
            ]
        },
        {
            "x": -19,
            "y": 83,
            "z": -2,
            "elements": [
                "actuallyadditions:block_testifi_bucks_white_stairs@4"
            ]
        },
        {
            "x": 1,
            "y": 65,
            "z": 1,
            "elements": [
                "chisel:laboratory@9"
            ]
        },
        {
            "x": 2,
            "y": 72,
            "z": 3,
            "elements": [
                "chisel:laboratory@9"
            ]
        },
        {
            "x": -1,
            "y": 76,
            "z": 7,
            "elements": [
                "chisel:technical@4"
            ]
        },
        {
            "x": 2,
            "y": 61,
            "z": 4,
            "elements": [
                "chisel:laboratory@9"
            ]
        },
        {
            "x": 2,
            "y": 23,
            "z": 5,
            "elements": [
                "chisel:laboratory@9"
            ]
        },
        {
            "x": -1,
            "y": 33,
            "z": 0,
            "elements": [
                "chisel:laboratory@9"
            ]
        },
        {
            "x": -1,
            "y": 4,
            "z": 6,
            "elements": [
                "chisel:laboratory@9"
            ]
        },
        {
            "x": 1,
            "y": 77,
            "z": -3,
            "elements": [
                "contenttweaker:crystalmatrixforcefieldcontrolblock@0"
            ]
        },
        {
            "x": 2,
            "y": 24,
            "z": 5,
            "elements": [
                "chisel:laboratory@9"
            ]
        },
        {
            "x": 2,
            "y": 60,
            "z": 4,
            "elements": [
                "chisel:laboratory@9"
            ]
        },
        {
            "x": -3,
            "y": 3,
            "z": 2,
            "elements": [
                "chisel:laboratory@9"
            ]
        },
        {
            "x": 2,
            "y": 69,
            "z": 3,
            "elements": [
                "chisel:laboratory@9"
            ]
        },
        {
            "x": 2,
            "y": -1,
            "z": 2,
            "elements": [
                "thermalfoundation:storage_alloy@0"
            ]
        },
        {
            "x": -1,
            "y": 74,
            "z": 3,
            "elements": [
                "chisel:laboratory@9"
            ]
        },
        {
            "x": -1,
            "y": 71,
            "z": 1,
            "elements": [
                "chisel:laboratory@9"
            ]
        },
        {
            "x": 1,
            "y": 27,
            "z": 6,
            "elements": [
                "chisel:laboratory@9"
            ]
        },
        {
            "x": -2,
            "y": 16,
            "z": 1,
            "elements": [
                "chisel:laboratory@9"
            ]
        },
        {
            "x": -1,
            "y": 73,
            "z": 3,
            "elements": [
                "chisel:laboratory@9"
            ]
        },
        {
            "x": -1,
            "y": 34,
            "z": 0,
            "elements": [
                "chisel:laboratory@9"
            ]
        },
        {
            "x": 0,
            "y": 41,
            "z": 1,
            "elements": [
                "chisel:laboratory@9"
            ]
        },
        {
            "x": -2,
            "y": 56,
            "z": 2,
            "elements": [
                "chisel:laboratory@9"
            ]
        },
        {
            "x": 2,
            "y": 71,
            "z": 3,
            "elements": [
                "chisel:laboratory@9"
            ]
        },
        {
            "x": 2,
            "y": 37,
            "z": 1,
            "elements": [
                "chisel:laboratory@9"
            ]
        },
        {
            "x": 3,
            "y": 36,
            "z": 2,
            "elements": [
                "chisel:laboratory@9"
            ]
        },
        {
            "x": 2,
            "y": 63,
            "z": 4,
            "elements": [
                "chisel:laboratory@9"
            ]
        },
        {
            "x": 2,
            "y": 70,
            "z": 3,
            "elements": [
                "chisel:laboratory@9"
            ]
        },
        {
            "x": -2,
            "y": 20,
            "z": 1,
            "elements": [
                "chisel:laboratory@9"
            ]
        },
        {
            "x": -1,
            "y": 78,
            "z": 7,
            "elements": [
                "chisel:technical@4"
            ]
        },
        {
            "x": 2,
            "y": 26,
            "z": 5,
            "elements": [
                "chisel:laboratory@9"
            ]
        },
        {
            "x": 1,
            "y": 67,
            "z": 1,
            "elements": [
                "chisel:laboratory@9"
            ]
        },
        {
            "x": -1,
            "y": 43,
            "z": 1,
            "elements": [
                "chisel:laboratory@9"
            ]
        },
        {
            "x": -1,
            "y": 69,
            "z": -2,
            "elements": [
                "chisel:quartz@7"
            ]
        },
        {
            "x": -3,
            "y": 1,
            "z": 2,
            "elements": [
                "chisel:laboratory@9"
            ]
        },
        {
            "x": -1,
            "y": 2,
            "z": 6,
            "elements": [
                "chisel:laboratory@9"
            ]
        },
        {
            "x": -2,
            "y": -1,
            "z": 7,
            "elements": [
                "immersiveengineering:steel_scaffolding_stairs1@0"
            ]
        },
        {
            "x": -2,
            "y": 54,
            "z": 2,
            "elements": [
                "chisel:laboratory@9"
            ]
        },
        {
            "x": -1,
            "y": 41,
            "z": 1,
            "elements": [
                "chisel:laboratory@9"
            ]
        },
        {
            "x": 1,
            "y": 69,
            "z": 1,
            "elements": [
                "chisel:laboratory@9"
            ]
        },
        {
            "x": 1,
            "y": 29,
            "z": 6,
            "elements": [
                "chisel:laboratory@9"
            ]
        },
        {
            "x": 2,
            "y": 62,
            "z": 4,
            "elements": [
                "chisel:laboratory@9"
            ]
        },
        {
            "x": -4,
            "y": 67,
            "z": -2,
            "elements": [
                "thermalfoundation:storage_alloy@0"
            ]
        },
        {
            "x": 2,
            "y": 25,
            "z": 5,
            "elements": [
                "chisel:laboratory@9"
            ]
        },
        {
            "x": -2,
            "y": 18,
            "z": 1,
            "elements": [
                "chisel:laboratory@9"
            ]
        },
        {
            "x": -3,
            "y": 7,
            "z": 2,
            "elements": [
                "chisel:laboratory@9"
            ]
        },
        {
            "x": -2,
            "y": 33,
            "z": 5,
            "elements": [
                "chisel:laboratory@9"
            ]
        },
        {
            "x": -2,
            "y": 60,
            "z": 2,
            "elements": [
                "chisel:laboratory@9"
            ]
        },
        {
            "x": 2,
            "y": 65,
            "z": 3,
            "elements": [
                "chisel:laboratory@9"
            ]
        },
        {
            "x": -1,
            "y": 14,
            "z": 6,
            "elements": [
                "chisel:laboratory@9"
            ]
        },
        {
            "x": 2,
            "y": 65,
            "z": 4,
            "elements": [
                "chisel:laboratory@9"
            ]
        },
        {
            "x": -1,
            "y": 59,
            "z": 1,
            "elements": [
                "chisel:laboratory@9"
            ]
        },
        {
            "x": -2,
            "y": -1,
            "z": -1,
            "elements": [
                "immersiveengineering:steel_scaffolding_stairs1@2"
            ]
        },
        {
            "x": 2,
            "y": 28,
            "z": 5,
            "elements": [
                "chisel:laboratory@9"
            ]
        },
        {
            "x": 2,
            "y": 67,
            "z": 4,
            "elements": [
                "chisel:laboratory@9"
            ]
        },
        {
            "x": -13,
            "y": 81,
            "z": -2,
            "elements": [
                "chisel:quartz@7"
            ]
        },
        {
            "x": -1,
            "y": 74,
            "z": 5,
            "elements": [
                "chisel:laboratory@9"
            ]
        },
        {
            "x": -2,
            "y": 6,
            "z": 1,
            "elements": [
                "chisel:laboratory@9"
            ]
        },
        {
            "x": 0,
            "y": -1,
            "z": 2,
            "elements": [
                "thermalfoundation:storage_alloy@0"
            ]
        },
        {
            "x": 2,
            "y": 66,
            "z": 3,
            "elements": [
                "chisel:laboratory@9"
            ]
        },
        {
            "x": -1,
            "y": 53,
            "z": 1,
            "elements": [
                "chisel:laboratory@9"
            ]
        },
        {
            "x": -16,
            "y": 83,
            "z": -2,
            "elements": [
                "chisel:quartz@7"
            ]
        },
        {
            "x": -4,
            "y": 65,
            "z": -2,
            "elements": [
                "chisel:quartz@7"
            ]
        },
        {
            "x": -2,
            "y": 20,
            "z": 5,
            "elements": [
                "chisel:laboratory@9"
            ]
        },
        {
            "x": 2,
            "y": 52,
            "z": 2,
            "elements": [
                "chisel:laboratory@9"
            ]
        },
        {
            "x": 2,
            "y": 27,
            "z": 5,
            "elements": [
                "chisel:laboratory@9"
            ]
        },
        {
            "x": 2,
            "y": 64,
            "z": 4,
            "elements": [
                "chisel:laboratory@9"
            ]
        },
        {
            "x": -2,
            "y": 34,
            "z": 5,
            "elements": [
                "chisel:laboratory@9"
            ]
        },
        {
            "x": -1,
            "y": 76,
            "z": -1,
            "elements": [
                "avaritia:block_resource@0"
            ]
        },
        {
            "x": -1,
            "y": 16,
            "z": 6,
            "elements": [
                "chisel:laboratory@9"
            ]
        },
        {
            "x": -2,
            "y": 31,
            "z": 5,
            "elements": [
                "chisel:laboratory@9"
            ]
        },
        {
            "x": -3,
            "y": 5,
            "z": 2,
            "elements": [
                "chisel:laboratory@9"
            ]
        },
        {
            "x": -1,
            "y": 57,
            "z": 1,
            "elements": [
                "chisel:laboratory@9"
            ]
        },
        {
            "x": -2,
            "y": 58,
            "z": 2,
            "elements": [
                "chisel:laboratory@9"
            ]
        },
        {
            "x": 2,
            "y": 67,
            "z": 3,
            "elements": [
                "chisel:laboratory@9"
            ]
        },
        {
            "x": -2,
            "y": 21,
            "z": 5,
            "elements": [
                "chisel:laboratory@9"
            ]
        },
        {
            "x": -2,
            "y": 39,
            "z": 3,
            "elements": [
                "chisel:laboratory@9"
            ]
        },
        {
            "x": -5,
            "y": 65,
            "z": -2,
            "elements": [
                "thermalfoundation:storage_alloy@0"
            ]
        },
        {
            "x": -1,
            "y": -1,
            "z": 2,
            "elements": [
                "thermalfoundation:storage_alloy@0"
            ]
        },
        {
            "x": -14,
            "y": 81,
            "z": -2,
            "elements": [
                "chisel:quartz@7"
            ]
        },
        {
            "x": -2,
            "y": 4,
            "z": 1,
            "elements": [
                "chisel:laboratory@9"
            ]
        },
        {
            "x": -4,
            "y": 63,
            "z": -2,
            "elements": [
                "chisel:quartz@7"
            ]
        },
        {
            "x": -2,
            "y": 19,
            "z": 5,
            "elements": [
                "chisel:laboratory@9"
            ]
        },
        {
            "x": -2,
            "y": 32,
            "z": 5,
            "elements": [
                "chisel:laboratory@9"
            ]
        },
        {
            "x": -2,
            "y": 38,
            "z": 3,
            "elements": [
                "chisel:laboratory@9"
            ]
        },
        {
            "x": 2,
            "y": 66,
            "z": 4,
            "elements": [
                "chisel:laboratory@9"
            ]
        },
        {
            "x": 2,
            "y": 29,
            "z": 5,
            "elements": [
                "chisel:laboratory@9"
            ]
        },
        {
            "x": -15,
            "y": 83,
            "z": -2,
            "elements": [
                "thermalfoundation:storage_alloy@0"
            ]
        },
        {
            "x": -2,
            "y": 22,
            "z": 5,
            "elements": [
                "chisel:laboratory@9"
            ]
        },
        {
            "x": 2,
            "y": 50,
            "z": 2,
            "elements": [
                "chisel:laboratory@9"
            ]
        },
        {
            "x": 2,
            "y": 68,
            "z": 3,
            "elements": [
                "chisel:laboratory@9"
            ]
        },
        {
            "x": -1,
            "y": 72,
            "z": 5,
            "elements": [
                "chisel:laboratory@9"
            ]
        },
        {
            "x": -1,
            "y": 73,
            "z": 4,
            "elements": [
                "chisel:laboratory@9"
            ]
        },
        {
            "x": -2,
            "y": 23,
            "z": 5,
            "elements": [
                "chisel:laboratory@9"
            ]
        },
        {
            "x": -2,
            "y": 41,
            "z": 3,
            "elements": [
                "chisel:laboratory@9"
            ]
        },
        {
            "x": 1,
            "y": 35,
            "z": 6,
            "elements": [
                "chisel:laboratory@9"
            ]
        },
        {
            "x": 7,
            "y": 96,
            "z": -2,
            "elements": [
                "chisel:quartz@7"
            ]
        },
        {
            "x": 2,
            "y": 62,
            "z": 3,
            "elements": [
                "chisel:laboratory@9"
            ]
        },
        {
            "x": 2,
            "y": 56,
            "z": 2,
            "elements": [
                "chisel:laboratory@9"
            ]
        },
        {
            "x": 2,
            "y": 70,
            "z": 4,
            "elements": [
                "chisel:laboratory@9"
            ]
        },
        {
            "x": 2,
            "y": 78,
            "z": 5,
            "elements": [
                "chisel:laboratory@13"
            ]
        },
        {
            "x": -1,
            "y": 10,
            "z": 6,
            "elements": [
                "chisel:laboratory@9"
            ]
        },
        {
            "x": -2,
            "y": 40,
            "z": 3,
            "elements": [
                "chisel:laboratory@9"
            ]
        },
        {
            "x": -2,
            "y": -1,
            "z": 2,
            "elements": [
                "thermalfoundation:storage_alloy@0"
            ]
        },
        {
            "x": -15,
            "y": 81,
            "z": -2,
            "elements": [
                "actuallyadditions:block_testifi_bucks_white_stairs@4"
            ]
        },
        {
            "x": -1,
            "y": 49,
            "z": 1,
            "elements": [
                "chisel:laboratory@9"
            ]
        },
        {
            "x": -2,
            "y": 24,
            "z": 5,
            "elements": [
                "chisel:laboratory@9"
            ]
        },
        {
            "x": 2,
            "y": 61,
            "z": 3,
            "elements": [
                "chisel:laboratory@9"
            ]
        },
        {
            "x": -1,
            "y": 78,
            "z": -1,
            "elements": [
                "avaritia:block_resource@0"
            ]
        },
        {
            "x": -1,
            "y": 63,
            "z": 1,
            "elements": [
                "chisel:laboratory@9"
            ]
        },
        {
            "x": -2,
            "y": 25,
            "z": 5,
            "elements": [
                "chisel:laboratory@9"
            ]
        },
        {
            "x": 2,
            "y": 71,
            "z": 4,
            "elements": [
                "chisel:laboratory@9"
            ]
        },
        {
            "x": -18,
            "y": 83,
            "z": -2,
            "elements": [
                "chisel:quartz@7"
            ]
        },
        {
            "x": -5,
            "y": 63,
            "z": -2,
            "elements": [
                "chisel:quartz@7"
            ]
        },
        {
            "x": -2,
            "y": 10,
            "z": 1,
            "elements": [
                "chisel:laboratory@9"
            ]
        },
        {
            "x": 2,
            "y": 76,
            "z": 5,
            "elements": [
                "chisel:laboratory@13"
            ]
        },
        {
            "x": 7,
            "y": 94,
            "z": -2,
            "elements": [
                "thermalfoundation:storage_alloy@0"
            ]
        },
        {
            "x": -1,
            "y": 38,
            "z": 5,
            "elements": [
                "chisel:laboratory@9"
            ]
        },
        {
            "x": -2,
            "y": 62,
            "z": 2,
            "elements": [
                "chisel:laboratory@9"
            ]
        },
        {
            "x": 2,
            "y": 68,
            "z": 4,
            "elements": [
                "chisel:laboratory@9"
            ]
        },
        {
            "x": 1,
            "y": 37,
            "z": 6,
            "elements": [
                "chisel:laboratory@9"
            ]
        },
        {
            "x": -2,
            "y": 26,
            "z": 5,
            "elements": [
                "chisel:laboratory@9"
            ]
        },
        {
            "x": -1,
            "y": 12,
            "z": 6,
            "elements": [
                "chisel:laboratory@9"
            ]
        },
        {
            "x": 1,
            "y": -1,
            "z": 2,
            "elements": [
                "thermalfoundation:storage_alloy@0"
            ]
        },
        {
            "x": 2,
            "y": 64,
            "z": 3,
            "elements": [
                "chisel:laboratory@9"
            ]
        },
        {
            "x": -12,
            "y": 81,
            "z": -2,
            "elements": [
                "chisel:quartz@7"
            ]
        },
        {
            "x": -1,
            "y": 74,
            "z": 4,
            "elements": [
                "chisel:laboratory@9"
            ]
        },
        {
            "x": -1,
            "y": 61,
            "z": 1,
            "elements": [
                "chisel:laboratory@9"
            ]
        },
        {
            "x": 2,
            "y": 77,
            "z": 5,
            "elements": [
                "chisel:laboratory@13"
            ]
        },
        {
            "x": -2,
            "y": 42,
            "z": 3,
            "elements": [
                "chisel:laboratory@9"
            ]
        },
        {
            "x": 2,
            "y": 69,
            "z": 4,
            "elements": [
                "chisel:laboratory@9"
            ]
        },
        {
            "x": 2,
            "y": 54,
            "z": 2,
            "elements": [
                "chisel:laboratory@9"
            ]
        },
        {
            "x": -1,
            "y": 51,
            "z": 1,
            "elements": [
                "chisel:laboratory@9"
            ]
        },
        {
            "x": -2,
            "y": 43,
            "z": 3,
            "elements": [
                "chisel:laboratory@9"
            ]
        },
        {
            "x": -2,
            "y": 13,
            "z": 5,
            "elements": [
                "chisel:laboratory@9"
            ]
        },
        {
            "x": -1,
            "y": 79,
            "z": 5,
            "elements": [
                "chisel:laboratory@4"
            ]
        },
        {
            "x": -2,
            "y": 8,
            "z": 1,
            "elements": [
                "chisel:laboratory@9"
            ]
        },
        {
            "x": 2,
            "y": 63,
            "z": 3,
            "elements": [
                "chisel:laboratory@9"
            ]
        },
        {
            "x": 3,
            "y": 13,
            "z": 2,
            "elements": [
                "chisel:laboratory@9"
            ]
        },
        {
            "x": 1,
            "y": 55,
            "z": 1,
            "elements": [
                "chisel:laboratory@9"
            ]
        },
        {
            "x": 2,
            "y": -1,
            "z": -1,
            "elements": [
                "immersiveengineering:steel_scaffolding_stairs1@1"
            ]
        },
        {
            "x": 8,
            "y": 74,
            "z": -2,
            "elements": [
                "thermalfoundation:storage_alloy@0"
            ]
        },
        {
            "x": -1,
            "y": 81,
            "z": -2,
            "elements": [
                "chisel:quartz@7"
            ]
        },
        {
            "x": 2,
            "y": 88,
            "z": -2,
            "elements": [
                "actuallyadditions:block_testifi_bucks_white_stairs@0"
            ]
        },
        {
            "x": -1,
            "y": 16,
            "z": 0,
            "elements": [
                "chisel:laboratory@9"
            ]
        },
        {
            "x": 0,
            "y": 57,
            "z": 1,
            "elements": [
                "chisel:laboratory@9"
            ]
        },
        {
            "x": -2,
            "y": 14,
            "z": 5,
            "elements": [
                "chisel:laboratory@9"
            ]
        },
        {
            "x": -1,
            "y": 40,
            "z": 5,
            "elements": [
                "chisel:laboratory@9"
            ]
        },
        {
            "x": 2,
            "y": 75,
            "z": 4,
            "elements": [
                "chisel:laboratory@4"
            ]
        },
        {
            "x": -1,
            "y": 66,
            "z": 5,
            "elements": [
                "chisel:laboratory@9"
            ]
        },
        {
            "x": -6,
            "y": 59,
            "z": -2,
            "elements": [
                "chisel:quartz@7"
            ]
        },
        {
            "x": -3,
            "y": 27,
            "z": 2,
            "elements": [
                "chisel:laboratory@9"
            ]
        },
        {
            "x": -3,
            "y": 67,
            "z": -2,
            "elements": [
                "chisel:quartz@7"
            ]
        },
        {
            "x": 1,
            "y": 49,
            "z": 1,
            "elements": [
                "chisel:laboratory@9"
            ]
        },
        {
            "x": -1,
            "y": 79,
            "z": 4,
            "elements": [
                "chisel:laboratory@4"
            ]
        },
        {
            "x": 2,
            "y": 42,
            "z": 2,
            "elements": [
                "chisel:laboratory@9"
            ]
        },
        {
            "x": 2,
            "y": 74,
            "z": 4,
            "elements": [
                "chisel:laboratory@9"
            ]
        },
        {
            "x": -1,
            "y": 39,
            "z": 5,
            "elements": [
                "chisel:laboratory@9"
            ]
        },
        {
            "x": -1,
            "y": 15,
            "z": 0,
            "elements": [
                "chisel:laboratory@9"
            ]
        },
        {
            "x": -3,
            "y": 25,
            "z": 2,
            "elements": [
                "chisel:laboratory@9"
            ]
        },
        {
            "x": -1,
            "y": 67,
            "z": 5,
            "elements": [
                "chisel:laboratory@9"
            ]
        },
        {
            "x": 0,
            "y": -1,
            "z": 7,
            "elements": [
                "immersiveengineering:steel_scaffolding_stairs1@3"
            ]
        },
        {
            "x": 2,
            "y": 78,
            "z": 4,
            "elements": [
                "chisel:laboratory@13"
            ]
        },
        {
            "x": -1,
            "y": 14,
            "z": 0,
            "elements": [
                "chisel:laboratory@9"
            ]
        },
        {
            "x": 2,
            "y": 86,
            "z": -2,
            "elements": [
                "chisel:quartz@7"
            ]
        },
        {
            "x": -6,
            "y": 61,
            "z": -2,
            "elements": [
                "chisel:quartz@7"
            ]
        },
        {
            "x": 3,
            "y": 15,
            "z": 2,
            "elements": [
                "chisel:laboratory@9"
            ]
        },
        {
            "x": 0,
            "y": 0,
            "z": 6,
            "elements": [
                "chisel:laboratory@9"
            ]
        },
        {
            "x": -2,
            "y": 11,
            "z": 5,
            "elements": [
                "chisel:laboratory@9"
            ]
        },
        {
            "x": -1,
            "y": 79,
            "z": -2,
            "elements": [
                "chisel:quartz@7"
            ]
        },
        {
            "x": -3,
            "y": 69,
            "z": -2,
            "elements": [
                "thermalfoundation:storage_alloy@0"
            ]
        },
        {
            "x": 0,
            "y": 59,
            "z": 1,
            "elements": [
                "chisel:laboratory@9"
            ]
        },
        {
            "x": 3,
            "y": -1,
            "z": 2,
            "elements": [
                "thermalfoundation:storage_alloy@0"
            ]
        },
        {
            "x": 2,
            "y": 44,
            "z": 2,
            "elements": [
                "chisel:laboratory@9"
            ]
        },
        {
            "x": -1,
            "y": -1,
            "z": -1,
            "elements": [
                "immersiveengineering:steel_scaffolding_stairs1@2"
            ]
        },
        {
            "x": 2,
            "y": 72,
            "z": 4,
            "elements": [
                "chisel:laboratory@9"
            ]
        },
        {
            "x": -2,
            "y": 12,
            "z": 5,
            "elements": [
                "chisel:laboratory@9"
            ]
        },
        {
            "x": -1,
            "y": 13,
            "z": 0,
            "elements": [
                "chisel:laboratory@9"
            ]
        },
        {
            "x": -1,
            "y": 65,
            "z": 5,
            "elements": [
                "chisel:laboratory@9"
            ]
        },
        {
            "x": 8,
            "y": 76,
            "z": -2,
            "elements": [
                "chisel:quartz@7"
            ]
        },
        {
            "x": 20,
            "y": 70,
            "z": -2,
            "elements": [
                "chisel:quartz@7"
            ]
        },
        {
            "x": -1,
            "y": 41,
            "z": 5,
            "elements": [
                "chisel:laboratory@9"
            ]
        },
        {
            "x": 0,
            "y": 2,
            "z": 6,
            "elements": [
                "chisel:laboratory@9"
            ]
        },
        {
            "x": -2,
            "y": 78,
            "z": 2,
            "elements": [
                "chisel:laboratory@13"
            ]
        },
        {
            "x": 1,
            "y": 51,
            "z": 1,
            "elements": [
                "chisel:laboratory@9"
            ]
        },
        {
            "x": 0,
            "y": -1,
            "z": -1,
            "elements": [
                "immersiveengineering:steel_scaffolding_stairs1@2"
            ]
        },
        {
            "x": -6,
            "y": 63,
            "z": -2,
            "elements": [
                "thermalfoundation:storage_alloy@0"
            ]
        },
        {
            "x": -1,
            "y": 19,
            "z": 0,
            "elements": [
                "chisel:laboratory@9"
            ]
        },
        {
            "x": -2,
            "y": 18,
            "z": 5,
            "elements": [
                "chisel:laboratory@9"
            ]
        },
        {
            "x": 2,
            "y": 84,
            "z": -2,
            "elements": [
                "thermalfoundation:storage_alloy@0"
            ]
        },
        {
            "x": -1,
            "y": 55,
            "z": 1,
            "elements": [
                "chisel:laboratory@9"
            ]
        },
        {
            "x": 2,
            "y": 46,
            "z": 2,
            "elements": [
                "chisel:laboratory@9"
            ]
        },
        {
            "x": 17,
            "y": 72,
            "z": -2,
            "elements": [
                "actuallyadditions:block_testifi_bucks_white_stairs@1"
            ]
        },
        {
            "x": -1,
            "y": 71,
            "z": 5,
            "elements": [
                "chisel:laboratory@9"
            ]
        },
        {
            "x": -2,
            "y": 2,
            "z": 1,
            "elements": [
                "chisel:laboratory@9"
            ]
        },
        {
            "x": -2,
            "y": 17,
            "z": 5,
            "elements": [
                "chisel:laboratory@9"
            ]
        },
        {
            "x": -1,
            "y": 20,
            "z": 0,
            "elements": [
                "chisel:laboratory@9"
            ]
        },
        {
            "x": -2,
            "y": 76,
            "z": 2,
            "elements": [
                "chisel:laboratory@13"
            ]
        },
        {
            "x": 1,
            "y": 74,
            "z": 2,
            "elements": [
                "chisel:laboratory@9"
            ]
        },
        {
            "x": -1,
            "y": 64,
            "z": 5,
            "elements": [
                "chisel:laboratory@9"
            ]
        },
        {
            "x": -3,
            "y": 23,
            "z": 2,
            "elements": [
                "chisel:laboratory@9"
            ]
        },
        {
            "x": 1,
            "y": 53,
            "z": 1,
            "elements": [
                "chisel:laboratory@9"
            ]
        },
        {
            "x": -1,
            "y": 70,
            "z": 5,
            "elements": [
                "chisel:laboratory@9"
            ]
        },
        {
            "x": 1,
            "y": -1,
            "z": -1,
            "elements": [
                "immersiveengineering:steel_scaffolding_stairs1@2"
            ]
        },
        {
            "x": 3,
            "y": 19,
            "z": 2,
            "elements": [
                "chisel:laboratory@9"
            ]
        },
        {
            "x": 0,
            "y": 55,
            "z": 1,
            "elements": [
                "chisel:laboratory@9"
            ]
        },
        {
            "x": -2,
            "y": 0,
            "z": 1,
            "elements": [
                "chisel:laboratory@9"
            ]
        },
        {
            "x": 17,
            "y": 70,
            "z": -2,
            "elements": [
                "thermalfoundation:storage_alloy@0"
            ]
        },
        {
            "x": -1,
            "y": 68,
            "z": 5,
            "elements": [
                "chisel:laboratory@9"
            ]
        },
        {
            "x": 0,
            "y": 4,
            "z": 6,
            "elements": [
                "chisel:laboratory@9"
            ]
        },
        {
            "x": 11,
            "y": 74,
            "z": -2,
            "elements": [
                "chisel:quartz@7"
            ]
        },
        {
            "x": 2,
            "y": 48,
            "z": 2,
            "elements": [
                "chisel:laboratory@9"
            ]
        },
        {
            "x": 2,
            "y": 77,
            "z": 4,
            "elements": [
                "chisel:laboratory@13"
            ]
        },
        {
            "x": -2,
            "y": 16,
            "z": 5,
            "elements": [
                "chisel:laboratory@9"
            ]
        },
        {
            "x": -3,
            "y": -1,
            "z": 2,
            "elements": [
                "thermalfoundation:storage_alloy@0"
            ]
        },
        {
            "x": -3,
            "y": 65,
            "z": -2,
            "elements": [
                "chisel:quartz@7"
            ]
        },
        {
            "x": 3,
            "y": 17,
            "z": 2,
            "elements": [
                "chisel:laboratory@9"
            ]
        },
        {
            "x": -2,
            "y": 15,
            "z": 5,
            "elements": [
                "chisel:laboratory@9"
            ]
        },
        {
            "x": 2,
            "y": 76,
            "z": 4,
            "elements": [
                "chisel:laboratory@13"
            ]
        },
        {
            "x": -2,
            "y": 74,
            "z": 2,
