{
    "registryname": "g_htmp",
    "localizedname": "§B巨型高温熔化工厂",
    "failure-action": "still",
    "requires-blueprint": false,
    "has-factory": true,
    "factory-only": true,
    "color": "CBCECD",
    "parts": [
        {
            "x": 0,
            "y": 0,
            "z": 0,
            "elements": [
                "modularmachinery:g_htmp_factory_controller@2"
            ]
        },
        {
            "x": 3,
            "y": 14,
            "z": 6,
            "elements": [
                "chisel:technical1@4"
            ]
        },
        {
            "x": -1,
            "y": 2,
            "z": 0,
            "elements": [
                "contenttweaker:universalforcefieldcontrolblock@0"
            ]
        },
        {
            "x": -3,
            "y": 0,
            "z": 5,
            "elements": [
                "contenttweaker:crystalmatrixforcefieldcontrolblock@0"
            ]
        },
        {
            "x": -2,
            "y": 4,
            "z": 0,
            "elements": [
                "chisel:technical1@4"
            ]
        },
        {
            "x": -6,
            "y": 0,
            "z": 10,
            "elements": [
                "contenttweaker:crystalmatrixforcefieldcontrolblock@0"
            ]
        },
        {
            "x": 0,
            "y": 14,
            "z": 7,
            "elements": [
                "chisel:technical1@4"
            ]
        },
        {
            "x": -3,
            "y": 6,
            "z": 0,
            "elements": [
                "chisel:technical1@4"
            ]
        },
        {
            "x": -4,
            "y": 8,
            "z": 0,
            "elements": [
                "chisel:technical1@4"
            ]
        },
        {
            "x": -5,
            "y": 2,
            "z": 10,
            "elements": [
                "chisel:technical1@4"
            ]
        },
        {
            "x": -5,
            "y": 10,
            "z": 0,
            "elements": [
                "chisel:technical1@4"
            ]
        },
        {
            "x": 8,
            "y": -1,
            "z": 7,
            "elements": [
                "chisel:technical1@4"
            ]
        },
        {
            "x": 5,
            "y": -1,
            "z": 1,
            "elements": [
                "chisel:technical1@4"
            ]
        },
        {
            "x": -6,
            "y": 12,
            "z": 0,
            "elements": [
                "chisel:technical1@4"
            ]
        },
        {
            "x": -5,
            "y": 0,
            "z": 15,
            "elements": [
                "chisel:technical1@4"
            ]
        },
        {
            "x": -6,
            "y": 14,
            "z": 14,
            "elements": [
                "chisel:technical1@4"
            ]
        },
        {
            "x": -7,
            "y": 8,
            "z": 5,
            "elements": [
                "chisel:technical1@4"
            ]
        },
        {
            "x": -7,
            "y": 6,
            "z": 10,
            "elements": [
                "chisel:technical1@4"
            ]
        },
        {
            "x": -6,
            "y": 2,
            "z": 15,
            "elements": [
                "chisel:technical1@4"
            ]
        },
        {
            "x": 6,
            "y": 2,
            "z": 7,
            "elements": [
                "tconevo:metal_block@2"
            ]
        },
        {
            "x": -3,
            "y": 14,
            "z": 3,
            "elements": [
                "chisel:technical1@4"
            ]
        },
        {
            "x": -2,
            "y": 2,
            "z": 5,
            "elements": [
                "tconevo:metal_block@2"
            ]
        },
        {
            "x": -6,
            "y": 13,
            "z": 14,
            "elements": [
                "contenttweaker:universalforcefieldcontrolblock@0"
            ]
        },
        {
            "x": 6,
            "y": 14,
            "z": 8,
            "elements": [
                "chisel:technical1@4"
            ]
        },
        {
            "x": 3,
            "y": -1,
            "z": 9,
            "elements": [
                "chisel:technical1@4"
            ]
        },
        {
            "x": 6,
            "y": 1,
            "z": 4,
            "elements": [
                "tconevo:metal_block@2"
            ]
        },
        {
            "x": 2,
            "y": 0,
            "z": 0,

            "elements": [
                "modularmachinery:blockmepatternprovider@0",
                "modularmachinery:blockoutputbus",
                "modularmachinery:blockmefluidoutputbus"
            ]
        },
        {
            "x": 6,
            "y": 3,
            "z": 1,
            "elements": [
                "chisel:technical1@4"
            ]
        },
        {
            "x": 3,
            "y": 3,
            "z": 4,
            "elements": [
                "chisel:technical1@4"
            ]
        },
        {
            "x": 1,
            "y": 2,
            "z": 0,
            "elements": [
                "contenttweaker:universalforcefieldcontrolblock@0"
            ]
        },
        {
            "x": -4,
            "y": 4,
            "z": 0,
            "elements": [
                "chisel:technical1@4"
            ]
        },
        {
            "x": -5,
            "y": 0,
            "z": 5,
            "elements": [
                "contenttweaker:crystalmatrixforcefieldcontrolblock@0"
            ]
        },
        {
            "x": -5,
            "y": 6,
            "z": 0,
            "elements": [
                "chisel:technical1@4"
            ]
        },
        {
            "x": 6,
            "y": 2,
            "z": 1,
            "elements": [
                "tconevo:metal_block@2"
            ]
        },
        {
            "x": -7,
            "y": 2,
            "z": 10,
            "elements": [
                "chisel:technical1@4"
            ]
        },
        {
            "x": 3,
            "y": 14,
            "z": 3,
            "elements": [
                "chisel:technical1@4"
            ]
        },
        {
            "x": -4,
            "y": 0,
            "z": 10,
            "elements": [
                "contenttweaker:crystalmatrixforcefieldcontrolblock@0"
            ]
        },
        {
            "x": -2,
            "y": 8,
            "z": 0,
            "elements": [
                "chisel:technical1@4"
            ]
        },
        {
            "x": -3,
            "y": 10,
            "z": 0,
            "elements": [
                "chisel:technical1@4"
            ]
        },
        {
            "x": -7,
            "y": 12,
            "z": 5,
            "elements": [
                "chisel:technical1@4"
            ]
        },
        {
            "x": -3,
            "y": 3,
            "z": 11,
            "elements": [
                "chisel:technical1@4"
            ]
        },
        {
            "x": 0,
            "y": 14,
            "z": 8,
            "elements": [
                "chisel:technical1@4"
            ]
        },
        {
            "x": -7,
            "y": 0,
            "z": 15,
            "elements": [
                "chisel:technical1@4"
            ]
        },
        {
            "x": -2,
            "y": 1,
            "z": 11,
            "elements": [
                "chisel:technical1@4"
            ]
        },
        {
            "x": 6,
            "y": 1,
            "z": 1,
            "elements": [
                "tconevo:metal_block@2"
            ]
        },
        {
            "x": 0,
            "y": -1,
            "z": 11,
            "elements": [
                "chisel:technical1@4"
            ]
        },
        {
            "x": -7,
            "y": -1,
            "z": 1,
            "elements": [
                "chisel:technical1@4"
            ]
        },
        {
            "x": 0,
            "y": 2,
            "z": 5,
            "elements": [
                "tconevo:metal_block@2"
            ]
        },
        {
            "x": 1,
            "y": 14,
            "z": 2,
            "elements": [
                "chisel:technical1@4"
            ]
        },
        {
            "x": -6,
            "y": 14,
            "z": 7,
            "elements": [
                "chisel:technical1@4"
            ]
        },
        {
            "x": -5,
            "y": 2,
            "z": 0,
            "elements": [
                "contenttweaker:universalforcefieldcontrolblock@0"
            ]
        },
        {
            "x": -7,
            "y": 0,
            "z": 5,
            "elements": [
                "chisel:technical1@4"
            ]
        },
        {
            "x": 4,
            "y": 0,
            "z": 0,

            "elements": [
                "modularmachinery:blockmepatternprovider@0",
                "modularmachinery:blockoutputbus",
                "modularmachinery:blockmefluidoutputbus"
            ]
        },
        {
            "x": -3,
            "y": 3,
            "z": 4,
            "elements": [
                "chisel:technical1@4"
            ]
        },
        {
            "x": 2,
            "y": -1,
            "z": 4,
            "elements": [
                "chisel:technical1@4"
            ]
        },
        {
            "x": -7,
            "y": 6,
            "z": 0,
            "elements": [
                "chisel:technical1@4"
            ]
        },
        {
            "x": 2,
            "y": 4,
            "z": 0,
            "elements": [
                "chisel:technical1@4"
            ]
        },
        {
            "x": 0,
            "y": 1,
            "z": 4,
            "elements": [
                "tconevo:metal_block@2"
            ]
        },
        {
            "x": -6,
            "y": 14,
            "z": 5,
            "elements": [
                "chisel:technical1@4"
            ]
        },
        {
            "x": -1,
            "y": 10,
            "z": 0,
            "elements": [
                "chisel:technical1@4"
            ]
        },
        {
            "x": 6,
            "y": 14,
            "z": 14,
            "elements": [
                "chisel:technical1@4"
            ]
        },
        {
            "x": -5,
            "y": 3,
            "z": 11,
            "elements": [
                "chisel:technical1@4"
            ]
        },
        {
            "x": 3,
            "y": 3,
            "z": 7,
            "elements": [
                "chisel:technical1@4"
            ]
        },
        {
            "x": 7,
            "y": 1,
            "z": 9,
            "elements": [
                "tconevo:metal_block@2"
            ]
        },
        {
            "x": -2,
            "y": 3,
            "z": 9,
            "elements": [
                "chisel:technical1@4"
            ]
        },
        {
            "x": -6,
            "y": -1,
            "z": 11,
            "elements": [
                "chisel:technical1@4"
            ]
        },
        {
            "x": 3,
            "y": 2,
            "z": 3,
            "elements": [
                "tconevo:metal_block@2"
            ]
        },
        {
            "x": 2,
            "y": 2,
            "z": 5,
            "elements": [
                "tconevo:metal_block@2"
            ]
        },
        {
            "x": 2,
            "y": 3,
            "z": 12,
            "elements": [
                "chisel:technical1@4"
            ]
        },
        {
            "x": -4,
            "y": -1,
            "z": 4,
            "elements": [
                "chisel:technical1@4"
            ]
        },
        {
            "x": -5,
            "y": 8,
            "z": 15,
            "elements": [
                "chisel:technical1@4"
            ]
        },
        {
            "x": 7,
            "y": 14,
            "z": 2,
            "elements": [
                "chisel:technical1@4"
            ]
        },
        {
            "x": -2,
            "y": 0,

            "elements": [
                "modularmachinery:blockmepatternprovider@0",
                "modularmachinery:blockoutputbus",
                "modularmachinery:blockmefluidoutputbus"
            ]
        },
        {
            "x": 8,
            "y": -1,
            "z": 4,
            "elements": [
                "chisel:technical1@4"
            ]
        },
        {
            "x": 5,
            "y": 2,
            "z": 0,
            "elements": [
                "contenttweaker:universalforcefieldcontrolblock@0"
            ]
        },
        {
            "x": 6,
            "y": 0,
            "z": 7,
            "elements": [
                "contenttweaker:crystalmatrixforcefieldcontrolblock@0"
            ]
        },
        {
            "x": -3,
            "y": 14,
            "z": 6,
            "elements": [
                "chisel:technical1@4"
            ]
        },
        {
            "x": -1,
            "y": 0,
            "z": 5,
            "elements": [
                "contenttweaker:crystalmatrixforcefieldcontrolblock@0"
            ]
        },
        {
            "x": -6,
            "y": 2,
            "z": 1,
            "elements": [
                "tconevo:metal_block@2"
            ]
        },
        {
            "x": -1,
            "y": 6,
            "z": 0,
            "elements": [
                "chisel:technical1@4"
            ]
        },
        {
            "x": 0,
            "y": 0,
            "z": 10,
            "elements": [
                "contenttweaker:crystalmatrixforcefieldcontrolblock@0"
            ]
        },
        {
            "x": -3,
            "y": 2,
            "z": 10,
            "elements": [
                "chisel:technical1@4"
            ]
        },
        {
            "x": 6,
            "y": 0,
            "z": 3,
            "elements": [
                "contenttweaker:crystalmatrixforcefieldcontrolblock@0"
            ]
        },
        {
            "x": -7,
            "y": 10,
            "z": 0,
            "elements": [
                "chisel:technical1@4"
            ]
        },
        {
            "x": -5,
            "y": 4,
            "z": 15,
            "elements": [
                "chisel:technical1@4"
            ]
        },
        {
            "x": -3,
            "y": 0,
            "z": 15,
            "elements": [
                "chisel:technical1@4"
            ]
        },
        {
            "x": -1,
            "y": 2,
            "z": 12,
            "elements": [
                "nuclearcraft:fluid_plasma@0"
            ]
        },
        {
            "x": 2,
            "y": 8,
            "z": 0,
            "elements": [
                "chisel:technical1@4"
            ]
        },
        {
            "x": -6,
            "y": 3,
            "z": 1,
            "elements": [
                "chisel:technical1@4"
            ]
        },
        {
            "x": 6,
            "y": 1,
            "z": 7,
            "elements": [
                "tconevo:metal_block@2"
            ]
        },
        {
            "x": -4,
            "y": 12,
            "z": 0,
            "elements": [
                "chisel:technical1@4"
            ]
        },
        {
            "x": 5,
            "y": -1,
            "z": 6,
            "elements": [
                "chisel:technical1@4"
            ]
        },
        {
            "x": 1,
            "y": -1,
            "z": 12,
            "elements": [
                "chisel:technical1@4"
            ]
        },
        {
            "x": -7,
            "y": 14,
            "z": 0,
            "elements": [
                "chisel:technical1@4"
            ]
        },
        {
            "x": 6,
            "y": 0,
            "z": 6,
            "elements": [
                "contenttweaker:crystalmatrixforcefieldcontrolblock@0"
            ]
        },
        {
            "x": 3,
            "y": 2,
            "z": 6,
            "elements": [
                "tconevo:metal_block@2"
            ]
        },
        {
            "x": 2,
            "y": -1,
            "z": 7,
            "elements": [
                "chisel:technical1@4"
            ]
        },
        {
            "x": 4,
            "y": 14,
            "z": 8,
            "elements": [
                "chisel:technical1@4"
            ]
        },
        {
            "x": 1,
            "y": 1,
            "z": 9,
            "elements": [
                "tconevo:metal_block@2"
            ]
        },
        {
            "x": -6,
            "y": 1,
            "z": 11,
            "elements": [
                "chisel:technical1@4"
            ]
        },
        {
            "x": 0,
            "y": 2,
            "z": 7,
            "elements": [
                "tconevo:metal_block@2"
            ]
        },
        {
            "x": -1,
            "y": 1,
            "z": 12,
            "elements": [
                "chisel:technical1@4"
            ]
        },
        {
            "x": -4,
            "y": -1,
            "z": 11,
            "elements": [
                "chisel:technical1@4"
            ]
        },
        {
            "x": 4,
            "y": 3,
            "z": 9,
            "elements": [
                "chisel:technical1@4"
            ]
        },
        {
            "x": -6,
            "y": 6,
            "z": 15,
            "elements": [
                "chisel:technical1@4"
            ]
        },
        {
            "x": -4,
            "y": 2,
            "z": 5,
            "elements": [
                "tconevo:metal_block@2"
            ]
        },
        {
            "x": -7,
            "y": 4,
            "z": 5,
            "elements": [
                "chisel:technical1@4"
            ]
        },
        {
            "x": 6,
            "y": 1,
            "z": 6,
            "elements": [
                "tconevo:metal_block@2"
            ]
        },
        {
            "x": -6,
            "y": 1,
            "z": 1,
            "elements": [
                "tconevo:metal_block@2"
            ]
        },
        {
            "x": -6,
            "y": 1,
            "z": 4,
            "elements": [
                "tconevo:metal_block@2"
            ]
        },
        {
            "x": -1,
            "y": 0,
            "z": 12,
            "elements": [
                "contenttweaker:crystalmatrixforcefieldcontrolblock@0"
            ]
        },
        {
            "x": 0,
            "y": 1,
            "z": 8,
            "elements": [
                "tconevo:metal_block@2"
            ]
        },
        {
            "x": -5,
            "y": 14,
            "z": 10,
            "elements": [
                "chisel:technical1@4"
            ]
        },
        {
            "x": 5,
            "y": 2,
            "z": 12,
            "elements": [
                "nuclearcraft:fluid_plasma@0"
            ]
        },
        {
            "x": 6,
            "y": 14,
            "z": 12,
            "elements": [
                "chisel:technical1@4"
            ]
        },
        {
            "x": -4,
            "y": 14,
            "z": 15,
            "elements": [
                "chisel:technical1@4"
            ]
        },
        {
            "x": 8,
            "y": 0,
            "z": 0,
            "elements": [
                "chisel:technical1@4"
            ]
        },
        {
            "x": -7,
            "y": 3,
            "z": 4,
            "elements": [
                "chisel:technical1@4"
            ]
        },
        {
            "x": 8,
            "y": 11,
            "z": 12,
            "elements": [
                "chisel:technical1@4"
            ]
        },
        {
            "x": -4,
            "y": 1,
            "z": 4,
            "elements": [
                "tconevo:metal_block@2"
            ]
        },
        {
            "x": 7,
            "y": 2,
            "z": 0,
            "elements": [
                "contenttweaker:universalforcefieldcontrolblock@0"
            ]
        },
        {
            "x": 5,
            "y": 0,
            "z": 5,
            "elements": [
                "contenttweaker:crystalmatrixforcefieldcontrolblock@0"
            ]
        },
        {
            "x": 7,
            "y": 11,
            "z": 15,
            "elements": [
                "chisel:technical1@4"
            ]
        },
        {
            "x": 4,
            "y": 0,
            "z": 3,
            "elements": [
                "contenttweaker:crystalmatrixforcefieldcontrolblock@0"
            ]
        },
        {
            "x": 6,
            "y": 3,
            "z": 13,
            "elements": [
                "chisel:technical1@4"
            ]
        },
        {
            "x": 4,
            "y": 8,
            "z": 0,
            "elements": [
                "chisel:technical1@4"
            ]
        },
        {
            "x": 3,
            "y": 0,
            "z": 8,
            "elements": [
                "contenttweaker:crystalmatrixforcefieldcontrolblock@0"
            ]
        },
        {
            "x": 3,
            "y": 2,
            "z": 10,
            "elements": [
                "chisel:technical1@4"
            ]
        },
        {
            "x": 8,
            "y": -1,
            "z": 14,
            "elements": [
                "chisel:technical1@4"
            ]
        },
        {
            "x": 0,
            "y": 2,
            "z": 8,
            "elements": [
                "tconevo:metal_block@2"
            ]
        },
        {
            "x": -7,
            "y": 5,
            "z": 9,
            "elements": [
                "chisel:technical1@4"
            ]
        },
        {
            "x": 8,
            "y": 1,
            "z": 14,
            "elements": [
                "chisel:technical1@4"
            ]
        },
        {
            "x": 5,
            "y": -1,
            "z": 8,
            "elements": [
                "chisel:technical1@4"
            ]
        },
        {
            "x": 7,
            "y": -1,
            "z": 12,
            "elements": [
                "chisel:technical1@4"
            ]
        },
        {
            "x": 6,
            "y": 2,
            "z": 5,
            "elements": [
                "tconevo:metal_block@2"
            ]
        },
        {
            "x": 0,
            "y": 3,
            "z": 8,
            "elements": [
                "chisel:technical1@4"
            ]
        },
        {
            "x": 5,
            "y": 1,
            "z": 12,
            "elements": [
                "chisel:technical1@4"
            ]
        },
        {
            "x": -1,
            "y": 8,
            "z": 15,
            "elements": [
                "chisel:technical1@4"
            ]
        },
        {
            "x": -5,
            "y": -1,
            "z": 9,
            "elements": [
                "chisel:technical1@4"
            ]
        },
        {
            "x": 6,
            "y": 14,
            "z": 1,
            "elements": [
                "chisel:technical1@4"
            ]
        },
        {
            "x": -3,
            "y": 14,
            "z": 13,
            "elements": [
                "chisel:technical1@4"
            ]
        },
        {
            "x": -1,
            "y": 14,
            "z": 12,
            "elements": [
                "chisel:technical1@4"
            ]
        },
        {
            "x": -6,
            "y": 3,
            "z": 9,
            "elements": [
                "chisel:technical1@4"
            ]
        },
        {
            "x": 5,
            "y": 0,
            "z": 12,
            "elements": [
                "contenttweaker:crystalmatrixforcefieldcontrolblock@0"
            ]
        },
        {
            "x": -5,
            "y": 1,
            "z": 9,
            "elements": [
                "tconevo:metal_block@2"
            ]
        },
        {
            "x": 7,
            "y": 13,
            "z": 15,
            "elements": [
                "chisel:technical1@4"
            ]
        },
        {
            "x": -7,
            "y": 12,
            "z": 15,
            "elements": [
                "chisel:technical1@4"
            ]
        },
        {
            "x": 6,
            "y": 14,
            "z": 11,
            "elements": [
                "chisel:technical1@4"
            ]
        },
        {
            "x": -3,
            "y": 14,
            "z": 10,
            "elements": [
                "chisel:technical1@4"
            ]
        },
        {
            "x": 8,
            "y": 7,
            "z": 12,
            "elements": [
                "chisel:technical1@4"
            ]
        },
        {
            "x": 6,
            "y": 0,
            "z": 13,
            "elements": [
                "contenttweaker:crystalmatrixforcefieldcontrolblock@0"
            ]
        },
        {
            "x": -2,
            "y": 1,
            "z": 4,
            "elements": [
                "tconevo:metal_block@2"
            ]
        },
        {
            "x": -7,
            "y": 7,
            "z": 4,
            "elements": [
                "chisel:technical1@4"
            ]
        },
        {
            "x": 6,
            "y": 1,
            "z": 8,
            "elements": [
                "tconevo:metal_block@2"
            ]
        },
        {
            "x": 5,
            "y": 2,
            "z": 13,
            "elements": [
                "nuclearcraft:fluid_plasma@0"
            ]
        },
        {
            "x": -5,
            "y": 3,
            "z": 4,
            "elements": [
                "chisel:technical1@4"
            ]
        },
        {
            "x": 4,
            "y": 4,
            "z": 0,
            "elements": [
                "chisel:technical1@4"
            ]
        },
        {
            "x": 3,
            "y": 0,
            "z": 5,
            "elements": [
                "contenttweaker:crystalmatrixforcefieldcontrolblock@0"
            ]
        },
        {
            "x": -1,
            "y": 4,
            "z": 15,
            "elements": [
                "chisel:technical1@4"
            ]
        },
        {
            "x": 5,
            "y": -1,
            "z": 13,
            "elements": [
                "chisel:technical1@4"
            ]
        },
        {
            "x": 5,
            "y": 1,
            "z": 13,
            "elements": [
                "chisel:technical1@4"
            ]
        },
        {
            "x": -5,
            "y": 2,
            "z": 3,
            "elements": [
                "tconevo:metal_block@2"
            ]
        },
        {
            "x": -4,
            "y": 14,
            "z": 5,
            "elements": [
                "chisel:technical1@4"
            ]
        },
        {
            "x": 6,
            "y": 2,
            "z": 8,
            "elements": [
                "tconevo:metal_block@2"
            ]
        },
        {
            "x": 6,
            "y": 1,
            "z": 11,
            "elements": [
                "chisel:technical1@4"
            ]
        },
        {
            "x": -7,
            "y": -1,
            "z": 8,
            "elements": [
                "chisel:technical1@4"
            ]
        },
        {
            "x": 4,
            "y": 0,
            "z": 10,
            "elements": [
                "contenttweaker:crystalmatrixforcefieldcontrolblock@0"
            ]
        },
        {
            "x": 1,
            "y": 2,
            "z": 10,
            "elements": [
                "chisel:technical1@4"
            ]
        },
        {
            "x": -6,
            "y": 0,
            "z": 3,
            "elements": [
                "contenttweaker:crystalmatrixforcefieldcontrolblock@0"
            ]
        },
        {
            "x": -1,
            "y": -1,
            "z": 8,
            "elements": [
                "chisel:technical1@4"
            ]
        },
        {
            "x": 0,
            "y": 14,
            "z": 14,
            "elements": [
                "chisel:technical1@4"
            ]
        },
        {
            "x": -7,
            "y": 9,
            "z": 9,
            "elements": [
                "chisel:technical1@4"
            ]
        },
        {
            "x": 8,
            "y": 2,
            "z": 5,
            "elements": [
                "chisel:technical1@4"
            ]
        },
        {
            "x": 7,
            "y": 13,
            "z": 1,
            "elements": [
                "contenttweaker:universalforcefieldcontrolblock@0"
            ]
        },
        {
            "x": 6,
            "y": 3,
            "z": 6,
            "elements": [
                "chisel:technical1@4"
            ]
        },
        {
            "x": -5,
            "y": 14,
            "z": 3,
            "elements": [
                "chisel:technical1@4"
            ]
        },
        {
            "x": 1,
            "y": 2,
            "z": 3,
            "elements": [
                "tconevo:metal_block@2"
            ]
        },
        {
            "x": -3,
            "y": -1,
            "z": 9,
            "elements": [
                "chisel:technical1@4"
            ]
        },
        {
            "x": 4,
            "y": -1,
            "z": 13,
            "elements": [
                "chisel:technical1@4"
            ]
        },
        {
            "x": 6,
            "y": 1,
            "z": 13,
            "elements": [
                "chisel:technical1@4"
            ]
        },
        {
            "x": 8,
            "y": 3,
            "z": 12,
            "elements": [
                "chisel:technical1@4"
            ]
        },
        {
            "x": 6,
            "y": 3,
            "z": 8,
            "elements": [
                "chisel:technical1@4"
            ]
        },
        {
            "x": -2,
            "y": -1,
            "z": 4,
            "elements": [
                "chisel:technical1@4"
            ]
        },
        {
            "x": -5,
            "y": 12,
            "z": 15,
            "elements": [
                "chisel:technical1@4"
            ]
        },
        {
            "x": -3,
            "y": 1,
            "z": 9,
            "elements": [
                "tconevo:metal_block@2"
            ]
        },
        {
            "x": -4,
            "y": 0,

            "elements": [
                "modularmachinery:blockmepatternprovider@0",
                "modularmachinery:blockoutputbus",
                "modularmachinery:blockmefluidoutputbus"
            ]
        },
        {
            "x": -7,
            "y": 2,
            "z": 0,
            "elements": [
                "chisel:technical1@4"
            ]
        },
        {
            "x": -4,
            "y": 10,
            "z": 15,
            "elements": [
                "chisel:technical1@4"
            ]
        },
        {
            "x": 8,
            "y": 0,
            "z": 13,
            "elements": [
                "chisel:technical1@4"
            ]
        },
        {
            "x": 2,
            "y": 14,
            "z": 5,
            "elements": [
                "chisel:technical1@4"
            ]
        },
        {
            "x": 1,
            "y": 6,
            "z": 0,
            "elements": [
                "chisel:technical1@4"
            ]
        },
        {
            "x": -3,
            "y": 2,
            "z": 3,
            "elements": [
                "tconevo:metal_block@2"
            ]
        },
        {
            "x": 3,
            "y": 3,
            "z": 11,
            "elements": [
                "chisel:technical1@4"
            ]
        },
        {
            "x": 0,
            "y": 0,
            "z": 3,
            "elements": [
                "contenttweaker:crystalmatrixforcefieldcontrolblock@0"
            ]
        },
        {
            "x": -2,
            "y": 0,
            "z": 10,
            "elements": [
                "contenttweaker:crystalmatrixforcefieldcontrolblock@0"
            ]
        },
        {
            "x": -4,
            "y": 2,
            "z": 15,
            "elements": [
                "chisel:technical1@4"
            ]
        },
        {
            "x": 0,
            "y": 1,
            "z": 11,
            "elements": [
                "chisel:technical1@4"
            ]
        },
        {
            "x": -7,
            "y": 4,
            "z": 15,
            "elements": [
                "chisel:technical1@4"
            ]
        },
        {
            "x": -7,
            "y": 11,
            "z": 4,
            "elements": [
                "chisel:technical1@4"
            ]
        },
        {
            "x": 2,
            "y": -1,
            "z": 11,
            "elements": [
                "chisel:technical1@4"
            ]
        },
        {
            "x": 3,
            "y": 3,
            "z": 14,
            "elements": [
                "chisel:technical1@4"
            ]
        },
        {
            "x": -2,
            "y": 12,
            "z": 0,
            "elements": [
                "chisel:technical1@4"
            ]
        },
        {
            "x": -1,
            "y": 0,
            "z": 15,
            "elements": [
                "chisel:technical1@4"
            ]
        },
        {
            "x": -5,
            "y": 14,
            "z": 0,
            "elements": [
                "chisel:technical1@4"
            ]
        },
        {
            "x": -4,
            "y": 6,
            "z": 15,
            "elements": [
                "chisel:technical1@4"
            ]
        },
        {
            "x": -7,
            "y": 14,
            "z": 3,
            "elements": [
                "chisel:technical1@4"
            ]
        },
        {
            "x": 6,
            "y": 0,
            "z": 14,
            "elements": [
                "contenttweaker:crystalmatrixforcefieldcontrolblock@0"
            ]
        },
        {
            "x": -6,
            "y": 14,
            "z": 8,
            "elements": [
                "chisel:technical1@4"
            ]
        },
        {
            "x": 8,
            "y": 4,
            "z": 13,
            "elements": [
                "chisel:technical1@4"
            ]
        },
        {
            "x": -6,
            "y": 2,
            "z": 5,
            "elements": [
                "tconevo:metal_block@2"
            ]
        },
        {
            "x": -1,
            "y": 1,
            "z": 9,
            "elements": [
                "tconevo:metal_block@2"
            ]
        },
        {
            "x": 5,
            "y": 3,
            "z": 13,
            "elements": [
                "chisel:technical1@4"
            ]
        },
        {
            "x": -1,
            "y": 3,
            "z": 4,
            "elements": [
                "chisel:technical1@4"
            ]
        },
        {
            "x": 6,
            "y": 14,
            "z": 7,
            "elements": [
                "chisel:technical1@4"
            ]
        },
        {
            "x": 0,
            "y": -1,
            "z": 4,
            "elements": [
                "chisel:technical1@4"
            ]
        },
        {
            "x": 2,
            "y": 1,
            "z": 4,
            "elements": [
                "tconevo:metal_block@2"
            ]
        },
        {
            "x": -1,
            "y": 2,
            "z": 3,
            "elements": [
                "tconevo:metal_block@2"
            ]
        },
        {
            "x": 7,
            "y": 6,
            "z": 0,
            "elements": [
                "chisel:technical1@4"
            ]
        },
        {
            "x": 2,
            "y": -1,
            "z": 14,
            "elements": [
                "chisel:technical1@4"
            ]
        },
        {
            "x": 0,
            "y": 14,
            "z": 12,
            "elements": [
                "chisel:technical1@4"
            ]
        },
        {
            "x": 8,
            "y": 13,
            "z": 5,
            "elements": [
                "chisel:technical1@4"
            ]
        },
        {
            "x": 1,
            "y": 3,
            "z": 11,
            "elements": [
                "chisel:technical1@4"
            ]
        },
        {
            "x": -2,
            "y": 0,
            "z": 3,
            "elements": [
                "contenttweaker:crystalmatrixforcefieldcontrolblock@0"
            ]
        },
        {
            "x": 5,
            "y": 0,
            "z": 15,
            "elements": [
                "chisel:technical1@4"
            ]
        },
        {
            "x": 2,
            "y": 2,
            "z": 15,
            "elements": [
                "chisel:technical1@4"
            ]
        },
        {
            "x": 1,
            "y": 10,
            "z": 0,
            "elements": [
                "chisel:technical1@4"
            ]
        },
        {
            "x": -7,
            "y": 10,
            "z": 3,
            "elements": [
                "chisel:technical1@4"
            ]
        },
        {
            "x": 7,
            "y": 10,
            "z": 0,
            "elements": [
                "chisel:technical1@4"
            ]
        },
        {
            "x": 6,
            "y": 1,
            "z": 14,
            "elements": [
                "chisel:technical1@4"
            ]
        },
        {
            "x": -4,
            "y": 3,
            "z": 9,
            "elements": [
                "chisel:technical1@4"
            ]
        },
        {
            "x": 5,
            "y": 14,
            "z": 12,
            "elements": [
                "chisel:technical1@4"
            ]
        },
        {
            "x": 4,
            "y": 12,
            "z": 0,
            "elements": [
                "chisel:technical1@4"
            ]
        },
        {
            "x": -7,
            "y": 8,
            "z": 15,
            "elements": [
                "chisel:technical1@4"
            ]
        },
        {
            "x": 1,
            "y": 14,
            "z": 0,
            "elements": [
                "chisel:technical1@4"
            ]
        },
        {
            "x": 3,
            "y": 14,
            "z": 13,
            "elements": [
                "chisel:technical1@4"
            ]
        },
        {
            "x": 2,
            "y": 6,
            "z": 15,
            "elements": [
                "chisel:technical1@4"
            ]
        },
        {
            "x": -6,
            "y": -1,
            "z": 4,
            "elements": [
                "chisel:technical1@4"
            ]
        },
        {
            "x": 6,
            "y": 2,
            "z": 14,
            "elements": [
                "nuclearcraft:fluid_plasma@0"
            ]
        },
        {
            "x": -7,
            "y": -1,
            "z": 2,
            "elements": [
                "chisel:technical1@4"
            ]
        },
        {
            "x": 4,
            "y": 14,
            "z": 1,
            "elements": [
                "chisel:technical1@4"
            ]
        },
        {
            "x": 1,
            "y": -1,
            "z": 9,
            "elements": [
                "chisel:technical1@4"
            ]
        },
        {
            "x": -7,
            "y": 1,
            "z": 9,
            "elements": [
                "chisel:technical1@4"
            ]
        },
        {
            "x": 8,
            "y": 11,
            "z": 5,
            "elements": [
                "chisel:technical1@4"
            ]
        },
        {
            "x": 1,
            "y": 3,
            "z": 4,
            "elements": [
                "chisel:technical1@4"
            ]
        },
        {
            "x": 4,
            "y": 1,
            "z": 4,
            "elements": [
                "tconevo:metal_block@2"
            ]
        },
        {
            "x": 3,
            "y": 14,
            "z": 10,
            "elements": [
                "chisel:technical1@4"
            ]
        },
        {
            "x": 7,
            "y": 2,
            "z": 11,
            "elements": [
                "nuclearcraft:fluid_plasma@0"
            ]
        },
        {
            "x": 5,
            "y": -1,
            "z": 15,
            "elements": [
                "chisel:technical1@4"
            ]
        },
        {
            "x": -7,
            "y": 12,
            "z": 8,
            "elements": [
                "chisel:technical1@4"
            ]
        },
        {
            "x": 6,
            "y": -1,
            "z": 4,
            "elements": [
                "chisel:technical1@4"
            ]
        },
        {
            "x": 7,
            "y": 0,
            "z": 4,
            "elements": [
                "contenttweaker:crystalmatrixforcefieldcontrolblock@0"
            ]
        },
        {
            "x": 7,
            "y": 3,
            "z": 11,
            "elements": [
                "chisel:technical1@4"
            ]
        },
        {
            "x": -7,
            "y": 10,
            "z": 6,
            "elements": [
                "chisel:technical1@4"
            ]
        },
        {
            "x": 8,
            "y": 13,
            "z": 0,
            "elements": [
                "chisel:technical1@4"
            ]
        },
        {
            "x": 4,
            "y": 1,
            "z": 11,
            "elements": [
                "chisel:technical1@4"
            ]
        },
        {
            "x": -1,
            "y": 3,
            "z": 7,
            "elements": [
                "chisel:technical1@4"
            ]
        },
        {
            "x": -1,
            "y": 3,
            "z": 14,
            "elements": [
                "chisel:technical1@4"
            ]
        },
        {
            "x": 8,
            "y": 4,
            "z": 6,
            "elements": [
                "chisel:technical1@4"
            ]
        },
        {
            "x": 2,
            "y": 1,
            "z": 14,
            "elements": [
                "chisel:technical1@4"
            ]
        },
        {
            "x": 8,
            "y": 1,
            "z": 7,
            "elements": [
                "chisel:technical1@4"
            ]
        },
        {
            "x": 7,
            "y": 4,
            "z": 1,
            "elements": [
                "contenttweaker:universalforcefieldcontrolblock@0"
            ]
        },
        {
            "x": 6,
            "y": 1,
            "z": 15,
            "elements": [
                "chisel:technical1@4"
            ]
        },
        {
            "x": -1,
            "y": -1,
            "z": 12,
            "elements": [
                "chisel:technical1@4"
            ]
        },
        {
            "x": 8,
            "y": 0,
            "z": 6,
            "elements": [
                "chisel:technical1@4"
            ]
        },
        {
            "x": 5,
            "y": 2,
            "z": 6,
            "elements": [
                "tconevo:metal_block@2"
            ]
        },
        {
            "x": 3,
            "y": 1,
            "z": 9,
            "elements": [
                "tconevo:metal_block@2"
            ]
        },
        {
            "x": -3,
            "y": 1,
            "z": 12,
            "elements": [
                "chisel:technical1@4"
            ]
        },
        {
            "x": 7,
            "y": 14,
            "z": 7,
            "elements": [
                "chisel:technical1@4"
            ]
        },
        {
            "x": 7,
            "y": 0,
            "z": 11,
            "elements": [
                "contenttweaker:crystalmatrixforcefieldcontrolblock@0"
            ]
        },
        {
            "x": 3,
            "y": 1,
            "z": 2,
            "elements": [
                "tconevo:metal_block@2"
            ]
        },
        {
            "x": -2,
            "y": 14,
            "z": 1,
            "elements": [
                "chisel:technical1@4"
            ]
        },
        {
            "x": -6,
            "y": 3,
            "z": 2,
            "elements": [
                "chisel:technical1@4"
            ]
        },
        {
            "x": -5,
            "y": 0,
            "z": 8,
            "elements": [
                "contenttweaker:crystalmatrixforcefieldcontrolblock@0"
            ]
        },
        {
            "x": 7,
            "y": 2,
            "z": 4,
            "elements": [
                "tconevo:metal_block@2"
            ]
        },
        {
            "x": -5,
            "y": -1,
            "z": 2,
            "elements": [
                "chisel:technical1@4"
            ]
        },
        {
            "x": 6,
            "y": 3,
            "z": 12,
            "elements": [
                "chisel:technical1@4"
            ]
        },
        {
            "x": -3,
            "y": 2,
            "z": 13,
            "elements": [
                "nuclearcraft:fluid_plasma@0"
            ]
        },
        {
            "x": 6,
            "y": 3,
            "z": 15,
            "elements": [
                "chisel:technical1@4"
            ]
        },
        {
            "x": 7,
            "y": 0,
            "z": 1,
            "elements": [
                "contenttweaker:crystalmatrixforcefieldcontrolblock@0"
            ]
        },
        {
            "x": -7,
            "y": 14,
            "z": 6,
            "elements": [
                "chisel:technical1@4"
            ]
        },
        {
            "x": 4,
            "y": 14,
            "z": 5,
            "elements": [
                "chisel:technical1@4"
            ]
        },
        {
            "x": -2,
            "y": 2,
            "z": 8,
            "elements": [
                "tconevo:metal_block@2"
            ]
        },
        {
            "x": 6,
            "y": 2,
            "z": 15,
            "elements": [
                "chisel:technical1@4"
            ]
        },
        {
            "x": -2,
            "y": -1,
            "z": 14,
            "elements": [
                "chisel:technical1@4"
            ]
        },
        {
            "x": 8,
            "y": 9,
            "z": 0,
            "elements": [
                "chisel:technical1@4"
            ]
        },
        {
            "x": 1,
            "y": 0,
            "z": 8,
            "elements": [
                "contenttweaker:crystalmatrixforcefieldcontrolblock@0"
            ]
        },
        {
            "x": 0,
            "y": 2,
            "z": 9,
            "elements": [
                "tconevo:metal_block@2"
            ]
        },
        {
            "x": 2,
            "y": 1,
            "z": 7,
            "elements": [
                "tconevo:metal_block@2"
            ]
        },
        {
            "x": 6,
            "y": -1,
            "z": 11,
            "elements": [
                "chisel:technical1@4"
            ]
        },
        {
            "x": 6,
            "y": 6,
            "z": 15,
            "elements": [
                "chisel:technical1@4"
            ]
        },
        {
            "x": 0,
            "y": 3,
            "z": 9,
            "elements": [
                "chisel:technical1@4"
            ]
        },
        {
            "x": 0,
            "y": 3,
            "z": 2,
            "elements": [
                "chisel:technical1@4"
            ]
        },
        {
            "x": -4,
            "y": 1,
            "z": 7,
            "elements": [
                "tconevo:metal_block@2"
            ]
        },
        {
            "x": -7,
            "y": 3,
            "z": 7,
            "elements": [
                "chisel:technical1@4"
            ]
        },
        {
            "x": 7,
            "y": 2,
            "z": 10,
            "elements": [
                "chisel:technical1@4"
            ]
        },
        {
            "x": 6,
            "y": 5,
            "z": 15,
            "elements": [
                "chisel:technical1@4"
            ]
        },
        {
            "x": 0,
            "y": 3,
            "z": 12,
            "elements": [
                "chisel:technical1@4"
            ]
        },
        {
            "x": 5,
            "y": -1,
            "z": 2,
            "elements": [
                "chisel:technical1@4"
            ]
        },
        {
            "x": 5,
            "y": 14,
            "z": 0,
            "elements": [
                "chisel:technical1@4"
            ]
        },
        {
            "x": 5,
            "y": -1,
            "z": 12,
            "elements": [
                "chisel:technical1@4"
            ]
        },
        {
            "x": 8,
            "y": 12,
            "z": 0,
            "elements": [
                "chisel:technical1@4"
            ]
        },
        {
            "x": 3,
            "y": 1,
            "z": 12,
            "elements": [
                "chisel:technical1@4"
            ]
        },
        {
            "x": -3,
            "y": 1,
            "z": 2,
            "elements": [
                "tconevo:metal_block@2"
            ]
        },
        {
            "x": 2,
            "y": 0,
            "z": 6,
            "elements": [
                "contenttweaker:crystalmatrixforcefieldcontrolblock@0"
            ]
        },
        {
            "x": -1,
            "y": 2,
            "z": 6,
            "elements": [
                "tconevo:metal_block@2"
            ]
        },
        {
            "x": -2,
            "y": -1,
            "z": 7,
            "elements": [
                "chisel:technical1@4"
            ]
        },
        {
            "x": 0,
            "y": 14,
            "z": 1,
            "elements": [
                "chisel:technical1@4"
            ]
        },
        {
            "x": 7,
            "y": 3,
            "z": 10,
            "elements": [
                "chisel:technical1@4"
            ]
        },
        {
            "x": 8,
            "y": 11,
            "z": 0,
            "elements": [
                "chisel:technical1@4"
            ]
        },
        {
            "x": 6,
            "y": 0,
            "z": 9,
            "elements": [
                "contenttweaker:crystalmatrixforcefieldcontrolblock@0"
            ]
        },
        {
            "x": 5,
            "y": -1,
            "z": 9,
            "elements": [
                "chisel:technical1@4"
            ]
        },
        {
            "x": -1,
            "y": 14,
            "z": 13,
            "elements": [
                "chisel:technical1@4"
            ]
        },
        {
            "x": 3,
            "y": 2,
            "z": 13,
            "elements": [
                "nuclearcraft:fluid_plasma@0"
            ]
        },
        {
            "x": -1,
            "y": 14,
            "z": 6,
            "elements": [
                "chisel:technical1@4"
            ]
        },
        {
            "x": 6,
            "y": 1,
            "z": 10,
            "elements": [
                "chisel:technical1@4"
            ]
        },
        {
            "x": 8,
            "y": 7,
            "z": 0,
            "elements": [
                "chisel:technical1@4"
            ]
        },
        {
            "x": 1,
            "y": 0,
            "z": 1,
            "elements": [
                "contenttweaker:crystalmatrixforcefieldcontrolblock@0"
            ]
        },
        {
            "x": 1,
            "y": 14,
            "z": 3,
            "elements": [
                "chisel:technical1@4"
            ]
        },
        {
            "x": -4,
            "y": 2,
            "z": 8,
            "elements": [
                "tconevo:metal_block@2"
            ]
        },
        {
            "x": -1,
            "y": 0,
            "z": 8,
            "elements": [
                "contenttweaker:crystalmatrixforcefieldcontrolblock@0"
            ]
        },
        {
            "x": 6,
            "y": 3,
            "z": 10,
            "elements": [
                "chisel:technical1@4"
            ]
        },
        {
            "x": 4,
            "y": 2,
            "z": 1,
            "elements": [
                "tconevo:metal_block@2"
            ]
        },
        {
            "x": -7,
            "y": 9,
            "z": 2,
            "elements": [
                "chisel:technical1@4"
            ]
        },
        {
            "x": 4,
            "y": -1,
            "z": 14,
            "elements": [
                "chisel:technical1@4"
            ]
        },
        {
            "x": 0,
            "y": 0,
            "z": 13,
            "elements": [
                "contenttweaker:crystalmatrixforcefieldcontrolblock@0"
            ]
        },
        {
            "x": 6,
            "y": 0,
            "z": 10,
            "elements": [
                "contenttweaker:crystalmatrixforcefieldcontrolblock@0"
            ]
        },
        {
            "x": 8,
            "y": 8,
            "z": 0,
            "elements": [
                "chisel:technical1@4"
            ]
        },
        {
            "x": 1,
            "y": 14,
            "z": 4,
            "elements": [
                "chisel:technical1@4"
            ]
        },
        {
            "x": -7,
            "y": 4,
            "z": 8,
            "elements": [
                "chisel:technical1@4"
            ]
        },
        {
            "x": 8,
            "y": -1,
            "z": 11,
            "elements": [
                "chisel:technical1@4"
            ]
        },
        {
            "x": 5,
            "y": 10,
            "z": 0,
            "elements": [
                "chisel:technical1@4"
            ]
        },
        {
            "x": -7,
            "y": 7,
            "z": 14,
            "elements": [
                "chisel:technical1@4"
            ]
        },
        {
            "x": 4,
            "y": -1,
            "z": 7,
            "elements": [
                "chisel:technical1@4"
            ]
        },
        {
            "x": -7,
            "y": 14,
            "z": 13,
            "elements": [
                "chisel:technical1@4"
            ]
        },
        {
            "x": 8,
            "y": 5,
            "z": 0,
            "elements": [
                "chisel:technical1@4"
            ]
        },
        {
            "x": -2,
            "y": 3,
            "z": 2,
            "elements": [
                "chisel:technical1@4"
            ]
        },
        {
            "x": 0,
            "y": 0,
            "z": 9,
            "elements": [
                "contenttweaker:crystalmatrixforcefieldcontrolblock@0"
            ]
        },
        {
            "x": 7,
            "y": 1,
            "z": 10,
            "elements": [
                "chisel:technical1@4"
            ]
        },
        {
            "x": -1,
            "y": 1,
            "z": 2,
            "elements": [
                "tconevo:metal_block@2"
            ]
        },
        {
            "x": 1,
            "y": 14,
            "z": 11,
            "elements": [
                "chisel:technical1@4"
            ]
        },
        {
            "x": -1,
            "y": -1,
            "z": 2,
            "elements": [
                "chisel:technical1@4"
            ]
        },
        {
            "x": 7,
            "y": 14,
            "z": 10,
            "elements": [
                "chisel:technical1@4"
            ]
        },
        {
            "x": 5,
            "y": 14,
            "z": 14,
            "elements": [
                "chisel:technical1@4"
            ]
        },
        {
            "x": -1,
            "y": -1,
            "z": 9,
            "elements": [
                "chisel:technical1@4"
            ]
        },
        {
            "x": 8,
            "y": 3,
            "z": 0,
            "elements": [
                "chisel:technical1@4"
            ]
        },
        {
            "x": -7,
            "y": 8,
            "z": 8,
            "elements": [
                "chisel:technical1@4"
            ]
        },
        {
            "x": 2,
            "y": 0,
            "z": 13,
            "elements": [
                "contenttweaker:crystalmatrixforcefieldcontrolblock@0"
            ]
        },
        {
            "x": 1,
            "y": 14,
            "z": 10,
            "elements": [
                "chisel:technical1@4"
            ]
        },
        {
            "x": -5,
            "y": 0,
            "z": 1,
            "elements": [
                "contenttweaker:crystalmatrixforcefieldcontrolblock@0"
            ]
        },
        {
            "x": 5,
            "y": 3,
            "z": 7,
            "elements": [
                "chisel:technical1@4"
            ]
        },
        {
            "x": -3,
            "y": 0,
            "z": 8,
            "elements": [
                "contenttweaker:crystalmatrixforcefieldcontrolblock@0"
            ]
        },
        {
            "x": 8,
            "y": 4,
            "z": 0,
            "elements": [
                "chisel:technical1@4"
            ]
        },
        {
            "x": -5,
            "y": 14,
            "z": 4,
            "elements": [
                "chisel:technical1@4"
            ]
        },
        {
            "x": -6,
            "y": 2,
            "z": 8,
            "elements": [
                "tconevo:metal_block@2"
            ]
        },
        {
            "x": 7,
            "y": 3,
            "z": 4,
            "elements": [
                "chisel:technical1@4"
            ]
        },
        {
            "x": -6,
            "y": 0,
            "z": 9,
            "elements": [
                "contenttweaker:crystalmatrixforcefieldcontrolblock@0"
            ]
        },
        {
            "x": 6,
            "y": -1,
            "z": 3,
            "elements": [
                "chisel:technical1@4"
            ]
        },
        {
            "x": -7,
            "y": 11,
            "z": 14,
            "elements": [
                "chisel:technical1@4"
            ]
        },
        {
            "x": 5,
            "y": 3,
            "z": 14,
            "elements": [
                "chisel:technical1@4"
            ]
        },
        {
            "x": -4,
            "y": 3,
            "z": 2,
            "elements": [
                "chisel:technical1@4"
            ]
        },
        {
            "x": 1,
            "y": 1,
            "z": 2,
            "elements": [
                "tconevo:metal_block@2"
            ]
        },
        {
            "x": 1,
            "y": -1,
            "z": 2,
            "elements": [
                "chisel:technical1@4"
            ]
        },
        {
            "x": 5,
            "y": -1,
            "z": 10,
            "elements": [
                "chisel:technical1@4"
            ]
        },
        {
            "x": -7,
            "y": -1,
            "z": 9,
            "elements": [
                "chisel:technical1@4"
            ]
        },
        {
            "x": 8,
            "y": 1,
            "z": 0,
            "elements": [
                "chisel:technical1@4"
            ]
        },
        {
            "x": 0,
            "y": 3,
            "z": 15,
            "elements": [
                "chisel:technical1@4"
            ]
        },
        {
            "x": -3,
            "y": 0,
            "z": 1,
            "elements": [
                "contenttweaker:crystalmatrixforcefieldcontrolblock@0"
            ]
        },
        {
            "x": -1,
            "y": 2,
            "z": 13,
            "elements": [
                "nuclearcraft:fluid_plasma@0"
            ]
        },
        {
            "x": -5,
            "y": 14,
            "z": 6,
            "elements": [
                "chisel:technical1@4"
            ]
        },
        {
            "x": -2,
            "y": 14,
            "z": 5,
            "elements": [
                "chisel:technical1@4"
            ]
        },
        {
            "x": 0,
            "y": 2,
            "z": 1,
            "elements": [
                "tconevo:metal_block@2"
            ]
        },
        {
            "x": -7,
            "y": 6,
            "z": 13,
            "elements": [
                "chisel:technical1@4"
            ]
        },
        {
            "x": -3,
            "y": 4,
            "z": 15,
            "elements": [
                "chisel:technical1@4"
            ]
        },
        {
            "x": 5,
            "y": 6,
            "z": 0,
            "elements": [
                "chisel:technical1@4"
            ]
        },
        {
            "x": -6,
            "y": 1,
            "z": 14,
            "elements": [
                "chisel:technical1@4"
            ]
        },
        {
            "x": -4,
            "y": 0,
            "z": 13,
            "elements": [
                "contenttweaker:crystalmatrixforcefieldcontrolblock@0"
            ]
        },
        {
            "x": -6,
            "y": 7,
            "z": 15,
            "elements": [
                "chisel:technical1@4"
            ]
        },
        {
            "x": 3,
            "y": 0,
            "z": 15,
            "elements": [
                "chisel:technical1@4"
            ]
        },
        {
            "x": -7,
            "y": 8,
            "z": 1,
            "elements": [
                "chisel:technical1@4"
            ]
        },
        {
            "x": 0,
            "y": 2,
            "z": 15,
            "elements": [
                "chisel:technical1@4"
            ]
        },
        {
            "x": -1,
            "y": 14,
            "z": 0,
            "elements": [
                "chisel:technical1@4"
            ]
        },
        {
            "x": -7,
            "y": 12,
            "z": 1,
            "elements": [
                "chisel:technical1@4"
            ]
        },
        {
            "x": 2,
            "y": 12,
            "z": 0,
            "elements": [
                "chisel:technical1@4"
            ]
        },
        {
            "x": -6,
            "y": 1,
            "z": 7,
            "elements": [
                "tconevo:metal_block@2"
            ]
        },
        {
            "x": 0,
            "y": -1,
            "z": 7,
            "elements": [
                "chisel:technical1@4"
            ]
        },
        {
            "x": -2,
            "y": 14,
            "z": 8,
            "elements": [
                "chisel:technical1@4"
            ]
        },
        {
            "x": -6,
            "y": 9,
            "z": 15,
            "elements": [
                "chisel:technical1@4"
            ]
        },
        {
            "x": 2,
            "y": 9,
            "z": 0,
            "elements": [
                "chisel:technical1@4"
            ]
        },
        {
            "x": 7,
            "y": 2,
            "z": 3,
            "elements": [
                "tconevo:metal_block@2"
            ]
        },
        {
            "x": 0,
            "y": 0,
            "z": 6,
            "elements": [
                "contenttweaker:crystalmatrixforcefieldcontrolblock@0"
            ]
        },
        {
            "x": -3,
            "y": 2,
            "z": 6,
            "elements": [
                "tconevo:metal_block@2"
            ]
        },
        {
            "x": 3,
            "y": -1,
            "z": 2,
            "elements": [
                "chisel:technical1@4"
            ]
        },
        {
            "x": -2,
            "y": 3,
            "z": 12,
            "elements": [
                "chisel:technical1@4"
            ]
        },
        {
            "x": -6,
            "y": 10,
            "z": 15,
            "elements": [
                "chisel:technical1@4"
            ]
        },
        {
            "x": 2,
            "y": 11,
            "z": 0,
            "elements": [
                "chisel:technical1@4"
            ]
        },
        {
            "x": -5,
            "y": 1,
            "z": 2,
            "elements": [
                "tconevo:metal_block@2"
            ]
        },
        {
            "x": -1,
            "y": -1,
            "z": 15,
            "elements": [
                "chisel:technical1@4"
            ]
        },
        {
            "x": 0,
            "y": 6,
            "z": 15,
            "elements": [
                "chisel:technical1@4"
            ]
        },
        {
            "x": 0,
            "y": 5,
            "z": 15,
            "elements": [
                "chisel:technical1@4"
            ]
        },
        {
            "x": -7,
            "y": 9,
            "z": 12,
            "elements": [
                "chisel:technical1@4"
            ]
        },
        {
            "x": 7,
            "y": 1,
            "z": 3,
            "elements": [
                "tconevo:metal_block@2"
            ]
        },
        {
            "x": -1,
            "y": 0,
            "z": 1,
            "elements": [
                "contenttweaker:crystalmatrixforcefieldcontrolblock@0"
            ]
        },
        {
            "x": -7,
            "y": 13,
            "z": 12,
            "elements": [
                "chisel:technical1@4"
            ]
        },
        {
            "x": -6,
            "y": 14,
            "z": 15,
            "elements": [
                "chisel:technical1@4"
            ]
        },
        {
            "x": 7,
            "y": 14,
            "z": 4,
            "elements": [
                "chisel:technical1@4"
            ]
        },
        {
            "x": -2,
            "y": 2,
            "z": 1,
            "elements": [
                "tconevo:metal_block@2"
            ]
        },
        {
            "x": -6,
            "y": 11,
            "z": 15,
            "elements": [
                "chisel:technical1@4"
            ]
        },
        {
            "x": 2,
            "y": 13,
            "z": 0,
            "elements": [
                "chisel:technical1@4"
            ]
        },
        {
            "x": 7,
            "y": 3,
            "z": 3,
            "elements": [
                "chisel:technical1@4"
            ]
        },
        {
            "x": -4,
            "y": 1,
            "z": 14,
            "elements": [
                "chisel:technical1@4"
            ]
        },
        {
            "x": -7,
            "y": 3,
            "z": 14,
            "elements": [
                "chisel:technical1@4"
            ]
        },
        {
            "x": 1,
            "y": 3,
            "z": 7,
            "elements": [
                "chisel:technical1@4"
            ]
        },
        {
            "x": 1,
            "y": 14,
            "z": 9,
            "elements": [
                "chisel:technical1@4"
            ]
        },
        {
            "x": -3,
            "y": -1,
            "z": 12,
            "elements": [
                "chisel:technical1@4"
            ]
        },
        {
            "x": 7,
            "y": 14,
            "z": 11,
            "elements": [
                "chisel:technical1@4"
            ]
        },
        {
            "x": -5,
            "y": 1,
            "z": 12,
            "elements": [
                "chisel:technical1@4"
            ]
        },
        {
            "x": -6,
            "y": 13,
            "z": 15,
            "elements": [
                "chisel:technical1@4"
            ]
        },
        {
            "x": 0,
            "y": 1,
            "z": 15,
            "elements": [
                "chisel:technical1@4"
            ]
        },
        {
            "x": -7,
            "y": 0,
            "z": 8,
            "elements": [
                "chisel:technical1@4"
            ]
        },
        {
            "x": -3,
            "y": -1,
            "z": 2,
            "elements": [
                "chisel:technical1@4"
            ]
        },
        {
            "x": -7,
            "y": 10,
            "z": 13,
            "elements": [
                "chisel:technical1@4"
            ]
        },
        {
            "x": 6,
            "y": 14,
            "z": 9,
            "elements": [
                "chisel:technical1@4"
            ]
        },
        {
            "x": -3,
            "y": 8,
            "z": 15,
            "elements": [
                "chisel:technical1@4"
            ]
        },
        {
            "x": -6,
            "y": 0,
            "z": 6,
            "elements": [
                "contenttweaker:crystalmatrixforcefieldcontrolblock@0"
            ]
        },
        {
            "x": 3,
            "y": 12,
            "z": 15,
            "elements": [
                "chisel:technical1@4"
            ]
        },
        {
            "x": 0,
            "y": 14,
            "z": 15,
            "elements": [
                "chisel:technical1@4"
            ]
        },
        {
            "x": 6,
            "y": 10,
            "z": 15,
            "elements": [
                "chisel:technical1@4"
            ]
        },
        {
            "x": -7,
            "y": 0,
            "z": 1,
            "elements": [
                "chisel:technical1@4"
            ]
        },
        {
            "x": 1,
            "y": 0,
            "z": 5,
            "elements": [
                "contenttweaker:crystalmatrixforcefieldcontrolblock@0"
            ]
        },
        {
            "x": 0,
            "y": 11,
            "z": 15,
            "elements": [
                "chisel:technical1@4"
            ]
        },
        {
            "x": 6,
            "y": 7,
            "z": 15,
            "elements": [
                "chisel:technical1@4"
            ]
        },
        {
            "x": -4,
            "y": 2,
            "z": 1,
            "elements": [
                "tconevo:metal_block@2"
            ]
        },
        {
            "x": 0,
            "y": 13,
            "z": 15,
            "elements": [
                "chisel:technical1@4"
            ]
        },
        {
            "x": -4,
            "y": -1,
            "z": 14,
            "elements": [
                "chisel:technical1@4"
            ]
        },
        {
            "x": 7,
            "y": 14,
            "z": 9,
            "elements": [
                "chisel:technical1@4"
            ]
        },
        {
            "x": -7,
            "y": 7,
            "z": 7,
            "elements": [
                "chisel:technical1@4"
            ]
        },
        {
            "x": -5,
            "y": 2,
            "z": 13,
            "elements": [
                "nuclearcraft:fluid_plasma@0"
            ]
        },
        {
            "x": 4,
            "y": 2,
            "z": 8,
            "elements": [
                "tconevo:metal_block@2"
            ]
        },
        {
            "x": 7,
            "y": 0,
            "z": 8,
            "elements": [
                "contenttweaker:crystalmatrixforcefieldcontrolblock@0"
            ]
        },
        {
            "x": 1,
            "y": 1,
            "z": 5,
            "elements": [
                "tconevo:metal_block@2"
            ]
        },
        {
            "x": 6,
            "y": 2,
            "z": 9,
            "elements": [
                "tconevo:metal_block@2"
            ]
        },
        {
            "x": -5,
            "y": -1,
            "z": 12,
            "elements": [
                "chisel:technical1@4"
            ]
        },
        {
            "x": -7,
            "y": 1,
            "z": 12,
            "elements": [
                "chisel:technical1@4"
            ]
        },
        {
            "x": 6,
            "y": 3,
            "z": 2,
            "elements": [
                "chisel:technical1@4"
            ]
        },
        {
            "x": -2,
            "y": 1,
            "z": 7,
            "elements": [
                "tconevo:metal_block@2"
            ]
        },
        {
            "x": 6,
            "y": 9,
            "z": 15,
            "elements": [
                "chisel:technical1@4"
            ]
        },
        {
            "x": -5,
            "y": 3,
            "z": 7,
            "elements": [
                "chisel:technical1@4"
            ]
        },
        {
            "x": 7,
            "y": 1,
            "z": 2,
            "elements": [
                "tconevo:metal_block@2"
            ]
        },
        {
            "x": -7,
            "y": 2,
            "z": 6,
            "elements": [
                "chisel:technical1@4"
            ]
        },
        {
            "x": -6,
            "y": 3,
            "z": 12,
            "elements": [
                "chisel:technical1@4"
            ]
        },
        {
            "x": -6,
            "y": 14,
            "z": 1,
            "elements": [
                "chisel:technical1@4"
            ]
        },
        {
            "x": -4,
            "y": -1,
            "z": 7,
            "elements": [
                "chisel:technical1@4"
            ]
        },
        {
            "x": 6,
            "y": 3,
            "z": 9,
            "elements": [
                "chisel:technical1@4"
            ]
        },
        {
            "x": 7,
            "y": 3,
            "z": 5,
            "elements": [
                "chisel:technical1@4"
            ]
        },
        {
            "x": -4,
            "y": 0,
            "z": 6,
            "elements": [
                "contenttweaker:crystalmatrixforcefieldcontrolblock@0"
            ]
        },
        {
            "x": -3,
            "y": 12,
            "z": 15,
            "elements": [
                "chisel:technical1@4"
            ]
        },
        {
            "x": 0,
            "y": -1,
            "z": 5,
            "elements": [
                "chisel:technical1@4"
            ]
        },
        {
            "x": 0,
            "y": 14,
            "z": 9,
            "elements": [
                "chisel:technical1@4"
            ]
        },
        {
            "x": 3,
            "y": 8,
            "z": 15,
            "elements": [
                "chisel:technical1@4"
            ]
        },
        {
            "x": 6,
            "y": 14,
            "z": 15,
            "elements": [
                "chisel:technical1@4"
            ]
        },
        {
            "x": 0,
            "y": 7,
            "z": 15,
            "elements": [
                "chisel:technical1@4"
            ]
        },
        {
            "x": 7,
            "y": 1,
            "z": 5,
            "elements": [
                "tconevo:metal_block@2"
            ]
        },
        {
            "x": -7,
            "y": 4,
            "z": 1,
            "elements": [
                "chisel:technical1@4"
            ]
        },
        {
            "x": -7,
            "y": 11,
            "z": 7,
            "elements": [
                "chisel:technical1@4"
            ]
        },
        {
            "x": 3,
            "y": 0,
            "z": 1,
            "elements": [
                "contenttweaker:crystalmatrixforcefieldcontrolblock@0"
            ]
        },
        {
            "x": 3,
            "y": 4,
            "z": 15,
            "elements": [
                "chisel:technical1@4"
            ]
        },
        {
            "x": 7,
            "y": 0,
            "z": 5,
            "elements": [
                "contenttweaker:crystalmatrixforcefieldcontrolblock@0"
            ]
        },
        {
            "x": -3,
            "y": 3,
            "z": 14,
            "elements": [
                "chisel:technical1@4"
            ]
        },
        {
            "x": 2,
            "y": 2,
            "z": 1,
            "elements": [
                "tconevo:metal_block@2"
            ]
        },
        {
            "x": -7,
            "y": 2,
            "z": 13,
            "elements": [
                "chisel:technical1@4"
            ]
        },
        {
            "x": 7,
            "y": 14,
            "z": 3,
            "elements": [
                "chisel:technical1@4"
            ]
        },
        {
            "x": -3,
            "y": 3,
            "z": 7,
            "elements": [
                "chisel:technical1@4"
            ]
        },
        {
            "x": 5,
            "y": 0,
            "z": 8,
            "elements": [
                "contenttweaker:crystalmatrixforcefieldcontrolblock@0"
            ]
        },
        {
            "x": -6,
            "y": 0,
            "z": 13,
            "elements": [
                "contenttweaker:crystalmatrixforcefieldcontrolblock@0"
            ]
        },
        {
            "x": 0,
            "y": 1,
            "z": 14,
            "elements": [
                "chisel:technical1@4"
            ]
        },
        {
            "x": 2,
            "y": 2,
            "z": 8,
            "elements": [
                "tconevo:metal_block@2"
            ]
        },
        {
            "x": -7,
            "y": -1,
            "z": 12,
            "elements": [
                "chisel:technical1@4"
            ]
        },
        {
            "x": 6,
            "y": 13,
            "z": 15,
            "elements": [
                "chisel:technical1@4"
            ]
        },
        {
            "x": 4,
            "y": 3,
            "z": 2,
            "elements": [
                "chisel:technical1@4"
            ]
        },
        {
            "x": -4,
            "y": 3,
            "z": 12,
            "elements": [
                "chisel:technical1@4"
            ]
        },
        {
            "x": 4,
            "y": 2,
            "z": 5,
            "elements": [
                "tconevo:metal_block@2"
            ]
        },
        {
            "x": 0,
            "y": 1,
            "z": 7,
            "elements": [
                "tconevo:metal_block@2"
            ]
        },
        {
            "x": -7,
            "y": 6,
            "z": 6,
            "elements": [
                "chisel:technical1@4"
            ]
        },
        {
            "x": -2,
            "y": 0,
            "z": 6,
            "elements": [
                "contenttweaker:crystalmatrixforcefieldcontrolblock@0"
            ]
        },
        {
            "x": -5,
            "y": 14,
            "z": 11,
            "elements": [
                "chisel:technical1@4"
            ]
        },
        {
            "x": -5,
            "y": 2,
            "z": 6,
            "elements": [
                "tconevo:metal_block@2"
            ]
        },
        {
            "x": -6,
            "y": -1,
            "z": 7,
            "elements": [
                "chisel:technical1@4"
            ]
        },
        {
            "x": 0,
            "y": 9,
            "z": 15,
            "elements": [
                "chisel:technical1@4"
            ]
        },
        {
            "x": -7,
            "y": 5,
            "z": 12,
            "elements": [
                "chisel:technical1@4"
            ]
        },
        {
            "x": 6,
            "y": 11,
            "z": 15,
            "elements": [
                "chisel:technical1@4"
            ]
        },
        {
            "x": 1,
            "y": 3,
            "z": 5,
            "elements": [
                "chisel:technical1@4"
            ]
        },
        {
            "x": 0,
            "y": 10,
            "z": 15,
            "elements": [
                "chisel:technical1@4"
            ]
        },
        {
            "x": 6,
            "y": -1,
            "z": 5,
            "elements": [
                "chisel:technical1@4"
            ]
        },
        {
            "x": 4,
            "y": 0,
            "z": 13,
            "elements": [
                "contenttweaker:crystalmatrixforcefieldcontrolblock@0"
            ]
        },
        {
            "x": 8,
            "y": 2,
            "z": 8,
            "elements": [
                "chisel:technical1@4"
            ]
        },
        {
            "x": -6,
            "y": 1,
            "z": 10,
            "elements": [
                "chisel:technical1@4"
            ]
        },
        {
            "x": 1,
            "y": 0,
            "z": 14,
            "elements": [
                "contenttweaker:crystalmatrixforcefieldcontrolblock@0"
            ]
        },
        {
            "x": 5,
            "y": 0,
            "z": 1,
            "elements": [
                "contenttweaker:crystalmatrixforcefieldcontrolblock@0"
            ]
        },
        {
            "x": 3,
            "y": -1,
            "z": 13,
            "elements": [
                "chisel:technical1@4"
            ]
        },
        {
            "x": -5,
            "y": 3,
            "z": 10,
            "elements": [
                "chisel:technical1@4"
            ]
        },
        {
            "x": -6,
            "y": -1,
            "z": 15,
            "elements": [
                "chisel:technical1@4"
            ]
        },
        {
            "x": -2,
            "y": 3,
            "z": 13,
            "elements": [
                "chisel:technical1@4"
            ]
        },
        {
            "x": 0,
            "y": -1,
            "z": 0,
            "elements": [
                "chisel:technical1@4"
            ]
        },
        {
            "x": 0,
            "y": -1,
            "z": 14,
            "elements": [
                "chisel:technical1@4"
            ]
        },
        {
            "x": -5,
            "y": 0,
            "z": 6,
            "elements": [
                "contenttweaker:crystalmatrixforcefieldcontrolblock@0"
            ]
        },
        {
            "x": 7,
            "y": 1,
            "z": 13,
            "elements": [
                "chisel:technical1@4"
            ]
        },
        {
            "x": -4,
            "y": -1,
            "z": 10,
            "elements": [
                "chisel:technical1@4"
            ]
        },
        {
            "x": 7,
            "y": 14,
            "z": 12,
            "elements": [
                "chisel:technical1@4"
            ]
        },
        {
            "x": -3,
            "y": 7,
            "z": 0,
            "elements": [
                "chisel:technical1@4"
            ]
        },
        {
            "x": -6,
            "y": 9,
            "z": 0,
            "elements": [
                "chisel:technical1@4"
            ]
        },
        {
            "x": 5,
            "y": 3,
            "z": 1,
            "elements": [
                "chisel:technical1@4"
            ]
        },
        {
            "x": 8,
            "y": 4,
            "z": 8,
            "elements": [
                "chisel:technical1@4"
            ]
        },
        {
            "x": -5,
            "y": 3,
            "z": 5,
            "elements": [
                "chisel:technical1@4"
            ]
        },
        {
            "x": -6,
            "y": -1,
            "z": 6,
            "elements": [
                "chisel:technical1@4"
            ]
        },
        {
            "x": 8,
            "y": 1,
            "z": 1,
            "elements": [
                "chisel:technical1@4"
            ]
        },
        {
            "x": -5,
            "y": 11,
            "z": 0,
            "elements": [
                "chisel:technical1@4"
            ]
        },
        {
            "x": 5,
            "y": 1,
            "z": 8,
            "elements": [
                "tconevo:metal_block@2"
            ]
        },
        {
            "x": 4,
            "y": 2,
            "z": 13,
            "elements": [
                "nuclearcraft:fluid_plasma@0"
            ]
        },
        {
            "x": -2,
            "y": 1,
            "z": 0,
            "elements": [
                "contenttweaker:universalforcefieldcontrolblock@0"
            ]
        },
        {
            "x": 8,
            "y": 3,
            "z": 8,
            "elements": [
                "chisel:technical1@4"
            ]
        },
        {
            "x": 1,
            "y": 1,
            "z": 14,
            "elements": [
                "chisel:technical1@4"
            ]
        },
        {
            "x": -4,
            "y": -1,
            "z": 5,
            "elements": [
                "chisel:technical1@4"
            ]
        },
        {
            "x": 5,
            "y": 2,
            "z": 1,
            "elements": [
                "tconevo:metal_block@2"
            ]
        },
        {
            "x": -1,
            "y": 3,
            "z": 0,
            "elements": [
                "chisel:technical1@4"
            ]
        },
        {
            "x": -4,
            "y": 5,
            "z": 0,
            "elements": [
                "chisel:technical1@4"
            ]
        },
        {
            "x": -2,
            "y": 1,
            "z": 5,
            "elements": [
                "tconevo:metal_block@2"
            ]
        },
        {
            "x": 6,
            "y": 3,
            "z": 3,
            "elements": [
                "chisel:technical1@4"
            ]
        },
        {
            "x": -7,
            "y": 7,
            "z": 5,
            "elements": [
                "chisel:technical1@4"
            ]
        },
        {
            "x": 0,
            "y": 14,
            "z": 4,
            "elements": [
                "chisel:technical1@4"
            ]
        },
        {
            "x": -4,
            "y": 1,
            "z": 10,
            "elements": [
                "chisel:technical1@4"
            ]
        },
        {
            "x": 3,
            "y": 1,
            "z": 3,
            "elements": [
                "tconevo:metal_block@2"
            ]
        },
        {
            "x": -7,
            "y": 3,
            "z": 10,
            "elements": [
                "chisel:technical1@4"
            ]
        },
        {
            "x": -2,
            "y": -1,
            "z": 10,
            "elements": [
                "chisel:technical1@4"
            ]
        },
        {
            "x": -3,
            "y": -1,
            "z": 13,
            "elements": [
                "chisel:technical1@4"
            ]
        },
        {
            "x": -7,
            "y": 11,
            "z": 5,
            "elements": [
                "chisel:technical1@4"
            ]
        },
        {
            "x": 1,
            "y": 0,
            "z": 6,
            "elements": [
                "contenttweaker:crystalmatrixforcefieldcontrolblock@0"
            ]
        },
        {
            "x": -3,
            "y": 2,
            "z": 11,
            "elements": [
                "nuclearcraft:fluid_plasma@0"
            ]
        },
        {
            "x": -1,
            "y": 14,
            "z": 1,
            "elements": [
                "chisel:technical1@4"
            ]
        },
        {
            "x": -2,
            "y": -1,
            "z": 0,
            "elements": [
                "chisel:technical1@4"
            ]
        },
        {
            "x": -6,
            "y": 1,
            "z": 15,
            "elements": [
                "chisel:technical1@4"
            ]
        },
        {
            "x": 6,
            "y": 2,
            "z": 4,
            "elements": [
                "tconevo:metal_block@2"
            ]
        },
        {
            "x": -2,
            "y": 14,
            "z": 13,
            "elements": [
                "chisel:technical1@4"
            ]
        },
        {
            "x": 4,
            "y": 3,
            "z": 13,
            "elements": [
                "chisel:technical1@4"
            ]
        },
        {
            "x": -2,
            "y": 0,
            "z": 13,
            "elements": [
                "contenttweaker:crystalmatrixforcefieldcontrolblock@0"
            ]
        },
        {
            "x": 1,
            "y": 3,
            "z": 14,
            "elements": [
                "chisel:technical1@4"
            ]
        },
        {
            "x": -2,
            "y": 2,
            "z": 13,
            "elements": [
                "nuclearcraft:fluid_plasma@0"
            ]
        },
        {
            "x": 7,
            "y": -1,
            "z": 8,
            "elements": [
                "chisel:technical1@4"
            ]
        },
        {
            "x": -7,
            "y": 7,
            "z": 10,
            "elements": [
                "chisel:technical1@4"
            ]
        },
        {
            "x": -6,
            "y": 13,
            "z": 0,
            "elements": [
                "chisel:technical1@4"
            ]
        },
        {
            "x": -3,
            "y": 11,
            "z": 0,
            "elements": [
                "chisel:technical1@4"
            ]
        },
        {
            "x": -6,
            "y": -1,
            "z": 5,
            "elements": [
                "chisel:technical1@4"
            ]
        },
        {
            "x": 1,
            "y": 14,
            "z": 12,
            "elements": [
                "chisel:technical1@4"
            ]
        },
        {
            "x": -2,
            "y": 5,
            "z": 0,
            "elements": [
                "chisel:technical1@4"
            ]
        },
        {
            "x": -2,
            "y": 0,
            "z": 11,
            "elements": [
                "contenttweaker:crystalmatrixforcefieldcontrolblock@0"
            ]
        },
        {
            "x": 1,
            "y": 3,
            "z": 0,
            "elements": [
                "chisel:technical1@4"
            ]
        },
        {
            "x": 0,
            "y": -1,
            "z": 6,
            "elements": [
                "chisel:technical1@4"
            ]
        },
        {
            "x": -5,
            "y": 7,
            "z": 0,
            "elements": [
                "chisel:technical1@4"
            ]
        },
        {
            "x": -2,
            "y": 14,
            "z": 9,
            "elements": [
                "chisel:technical1@4"
            ]
        },
        {
            "x": 8,
            "y": 0,
            "z": 8,
            "elements": [
                "chisel:technical1@4"
            ]
        },
        {
            "x": -3,
            "y": 3,
            "z": 5,
            "elements": [
                "chisel:technical1@4"
            ]
        },
        {
            "x": 0,
            "y": 1,
            "z": 5,
            "elements": [
                "tconevo:metal_block@2"
            ]
        },
        {
            "x": 0,
            "y": 3,
            "z": 3,
            "elements": [
                "chisel:technical1@4"
            ]
        },
        {
            "x": 7,
            "y": 0,
            "z": 6,
            "elements": [
                "contenttweaker:crystalmatrixforcefieldcontrolblock@0"
            ]
        },
        {
            "x": -2,
            "y": 2,
            "z": 14,
            "elements": [
                "nuclearcraft:fluid_plasma@0"
            ]
        },
        {
            "x": 1,
            "y": 0,
            "z": 9,
            "elements": [
                "contenttweaker:crystalmatrixforcefieldcontrolblock@0"
            ]
        },
        {
            "x": 1,
            "y": 3,
            "z": 12,
            "elements": [
                "chisel:technical1@4"
            ]
        },
        {
            "x": -4,
            "y": 1,
            "z": 0,
            "elements": [
                "contenttweaker:universalforcefieldcontrolblock@0"
            ]
        },
        {
            "x": 8,
            "y": 11,
            "z": 8,
            "elements": [
                "chisel:technical1@4"
            ]
        },
        {
            "x": -4,
            "y": 13,
            "z": 0,
            "elements": [
                "chisel:technical1@4"
            ]
        },
        {
            "x": 5,
            "y": 14,
            "z": 1,
            "elements": [
                "chisel:technical1@4"
            ]
        },
        {
            "x": -2,
            "y": 2,
            "z": 9,
            "elements": [
                "tconevo:metal_block@2"
            ]
        },
        {
            "x": 8,
            "y": 9,
            "z": 1,
            "elements": [
                "chisel:technical1@4"
            ]
        },
        {
            "x": 4,
            "y": 1,
            "z": 7,
            "elements": [
                "tconevo:metal_block@2"
            ]
        },
        {
            "x": 8,
            "y": 12,
            "z": 8,
            "elements": [
                "chisel:technical1@4"
            ]
        },
        {
            "x": -5,
            "y": 3,
            "z": 14,
            "elements": [
                "chisel:technical1@4"
            ]
        },
        {
            "x": 0,
            "y": 2,
            "z": 4,
            "elements": [
                "tconevo:metal_block@2"
            ]
        },
        {
            "x": 3,
            "y": 0,
            "z": 4,
            "elements": [
                "contenttweaker:crystalmatrixforcefieldcontrolblock@0"
            ]
        },
        {
            "x": 1,
            "y": 2,
            "z": 12,
            "elements": [
                "nuclearcraft:fluid_plasma@0"
            ]
        },
        {
            "x": 1,
            "y": 2,
            "z": 6,
            "elements": [
                "tconevo:metal_block@2"
            ]
        },
        {
            "x": 8,
            "y": 13,
            "z": 2,
            "elements": [
                "chisel:technical1@4"
            ]
        },
        {
            "x": 2,
            "y": 14,
            "z": 8,
            "elements": [
                "chisel:technical1@4"
            ]
        },
        {
            "x": -3,
            "y": 0,
            "z": 4,
            "elements": [
                "contenttweaker:crystalmatrixforcefieldcontrolblock@0"
            ]
        },
        {
            "x": 1,
            "y": 1,
            "z": 12,
            "elements": [
                "chisel:technical1@4"
            ]
        },
        {
            "x": 4,
            "y": -1,
            "z": 0,
            "elements": [
                "chisel:technical1@4"
            ]
        },
        {
            "x": -1,
            "y": 11,
            "z": 0,
            "elements": [
                "chisel:technical1@4"
            ]
        },
        {
            "x": 4,
            "y": 1,
            "z": 6,
            "elements": [
                "tconevo:metal_block@2"
            ]
        },
        {
            "x": 4,
            "y": 2,
            "z": 14,
            "elements": [
                "nuclearcraft:fluid_plasma@0"
            ]
        },
        {
            "x": 8,
            "y": 12,
            "z": 2,
            "elements": [
                "chisel:technical1@4"
            ]
        },
        {
            "x": -5,
            "y": 3,
            "z": 0,
            "elements": [
                "chisel:technical1@4"
            ]
        },
        {
            "x": 2,
            "y": 1,
            "z": 0,
            "elements": [
                "contenttweaker:universalforcefieldcontrolblock@0"
            ]
        },
        {
            "x": 1,
            "y": 3,
            "z": 6,
            "elements": [
                "chisel:technical1@4"
            ]
        },
        {
            "x": -5,
            "y": 7,
            "z": 15,
            "elements": [
                "chisel:technical1@4"
            ]
        },
        {
            "x": -5,
            "y": 14,
            "z": 12,
            "elements": [
                "chisel:technical1@4"
            ]
        },
        {
            "x": 5,
            "y": -1,
            "z": 3,
            "elements": [
                "chisel:technical1@4"
            ]
        },
        {
            "x": -7,
            "y": 7,
            "z": 0,
            "elements": [
                "chisel:technical1@4"
            ]
        },
        {
            "x": 8,
            "y": 10,
            "z": 8,
            "elements": [
                "chisel:technical1@4"
            ]
        },
        {
            "x": 2,
            "y": 1,
            "z": 5,
            "elements": [
                "tconevo:metal_block@2"
            ]
        },
        {
            "x": -1,
            "y": 3,
            "z": 5,
            "elements": [
                "chisel:technical1@4"
            ]
        },
        {
            "x": 6,
            "y": -1,
            "z": 6,
            "elements": [
                "chisel:technical1@4"
            ]
        },
        {
            "x": 8,
            "y": 11,
            "z": 2,
            "elements": [
                "chisel:technical1@4"
            ]
        },
        {
            "x": 2,
            "y": -1,
            "z": 10,
            "elements": [
                "chisel:technical1@4"
            ]
        },
        {
            "x": -5,
            "y": 0,
            "z": 14,
            "elements": [
                "contenttweaker:crystalmatrixforcefieldcontrolblock@0"
            ]
        },
        {
            "x": 8,
            "y": 6,
            "z": 8,
            "elements": [
                "chisel:technical1@4"
            ]
