
{
    "registryname": "kysn_research",
    "localizedname": "§b科学枢纽-研究模块数据接收器",
    "failure-action": "still",
    "has-factory": true,
    "factory-only": true,
    "requires-blueprint": false,
        "parts": [
            {
                "x": 0,
                "y": 0,
                "z": 0,
                "elements": [
                    "modularmachinery:kysn_research_factory_controller"
                ]
            },
            {
                "x": 0,
                "y": 16,
                "z": -1,
                "elements": [
                    "avaritiaddons:infinity_glass@1"
                ]
            },
            {
                "x": 9,
                "y": 17,
                "z": 6,
                "elements": [
                    "contenttweaker:arkmachineblock@0"
                ]
            },
            {
                "x": 0,
                "y": 11,
                "z": 4,
                "elements": [
                    "avaritia:block_resource@0"
                ]
            },
            {
                "x": -6,
                "y": 8,
                "z": 5,
                "elements": [
                    "contenttweaker:arkmachineblock@0"
                ]
            },
            {
                "x": -3,
                "y": 0,
                "z": 5,
                "elements": [
                    "contenttweaker:arkmachineblock@0"
                ]
            },
            {
                "x": 0,
                "y": 22,
                "z": 8,
                "elements": [
                    "contenttweaker:arkmachineblock@0"
                ]
            },
            {
                "x": -6,
                "y": 0,
                "z": 10,
                "elements": [
                    "casings_all",
                    "modularmachinery:blockupgradebus"
                ]
            },
            {
                "x": -3,
                "y": 7,
                "z": 7,
                "elements": [
                    "contenttweaker:arkmachineblock@0"
                ]
            },
            {
                "x": -2,
                "y": 7,
                "z": -5,
                "elements": [
                    "contenttweaker:arkmachineblock@0"
                ]
            },
            {
                "x": 9,
                "y": 16,
                "z": 6,
                "elements": [
                    "contenttweaker:arkmachineblock@0"
                ]
            },
            {
                "x": 0,
                "y": 17,
                "z": -1,
                "elements": [
                    "avaritiaddons:infinity_glass@3"
                ]
            },
            {
                "x": 1,
                "y": 16,
                "z": 2,
                "elements": [
                    "avaritia:block_resource@0"
                ]
            },
            {
                "x": 0,
                "y": 10,
                "z": 3,
                "elements": [
                    "avaritia:block_resource@0"
                ]
            },
            {
                "x": -9,
                "y": 12,
                "z": 5,
                "elements": [
                    "contenttweaker:arkmachineblock@0"
                ]
            },
            {
                "x": 0,
                "y": 9,
                "z": 4,
                "elements": [
                    "avaritia:block_resource@0"
                ]
            },
            {
                "x": 1,
                "y": 0,
                "z": 0,
                "elements": [
                    "casings_all",
                    "modularmachinery:blockupgradebus"
                ]
            },
            {
                "x": 0,
                "y": 13,
                "z": 4,
                "elements": [
                    "avaritia:block_resource@0"
                ]
            },
            {
                "x": 0,
                "y": 19,
                "z": -1,
                "elements": [
                    "avaritiaddons:infinity_glass@3"
                ]
            },
            {
                "x": -4,
                "y": 6,
                "z": 0,
                "elements": [
                    "contenttweaker:arkmachineblock@0"
                ]
            },
            {
                "x": 10,
                "y": 14,
                "z": 2,
                "elements": [
                    "contenttweaker:arkmachineblock@0"
                ]
            },
            {
                "x": -2,
                "y": 0,
                "z": 5,
                "elements": [
                    "contenttweaker:arkmachineblock@0"
                ]
            },
            {
                "x": 9,
                "y": 15,
                "z": 6,
                "elements": [
                    "contenttweaker:arkmachineblock@0"
                ]
            },
            {
                "x": -1,
                "y": 15,
                "z": 4,
                "elements": [
                    "avaritia:block_resource@0"
                ]
            },
            {
                "x": -6,
                "y": 17,
                "z": 9,
                "elements": [
                    "contenttweaker:arkmachineblock@0"
                ]
            },
            {
                "x": 0,
                "y": 14,
                "z": 3,
                "elements": [
                    "avaritia:block_resource@0"
                ]
            },
            {
                "x": 0,
                "y": 18,
                "z": -1,
                "elements": [
                    "avaritiaddons:infinity_glass@1"
                ]
            },
            {
                "x": -9,
                "y": 14,
                "z": 5,
                "elements": [
                    "contenttweaker:arkmachineblock@0"
                ]
            },
            {
                "x": -5,
                "y": 0,
                "z": 10,
                "elements": [
                    "contenttweaker:arkmachineblock@0"
                ]
            },
            {
                "x": -2,
                "y": 2,
                "z": 5,
                "elements": [
                    "contenttweaker:arkforcefieldcontrolblock@0"
                ]
            },
            {
                "x": 1,
                "y": 17,
                "z": 2,
                "elements": [
                    "avaritia:block_resource@0"
                ]
            },
            {
                "x": -3,
                "y": 7,
                "z": -5,
                "elements": [
                    "contenttweaker:arkmachineblock@0"
                ]
            },
            {
                "x": 9,
                "y": 14,
                "z": 6,
                "elements": [
                    "contenttweaker:arkmachineblock@0"
                ]
            },
            {
                "x": -2,
                "y": 9,
                "z": 9,
                "elements": [
                    "contenttweaker:arkmachineblock@0"
                ]
            },
            {
                "x": 2,
                "y": 0,
                "z": 0,
                "elements": [
                    "casings_all",
                    "modularmachinery:blockupgradebus"
                ]
            },
            {
                "x": -1,
                "y": 13,
                "z": 4,
                "elements": [
                    "avaritia:block_resource@0"
                ]
            },
            {
                "x": -3,
                "y": 6,
                "z": 5,
                "elements": [
                    "contenttweaker:arkmachineblock@0"
                ]
            },
            {
                "x": 6,
                "y": 9,
                "z": 7,
                "elements": [
                    "contenttweaker:arkmachineblock@0"
                ]
            },
            {
                "x": 7,
                "y": 8,
                "z": 2,
                "elements": [
                    "contenttweaker:arkmachineblock@0"
                ]
            },
            {
                "x": -5,
                "y": 0,
                "z": 5,
                "elements": [
                    "contenttweaker:arkmachineblock@0"
                ]
            },
            {
                "x": 6,
                "y": 18,
                "z": 9,
                "elements": [
                    "contenttweaker:arkmachineblock@0"
                ]
            },
            {
                "x": -5,
                "y": 6,
                "z": 0,
                "elements": [
                    "contenttweaker:arkmachineblock@0"
                ]
            },
            {
                "x": 3,
                "y": 7,
                "z": 7,
                "elements": [
                    "contenttweaker:arkmachineblock@0"
                ]
            },
            {
                "x": 9,
                "y": 13,
                "z": 6,
                "elements": [
                    "contenttweaker:arkmachineblock@0"
                ]
            },
            {
                "x": 1,
                "y": 13,
                "z": 2,
                "elements": [
                    "avaritia:block_resource@0"
                ]
            },
            {
                "x": 0,
                "y": 12,
                "z": 7,
                "elements": [
                    "avaritia:block_resource@0"
                ]
            },
            {
                "x": -4,
                "y": 0,
                "z": 10,
                "elements": [
                    "contenttweaker:arkmachineblock@0"
                ]
            },
            {
                "x": 0,
                "y": 16,
                "z": 3,
                "elements": [
                    "avaritia:block_resource@0"
                ]
            },
            {
                "x": 1,
                "y": 12,
                "z": 2,
                "elements": [
                    "avaritia:block_resource@0"
                ]
            },
            {
                "x": -1,
                "y": 0,
                "z": 0,
                "elements": [
                    "casings_all",
                    "modularmachinery:blockupgradebus"
                ]
            },
            {
                "x": -5,
                "y": 19,
                "z": 9,
                "elements": [
                    "contenttweaker:arkmachineblock@0"
                ]
            },
            {
                "x": 6,
                "y": 19,
                "z": 8,
                "elements": [
                    "contenttweaker:arkmachineblock@0"
                ]
            },
            {
                "x": 6,
                "y": 0,
                "z": 1,
                "elements": [
                    "casings_all",
                    "modularmachinery:blockupgradebus"
                ]
            },
            {
                "x": -1,
                "y": 11,
                "z": 4,
                "elements": [
                    "avaritia:block_resource@0"
                ]
            },
            {
                "x": 1,
                "y": 15,
                "z": 2,
                "elements": [
                    "avaritia:block_resource@0"
                ]
            },
            {
                "x": 0,
                "y": 11,
                "z": 7,
                "elements": [
                    "avaritia:block_resource@0"
                ]
            },
            {
                "x": 0,
                "y": 14,
                "z": -1,
                "elements": [
                    "avaritia:block_resource@0"
                ]
            },
            {
                "x": 0,
                "y": 0,
                "z": 5,
                "elements": [
                    "contenttweaker:arkmachineblock@0"
                ]
            },
            {
                "x": 5,
                "y": 8,
                "z": -4,
                "elements": [
                    "contenttweaker:arkmachineblock@0"
                ]
            },
            {
                "x": 0,
                "y": 2,
                "z": 5,
                "elements": [
                    "contenttweaker:arkforcefieldcontrolblock@0"
                ]
            },
            {
                "x": 3,
                "y": 0,
                "z": 3,
                "elements": [
                    "contenttweaker:arkmachineblock@0"
                ]
            },
            {
                "x": 1,
                "y": 14,
                "z": 2,
                "elements": [
                    "avaritia:block_resource@0"
                ]
            },
            {
                "x": 0,
                "y": 15,
                "z": -1,
                "elements": [
                    "avaritia:block_resource@0"
                ]
            },
            {
                "x": -1,
                "y": 7,
                "z": -5,
                "elements": [
                    "contenttweaker:arkmachineblock@0"
                ]
            },
            {
                "x": 0,
                "y": 10,
                "z": 7,
                "elements": [
                    "avaritia:block_resource@0"
                ]
            },
            {
                "x": 6,
                "y": 7,
                "z": -1,
                "elements": [
                    "contenttweaker:arkmachineblock@0"
                ]
            },
            {
                "x": 3,
                "y": 7,
                "z": 6,
                "elements": [
                    "contenttweaker:arkmachineblock@0"
                ]
            },
            {
                "x": 4,
                "y": 0,
                "z": 0,
                "elements": [
                    "casings_all",
                    "modularmachinery:blockupgradebus"
                ]
            },
            {
                "x": -1,
                "y": 6,
                "z": 5,
                "elements": [
                    "contenttweaker:arkmachineblock@0"
                ]
            },
            {
                "x": 0,
                "y": 4,
                "z": 5,
                "elements": [
                    "contenttweaker:arkforcefieldcontrolblock@0"
                ]
            },
            {
                "x": 0,
                "y": 12,
                "z": 6,
                "elements": [
                    "avaritia:block_resource@0"
                ]
            },
            {
                "x": 0,
                "y": 9,
                "z": 7,
                "elements": [
                    "avaritia:block_resource@0"
                ]
            },
            {
                "x": 0,
                "y": 1,
                "z": 4,
                "elements": [
                    "contenttweaker:arkforcefieldcontrolblock@0"
                ]
            },
            {
                "x": 2,
                "y": 7,
                "z": -5,
                "elements": [
                    "contenttweaker:arkmachineblock@0"
                ]
            },
            {
                "x": 0,
                "y": 13,
                "z": 6,
                "elements": [
                    "avaritia:block_resource@0"
                ]
            },
            {
                "x": 2,
                "y": 0,
                "z": 12,
                "elements": [
                    "casings_all",
                    "modularmachinery:blockupgradebus"
                ]
            },
            {
                "x": -10,
                "y": 12,
                "z": 0,
                "elements": [
                    "contenttweaker:arkmachineblock@0"
                ]
            },
            {
                "x": 1,
                "y": 9,
                "z": 9,
                "elements": [
                    "contenttweaker:arkmachineblock@0"
                ]
            },
            {
                "x": 0,
                "y": 8,
                "z": 7,
                "elements": [
                    "avaritia:block_resource@0"
                ]
            },
            {
                "x": 9,
                "y": 11,
                "z": 2,
                "elements": [
                    "contenttweaker:arkmachineblock@0"
                ]
            },
            {
                "x": 0,
                "y": 6,
                "z": 7,
                "elements": [
                    "contenttweaker:arkforcefieldcontrolblock@0"
                ]
            },
            {
                "x": 5,
                "y": 0,
                "z": 0,
                "elements": [
                    "casings_all",
                    "modularmachinery:blockupgradebus"
                ]
            },
            {
                "x": 0,
                "y": 6,
                "z": 5,
                "elements": [
                    "contenttweaker:arkmachineblock@0"
                ]
            },
            {
                "x": 3,
                "y": 6,
                "z": -1,
                "elements": [
                    "contenttweaker:arkmachineblock@0"
                ]
            },
            {
                "x": -1,
                "y": 4,
                "z": 5,
                "elements": [
                    "contenttweaker:arkforcefieldcontrolblock@0"
                ]
            },
            {
                "x": 1,
                "y": 22,
                "z": 8,
                "elements": [
                    "contenttweaker:arkmachineblock@0"
                ]
            },
            {
                "x": -7,
                "y": 8,
                "z": 0,
                "elements": [
                    "contenttweaker:arkmachineblock@0"
                ]
            },
            {
                "x": 2,
                "y": 0,
                "z": 5,
                "elements": [
                    "contenttweaker:arkmachineblock@0"
                ]
            },
            {
                "x": 2,
                "y": 2,
                "z": 5,
                "elements": [
                    "contenttweaker:arkforcefieldcontrolblock@0"
                ]
            },
            {
                "x": 0,
                "y": 7,
                "z": 7,
                "elements": [
                    "contenttweaker:arkmachineblock@0"
                ]
            },
            {
                "x": 1,
                "y": 7,
                "z": -5,
                "elements": [
                    "contenttweaker:arkmachineblock@0"
                ]
            },
            {
                "x": 0,
                "y": 10,
                "z": 6,
                "elements": [
                    "avaritia:block_resource@0"
                ]
            },
            {
                "x": 9,
                "y": 10,
                "z": 2,
                "elements": [
                    "contenttweaker:arkmachineblock@0"
                ]
            },
            {
                "x": -2,
                "y": 0,
                "z": 0,
                "elements": [
                    "casings_all",
                    "modularmachinery:blockupgradebus"
                ]
            },
            {
                "x": 0,
                "y": 11,
                "z": 6,
                "elements": [
                    "avaritia:block_resource@0"
                ]
            },
            {
                "x": 0,
                "y": 9,
                "z": 6,
                "elements": [
                    "avaritia:block_resource@0"
                ]
            },
            {
                "x": -2,
                "y": 22,
                "z": 8,
                "elements": [
                    "contenttweaker:arkmachineblock@0"
                ]
            },
            {
                "x": 6,
                "y": 0,
                "z": 7,
                "elements": [
                    "casings_all",
                    "modularmachinery:blockupgradebus"
                ]
            },
            {
                "x": -1,
                "y": 0,
                "z": 5,
                "elements": [
                    "contenttweaker:arkmachineblock@0"
                ]
            },
            {
                "x": 6,
                "y": 11,
                "z": 8,
                "elements": [
                    "contenttweaker:arkmachineblock@0"
                ]
            },
            {
                "x": 0,
                "y": 4,
                "z": 7,
                "elements": [
                    "contenttweaker:arkforcefieldcontrolblock@0"
                ]
            },
            {
                "x": 0,
                "y": 0,
                "z": 10,
                "elements": [
                    "contenttweaker:arkmachineblock@0"
                ]
            },
            {
                "x": -1,
                "y": 2,
                "z": 5,
                "elements": [
                    "contenttweaker:arkforcefieldcontrolblock@0"
                ]
            },
            {
                "x": 0,
                "y": 8,
                "z": 6,
                "elements": [
                    "avaritia:block_resource@0"
                ]
            },
            {
                "x": 6,
                "y": 0,
                "z": 3,
                "elements": [
                    "casings_all",
                    "modularmachinery:blockupgradebus"
                ]
            },
            {
                "x": -9,
                "y": 16,
                "z": 5,
                "elements": [
                    "contenttweaker:arkmachineblock@0"
                ]
            },
            {
                "x": 5,
                "y": 7,
                "z": -3,
                "elements": [
                    "contenttweaker:arkmachineblock@0"
                ]
            },
            {
                "x": 3,
                "y": 0,
                "z": 7,
                "elements": [
                    "contenttweaker:arkmachineblock@0"
                ]
            },
            {
                "x": 0,
                "y": 5,
                "z": 7,
                "elements": [
                    "contenttweaker:arkforcefieldcontrolblock@0"
                ]
            },
            {
                "x": 0,
                "y": 5,
                "z": 4,
                "elements": [
                    "contenttweaker:arkmachineblock@0"
                ]
            },
            {
                "x": -5,
                "y": 0,
                "z": 0,
                "elements": [
                    "casings_all",
                    "modularmachinery:blockupgradebus"
                ]
            },
            {
                "x": -9,
                "y": 11,
                "z": -1,
                "elements": [
                    "contenttweaker:arkmachineblock@0"
                ]
            },
            {
                "x": 0,
                "y": 3,
                "z": 4,
                "elements": [
                    "contenttweaker:arkforcefieldcontrolblock@0"
                ]
            },
            {
                "x": 6,
                "y": 0,
                "z": 6,
                "elements": [
                    "casings_all",
                    "modularmachinery:blockupgradebus"
                ]
            },
            {
                "x": 3,
                "y": 6,
                "z": 3,
                "elements": [
                    "contenttweaker:arkmachineblock@0"
                ]
            },
            {
                "x": -6,
                "y": 0,
                "z": 1,
                "elements": [
                    "casings_all",
                    "modularmachinery:blockupgradebus"
                ]
            },
            {
                "x": -4,
                "y": 0,
                "z": 5,
                "elements": [
                    "contenttweaker:arkmachineblock@0"
                ]
            },
            {
                "x": 10,
                "y": 13,
                "z": 2,
                "elements": [
                    "contenttweaker:arkmachineblock@0"
                ]
            },
            {
                "x": 0,
                "y": 2,
                "z": 7,
                "elements": [
                    "contenttweaker:arkforcefieldcontrolblock@0"
                ]
            },
            {
                "x": -9,
                "y": 10,
                "z": -1,
                "elements": [
                    "contenttweaker:arkmachineblock@0"
                ]
            },
            {
                "x": 0,
                "y": 12,
                "z": 3,
                "elements": [
                    "avaritia:block_resource@0"
                ]
            },
            {
                "x": 0,
                "y": 7,
                "z": 6,
                "elements": [
                    "avaritia:block_resource@0"
                ]
            },
            {
                "x": 6,
                "y": 10,
                "z": 8,
                "elements": [
                    "contenttweaker:arkmachineblock@0"
                ]
            },
            {
                "x": 10,
                "y": 12,
                "z": 2,
                "elements": [
                    "contenttweaker:arkmachineblock@0"
                ]
            },
            {
                "x": -1,
                "y": 0,
                "z": 12,
                "elements": [
                    "casings_all",
                    "modularmachinery:blockupgradebus"
                ]
            },
            {
                "x": -3,
                "y": 0,
                "z": 10,
                "elements": [
                    "contenttweaker:arkmachineblock@0"
                ]
            },
            {
                "x": -5,
                "y": 11,
                "z": 9,
                "elements": [
                    "contenttweaker:arkmachineblock@0"
                ]
            },
            {
                "x": 0,
                "y": 5,
                "z": -1,
                "elements": [
                    "contenttweaker:arkmachineblock@0"
                ]
            },
            {
                "x": 0,
                "y": 3,
                "z": 7,
                "elements": [
                    "contenttweaker:arkforcefieldcontrolblock@0"
                ]
            },
            {
                "x": 0,
                "y": 6,
                "z": 6,
                "elements": [
                    "contenttweaker:arkmachineblock@0"
                ]
            },
            {
                "x": 0,
                "y": 1,
                "z": 8,
                "elements": [
                    "contenttweaker:arkforcefieldcontrolblock@0"
                ]
            },
            {
                "x": -5,
                "y": 14,
                "z": 10,
                "elements": [
                    "contenttweaker:arkmachineblock@0"
                ]
            },
            {
                "x": 3,
                "y": 6,
                "z": 5,
                "elements": [
                    "contenttweaker:arkmachineblock@0"
                ]
            },
            {
                "x": -2,
                "y": 12,
                "z": 10,
                "elements": [
                    "contenttweaker:arkmachineblock@0"
                ]
            },
            {
                "x": 5,
                "y": 0,
                "z": 5,
                "elements": [
                    "contenttweaker:arkmachineblock@0"
                ]
            },
            {
                "x": 0,
                "y": 15,
                "z": 11,
                "elements": [
                    "contenttweaker:arkmachineblock@0"
                ]
            },
            {
                "x": 4,
                "y": 0,
                "z": 3,
                "elements": [
                    "contenttweaker:arkmachineblock@0"
                ]
            },
            {
                "x": -5,
                "y": 7,
                "z": 4,
                "elements": [
                    "contenttweaker:arkmachineblock@0"
                ]
            },
            {
                "x": -1,
                "y": 12,
                "z": 5,
                "elements": [
                    "avaritia:block_resource@0"
                ]
            },
            {
                "x": -8,
                "y": 9,
                "z": 4,
                "elements": [
                    "contenttweaker:arkmachineblock@0"
                ]
            },
            {
                "x": 3,
                "y": 0,
                "z": 8,
                "elements": [
                    "contenttweaker:arkmachineblock@0"
                ]
            },
            {
                "x": 0,
                "y": 10,
                "z": 5,
                "elements": [
                    "avaritia:block_resource@0"
                ]
            },
            {
                "x": 0,
                "y": 2,
                "z": 8,
                "elements": [
                    "contenttweaker:arkforcefieldcontrolblock@0"
                ]
            },
            {
                "x": -5,
                "y": 16,
                "z": 10,
                "elements": [
                    "contenttweaker:arkmachineblock@0"
                ]
            },
            {
                "x": -5,
                "y": 8,
                "z": -4,
                "elements": [
                    "contenttweaker:arkmachineblock@0"
                ]
            },
            {
                "x": 7,
                "y": 8,
                "z": 1,
                "elements": [
                    "contenttweaker:arkmachineblock@0"
                ]
            },
            {
                "x": -1,
                "y": 1,
                "z": 4,
                "elements": [
                    "contenttweaker:arkforcefieldcontrolblock@0"
                ]
            },
            {
                "x": 0,
                "y": 6,
                "z": -4,
                "elements": [
                    "contenttweaker:arkmachineblock@0"
                ]
            },
            {
                "x": -1,
                "y": 14,
                "z": 5,
                "elements": [
                    "avaritia:block_resource@0"
                ]
            },
            {
                "x": 0,
                "y": 3,
                "z": 8,
                "elements": [
                    "contenttweaker:arkforcefieldcontrolblock@0"
                ]
            },
            {
                "x": -3,
                "y": 12,
                "z": 10,
                "elements": [
                    "contenttweaker:arkmachineblock@0"
                ]
            },
            {
                "x": 6,
                "y": 0,
                "z": 5,
                "elements": [
                    "casings_all",
                    "modularmachinery:blockupgradebus"
                ]
            },
            {
                "x": 5,
                "y": 0,
                "z": 12,
                "elements": [
                    "casings_all",
                    "modularmachinery:blockupgradebus"
                ]
            },
            {
                "x": -3,
                "y": 15,
                "z": 11,
                "elements": [
                    "contenttweaker:arkmachineblock@0"
                ]
            },
            {
                "x": 4,
                "y": 6,
                "z": 0,
                "elements": [
                    "contenttweaker:arkmachineblock@0"
                ]
            },
            {
                "x": 1,
                "y": 0,
                "z": 3,
                "elements": [
                    "contenttweaker:arkmachineblock@0"
                ]
            },
            {
                "x": -2,
                "y": 10,
                "z": 10,
                "elements": [
                    "contenttweaker:arkmachineblock@0"
                ]
            },
            {
                "x": 0,
                "y": 13,
                "z": 11,
                "elements": [
                    "contenttweaker:arkmachineblock@0"
                ]
            },
            {
                "x": 0,
                "y": 4,
                "z": 8,
                "elements": [
                    "contenttweaker:arkforcefieldcontrolblock@0"
                ]
            },
            {
                "x": 6,
                "y": 0,
                "z": 8,
                "elements": [
                    "casings_all",
                    "modularmachinery:blockupgradebus"
                ]
            },
            {
                "x": 9,
                "y": 10,
                "z": -1,
                "elements": [
                    "contenttweaker:arkmachineblock@0"
                ]
            },
            {
                "x": 3,
                "y": 0,
                "z": 10,
                "elements": [
                    "contenttweaker:arkmachineblock@0"
                ]
            },
            {
                "x": 0,
                "y": 8,
                "z": 5,
                "elements": [
                    "avaritia:block_resource@0"
                ]
            },
            {
                "x": 9,
                "y": 11,
                "z": 1,
                "elements": [
                    "contenttweaker:arkmachineblock@0"
                ]
            },
            {
                "x": -3,
                "y": 8,
                "z": 8,
                "elements": [
                    "contenttweaker:arkmachineblock@0"
                ]
            },
            {
                "x": 0,
                "y": 19,
                "z": -2,
                "elements": [
                    "contenttweaker:arkforcefieldcontrolblock@0"
                ]
            },
            {
                "x": 2,
                "y": 4,
                "z": 5,
                "elements": [
                    "contenttweaker:arkforcefieldcontrolblock@0"
                ]
            },
            {
                "x": 9,
                "y": 10,
                "z": 1,
                "elements": [
                    "contenttweaker:arkmachineblock@0"
                ]
            },
            {
                "x": -6,
                "y": 0,
                "z": 8,
                "elements": [
                    "casings_all",
                    "modularmachinery:blockupgradebus"
                ]
            },
            {
                "x": -6,
                "y": 10,
                "z": 8,
                "elements": [
                    "contenttweaker:arkmachineblock@0"
                ]
            },
            {
                "x": 3,
                "y": 0,
                "z": 5,
                "elements": [
                    "contenttweaker:arkmachineblock@0"
                ]
            },
            {
                "x": 9,
                "y": 11,
                "z": -1,
                "elements": [
                    "contenttweaker:arkmachineblock@0"
                ]
            },
            {
                "x": -9,
                "y": 11,
                "z": 4,
                "elements": [
                    "contenttweaker:arkmachineblock@0"
                ]
            },
            {
                "x": 4,
                "y": 0,
                "z": 10,
                "elements": [
                    "contenttweaker:arkmachineblock@0"
                ]
            },
            {
                "x": -6,
                "y": 0,
                "z": 3,
                "elements": [
                    "casings_all",
                    "modularmachinery:blockupgradebus"
                ]
            },
            {
                "x": -1,
                "y": 8,
                "z": 5,
                "elements": [
                    "avaritia:block_resource@0"
                ]
            },
            {
                "x": 2,
                "y": 6,
                "z": 5,
                "elements": [
                    "contenttweaker:arkmachineblock@0"
                ]
            },
            {
                "x": 0,
                "y": 10,
                "z": 10,
                "elements": [
                    "contenttweaker:arkmachineblock@0"
                ]
            },
            {
                "x": 0,
                "y": 17,
                "z": -2,
                "elements": [
                    "avaritiaddons:infinity_glass@7"
                ]
            },
            {
                "x": 1,
                "y": 0,
                "z": 10,
                "elements": [
                    "contenttweaker:arkmachineblock@0"
                ]
            },
            {
                "x": -5,
                "y": 0,
                "z": 3,
                "elements": [
                    "contenttweaker:arkmachineblock@0"
                ]
            },
            {
                "x": 0,
                "y": 0,
                "z": 8,
                "elements": [
                    "contenttweaker:arkmachineblock@0"
                ]
            },
            {
                "x": -6,
                "y": 7,
                "z": 4,
                "elements": [
                    "contenttweaker:arkmachineblock@0"
                ]
            },
            {
                "x": -2,
                "y": 6,
                "z": -4,
                "elements": [
                    "contenttweaker:arkmachineblock@0"
                ]
            },
            {
                "x": -9,
                "y": 13,
                "z": 4,
                "elements": [
                    "contenttweaker:arkmachineblock@0"
                ]
            },
            {
                "x": -1,
                "y": 10,
                "z": 5,
                "elements": [
                    "avaritia:block_resource@0"
                ]
            },
            {
                "x": -6,
                "y": 11,
                "z": 8,
                "elements": [
                    "contenttweaker:arkmachineblock@0"
                ]
            },
            {
                "x": 0,
                "y": 18,
                "z": -2,
                "elements": [
                    "avaritiaddons:infinity_glass@5"
                ]
            },
            {
                "x": -4,
                "y": 0,
                "z": 0,
                "elements": [
                    "casings_all",
                    "modularmachinery:blockupgradebus"
                ]
            },
            {
                "x": -10,
                "y": 14,
                "z": 3,
                "elements": [
                    "contenttweaker:arkmachineblock@0"
                ]
            },
            {
                "x": 10,
                "y": 13,
                "z": 1,
                "elements": [
                    "contenttweaker:arkmachineblock@0"
                ]
            },
            {
                "x": -10,
                "y": 15,
                "z": 4,
                "elements": [
                    "contenttweaker:arkmachineblock@0"
                ]
            },
            {
                "x": -1,
                "y": 6,
                "z": -4,
                "elements": [
                    "contenttweaker:arkmachineblock@0"
                ]
            },
            {
                "x": 0,
                "y": 11,
                "z": 8,
                "elements": [
                    "avaritia:block_resource@0"
                ]
            },
            {
                "x": 3,
                "y": 8,
                "z": 8,
                "elements": [
                    "contenttweaker:arkmachineblock@0"
                ]
            },
            {
                "x": -7,
                "y": 9,
                "z": -3,
                "elements": [
                    "contenttweaker:arkmachineblock@0"
                ]
            },
            {
                "x": -4,
                "y": 7,
                "z": -3,
                "elements": [
                    "contenttweaker:arkmachineblock@0"
                ]
            },
            {
                "x": 6,
                "y": 8,
                "z": 6,
                "elements": [
                    "contenttweaker:arkmachineblock@0"
                ]
            },
            {
                "x": 0,
                "y": 0,
                "z": 3,
                "elements": [
                    "contenttweaker:arkmachineblock@0"
                ]
            },
            {
                "x": 10,
                "y": 12,
                "z": 1,
                "elements": [
                    "contenttweaker:arkmachineblock@0"
                ]
            },
            {
                "x": -2,
                "y": 0,
                "z": 10,
                "elements": [
                    "contenttweaker:arkmachineblock@0"
                ]
            },
            {
                "x": 0,
                "y": 9,
                "z": 8,
                "elements": [
                    "avaritia:block_resource@0"
                ]
            },
            {
                "x": 0,
                "y": 16,
                "z": -2,
                "elements": [
                    "avaritiaddons:infinity_glass@5"
                ]
            },
            {
                "x": -9,
                "y": 10,
                "z": 3,
                "elements": [
                    "contenttweaker:arkmachineblock@0"
                ]
            },
            {
                "x": -6,
                "y": 0,
                "z": 5,
                "elements": [
                    "casings_all",
                    "modularmachinery:blockupgradebus"
                ]
            },
            {
                "x": -3,
                "y": 6,
                "z": 3,
                "elements": [
                    "contenttweaker:arkmachineblock@0"
                ]
            },
            {
                "x": 1,
                "y": 18,
                "z": 0,
                "elements": [
                    "avaritiaddons:infinity_glass@4"
                ]
            },
            {
                "x": 0,
                "y": 10,
                "z": 8,
                "elements": [
                    "avaritia:block_resource@0"
                ]
            },
            {
                "x": 6,
                "y": 7,
                "z": 1,
                "elements": [
                    "contenttweaker:arkmachineblock@0"
                ]
            },
            {
                "x": -3,
                "y": 0,
                "z": 3,
                "elements": [
                    "contenttweaker:arkmachineblock@0"
                ]
            },
            {
                "x": -3,
                "y": 18,
                "z": 10,
                "elements": [
                    "contenttweaker:arkmachineblock@0"
                ]
            },
            {
                "x": -1,
                "y": 9,
                "z": 4,
                "elements": [
                    "avaritia:block_resource@0"
                ]
            },
            {
                "x": 3,
                "y": 19,
                "z": 10,
                "elements": [
                    "contenttweaker:arkmachineblock@0"
                ]
            },
            {
                "x": -1,
                "y": 3,
                "z": 4,
                "elements": [
                    "contenttweaker:arkforcefieldcontrolblock@0"
                ]
            },
            {
                "x": -9,
                "y": 12,
                "z": 3,
                "elements": [
                    "contenttweaker:arkmachineblock@0"
                ]
            },
            {
                "x": 0,
                "y": 6,
                "z": 8,
                "elements": [
                    "contenttweaker:arkforcefieldcontrolblock@0"
                ]
            },
            {
                "x": -6,
                "y": 15,
                "z": 9,
                "elements": [
                    "contenttweaker:arkmachineblock@0"
                ]
            },
            {
                "x": -7,
                "y": 8,
                "z": 3,
                "elements": [
                    "contenttweaker:arkmachineblock@0"
                ]
            },
            {
                "x": 3,
                "y": 6,
                "z": -2,
                "elements": [
                    "contenttweaker:arkmachineblock@0"
                ]
            },
            {
                "x": -4,
                "y": 6,
                "z": 3,
                "elements": [
                    "contenttweaker:arkmachineblock@0"
                ]
            },
            {
                "x": 1,
                "y": 16,
                "z": 0,
                "elements": [
                    "avaritia:block_resource@0"
                ]
            },
            {
                "x": 1,
                "y": 19,
                "z": 1,
                "elements": [
                    "avaritiaddons:infinity_glass@2"
                ]
            },
            {
                "x": 0,
                "y": 7,
                "z": -5,
                "elements": [
                    "contenttweaker:arkmachineblock@0"
                ]
            },
            {
                "x": 0,
                "y": 5,
                "z": 8,
                "elements": [
                    "contenttweaker:arkforcefieldcontrolblock@0"
                ]
            },
            {
                "x": -2,
                "y": 0,
                "z": 3,
                "elements": [
                    "contenttweaker:arkmachineblock@0"
                ]
            },
            {
                "x": 1,
                "y": 18,
                "z": 1,
                "elements": [
                    "avaritiaddons:infinity_glass@0"
                ]
            },
            {
                "x": -1,
                "y": 5,
                "z": 4,
                "elements": [
                    "contenttweaker:arkmachineblock@0"
                ]
            },
            {
                "x": 2,
                "y": 6,
                "z": -4,
                "elements": [
                    "contenttweaker:arkmachineblock@0"
                ]
            },
            {
                "x": 3,
                "y": 17,
                "z": 10,
                "elements": [
                    "contenttweaker:arkmachineblock@0"
                ]
            },
            {
                "x": 1,
                "y": 17,
                "z": 1,
                "elements": [
                    "avaritia:block_resource@0"
                ]
            },
            {
                "x": -5,
                "y": 6,
                "z": 3,
                "elements": [
                    "contenttweaker:arkmachineblock@0"
                ]
            },
            {
                "x": 1,
                "y": 14,
                "z": 0,
                "elements": [
                    "avaritia:block_resource@0"
                ]
            },
            {
                "x": -6,
                "y": 19,
                "z": 8,
                "elements": [
                    "contenttweaker:arkmachineblock@0"
                ]
            },
            {
                "x": 1,
                "y": 1,
                "z": 4,
                "elements": [
                    "contenttweaker:arkforcefieldcontrolblock@0"
                ]
            },
            {
                "x": 0,
                "y": 8,
                "z": 8,
                "elements": [
                    "contenttweaker:arkmachineblock@0"
                ]
            },
            {
                "x": 3,
                "y": 7,
                "z": -5,
                "elements": [
                    "contenttweaker:arkmachineblock@0"
                ]
            },
            {
                "x": -6,
                "y": 13,
                "z": 9,
                "elements": [
                    "contenttweaker:arkmachineblock@0"
                ]
            },
            {
                "x": -1,
                "y": 0,
                "z": 3,
                "elements": [
                    "contenttweaker:arkmachineblock@0"
                ]
            },
            {
                "x": 1,
                "y": 16,
                "z": 1,
                "elements": [
                    "avaritia:block_resource@0"
                ]
            },
            {
                "x": 6,
                "y": 7,
                "z": -2,
                "elements": [
                    "contenttweaker:arkmachineblock@0"
                ]
            },
            {
                "x": 0,
                "y": 7,
                "z": 8,
                "elements": [
                    "contenttweaker:arkforcefieldcontrolblock@0"
                ]
            },
            {
                "x": 7,
                "y": 8,
                "z": 0,
                "elements": [
                    "contenttweaker:arkmachineblock@0"
                ]
            },
            {
                "x": 8,
                "y": 11,
                "z": 5,
                "elements": [
                    "contenttweaker:arkmachineblock@0"
                ]
            },
            {
                "x": 1,
                "y": 3,
                "z": 4,
                "elements": [
                    "contenttweaker:arkforcefieldcontrolblock@0"
                ]
            },
            {
                "x": 1,
                "y": 19,
                "z": 10,
                "elements": [
                    "contenttweaker:arkmachineblock@0"
                ]
            },
            {
                "x": 2,
                "y": 2,
                "z": 6,
                "elements": [
                    "contenttweaker:arkforcefieldcontrolblock@0"
                ]
            },
            {
                "x": 0,
                "y": 5,
                "z": 2,
                "elements": [
                    "contenttweaker:arkmachineblock@0"
                ]
            },
            {
                "x": 4,
                "y": 0,
                "z": 11,
                "elements": [
                    "contenttweaker:arkmachineblock@0"
                ]
            },
            {
                "x": 1,
                "y": 20,
                "z": 10,
                "elements": [
                    "contenttweaker:arkmachineblock@0"
                ]
            },
            {
                "x": 3,
                "y": 13,
                "z": 10,
                "elements": [
                    "contenttweaker:arkmachineblock@0"
                ]
            },
            {
                "x": -3,
                "y": 10,
                "z": 9,
                "elements": [
                    "contenttweaker:arkmachineblock@0"
                ]
            },
            {
                "x": -7,
                "y": 12,
                "z": 8,
                "elements": [
                    "contenttweaker:arkmachineblock@0"
                ]
            },
            {
                "x": -1,
                "y": 8,
                "z": 8,
                "elements": [
                    "contenttweaker:arkmachineblock@0"
                ]
            },
            {
                "x": -7,
                "y": 14,
                "z": 8,
                "elements": [
                    "contenttweaker:arkmachineblock@0"
                ]
            },
            {
                "x": 1,
                "y": 14,
                "z": 1,
                "elements": [
                    "avaritia:block_resource@0"
                ]
            },
            {
                "x": 10,
                "y": 16,
                "z": 4,
                "elements": [
                    "contenttweaker:arkmachineblock@0"
                ]
            },
            {
                "x": 1,
                "y": 15,
                "z": -1,
                "elements": [
                    "avaritia:block_resource@0"
                ]
            },
            {
                "x": 10,
                "y": 15,
                "z": 4,
                "elements": [
                    "contenttweaker:arkmachineblock@0"
                ]
            },
            {
                "x": 1,
                "y": 4,
                "z": 4,
                "elements": [
                    "contenttweaker:arkforcefieldcontrolblock@0"
                ]
            },
            {
                "x": 0,
                "y": 16,
                "z": 1,
                "elements": [
                    "avaritia:block_resource@0"
                ]
            },
            {
                "x": -7,
                "y": 10,
                "z": 6,
                "elements": [
                    "contenttweaker:arkmachineblock@0"
                ]
            },
            {
                "x": -3,
                "y": 9,
                "z": 9,
                "elements": [
                    "contenttweaker:arkmachineblock@0"
                ]
            },
            {
                "x": -1,
                "y": 6,
                "z": 6,
                "elements": [
                    "contenttweaker:arkmachineblock@0"
                ]
            },
            {
                "x": -1,
                "y": 3,
                "z": 7,
                "elements": [
                    "contenttweaker:arkforcefieldcontrolblock@0"
                ]
            },
            {
                "x": -7,
                "y": 16,
                "z": 8,
                "elements": [
                    "contenttweaker:arkmachineblock@0"
                ]
            },
            {
                "x": -1,
                "y": 6,
                "z": 8,
                "elements": [
                    "contenttweaker:arkforcefieldcontrolblock@0"
                ]
            },
            {
                "x": 0,
                "y": 19,
                "z": 10,
                "elements": [
                    "contenttweaker:arkmachineblock@0"
                ]
            },
            {
                "x": 1,
                "y": 12,
                "z": 1,
                "elements": [
                    "avaritia:block_resource@0"
                ]
            },
            {
                "x": -5,
                "y": 0,
                "z": 8,
                "elements": [
                    "contenttweaker:arkmachineblock@0"
                ]
            },
            {
                "x": 0,
                "y": 20,
                "z": 10,
                "elements": [
                    "contenttweaker:arkmachineblock@0"
                ]
            },
            {
                "x": -2,
                "y": 0,
                "z": 8,
                "elements": [
                    "contenttweaker:arkmachineblock@0"
                ]
            },
            {
                "x": -1,
                "y": 8,
                "z": 6,
                "elements": [
                    "avaritia:block_resource@0"
                ]
            },
            {
                "x": -1,
                "y": 5,
                "z": 7,
                "elements": [
                    "contenttweaker:arkforcefieldcontrolblock@0"
                ]
            },
            {
                "x": 4,
                "y": 13,
                "z": 10,
                "elements": [
                    "contenttweaker:arkmachineblock@0"
                ]
            },
            {
                "x": 1,
                "y": 5,
                "z": 4,
                "elements": [
                    "contenttweaker:arkmachineblock@0"
                ]
            },
            {
                "x": 0,
                "y": 18,
                "z": 1,
                "elements": [
                    "avaritiaddons:infinity_glass@1"
                ]
            },
            {
                "x": 2,
                "y": 5,
                "z": -1,
                "elements": [
                    "contenttweaker:arkmachineblock@0"
                ]
            },
            {
                "x": 2,
                "y": 6,
                "z": 6,
                "elements": [
                    "contenttweaker:arkmachineblock@0"
                ]
            },
            {
                "x": 4,
                "y": 0,
                "z": 4,
                "elements": [
                    "contenttweaker:arkmachineblock@0"
                ]
            },
            {
                "x": -1,
                "y": 1,
                "z": 7,
                "elements": [
                    "contenttweaker:arkforcefieldcontrolblock@0"
                ]
            },
            {
                "x": 10,
                "y": 13,
                "z": 3,
                "elements": [
                    "contenttweaker:arkmachineblock@0"
                ]
            },
            {
                "x": -1,
                "y": 4,
                "z": 6,
                "elements": [
                    "contenttweaker:arkforcefieldcontrolblock@0"
                ]
            },
            {
                "x": 0,
                "y": 12,
                "z": 1,
                "elements": [
                    "avaritia:block_resource@0"
                ]
            },
            {
                "x": 3,
                "y": 0,
                "z": 9,
                "elements": [
                    "contenttweaker:arkmachineblock@0"
                ]
            },
            {
                "x": -2,
                "y": 14,
                "z": 11,
                "elements": [
                    "contenttweaker:arkmachineblock@0"
                ]
            },
            {
                "x": 4,
                "y": 6,
                "z": 4,
                "elements": [
                    "contenttweaker:arkmachineblock@0"
                ]
            },
            {
                "x": 8,
                "y": 9,
                "z": 0,
                "elements": [
                    "contenttweaker:arkmachineblock@0"
                ]
            },
            {
                "x": 1,
                "y": 0,
                "z": 8,
                "elements": [
                    "contenttweaker:arkmachineblock@0"
                ]
            },
            {
                "x": -1,
                "y": 15,
                "z": -1,
                "elements": [
                    "avaritia:block_resource@0"
                ]
            },
            {
                "x": 2,
                "y": 1,
                "z": 7,
                "elements": [
                    "contenttweaker:arkforcefieldcontrolblock@0"
                ]
            },
            {
                "x": -1,
                "y": 4,
                "z": 8,
                "elements": [
                    "contenttweaker:arkforcefieldcontrolblock@0"
                ]
            },
            {
                "x": 4,
                "y": 6,
                "z": 1,
                "elements": [
                    "contenttweaker:arkmachineblock@0"
                ]
            },
            {
                "x": -2,
                "y": 15,
                "z": 11,
                "elements": [
                    "contenttweaker:arkmachineblock@0"
                ]
            },
            {
                "x": 3,
                "y": 12,
                "z": 10,
                "elements": [
                    "contenttweaker:arkmachineblock@0"
                ]
            },
            {
                "x": -6,
                "y": 7,
                "z": 2,
                "elements": [
                    "contenttweaker:arkmachineblock@0"
                ]
            },
            {
                "x": 7,
                "y": 9,
                "z": 5,
                "elements": [
                    "contenttweaker:arkmachineblock@0"
                ]
            },
            {
                "x": 1,
                "y": 10,
                "z": 4,
                "elements": [
                    "avaritia:block_resource@0"
                ]
            },
            {
                "x": 10,
                "y": 15,
                "z": 3,
                "elements": [
                    "contenttweaker:arkmachineblock@0"
                ]
            },
            {
                "x": 2,
                "y": 0,
                "z": 6,
                "elements": [
                    "contenttweaker:arkmachineblock@0"
                ]
            },
            {
                "x": -1,
                "y": 2,
                "z": 6,
                "elements": [
                    "contenttweaker:arkforcefieldcontrolblock@0"
                ]
            },
            {
                "x": 0,
                "y": 14,
                "z": 1,
                "elements": [
                    "avaritia:block_resource@0"
                ]
            },
            {
                "x": 6,
                "y": 0,
                "z": 9,
                "elements": [
                    "casings_all",
                    "modularmachinery:blockupgradebus"
                ]
            },
            {
                "x": 5,
                "y": 8,
                "z": 6,
                "elements": [
                    "contenttweaker:arkmachineblock@0"
                ]
            },
            {
                "x": 1,
                "y": 16,
                "z": 3,
                "elements": [
                    "avaritia:block_resource@0"
                ]
            },
            {
                "x": -2,
                "y": 13,
                "z": 11,
                "elements": [
                    "contenttweaker:arkmachineblock@0"
                ]
            },
            {
                "x": 1,
                "y": 9,
                "z": 4,
                "elements": [
                    "avaritia:block_resource@0"
                ]
            },
            {
                "x": 10,
                "y": 14,
                "z": 3,
                "elements": [
                    "contenttweaker:arkmachineblock@0"
                ]
            },
            {
                "x": 3,
                "y": 11,
                "z": 10,
                "elements": [
                    "contenttweaker:arkmachineblock@0"
                ]
            },
            {
                "x": -9,
                "y": 11,
                "z": 2,
                "elements": [
                    "contenttweaker:arkmachineblock@0"
                ]
            },
            {
                "x": -1,
                "y": 2,
                "z": 8,
                "elements": [
                    "contenttweaker:arkforcefieldcontrolblock@0"
                ]
            },
            {
                "x": 1,
                "y": 13,
                "z": 4,
                "elements": [
                    "avaritia:block_resource@0"
                ]
            },
            {
                "x": 1,
                "y": 15,
                "z": 3,
                "elements": [
                    "avaritia:block_resource@0"
                ]
            },
            {
                "x": -1,
                "y": 11,
                "z": 7,
                "elements": [
                    "avaritia:block_resource@0"
                ]
            },
            {
                "x": 4,
                "y": 17,
                "z": 10,
                "elements": [
                    "contenttweaker:arkmachineblock@0"
                ]
            },
            {
                "x": 1,
                "y": 12,
                "z": 11,
                "elements": [
                    "contenttweaker:arkmachineblock@0"
                ]
            },
            {
                "x": 1,
                "y": 10,
                "z": 10,
                "elements": [
                    "contenttweaker:arkmachineblock@0"
                ]
            },
            {
                "x": 7,
                "y": 8,
                "z": 4,
                "elements": [
                    "contenttweaker:arkmachineblock@0"
                ]
            },
            {
                "x": 1,
                "y": 12,
                "z": 3,
                "elements": [
                    "avaritia:block_resource@0"
                ]
            },
            {
                "x": 1,
                "y": 7,
                "z": 7,
                "elements": [
                    "contenttweaker:arkmachineblock@0"
                ]
            },
            {
                "x": 1,
                "y": 0,
                "z": 1,
                "elements": [
                    "contenttweaker:arkmachineblock@0"
                ]
            },
            {
                "x": 4,
                "y": 18,
                "z": 10,
                "elements": [
                    "contenttweaker:arkmachineblock@0"
                ]
            },
            {
                "x": 1,
                "y": 14,
                "z": 3,
                "elements": [
                    "avaritia:block_resource@0"
                ]
            },
            {
                "x": -1,
                "y": 0,
                "z": 8,
                "elements": [
                    "contenttweaker:arkmachineblock@0"
                ]
            },
            {
                "x": 2,
                "y": 5,
                "z": 7,
                "elements": [
                    "contenttweaker:arkforcefieldcontrolblock@0"
                ]
            },
            {
                "x": 1,
                "y": 13,
                "z": 11,
                "elements": [
                    "contenttweaker:arkmachineblock@0"
                ]
            },
            {
                "x": 1,
                "y": 14,
                "z": 4,
                "elements": [
                    "avaritia:block_resource@0"
                ]
            },
            {
                "x": 6,
                "y": 0,
                "z": 10,
                "elements": [
                    "casings_all",
                    "modularmachinery:blockupgradebus"
                ]
            },
            {
                "x": 1,
                "y": 13,
                "z": 3,
                "elements": [
                    "avaritia:block_resource@0"
                ]
            },
            {
                "x": -2,
                "y": 16,
                "z": 11,
                "elements": [
                    "contenttweaker:arkmachineblock@0"
                ]
            },
            {
                "x": -3,
                "y": 5,
                "z": 2,
                "elements": [
                    "contenttweaker:arkmachineblock@0"
                ]
            },
            {
                "x": 1,
                "y": 11,
                "z": 4,
                "elements": [
                    "avaritia:block_resource@0"
                ]
            },
            {
                "x": 0,
                "y": 0,
                "z": 9,
                "elements": [
                    "contenttweaker:arkmachineblock@0"
                ]
            },
            {
                "x": 1,
                "y": 9,
                "z": 7,
                "elements": [
                    "avaritia:block_resource@0"
                ]
            },
            {
                "x": 4,
                "y": 0,
                "z": 1,
                "elements": [
                    "contenttweaker:arkmachineblock@0"
                ]
            },
            {
                "x": 1,
                "y": 15,
                "z": 11,
                "elements": [
                    "contenttweaker:arkmachineblock@0"
                ]
            },
            {
                "x": 1,
                "y": 14,
                "z": 11,
                "elements": [
                    "contenttweaker:arkmachineblock@0"
                ]
            },
            {
                "x": -5,
                "y": 6,
                "z": 1,
                "elements": [
                    "contenttweaker:arkmachineblock@0"
                ]
            },
            {
                "x": 1,
                "y": 12,
                "z": 4,
                "elements": [
                    "avaritia:block_resource@0"
                ]
            },
            {
                "x": -2,
                "y": 17,
                "z": 11,
                "elements": [
                    "contenttweaker:arkmachineblock@0"
                ]
            },
            {
                "x": -7,
                "y": 19,
                "z": 7,
                "elements": [
                    "contenttweaker:arkmachineblock@0"
                ]
            },
            {
                "x": 1,
                "y": 11,
                "z": 10,
                "elements": [
                    "contenttweaker:arkmachineblock@0"
                ]
            },
            {
                "x": -3,
                "y": 6,
                "z": -2,
                "elements": [
                    "contenttweaker:arkmachineblock@0"
                ]
            },
            {
                "x": 4,
                "y": 6,
                "z": 3,
                "elements": [
                    "contenttweaker:arkmachineblock@0"
                ]
            },
            {
                "x": 2,
                "y": 3,
                "z": 7,
                "elements": [
                    "contenttweaker:arkforcefieldcontrolblock@0"
                ]
            },
            {
                "x": 5,
                "y": 0,
                "z": 6,
                "elements": [
                    "contenttweaker:arkmachineblock@0"
                ]
            },
            {
                "x": 1,
                "y": 19,
                "z": -1,
                "elements": [
                    "avaritiaddons:infinity_glass@2"
                ]
            },
            {
                "x": 4,
                "y": 12,
                "z": 10,
                "elements": [
                    "contenttweaker:arkmachineblock@0"
                ]
            },
            {
                "x": 1,
                "y": 16,
                "z": 11,
                "elements": [
                    "contenttweaker:arkmachineblock@0"
                ]
            },
            {
                "x": -5,
                "y": 0,
                "z": 1,
                "elements": [
                    "contenttweaker:arkmachineblock@0"
                ]
            },
            {
                "x": -2,
                "y": 5,
                "z": 2,
                "elements": [
                    "contenttweaker:arkmachineblock@0"
                ]
            },
            {
                "x": 1,
                "y": 11,
                "z": 7,
                "elements": [
                    "avaritia:block_resource@0"
                ]
            },
            {
                "x": -1,
                "y": 7,
                "z": 7,
                "elements": [
                    "contenttweaker:arkmachineblock@0"
                ]
            },
            {
                "x": -3,
                "y": 0,
                "z": 8,
                "elements": [
                    "contenttweaker:arkmachineblock@0"
                ]
            },
            {
                "x": -1,
                "y": 10,
                "z": 6,
                "elements": [
                    "avaritia:block_resource@0"
                ]
            },
            {
                "x": 1,
                "y": 17,
                "z": 11,
                "elements": [
                    "contenttweaker:arkmachineblock@0"
                ]
            },
            {
                "x": -2,
                "y": 18,
                "z": 10,
                "elements": [
                    "contenttweaker:arkmachineblock@0"
                ]
            },
            {
                "x": 4,
                "y": 14,
                "z": 10,
                "elements": [
                    "contenttweaker:arkmachineblock@0"
                ]
            },
            {
                "x": 2,
                "y": 4,
                "z": 6,
                "elements": [
                    "contenttweaker:arkforcefieldcontrolblock@0"
                ]
            },
            {
                "x": -8,
                "y": 10,
                "z": -2,
                "elements": [
                    "contenttweaker:arkmachineblock@0"
                ]
            },
            {
                "x": -6,
                "y": 0,
                "z": 9,
                "elements": [
                    "casings_all",
                    "modularmachinery:blockupgradebus"
                ]
            },
            {
                "x": -2,
                "y": 6,
                "z": -2,
                "elements": [
                    "contenttweaker:arkmachineblock@0"
                ]
            },
            {
                "x": 10,
                "y": 14,
                "z": 4,
                "elements": [
                    "contenttweaker:arkmachineblock@0"
                ]
            },
            {
                "x": -2,
                "y": 19,
                "z": 10,
                "elements": [
                    "contenttweaker:arkmachineblock@0"
                ]
            },
            {
                "x": -1,
                "y": 12,
                "z": 6,
                "elements": [
                    "avaritia:block_resource@0"
                ]
            },
            {
                "x": 4,
                "y": 15,
                "z": 10,
                "elements": [
                    "contenttweaker:arkmachineblock@0"
                ]
            },
            {
                "x": 1,
                "y": 15,
                "z": 4,
                "elements": [
                    "avaritia:block_resource@0"
                ]
            },
            {
                "x": -1,
                "y": 9,
                "z": 7,
                "elements": [
                    "avaritia:block_resource@0"
                ]
            },
            {
                "x": -5,
                "y": 17,
                "z": 10,
                "elements": [
                    "contenttweaker:arkmachineblock@0"
                ]
            },
            {
                "x": 2,
                "y": 7,
                "z": 7,
                "elements": [
                    "contenttweaker:arkmachineblock@0"
                ]
            },
            {
                "x": -4,
                "y": 0,
                "z": 8,
                "elements": [
                    "contenttweaker:arkmachineblock@0"
                ]
            },
            {
                "x": -2,
                "y": 20,
                "z": 10,
                "elements": [
                    "contenttweaker:arkmachineblock@0"
                ]
            },
            {
                "x": 4,
                "y": 16,
                "z": 10,
                "elements": [
                    "contenttweaker:arkmachineblock@0"
                ]
            },
            {
                "x": 1,
                "y": 11,
                "z": 3,
                "elements": [
                    "avaritia:block_resource@0"
                ]
            },
            {
                "x": 1,
                "y": 10,
                "z": 3,
                "elements": [
                    "avaritia:block_resource@0"
                ]
            },
            {
                "x": -8,
                "y": 9,
                "z": 2,
                "elements": [
                    "contenttweaker:arkmachineblock@0"
                ]
            },
            {
                "x": 1,
                "y": 17,
                "z": -1,
                "elements": [
                    "avaritiaddons:infinity_glass@2"
                ]
            },
            {
                "x": 1,
                "y": 18,
                "z": 11,
                "elements": [
                    "contenttweaker:arkmachineblock@0"
                ]
            },
            {
                "x": -10,
                "y": 12,
                "z": 1,
                "elements": [
                    "contenttweaker:arkmachineblock@0"
                ]
            },
            {
                "x": -3,
                "y": 0,
                "z": 1,
                "elements": [
                    "contenttweaker:arkmachineblock@0"
                ]
            },
            {
                "x": 1,
                "y": 1,
                "z": 7,
                "elements": [
                    "contenttweaker:arkforcefieldcontrolblock@0"
                ]
            },
            {
                "x": -1,
                "y": 16,
                "z": 0,
                "elements": [
                    "avaritia:block_resource@0"
                ]
            },
            {
                "x": 3,
                "y": 0,
                "z": 6,
                "elements": [
                    "contenttweaker:arkmachineblock@0"
                ]
            },
            {
                "x": -1,
                "y": 5,
                "z": -1,
                "elements": [
                    "contenttweaker:arkmachineblock@0"
                ]
            },
            {
                "x": 5,
                "y": 6,
                "z": 0,
                "elements": [
                    "contenttweaker:arkmachineblock@0"
                ]
            },
            {
                "x": -2,
                "y": 21,
                "z": 9,
                "elements": [
                    "contenttweaker:arkmachineblock@0"
                ]
            },
            {
                "x": 0,
                "y": 17,
                "z": 2,
                "elements": [
                    "avaritia:block_resource@0"
                ]
            },
            {
                "x": -6,
                "y": 8,
                "z": 6,
                "elements": [
                    "contenttweaker:arkmachineblock@0"
                ]
            },
            {
                "x": -2,
                "y": 5,
                "z": 7,
                "elements": [
                    "contenttweaker:arkforcefieldcontrolblock@0"
                ]
            },
            {
                "x": -7,
                "y": 8,
                "z": 1,
                "elements": [
                    "contenttweaker:arkmachineblock@0"
                ]
            },
            {
                "x": -1,
                "y": 15,
                "z": 0,
                "elements": [
                    "avaritia:block_resource@0"
                ]
            },
            {
                "x": 1,
                "y": 8,
                "z": 5,
                "elements": [
                    "avaritia:block_resource@0"
                ]
            },
            {
                "x": 6,
                "y": 12,
                "z": 9,
                "elements": [
                    "contenttweaker:arkmachineblock@0"
                ]
            },
            {
                "x": -6,
                "y": 7,
                "z": -1,
                "elements": [
                    "contenttweaker:arkmachineblock@0"
                ]
            },
            {
                "x": -8,
                "y": 18,
                "z": 6,
                "elements": [
                    "contenttweaker:arkmachineblock@0"
                ]
            },
            {
                "x": 6,
                "y": 8,
                "z": -3,
                "elements": [
                    "contenttweaker:arkmachineblock@0"
                ]
            },
            {
                "x": -1,
                "y": 14,
                "z": 0,
                "elements": [
                    "avaritia:block_resource@0"
                ]
            },
            {
                "x": -8,
                "y": 15,
                "z": 7,
                "elements": [
                    "contenttweaker:arkmachineblock@0"
                ]
            },
            {
                "x": 1,
                "y": 9,
                "z": 5,
                "elements": [
                    "avaritia:block_resource@0"
                ]
            },
            {
                "x": 0,
                "y": 0,
                "z": 6,
                "elements": [
                    "contenttweaker:arkmachineblock@0"
                ]
            },
            {
                "x": 0,
                "y": 0,
                "z": 1,
                "elements": [
                    "contenttweaker:arkmachineblock@0"
                ]
            },
            {
                "x": -5,
                "y": 20,
                "z": 8,
                "elements": [
                    "contenttweaker:arkmachineblock@0"
                ]
            },
            {
                "x": 7,
                "y": 13,
                "z": 8,
                "elements": [
                    "contenttweaker:arkmachineblock@0"
                ]
            },
            {
                "x": -8,
                "y": 17,
                "z": 7,
                "elements": [
                    "contenttweaker:arkmachineblock@0"
                ]
            },
            {
                "x": -1,
                "y": 13,
                "z": 0,
                "elements": [
                    "avaritia:block_resource@0"
                ]
            },
            {
                "x": 1,
                "y": 10,
                "z": 5,
                "elements": [
                    "avaritia:block_resource@0"
                ]
            },
            {
                "x": -2,
                "y": 3,
                "z": 7,
                "elements": [
                    "contenttweaker:arkforcefieldcontrolblock@0"
                ]
            },
            {
                "x": 6,
                "y": 15,
                "z": 9,
                "elements": [
                    "contenttweaker:arkmachineblock@0"
                ]
            },
            {
                "x": -1,
                "y": 0,
                "z": 1,
                "elements": [
                    "contenttweaker:arkmachineblock@0"
                ]
            },
            {
                "x": 0,
                "y": 2,
                "z": 6,
                "elements": [
                    "contenttweaker:space_time_coil@0"
                ]
            },
            {
                "x": -1,
                "y": 19,
                "z": 0,
                "elements": [
                    "avaritiaddons:infinity_glass@6"
                ]
            },
            {
                "x": 1,
                "y": 11,
                "z": 5,
                "elements": [
                    "avaritia:block_resource@0"
                ]
            },
            {
                "x": -8,
                "y": 13,
                "z": 7,
                "elements": [
                    "contenttweaker:arkmachineblock@0"
                ]
            },
            {
                "x": 3,
                "y": 20,
                "z": 9,
                "elements": [
                    "contenttweaker:arkmachineblock@0"
                ]
            },
            {
                "x": 7,
                "y": 15,
                "z": 8,
                "elements": [
                    "contenttweaker:arkmachineblock@0"
                ]
            },
            {
                "x": -4,
                "y": 6,
                "z": 1,
                "elements": [
                    "contenttweaker:arkmachineblock@0"
                ]
            },
            {
                "x": 1,
                "y": 12,
                "z": 5,
                "elements": [
                    "avaritia:block_resource@0"
                ]
            },
            {
                "x": 4,
                "y": 11,
                "z": 9,
                "elements": [
                    "contenttweaker:arkmachineblock@0"
                ]
            },
            {
                "x": 1,
                "y": 10,
                "z": 8,
                "elements": [
                    "avaritia:block_resource@0"
                ]
            },
            {
                "x": 6,
                "y": 16,
                "z": 9,
                "elements": [
                    "contenttweaker:arkmachineblock@0"
                ]
            },
            {
                "x": 0,
                "y": 21,
                "z": 9,
                "elements": [
                    "contenttweaker:arkmachineblock@0"
                ]
            },
            {
                "x": -4,
                "y": 6,
                "z": -2,
                "elements": [
                    "contenttweaker:arkmachineblock@0"
                ]
            },
            {
                "x": 1,
                "y": 3,
                "z": 7,
                "elements": [
                    "contenttweaker:arkforcefieldcontrolblock@0"
                ]
            },
            {
                "x": -2,
                "y": 0,
                "z": 1,
                "elements": [
                    "contenttweaker:arkmachineblock@0"
                ]
            },
            {
                "x": 7,
                "y": 17,
                "z": 8,
                "elements": [
                    "contenttweaker:arkmachineblock@0"
                ]
            },
            {
                "x": -7,
                "y": 8,
                "z": -2,
                "elements": [
                    "contenttweaker:arkmachineblock@0"
                ]
            },
            {
                "x": 0,
                "y": 4,
                "z": 6,
                "elements": [
                    "contenttweaker:space_time_coil@0"
                ]
            },
            {
                "x": 4,
                "y": 10,
                "z": 9,
                "elements": [
                    "contenttweaker:arkmachineblock@0"
                ]
            },
            {
                "x": 2,
                "y": 6,
                "z": -2,
                "elements": [
                    "contenttweaker:arkmachineblock@0"
                ]
            },
            {
                "x": 1,
                "y": 14,
                "z": 5,
                "elements": [
                    "avaritia:block_resource@0"
                ]
            },
            {
                "x": 6,
                "y": 13,
                "z": 9,
                "elements": [
                    "contenttweaker:arkmachineblock@0"
                ]
            },
            {
                "x": -5,
                "y": 10,
                "z": 8,
                "elements": [
                    "contenttweaker:arkmachineblock@0"
                ]
            },
            {
                "x": 6,
                "y": 14,
                "z": 9,
                "elements": [
                    "contenttweaker:arkmachineblock@0"
                ]
            },
            {
                "x": -2,
                "y": 7,
                "z": 7,
                "elements": [
                    "contenttweaker:arkmachineblock@0"
                ]
            },
            {
                "x": 1,
                "y": 5,
                "z": 7,
                "elements": [
                    "contenttweaker:arkforcefieldcontrolblock@0"
                ]
            },
            {
                "x": -6,
                "y": 0,
                "z": 6,
                "elements": [
                    "casings_all",
                    "modularmachinery:blockupgradebus"
                ]
            },
            {
                "x": -1,
                "y": 18,
                "z": 0,
                "elements": [
                    "avaritiaddons:infinity_glass@4"
                ]
            },
            {
                "x": -3,
                "y": 21,
                "z": 9,
                "elements": [
                    "contenttweaker:arkmachineblock@0"
                ]
            },
            {
                "x": 4,
                "y": 21,
                "z": 8,
                "elements": [
                    "contenttweaker:arkmachineblock@0"
                ]
            },
            {
                "x": -1,
                "y": 17,
                "z": 0,
                "elements": [
                    "avaritiaddons:infinity_glass@6"
                ]
            },
            {
                "x": 1,
                "y": 13,
                "z": 5,
                "elements": [
                    "avaritia:block_resource@0"
                ]
            },
            {
                "x": 0,
                "y": 15,
                "z": 2,
                "elements": [
                    "avaritia:block_resource@0"
                ]
            },
            {
                "x": 1,
                "y": 4,
                "z": 8,
                "elements": [
                    "contenttweaker:arkforcefieldcontrolblock@0"
                ]
            },
            {
                "x": 1,
                "y": 0,
                "z": 5,
                "elements": [
                    "contenttweaker:arkmachineblock@0"
                ]
            },
            {
                "x": -1,
                "y": 0,
                "z": 6,
                "elements": [
                    "contenttweaker:arkmachineblock@0"
                ]
            },
            {
                "x": 1,
                "y": 2,
                "z": 5,
                "elements": [
                    "contenttweaker:arkforcefieldcontrolblock@0"
                ]
            },
            {
                "x": -3,
                "y": 20,
                "z": 9,
                "elements": [
                    "contenttweaker:arkmachineblock@0"
                ]
            },
            {
                "x": -2,
                "y": 2,
                "z": 6,
                "elements": [
                    "contenttweaker:arkforcefieldcontrolblock@0"
                ]
            },
            {
                "x": -9,
                "y": 14,
                "z": 6,
                "elements": [
                    "contenttweaker:arkmachineblock@0"
                ]
            },
            {
                "x": -8,
                "y": 12,
                "z": 6,
                "elements": [
                    "contenttweaker:arkmachineblock@0"
                ]
            },
            {
                "x": 7,
                "y": 8,
                "z": 3,
                "elements": [
                    "contenttweaker:arkmachineblock@0"
                ]
            },
            {
                "x": 3,
                "y": 5,
                "z": 2,
                "elements": [
                    "contenttweaker:arkmachineblock@0"
                ]
            },
            {
                "x": 1,
                "y": 1,
                "z": 5,
                "elements": [
                    "contenttweaker:arkforcefieldcontrolblock@0"
                ]
            },
            {
                "x": -4,
                "y": 0,
                "z": 1,
                "elements": [
                    "contenttweaker:arkmachineblock@0"
                ]
            },
            {
                "x": -2,
                "y": 1,
                "z": 7,
                "elements": [
                    "contenttweaker:arkforcefieldcontrolblock@0"
                ]
            },
            {
                "x": 4,
                "y": 20,
                "z": 9,
                "elements": [
                    "contenttweaker:arkmachineblock@0"
                ]
            },
            {
                "x": -2,
                "y": 4,
                "z": 6,
                "elements": [
                    "contenttweaker:arkforcefieldcontrolblock@0"
                ]
            },
            {
                "x": 1,
                "y": 11,
                "z": 2,
                "elements": [
                    "avaritia:block_resource@0"
                ]
            },
            {
                "x": -9,
                "y": 16,
                "z": 6,
                "elements": [
                    "contenttweaker:arkmachineblock@0"
                ]
            },
            {
                "x": 0,
                "y": 13,
                "z": 2,
                "elements": [
                    "avaritia:block_resource@0"
                ]
            },
            {
                "x": -2,
                "y": 8,
                "z": 8,
                "elements": [
                    "contenttweaker:arkmachineblock@0"
                ]
            },
            {
                "x": 4,
                "y": 7,
                "z": 5,
                "elements": [
                    "contenttweaker:arkmachineblock@0"
                ]
            },
            {
                "x": -2,
                "y": 5,
                "z": -1,
                "elements": [
                    "contenttweaker:arkmachineblock@0"
                ]
            },
            {
                "x": 2,
                "y": 0,
                "z": 8,
                "elements": [
                    "contenttweaker:arkmachineblock@0"
                ]
            },
            {
                "x": -4,
                "y": 0,
                "z": 6,
                "elements": [
                    "contenttweaker:arkmachineblock@0"
                ]
            },
            {
                "x": -8,
                "y": 9,
                "z": -1,
                "elements": [
                    "contenttweaker:arkmachineblock@0"
                ]
            },
            {
                "x": 1,
                "y": 2,
                "z": 8,
                "elements": [
                    "contenttweaker:arkforcefieldcontrolblock@0"
                ]
            },
            {
                "x": 4,
                "y": 19,
                "z": 9,
                "elements": [
                    "contenttweaker:arkmachineblock@0"
                ]
            },
            {
                "x": -5,
                "y": 8,
                "z": 6,
                "elements": [
                    "contenttweaker:arkmachineblock@0"
                ]
            },
            {
                "x": 1,
                "y": 6,
                "z": 5,
                "elements": [
                    "contenttweaker:arkmachineblock@0"
                ]
            },
            {
                "x": -1,
                "y": 16,
                "z": -2,
                "elements": [
                    "avaritiaddons:infinity_glass@4"
                ]
            },
            {
                "x": 3,
                "y": 10,
                "z": 9,
                "elements": [
                    "contenttweaker:arkmachineblock@0"
                ]
            },
            {
                "x": 0,
                "y": 11,
                "z": 2,
                "elements": [
                    "avaritia:block_resource@0"
                ]
            },
            {
                "x": -3,
                "y": 0,
                "z": 6,
                "elements": [
                    "contenttweaker:arkmachineblock@0"
                ]
            },
            {
                "x": -7,
                "y": 11,
                "z": 7,
                "elements": [
                    "contenttweaker:arkmachineblock@0"
                ]
            },
            {
                "x": -2,
                "y": 4,
                "z": 5,
                "elements": [
                    "contenttweaker:arkforcefieldcontrolblock@0"
                ]
            },
            {
                "x": 3,
                "y": 0,
                "z": 1,
                "elements": [
                    "contenttweaker:arkmachineblock@0"
                ]
            },
            {
                "x": 1,
                "y": 8,
                "z": 8,
                "elements": [
                    "contenttweaker:arkmachineblock@0"
                ]
            },
            {
                "x": -6,
                "y": 9,
                "z": 7,
                "elements": [
                    "contenttweaker:arkmachineblock@0"
                ]
            },
            {
                "x": 6,
                "y": 7,
                "z": 2,
                "elements": [
                    "contenttweaker:arkmachineblock@0"
                ]
            },
            {
                "x": 3,
                "y": 9,
                "z": 9,
                "elements": [
                    "contenttweaker:arkmachineblock@0"
                ]
            },
            {
                "x": 1,
                "y": 5,
                "z": 5,
                "elements": [
                    "contenttweaker:arkforcefieldcontrolblock@0"
                ]
            },
            {
                "x": 5,
                "y": 0,
                "z": 8,
                "elements": [
                    "contenttweaker:arkmachineblock@0"
                ]
            },
            {
                "x": 1,
                "y": 5,
                "z": 2,
