{
    "registryname": "obsidian_generate",
    "localizedname": "§6黑曜石熔炼机",
    "failure-action": "still",
    "requires-blueprint": false,
    "has-factory": false,
    "parts": [
        {
            "x": 2,
            "y": 0,
            "z": 0,
            "elements": [
                "tconstruct:clear_glass@0"
            ]
        },
        {
            "x": 4,
            "y": 0,
            "z": 0,
            "elements": [
                "ic2:resource@12"
            ]
        },
        {
            "x": 2,
            "y": 1,
            "z": 2,
            "elements": [
                "modularmachinery:blockparallelcontroller",
                "modularmachinery:blockcasing@4"
            ]
        },
        {
            "x": 4,
            "y": -1,
            "z": 2,
            "elements": [
                "ic2:resource@12"
            ]
        },
        {
            "x": 4,
            "y": 1,
            "z": 2,
            "elements": [
                "ic2:resource@12"
            ]
        },
        {
            "x": 3,
            "y": 0,
            "z": 1,
            "elements": [
                "minecraft:water@0"
            ]
        },
        {
            "x": 0,
            "y": 1,
            "z": 2,
            "elements": [
                "ic2:resource@12"
            ]
        },
        {
            "x": 2,
            "y": -1,
            "z": 2,
            "elements": [
                "modularmachinery:blockcasing@0"
            ]
        },
        {
            "x": 3,
            "y": -1,
            "z": 0,
            "elements": [
                "modularmachinery:blockoutputbus",
                "modularmachinery:blockmeitemoutputbus"
            ]
        },
        {
            "x": 1,
            "y": 0,
            "z": 1,
            "elements": [
                "minecraft:lava@0"
            ]
        },
        {
            "x": 0,
            "y": -1,
            "z": 0,
            "elements": [
                "ic2:resource@12"
            ]
        },
        {
            "x": 1,
            "y": -1,
            "z": 1,
            "elements": [
                "minecraft:brick_block@0"
            ]
        },
        {
            "x": 1,
            "y": 1,
            "z": 0,
            "elements": [
                "modularmachinery:blockenergyinputhatch"
            ]
        },
        {
            "x": 0,
            "y": -1,
            "z": 2,
            "elements": [
                "ic2:resource@12"
            ]
        },
        {
            "x": 3,
            "y": 1,
            "z": 0,
            "elements": [
                "modularmachinery:blockinputbus",
                "modularmachinery:blockmepatternprovider",
                "modularmachinery:blockmeiteminputbus"
            ]
        },
        {
            "x": 4,
            "y": 0,
            "z": 2,
            "elements": [
                "ic2:resource@12"
            ]
        },
        {
            "x": 3,
            "y": 1,
            "z": 1,
            "elements": [
                "minecraft:brick_block@0"
            ]
        },
        {
            "x": 1,
            "y": 1,
            "z": 1,
            "elements": [
                "minecraft:brick_block@0"
            ]
        },
        {
            "x": 0,
            "y": 0,
            "z": 2,
            "elements": [
                "ic2:resource@12"
            ]
        },
        {
            "x": 2,
            "y": 0,
            "z": 2,
            "elements": [
                "tconstruct:clear_glass@0"
            ]
        },
        {
            "x": 3,
            "y": -1,
            "z": 1,
            "elements": [
                "minecraft:brick_block@0"
            ]
        },
        {
            "x": 1,
            "y": 0,
            "z": 0,
            "elements": [
                "tconstruct:clear_glass@0"
            ]
        },
        {
            "x": 3,
            "y": 0,
            "z": 0,
            "elements": [
                "tconstruct:clear_glass@0"
            ]
        },
        {
            "x": 1,
            "y": 1,
            "z": 2,
            "elements": [
                "modularmachinery:blockupgradebus"
            ]
        },
        {
            "x": 2,
            "y": 0,
            "z": 1,
            "elements": [
                "tconstruct:clear_glass@0"
            ]
        },
        {
            "x": 1,
            "y": -1,
            "z": 2,
            "elements": [
                "modularmachinery:blockcasing@0"
            ]
        },
        {
            "x": 1,
            "y": -1,
            "z": 0,
            "elements": [
                "modularmachinery:blockfluidoutputhatch",
                "modularmachinery:blockmefluidoutputbus"
            ]
        },
        {
            "x": 4,
            "y": 0,
            "z": 1,
            "elements": [
                "tconstruct:clear_glass@0"
            ]
        },
        {
            "x": 3,
            "y": 1,
            "z": 2,
            "elements": [
                "modularmachinery:blocksmartinterface@0"
            ]
        },
        {
            "x": 3,
            "y": -1,
            "z": 2,
            "elements": [
                "modularmachinery:blockcasing@0"
            ]
        },
        {
            "x": 4,
            "y": -1,
            "z": 0,
            "elements": [
                "ic2:resource@12"
            ]
        },
        {
            "x": 0,
            "y": 0,
            "z": 1,
            "elements": [
                "tconstruct:clear_glass@0"
            ]
        },
        {
            "x": 2,
            "y": -1,
            "z": 0,
            "elements": [
                "modularmachinery:blockfluidinputhatch",
                "modularmachinery:blockmefluidinputbus"
            ]
        },
        {
            "x": 0,
            "y": -1,
            "z": 1,
            "elements": [
                "modularmachinery:blockcasing@0"
            ]
        },
        {
            "x": 0,
            "y": 1,
            "z": 0,
            "elements": [
                "ic2:resource@12"
            ]
        },
        {
            "x": 2,
            "y": 1,
            "z": 0,
            "elements": [
                "modularmachinery:blockfluidinputhatch",
                "modularmachinery:blockmefluidinputbus"
            ]
        },
        {
            "x": 4,
            "y": 1,
            "z": 0,
            "elements": [
                "ic2:resource@12"
            ]
        },
        {
            "x": 4,
            "y": 1,
            "z": 1,
            "elements": [
                "modularmachinery:blockcasing@0"
            ]
        },
        {
            "x": 2,
            "y": -1,
            "z": 1,
            "elements": [
                "minecraft:brick_block@0"
            ]
        },
        {
            "x": 2,
            "y": 1,
            "z": 1,
            "elements": [
                "minecraft:brick_block@0"
            ]
        },
        {
            "x": 4,
            "y": -1,
            "z": 1,
            "elements": [
                "modularmachinery:blockcasing@0"
            ]
        },
        {
            "x": 0,
            "y": 1,
            "z": 1,
            "elements": [
                "modularmachinery:blockcasing@0"
            ]
        },
        {
            "x": 1,
            "y": 0,
            "z": 2,
            "elements": [
                "tconstruct:clear_glass@0"
            ]
        },
        {
            "x": 3,
            "y": 0,
            "z": 2,
            "elements": [
                "tconstruct:clear_glass@0"
            ]
        }
    ]}