{
    "registryname": "energychange",
    "localizedname": "进阶能量转换器",
    "requires-blueprint": false,
    "has-factory": false,
    "dynamic-patterns": [
        {
            "name": "line",
            "faces": [
                "up"
            ],
            "minSize": 1,
            "maxSize": 16,
            "parts": [
                {
                    "x": 0,
                    "y": 0,
                    "z": 0,
                    "elements": [
                        "contenttweaker:extrememachineblock"
                    ]
                },
                {
                    "x": -3,
                    "y": 0,
                    "z": 1,
                    "elements": [
                        "chisel:technicalnew@3"
                    ]
                },
                {
                    "x": 4,
                    "y": 0,
                    "z": 0,
                    "elements": [
                        "modularmachinery:blockcasing@4"
                    ]
                },
                {
                    "x": -2,
                    "y": 0,
                    "z": 2,
                    "elements": [
                        "chisel:technicalnew@3"
                    ]
                },
                {
                    "x": -3,
                    "y": 0,
                    "z": 5,
                    "elements": [
                        "fluxnetworks:fluxblock@0"
                    ]
                },
                {
                    "x": -4,
                    "y": 0,
                    "z": 4,
                    "elements": [
                        "contenttweaker:extrememachineblock@0"
                    ]
                },
                {
                    "x": 1,
                    "y": 0,
                    "z": 5,
                    "elements": [
                        "avaritia:block_resource@2"
                    ]
                },
                {
                    "x": -1,
                    "y": 0,
                    "z": 6,
                    "elements": [
                        "fluxnetworks:fluxblock@0"
                    ]
                },
                {
                    "x": 3,
                    "y": 0,
                    "z": 6,
                    "elements": [
                        "chisel:technicalnew@3"
                    ]
                },
                {
                    "x": 1,
                    "y": 0,
                    "z": 1,
                    "elements": [
                        "fluxnetworks:fluxblock@0"
                    ]
                },
                {
                    "x": -3,
                    "y": 0,
                    "z": 7,
                    "elements": [
                        "chisel:technicalnew@3"
                    ]
                },
                {
                    "x": 4,
                    "y": 0,
                    "z": 3,
                    "elements": [
                        "ic2:resource@13"
                    ]
                },
                {
                    "x": -1,
                    "y": 0,
                    "z": 8,
                    "elements": [
                        "modularmachinery:blockenergyoutputhatch"
                    ]
                },
                {
                    "x": 1,
                    "y": 0,
                    "z": 7,
                    "elements": [
                        "fluxnetworks:fluxblock@0"
                    ]
                },
                {
                    "x": 0,
                    "y": 0,
                    "z": 3,
                    "elements": [
                        "avaritia:block_resource@2"
                    ]
                },
                {
                    "x": 3,
                    "y": 0,
                    "z": 8,
                    "elements": [
                        "ic2:resource@13"
                    ]
                },
                {
                    "x": -4,
                    "y": 0,
                    "z": 3,
                    "elements": [
                        "ic2:resource@13"
                    ]
                },
                {
                    "x": -1,
                    "y": 0,
                    "z": 4,
                    "elements": [
                        "avaritia:block_resource@2"
                    ]
                },
                {
                    "x": -3,
                    "y": 0,
                    "z": 0,
                    "elements": [
                        "modularmachinery:blockcasing@0"
                    ]
                },
                {
                    "x": 3,
                    "y": 0,
                    "z": 4,
                    "elements": [
                        "avaritia:block_resource@2"
                    ]
                },
                {
                    "x": 2,
                    "y": 0,
                    "z": 2,
                    "elements": [
                        "chisel:technicalnew@3"
                    ]
                },
                {
                    "x": 1,
                    "y": 0,
                    "z": 0,
                    "elements": [
                        "modularmachinery:blockcasing@0"
                    ]
                },
                {
                    "x": -4,
                    "y": 0,
                    "z": 1,
                    "elements": [
                        "ic2:resource@13"
                    ]
                },
                {
                    "x": -3,
                    "y": 0,
                    "z": 4,
                    "elements": [
                        "avaritia:block_resource@2"
                    ]
                },
                {
                    "x": 4,
                    "y": 0,
                    "z": 1,
                    "elements": [
                        "ic2:resource@13"
                    ]
                },
                {
                    "x": -2,
                    "y": 0,
                    "z": 5,
                    "elements": [
                        "fluxnetworks:fluxblock@0"
                    ]
                },
                {
                    "x": 0,
                    "y": 0,
                    "z": 6,
                    "elements": [
                        "avaritia:block_resource@2"
                    ]
                },
                {
                    "x": 2,
                    "y": 0,
                    "z": 5,
                    "elements": [
                        "fluxnetworks:fluxblock@0"
                    ]
                },
                {
                    "x": 0,
                    "y": 0,
                    "z": 1,
                    "elements": [
                        "avaritia:block_resource@2"
                    ]
                },
                {
                    "x": 4,
                    "y": 0,
                    "z": 6,
                    "elements": [
                        "ic2:resource@13"
                    ]
                },
                {
                    "x": -2,
                    "y": 0,
                    "z": 7,
                    "elements": [
                        "chisel:technicalnew@3"
                    ]
                },
                {
                    "x": -2,
                    "y": 0,
                    "z": 8,
                    "elements": [
                        "ic2:resource@13"
                    ]
                },
                {
                    "x": 2,
                    "y": 0,
                    "z": 8,
                    "elements": [
                        "ic2:resource@13"
                    ]
                },
                {
                    "x": 2,
                    "y": 0,
                    "z": 7,
                    "elements": [
                        "chisel:technicalnew@3"
                    ]
                },
                {
                    "x": 1,
                    "y": 0,
                    "z": 3,
                    "elements": [
                        "avaritia:block_resource@2"
                    ]
                },
                {
                    "x": -4,
                    "y": 0,
                    "z": 6,
                    "elements": [
                        "ic2:resource@13"
                    ]
                },
                {
                    "x": -3,
                    "y": 0,
                    "z": 3,
                    "elements": [
                        "fluxnetworks:fluxblock@0"
                    ]
                },
                {
                    "x": 0,
                    "y": 0,
                    "z": 4,
                    "elements": [
                        "contenttweaker:neutronforcefieldcontrolblock@0"
                    ]
                },
                {
                    "x": -1,
                    "y": 0,
                    "z": 1,
                    "elements": [
                        "fluxnetworks:fluxblock@0"
                    ]
                },
                {
                    "x": -1,
                    "y": 0,
                    "z": 2,
                    "elements": [
                        "fluxnetworks:fluxblock@0"
                    ]
                },
                {
                    "x": -2,
                    "y": 0,
                    "z": 0,
                    "elements": [
                        "modularmachinery:blockcasing@0"
                    ]
                },
                {
                    "x": 4,
                    "y": 0,
                    "z": 4,
                    "elements": [
                        "contenttweaker:extrememachineblock@0"
                    ]
                },
                {
                    "x": 3,
                    "y": 0,
                    "z": 2,
                    "elements": [
                        "chisel:technicalnew@3"
                    ]
                },
                {
                    "x": 2,
                    "y": 0,
                    "z": 0,
                    "elements": [
                        "modularmachinery:blockcasing@0"
                    ]
                },
                {
                    "x": -4,
                    "y": 0,
                    "z": 2,
                    "elements": [
                        "ic2:resource@13"
                    ]
                },
                {
                    "x": -3,
                    "y": 0,
                    "z": 6,
                    "elements": [
                        "chisel:technicalnew@3"
                    ]
                },
                {
                    "x": -1,
                    "y": 0,
                    "z": 5,
                    "elements": [
                        "avaritia:block_resource@2"
                    ]
                },
                {
                    "x": 1,
                    "y": 0,
                    "z": 6,
                    "elements": [
                        "fluxnetworks:fluxblock@0"
                    ]
                },
                {
                    "x": 3,
                    "y": 0,
                    "z": 1,
                    "elements": [
                        "chisel:technicalnew@3"
                    ]
                },
                {
                    "x": 3,
                    "y": 0,
                    "z": 5,
                    "elements": [
                        "fluxnetworks:fluxblock@0"
                    ]
                },
                {
                    "x": -3,
                    "y": 0,
                    "z": 8,
                    "elements": [
                        "ic2:resource@13"
                    ]
                },
                {
                    "x": -1,
                    "y": 0,
                    "z": 7,
                    "elements": [
                        "fluxnetworks:fluxblock@0"
                    ]
                },
                {
                    "x": 1,
                    "y": 0,
                    "z": 8,
                    "elements": [
                        "modularmachinery:blockenergyoutputhatch"
                    ]
                },
                {
                    "x": 3,
                    "y": 0,
                    "z": 7,
                    "elements": [
                        "chisel:technicalnew@3"
                    ]
                },
                {
                    "x": 2,
                    "y": 0,
                    "z": 3,
                    "elements": [
                        "fluxnetworks:fluxblock@0"
                    ]
                },
                {
                    "x": 4,
                    "y": 0,
                    "z": 2,
                    "elements": [
                        "ic2:resource@13"
                    ]
                },
                {
                    "x": -2,
                    "y": 0,
                    "z": 3,
                    "elements": [
                        "fluxnetworks:fluxblock@0"
                    ]
                },
                {
                    "x": 1,
                    "y": 0,
                    "z": 4,
                    "elements": [
                        "avaritia:block_resource@2"
                    ]
                },
                {
                    "x": 0,
                    "y": 0,
                    "z": 2,
                    "elements": [
                        "avaritia:block_resource@2"
                    ]
                },
                {
                    "x": -1,
                    "y": 0,
                    "z": 0,
                    "elements": [
                        "modularmachinery:blockcasing@0"
                    ]
                },
                {
                    "x": -2,
                    "y": 0,
                    "z": 1,
                    "elements": [
                        "chisel:technicalnew@3"
                    ]
                },
                {
                    "x": 3,
                    "y": 0,
                    "z": 0,
                    "elements": [
                        "modularmachinery:blockcasing@0"
                    ]
                },
                {
                    "x": -3,
                    "y": 0,
                    "z": 2,
                    "elements": [
                        "chisel:technicalnew@3"
                    ]
                },
                {
                    "x": -4,
                    "y": 0,
                    "z": 5,
                    "elements": [
                        "ic2:resource@13"
                    ]
                },
                {
                    "x": 0,
                    "y": 0,
                    "z": 5,
                    "elements": [
                        "avaritia:block_resource@2"
                    ]
                },
                {
                    "x": -2,
                    "y": 0,
                    "z": 6,
                    "elements": [
                        "chisel:technicalnew@3"
                    ]
                },
                {
                    "x": 4,
                    "y": 0,
                    "z": 5,
                    "elements": [
                        "ic2:resource@13"
                    ]
                },
                {
                    "x": 2,
                    "y": 0,
                    "z": 1,
                    "elements": [
                        "chisel:technicalnew@3"
                    ]
                },
                {
                    "x": 2,
                    "y": 0,
                    "z": 6,
                    "elements": [
                        "chisel:technicalnew@3"
                    ]
                },
                {
                    "x": -4,
                    "y": 0,
                    "z": 8,
                    "elements": [
                        "modularmachinery:blockcasing@4"
                    ]
                },
                {
                    "x": 3,
                    "y": 0,
                    "z": 3,
                    "elements": [
                        "fluxnetworks:fluxblock@0"
                    ]
                },
                {
                    "x": 0,
                    "y": 0,
                    "z": 8,
                    "elements": [
                        "contenttweaker:extrememachineblock@0"
                    ]
                },
                {
                    "x": 0,
                    "y": 0,
                    "z": 7,
                    "elements": [
                        "avaritia:block_resource@2"
                    ]
                },
                {
                    "x": -1,
                    "y": 0,
                    "z": 3,
                    "elements": [
                        "avaritia:block_resource@2"
                    ]
                },
                {
                    "x": 4,
                    "y": 0,
                    "z": 8,
                    "elements": [
                        "modularmachinery:blockcasing@4"
                    ]
                },
                {
                    "x": 4,
                    "y": 0,
                    "z": 7,
                    "elements": [
                        "ic2:resource@13"
                    ]
                },
                {
                    "x": -2,
                    "y": 0,
                    "z": 4,
                    "elements": [
                        "avaritia:block_resource@2"
                    ]
                },
                {
                    "x": -4,
                    "y": 0,
                    "z": 0,
                    "elements": [
                        "modularmachinery:blockcasing@4"
                    ]
                },
                {
                    "x": 2,
                    "y": 0,
                    "z": 4,
                    "elements": [
                        "avaritia:block_resource@2"
                    ]
                },
                {
                    "x": 1,
                    "y": 0,
                    "z": 2,
                    "elements": [
                        "fluxnetworks:fluxblock@0"
                    ]
                },
                {
                    "x": -4,
                    "y": 0,
                    "z": 7,
                    "elements": [
                        "ic2:resource@13"
                    ]
                }
            ],
            "parts-end": [
                {
                    "x": 0,
                    "y": 0,
                    "z": 0,
                    "elements": [
                        "contenttweaker:extrememachineblock"
                    ]
                },
                {
                    "x": 0,
                    "y": 1,
                    "z": 8,
                    "elements": [
                        "contenttweaker:extrememachineblock@0"
                    ]
                },
                {
                    "x": 1,
                    "y": 1,
                    "z": 3,
                    "elements": [
                        "contenttweaker:crystalmatrixforcefieldcontrolblock@0"
                    ]
                },
                {
                    "x": 4,
                    "y": 1,
                    "z": 4,
                    "elements": [
                        "contenttweaker:extrememachineblock@0"
                    ]
                },
                {
                    "x": -3,
                    "y": 0,
                    "z": 1,
                    "elements": [
                        "chisel:technicalnew@3"
                    ]
                },
                {
                    "x": -3,
                    "y": 0,
                    "z": 5,
                    "elements": [
                        "chisel:technicalnew@3"
                    ]
                },
                {
                    "x": -4,
                    "y": 0,
                    "z": 4,
                    "elements": [
                        "contenttweaker:extrememachineblock@0"
                    ]
                },
                {
                    "x": 1,
                    "y": 1,
                    "z": 7,
                    "elements": [
                        "modularmachinery:blockcasing@0"
                    ]
                },
                {
                    "x": 2,
                    "y": 1,
                    "z": 2,
                    "elements": [
                        "modularmachinery:blockcasing@0"
                    ]
                },
                {
                    "x": -4,
                    "y": 1,
                    "z": 4,
                    "elements": [
                        "contenttweaker:extrememachineblock@0"
                    ]
                },
                {
                    "x": 3,
                    "y": 0,
                    "z": 6,
                    "elements": [
                        "chisel:technicalnew@3"
                    ]
                },
                {
                    "x": 3,
                    "y": 1,
                    "z": 6,
                    "elements": [
                        "modularmachinery:blockcasing@0"
                    ]
                },
                {
                    "x": -1,
                    "y": 1,
                    "z": 0,
                    "elements": [
                        "contenttweaker:extrememachineblock@0"
                    ]
                },
                {
                    "x": 4,
                    "y": 0,
                    "z": 3,
                    "elements": [
                        "ic2:resource@13"
                    ]
                },
                {
                    "x": 1,
                    "y": 0,
                    "z": 7,
                    "elements": [
                        "chisel:technicalnew@3"
                    ]
                },
                {
                    "x": 3,
                    "y": 0,
                    "z": 8,
                    "elements": [
                        "ic2:resource@13"
                    ]
                },
                {
                    "x": -3,
                    "y": 1,
                    "z": 5,
                    "elements": [
                        "modularmachinery:blockcasing@0"
                    ]
                },
                {
                    "x": -4,
                    "y": 0,
                    "z": 3,
                    "elements": [
                        "ic2:resource@13"
                    ]
                },
                {
                    "x": -1,
                    "y": 0,
                    "z": 4,
                    "elements": [
                        "avaritia:block_resource@2"
                    ]
                },
                {
                    "x": 4,
                    "y": 1,
                    "z": 3,
                    "elements": [
                        "contenttweaker:extrememachineblock@0"
                    ]
                },
                {
                    "x": -3,
                    "y": 1,
                    "z": 1,
                    "elements": [
                        "modularmachinery:blockcasing@0"
                    ]
                },
                {
                    "x": 2,
                    "y": 0,
                    "z": 2,
                    "elements": [
                        "chisel:technicalnew@3"
                    ]
                },
                {
                    "x": 1,
                    "y": 0,
                    "z": 0,
                    "elements": [
                        "ic2:resource@13"
                    ]
                },
                {
                    "x": -3,
                    "y": 1,
                    "z": 8,
                    "elements": [
                        "modularmachinery:blockcasing@4"
                    ]
                },
                {
                    "x": -4,
                    "y": 1,
                    "z": 3,
                    "elements": [
                        "contenttweaker:extrememachineblock@0"
                    ]
                },
                {
                    "x": -1,
                    "y": 1,
                    "z": 4,
                    "elements": [
                        "contenttweaker:extrememachineblock@0"
                    ]
                },
                {
                    "x": 0,
                    "y": 0,
                    "z": 6,
                    "elements": [
                        "avaritia:block_resource@2"
                    ]
                },
                {
                    "x": -2,
                    "y": 0,
                    "z": 5,
                    "elements": [
                        "chisel:technicalnew@3"
                    ]
                },
                {
                    "x": 3,
                    "y": 1,
                    "z": 2,
                    "elements": [
                        "modularmachinery:blockcasing@0"
                    ]
                },
                {
                    "x": 0,
                    "y": 0,
                    "z": 1,
                    "elements": [
                        "avaritia:block_resource@2"
                    ]
                },
                {
                    "x": -2,
                    "y": 1,
                    "z": 0,
                    "elements": [
                        "ic2:resource@13"
                    ]
                },
                {
                    "x": -2,
                    "y": 0,
                    "z": 8,
                    "elements": [
                        "ic2:resource@13"
                    ]
                },
                {
                    "x": 2,
                    "y": 0,
                    "z": 7,
                    "elements": [
                        "chisel:technicalnew@3"
                    ]
                },
                {
                    "x": 1,
                    "y": 0,
                    "z": 3,
                    "elements": [
                        "chisel:technicalnew@3"
                    ]
                },
                {
                    "x": -2,
                    "y": 1,
                    "z": 5,
                    "elements": [
                        "modularmachinery:blockcasing@0"
                    ]
                },
                {
                    "x": -2,
                    "y": 1,
                    "z": 8,
                    "elements": [
                        "ic2:resource@13"
                    ]
                },
                {
                    "x": 0,
                    "y": 1,
                    "z": 6,
                    "elements": [
                        "contenttweaker:extrememachineblock@0"
                    ]
                },
                {
                    "x": 0,
                    "y": 1,
                    "z": 1,
                    "elements": [
                        "contenttweaker:extrememachineblock@0"
                    ]
                },
                {
                    "x": 4,
                    "y": 0,
                    "z": 4,
                    "elements": [
                        "contenttweaker:extrememachineblock@0"
                    ]
                },
                {
                    "x": 3,
                    "y": 0,
                    "z": 2,
                    "elements": [
                        "chisel:technicalnew@3"
                    ]
                },
                {
                    "x": -1,
                    "y": 0,
                    "z": 1,
                    "elements": [
                        "chisel:technicalnew@3"
                    ]
                },
                {
                    "x": 2,
                    "y": 0,
                    "z": 0,
                    "elements": [
                        "ic2:resource@13"
                    ]
                },
                {
                    "x": 3,
                    "y": 1,
                    "z": 5,
                    "elements": [
                        "modularmachinery:blockcasing@0"
                    ]
                },
                {
                    "x": 3,
                    "y": 1,
                    "z": 3,
                    "elements": [
                        "modularmachinery:blockcasing@0"
                    ]
                },
                {
                    "x": -1,
                    "y": 1,
                    "z": 7,
                    "elements": [
                        "modularmachinery:blockcasing@0"
                    ]
                },
                {
                    "x": -2,
                    "y": 1,
                    "z": 4,
                    "elements": [
                        "contenttweaker:extrememachineblock@0"
                    ]
                },
                {
                    "x": 1,
                    "y": 0,
                    "z": 6,
                    "elements": [
                        "chisel:technicalnew@3"
                    ]
                },
                {
                    "x": 0,
                    "y": 1,
                    "z": 2,
                    "elements": [
                        "contenttweaker:extrememachineblock@0"
                    ]
                },
                {
                    "x": 3,
                    "y": 0,
                    "z": 5,
                    "elements": [
                        "chisel:technicalnew@3"
                    ]
                },
                {
                    "x": -1,
                    "y": 0,
                    "z": 7,
                    "elements": [
                        "chisel:technicalnew@3"
                    ]
                },
                {
                    "x": 1,
                    "y": 1,
                    "z": 0,
                    "elements": [
                        "contenttweaker:extrememachineblock@0"
                    ]
                },
                {
                    "x": 1,
                    "y": 0,
                    "z": 8,
                    "elements": [
                        "modularmachinery:blockenergyoutputhatch"
                    ]
                },
                {
                    "x": 2,
                    "y": 0,
                    "z": 3,
                    "elements": [
                        "chisel:technicalnew@3"
                    ]
                },
                {
                    "x": 2,
                    "y": 1,
                    "z": 7,
                    "elements": [
                        "modularmachinery:blockcasing@0"
                    ]
                },
                {
                    "x": -1,
                    "y": 1,
                    "z": 8,
                    "elements": [
                        "contenttweaker:extrememachineblock@0"
                    ]
                },
                {
                    "x": -4,
                    "y": 1,
                    "z": 7,
                    "elements": [
                        "modularmachinery:blockcasing@4"
                    ]
                },
                {
                    "x": -1,
                    "y": 1,
                    "z": 1,
                    "elements": [
                        "modularmachinery:blockcasing@0"
                    ]
                },
                {
                    "x": 0,
                    "y": 0,
                    "z": 2,
                    "elements": [
                        "avaritia:block_resource@2"
                    ]
                },
                {
                    "x": 1,
                    "y": 1,
                    "z": 6,
                    "elements": [
                        "modularmachinery:blockcasing@0"
                    ]
                },
                {
                    "x": -1,
                    "y": 0,
                    "z": 0,
                    "elements": [
                        "ic2:resource@13"
                    ]
                },
                {
                    "x": -2,
                    "y": 0,
                    "z": 1,
                    "elements": [
                        "chisel:technicalnew@3"
                    ]
                },
                {
                    "x": -3,
                    "y": 0,
                    "z": 2,
                    "elements": [
                        "chisel:technicalnew@3"
                    ]
                },
                {
                    "x": 2,
                    "y": 1,
                    "z": 3,
                    "elements": [
                        "modularmachinery:blockcasing@0"
                    ]
                },
                {
                    "x": 0,
                    "y": 0,
                    "z": 5,
                    "elements": [
                        "avaritia:block_resource@2"
                    ]
                },
                {
                    "x": -3,
                    "y": 1,
                    "z": 4,
                    "elements": [
                        "contenttweaker:extrememachineblock@0"
                    ]
                },
                {
                    "x": 2,
                    "y": 0,
                    "z": 6,
                    "elements": [
                        "chisel:technicalnew@3"
                    ]
                },
                {
                    "x": -3,
                    "y": 1,
                    "z": 2,
                    "elements": [
                        "modularmachinery:blockcasing@0"
                    ]
                },
                {
                    "x": 3,
                    "y": 0,
                    "z": 3,
                    "elements": [
                        "chisel:technicalnew@3"
                    ]
                },
                {
                    "x": 0,
                    "y": 0,
                    "z": 8,
                    "elements": [
                        "contenttweaker:extrememachineblock@0"
                    ]
                },
                {
                    "x": 4,
                    "y": 1,
                    "z": 0,
                    "elements": [
                        "modularmachinery:blockcasing@4"
                    ]
                },
                {
                    "x": 4,
                    "y": 0,
                    "z": 7,
                    "elements": [
                        "ic2:resource@13"
                    ]
                },
                {
                    "x": -2,
                    "y": 0,
                    "z": 4,
                    "elements": [
                        "avaritia:block_resource@2"
                    ]
                },
                {
                    "x": -4,
                    "y": 0,
                    "z": 7,
                    "elements": [
                        "ic2:resource@13"
                    ]
                },
                {
                    "x": -4,
                    "y": 0,
                    "z": 0,
                    "elements": [
                        "modularmachinery:blockcasing@4"
                    ]
                },
                {
                    "x": 2,
                    "y": 1,
                    "z": 6,
                    "elements": [
                        "modularmachinery:blockcasing@0"
                    ]
                },
                {
                    "x": 0,
                    "y": 1,
                    "z": 5,
                    "elements": [
                        "contenttweaker:extrememachineblock@0"
                    ]
                },
                {
                    "x": -2,
                    "y": 1,
                    "z": 1,
                    "elements": [
                        "modularmachinery:blockcasing@0"
                    ]
                },
                {
                    "x": -3,
                    "y": 1,
                    "z": 7,
                    "elements": [
                        "modularmachinery:blockcasing@0"
                    ]
                },
                {
                    "x": 4,
                    "y": 0,
                    "z": 0,
                    "elements": [
                        "modularmachinery:blockcasing@4"
                    ]
                },
                {
                    "x": -2,
                    "y": 0,
                    "z": 2,
                    "elements": [
                        "chisel:technicalnew@3"
                    ]
                },
                {
                    "x": -4,
                    "y": 1,
                    "z": 8,
                    "elements": [
                        "modularmachinery:blockcasing@4"
                    ]
                },
                {
                    "x": -3,
                    "y": 1,
                    "z": 3,
                    "elements": [
                        "modularmachinery:blockcasing@0"
                    ]
                },
                {
                    "x": 1,
                    "y": 0,
                    "z": 5,
                    "elements": [
                        "chisel:technicalnew@3"
                    ]
                },
                {
                    "x": -1,
                    "y": 0,
                    "z": 6,
                    "elements": [
                        "chisel:technicalnew@3"
                    ]
                },
                {
                    "x": 4,
                    "y": 1,
                    "z": 8,
                    "elements": [
                        "modularmachinery:blockcasing@4"
                    ]
                },
                {
                    "x": -2,
                    "y": 1,
                    "z": 2,
                    "elements": [
                        "modularmachinery:blockcasing@0"
                    ]
                },
                {
                    "x": 1,
                    "y": 0,
                    "z": 1,
                    "elements": [
                        "chisel:technicalnew@3"
                    ]
                },
                {
                    "x": -4,
                    "y": 1,
                    "z": 0,
                    "elements": [
                        "modularmachinery:blockcasing@4"
                    ]
                },
                {
                    "x": 0,
                    "y": 1,
                    "z": 4,
                    "elements": [
                        "contenttweaker:extrememachineblock@0"
                    ]
                },
                {
                    "x": -3,
                    "y": 0,
                    "z": 7,
                    "elements": [
                        "chisel:technicalnew@3"
                    ]
                },
                {
                    "x": -1,
                    "y": 0,
                    "z": 8,
                    "elements": [
                        "modularmachinery:blockenergyoutputhatch"
                    ]
                },
                {
                    "x": 3,
                    "y": 1,
                    "z": 0,
                    "elements": [
                        "modularmachinery:blockcasing@4"
                    ]
                },
                {
                    "x": 0,
                    "y": 0,
                    "z": 3,
                    "elements": [
                        "avaritia:block_resource@2"
                    ]
                },
                {
                    "x": 4,
                    "y": 1,
                    "z": 7,
                    "elements": [
                        "modularmachinery:blockcasing@4"
                    ]
                },
                {
                    "x": -1,
                    "y": 1,
                    "z": 6,
                    "elements": [
                        "modularmachinery:blockcasing@0"
                    ]
                },
                {
                    "x": 1,
                    "y": 1,
                    "z": 1,
                    "elements": [
                        "modularmachinery:blockcasing@0"
                    ]
                },
                {
                    "x": 1,
                    "y": 1,
                    "z": 5,
                    "elements": [
                        "contenttweaker:crystalmatrixforcefieldcontrolblock@0"
                    ]
                },
                {
                    "x": -3,
                    "y": 0,
                    "z": 0,
                    "elements": [
                        "ic2:resource@13"
                    ]
                },
                {
                    "x": 3,
                    "y": 0,
                    "z": 4,
                    "elements": [
                        "avaritia:block_resource@2"
                    ]
                },
                {
                    "x": 0,
                    "y": 1,
                    "z": 3,
                    "elements": [
                        "contenttweaker:extrememachineblock@0"
                    ]
                },
                {
                    "x": -4,
                    "y": 0,
                    "z": 1,
                    "elements": [
                        "ic2:resource@13"
                    ]
                },
                {
                    "x": -2,
                    "y": 1,
                    "z": 7,
                    "elements": [
                        "modularmachinery:blockcasing@0"
                    ]
                },
                {
                    "x": -3,
                    "y": 0,
                    "z": 4,
                    "elements": [
                        "avaritia:block_resource@2"
                    ]
                },
                {
                    "x": 1,
                    "y": 1,
                    "z": 8,
                    "elements": [
                        "contenttweaker:extrememachineblock@0"
                    ]
                },
                {
                    "x": 4,
                    "y": 0,
                    "z": 1,
                    "elements": [
                        "ic2:resource@13"
                    ]
                },
                {
                    "x": -2,
                    "y": 0,
                    "z": 7,
                    "elements": [
                        "chisel:technicalnew@3"
                    ]
                },
                {
                    "x": 3,
                    "y": 1,
                    "z": 4,
                    "elements": [
                        "contenttweaker:extrememachineblock@0"
                    ]
                },
                {
                    "x": 4,
                    "y": 0,
                    "z": 6,
                    "elements": [
                        "ic2:resource@13"
                    ]
                },
                {
                    "x": 2,
                    "y": 0,
                    "z": 5,
                    "elements": [
                        "chisel:technicalnew@3"
                    ]
                },
                {
                    "x": -1,
                    "y": 1,
                    "z": 2,
                    "elements": [
                        "modularmachinery:blockcasing@0"
                    ]
                },
                {
                    "x": 4,
                    "y": 1,
                    "z": 6,
                    "elements": [
                        "ic2:resource@13"
                    ]
                },
                {
                    "x": -4,
                    "y": 1,
                    "z": 1,
                    "elements": [
                        "modularmachinery:blockcasing@4"
                    ]
                },
                {
                    "x": 2,
                    "y": 1,
                    "z": 0,
                    "elements": [
                        "ic2:resource@13"
                    ]
                },
                {
                    "x": 2,
                    "y": 0,
                    "z": 8,
                    "elements": [
                        "ic2:resource@13"
                    ]
                },
                {
                    "x": -4,
                    "y": 0,
                    "z": 6,
                    "elements": [
                        "ic2:resource@13"
                    ]
                },
                {
                    "x": -3,
                    "y": 0,
                    "z": 3,
                    "elements": [
                        "chisel:technicalnew@3"
                    ]
                },
                {
                    "x": 4,
                    "y": 1,
                    "z": 1,
                    "elements": [
                        "modularmachinery:blockcasing@4"
                    ]
                },
                {
                    "x": 0,
                    "y": 0,
                    "z": 4,
                    "elements": [
                        "avaritia:block_resource@2"
                    ]
                },
                {
                    "x": -4,
                    "y": 1,
                    "z": 6,
                    "elements": [
                        "ic2:resource@13"
                    ]
                },
                {
                    "x": -1,
                    "y": 0,
                    "z": 2,
                    "elements": [
                        "chisel:technicalnew@3"
                    ]
                },
                {
                    "x": 2,
                    "y": 1,
                    "z": 5,
                    "elements": [
                        "modularmachinery:blockcasing@0"
                    ]
                },
                {
                    "x": -2,
                    "y": 0,
                    "z": 0,
                    "elements": [
                        "ic2:resource@13"
                    ]
                },
                {
                    "x": -4,
                    "y": 0,
                    "z": 2,
                    "elements": [
                        "ic2:resource@13"
                    ]
                },
                {
                    "x": -1,
                    "y": 1,
                    "z": 3,
                    "elements": [
                        "contenttweaker:crystalmatrixforcefieldcontrolblock@0"
                    ]
                },
                {
                    "x": -3,
                    "y": 0,
                    "z": 6,
                    "elements": [
                        "chisel:technicalnew@3"
                    ]
                },
                {
                    "x": 4,
                    "y": 1,
                    "z": 2,
                    "elements": [
                        "ic2:resource@13"
                    ]
                },
                {
                    "x": -1,
                    "y": 0,
                    "z": 5,
                    "elements": [
                        "chisel:technicalnew@3"
                    ]
                },
                {
                    "x": 3,
                    "y": 0,
                    "z": 1,
                    "elements": [
                        "chisel:technicalnew@3"
                    ]
                },
                {
                    "x": 2,
                    "y": 1,
                    "z": 4,
                    "elements": [
                        "contenttweaker:extrememachineblock@0"
                    ]
                },
                {
                    "x": 2,
                    "y": 1,
                    "z": 8,
                    "elements": [
                        "ic2:resource@13"
                    ]
                },
                {
                    "x": -3,
                    "y": 0,
                    "z": 8,
                    "elements": [
                        "ic2:resource@13"
                    ]
                },
                {
                    "x": -4,
                    "y": 1,
                    "z": 2,
                    "elements": [
                        "ic2:resource@13"
                    ]
                },
                {
                    "x": 3,
                    "y": 0,
                    "z": 7,
                    "elements": [
                        "chisel:technicalnew@3"
                    ]
                },
                {
                    "x": 4,
                    "y": 0,
                    "z": 2,
                    "elements": [
                        "ic2:resource@13"
                    ]
                },
                {
                    "x": 3,
                    "y": 1,
                    "z": 1,
                    "elements": [
                        "modularmachinery:blockcasing@0"
                    ]
                },
                {
                    "x": -3,
                    "y": 1,
                    "z": 6,
                    "elements": [
                        "modularmachinery:blockcasing@0"
                    ]
                },
                {
                    "x": -2,
                    "y": 0,
                    "z": 3,
                    "elements": [
                        "chisel:technicalnew@3"
                    ]
                },
                {
                    "x": 1,
                    "y": 0,
                    "z": 4,
                    "elements": [
                        "avaritia:block_resource@2"
                    ]
                },
                {
                    "x": -1,
                    "y": 1,
                    "z": 5,
                    "elements": [
                        "contenttweaker:crystalmatrixforcefieldcontrolblock@0"
                    ]
                },
                {
                    "x": 3,
                    "y": 0,
                    "z": 0,
                    "elements": [
                        "ic2:resource@13"
                    ]
                },
                {
                    "x": 4,
                    "y": 1,
                    "z": 5,
                    "elements": [
                        "contenttweaker:extrememachineblock@0"
                    ]
                },
                {
                    "x": -4,
                    "y": 0,
                    "z": 5,
                    "elements": [
                        "ic2:resource@13"
                    ]
                },
                {
                    "x": 0,
                    "y": 1,
                    "z": 7,
                    "elements": [
                        "contenttweaker:extrememachineblock@0"
                    ]
                },
                {
                    "x": -2,
                    "y": 1,
                    "z": 3,
                    "elements": [
                        "modularmachinery:blockcasing@0"
                    ]
                },
                {
                    "x": -2,
                    "y": 0,
                    "z": 6,
                    "elements": [
                        "chisel:technicalnew@3"
                    ]
                },
                {
                    "x": 1,
                    "y": 1,
                    "z": 2,
                    "elements": [
                        "modularmachinery:blockcasing@0"
                    ]
                },
                {
                    "x": 4,
                    "y": 0,
                    "z": 5,
                    "elements": [
                        "ic2:resource@13"
                    ]
                },
                {
                    "x": 2,
                    "y": 0,
                    "z": 1,
                    "elements": [
                        "chisel:technicalnew@3"
                    ]
                },
                {
                    "x": 3,
                    "y": 1,
                    "z": 8,
                    "elements": [
                        "modularmachinery:blockcasing@4"
                    ]
                },
                {
                    "x": 1,
                    "y": 1,
                    "z": 4,
                    "elements": [
                        "contenttweaker:extrememachineblock@0"
                    ]
                },
                {
                    "x": -3,
                    "y": 1,
                    "z": 0,
                    "elements": [
                        "modularmachinery:blockcasing@4"
                    ]
                },
                {
                    "x": -4,
                    "y": 0,
                    "z": 8,
                    "elements": [
                        "modularmachinery:blockcasing@4"
                    ]
                },
                {
                    "x": 0,
                    "y": 1,
                    "z": 0,
                    "elements": [
                        "contenttweaker:extrememachineblock@0"
                    ]
                },
                {
                    "x": 0,
                    "y": 0,
                    "z": 7,
                    "elements": [
                        "avaritia:block_resource@2"
                    ]
                },
                {
                    "x": -1,
                    "y": 0,
                    "z": 3,
                    "elements": [
                        "chisel:technicalnew@3"
                    ]
                },
                {
                    "x": 4,
                    "y": 0,
                    "z": 8,
                    "elements": [
                        "modularmachinery:blockcasing@4"
                    ]
                },
                {
                    "x": 3,
                    "y": 1,
                    "z": 7,
                    "elements": [
                        "modularmachinery:blockcasing@0"
                    ]
                },
                {
                    "x": -4,
                    "y": 1,
                    "z": 5,
                    "elements": [
                        "contenttweaker:extrememachineblock@0"
                    ]
                },
                {
                    "x": 2,
                    "y": 1,
                    "z": 1,
                    "elements": [
                        "modularmachinery:blockcasing@0"
                    ]
                },
                {
                    "x": 2,
                    "y": 0,
                    "z": 4,
                    "elements": [
                        "avaritia:block_resource@2"
                    ]
                },
                {
                    "x": -2,
                    "y": 1,
                    "z": 6,
                    "elements": [
                        "modularmachinery:blockcasing@0"
                    ]
                },
                {
                    "x": 1,
                    "y": 0,
                    "z": 2,
                    "elements": [
                        "chisel:technicalnew@3"
                    ]
                }
    ],
            "structure-size-offset-start": {
                "x": 0,
                "y": 1,
                "z": 0
            },
            "structure-size-offset": {
                "x": 0,
                "y": 1,
                "z": 0
            }
        }
    ],
    "parts": [
        {
            "x": 2,
            "y": -1,
            "z": 8,
            "elements": [
                "ic2:resource@13"
            ]
        },
        {
            "x": 1,
            "y": -1,
            "z": 7,
            "elements": [
                "modularmachinery:blockcasing@0"
            ]
        },
        {
            "x": -3,
            "y": 0,
            "z": 1,
            "elements": [
                "chisel:technicalnew@3"
            ]
        },
        {
            "x": -3,
            "y": 0,
            "z": 5,
            "elements": [
                "chisel:technicalnew@3"
            ]
        },
        {
            "x": 3,
            "y": -1,
            "z": 3,
            "elements": [
                "modularmachinery:blockcasing@0"
            ]
        },
        {
            "x": -4,
            "y": 0,
            "z": 4,
            "elements": [
                "contenttweaker:extrememachineblock@0"
            ]
        },
        {
            "x": 3,
            "y": 0,
            "z": 6,
            "elements": [
                "chisel:technicalnew@3"
            ]
        },
        {
            "x": 4,
            "y": -1,
            "z": 2,
            "elements": [
                "ic2:resource@13"
            ]
        },
        {
            "x": 0,
            "y": -1,
            "z": 0,
            "elements": [
                "modularmachinery:blocksmartinterface@0"
            ]
        },
        {
            "x": 4,
            "y": 0,
            "z": 3,
            "elements": [
                "ic2:resource@13"
            ]
        },
        {
            "x": 3,
            "y": 0,
            "z": 8,
            "elements": [
                "ic2:resource@13"
            ]
        },
        {
            "x": 1,
            "y": 0,
            "z": 7,
            "elements": [
                "chisel:technicalnew@3"
            ]
        },
        {
            "x": -1,
            "y": -1,
            "z": 6,
            "elements": [
                "modularmachinery:blockcasing@0"
            ]
        },
        {
            "x": -3,
            "y": -1,
            "z": 1,
            "elements": [
                "ic2:resource@13"
            ]
        },
        {
            "x": -4,
            "y": -1,
            "z": 2,
            "elements": [
                "ic2:resource@13"
            ]
        },
        {
            "x": -3,
            "y": -1,
            "z": 5,
            "elements": [
                "modularmachinery:blockcasing@0"
            ]
        },
        {
            "x": -4,
            "y": 0,
            "z": 3,
            "elements": [
                "ic2:resource@13"
            ]
        },
        {
            "x": -1,
            "y": 0,
            "z": 4,
            "elements": [
                "avaritia:block_resource@2"
            ]
        },
        {
            "x": 2,
            "y": 0,
            "z": 2,
            "elements": [
                "chisel:technicalnew@3"
            ]
        },
        {
            "x": 1,
            "y": 0,
            "z": 0,
            "elements": [
                "modularmachinery:blockfluidinputhatch",
                "modularmachinery:blockmefluidinputbus"
            ]
        },
        {
            "x": 0,
            "y": -1,
            "z": 7,
            "elements": [
                "contenttweaker:extrememachineblock@0"
            ]
        },
        {
            "x": 0,
            "y": 0,
            "z": 6,
            "elements": [
                "avaritia:block_resource@2"
            ]
        },
        {
            "x": -2,
            "y": 0,
            "z": 5,
            "elements": [
                "chisel:technicalnew@3"
            ]
        },
        {
            "x": 0,
            "y": -1,
            "z": 3,
            "elements": [
                "contenttweaker:extrememachineblock@0"
            ]
        },
        {
            "x": 3,
            "y": -1,
            "z": 4,
            "elements": [
                "contenttweaker:extrememachineblock@0"
            ]
        },
        {
            "x": 3,
            "y": -1,
            "z": 2,
            "elements": [
                "ic2:resource@13"
            ]
        },
        {
            "x": 0,
            "y": 0,
            "z": 1,
            "elements": [
                "avaritia:block_resource@2"
            ]
        },
        {
            "x": 1,
            "y": -1,
            "z": 0,
            "elements": [
                "contenttweaker:extrememachineblock@0"
            ]
        },
        {
            "x": -2,
            "y": 0,
            "z": 8,
            "elements": [
                "ic2:resource@13"
            ]
        },
        {
            "x": 2,
            "y": 0,
            "z": 7,
            "elements": [
                "chisel:technicalnew@3"
            ]
        },
        {
            "x": 1,
            "y": 0,
            "z": 3,
            "elements": [
                "chisel:technicalnew@3"
            ]
        },
        {
            "x": -4,
            "y": -1,
            "z": 5,
            "elements": [
                "contenttweaker:extrememachineblock@0"
            ]
        },
        {
            "x": 2,
            "y": -1,
            "z": 6,
            "elements": [
                "ic2:resource@13"
            ]
        },
        {
            "x": 4,
            "y": -1,
            "z": 5,
            "elements": [
                "contenttweaker:extrememachineblock@0"
            ]
        },
        {
            "x": 2,
            "y": -1,
            "z": 1,
            "elements": [
                "ic2:resource@13"
            ]
        },
        {
            "x": 4,
            "y": 0,
            "z": 4,
            "elements": [
                "contenttweaker:extrememachineblock@0"
            ]
        },
        {
            "x": 3,
            "y": 0,
            "z": 2,
            "elements": [
                "chisel:technicalnew@3"
            ]
        },
        {
            "x": -1,
            "y": 0,
            "z": 1,
            "elements": [
                "chisel:technicalnew@3"
            ]
        },
        {
            "x": 2,
            "y": 0,
            "z": 0,
            "elements": [
                "ic2:resource@13"
            ]
        },
        {
            "x": 0,
            "y": -1,
            "z": 8,
            "elements": [
                "contenttweaker:extrememachineblock@0"
            ]
        },
        {
            "x": 3,
            "y": -1,
            "z": 7,
            "elements": [
                "ic2:resource@13"
            ]
        },
        {
            "x": 1,
            "y": -1,
            "z": 3,
            "elements": [
                "contenttweaker:crystalmatrixforcefieldcontrolblock@0"
            ]
        },
        {
            "x": 1,
            "y": 0,
            "z": 6,
            "elements": [
                "chisel:technicalnew@3"
            ]
        },
        {
            "x": 4,
            "y": -1,
            "z": 4,
            "elements": [
                "contenttweaker:extrememachineblock@0"
            ]
        },
        {
            "x": 2,
            "y": -1,
            "z": 2,
            "elements": [
                "ic2:resource@13"
            ]
        },
        {
            "x": 3,
            "y": 0,
            "z": 5,
            "elements": [
                "chisel:technicalnew@3"
            ]
        },
        {
            "x": 1,
            "y": 0,
            "z": 8,
            "elements": [
                "modularmachinery:blockenergyoutputhatch"
            ]
        },
        {
            "x": -1,
            "y": 0,
            "z": 7,
            "elements": [
                "chisel:technicalnew@3"
            ]
        },
        {
            "x": -2,
            "y": -1,
            "z": 0,
            "elements": [
                "ic2:resource@13"
            ]
        },
        {
            "x": -1,
            "y": -1,
            "z": 1,
            "elements": [
                "modularmachinery:blockcasing@0"
            ]
        },
        {
            "x": -3,
            "y": -1,
            "z": 4,
            "elements": [
                "contenttweaker:extrememachineblock@0"
            ]
        },
        {
            "x": -1,
            "y": -1,
            "z": 5,
            "elements": [
                "contenttweaker:crystalmatrixforcefieldcontrolblock@0"
            ]
        },
        {
            "x": 2,
            "y": 0,
            "z": 3,
            "elements": [
                "chisel:technicalnew@3"
            ]
        },
        {
            "x": 1,
            "y": -1,
            "z": 6,
            "elements": [
                "modularmachinery:blockcasing@0"
            ]
        },
        {
            "x": 0,
            "y": 0,
            "z": 2,
            "elements": [
                "avaritia:block_resource@2"
            ]
        },
        {
            "x": -1,
            "y": 0,
            "z": 0,
            "elements": [
                "modularmachinery:blockfluidinputhatch",
                "modularmachinery:blockmefluidinputbus"
            ]
        },
        {
            "x": -2,
            "y": 0,
            "z": 1,
            "elements": [
                "chisel:technicalnew@3"
            ]
        },
        {
            "x": -1,
            "y": -1,
            "z": 8,
            "elements": [
                "contenttweaker:extrememachineblock@0"
            ]
        },
        {
            "x": -3,
            "y": 0,
            "z": 2,
            "elements": [
                "chisel:technicalnew@3"
            ]
        },
        {
            "x": 2,
            "y": -1,
            "z": 3,
            "elements": [
                "modularmachinery:blockcasing@0"
            ]
        },
        {
            "x": 0,
            "y": 0,
            "z": 5,
            "elements": [
                "avaritia:block_resource@2"
            ]
        },
        {
            "x": -2,
            "y": -1,
            "z": 7,
            "elements": [
                "ic2:resource@13"
            ]
        },
        {
            "x": 2,
            "y": 0,
            "z": 6,
            "elements": [
                "chisel:technicalnew@3"
            ]
        },
        {
            "x": -3,
            "y": -1,
            "z": 2,
            "elements": [
                "ic2:resource@13"
            ]
        },
        {
            "x": 0,
            "y": -1,
            "z": 1,
            "elements": [
                "contenttweaker:extrememachineblock@0"
            ]
        },
        {
            "x": 3,
            "y": 0,
            "z": 3,
            "elements": [
                "chisel:technicalnew@3"
            ]
        },
        {
            "x": 0,
            "y": 0,
            "z": 8,
            "elements": [
                "contenttweaker:extrememachineblock@0"
            ]
        },
        {
            "x": 4,
            "y": 0,
            "z": 7,
            "elements": [
                "ic2:resource@13"
            ]
        },
        {
            "x": -2,
            "y": -1,
            "z": 4,
            "elements": [
                "contenttweaker:extrememachineblock@0"
            ]
        },
        {
            "x": -2,
            "y": 0,
            "z": 4,
            "elements": [
                "avaritia:block_resource@2"
            ]
        },
        {
            "x": 2,
            "y": -1,
            "z": 5,
            "elements": [
                "modularmachinery:blockcasing@0"
            ]
        },
        {
            "x": 0,
            "y": -1,
            "z": 6,
            "elements": [
                "contenttweaker:extrememachineblock@0"
            ]
        },
        {
            "x": -4,
            "y": 0,
            "z": 0,
            "elements": [
                "modularmachinery:blockcasing@4"
            ]
        },
        {
            "x": -4,
            "y": 0,
            "z": 7,
            "elements": [
                "ic2:resource@13"
            ]
        },
        {
            "x": -2,
            "y": -1,
            "z": 8,
            "elements": [
                "ic2:resource@13"
            ]
        },
        {
            "x": 4,
            "y": 0,
            "z": 0,
            "elements": [
                "modularmachinery:blockcasing@4"
            ]
        },
        {
            "x": -2,
            "y": 0,
            "z": 2,
            "elements": [
                "chisel:technicalnew@3"
            ]
        },
        {
            "x": -1,
            "y": 0,
            "z": 6,
            "elements": [
                "chisel:technicalnew@3"
            ]
        },
        {
            "x": 1,
            "y": 0,
            "z": 5,
            "elements": [
                "chisel:technicalnew@3"
            ]
        },
        {
            "x": -1,
            "y": -1,
            "z": 3,
            "elements": [
                "contenttweaker:crystalmatrixforcefieldcontrolblock@0"
            ]
        },
        {
            "x": 2,
            "y": -1,
            "z": 4,
            "elements": [
                "contenttweaker:extrememachineblock@0"
            ]
        },
        {
            "x": -3,
            "y": -1,
            "z": 7,
            "elements": [
                "ic2:resource@13"
            ]
        },
        {
            "x": 3,
            "y": -1,
            "z": 0,
            "elements": [
                "modularmachinery:blockcasing@4"
            ]
        },
        {
            "x": 1,
            "y": 0,
            "z": 1,
            "elements": [
                "chisel:technicalnew@3"
            ]
        },
        {
            "x": -3,
            "y": 0,
            "z": 7,
            "elements": [
                "chisel:technicalnew@3"
            ]
        },
        {
            "x": 1,
            "y": -1,
            "z": 1,
            "elements": [
                "modularmachinery:blockcasing@0"
            ]
        },
        {
            "x": -1,
            "y": 0,
            "z": 8,
            "elements": [
                "modularmachinery:blockenergyoutputhatch"
            ]
        },
        {
            "x": 0,
            "y": -1,
            "z": 2,
            "elements": [
                "contenttweaker:extrememachineblock@0"
            ]
        },
        {
            "x": -4,
            "y": -1,
            "z": 0,
            "elements": [
                "modularmachinery:blockcasing@4"
            ]
        },
        {
            "x": 0,
            "y": 0,
            "z": 3,
            "elements": [
                "avaritia:block_resource@2"
            ]
        },
        {
            "x": -1,
            "y": -1,
            "z": 4,
            "elements": [
                "contenttweaker:extrememachineblock@0"
            ]
        },
        {
            "x": 3,
            "y": -1,
            "z": 6,
            "elements": [
                "ic2:resource@13"
            ]
        },
        {
            "x": 1,
            "y": -1,
            "z": 5,
            "elements": [
                "contenttweaker:crystalmatrixforcefieldcontrolblock@0"
            ]
        },
        {
            "x": -3,
            "y": 0,
            "z": 0,
            "elements": [
                "ic2:resource@13"
            ]
        },
        {
            "x": 3,
            "y": 0,
            "z": 4,
            "elements": [
                "avaritia:block_resource@2"
            ]
        },
        {
            "x": -4,
            "y": 0,
            "z": 1,
            "elements": [
                "ic2:resource@13"
            ]
        },
        {
            "x": 1,
            "y": -1,
            "z": 8,
            "elements": [
                "contenttweaker:extrememachineblock@0"
            ]
        },
        {
            "x": 4,
            "y": -1,
            "z": 7,
            "elements": [
                "modularmachinery:blockcasing@4"
            ]
        },
        {
            "x": -2,
            "y": -1,
            "z": 6,
            "elements": [
                "ic2:resource@13"
            ]
        },
        {
            "x": 4,
            "y": -1,
            "z": 3,
            "elements": [
                "contenttweaker:extrememachineblock@0"
            ]
        },
        {
            "x": -3,
            "y": 0,
            "z": 4,
            "elements": [
                "avaritia:block_resource@2"
            ]
        },
        {
            "x": 4,
            "y": 0,
            "z": 1,
            "elements": [
                "ic2:resource@13"
            ]
        },
        {
            "x": -4,
            "y": -1,
            "z": 7,
            "elements": [
                "modularmachinery:blockcasing@4"
            ]
        },
        {
            "x": 4,
            "y": 0,
            "z": 6,
            "elements": [
                "ic2:resource@13"
            ]
        },
        {
            "x": 4,
            "y": -1,
            "z": 0,
            "elements": [
                "modularmachinery:blockcasing@4"
            ]
        },
        {
            "x": 2,
            "y": 0,
            "z": 5,
            "elements": [
                "chisel:technicalnew@3"
            ]
        },
        {
            "x": -4,
            "y": -1,
            "z": 3,
            "elements": [
                "contenttweaker:extrememachineblock@0"
            ]
        },
        {
            "x": -2,
            "y": 0,
            "z": 7,
            "elements": [
                "chisel:technicalnew@3"
            ]
        },
        {
            "x": -1,
            "y": -1,
            "z": 2,
            "elements": [
                "modularmachinery:blockcasing@0"
            ]
        },
        {
            "x": -2,
            "y": -1,
            "z": 1,
            "elements": [
                "ic2:resource@13"
            ]
        },
        {
            "x": -3,
            "y": -1,
            "z": 0,
            "elements": [
                "modularmachinery:blockcasing@4"
            ]
        },
        {
            "x": -4,
            "y": -1,
            "z": 4,
            "elements": [
                "contenttweaker:extrememachineblock@0"
            ]
        },
        {
            "x": 2,
            "y": 0,
            "z": 8,
            "elements": [
                "ic2:resource@13"
            ]
        },
        {
            "x": -4,
            "y": 0,
            "z": 6,
            "elements": [
                "ic2:resource@13"
            ]
        },
        {
            "x": -3,
            "y": 0,
            "z": 3,
            "elements": [
                "chisel:technicalnew@3"
            ]
        },
        {
            "x": 0,
            "y": 0,
            "z": 4,
            "elements": [
                "avaritia:block_resource@2"
            ]
        },
        {
            "x": 0,
            "y": -1,
            "z": 5,
            "elements": [
                "contenttweaker:extrememachineblock@0"
            ]
        },
        {
            "x": -1,
            "y": 0,
            "z": 2,
            "elements": [
                "chisel:technicalnew@3"
            ]
        },
        {
            "x": -2,
            "y": 0,
            "z": 0,
            "elements": [
                "ic2:resource@13"
            ]
        },
        {
            "x": -1,
            "y": -1,
            "z": 7,
            "elements": [
                "modularmachinery:blockcasing@0"
            ]
        },
        {
            "x": -4,
            "y": 0,
            "z": 2,
            "elements": [
                "ic2:resource@13"
            ]
        },
        {
            "x": 4,
            "y": -1,
            "z": 8,
            "elements": [
                "modularmachinery:blockcasing@4"
            ]
        },
        {
            "x": -3,
            "y": 0,
            "z": 6,
            "elements": [
                "chisel:technicalnew@3"
            ]
        },
        {
            "x": -3,
            "y": -1,
            "z": 6,
            "elements": [
                "ic2:resource@13"
            ]
        },
        {
            "x": -3,
            "y": -1,
            "z": 3,
            "elements": [
                "modularmachinery:blockcasing@0"
            ]
        },
        {
            "x": 0,
            "y": -1,
            "z": 4,
            "elements": [
                "contenttweaker:extrememachineblock@0"
            ]
        },
        {
            "x": -1,
            "y": 0,
            "z": 5,
            "elements": [
                "chisel:technicalnew@3"
            ]
        },
        {
            "x": 3,
            "y": 0,
            "z": 1,
            "elements": [
                "chisel:technicalnew@3"
            ]
        },
        {
            "x": -3,
            "y": 0,
            "z": 8,
            "elements": [
                "ic2:resource@13"
            ]
        },
        {
            "x": -2,
            "y": -1,
            "z": 2,
            "elements": [
                "ic2:resource@13"
            ]
        },
        {
            "x": 3,
            "y": 0,
            "z": 7,
            "elements": [
                "chisel:technicalnew@3"
            ]
        },
        {
            "x": 4,
            "y": 0,
            "z": 2,
            "elements": [
                "ic2:resource@13"
            ]
        },
        {
            "x": 3,
            "y": -1,
            "z": 5,
            "elements": [
                "modularmachinery:blockcasing@0"
            ]
        },
        {
            "x": -2,
            "y": 0,
            "z": 3,
            "elements": [
                "chisel:technicalnew@3"
            ]
        },
        {
            "x": 1,
            "y": 0,
            "z": 4,
            "elements": [
                "avaritia:block_resource@2"
            ]
        },
        {
            "x": -3,
            "y": -1,
            "z": 8,
            "elements": [
                "modularmachinery:blockcasing@4"
            ]
        },
        {
            "x": 3,
            "y": -1,
            "z": 1,
            "elements": [
                "ic2:resource@13"
            ]
        },
        {
            "x": 3,
            "y": -1,
            "z": 8,
            "elements": [
                "modularmachinery:blockcasing@4"
            ]
        },
        {
            "x": 3,
            "y": 0,
            "z": 0,
            "elements": [
                "ic2:resource@13"
            ]
        },
        {
            "x": 2,
            "y": -1,
            "z": 7,
            "elements": [
                "ic2:resource@13"
            ]
        },
        {
            "x": -4,
            "y": 0,
            "z": 5,
            "elements": [
                "ic2:resource@13"
            ]
        },
        {
            "x": -4,
            "y": -1,
            "z": 6,
            "elements": [
                "ic2:resource@13"
            ]
        },
        {
            "x": -2,
            "y": 0,
            "z": 6,
            "elements": [
                "chisel:technicalnew@3"
            ]
        },
        {
            "x": -2,
            "y": -1,
            "z": 3,
            "elements": [
                "modularmachinery:blockcasing@0"
            ]
        },
        {
            "x": 1,
            "y": -1,
            "z": 4,
            "elements": [
                "contenttweaker:extrememachineblock@0"
            ]
        },
        {
            "x": 4,
            "y": 0,
            "z": 5,
            "elements": [
                "ic2:resource@13"
            ]
        },
        {
            "x": 1,
            "y": -1,
            "z": 2,
            "elements": [
                "modularmachinery:blockcasing@0"
            ]
        },
        {
            "x": 2,
            "y": 0,
            "z": 1,
            "elements": [
                "chisel:technicalnew@3"
            ]
        },
        {
            "x": -4,
            "y": 0,
            "z": 8,
            "elements": [
                "modularmachinery:blockcasing@4"
            ]
        },
        {
            "x": 2,
            "y": -1,
            "z": 0,
            "elements": [
                "ic2:resource@13"
            ]
        },
        {
            "x": 0,
            "y": 0,
            "z": 7,
            "elements": [
                "avaritia:block_resource@2"
            ]
        },
        {
            "x": -4,
            "y": -1,
            "z": 1,
            "elements": [
                "modularmachinery:blockcasing@4"
            ]
        },
        {
            "x": -1,
            "y": -1,
            "z": 0,
            "elements": [
                "contenttweaker:extrememachineblock@0"
            ]
        },
        {
            "x": -1,
            "y": 0,
            "z": 3,
            "elements": [
                "chisel:technicalnew@3"
            ]
        },
        {
            "x": -2,
            "y": -1,
            "z": 5,
            "elements": [
                "modularmachinery:blockcasing@0"
            ]
        },
        {
            "x": 4,
            "y": 0,
            "z": 8,
            "elements": [
                "modularmachinery:blockcasing@4"
            ]
        },
        {
            "x": -4,
            "y": -1,
            "z": 8,
            "elements": [
                "modularmachinery:blockcasing@4"
            ]
        },
        {
            "x": 4,
            "y": -1,
            "z": 1,
            "elements": [
                "modularmachinery:blockcasing@4"
            ]
        },
        {
            "x": 2,
            "y": 0,
            "z": 4,
            "elements": [
                "avaritia:block_resource@2"
            ]
        },
        {
            "x": 4,
            "y": -1,
            "z": 6,
            "elements": [
                "ic2:resource@13"
            ]
        },
        {
            "x": 1,
            "y": 0,
            "z": 2,
            "elements": [
                "chisel:technicalnew@3"
            ]
        }
    ]}