{
    "registryname": "extreme_stellarator", 
    "localizedname": "极限仿星器", 
    "parts": [
        {
            "x": 8,
            "y": 0,
            "z": 26,
            "elements": [
                "contenttweaker:arkmachineblock@0"
            ]
        },
        {
            "x": -14,
            "y": -1,
            "z": 16,
            "elements": [
                "contenttweaker:infinite_coil@0"
            ]
        },
        {
            "x": 14,
            "y": 1,
            "z": 19,
            "elements": [
                "contenttweaker:arkmachineblock@0"
            ]
        },
        {
            "x": -13,
            "y": -2,
            "z": 22,
            "elements": [
                "contenttweaker:arkmachineblock@0"
            ]
        },
        {
            "x": -15,
            "y": 0,
            "z": 22,
            "elements": [
                "contenttweaker:arkmachineblock@0"
            ]
        },
        {
            "x": -6,
            "y": 1,
            "z": 29,
            "elements": [
                "contenttweaker:arkmachineblock@0"
            ]
        },
        {
            "x": -12,
            "y": 0,
            "z": 20,
            "elements": [
                "contenttweaker:arkmachineblock@0"
            ]
        },
        {
            "x": -10,
            "y": 0,
            "z": 25,
            "elements": [
                "contenttweaker:arkmachineblock@0"
            ]
        },
        {
            "x": 5,
            "y": -1,
            "z": 1,
            "elements": [
                "contenttweaker:arkmachineblock@0"
            ]
        },
        {
            "x": -16,
            "y": 0,
            "z": 19,
            "elements": [
                "contenttweaker:arkmachineblock@0"
            ]
        },
        {
            "x": 4,
            "y": -1,
            "z": 28,
            "elements": [
                "contenttweaker:arkmachineblock@0"
            ]
        },
        {
            "x": 1,
            "y": 0,
            "z": 0,
            "elements": [
                "modularmachinery:blockinputbus",
                "modularmachinery:blockmeiteminputbus",
                "modularmachinery:blockmepatternprovider"
            ]
        },
        {
            "x": -12,
            "y": -1,
            "z": 9,
            "elements": [
                "contenttweaker:infinite_coil@0"
            ]
        },
        {
            "x": -14,
            "y": 1,
            "z": 21,
            "elements": [
                "contenttweaker:arkmachineblock@0"
            ]
        },
        {
            "x": 5,
            "y": 0,
            "z": 28,
            "elements": [
                "contenttweaker:arkmachineblock@0"
            ]
        },
        {
            "x": -11,
            "y": -2,
            "z": 25,
            "elements": [
                "contenttweaker:arkmachineblock@0"
            ]
        },
        {
            "x": -14,
            "y": -2,
            "z": 14,
            "elements": [
                "contenttweaker:arkmachineblock@0"
            ]
        },
        {
            "x": -13,
            "y": 1,
            "z": 9,
            "elements": [
                "contenttweaker:arkmachineblock@0"
            ]
        },
        {
            "x": -13,
            "y": 0,
            "z": 25,
            "elements": [
                "contenttweaker:arkmachineblock@0"
            ]
        },
        {
            "x": -15,
            "y": -1,
            "z": 21,
            "elements": [
                "contenttweaker:arkmachineblock@0"
            ]
        },
        {
            "x": 2,
            "y": 0,
            "z": 0,
            "elements": [
                "contenttweaker:arkmachineblock@0"
            ]
        },
        {
            "x": -14,
            "y": -2,
            "z": 19,
            "elements": [
                "contenttweaker:arkmachineblock@0"
            ]
        },
        {
            "x": 14,
            "y": 1,
            "z": 22,
            "elements": [
                "contenttweaker:arkmachineblock@0"
            ]
        },
        {
            "x": 15,
            "y": 1,
            "z": 14,
            "elements": [
                "contenttweaker:arkmachineblock@0"
            ]
        },
        {
            "x": 9,
            "y": 0,
            "z": 3,
            "elements": [
                "contenttweaker:arkmachineblock@0"
            ]
        },
        {
            "x": -12,
            "y": -2,
            "z": 25,
            "elements": [
                "contenttweaker:arkmachineblock@0"
            ]
        },
        {
            "x": 16,
            "y": -1,
            "z": 19,
            "elements": [
                "contenttweaker:arkmachineblock@0"
            ]
        },
        {
            "x": 13,
            "y": 0,
            "z": 16,
            "elements": [
                "contenttweaker:arkmachineblock@0"
            ]
        },
        {
            "x": -9,
            "y": 1,
            "z": 4,
            "elements": [
                "contenttweaker:arkmachineblock@0"
            ]
        },
        {
            "x": -1,
            "y": 0,
            "z": 0,
            "elements": [
                "modularmachinery:blockfluidinputhatch",
                "modularmachinery:blockmefluidinputbus",
                "modularmachinery:blockmepatternprovider"
            ]
        },
        {
            "x": -12,
            "y": 0,
            "z": 25,
            "elements": [
                "contenttweaker:infinite_coil@0"
            ]
        },
        {
            "x": -14,
            "y": -2,
            "z": 12,
            "elements": [
                "contenttweaker:arkmachineblock@0"
            ]
        },
        {
            "x": 14,
            "y": 0,
            "z": 19,
            "elements": [
                "contenttweaker:infinite_coil@0"
            ]
        },
        {
            "x": 14,
            "y": -1,
            "z": 14,
            "elements": [
                "contenttweaker:infinite_coil@0"
            ]
        },
        {
            "x": -16,
            "y": 0,
            "z": 12,
            "elements": [
                "contenttweaker:arkmachineblock@0"
            ]
        },
        {
            "x": -12,
            "y": -1,
            "z": 21,
            "elements": [
                "contenttweaker:arkmachineblock@0"
            ]
        },
        {
            "x": 6,
            "y": 0,
            "z": 1,
            "elements": [
                "contenttweaker:arkmachineblock@0"
            ]
        },
        {
            "x": 8,
            "y": -2,
            "z": 29,
            "elements": [
                "contenttweaker:arkmachineblock@0"
            ]
        },
        {
            "x": -14,
            "y": -1,
            "z": 9,
            "elements": [
                "contenttweaker:arkmachineblock@0"
            ]
        },
        {
            "x": 5,
            "y": -1,
            "z": 4,
            "elements": [
                "contenttweaker:arkmachineblock@0"
            ]
        },
        {
            "x": -14,
            "y": -1,
            "z": 19,
            "elements": [
                "contenttweaker:infinite_coil@0"
            ]
        },
        {
            "x": 13,
            "y": -1,
            "z": 19,
            "elements": [
                "contenttweaker:arkmachineblock@0"
            ]
        },
        {
            "x": 3,
            "y": 0,
            "z": 3,
            "elements": [
                "contenttweaker:arkmachineblock@0"
            ]
        },
        {
            "x": 9,
            "y": 0,
            "z": 29,
            "elements": [
                "contenttweaker:arkmachineblock@0"
            ]
        },
        {
            "x": 15,
            "y": 0,
            "z": 21,
            "elements": [
                "contenttweaker:arkmachineblock@0"
            ]
        },
        {
            "x": 15,
            "y": 0,
            "z": 14,
            "elements": [
                "contenttweaker:infinite_coil@0"
            ]
        },
        {
            "x": -11,
            "y": -1,
            "z": 9,
            "elements": [
                "contenttweaker:arkmachineblock@0"
            ]
        },
        {
            "x": -14,
            "y": -1,
            "z": 12,
            "elements": [
                "contenttweaker:infinite_coil@0"
            ]
        },
        {
            "x": -13,
            "y": 0,
            "z": 19,
            "elements": [
                "contenttweaker:arkmachineblock@0"
            ]
        },
        {
            "x": 13,
            "y": -1,
            "z": 26,
            "elements": [
                "contenttweaker:arkmachineblock@0"
            ]
        },
        {
            "x": -11,
            "y": 0,
            "z": 25,
            "elements": [
                "contenttweaker:infinite_coil@0"
            ]
        },
        {
            "x": -10,
            "y": -1,
            "z": 4,
            "elements": [
                "contenttweaker:infinite_coil@0"
            ]
        },
        {
            "x": -7,
            "y": 0,
            "z": 5,
            "elements": [
                "contenttweaker:arkmachineblock@0"
            ]
        },
        {
            "x": 4,
            "y": 0,
            "z": 0,
            "elements": [
                "contenttweaker:arkmachineblock@0"
            ]
        },
        {
            "x": -6,
            "y": -2,
            "z": 3,
            "elements": [
                "contenttweaker:arkmachineblock@0"
            ]
        },
        {
            "x": 10,
            "y": -2,
            "z": 26,
            "elements": [
                "contenttweaker:arkmachineblock@0"
            ]
        },
        {
            "x": -13,
            "y": 0,
            "z": 12,
            "elements": [
                "contenttweaker:infinite_coil@0"
            ]
        },
        {
            "x": -10,
            "y": -1,
            "z": 29,
            "elements": [
                "contenttweaker:arkmachineblock@0"
            ]
        },
        {
            "x": 14,
            "y": -1,
            "z": 8,
            "elements": [
                "contenttweaker:arkmachineblock@0"
            ]
        },
        {
            "x": 10,
            "y": -1,
            "z": 26,
            "elements": [
                "contenttweaker:infinite_coil@0"
            ]
        },
        {
            "x": 12,
            "y": 1,
            "z": 8,
            "elements": [
                "contenttweaker:arkmachineblock@0"
            ]
        },
        {
            "x": -8,
            "y": 0,
            "z": 3,
            "elements": [
                "contenttweaker:infinite_coil@0"
            ]
        },
        {
            "x": -13,
            "y": 1,
            "z": 12,
            "elements": [
                "contenttweaker:arkmachineblock@0"
            ]
        },
        {
            "x": 16,
            "y": -1,
            "z": 20,
            "elements": [
                "contenttweaker:arkmachineblock@0"
            ]
        },
        {
            "x": -23,
            "y": 5,
            "z": 32,
            "elements": [
                "minecraft:air@0"
            ]
        },
        {
            "x": 8,
            "y": 1,
            "z": 28,
            "elements": [
                "contenttweaker:arkmachineblock@0"
            ]
        },
        {
            "x": 13,
            "y": -1,
            "z": 22,
            "elements": [
                "contenttweaker:infinite_coil@0"
            ]
        },
        {
            "x": 11,
            "y": 0,
            "z": 26,
            "elements": [
                "contenttweaker:infinite_coil@0"
            ]
        },
        {
            "x": -16,
            "y": 0,
            "z": 13,
            "elements": [
                "contenttweaker:arkmachineblock@0"
            ]
        },
        {
            "x": 12,
            "y": -2,
            "z": 23,
            "elements": [
                "contenttweaker:arkmachineblock@0"
            ]
        },
        {
            "x": -14,
            "y": -2,
            "z": 13,
            "elements": [
                "contenttweaker:arkmachineblock@0"
            ]
        },
        {
            "x": -13,
            "y": 0,
            "z": 13,
            "elements": [
                "contenttweaker:arkmachineblock@0"
            ]
        },
        {
            "x": 5,
            "y": -2,
            "z": 3,
            "elements": [
                "contenttweaker:arkmachineblock@0"
            ]
        },
        {
            "x": -4,
            "y": -1,
            "z": 4,
            "elements": [
                "contenttweaker:arkmachineblock@0"
            ]
        },
        {
            "x": -1,
            "y": -1,
            "z": 29,
            "elements": [
                "contenttweaker:arkmachineblock@0"
            ]
        },
        {
            "x": 11,
            "y": 1,
            "z": 26,
            "elements": [
                "contenttweaker:arkmachineblock@0"
            ]
        },
        {
            "x": -2,
            "y": 0,
            "z": 0,
            "elements": [
                "contenttweaker:arkmachineblock@0"
            ]
        },
        {
            "x": 8,
            "y": -1,
            "z": 4,
            "elements": [
                "contenttweaker:infinite_coil@0"
            ]
        },
        {
            "x": 7,
            "y": -1,
            "z": 28,
            "elements": [
                "contenttweaker:infinite_coil@0"
            ]
        },
        {
            "x": -13,
            "y": 1,
            "z": 21,
            "elements": [
                "contenttweaker:arkmachineblock@0"
            ]
        },
        {
            "x": -4,
            "y": -1,
            "z": 29,
            "elements": [
                "contenttweaker:infinite_coil@0"
            ]
        },
        {
            "x": -7,
            "y": -1,
            "z": 4,
            "elements": [
                "contenttweaker:infinite_coil@0"
            ]
        },
        {
            "x": 15,
            "y": -2,
            "z": 16,
            "elements": [
                "contenttweaker:arkmachineblock@0"
            ]
        },
        {
            "x": 6,
            "y": 0,
            "z": 3,
            "elements": [
                "contenttweaker:infinite_coil@0"
            ]
        },
        {
            "x": -14,
            "y": 0,
            "z": 20,
            "elements": [
                "contenttweaker:infinite_coil@0"
            ]
        },
        {
            "x": 8,
            "y": 0,
            "z": 28,
            "elements": [
                "contenttweaker:infinite_coil@0"
            ]
        },
        {
            "x": 8,
            "y": -2,
            "z": 3,
            "elements": [
                "contenttweaker:arkmachineblock@0"
            ]
        },
        {
            "x": -4,
            "y": -2,
            "z": 1,
            "elements": [
                "contenttweaker:arkmachineblock@0"
            ]
        },
        {
            "x": 11,
            "y": -2,
            "z": 8,
            "elements": [
                "contenttweaker:arkmachineblock@0"
            ]
        },
        {
            "x": -8,
            "y": -2,
            "z": 5,
            "elements": [
                "contenttweaker:arkmachineblock@0"
            ]
        },
        {
            "x": -14,
            "y": -1,
            "z": 13,
            "elements": [
                "contenttweaker:infinite_coil@0"
            ]
        },
        {
            "x": -6,
            "y": 0,
            "z": 1,
            "elements": [
                "contenttweaker:arkmachineblock@0"
            ]
        },
        {
            "x": 9,
            "y": 1,
            "z": 4,
            "elements": [
                "contenttweaker:arkmachineblock@0"
            ]
        },
        {
            "x": -7,
            "y": -1,
            "z": 29,
            "elements": [
                "contenttweaker:infinite_coil@0"
            ]
        },
        {
            "x": 11,
            "y": -1,
            "z": 8,
            "elements": [
                "contenttweaker:infinite_coil@0"
            ]
        },
        {
            "x": 7,
            "y": -2,
            "z": 28,
            "elements": [
                "contenttweaker:arkmachineblock@0"
            ]
        },
        {
            "x": -13,
            "y": -2,
            "z": 20,
            "elements": [
                "contenttweaker:arkmachineblock@0"
            ]
        },
        {
            "x": -4,
            "y": -1,
            "z": 1,
            "elements": [
                "contenttweaker:infinite_coil@0"
            ]
        },
        {
            "x": 16,
            "y": 0,
            "z": 16,
            "elements": [
                "contenttweaker:arkmachineblock@0"
            ]
        },
        {
            "x": -9,
            "y": 0,
            "z": 3,
            "elements": [
                "contenttweaker:arkmachineblock@0"
            ]
        },
        {
            "x": 12,
            "y": 0,
            "z": 8,
            "elements": [
                "contenttweaker:infinite_coil@0"
            ]
        },
        {
            "x": 13,
            "y": -1,
            "z": 15,
            "elements": [
                "contenttweaker:arkmachineblock@0"
            ]
        },
        {
            "x": -14,
            "y": 0,
            "z": 10,
            "elements": [
                "contenttweaker:infinite_coil@0"
            ]
        },
        {
            "x": 14,
            "y": 0,
            "z": 12,
            "elements": [
                "contenttweaker:infinite_coil@0"
            ]
        },
        {
            "x": 12,
            "y": 0,
            "z": 11,
            "elements": [
                "contenttweaker:arkmachineblock@0"
            ]
        },
        {
            "x": -13,
            "y": -1,
            "z": 21,
            "elements": [
                "contenttweaker:infinite_coil@0"
            ]
        },
        {
            "x": 15,
            "y": 1,
            "z": 20,
            "elements": [
                "contenttweaker:arkmachineblock@0"
            ]
        },
        {
            "x": -16,
            "y": 0,
            "z": 15,
            "elements": [
                "contenttweaker:arkmachineblock@0"
            ]
        },
        {
            "x": -2,
            "y": 0,
            "z": 32,
            "elements": [
                "contenttweaker:arkmachineblock@0"
            ]
        },
        {
            "x": -15,
            "y": -1,
            "z": 11,
            "elements": [
                "contenttweaker:arkmachineblock@0"
            ]
        },
        {
            "x": 6,
            "y": -2,
            "z": 3,
            "elements": [
                "contenttweaker:arkmachineblock@0"
            ]
        },
        {
            "x": 4,
            "y": 0,
            "z": 3,
            "elements": [
                "contenttweaker:infinite_coil@0"
            ]
        },
        {
            "x": -5,
            "y": -1,
            "z": 4,
            "elements": [
                "contenttweaker:arkmachineblock@0"
            ]
        },
        {
            "x": 5,
            "y": 0,
            "z": 31,
            "elements": [
                "contenttweaker:arkmachineblock@0"
            ]
        },
        {
            "x": 14,
            "y": 1,
            "z": 12,
            "elements": [
                "contenttweaker:arkmachineblock@0"
            ]
        },
        {
            "x": -14,
            "y": -2,
            "z": 15,
            "elements": [
                "contenttweaker:arkmachineblock@0"
            ]
        },
        {
            "x": -3,
            "y": -1,
            "z": 32,
            "elements": [
                "contenttweaker:arkmachineblock@0"
            ]
        },
        {
            "x": -13,
            "y": 0,
            "z": 6,
            "elements": [
                "contenttweaker:arkmachineblock@0"
            ]
        },
        {
            "x": -10,
            "y": -2,
            "z": 5,
            "elements": [
                "contenttweaker:arkmachineblock@0"
            ]
        },
        {
            "x": 15,
            "y": 0,
            "z": 11,
            "elements": [
                "contenttweaker:arkmachineblock@0"
            ]
        },
        {
            "x": 15,
            "y": 1,
            "z": 13,
            "elements": [
                "contenttweaker:arkmachineblock@0"
            ]
        },
        {
            "x": -7,
            "y": -2,
            "z": 3,
            "elements": [
                "contenttweaker:arkmachineblock@0"
            ]
        },
        {
            "x": -13,
            "y": 0,
            "z": 15,
            "elements": [
                "contenttweaker:arkmachineblock@0"
            ]
        },
        {
            "x": -2,
            "y": -1,
            "z": 31,
            "elements": [
                "contenttweaker:infinite_coil@0"
            ]
        },
        {
            "x": -4,
            "y": 1,
            "z": 31,
            "elements": [
                "contenttweaker:arkmachineblock@0"
            ]
        },
        {
            "x": 15,
            "y": 0,
            "z": 13,
            "elements": [
                "contenttweaker:infinite_coil@0"
            ]
        },
        {
            "x": -14,
            "y": -2,
            "z": 22,
            "elements": [
                "contenttweaker:arkmachineblock@0"
            ]
        },
        {
            "x": -15,
            "y": 0,
            "z": 20,
            "elements": [
                "contenttweaker:infinite_coil@0"
            ]
        },
        {
            "x": 1,
            "y": 0,
            "z": 3,
            "elements": [
                "contenttweaker:arkmachineblock@0"
            ]
        },
        {
            "x": 14,
            "y": -1,
            "z": 13,
            "elements": [
                "contenttweaker:infinite_coil@0"
            ]
        },
        {
            "x": 14,
            "y": 1,
            "z": 15,
            "elements": [
                "contenttweaker:arkmachineblock@0"
            ]
        },
        {
            "x": -7,
            "y": 0,
            "z": 27,
            "elements": [
                "contenttweaker:arkmachineblock@0"
            ]
        },
        {
            "x": -15,
            "y": -2,
            "z": 20,
            "elements": [
                "contenttweaker:arkmachineblock@0"
            ]
        },
        {
            "x": 15,
            "y": -1,
            "z": 15,
            "elements": [
                "contenttweaker:infinite_coil@0"
            ]
        },
        {
            "x": 3,
            "y": -1,
            "z": 32,
            "elements": [
                "contenttweaker:arkmachineblock@0"
            ]
        },
        {
            "x": -1,
            "y": 1,
            "z": 31,
            "elements": [
                "contenttweaker:arkmachineblock@0"
            ]
        },
        {
            "x": 9,
            "y": 0,
            "z": 6,
            "elements": [
                "contenttweaker:arkmachineblock@0"
            ]
        },
        {
            "x": 14,
            "y": -2,
            "z": 13,
            "elements": [
                "contenttweaker:arkmachineblock@0"
            ]
        },
        {
            "x": 14,
            "y": -2,
            "z": 11,
            "elements": [
                "contenttweaker:arkmachineblock@0"
            ]
        },
        {
            "x": 5,
            "y": 1,
            "z": 30,
            "elements": [
                "contenttweaker:arkmachineblock@0"
            ]
        },
        {
            "x": -4,
            "y": 0,
            "z": 28,
            "elements": [
                "contenttweaker:arkmachineblock@0"
            ]
        },
        {
            "x": 8,
            "y": 0,
            "z": 27,
            "elements": [
                "contenttweaker:infinite_coil@0"
            ]
        },
        {
            "x": 14,
            "y": 1,
            "z": 18,
            "elements": [
                "contenttweaker:arkmachineblock@0"
            ]
        },
        {
            "x": 4,
            "y": 0,
            "z": 32,
            "elements": [
                "contenttweaker:arkmachineblock@0"
            ]
        },
        {
            "x": 10,
            "y": -2,
            "z": 28,
            "elements": [
                "contenttweaker:arkmachineblock@0"
            ]
        },
        {
            "x": 16,
            "y": -1,
            "z": 12,
            "elements": [
                "contenttweaker:arkmachineblock@0"
            ]
        },
        {
            "x": -13,
            "y": -1,
            "z": 7,
            "elements": [
                "contenttweaker:arkmachineblock@0"
            ]
        },
        {
            "x": -13,
            "y": 0,
            "z": 22,
            "elements": [
                "contenttweaker:infinite_coil@0"
            ]
        },
        {
            "x": -5,
            "y": -1,
            "z": 28,
            "elements": [
                "contenttweaker:arkmachineblock@0"
            ]
        },
        {
            "x": -7,
            "y": 1,
            "z": 28,
            "elements": [
                "contenttweaker:arkmachineblock@0"
            ]
        },
        {
            "x": 12,
            "y": -1,
            "z": 25,
            "elements": [
                "contenttweaker:infinite_coil@0"
            ]
        },
        {
            "x": -4,
            "y": -2,
            "z": 3,
            "elements": [
                "contenttweaker:arkmachineblock@0"
            ]
        },
        {
            "x": 8,
            "y": 1,
            "z": 27,
            "elements": [
                "contenttweaker:arkmachineblock@0"
            ]
        },
        {
            "x": -6,
            "y": 0,
            "z": 3,
            "elements": [
                "contenttweaker:infinite_coil@0"
            ]
        },
        {
            "x": 14,
            "y": 1,
            "z": 20,
            "elements": [
                "contenttweaker:arkmachineblock@0"
            ]
        },
        {
            "x": 4,
            "y": -1,
            "z": 32,
            "elements": [
                "contenttweaker:arkmachineblock@0"
            ]
        },
        {
            "x": 16,
            "y": -1,
            "z": 15,
            "elements": [
                "contenttweaker:arkmachineblock@0"
            ]
        },
        {
            "x": 7,
            "y": -1,
            "z": 27,
            "elements": [
                "contenttweaker:arkmachineblock@0"
            ]
        },
        {
            "x": 10,
            "y": -1,
            "z": 28,
            "elements": [
                "contenttweaker:infinite_coil@0"
            ]
        },
        {
            "x": -12,
            "y": 0,
            "z": 7,
            "elements": [
                "contenttweaker:infinite_coil@0"
            ]
        },
        {
            "x": -15,
            "y": 0,
            "z": 15,
            "elements": [
                "contenttweaker:infinite_coil@0"
            ]
        },
        {
            "x": -12,
            "y": 1,
            "z": 7,
            "elements": [
                "contenttweaker:arkmachineblock@0"
            ]
        },
        {
            "x": 13,
            "y": -1,
            "z": 12,
            "elements": [
                "contenttweaker:infinite_coil@0"
            ]
        },
        {
            "x": 14,
            "y": -1,
            "z": 20,
            "elements": [
                "contenttweaker:infinite_coil@0"
            ]
        },
        {
            "x": -8,
            "y": -1,
            "z": 27,
            "elements": [
                "contenttweaker:infinite_coil@0"
            ]
        },
        {
            "x": 8,
            "y": 0,
            "z": 5,
            "elements": [
                "contenttweaker:infinite_coil@0"
            ]
        },
        {
            "x": 8,
            "y": -1,
            "z": 6,
            "elements": [
                "contenttweaker:arkmachineblock@0"
            ]
        },
        {
            "x": 2,
            "y": 0,
            "z": 31,
            "elements": [
                "contenttweaker:infinite_coil@0"
            ]
        },
        {
            "x": -5,
            "y": 0,
            "z": 3,
            "elements": [
                "contenttweaker:infinite_coil@0"
            ]
        },
        {
            "x": 11,
            "y": 0,
            "z": 28,
            "elements": [
                "contenttweaker:arkmachineblock@0"
            ]
        },
        {
            "x": -8,
            "y": -2,
            "z": 27,
            "elements": [
                "contenttweaker:arkmachineblock@0"
            ]
        },
        {
            "x": -4,
            "y": 0,
            "z": 0,
            "elements": [
                "contenttweaker:arkmachineblock@0"
            ]
        },
        {
            "x": 4,
            "y": -2,
            "z": 31,
            "elements": [
                "contenttweaker:arkmachineblock@0"
            ]
        },
        {
            "x": 13,
            "y": -2,
            "z": 12,
            "elements": [
                "contenttweaker:arkmachineblock@0"
            ]
        },
        {
            "x": 11,
            "y": -2,
            "z": 6,
            "elements": [
                "contenttweaker:arkmachineblock@0"
            ]
        },
        {
            "x": -8,
            "y": -2,
            "z": 28,
            "elements": [
                "contenttweaker:arkmachineblock@0"
            ]
        },
        {
            "x": -10,
            "y": 0,
            "z": 28,
            "elements": [
                "contenttweaker:infinite_coil@0"
            ]
        },
        {
            "x": 7,
            "y": -1,
            "z": 30,
            "elements": [
                "contenttweaker:arkmachineblock@0"
            ]
        },
        {
            "x": 16,
            "y": -1,
            "z": 17,
            "elements": [
                "contenttweaker:arkmachineblock@0"
            ]
        },
        {
            "x": -12,
            "y": 0,
            "z": 8,
            "elements": [
                "contenttweaker:infinite_coil@0"
            ]
        },
        {
            "x": -4,
            "y": -2,
            "z": 30,
            "elements": [
                "contenttweaker:arkmachineblock@0"
            ]
        },
        {
            "x": -12,
            "y": -2,
            "z": 23,
            "elements": [
                "contenttweaker:arkmachineblock@0"
            ]
        },
        {
            "x": -4,
            "y": 0,
            "z": 30,
            "elements": [
                "contenttweaker:infinite_coil@0"
            ]
        },
        {
            "x": 12,
            "y": 0,
            "z": 7,
            "elements": [
                "contenttweaker:infinite_coil@0"
            ]
        },
        {
            "x": 2,
            "y": 0,
            "z": 32,
            "elements": [
                "contenttweaker:arkmachineblock@0"
            ]
        },
        {
            "x": 14,
            "y": -2,
            "z": 14,
            "elements": [
                "contenttweaker:arkmachineblock@0"
            ]
        },
        {
            "x": -11,
            "y": -1,
            "z": 28,
            "elements": [
                "contenttweaker:arkmachineblock@0"
            ]
        },
        {
            "x": 12,
            "y": 1,
            "z": 7,
            "elements": [
                "contenttweaker:arkmachineblock@0"
            ]
        },
        {
            "x": 0,
            "y": 0,
            "z": 3,
            "elements": [
                "contenttweaker:arkmachineblock@0"
            ]
        },
        {
            "x": 11,
            "y": -1,
            "z": 6,
            "elements": [
                "contenttweaker:infinite_coil@0"
            ]
        },
        {
            "x": -13,
            "y": -1,
            "z": 8,
            "elements": [
                "contenttweaker:infinite_coil@0"
            ]
        },
        {
            "x": 16,
            "y": -1,
            "z": 18,
            "elements": [
                "contenttweaker:arkmachineblock@0"
            ]
        },
        {
            "x": -9,
            "y": -1,
            "z": 4,
            "elements": [
                "contenttweaker:infinite_coil@0"
            ]
        },
        {
            "x": 1,
            "y": -1,
            "z": 32,
            "elements": [
                "contenttweaker:arkmachineblock@0"
            ]
        },
        {
            "x": -13,
            "y": -2,
            "z": 8,
            "elements": [
                "contenttweaker:arkmachineblock@0"
            ]
        },
        {
            "x": 12,
            "y": 0,
            "z": 6,
            "elements": [
                "contenttweaker:infinite_coil@0"
            ]
        },
        {
            "x": -7,
            "y": 0,
            "z": 28,
            "elements": [
                "contenttweaker:infinite_coil@0"
            ]
        },
        {
            "x": 11,
            "y": -2,
            "z": 7,
            "elements": [
                "contenttweaker:arkmachineblock@0"
            ]
        },
        {
            "x": 14,
            "y": 0,
            "z": 18,
            "elements": [
                "contenttweaker:infinite_coil@0"
            ]
        },
        {
            "x": -1,
            "y": 0,
            "z": 32,
            "elements": [
                "contenttweaker:arkmachineblock@0"
            ]
        },
        {
            "x": -9,
            "y": -1,
            "z": 29,
            "elements": [
                "contenttweaker:arkmachineblock@0"
            ]
        },
        {
            "x": 14,
            "y": -2,
            "z": 21,
            "elements": [
                "contenttweaker:arkmachineblock@0"
            ]
        },
        {
            "x": -8,
            "y": -1,
            "z": 28,
            "elements": [
                "contenttweaker:infinite_coil@0"
            ]
        },
        {
            "x": -8,
            "y": 1,
            "z": 4,
            "elements": [
                "contenttweaker:arkmachineblock@0"
            ]
        },
        {
            "x": -10,
            "y": -1,
            "z": 8,
            "elements": [
                "contenttweaker:arkmachineblock@0"
            ]
        },
        {
            "x": 13,
            "y": -1,
            "z": 18,
            "elements": [
                "contenttweaker:arkmachineblock@0"
            ]
        },
        {
            "x": -3,
            "y": 0,
            "z": 3,
            "elements": [
                "contenttweaker:arkmachineblock@0"
            ]
        },
        {
            "x": -2,
            "y": -1,
            "z": 32,
            "elements": [
                "contenttweaker:arkmachineblock@0"
            ]
        },
        {
            "x": 11,
            "y": -1,
            "z": 7,
            "elements": [
                "contenttweaker:infinite_coil@0"
            ]
        },
        {
            "x": 12,
            "y": 0,
            "z": 12,
            "elements": [
                "contenttweaker:arkmachineblock@0"
            ]
        },
        {
            "x": 10,
            "y": -1,
            "z": 27,
            "elements": [
                "contenttweaker:infinite_coil@0"
            ]
        },
        {
            "x": -9,
            "y": 0,
            "z": 5,
            "elements": [
                "contenttweaker:infinite_coil@0"
            ]
        },
        {
            "x": 10,
            "y": -1,
            "z": 24,
            "elements": [
                "contenttweaker:arkmachineblock@0"
            ]
        },
        {
            "x": 13,
            "y": -2,
            "z": 21,
            "elements": [
                "contenttweaker:arkmachineblock@0"
            ]
        },
        {
            "x": -6,
            "y": 0,
            "z": 30,
            "elements": [
                "contenttweaker:infinite_coil@0"
            ]
        },
        {
            "x": 12,
            "y": 1,
            "z": 6,
            "elements": [
                "contenttweaker:arkmachineblock@0"
            ]
        },
        {
            "x": 10,
            "y": -2,
            "z": 27,
            "elements": [
                "contenttweaker:arkmachineblock@0"
            ]
        },
        {
            "x": -5,
            "y": -1,
            "z": 31,
            "elements": [
                "contenttweaker:arkmachineblock@0"
            ]
        },
        {
            "x": -14,
            "y": 0,
            "z": 23,
            "elements": [
                "contenttweaker:arkmachineblock@0"
            ]
        },
        {
            "x": 14,
            "y": 0,
            "z": 21,
            "elements": [
                "contenttweaker:infinite_coil@0"
            ]
        },
        {
            "x": 11,
            "y": 0,
            "z": 24,
            "elements": [
                "contenttweaker:infinite_coil@0"
            ]
        },
        {
            "x": 14,
            "y": 0,
            "z": 17,
            "elements": [
                "contenttweaker:infinite_coil@0"
            ]
        },
        {
            "x": -2,
            "y": 0,
            "z": 3,
            "elements": [
                "contenttweaker:arkmachineblock@0"
            ]
        },
        {
            "x": -12,
            "y": 0,
            "z": 5,
            "elements": [
                "contenttweaker:arkmachineblock@0"
            ]
        },
        {
            "x": -5,
            "y": -2,
            "z": 30,
            "elements": [
                "contenttweaker:arkmachineblock@0"
            ]
        },
        {
            "x": -7,
            "y": 0,
            "z": 30,
            "elements": [
                "contenttweaker:arkmachineblock@0"
            ]
        },
        {
            "x": -12,
            "y": -1,
            "z": 11,
            "elements": [
                "contenttweaker:arkmachineblock@0"
            ]
        },
        {
            "x": 11,
            "y": 1,
            "z": 24,
            "elements": [
                "contenttweaker:arkmachineblock@0"
            ]
        },
        {
            "x": 11,
            "y": 0,
            "z": 27,
            "elements": [
                "contenttweaker:infinite_coil@0"
            ]
        },
        {
            "x": 13,
            "y": -1,
            "z": 17,
            "elements": [
                "contenttweaker:arkmachineblock@0"
            ]
        },
        {
            "x": -14,
            "y": 1,
            "z": 11,
            "elements": [
                "contenttweaker:arkmachineblock@0"
            ]
        },
        {
            "x": 1,
            "y": 0,
            "z": 32,
            "elements": [
                "contenttweaker:arkmachineblock@0"
            ]
        },
        {
            "x": -1,
            "y": 0,
            "z": 3,
            "elements": [
                "contenttweaker:arkmachineblock@0"
            ]
        },
        {
            "x": -6,
            "y": -1,
            "z": 4,
            "elements": [
                "contenttweaker:arkmachineblock@0"
            ]
        },
        {
            "x": -7,
            "y": -1,
            "z": 2,
            "elements": [
                "contenttweaker:arkmachineblock@0"
            ]
        },
        {
            "x": -10,
            "y": 1,
            "z": 28,
            "elements": [
                "contenttweaker:arkmachineblock@0"
            ]
        },
        {
            "x": -16,
            "y": 0,
            "z": 14,
            "elements": [
                "contenttweaker:arkmachineblock@0"
            ]
        },
        {
            "x": 14,
            "y": 1,
            "z": 17,
            "elements": [
                "contenttweaker:arkmachineblock@0"
            ]
        },
        {
            "x": -12,
            "y": 0,
            "z": 22,
            "elements": [
                "contenttweaker:arkmachineblock@0"
            ]
        },
        {
            "x": -12,
            "y": 1,
            "z": 8,
            "elements": [
                "contenttweaker:arkmachineblock@0"
            ]
        },
        {
            "x": 0,
            "y": -1,
            "z": 32,
            "elements": [
                "contenttweaker:arkmachineblock@0"
            ]
        },
        {
            "x": 11,
            "y": 1,
            "z": 27,
            "elements": [
                "contenttweaker:arkmachineblock@0"
            ]
        },
        {
            "x": -5,
            "y": 0,
            "z": 29,
            "elements": [
                "contenttweaker:infinite_coil@0"
            ]
        },
        {
            "x": -9,
            "y": 0,
            "z": 27,
            "elements": [
                "contenttweaker:infinite_coil@0"
            ]
        },
        {
            "x": -15,
            "y": 0,
            "z": 11,
            "elements": [
                "contenttweaker:arkmachineblock@0"
            ]
        },
        {
            "x": -16,
            "y": -1,
            "z": 14,
            "elements": [
                "contenttweaker:arkmachineblock@0"
            ]
        },
        {
            "x": 11,
            "y": 0,
            "z": 6,
            "elements": [
                "contenttweaker:infinite_coil@0"
            ]
        },
        {
            "x": -9,
            "y": -1,
            "z": 26,
            "elements": [
                "contenttweaker:arkmachineblock@0"
            ]
        },
        {
            "x": 12,
            "y": -1,
            "z": 10,
            "elements": [
                "contenttweaker:arkmachineblock@0"
            ]
        },
        {
            "x": -6,
            "y": -1,
            "z": 29,
            "elements": [
                "contenttweaker:infinite_coil@0"
            ]
        },
        {
            "x": 6,
            "y": -1,
            "z": 4,
            "elements": [
                "contenttweaker:arkmachineblock@0"
            ]
        },
        {
            "x": 7,
            "y": 0,
            "z": 4,
            "elements": [
                "contenttweaker:infinite_coil@0"
            ]
        },
        {
            "x": -6,
            "y": 1,
            "z": 2,
            "elements": [
                "contenttweaker:arkmachineblock@0"
            ]
        },
        {
            "x": 10,
            "y": 0,
            "z": 29,
            "elements": [
                "contenttweaker:arkmachineblock@0"
            ]
        },
        {
            "x": 13,
            "y": -2,
            "z": 24,
            "elements": [
                "contenttweaker:arkmachineblock@0"
            ]
        },
        {
            "x": -4,
            "y": -1,
            "z": 2,
            "elements": [
                "contenttweaker:infinite_coil@0"
            ]
        },
        {
            "x": 13,
            "y": 0,
            "z": 24,
            "elements": [
                "contenttweaker:infinite_coil@0"
            ]
        },
        {
            "x": 12,
            "y": -1,
            "z": 27,
            "elements": [
                "contenttweaker:arkmachineblock@0"
            ]
        },
        {
            "x": 12,
            "y": -1,
            "z": 11,
            "elements": [
                "contenttweaker:arkmachineblock@0"
            ]
        },
        {
            "x": 15,
            "y": 0,
            "z": 19,
            "elements": [
                "contenttweaker:infinite_coil@0"
            ]
        },
        {
            "x": 7,
            "y": 1,
            "z": 4,
            "elements": [
                "contenttweaker:arkmachineblock@0"
            ]
        },
        {
            "x": 9,
            "y": -2,
            "z": 4,
            "elements": [
                "contenttweaker:arkmachineblock@0"
            ]
        },
        {
            "x": 14,
            "y": -2,
            "z": 12,
            "elements": [
                "contenttweaker:arkmachineblock@0"
            ]
        },
        {
            "x": 10,
            "y": -2,
            "z": 6,
            "elements": [
                "contenttweaker:arkmachineblock@0"
            ]
        },
        {
            "x": 14,
            "y": -2,
            "z": 19,
            "elements": [
                "contenttweaker:arkmachineblock@0"
            ]
        },
        {
            "x": 8,
            "y": 0,
            "z": 6,
            "elements": [
                "contenttweaker:arkmachineblock@0"
            ]
        },
        {
            "x": 6,
            "y": -1,
            "z": 31,
            "elements": [
                "contenttweaker:arkmachineblock@0"
            ]
        },
        {
            "x": -12,
            "y": 0,
            "z": 9,
            "elements": [
                "contenttweaker:infinite_coil@0"
            ]
        },
        {
            "x": 12,
            "y": -1,
            "z": 5,
            "elements": [
                "contenttweaker:arkmachineblock@0"
            ]
        },
        {
            "x": 4,
            "y": 1,
            "z": 31,
            "elements": [
                "contenttweaker:arkmachineblock@0"
            ]
        },
        {
            "x": -15,
            "y": 1,
            "z": 14,
            "elements": [
                "contenttweaker:arkmachineblock@0"
            ]
        },
        {
            "x": 3,
            "y": 1,
            "z": 2,
            "elements": [
                "contenttweaker:arkmachineblock@0"
            ]
        },
        {
            "x": -13,
            "y": 0,
            "z": 23,
            "elements": [
                "contenttweaker:infinite_coil@0"
            ]
        },
        {
            "x": -10,
            "y": -2,
            "z": 27,
            "elements": [
                "contenttweaker:arkmachineblock@0"
            ]
        },
        {
            "x": 4,
            "y": 0,
            "z": 31,
            "elements": [
                "contenttweaker:infinite_coil@0"
            ]
        },
        {
            "x": -5,
            "y": -1,
            "z": 2,
            "elements": [
                "contenttweaker:infinite_coil@0"
            ]
        },
        {
            "x": 4,
            "y": 0,
            "z": 4,
            "elements": [
                "contenttweaker:arkmachineblock@0"
            ]
        },
        {
            "x": -6,
            "y": -2,
            "z": 29,
            "elements": [
                "contenttweaker:arkmachineblock@0"
            ]
        },
        {
            "x": -4,
            "y": 0,
            "z": 32,
            "elements": [
                "contenttweaker:arkmachineblock@0"
            ]
        },
        {
            "x": 2,
            "y": -1,
            "z": 2,
            "elements": [
                "contenttweaker:infinite_coil@0"
            ]
        },
        {
            "x": 0,
            "y": 1,
            "z": 2,
            "elements": [
                "contenttweaker:arkmachineblock@0"
            ]
        },
        {
            "x": -8,
            "y": 1,
            "z": 29,
            "elements": [
                "contenttweaker:arkmachineblock@0"
            ]
        },
        {
            "x": -14,
            "y": 1,
            "z": 17,
            "elements": [
                "contenttweaker:arkmachineblock@0"
            ]
        },
        {
            "x": 14,
            "y": -2,
            "z": 10,
            "elements": [
                "contenttweaker:arkmachineblock@0"
            ]
        },
        {
            "x": 13,
            "y": -1,
            "z": 13,
            "elements": [
                "contenttweaker:arkmachineblock@0"
            ]
        },
        {
            "x": -11,
            "y": 0,
            "z": 23,
            "elements": [
                "contenttweaker:arkmachineblock@0"
            ]
        },
        {
            "x": 12,
            "y": 0,
            "z": 10,
            "elements": [
                "contenttweaker:arkmachineblock@0"
            ]
        },
        {
            "x": -2,
            "y": 0,
            "z": 29,
            "elements": [
                "contenttweaker:arkmachineblock@0"
            ]
        },
        {
            "x": 13,
            "y": 0,
            "z": 11,
            "elements": [
                "contenttweaker:infinite_coil@0"
            ]
        },
        {
            "x": -13,
            "y": -1,
            "z": 14,
            "elements": [
                "contenttweaker:arkmachineblock@0"
            ]
        },
        {
            "x": 5,
            "y": -1,
            "z": 2,
            "elements": [
                "contenttweaker:infinite_coil@0"
            ]
        },
        {
            "x": 12,
            "y": 0,
            "z": 21,
            "elements": [
                "contenttweaker:arkmachineblock@0"
            ]
        },
        {
            "x": -3,
            "y": 1,
            "z": 2,
            "elements": [
                "contenttweaker:arkmachineblock@0"
            ]
        },
        {
            "x": -3,
            "y": -1,
            "z": 29,
            "elements": [
                "contenttweaker:arkmachineblock@0"
            ]
        },
        {
            "x": 13,
            "y": 1,
            "z": 11,
            "elements": [
                "contenttweaker:arkmachineblock@0"
            ]
        },
        {
            "x": 12,
            "y": -2,
            "z": 24,
            "elements": [
                "contenttweaker:arkmachineblock@0"
            ]
        },
        {
            "x": 15,
            "y": -1,
            "z": 11,
            "elements": [
                "contenttweaker:arkmachineblock@0"
            ]
        },
        {
            "x": -15,
            "y": -1,
            "z": 17,
            "elements": [
                "contenttweaker:infinite_coil@0"
            ]
        },
        {
            "x": 10,
            "y": 0,
            "z": 24,
            "elements": [
                "contenttweaker:arkmachineblock@0"
            ]
        },
        {
            "x": -5,
            "y": 1,
            "z": 29,
            "elements": [
                "contenttweaker:arkmachineblock@0"
            ]
        },
        {
            "x": 14,
            "y": 1,
            "z": 13,
            "elements": [
                "contenttweaker:arkmachineblock@0"
            ]
        },
        {
            "x": -12,
            "y": 0,
            "z": 23,
            "elements": [
                "contenttweaker:infinite_coil@0"
            ]
        },
        {
            "x": 1,
            "y": 1,
            "z": 31,
            "elements": [
                "contenttweaker:arkmachineblock@0"
            ]
        },
        {
            "x": 13,
            "y": 0,
            "z": 10,
            "elements": [
                "contenttweaker:infinite_coil@0"
            ]
        },
        {
            "x": 15,
            "y": 1,
            "z": 16,
            "elements": [
                "contenttweaker:arkmachineblock@0"
            ]
        },
        {
            "x": 13,
            "y": 1,
            "z": 10,
            "elements": [
                "contenttweaker:arkmachineblock@0"
            ]
        },
        {
            "x": -2,
            "y": 1,
            "z": 2,
            "elements": [
                "contenttweaker:arkmachineblock@0"
            ]
        },
        {
            "x": -14,
            "y": -2,
            "z": 18,
            "elements": [
                "contenttweaker:arkmachineblock@0"
            ]
        },
        {
            "x": 12,
            "y": 0,
            "z": 26,
            "elements": [
                "contenttweaker:infinite_coil@0"
            ]
        },
        {
            "x": 7,
            "y": 0,
            "z": 29,
            "elements": [
                "contenttweaker:infinite_coil@0"
            ]
        },
        {
            "x": 13,
            "y": -1,
            "z": 20,
            "elements": [
                "contenttweaker:infinite_coil@0"
            ]
        },
        {
            "x": 14,
            "y": -1,
            "z": 22,
            "elements": [
                "contenttweaker:infinite_coil@0"
            ]
        },
        {
            "x": 1,
            "y": 0,
            "z": 1,
            "elements": [
                "contenttweaker:infinite_coil@0"
            ]
        },
        {
            "x": 1,
            "y": 0,
            "z": 31,
            "elements": [
                "contenttweaker:infinite_coil@0"
            ]
        },
        {
            "x": -13,
            "y": -1,
            "z": 12,
            "elements": [
                "contenttweaker:infinite_coil@0"
            ]
        },
        {
            "x": -9,
            "y": 0,
            "z": 6,
            "elements": [
                "contenttweaker:arkmachineblock@0"
            ]
        },
        {
            "x": 0,
            "y": -1,
            "z": 2,
            "elements": [
                "contenttweaker:infinite_coil@0"
            ]
        },
        {
            "x": 15,
            "y": 0,
            "z": 16,
            "elements": [
                "contenttweaker:infinite_coil@0"
            ]
        },
        {
            "x": -11,
            "y": -2,
            "z": 27,
            "elements": [
                "contenttweaker:arkmachineblock@0"
            ]
        },
        {
            "x": 15,
            "y": -1,
            "z": 10,
            "elements": [
                "contenttweaker:arkmachineblock@0"
            ]
        },
        {
            "x": -11,
            "y": -1,
            "z": 7,
            "elements": [
                "contenttweaker:infinite_coil@0"
            ]
        },
        {
            "x": 6,
            "y": -1,
            "z": 29,
            "elements": [
                "contenttweaker:infinite_coil@0"
            ]
        },
        {
            "x": 13,
            "y": -2,
            "z": 20,
            "elements": [
                "contenttweaker:arkmachineblock@0"
            ]
        },
        {
            "x": 14,
            "y": -2,
            "z": 22,
            "elements": [
                "contenttweaker:arkmachineblock@0"
            ]
        },
        {
            "x": -10,
            "y": 0,
            "z": 27,
            "elements": [
                "contenttweaker:infinite_coil@0"
            ]
        },
        {
            "x": 12,
            "y": 0,
            "z": 22,
            "elements": [
                "contenttweaker:arkmachineblock@0"
            ]
        },
        {
            "x": -13,
            "y": 0,
            "z": 18,
            "elements": [
                "contenttweaker:arkmachineblock@0"
            ]
        },
        {
            "x": 14,
            "y": -1,
            "z": 16,
            "elements": [
                "contenttweaker:infinite_coil@0"
            ]
        },
        {
            "x": 11,
            "y": -2,
            "z": 26,
            "elements": [
                "contenttweaker:arkmachineblock@0"
            ]
        },
        {
            "x": 6,
            "y": -2,
            "z": 29,
            "elements": [
                "contenttweaker:arkmachineblock@0"
            ]
        },
        {
            "x": -13,
            "y": -1,
            "z": 16,
            "elements": [
                "contenttweaker:arkmachineblock@0"
            ]
        },
        {
            "x": 4,
            "y": 0,
            "z": 1,
            "elements": [
                "contenttweaker:infinite_coil@0"
            ]
        },
        {
            "x": -14,
            "y": 1,
            "z": 19,
            "elements": [
                "contenttweaker:arkmachineblock@0"
            ]
        },
        {
            "x": -1,
            "y": 1,
            "z": 2,
            "elements": [
                "contenttweaker:arkmachineblock@0"
            ]
        },
        {
            "x": 14,
            "y": -2,
            "z": 16,
            "elements": [
                "contenttweaker:arkmachineblock@0"
            ]
        },
        {
            "x": -1,
            "y": -1,
            "z": 2,
            "elements": [
                "contenttweaker:infinite_coil@0"
            ]
        },
        {
            "x": 14,
            "y": -1,
            "z": 10,
            "elements": [
                "contenttweaker:infinite_coil@0"
            ]
        },
        {
            "x": -12,
            "y": -1,
            "z": 12,
            "elements": [
                "contenttweaker:arkmachineblock@0"
            ]
        },
        {
            "x": -14,
            "y": 1,
            "z": 12,
            "elements": [
                "contenttweaker:arkmachineblock@0"
            ]
        },
        {
            "x": -8,
            "y": 1,
            "z": 28,
            "elements": [
                "contenttweaker:arkmachineblock@0"
            ]
        },
        {
            "x": -10,
            "y": -2,
            "z": 6,
            "elements": [
                "contenttweaker:arkmachineblock@0"
            ]
        },
        {
            "x": 3,
            "y": -2,
            "z": 1,
            "elements": [
                "contenttweaker:arkmachineblock@0"
            ]
        },
        {
            "x": -12,
            "y": 0,
            "z": 6,
            "elements": [
                "contenttweaker:infinite_coil@0"
            ]
        },
        {
            "x": 3,
            "y": -1,
            "z": 31,
            "elements": [
                "contenttweaker:infinite_coil@0"
            ]
        },
        {
            "x": 12,
            "y": -2,
            "z": 26,
            "elements": [
                "contenttweaker:arkmachineblock@0"
            ]
        },
        {
            "x": 1,
            "y": 1,
            "z": 30,
            "elements": [
                "contenttweaker:arkmachineblock@0"
            ]
        },
        {
            "x": 7,
            "y": 1,
            "z": 29,
            "elements": [
                "contenttweaker:arkmachineblock@0"
            ]
        },
        {
            "x": 10,
            "y": 0,
            "z": 26,
            "elements": [
                "contenttweaker:infinite_coil@0"
            ]
        },
        {
            "x": -5,
            "y": 0,
            "z": 1,
            "elements": [
                "contenttweaker:arkmachineblock@0"
            ]
        },
        {
            "x": 10,
            "y": 1,
            "z": 4,
            "elements": [
                "contenttweaker:arkmachineblock@0"
            ]
        },
        {
            "x": -16,
            "y": -1,
            "z": 16,
            "elements": [
                "contenttweaker:arkmachineblock@0"
            ]
        },
        {
            "x": -11,
            "y": 0,
            "z": 27,
            "elements": [
                "contenttweaker:infinite_coil@0"
            ]
        },
        {
            "x": -13,
            "y": -1,
            "z": 9,
            "elements": [
                "contenttweaker:infinite_coil@0"
            ]
        },
        {
            "x": -15,
            "y": -1,
            "z": 19,
            "elements": [
                "contenttweaker:infinite_coil@0"
            ]
        },
        {
            "x": 1,
            "y": 0,
            "z": 30,
            "elements": [
                "contenttweaker:infinite_coil@0"
            ]
        },
        {
            "x": -2,
            "y": -1,
            "z": 2,
            "elements": [
                "contenttweaker:infinite_coil@0"
            ]
        },
        {
            "x": -12,
            "y": 1,
            "z": 9,
            "elements": [
                "contenttweaker:arkmachineblock@0"
            ]
        },
        {
            "x": -4,
            "y": 1,
            "z": 2,
            "elements": [
                "contenttweaker:arkmachineblock@0"
            ]
        },
        {
            "x": -15,
            "y": -1,
            "z": 12,
            "elements": [
                "contenttweaker:infinite_coil@0"
            ]
        },
        {
            "x": -9,
            "y": -1,
            "z": 28,
            "elements": [
                "contenttweaker:infinite_coil@0"
            ]
        },
        {
            "x": 14,
            "y": 0,
            "z": 14,
            "elements": [
                "contenttweaker:infinite_coil@0"
            ]
        },
        {
            "x": -15,
            "y": 1,
            "z": 12,
            "elements": [
                "contenttweaker:arkmachineblock@0"
            ]
        },
        {
            "x": -11,
            "y": -2,
            "z": 6,
            "elements": [
                "contenttweaker:arkmachineblock@0"
            ]
        },
        {
            "x": 3,
            "y": -2,
            "z": 31,
            "elements": [
                "contenttweaker:arkmachineblock@0"
            ]
        },
        {
            "x": 6,
            "y": -1,
            "z": 3,
            "elements": [
                "contenttweaker:infinite_coil@0"
            ]
        },
        {
            "x": 4,
            "y": 1,
            "z": 29,
            "elements": [
                "contenttweaker:arkmachineblock@0"
            ]
        },
        {
            "x": -2,
            "y": 1,
            "z": 31,
            "elements": [
                "contenttweaker:arkmachineblock@0"
            ]
        },
        {
            "x": 9,
            "y": -1,
            "z": 4,
            "elements": [
                "contenttweaker:infinite_coil@0"
            ]
        },
        {
            "x": -15,
            "y": 1,
            "z": 16,
            "elements": [
                "contenttweaker:arkmachineblock@0"
            ]
        },
        {
            "x": 15,
            "y": 0,
            "z": 12,
            "elements": [
                "contenttweaker:infinite_coil@0"
            ]
        },
        {
            "x": -12,
            "y": 0,
            "z": 27,
            "elements": [
                "contenttweaker:arkmachineblock@0"
            ]
        },
        {
            "x": 1,
            "y": 1,
            "z": 2,
            "elements": [
                "contenttweaker:arkmachineblock@0"
            ]
        },
        {
            "x": -13,
            "y": -2,
            "z": 23,
            "elements": [
                "contenttweaker:arkmachineblock@0"
            ]
        },
        {
            "x": 1,
            "y": -1,
            "z": 2,
            "elements": [
                "contenttweaker:infinite_coil@0"
            ]
        },
        {
            "x": 3,
            "y": -2,
            "z": 30,
            "elements": [
                "contenttweaker:arkmachineblock@0"
            ]
        },
        {
            "x": 0,
            "y": -1,
            "z": 31,
            "elements": [
                "contenttweaker:infinite_coil@0"
            ]
        },
        {
            "x": -14,
            "y": -1,
            "z": 24,
            "elements": [
                "contenttweaker:arkmachineblock@0"
            ]
        },
        {
            "x": 13,
            "y": 0,
            "z": 26,
            "elements": [
                "contenttweaker:arkmachineblock@0"
            ]
        },
        {
            "x": -15,
            "y": 0,
            "z": 13,
            "elements": [
                "contenttweaker:infinite_coil@0"
            ]
        },
        {
            "x": -10,
            "y": -1,
            "z": 28,
            "elements": [
                "contenttweaker:infinite_coil@0"
            ]
        },
        {
            "x": -10,
            "y": 0,
            "z": 6,
            "elements": [
                "contenttweaker:infinite_coil@0"
            ]
        },
        {
            "x": 15,
            "y": 0,
            "z": 22,
            "elements": [
                "contenttweaker:arkmachineblock@0"
            ]
        },
        {
            "x": 10,
            "y": 0,
            "z": 4,
            "elements": [
                "contenttweaker:infinite_coil@0"
            ]
        },
        {
            "x": -13,
            "y": 1,
            "z": 24,
            "elements": [
                "contenttweaker:arkmachineblock@0"
            ]
        },
        {
            "x": 0,
            "y": -2,
            "z": 31,
            "elements": [
                "contenttweaker:arkmachineblock@0"
            ]
        },
        {
            "x": -15,
            "y": 0,
            "z": 16,
            "elements": [
                "contenttweaker:infinite_coil@0"
            ]
        },
        {
            "x": -13,
            "y": -2,
            "z": 9,
            "elements": [
                "contenttweaker:arkmachineblock@0"
            ]
        },
        {
            "x": 9,
            "y": -1,
            "z": 29,
            "elements": [
                "contenttweaker:arkmachineblock@0"
            ]
        },
        {
            "x": -2,
            "y": 0,
            "z": 31,
            "elements": [
                "contenttweaker:infinite_coil@0"
            ]
        },
        {
            "x": 16,
            "y": -1,
            "z": 13,
            "elements": [
                "contenttweaker:arkmachineblock@0"
            ]
        },
        {
            "x": 3,
            "y": -1,
            "z": 30,
            "elements": [
                "contenttweaker:infinite_coil@0"
            ]
        },
        {
            "x": 12,
            "y": -1,
            "z": 9,
            "elements": [
                "contenttweaker:infinite_coil@0"
            ]
        },
        {
            "x": -3,
            "y": 0,
            "z": 1,
            "elements": [
                "contenttweaker:infinite_coil@0"
            ]
        },
        {
            "x": -3,
            "y": -2,
            "z": 1,
            "elements": [
                "contenttweaker:arkmachineblock@0"
            ]
        },
        {
            "x": -8,
            "y": 0,
            "z": 30,
            "elements": [
                "contenttweaker:arkmachineblock@0"
            ]
        },
        {
            "x": -14,
            "y": 0,
            "z": 18,
            "elements": [
                "contenttweaker:infinite_coil@0"
            ]
        },
        {
            "x": -3,
            "y": -1,
            "z": 31,
            "elements": [
                "contenttweaker:infinite_coil@0"
            ]
        },
        {
            "x": 0,
            "y": -2,
            "z": 30,
            "elements": [
                "contenttweaker:arkmachineblock@0"
            ]
        },
        {
            "x": 7,
            "y": 0,
            "z": 3,
            "elements": [
                "contenttweaker:infinite_coil@0"
            ]
        },
        {
            "x": -11,
            "y": -1,
            "z": 24,
            "elements": [
                "contenttweaker:infinite_coil@0"
            ]
        },
        {
            "x": -11,
            "y": 1,
            "z": 5,
            "elements": [
                "contenttweaker:arkmachineblock@0"
            ]
        },
        {
            "x": -12,
            "y": 1,
            "z": 24,
            "elements": [
                "contenttweaker:arkmachineblock@0"
            ]
        },
        {
            "x": -7,
            "y": -1,
            "z": 28,
            "elements": [
                "contenttweaker:infinite_coil@0"
            ]
        },
        {
            "x": -3,
            "y": -2,
            "z": 31,
            "elements": [
                "contenttweaker:arkmachineblock@0"
            ]
        },
        {
            "x": -9,
            "y": 1,
            "z": 28,
            "elements": [
                "contenttweaker:arkmachineblock@0"
            ]
        },
        {
            "x": 10,
            "y": -1,
            "z": 25,
            "elements": [
                "contenttweaker:arkmachineblock@0"
            ]
        },
        {
            "x": -8,
            "y": -1,
            "z": 26,
            "elements": [
                "contenttweaker:arkmachineblock@0"
            ]
        },
        {
            "x": 0,
            "y": -1,
            "z": 30,
            "elements": [
                "contenttweaker:infinite_coil@0"
            ]
        },
        {
            "x": 2,
            "y": -2,
            "z": 1,
            "elements": [
                "contenttweaker:arkmachineblock@0"
            ]
        },
        {
            "x": 13,
            "y": 0,
            "z": 9,
            "elements": [
                "contenttweaker:infinite_coil@0"
            ]
        },
        {
            "x": -14,
            "y": -1,
            "z": 21,
            "elements": [
                "contenttweaker:infinite_coil@0"
            ]
        },
        {
            "x": -2,
            "y": 1,
            "z": 30,
            "elements": [
                "contenttweaker:arkmachineblock@0"
            ]
        },
        {
            "x": 11,
            "y": 0,
            "z": 25,
            "elements": [
                "contenttweaker:infinite_coil@0"
            ]
        },
        {
            "x": 11,
            "y": -1,
            "z": 9,
            "elements": [
                "contenttweaker:arkmachineblock@0"
            ]
        },
        {
            "x": -5,
            "y": 0,
            "z": 30,
            "elements": [
                "contenttweaker:infinite_coil@0"
            ]
        },
        {
            "x": -13,
            "y": -2,
            "z": 10,
            "elements": [
                "contenttweaker:arkmachineblock@0"
            ]
        },
        {
            "x": 13,
            "y": -1,
            "z": 23,
            "elements": [
                "contenttweaker:infinite_coil@0"
            ]
        },
        {
            "x": -13,
            "y": 0,
            "z": 8,
            "elements": [
                "contenttweaker:infinite_coil@0"
            ]
        },
        {
            "x": -3,
            "y": -2,
            "z": 30,
            "elements": [
                "contenttweaker:arkmachineblock@0"
            ]
        },
        {
            "x": 4,
            "y": 0,
            "z": 29,
            "elements": [
                "contenttweaker:infinite_coil@0"
            ]
        },
        {
            "x": -15,
            "y": -2,
            "z": 18,
            "elements": [
                "contenttweaker:arkmachineblock@0"
            ]
        },
        {
            "x": 3,
            "y": -1,
            "z": 2,
            "elements": [
                "contenttweaker:infinite_coil@0"
            ]
        },
        {
            "x": 0,
            "y": 0,
            "z": 1,
            "elements": [
                "contenttweaker:infinite_coil@0"
            ]
        },
        {
            "x": -12,
            "y": -1,
            "z": 24,
            "elements": [
                "contenttweaker:infinite_coil@0"
            ]
        },
        {
            "x": 13,
            "y": 1,
            "z": 8,
            "elements": [
                "contenttweaker:arkmachineblock@0"
            ]
        },
        {
            "x": -14,
            "y": -2,
            "z": 21,
            "elements": [
                "contenttweaker:arkmachineblock@0"
            ]
        },
        {
            "x": -11,
            "y": 1,
            "z": 24,
            "elements": [
                "contenttweaker:arkmachineblock@0"
            ]
        },
        {
            "x": -13,
            "y": -1,
            "z": 10,
            "elements": [
                "contenttweaker:infinite_coil@0"
            ]
        },
        {
            "x": -5,
            "y": 1,
            "z": 2,
            "elements": [
                "contenttweaker:arkmachineblock@0"
            ]
        },
        {
            "x": 12,
            "y": -2,
            "z": 9,
            "elements": [
                "contenttweaker:arkmachineblock@0"
            ]
        },
        {
            "x": -3,
            "y": -1,
            "z": 30,
            "elements": [
                "contenttweaker:infinite_coil@0"
            ]
        },
        {
            "x": 15,
            "y": 1,
            "z": 18,
            "elements": [
                "contenttweaker:arkmachineblock@0"
            ]
        },
        {
            "x": -4,
            "y": -1,
            "z": 28,
            "elements": [
                "contenttweaker:arkmachineblock@0"
            ]
        },
        {
            "x": 13,
            "y": -1,
            "z": 25,
            "elements": [
                "contenttweaker:arkmachineblock@0"
            ]
        },
        {
            "x": 3,
            "y": -1,
            "z": 29,
            "elements": [
                "contenttweaker:arkmachineblock@0"
            ]
        },
        {
            "x": 13,
            "y": 0,
            "z": 17,
            "elements": [
                "contenttweaker:arkmachineblock@0"
            ]
        },
        {
            "x": -5,
            "y": 1,
            "z": 30,
            "elements": [
                "contenttweaker:arkmachineblock@0"
            ]
        },
        {
            "x": 12,
            "y": 0,
            "z": 9,
            "elements": [
                "contenttweaker:infinite_coil@0"
            ]
        },
        {
            "x": 7,
            "y": 1,
            "z": 3,
            "elements": [
                "contenttweaker:arkmachineblock@0"
            ]
        },
        {
            "x": -1,
            "y": 0,
            "z": 1,
            "elements": [
                "contenttweaker:infinite_coil@0"
            ]
        },
        {
            "x": -1,
            "y": -2,
            "z": 1,
            "elements": [
                "contenttweaker:arkmachineblock@0"
            ]
        },
        {
            "x": 11,
            "y": 1,
            "z": 25,
            "elements": [
                "contenttweaker:arkmachineblock@0"
            ]
        },
        {
            "x": -16,
            "y": 0,
            "z": 18,
            "elements": [
                "contenttweaker:arkmachineblock@0"
            ]
        },
        {
            "x": 12,
            "y": -1,
            "z": 23,
            "elements": [
                "contenttweaker:infinite_coil@0"
            ]
        },
        {
            "x": -11,
            "y": -1,
            "z": 26,
            "elements": [
                "contenttweaker:infinite_coil@0"
            ]
        },
        {
            "x": 1,
            "y": 0,
            "z": 29,
            "elements": [
                "contenttweaker:arkmachineblock@0"
            ]
        },
        {
            "x": -2,
            "y": 0,
            "z": 30,
            "elements": [
                "contenttweaker:infinite_coil@0"
            ]
        },
        {
            "x": -13,
            "y": -1,
            "z": 24,
            "elements": [
                "contenttweaker:infinite_coil@0"
            ]
        },
        {
            "x": -12,
            "y": 0,
            "z": 10,
            "elements": [
                "contenttweaker:arkmachineblock@0"
            ]
        },
        {
            "x": -12,
            "y": -1,
            "z": 5,
            "elements": [
                "contenttweaker:arkmachineblock@0"
            ]
        },
        {
            "x": -10,
            "y": -1,
            "z": 24,
            "elements": [
                "contenttweaker:arkmachineblock@0"
            ]
        },
        {
            "x": -6,
            "y": -1,
            "z": 2,
            "elements": [
                "contenttweaker:infinite_coil@0"
            ]
        },
        {
            "x": 0,
            "y": -1,
            "z": 29,
            "elements": [
                "contenttweaker:arkmachineblock@0"
            ]
        },
        {
            "x": 14,
            "y": -1,
            "z": 18,
            "elements": [
                "contenttweaker:infinite_coil@0"
            ]
        },
        {
            "x": -9,
            "y": -2,
            "z": 27,
            "elements": [
                "contenttweaker:arkmachineblock@0"
            ]
        },
        {
            "x": -8,
            "y": 0,
            "z": 5,
            "elements": [
                "contenttweaker:infinite_coil@0"
            ]
        },
        {
            "x": -15,
            "y": 0,
            "z": 10,
            "elements": [
                "contenttweaker:arkmachineblock@0"
            ]
        },
        {
            "x": -2,
            "y": 0,
            "z": 1,
            "elements": [
                "contenttweaker:infinite_coil@0"
            ]
        },
        {
            "x": 6,
            "y": -1,
            "z": 30,
            "elements": [
                "contenttweaker:infinite_coil@0"
            ]
        },
        {
            "x": -8,
            "y": 0,
            "z": 27,
            "elements": [
                "contenttweaker:infinite_coil@0"
            ]
        },
        {
            "x": -10,
            "y": 1,
            "z": 26,
            "elements": [
                "contenttweaker:arkmachineblock@0"
            ]
        },
        {
            "x": 0,
            "y": -2,
            "z": 1,
            "elements": [
                "contenttweaker:arkmachineblock@0"
            ]
        },
        {
            "x": 4,
            "y": 1,
            "z": 30,
            "elements": [
                "contenttweaker:arkmachineblock@0"
            ]
        },
        {
            "x": -10,
            "y": -1,
            "z": 7,
            "elements": [
                "contenttweaker:arkmachineblock@0"
            ]
        },
        {
            "x": 13,
            "y": 1,
            "z": 9,
            "elements": [
                "contenttweaker:arkmachineblock@0"
            ]
        },
        {
            "x": -9,
            "y": -1,
            "z": 5,
            "elements": [
                "contenttweaker:infinite_coil@0"
            ]
        },
        {
            "x": 6,
            "y": -2,
            "z": 30,
            "elements": [
                "contenttweaker:arkmachineblock@0"
            ]
        },
        {
            "x": 10,
            "y": 0,
            "z": 3,
            "elements": [
                "contenttweaker:arkmachineblock@0"
            ]
        },
        {
            "x": -3,
            "y": -1,
            "z": 2,
            "elements": [
                "contenttweaker:infinite_coil@0"
            ]
        },
        {
            "x": 4,
            "y": 0,
            "z": 30,
            "elements": [
                "contenttweaker:infinite_coil@0"
            ]
        },
        {
            "x": -6,
            "y": -1,
            "z": 28,
            "elements": [
                "contenttweaker:arkmachineblock@0"
            ]
        },
        {
            "x": -8,
            "y": 1,
            "z": 5,
            "elements": [
                "contenttweaker:arkmachineblock@0"
            ]
        },
        {
            "x": 15,
            "y": -1,
            "z": 18,
            "elements": [
                "contenttweaker:infinite_coil@0"
            ]
        },
        {
            "x": 13,
            "y": 1,
            "z": 23,
            "elements": [
                "contenttweaker:arkmachineblock@0"
            ]
        },
        {
            "x": 9,
            "y": -1,
            "z": 3,
            "elements": [
                "contenttweaker:arkmachineblock@0"
            ]
        },
        {
            "x": -11,
            "y": 0,
            "z": 5,
            "elements": [
                "contenttweaker:infinite_coil@0"
            ]
        },
        {
            "x": -9,
            "y": -2,
            "z": 5,
            "elements": [
                "contenttweaker:arkmachineblock@0"
            ]
        },
        {
            "x": 8,
            "y": -1,
            "z": 27,
            "elements": [
                "contenttweaker:infinite_coil@0"
            ]
        },
        {
            "x": -11,
            "y": 1,
            "z": 26,
            "elements": [
                "contenttweaker:arkmachineblock@0"
            ]
        },
        {
            "x": 9,
            "y": -1,
            "z": 5,
            "elements": [
                "contenttweaker:infinite_coil@0"
            ]
        },
        {
            "x": -14,
            "y": -1,
            "z": 20,
            "elements": [
                "contenttweaker:infinite_coil@0"
            ]
        },
        {
            "x": 1,
            "y": -2,
            "z": 1,
            "elements": [
                "contenttweaker:arkmachineblock@0"
            ]
        },
        {
            "x": 6,
            "y": 1,
            "z": 2,
            "elements": [
                "contenttweaker:arkmachineblock@0"
            ]
        },
        {
            "x": 8,
            "y": -1,
            "z": 2,
            "elements": [
                "contenttweaker:arkmachineblock@0"
            ]
        },
        {
            "x": 9,
            "y": -2,
            "z": 5,
            "elements": [
                "contenttweaker:arkmachineblock@0"
            ]
        },
        {
            "x": -13,
            "y": -1,
            "z": 19,
            "elements": [
                "contenttweaker:arkmachineblock@0"
            ]
        },
        {
            "x": -14,
            "y": -2,
            "z": 20,
            "elements": [
                "contenttweaker:arkmachineblock@0"
            ]
        },
        {
            "x": 8,
            "y": -2,
            "z": 28,
            "elements": [
                "contenttweaker:arkmachineblock@0"
            ]
        },
        {
            "x": -16,
            "y": 0,
            "z": 20,
            "elements": [
                "contenttweaker:arkmachineblock@0"
            ]
        },
        {
            "x": 6,
            "y": 0,
            "z": 28,
            "elements": [
                "contenttweaker:arkmachineblock@0"
            ]
        },
        {
            "x": 7,
            "y": 0,
            "z": 30,
            "elements": [
                "contenttweaker:arkmachineblock@0"
            ]
        },
        {
            "x": 15,
            "y": 0,
            "z": 15,
            "elements": [
                "contenttweaker:infinite_coil@0"
            ]
        },
        {
            "x": 15,
            "y": 1,
            "z": 15,
            "elements": [
                "contenttweaker:arkmachineblock@0"
            ]
        },
        {
            "x": -13,
            "y": -1,
            "z": 26,
            "elements": [
                "contenttweaker:arkmachineblock@0"
            ]
        },
        {
            "x": -13,
            "y": 1,
            "z": 20,
            "elements": [
                "contenttweaker:arkmachineblock@0"
            ]
        },
        {
            "x": 16,
            "y": 0,
            "z": 17,
            "elements": [
                "contenttweaker:arkmachineblock@0"
            ]
        },
        {
            "x": -12,
            "y": 1,
            "z": 26,
            "elements": [
                "contenttweaker:arkmachineblock@0"
            ]
        },
        {
            "x": -4,
            "y": 0,
            "z": 1,
            "elements": [
                "contenttweaker:infinite_coil@0"
            ]
        },
        {
            "x": 14,
            "y": -1,
            "z": 15,
            "elements": [
                "contenttweaker:infinite_coil@0"
            ]
        },
        {
            "x": -12,
            "y": -1,
            "z": 26,
            "elements": [
                "contenttweaker:infinite_coil@0"
            ]
        },
        {
            "x": 10,
            "y": 1,
            "z": 5,
            "elements": [
                "contenttweaker:arkmachineblock@0"
            ]
        },
        {
            "x": -2,
            "y": -2,
            "z": 1,
            "elements": [
                "contenttweaker:arkmachineblock@0"
            ]
        },
        {
            "x": -6,
            "y": -1,
            "z": 31,
            "elements": [
                "contenttweaker:arkmachineblock@0"
            ]
        },
        {
            "x": -11,
            "y": 0,
            "z": 4,
            "elements": [
                "contenttweaker:arkmachineblock@0"
            ]
        },
        {
            "x": 14,
            "y": -2,
            "z": 15,
            "elements": [
                "contenttweaker:arkmachineblock@0"
            ]
        },
        {
            "x": 10,
            "y": 0,
            "z": 5,
            "elements": [
                "contenttweaker:infinite_coil@0"
            ]
        },
        {
            "x": 9,
            "y": 0,
            "z": 28,
            "elements": [
                "contenttweaker:infinite_coil@0"
            ]
        },
        {
            "x": 9,
            "y": 1,
            "z": 27,
            "elements": [
                "contenttweaker:arkmachineblock@0"
            ]
        },
        {
            "x": 15,
            "y": -2,
            "z": 17,
            "elements": [
                "contenttweaker:arkmachineblock@0"
            ]
        },
        {
            "x": -6,
            "y": -2,
            "z": 30,
            "elements": [
                "contenttweaker:arkmachineblock@0"
            ]
        },
        {
            "x": -10,
            "y": 0,
            "z": 8,
            "elements": [
                "contenttweaker:arkmachineblock@0"
            ]
        },
        {
            "x": -14,
            "y": -1,
            "z": 14,
            "elements": [
                "contenttweaker:infinite_coil@0"
            ]
        },
        {
            "x": 6,
            "y": -1,
            "z": 2,
            "elements": [
                "contenttweaker:infinite_coil@0"
            ]
        },
        {
            "x": 4,
            "y": 1,
            "z": 2,
            "elements": [
                "contenttweaker:arkmachineblock@0"
            ]
        },
        {
            "x": -15,
            "y": 1,
            "z": 19,
            "elements": [
                "contenttweaker:arkmachineblock@0"
            ]
        },
        {
            "x": 3,
            "y": 0,
            "z": 1,
            "elements": [
                "contenttweaker:infinite_coil@0"
            ]
        },
        {
            "x": 12,
            "y": 1,
            "z": 9,
            "elements": [
                "contenttweaker:arkmachineblock@0"
            ]
        },
        {
            "x": 14,
            "y": -1,
            "z": 9,
            "elements": [
                "contenttweaker:arkmachineblock@0"
            ]
        },
        {
            "x": -13,
            "y": -2,
            "z": 11,
            "elements": [
                "contenttweaker:arkmachineblock@0"
            ]
        },
        {
            "x": 7,
            "y": 0,
            "z": 5,
            "elements": [
                "contenttweaker:arkmachineblock@0"
            ]
        },
        {
            "x": -13,
            "y": -1,
            "z": 11,
            "elements": [
                "contenttweaker:infinite_coil@0"
            ]
        },
        {
            "x": -14,
            "y": -1,
            "z": 17,
            "elements": [
                "contenttweaker:infinite_coil@0"
            ]
        },
        {
            "x": -6,
            "y": -1,
            "z": 30,
            "elements": [
                "contenttweaker:infinite_coil@0"
            ]
        },
        {
            "x": -5,
            "y": 0,
            "z": 31,
            "elements": [
                "contenttweaker:arkmachineblock@0"
            ]
        },
        {
            "x": 4,
            "y": -2,
            "z": 1,
            "elements": [
                "contenttweaker:arkmachineblock@0"
            ]
        },
        {
            "x": 11,
            "y": -1,
            "z": 27,
            "elements": [
                "contenttweaker:infinite_coil@0"
            ]
        },
        {
            "x": -11,
            "y": -2,
            "z": 8,
            "elements": [
                "contenttweaker:arkmachineblock@0"
            ]
        },
        {
            "x": -10,
            "y": -1,
            "z": 26,
            "elements": [
                "contenttweaker:infinite_coil@0"
            ]
        },
        {
            "x": 2,
            "y": 0,
            "z": 1,
            "elements": [
                "contenttweaker:infinite_coil@0"
            ]
        },
        {
            "x": -13,
            "y": 0,
            "z": 20,
            "elements": [
                "contenttweaker:infinite_coil@0"
            ]
        },
        {
            "x": 14,
            "y": 0,
            "z": 24,
            "elements": [
                "contenttweaker:arkmachineblock@0"
            ]
        },
        {
            "x": -9,
            "y": -1,
            "z": 6,
            "elements": [
                "contenttweaker:arkmachineblock@0"
            ]
        },
        {
            "x": 15,
            "y": -2,
            "z": 19,
            "elements": [
                "contenttweaker:arkmachineblock@0"
            ]
        },
        {
            "x": -13,
            "y": -1,
            "z": 22,
            "elements": [
                "contenttweaker:infinite_coil@0"
            ]
        },
        {
            "x": 15,
            "y": -1,
            "z": 14,
            "elements": [
                "contenttweaker:infinite_coil@0"
            ]
        },
        {
            "x": -11,
            "y": 0,
            "z": 9,
            "elements": [
                "contenttweaker:arkmachineblock@0"
            ]
        },
        {
            "x": 10,
            "y": -1,
            "z": 8,
            "elements": [
                "contenttweaker:arkmachineblock@0"
            ]
        },
        {
            "x": 5,
            "y": 0,
            "z": 1,
            "elements": [
                "contenttweaker:arkmachineblock@0"
            ]
        },
        {
            "x": -10,
            "y": -2,
            "z": 4,
            "elements": [
                "contenttweaker:arkmachineblock@0"
            ]
        },
        {
            "x": 12,
            "y": 1,
            "z": 24,
            "elements": [
                "contenttweaker:arkmachineblock@0"
            ]
        },
        {
            "x": -14,
            "y": 1,
            "z": 14,
            "elements": [
                "contenttweaker:arkmachineblock@0"
            ]
        },
        {
            "x": 0,
            "y": -1,
            "z": 0,
            "elements": [
                "modularmachinery:blockenergyoutputhatch"
            ]
        },
        {
            "x": 10,
            "y": 0,
            "z": 27,
            "elements": [
                "contenttweaker:infinite_coil@0"
            ]
        },
        {
            "x": 15,
            "y": -2,
            "z": 12,
            "elements": [
                "contenttweaker:arkmachineblock@0"
            ]
        },
        {
            "x": -14,
            "y": -2,
            "z": 16,
            "elements": [
                "contenttweaker:arkmachineblock@0"
            ]
        },
        {
            "x": -8,
            "y": -1,
            "z": 30,
            "elements": [
                "contenttweaker:arkmachineblock@0"
            ]
        },
        {
            "x": 16,
            "y": 0,
            "z": 14,
            "elements": [
                "contenttweaker:arkmachineblock@0"
            ]
        },
        {
            "x": -16,
            "y": 0,
            "z": 16,
            "elements": [
                "contenttweaker:arkmachineblock@0"
            ]
        },
        {
            "x": 8,
            "y": -1,
            "z": 3,
            "elements": [
                "contenttweaker:infinite_coil@0"
            ]
        },
        {
            "x": 10,
            "y": 1,
            "z": 27,
            "elements": [
                "contenttweaker:arkmachineblock@0"
            ]
        },
        {
            "x": -12,
            "y": -2,
            "z": 9,
            "elements": [
                "contenttweaker:arkmachineblock@0"
            ]
        },
        {
            "x": 13,
            "y": -2,
            "z": 8,
            "elements": [
                "contenttweaker:arkmachineblock@0"
            ]
        },
        {
            "x": 10,
            "y": -1,
            "z": 29,
            "elements": [
                "contenttweaker:arkmachineblock@0"
            ]
        },
        {
            "x": 11,
            "y": 0,
            "z": 8,
            "elements": [
                "contenttweaker:infinite_coil@0"
            ]
        },
        {
            "x": 2,
            "y": -1,
            "z": 32,
            "elements": [
                "contenttweaker:arkmachineblock@0"
            ]
        },
        {
            "x": 9,
            "y": -1,
            "z": 27,
            "elements": [
                "contenttweaker:infinite_coil@0"
            ]
        },
        {
            "x": 14,
            "y": 0,
            "z": 8,
            "elements": [
                "contenttweaker:arkmachineblock@0"
            ]
        },
        {
            "x": 8,
            "y": 1,
            "z": 29,
            "elements": [
                "contenttweaker:arkmachineblock@0"
            ]
        },
        {
            "x": 13,
            "y": 0,
            "z": 12,
            "elements": [
                "contenttweaker:infinite_coil@0"
            ]
        },
        {
            "x": 11,
            "y": -1,
            "z": 24,
            "elements": [
                "contenttweaker:infinite_coil@0"
            ]
        },
        {
            "x": -15,
            "y": -1,
            "z": 14,
            "elements": [
                "contenttweaker:infinite_coil@0"
            ]
        },
        {
            "x": 9,
            "y": -2,
            "z": 27,
            "elements": [
                "contenttweaker:arkmachineblock@0"
            ]
        },
        {
            "x": 13,
            "y": -1,
            "z": 8,
            "elements": [
                "contenttweaker:infinite_coil@0"
            ]
        },
        {
            "x": -16,
            "y": -1,
            "z": 19,
            "elements": [
                "contenttweaker:arkmachineblock@0"
            ]
        },
        {
            "x": -11,
            "y": -1,
            "z": 25,
            "elements": [
                "contenttweaker:infinite_coil@0"
            ]
        },
        {
            "x": -7,
            "y": -2,
            "z": 4,
            "elements": [
                "contenttweaker:arkmachineblock@0"
            ]
        },
        {
            "x": 15,
            "y": -1,
            "z": 12,
            "elements": [
                "contenttweaker:infinite_coil@0"
            ]
        },
        {
            "x": 1,
            "y": -1,
            "z": 0,
            "elements": [
                "modularmachinery:blockoutputbus",
                "modularmachinery:blockmeitemoutputbus"
            ]
        },
        {
            "x": 3,
            "y": 0,
            "z": 32,
            "elements": [
                "contenttweaker:arkmachineblock@0"
            ]
        },
        {
            "x": 15,
            "y": -1,
            "z": 19,
            "elements": [
                "contenttweaker:infinite_coil@0"
            ]
        },
        {
            "x": -8,
            "y": 0,
            "z": 6,
            "elements": [
                "contenttweaker:arkmachineblock@0"
            ]
        },
        {
            "x": 13,
            "y": 1,
            "z": 12,
            "elements": [
                "contenttweaker:arkmachineblock@0"
            ]
        },
        {
            "x": -14,
            "y": 0,
            "z": 21,
            "elements": [
                "contenttweaker:infinite_coil@0"
            ]
        },
        {
            "x": 12,
            "y": 0,
            "z": 24,
            "elements": [
                "contenttweaker:infinite_coil@0"
            ]
        },
