{
    "registryname": "Inversion",
    "localizedname": "§c「§e规天§c」§0视界§o§f反演§r§3约束装置",
    "parts": [
        {
            "x": -11,
            "y": 6,
            "z": 15,
            "elements": [
                "contenttweaker:arkforcefieldcontrolblock@0"
            ]
        },
        {
            "x": -8,
            "y": -10,
            "z": 14,
            "elements": [
                "contenttweaker:universalforcefieldcontrolblock@0"
            ]
        },
        {
            "x": -1,
            "y": 2,
            "z": 0,
            "elements": [
                "contenttweaker:arkmachineblock@0"
            ]
        },
        {
            "x": 10,
            "y": 8,
            "z": 16,
            "elements": [
                "contenttweaker:universalforcefieldcontrolblock@0"
            ]
        },
        {
            "x": 0,
            "y": -2,
            "z": 0,
            "elements": [
                "contenttweaker:arkmachineblock@0"
            ]
        },
        {
            "x": 1,
            "y": -14,
            "z": 15,
            "elements": [
                "contenttweaker:arousal_building_block@0"
            ]
        },
        {
            "x": -14,
            "y": -1,
            "z": 16,
            "elements": [
                "contenttweaker:arousal_building_block@0"
            ]
        },
        {
            "x": 13,
            "y": 6,
            "z": 16,
            "elements": [
                "environmentaltech:pladium_paver@0"
            ]
        },
        {
            "x": -6,
            "y": 1,
            "z": 29,
            "elements": [
                "environmentaltech:pladium_paver@0"
            ]
        },
        {
            "x": 12,
            "y": 8,
            "z": 14,
            "elements": [
                "environmentaltech:pladium_paver@0"
            ]
        },
        {
            "x": -1,
            "y": 13,
            "z": 23,
            "elements": [
                "environmentaltech:pladium_paver@0"
            ]
        },
        {
            "x": -2,
            "y": -14,
            "z": 12,
            "elements": [
                "environmentaltech:pladium_tiles@0"
            ]
        },
        {
            "x": 4,
            "y": -2,
            "z": 28,
            "elements": [
                "environmentaltech:pladium_tiles@0"
            ]
        },
        {
            "x": 14,
            "y": 1,
            "z": 19,
            "elements": [
                "environmentaltech:pladium_paver@0"
            ]
        },
        {
            "x": 2,
            "y": 0,
            "z": 28,
            "elements": [
                "contenttweaker:universalforcefieldcontrolblock@0"
            ]
        },
        {
            "x": -1,
            "y": 2,
            "z": 28,
            "elements": [
                "contenttweaker:universalforcefieldcontrolblock@0"
            ]
        },
        {
            "x": 13,
            "y": -4,
            "z": 17,
            "elements": [
                "environmentaltech:pladium_tiles@0"
            ]
        },
        {
            "x": -11,
            "y": -9,
            "z": 14,
            "elements": [
                "environmentaltech:pladium_paver@0"
            ]
        },
        {
            "x": 1,
            "y": -8,
            "z": 5,
            "elements": [
                "contenttweaker:universalforcefieldcontrolblock@0"
            ]
        },
        {
            "x": -9,
            "y": 10,
            "z": 15,
            "elements": [
                "environmentaltech:pladium_tiles@0"
            ]
        },
        {
            "x": 3,
            "y": 10,
            "z": 7,
            "elements": [
                "contenttweaker:fallenstarforcefieldcontrolblock@0"
            ]
        },
        {
            "x": 10,
            "y": -8,
            "z": 18,
            "elements": [
                "contenttweaker:fallenstarforcefieldcontrolblock@0"
            ]
        },
        {
            "x": -14,
            "y": 1,
            "z": 9,
            "elements": [
                "environmentaltech:pladium_paver@0"
            ]
        },
        {
            "x": 4,
            "y": -1,
            "z": 28,
            "elements": [
                "environmentaltech:pladium_tiles@0"
            ]
        },
        {
            "x": 0,
            "y": 9,
            "z": 4,
            "elements": [
                "environmentaltech:pladium_paver@0"
            ]
        },
        {
            "x": 1,
            "y": 14,
            "z": 16,
            "elements": [
                "contenttweaker:arousal_building_block@0"
            ]
        },
        {
            "x": 5,
            "y": -1,
            "z": 1,
            "elements": [
                "environmentaltech:pladium_paver@0"
            ]
        },
        {
            "x": 4,
            "y": -13,
            "z": 16,
            "elements": [
                "environmentaltech:pladium_tiles@0"
            ]
        },
        {
            "x": 1,
            "y": -1,
            "z": 28,
            "elements": [
                "contenttweaker:arkforcefieldcontrolblock@0"
            ]
        },
        {
            "x": 9,
            "y": 12,
            "z": 14,
            "elements": [
                "environmentaltech:pladium_paver@0"
            ]
        },
        {
            "x": -1,
            "y": 10,
            "z": 23,
            "elements": [
                "contenttweaker:universalforcefieldcontrolblock@0"
            ]
        },
        {
            "x": 1,
            "y": 0,
            "z": 0,
            "elements": [
                "modularmachinery:blockinputbus",
                "modularmachinery:blockmeiteminputbus",
                "modularmachinery:blockmepatternprovider"
            ]
        },
        {
            "x": -13,
            "y": 1,
            "z": 16,
            "elements": [
                "contenttweaker:arkforcefieldcontrolblock@0"
            ]
        },
        {
            "x": -2,
            "y": 2,
            "z": 0,
            "elements": [
                "contenttweaker:arkmachineblock@0"
            ]
        },
        {
            "x": 1,
            "y": -2,
            "z": 0,
            "elements": [
                "contenttweaker:arkmachineblock@0"
            ]
        },
        {
            "x": -6,
            "y": 14,
            "z": 14,
            "elements": [
                "environmentaltech:pladium_paver@0"
            ]
        },
        {
            "x": -14,
            "y": -3,
            "z": 14,
            "elements": [
                "environmentaltech:pladium_tiles@0"
            ]
        },
        {
            "x": 13,
            "y": 8,
            "z": 16,
            "elements": [
                "environmentaltech:pladium_paver@0"
            ]
        },
        {
            "x": 0,
            "y": -9,
            "z": 24,
            "elements": [
                "contenttweaker:arkforcefieldcontrolblock@0"
            ]
        },
        {
            "x": -2,
            "y": -14,
            "z": 15,
            "elements": [
                "contenttweaker:arkmachineblock@0"
            ]
        },
        {
            "x": 1,
            "y": -2,
            "z": 28,
            "elements": [
                "contenttweaker:universalforcefieldcontrolblock@0"
            ]
        },
        {
            "x": -14,
            "y": 1,
            "z": 21,
            "elements": [
                "environmentaltech:pladium_paver@0"
            ]
        },
        {
            "x": -8,
            "y": -13,
            "z": 14,
            "elements": [
                "environmentaltech:pladium_paver@0"
            ]
        },
        {
            "x": 5,
            "y": 0,
            "z": 28,
            "elements": [
                "environmentaltech:pladium_tiles@0"
            ]
        },
        {
            "x": 0,
            "y": 7,
            "z": 4,
            "elements": [
                "contenttweaker:arkforcefieldcontrolblock@0"
            ]
        },
        {
            "x": 1,
            "y": -10,
            "z": 5,
            "elements": [
                "environmentaltech:pladium_paver@0"
            ]
        },
        {
            "x": 1,
            "y": -13,
            "z": 16,
            "elements": [
                "contenttweaker:arkforcefieldcontrolblock@0"
            ]
        },
        {
            "x": 0,
            "y": -11,
            "z": 21,
            "elements": [
                "contenttweaker:arkforcefieldcontrolblock@0"
            ]
        },
        {
            "x": -14,
            "y": -2,
            "z": 14,
            "elements": [
                "contenttweaker:arkmachineblock@0"
            ]
        },
        {
            "x": -13,
            "y": 1,
            "z": 9,
            "elements": [
                "environmentaltech:pladium_paver@0"
            ]
        },
        {
            "x": 13,
            "y": 2,
            "z": 16,
            "elements": [
                "contenttweaker:universalforcefieldcontrolblock@0"
            ]
        },
        {
            "x": 2,
            "y": 0,
            "z": 0,
            "elements": [
                "contenttweaker:arkmachineblock@0"
            ]
        },
        {
            "x": 2,
            "y": -8,
            "z": 5,
            "elements": [
                "contenttweaker:universalforcefieldcontrolblock@0"
            ]
        },
        {
            "x": -1,
            "y": 12,
            "z": 23,
            "elements": [
                "environmentaltech:pladium_paver@0"
            ]
        },
        {
            "x": -1,
            "y": 4,
            "z": 28,
            "elements": [
                "environmentaltech:pladium_tiles@0"
            ]
        },
        {
            "x": -6,
            "y": 13,
            "z": 14,
            "elements": [
                "environmentaltech:pladium_paver@0"
            ]
        },
        {
            "x": -8,
            "y": -12,
            "z": 14,
            "elements": [
                "environmentaltech:pladium_paver@0"
            ]
        },
        {
            "x": -3,
            "y": 14,
            "z": 14,
            "elements": [
                "environmentaltech:pladium_paver@0"
            ]
        },
        {
            "x": 2,
            "y": 10,
            "z": 23,
            "elements": [
                "contenttweaker:universalforcefieldcontrolblock@0"
            ]
        },
        {
            "x": 13,
            "y": -2,
            "z": 19,
            "elements": [
                "environmentaltech:pladium_tiles@0"
            ]
        },
        {
            "x": 12,
            "y": 9,
            "z": 14,
            "elements": [
                "environmentaltech:pladium_paver@0"
            ]
        },
        {
            "x": -13,
            "y": 3,
            "z": 12,
            "elements": [
                "environmentaltech:pladium_tiles@0"
            ]
        },
        {
            "x": -1,
            "y": 8,
            "z": 28,
            "elements": [
                "environmentaltech:pladium_paver@0"
            ]
        },
        {
            "x": 2,
            "y": 9,
            "z": 26,
            "elements": [
                "environmentaltech:pladium@0"
            ]
        },
        {
            "x": -2,
            "y": -13,
            "z": 11,
            "elements": [
                "environmentaltech:pladium_tiles@0"
            ]
        },
        {
            "x": 0,
            "y": 6,
            "z": 3,
            "elements": [
                "environmentaltech:pladium_tiles@0"
            ]
        },
        {
            "x": -2,
            "y": -2,
            "z": 0,
            "elements": [
                "contenttweaker:arkmachineblock@0"
            ]
        },
        {
            "x": 1,
            "y": 2,
            "z": 0,
            "elements": [
                "contenttweaker:arkmachineblock@0"
            ]
        },
        {
            "x": -1,
            "y": -14,
            "z": 15,
            "elements": [
                "contenttweaker:arousal_building_block@0"
            ]
        },
        {
            "x": -1,
            "y": 14,
            "z": 18,
            "elements": [
                "environmentaltech:pladium_paver@0"
            ]
        },
        {
            "x": -2,
            "y": 13,
            "z": 16,
            "elements": [
                "contenttweaker:universalforcefieldcontrolblock@0"
            ]
        },
        {
            "x": -1,
            "y": 10,
            "z": 26,
            "elements": [
                "environmentaltech:pladium_paver@0"
            ]
        },
        {
            "x": 0,
            "y": -10,
            "z": 24,
            "elements": [
                "environmentaltech:pladium_tiles@0"
            ]
        },
        {
            "x": -1,
            "y": 7,
            "z": 28,
            "elements": [
                "environmentaltech:pladium_paver@0"
            ]
        },
        {
            "x": 13,
            "y": 0,
            "z": 16,
            "elements": [
                "contenttweaker:arkforcefieldcontrolblock@0"
            ]
        },
        {
            "x": 3,
            "y": -8,
            "z": 5,
            "elements": [
                "contenttweaker:fallenstarforcefieldcontrolblock@0"
            ]
        },
        {
            "x": -9,
            "y": 1,
            "z": 4,
            "elements": [
                "environmentaltech:pladium_paver@0"
            ]
        },
        {
            "x": 2,
            "y": 9,
            "z": 4,
            "elements": [
                "environmentaltech:pladium_paver@0"
            ]
        },
        {
            "x": 2,
            "y": 4,
            "z": 28,
            "elements": [
                "environmentaltech:pladium_tiles@0"
            ]
        },
        {
            "x": -3,
            "y": 10,
            "z": 7,
            "elements": [
                "contenttweaker:fallenstarforcefieldcontrolblock@0"
            ]
        },
        {
            "x": -1,
            "y": 6,
            "z": 28,
            "elements": [
                "environmentaltech:pladium_paver@0"
            ]
        },
        {
            "x": 0,
            "y": -11,
            "z": 24,
            "elements": [
                "environmentaltech:pladium_paver@0"
            ]
        },
        {
            "x": -1,
            "y": 0,
            "z": 0,
            "elements": [
                "modularmachinery:blockinputbus",
                "modularmachinery:blockmeiteminputbus",
                "modularmachinery:blockmepatternprovider"
            ]
        },
        {
            "x": 2,
            "y": 1,
            "z": 28,
            "elements": [
                "contenttweaker:universalforcefieldcontrolblock@0"
            ]
        },
        {
            "x": 10,
            "y": -11,
            "z": 16,
            "elements": [
                "environmentaltech:pladium_paver@0"
            ]
        },
        {
            "x": 3,
            "y": -2,
            "z": 0,
            "elements": [
                "contenttweaker:arkmachineblock@0"
            ]
        },
        {
            "x": -14,
            "y": -2,
            "z": 12,
            "elements": [
                "environmentaltech:pladium_tiles@0"
            ]
        },
        {
            "x": 14,
            "y": -1,
            "z": 14,
            "elements": [
                "contenttweaker:arousal_building_block@0"
            ]
        },
        {
            "x": -11,
            "y": -10,
            "z": 14,
            "elements": [
                "environmentaltech:pladium_paver@0"
            ]
        },
        {
            "x": 0,
            "y": 11,
            "z": 7,
            "elements": [
                "environmentaltech:pladium_tiles@0"
            ]
        },
        {
            "x": 0,
            "y": -14,
            "z": 15,
            "elements": [
                "contenttweaker:arousal_building_block@0"
            ]
        },
        {
            "x": 6,
            "y": 1,
            "z": 1,
            "elements": [
                "environmentaltech:pladium_paver@0"
            ]
        },
        {
            "x": -1,
            "y": -13,
            "z": 11,
            "elements": [
                "environmentaltech:pladium_tiles@0"
            ]
        },
        {
            "x": -14,
            "y": -1,
            "z": 9,
            "elements": [
                "environmentaltech:pladium_paver@0"
            ]
        },
        {
            "x": -11,
            "y": 8,
            "z": 15,
            "elements": [
                "environmentaltech:pladium_tiles@0"
            ]
        },
        {
            "x": 0,
            "y": 5,
            "z": 28,
            "elements": [
                "environmentaltech:pladium_tiles@0"
            ]
        },
        {
            "x": -14,
            "y": -1,
            "z": 19,
            "elements": [
                "environmentaltech:pladium_paver@0"
            ]
        },
        {
            "x": 13,
            "y": -1,
            "z": 19,
            "elements": [
                "environmentaltech:pladium_tiles@0"
            ]
        },
        {
            "x": 0,
            "y": -8,
            "z": 5,
            "elements": [
                "contenttweaker:arkforcefieldcontrolblock@0"
            ]
        },
        {
            "x": -14,
            "y": -1,
            "z": 12,
            "elements": [
                "environmentaltech:pladium_tiles@0"
            ]
        },
        {
            "x": 0,
            "y": 10,
            "z": 7,
            "elements": [
                "contenttweaker:arkforcefieldcontrolblock@0"
            ]
        },
        {
            "x": -2,
            "y": -14,
            "z": 13,
            "elements": [
                "environmentaltech:pladium_tiles@0"
            ]
        },
        {
            "x": -13,
            "y": 0,
            "z": 19,
            "elements": [
                "environmentaltech:pladium_tiles@0"
            ]
        },
        {
            "x": 10,
            "y": -8,
            "z": 17,
            "elements": [
                "contenttweaker:universalforcefieldcontrolblock@0"
            ]
        },
        {
            "x": 4,
            "y": 14,
            "z": 16,
            "elements": [
                "environmentaltech:pladium_paver@0"
            ]
        },
        {
            "x": -10,
            "y": -1,
            "z": 4,
            "elements": [
                "environmentaltech:pladium_paver@0"
            ]
        },
        {
            "x": -5,
            "y": -14,
            "z": 14,
            "elements": [
                "environmentaltech:pladium_paver@0"
            ]
        },
        {
            "x": -2,
            "y": 10,
            "z": 23,
            "elements": [
                "contenttweaker:universalforcefieldcontrolblock@0"
            ]
        },
        {
            "x": -13,
            "y": 1,
            "z": 19,
            "elements": [
                "environmentaltech:pladium_tiles@0"
            ]
        },
        {
            "x": -13,
            "y": 1,
            "z": 13,
            "elements": [
                "contenttweaker:universalforcefieldcontrolblock@0"
            ]
        },
        {
            "x": 10,
            "y": 2,
            "z": 23,
            "elements": [
                "contenttweaker:universalforcefieldcontrolblock@0"
            ]
        },
        {
            "x": -1,
            "y": -3,
            "z": 29,
            "elements": [
                "environmentaltech:pladium_tiles@0"
            ]
        },
        {
            "x": 6,
            "y": 13,
            "z": 14,
            "elements": [
                "environmentaltech:pladium_paver@0"
            ]
        },
        {
            "x": 9,
            "y": 11,
            "z": 13,
            "elements": [
                "environmentaltech:pladium_paver@0"
            ]
        },
        {
            "x": -3,
            "y": -8,
            "z": 5,
            "elements": [
                "contenttweaker:fallenstarforcefieldcontrolblock@0"
            ]
        },
        {
            "x": 10,
            "y": -1,
            "z": 26,
            "elements": [
                "environmentaltech:pladium_paver@0"
            ]
        },
        {
            "x": -13,
            "y": 2,
            "z": 19,
            "elements": [
                "environmentaltech:pladium_tiles@0"
            ]
        },
        {
            "x": 10,
            "y": 1,
            "z": 23,
            "elements": [
                "contenttweaker:universalforcefieldcontrolblock@0"
            ]
        },
        {
            "x": 6,
            "y": 14,
            "z": 14,
            "elements": [
                "environmentaltech:pladium_paver@0"
            ]
        },
        {
            "x": 1,
            "y": 10,
            "z": 23,
            "elements": [
                "contenttweaker:universalforcefieldcontrolblock@0"
            ]
        },
        {
            "x": -8,
            "y": 13,
            "z": 16,
            "elements": [
                "environmentaltech:pladium_paver@0"
            ]
        },
        {
            "x": -3,
            "y": 8,
            "z": 5,
            "elements": [
                "contenttweaker:fallenstarforcefieldcontrolblock@0"
            ]
        },
        {
            "x": -12,
            "y": 6,
            "z": 15,
            "elements": [
                "environmentaltech:pladium_tiles@0"
            ]
        },
        {
            "x": 2,
            "y": -14,
            "z": 15,
            "elements": [
                "contenttweaker:arkmachineblock@0"
            ]
        },
        {
            "x": 2,
            "y": 2,
            "z": 0,
            "elements": [
                "contenttweaker:arkmachineblock@0"
            ]
        },
        {
            "x": -3,
            "y": -2,
            "z": 0,
            "elements": [
                "contenttweaker:arkmachineblock@0"
            ]
        },
        {
            "x": 1,
            "y": -13,
            "z": 11,
            "elements": [
                "environmentaltech:pladium_tiles@0"
            ]
        },
        {
            "x": 8,
            "y": 1,
            "z": 28,
            "elements": [
                "environmentaltech:pladium_paver@0"
            ]
        },
        {
            "x": -1,
            "y": -1,
            "z": 29,
            "elements": [
                "contenttweaker:arousal_building_block@0"
            ]
        },
        {
            "x": -8,
            "y": -10,
            "z": 12,
            "elements": [
                "contenttweaker:fallenstarforcefieldcontrolblock@0"
            ]
        },
        {
            "x": 13,
            "y": -1,
            "z": 22,
            "elements": [
                "environmentaltech:pladium_paver@0"
            ]
        },
        {
            "x": -1,
            "y": -14,
            "z": 20,
            "elements": [
                "environmentaltech:pladium_paver@0"
            ]
        },
        {
            "x": -14,
            "y": -2,
            "z": 13,
            "elements": [
                "environmentaltech:pladium_tiles@0"
            ]
        },
        {
            "x": -13,
            "y": 0,
            "z": 13,
            "elements": [
                "contenttweaker:universalforcefieldcontrolblock@0"
            ]
        },
        {
            "x": 10,
            "y": 0,
            "z": 23,
            "elements": [
                "contenttweaker:arkforcefieldcontrolblock@0"
            ]
        },
        {
            "x": 0,
            "y": 10,
            "z": 6,
            "elements": [
                "environmentaltech:pladium_tiles@0"
            ]
        },
        {
            "x": -2,
            "y": -8,
            "z": 5,
            "elements": [
                "contenttweaker:universalforcefieldcontrolblock@0"
            ]
        },
        {
            "x": -3,
            "y": 1,
            "z": 29,
            "elements": [
                "environmentaltech:pladium_tiles@0"
            ]
        },
        {
            "x": -13,
            "y": -2,
            "z": 15,
            "elements": [
                "contenttweaker:universalforcefieldcontrolblock@0"
            ]
        },
        {
            "x": -1,
            "y": 14,
            "z": 17,
            "elements": [
                "contenttweaker:arkmachineblock@0"
            ]
        },
        {
            "x": -14,
            "y": -3,
            "z": 13,
            "elements": [
                "environmentaltech:pladium_tiles@0"
            ]
        },
        {
            "x": 0,
            "y": 11,
            "z": 6,
            "elements": [
                "environmentaltech:pladium_paver@0"
            ]
        },
        {
            "x": -2,
            "y": 0,
            "z": 0,
            "elements": [
                "contenttweaker:arkmachineblock@0"
            ]
        },
        {
            "x": 7,
            "y": -1,
            "z": 28,
            "elements": [
                "environmentaltech:pladium_paver@0"
            ]
        },
        {
            "x": 1,
            "y": 13,
            "z": 23,
            "elements": [
                "environmentaltech:pladium_paver@0"
            ]
        },
        {
            "x": -1,
            "y": 13,
            "z": 17,
            "elements": [
                "contenttweaker:universalforcefieldcontrolblock@0"
            ]
        },
        {
            "x": 0,
            "y": 9,
            "z": 6,
            "elements": [
                "contenttweaker:arkforcefieldcontrolblock@0"
            ]
        },
        {
            "x": -13,
            "y": 1,
            "z": 21,
            "elements": [
                "environmentaltech:pladium_paver@0"
            ]
        },
        {
            "x": 2,
            "y": -13,
            "z": 11,
            "elements": [
                "environmentaltech:pladium_tiles@0"
            ]
        },
        {
            "x": 1,
            "y": -14,
            "z": 10,
            "elements": [
                "environmentaltech:pladium_paver@0"
            ]
        },
        {
            "x": -4,
            "y": -1,
            "z": 29,
            "elements": [
                "environmentaltech:pladium_paver@0"
            ]
        },
        {
            "x": 6,
            "y": 0,
            "z": 3,
            "elements": [
                "environmentaltech:pladium_tiles@0"
            ]
        },
        {
            "x": -8,
            "y": -2,
            "z": 5,
            "elements": [
                "contenttweaker:universalforcefieldcontrolblock@0"
            ]
        },
        {
            "x": -8,
            "y": 0,
            "z": 25,
            "elements": [
                "contenttweaker:arkforcefieldcontrolblock@0"
            ]
        },
        {
            "x": -14,
            "y": -5,
            "z": 16,
            "elements": [
                "environmentaltech:pladium_paver@0"
            ]
        },
        {
            "x": -14,
            "y": -1,
            "z": 13,
            "elements": [
                "contenttweaker:arkmachineblock@0"
            ]
        },
        {
            "x": -8,
            "y": -2,
            "z": 25,
            "elements": [
                "contenttweaker:universalforcefieldcontrolblock@0"
            ]
        },
        {
            "x": 10,
            "y": 10,
            "z": 16,
            "elements": [
                "environmentaltech:pladium_paver@0"
            ]
        },
        {
            "x": -14,
            "y": -3,
            "z": 16,
            "elements": [
                "environmentaltech:pladium_tiles@0"
            ]
        },
        {
            "x": -1,
            "y": -5,
            "z": 1,
            "elements": [
                "environmentaltech:pladium_paver@0"
            ]
        },
        {
            "x": -1,
            "y": 8,
            "z": 27,
            "elements": [
                "environmentaltech:pladium_paver@0"
            ]
        },
        {
            "x": 9,
            "y": 1,
            "z": 4,
            "elements": [
                "environmentaltech:pladium_paver@0"
            ]
        },
        {
            "x": -1,
            "y": -13,
            "z": 21,
            "elements": [
                "environmentaltech:pladium_paver@0"
            ]
        },
        {
            "x": -8,
            "y": -13,
            "z": 16,
            "elements": [
                "environmentaltech:pladium_paver@0"
            ]
        },
        {
            "x": -1,
            "y": -5,
            "z": 29,
            "elements": [
                "environmentaltech:pladium_paver@0"
            ]
        },
        {
            "x": -11,
            "y": -9,
            "z": 13,
            "elements": [
                "environmentaltech:pladium_paver@0"
            ]
        },
        {
            "x": -3,
            "y": -8,
            "z": 25,
            "elements": [
                "contenttweaker:fallenstarforcefieldcontrolblock@0"
            ]
        },
        {
            "x": 13,
            "y": 4,
            "z": 16,
            "elements": [
                "environmentaltech:pladium_tiles@0"
            ]
        },
        {
            "x": -10,
            "y": -11,
            "z": 16,
            "elements": [
                "environmentaltech:pladium_paver@0"
            ]
        },
        {
            "x": -6,
            "y": 1,
            "z": 1,
            "elements": [
                "environmentaltech:pladium_paver@0"
            ]
        },
        {
            "x": -1,
            "y": 9,
            "z": 27,
            "elements": [
                "environmentaltech:pladium_paver@0"
            ]
        },
        {
            "x": 9,
            "y": 11,
            "z": 14,
            "elements": [
                "environmentaltech:pladium_paver@0"
            ]
        },
        {
            "x": -8,
            "y": 10,
            "z": 15,
            "elements": [
                "contenttweaker:arkforcefieldcontrolblock@0"
            ]
        },
        {
            "x": -4,
            "y": -1,
            "z": 1,
            "elements": [
                "environmentaltech:pladium_paver@0"
            ]
        },
        {
            "x": -11,
            "y": -9,
            "z": 16,
            "elements": [
                "environmentaltech:pladium_paver@0"
            ]
        },
        {
            "x": -8,
            "y": -10,
            "z": 13,
            "elements": [
                "contenttweaker:universalforcefieldcontrolblock@0"
            ]
        },
        {
            "x": 1,
            "y": 12,
            "z": 23,
            "elements": [
                "environmentaltech:pladium_paver@0"
            ]
        },
        {
            "x": -1,
            "y": -6,
            "z": 1,
            "elements": [
                "environmentaltech:pladium_paver@0"
            ]
        },
        {
            "x": -7,
            "y": 13,
            "z": 16,
            "elements": [
                "environmentaltech:pladium_paver@0"
            ]
        },
        {
            "x": 12,
            "y": 0,
            "z": 8,
            "elements": [
                "environmentaltech:pladium_tiles@0"
            ]
        },
        {
            "x": 7,
            "y": -13,
            "z": 16,
            "elements": [
                "environmentaltech:pladium_paver@0"
            ]
        },
        {
            "x": 13,
            "y": -1,
            "z": 15,
            "elements": [
                "contenttweaker:arkforcefieldcontrolblock@0"
            ]
        },
        {
            "x": 13,
            "y": -6,
            "z": 14,
            "elements": [
                "environmentaltech:pladium_paver@0"
            ]
        },
        {
            "x": 14,
            "y": 0,
            "z": 12,
            "elements": [
                "environmentaltech:pladium_tiles@0"
            ]
        },
        {
            "x": -13,
            "y": -1,
            "z": 21,
            "elements": [
                "environmentaltech:pladium_paver@0"
            ]
        },
        {
            "x": -1,
            "y": -9,
            "z": 4,
            "elements": [
                "environmentaltech:pladium_paver@0"
            ]
        },
        {
            "x": -1,
            "y": 14,
            "z": 19,
            "elements": [
                "environmentaltech:pladium_paver@0"
            ]
        },
        {
            "x": 0,
            "y": -13,
            "z": 11,
            "elements": [
                "environmentaltech:pladium_tiles@0"
            ]
        },
        {
            "x": -7,
            "y": -13,
            "z": 16,
            "elements": [
                "environmentaltech:pladium_paver@0"
            ]
        },
        {
            "x": -2,
            "y": -8,
            "z": 25,
            "elements": [
                "contenttweaker:universalforcefieldcontrolblock@0"
            ]
        },
        {
            "x": -1,
            "y": -8,
            "z": 3,
            "elements": [
                "environmentaltech:pladium_paver@0"
            ]
        },
        {
            "x": 13,
            "y": 5,
            "z": 15,
            "elements": [
                "environmentaltech:pladium_tiles@0"
            ]
        },
        {
            "x": 1,
            "y": -8,
            "z": 25,
            "elements": [
                "contenttweaker:universalforcefieldcontrolblock@0"
            ]
        },
        {
            "x": -4,
            "y": -13,
            "z": 16,
            "elements": [
                "environmentaltech:pladium_tiles@0"
            ]
        },
        {
            "x": 0,
            "y": 13,
            "z": 13,
            "elements": [
                "contenttweaker:universalforcefieldcontrolblock@0"
            ]
        },
        {
            "x": 10,
            "y": 9,
            "z": 15,
            "elements": [
                "environmentaltech:pladium_tiles@0"
            ]
        },
        {
            "x": 7,
            "y": 11,
            "z": 15,
            "elements": [
                "contenttweaker:arkforcefieldcontrolblock@0"
            ]
        },
        {
            "x": 8,
            "y": 10,
            "z": 18,
            "elements": [
                "contenttweaker:fallenstarforcefieldcontrolblock@0"
            ]
        },
        {
            "x": 10,
            "y": -8,
            "z": 12,
            "elements": [
                "contenttweaker:fallenstarforcefieldcontrolblock@0"
            ]
        },
        {
            "x": 14,
            "y": 1,
            "z": 12,
            "elements": [
                "environmentaltech:pladium_tiles@0"
            ]
        },
        {
            "x": -1,
            "y": 13,
            "z": 19,
            "elements": [
                "environmentaltech:pladium_tiles@0"
            ]
        },
        {
            "x": -14,
            "y": -2,
            "z": 15,
            "elements": [
                "contenttweaker:arkmachineblock@0"
            ]
        },
        {
            "x": 13,
            "y": -7,
            "z": 14,
            "elements": [
                "environmentaltech:pladium_paver@0"
            ]
        },
        {
            "x": 0,
            "y": -11,
            "z": 9,
            "elements": [
                "contenttweaker:arkforcefieldcontrolblock@0"
            ]
        },
        {
            "x": -2,
            "y": 11,
            "z": 24,
            "elements": [
                "environmentaltech:pladium_paver@0"
            ]
        },
        {
            "x": 8,
            "y": 10,
            "z": 12,
            "elements": [
                "contenttweaker:fallenstarforcefieldcontrolblock@0"
            ]
        },
        {
            "x": 0,
            "y": 14,
            "z": 13,
            "elements": [
                "contenttweaker:arkmachineblock@0"
            ]
        },
        {
            "x": -8,
            "y": -10,
            "z": 15,
            "elements": [
                "contenttweaker:arkforcefieldcontrolblock@0"
            ]
        },
        {
            "x": -8,
            "y": 2,
            "z": 25,
            "elements": [
                "contenttweaker:universalforcefieldcontrolblock@0"
            ]
        },
        {
            "x": 14,
            "y": 2,
            "z": 12,
            "elements": [
                "environmentaltech:pladium_tiles@0"
            ]
        },
        {
            "x": -7,
            "y": -12,
            "z": 15,
            "elements": [
                "environmentaltech:pladium_tiles@0"
            ]
        },
        {
            "x": -13,
            "y": 0,
            "z": 15,
            "elements": [
                "contenttweaker:arkforcefieldcontrolblock@0"
            ]
        },
        {
            "x": -7,
            "y": 0,
            "z": 27,
            "elements": [
                "environmentaltech:pladium_tiles@0"
            ]
        },
        {
            "x": -4,
            "y": 2,
            "z": 28,
            "elements": [
                "environmentaltech:pladium_tiles@0"
            ]
        },
        {
            "x": 10,
            "y": -8,
            "z": 13,
            "elements": [
                "contenttweaker:universalforcefieldcontrolblock@0"
            ]
        },
        {
            "x": 1,
            "y": -10,
            "z": 26,
            "elements": [
                "environmentaltech:pladium_paver@0"
            ]
        },
        {
            "x": 0,
            "y": 13,
            "z": 11,
            "elements": [
                "environmentaltech:pladium_tiles@0"
            ]
        },
        {
            "x": 13,
            "y": -8,
            "z": 14,
            "elements": [
                "environmentaltech:pladium_paver@0"
            ]
        },
        {
            "x": 14,
            "y": 1,
            "z": 15,
            "elements": [
                "contenttweaker:arousal_building_block@0"
            ]
        },
        {
            "x": 14,
            "y": -1,
            "z": 13,
            "elements": [
                "contenttweaker:arkmachineblock@0"
            ]
        },
        {
            "x": -3,
            "y": 14,
            "z": 13,
            "elements": [
                "environmentaltech:pladium_paver@0"
            ]
        },
        {
            "x": -1,
            "y": 14,
            "z": 12,
            "elements": [
                "environmentaltech:pladium_paver@0"
            ]
        },
        {
            "x": -10,
            "y": -8,
            "z": 15,
            "elements": [
                "contenttweaker:arkforcefieldcontrolblock@0"
            ]
        },
        {
            "x": -11,
            "y": -6,
            "z": 15,
            "elements": [
                "contenttweaker:arkforcefieldcontrolblock@0"
            ]
        },
        {
            "x": 0,
            "y": 8,
            "z": 5,
            "elements": [
                "contenttweaker:arkforcefieldcontrolblock@0"
            ]
        },
        {
            "x": -4,
            "y": 1,
            "z": 28,
            "elements": [
                "environmentaltech:pladium_tiles@0"
            ]
        },
        {
            "x": -7,
            "y": 12,
            "z": 15,
            "elements": [
                "environmentaltech:pladium_tiles@0"
            ]
        },
        {
            "x": 14,
            "y": 2,
            "z": 18,
            "elements": [
                "environmentaltech:pladium_tiles@0"
            ]
        },
        {
            "x": -10,
            "y": 11,
            "z": 16,
            "elements": [
                "environmentaltech:pladium_paver@0"
            ]
        },
        {
            "x": 14,
            "y": -2,
            "z": 13,
            "elements": [
                "environmentaltech:pladium_tiles@0"
            ]
        },
        {
            "x": 9,
            "y": 0,
            "z": 6,
            "elements": [
                "contenttweaker:arkforcefieldcontrolblock@0"
            ]
        },
        {
            "x": 1,
            "y": -9,
            "z": 4,
            "elements": [
                "environmentaltech:pladium_paver@0"
            ]
        },
        {
            "x": -4,
            "y": 0,
            "z": 28,
            "elements": [
                "environmentaltech:pladium_tiles@0"
            ]
        },
        {
            "x": 13,
            "y": -3,
            "z": 12,
            "elements": [
                "environmentaltech:pladium_tiles@0"
            ]
        },
        {
            "x": 1,
            "y": -10,
            "z": 25,
            "elements": [
                "environmentaltech:pladium_paver@0"
            ]
        },
        {
            "x": 0,
            "y": -8,
            "z": 25,
            "elements": [
                "contenttweaker:arkforcefieldcontrolblock@0"
            ]
        },
        {
            "x": 2,
            "y": 14,
            "z": 17,
            "elements": [
                "environmentaltech:pladium_paver@0"
            ]
        },
        {
            "x": -1,
            "y": 8,
            "z": 5,
            "elements": [
                "contenttweaker:universalforcefieldcontrolblock@0"
            ]
        },
        {
            "x": -13,
            "y": -1,
            "z": 7,
            "elements": [
                "environmentaltech:pladium_paver@0"
            ]
        },
        {
            "x": 2,
            "y": -13,
            "z": 16,
            "elements": [
                "contenttweaker:universalforcefieldcontrolblock@0"
            ]
        },
        {
            "x": -13,
            "y": -4,
            "z": 15,
            "elements": [
                "environmentaltech:pladium_tiles@0"
            ]
        },
        {
            "x": 14,
            "y": 1,
            "z": 18,
            "elements": [
                "environmentaltech:pladium_tiles@0"
            ]
        },
        {
            "x": 14,
            "y": -3,
            "z": 13,
            "elements": [
                "environmentaltech:pladium_tiles@0"
            ]
        },
        {
            "x": 8,
            "y": 10,
            "z": 17,
            "elements": [
                "contenttweaker:universalforcefieldcontrolblock@0"
            ]
        },
        {
            "x": 1,
            "y": -9,
            "z": 26,
            "elements": [
                "environmentaltech:pladium_paver@0"
            ]
        },
        {
            "x": 7,
            "y": -12,
            "z": 15,
            "elements": [
                "environmentaltech:pladium_tiles@0"
            ]
        },
        {
            "x": -7,
            "y": 1,
            "z": 28,
            "elements": [
                "environmentaltech:pladium_paver@0"
            ]
        },
        {
            "x": -14,
            "y": 3,
            "z": 16,
            "elements": [
                "environmentaltech:pladium_tiles@0"
            ]
        },
        {
            "x": 1,
            "y": -13,
            "z": 9,
            "elements": [
                "environmentaltech:pladium_paver@0"
            ]
        },
        {
            "x": 8,
            "y": 1,
            "z": 27,
            "elements": [
                "environmentaltech:pladium_paver@0"
            ]
        },
        {
            "x": 10,
            "y": -8,
            "z": 14,
            "elements": [
                "contenttweaker:universalforcefieldcontrolblock@0"
            ]
        },
        {
            "x": -6,
            "y": 0,
            "z": 3,
            "elements": [
                "environmentaltech:pladium_tiles@0"
            ]
        },
        {
            "x": 14,
            "y": 3,
            "z": 15,
            "elements": [
                "environmentaltech:pladium_tiles@0"
            ]
        },
        {
            "x": 14,
            "y": 1,
            "z": 20,
            "elements": [
                "environmentaltech:pladium_paver@0"
            ]
        },
        {
            "x": -11,
            "y": -8,
            "z": 15,
            "elements": [
                "environmentaltech:pladium_tiles@0"
            ]
        },
        {
            "x": 0,
            "y": 14,
            "z": 14,
            "elements": [
                "contenttweaker:arousal_building_block@0"
            ]
        },
        {
            "x": 2,
            "y": -9,
            "z": 4,
            "elements": [
                "environmentaltech:pladium@0"
            ]
        },
        {
            "x": 8,
            "y": 2,
            "z": 5,
            "elements": [
                "contenttweaker:universalforcefieldcontrolblock@0"
            ]
        },
        {
            "x": -12,
            "y": 1,
            "z": 7,
            "elements": [
                "environmentaltech:pladium_paver@0"
            ]
        },
        {
            "x": 14,
            "y": -1,
            "z": 20,
            "elements": [
                "environmentaltech:pladium_paver@0"
            ]
        },
        {
            "x": -8,
            "y": -1,
            "z": 27,
            "elements": [
                "environmentaltech:pladium_paver@0"
            ]
        },
        {
            "x": 8,
            "y": 0,
            "z": 5,
            "elements": [
                "contenttweaker:arkforcefieldcontrolblock@0"
            ]
        },
        {
            "x": 0,
            "y": 13,
            "z": 14,
            "elements": [
                "contenttweaker:arkforcefieldcontrolblock@0"
            ]
        },
        {
            "x": 11,
            "y": 9,
            "z": 15,
            "elements": [
                "environmentaltech:pladium_paver@0"
            ]
        },
        {
            "x": -14,
            "y": 5,
            "z": 16,
            "elements": [
                "environmentaltech:pladium_paver@0"
            ]
        },
        {
            "x": -1,
            "y": 10,
            "z": 5,
            "elements": [
                "environmentaltech:pladium_paver@0"
            ]
        },
        {
            "x": 0,
            "y": -7,
            "z": 4,
            "elements": [
                "contenttweaker:arkforcefieldcontrolblock@0"
            ]
        },
        {
            "x": 2,
            "y": 8,
            "z": 5,
            "elements": [
                "contenttweaker:universalforcefieldcontrolblock@0"
            ]
        },
        {
            "x": 3,
            "y": -10,
            "z": 23,
            "elements": [
                "contenttweaker:fallenstarforcefieldcontrolblock@0"
            ]
        },
        {
            "x": 3,
            "y": 14,
            "z": 14,
            "elements": [
                "environmentaltech:pladium_paver@0"
            ]
        },
        {
            "x": 11,
            "y": -2,
            "z": 6,
            "elements": [
                "environmentaltech:pladium@0"
            ]
        },
        {
            "x": 14,
            "y": 2,
            "z": 17,
            "elements": [
                "environmentaltech:pladium_tiles@0"
            ]
        },
        {
            "x": -2,
            "y": 8,
            "z": 25,
            "elements": [
                "contenttweaker:universalforcefieldcontrolblock@0"
            ]
        },
        {
            "x": 11,
            "y": -9,
            "z": 13,
            "elements": [
                "environmentaltech:pladium_paver@0"
            ]
        },
        {
            "x": 0,
            "y": -11,
            "z": 23,
            "elements": [
                "environmentaltech:pladium_tiles@0"
            ]
        },
        {
            "x": 13,
            "y": -4,
            "z": 13,
            "elements": [
                "environmentaltech:pladium_tiles@0"
            ]
        },
        {
            "x": 0,
            "y": -6,
            "z": 3,
            "elements": [
                "environmentaltech:pladium_tiles@0"
            ]
        },
        {
            "x": 0,
            "y": 11,
            "z": 8,
            "elements": [
                "contenttweaker:arkforcefieldcontrolblock@0"
            ]
        },
        {
            "x": 11,
            "y": 9,
            "z": 17,
            "elements": [
                "environmentaltech:pladium_paver@0"
            ]
        },
        {
            "x": -12,
            "y": 0,
            "z": 8,
            "elements": [
                "environmentaltech:pladium_tiles@0"
            ]
        },
        {
            "x": -11,
            "y": 0,
            "z": 22,
            "elements": [
                "contenttweaker:arkforcefieldcontrolblock@0"
            ]
        },
        {
            "x": 3,
            "y": 13,
            "z": 12,
            "elements": [
                "environmentaltech:pladium_tiles@0"
            ]
        },
        {
            "x": -14,
            "y": -6,
            "z": 14,
            "elements": [
                "environmentaltech:pladium_paver@0"
            ]
        },
        {
            "x": -10,
            "y": 8,
            "z": 15,
            "elements": [
                "contenttweaker:arkforcefieldcontrolblock@0"
            ]
        },
        {
            "x": 14,
            "y": 3,
            "z": 17,
            "elements": [
                "environmentaltech:pladium_tiles@0"
            ]
        },
        {
            "x": 14,
            "y": -4,
            "z": 14,
            "elements": [
                "environmentaltech:pladium_paver@0"
            ]
        },
        {
            "x": 14,
            "y": -5,
            "z": 14,
            "elements": [
                "environmentaltech:pladium_paver@0"
            ]
        },
        {
            "x": 14,
            "y": -2,
            "z": 14,
            "elements": [
                "contenttweaker:arkmachineblock@0"
            ]
        },
        {
            "x": 0,
            "y": -13,
            "z": 16,
            "elements": [
                "contenttweaker:arkforcefieldcontrolblock@0"
            ]
        },
        {
            "x": 0,
            "y": 12,
            "z": 8,
            "elements": [
                "environmentaltech:pladium_tiles@0"
            ]
        },
        {
            "x": 12,
            "y": 1,
            "z": 7,
            "elements": [
                "environmentaltech:pladium_paver@0"
            ]
        },
        {
            "x": 11,
            "y": -10,
            "z": 14,
            "elements": [
                "environmentaltech:pladium_paver@0"
            ]
        },
        {
            "x": 11,
            "y": -1,
            "z": 6,
            "elements": [
                "environmentaltech:pladium_paver@0"
            ]
        },
        {
            "x": -13,
            "y": -1,
            "z": 8,
            "elements": [
                "environmentaltech:pladium_paver@0"
            ]
        },
        {
            "x": 2,
            "y": 14,
            "z": 12,
            "elements": [
                "environmentaltech:pladium_paver@0"
            ]
        },
        {
            "x": 2,
            "y": 11,
            "z": 24,
            "elements": [
                "environmentaltech:pladium_paver@0"
            ]
        },
        {
            "x": 0,
            "y": -10,
            "z": 23,
            "elements": [
                "contenttweaker:arkforcefieldcontrolblock@0"
            ]
        },
        {
            "x": -9,
            "y": -1,
            "z": 4,
            "elements": [
                "environmentaltech:pladium_paver@0"
            ]
        },
        {
            "x": 13,
            "y": -3,
            "z": 18,
            "elements": [
                "environmentaltech:pladium_tiles@0"
            ]
        },
        {
            "x": -2,
            "y": -4,
            "z": 28,
            "elements": [
                "environmentaltech:pladium_tiles@0"
            ]
        },
        {
            "x": 0,
            "y": -9,
            "z": 4,
            "elements": [
                "environmentaltech:pladium_paver@0"
            ]
        },
        {
            "x": 10,
            "y": 1,
            "z": 25,
            "elements": [
                "environmentaltech:pladium_paver@0"
            ]
        },
        {
            "x": 10,
            "y": -11,
            "z": 14,
            "elements": [
                "environmentaltech:pladium_paver@0"
            ]
        },
        {
            "x": 14,
            "y": 0,
            "z": 18,
            "elements": [
                "environmentaltech:pladium_tiles@0"
            ]
        },
        {
            "x": 1,
            "y": -8,
            "z": 27,
            "elements": [
                "environmentaltech:pladium_paver@0"
            ]
        },
        {
            "x": -1,
            "y": 9,
            "z": 26,
            "elements": [
                "environmentaltech:pladium_paver@0"
            ]
        },
        {
            "x": 10,
            "y": -8,
            "z": 15,
            "elements": [
                "contenttweaker:arkforcefieldcontrolblock@0"
            ]
        },
        {
            "x": 10,
            "y": -10,
            "z": 14,
            "elements": [
                "environmentaltech:pladium_paver@0"
            ]
        },
        {
            "x": -3,
            "y": -10,
            "z": 23,
            "elements": [
                "contenttweaker:fallenstarforcefieldcontrolblock@0"
            ]
        },
        {
            "x": -13,
            "y": 7,
            "z": 16,
            "elements": [
                "environmentaltech:pladium_paver@0"
            ]
        },
        {
            "x": -8,
            "y": -1,
            "z": 28,
            "elements": [
                "environmentaltech:pladium_paver@0"
            ]
        },
        {
            "x": 1,
            "y": -8,
            "z": 28,
            "elements": [
                "environmentaltech:pladium_paver@0"
            ]
        },
        {
            "x": 2,
            "y": 13,
            "z": 19,
            "elements": [
                "environmentaltech:pladium_tiles@0"
            ]
        },
        {
            "x": 14,
            "y": -3,
            "z": 14,
            "elements": [
                "environmentaltech:pladium_tiles@0"
            ]
        },
        {
            "x": -1,
            "y": 9,
            "z": 4,
            "elements": [
                "environmentaltech:pladium_paver@0"
            ]
        },
        {
            "x": 1,
            "y": -9,
            "z": 27,
            "elements": [
                "environmentaltech:pladium_paver@0"
            ]
        },
        {
            "x": -13,
            "y": 2,
            "z": 15,
            "elements": [
                "contenttweaker:universalforcefieldcontrolblock@0"
            ]
        },
        {
            "x": 1,
            "y": -7,
            "z": 28,
            "elements": [
                "environmentaltech:pladium_paver@0"
            ]
        },
        {
            "x": -9,
            "y": 0,
            "z": 5,
            "elements": [
                "environmentaltech:pladium_tiles@0"
            ]
        },
        {
            "x": 1,
            "y": -4,
            "z": 28,
            "elements": [
                "environmentaltech:pladium_tiles@0"
            ]
        },
        {
            "x": 12,
            "y": 1,
            "z": 6,
            "elements": [
                "environmentaltech:pladium_paver@0"
            ]
        },
        {
            "x": -11,
            "y": 9,
            "z": 16,
            "elements": [
                "environmentaltech:pladium_paver@0"
            ]
        },
        {
            "x": 1,
            "y": -8,
            "z": 3,
            "elements": [
                "environmentaltech:pladium_paver@0"
            ]
        },
        {
            "x": 11,
            "y": 0,
            "z": 21,
            "elements": [
                "contenttweaker:arkforcefieldcontrolblock@0"
            ]
        },
        {
            "x": 1,
            "y": -6,
            "z": 28,
            "elements": [
                "environmentaltech:pladium_paver@0"
            ]
        },
        {
            "x": 2,
            "y": 14,
            "z": 13,
            "elements": [
                "environmentaltech:pladium_paver@0"
            ]
        },
        {
            "x": -1,
            "y": -8,
            "z": 5,
            "elements": [
                "contenttweaker:universalforcefieldcontrolblock@0"
            ]
        },
        {
            "x": -2,
            "y": -13,
            "z": 16,
            "elements": [
                "contenttweaker:universalforcefieldcontrolblock@0"
            ]
        },
        {
            "x": 11,
            "y": 0,
            "z": 24,
            "elements": [
                "environmentaltech:pladium_paver@0"
            ]
        },
        {
            "x": 14,
            "y": 0,
            "z": 17,
            "elements": [
                "contenttweaker:arkmachineblock@0"
            ]
        },
        {
            "x": 0,
            "y": 14,
            "z": 12,
            "elements": [
                "environmentaltech:pladium_paver@0"
            ]
        },
        {
            "x": -4,
            "y": 13,
            "z": 17,
            "elements": [
                "environmentaltech:pladium_tiles@0"
            ]
        },
        {
            "x": 14,
            "y": -6,
            "z": 14,
            "elements": [
                "environmentaltech:pladium_paver@0"
            ]
        },
        {
            "x": -1,
            "y": -10,
            "z": 5,
            "elements": [
                "environmentaltech:pladium_paver@0"
            ]
        },
        {
            "x": 11,
            "y": -9,
            "z": 14,
            "elements": [
                "environmentaltech:pladium_paver@0"
            ]
        },
        {
            "x": -14,
            "y": -4,
            "z": 14,
            "elements": [
                "environmentaltech:pladium_paver@0"
            ]
        },
        {
            "x": -13,
            "y": 4,
            "z": 15,
            "elements": [
                "environmentaltech:pladium_tiles@0"
            ]
        },
        {
            "x": -12,
            "y": 9,
            "z": 16,
            "elements": [
                "environmentaltech:pladium_paver@0"
            ]
        },
        {
            "x": -1,
            "y": 12,
            "z": 24,
            "elements": [
                "environmentaltech:pladium_paver@0"
            ]
        },
        {
            "x": 2,
            "y": 14,
            "z": 18,
            "elements": [
                "environmentaltech:pladium_paver@0"
            ]
        },
        {
            "x": 13,
            "y": -1,
            "z": 17,
            "elements": [
                "contenttweaker:universalforcefieldcontrolblock@0"
            ]
        },
        {
            "x": 11,
            "y": 1,
            "z": 24,
            "elements": [
                "environmentaltech:pladium_paver@0"
            ]
        },
        {
            "x": -1,
            "y": 0,
            "z": 28,
            "elements": [
                "contenttweaker:arkforcefieldcontrolblock@0"
            ]
        },
        {
            "x": -14,
            "y": 1,
            "z": 11,
            "elements": [
                "environmentaltech:pladium_paver@0"
            ]
        },
        {
            "x": 1,
            "y": 11,
            "z": 25,
            "elements": [
                "environmentaltech:pladium_paver@0"
            ]
        },
        {
            "x": 3,
            "y": 14,
            "z": 13,
            "elements": [
                "environmentaltech:pladium_paver@0"
            ]
        },
        {
            "x": -7,
            "y": -1,
            "z": 2,
            "elements": [
                "environmentaltech:pladium_paver@0"
            ]
        },
        {
            "x": -1,
            "y": -13,
            "z": 16,
            "elements": [
                "contenttweaker:arkforcefieldcontrolblock@0"
            ]
        },
        {
            "x": -12,
            "y": 0,
            "z": 22,
            "elements": [
                "environmentaltech:pladium_tiles@0"
            ]
        },
        {
            "x": 14,
            "y": 1,
            "z": 17,
            "elements": [
                "contenttweaker:arkmachineblock@0"
            ]
        },
        {
            "x": 11,
            "y": 2,
            "z": 24,
            "elements": [
                "environmentaltech:pladium_paver@0"
            ]
        },
        {
            "x": -2,
            "y": -1,
            "z": 28,
            "elements": [
                "contenttweaker:universalforcefieldcontrolblock@0"
            ]
        },
        {
            "x": -14,
            "y": -5,
            "z": 14,
            "elements": [
                "environmentaltech:pladium_paver@0"
            ]
        },
        {
            "x": -1,
            "y": 11,
            "z": 24,
            "elements": [
                "environmentaltech:pladium_paver@0"
            ]
        },
        {
            "x": 3,
            "y": 3,
            "z": 2,
            "elements": [
                "environmentaltech:pladium_tiles@0"
            ]
        },
        {
            "x": 11,
            "y": 0,
            "z": 6,
            "elements": [
                "environmentaltech:pladium_paver@0"
            ]
        },
        {
            "x": 14,
            "y": 4,
            "z": 14,
            "elements": [
                "environmentaltech:pladium_paver@0"
            ]
        },
        {
            "x": 0,
            "y": 5,
            "z": 2,
            "elements": [
                "environmentaltech:pladium_tiles@0"
            ]
        },
        {
            "x": 10,
            "y": -3,
            "z": 7,
            "elements": [
                "contenttweaker:fallenstarforcefieldcontrolblock@0"
            ]
        },
        {
            "x": 2,
            "y": 8,
            "z": 25,
            "elements": [
                "contenttweaker:universalforcefieldcontrolblock@0"
            ]
        },
        {
            "x": -9,
            "y": -1,
            "z": 26,
            "elements": [
                "environmentaltech:pladium_paver@0"
            ]
        },
        {
            "x": 0,
            "y": 13,
            "z": 20,
            "elements": [
                "environmentaltech:pladium_tiles@0"
            ]
        },
        {
            "x": 11,
            "y": -8,
            "z": 15,
            "elements": [
                "environmentaltech:pladium_tiles@0"
            ]
        },
        {
            "x": -6,
            "y": -1,
            "z": 29,
            "elements": [
                "environmentaltech:pladium_paver@0"
            ]
        },
        {
            "x": 7,
            "y": 0,
            "z": 4,
            "elements": [
                "contenttweaker:arkforcefieldcontrolblock@0"
            ]
        },
        {
            "x": -6,
            "y": 1,
            "z": 2,
            "elements": [
                "environmentaltech:pladium_paver@0"
            ]
        },
        {
            "x": -4,
            "y": -1,
            "z": 2,
            "elements": [
                "environmentaltech:pladium_tiles@0"
            ]
        },
        {
            "x": 9,
            "y": -2,
            "z": 4,
            "elements": [
                "environmentaltech:pladium_paver@0"
            ]
        },
        {
            "x": -6,
            "y": 0,
            "z": 27,
            "elements": [
                "environmentaltech:pladium_tiles@0"
            ]
        },
        {
            "x": 11,
            "y": -7,
            "z": 15,
            "elements": [
                "contenttweaker:arkforcefieldcontrolblock@0"
            ]
        },
        {
            "x": 7,
            "y": -13,
            "z": 14,
            "elements": [
                "environmentaltech:pladium_paver@0"
            ]
        },
        {
            "x": 14,
            "y": -2,
            "z": 12,
            "elements": [
                "environmentaltech:pladium_tiles@0"
            ]
        },
        {
            "x": 7,
            "y": 0,
            "z": 26,
            "elements": [
                "contenttweaker:arkforcefieldcontrolblock@0"
            ]
        },
        {
            "x": -1,
            "y": -7,
            "z": 2,
            "elements": [
                "environmentaltech:pladium_paver@0"
            ]
        },
        {
            "x": 14,
            "y": 6,
            "z": 14,
            "elements": [
                "environmentaltech:pladium_paver@0"
            ]
        },
        {
            "x": -12,
            "y": 0,
            "z": 9,
            "elements": [
                "environmentaltech:pladium_tiles@0"
            ]
        },
        {
            "x": -1,
            "y": 11,
            "z": 25,
            "elements": [
                "environmentaltech:pladium_paver@0"
            ]
        },
        {
            "x": 11,
            "y": -9,
            "z": 16,
            "elements": [
                "environmentaltech:pladium_paver@0"
            ]
        },
        {
            "x": 13,
            "y": 8,
            "z": 14,
            "elements": [
                "environmentaltech:pladium_paver@0"
            ]
        },
        {
            "x": -9,
            "y": 12,
            "z": 16,
            "elements": [
                "environmentaltech:pladium_paver@0"
            ]
        },
        {
            "x": -10,
            "y": 8,
            "z": 18,
            "elements": [
                "contenttweaker:fallenstarforcefieldcontrolblock@0"
            ]
        },
        {
            "x": 0,
            "y": -14,
            "z": 18,
            "elements": [
                "environmentaltech:pladium_tiles@0"
            ]
        },
        {
            "x": 11,
            "y": 9,
            "z": 13,
            "elements": [
                "environmentaltech:pladium_paver@0"
            ]
        },
        {
            "x": 11,
            "y": -10,
            "z": 16,
            "elements": [
                "environmentaltech:pladium_paver@0"
            ]
        },
        {
            "x": 11,
            "y": -9,
            "z": 15,
            "elements": [
                "environmentaltech:pladium_paver@0"
            ]
        },
        {
            "x": -14,
            "y": 3,
            "z": 17,
            "elements": [
                "environmentaltech:pladium_tiles@0"
            ]
        },
        {
            "x": 8,
            "y": -13,
            "z": 14,
            "elements": [
                "environmentaltech:pladium_paver@0"
            ]
        },
        {
            "x": -10,
            "y": 0,
            "z": 23,
            "elements": [
                "contenttweaker:arkforcefieldcontrolblock@0"
            ]
        },
        {
            "x": 11,
            "y": 10,
            "z": 14,
            "elements": [
                "environmentaltech:pladium_paver@0"
            ]
        },
        {
            "x": -9,
            "y": -11,
            "z": 17,
            "elements": [
                "environmentaltech:pladium@0"
            ]
        },
        {
            "x": -10,
            "y": 3,
            "z": 7,
            "elements": [
                "contenttweaker:fallenstarforcefieldcontrolblock@0"
            ]
        },
        {
            "x": -1,
            "y": -12,
            "z": 6,
            "elements": [
                "environmentaltech:pladium_paver@0"
            ]
        },
        {
            "x": 0,
            "y": -13,
            "z": 17,
            "elements": [
                "contenttweaker:universalforcefieldcontrolblock@0"
            ]
        },
        {
            "x": 14,
            "y": -4,
            "z": 16,
            "elements": [
                "environmentaltech:pladium_paver@0"
            ]
        },
        {
            "x": 0,
            "y": 12,
            "z": 21,
            "elements": [
                "environmentaltech:pladium_tiles@0"
            ]
        },
        {
            "x": -3,
            "y": 3,
            "z": 2,
            "elements": [
                "environmentaltech:pladium_tiles@0"
            ]
        },
        {
            "x": 0,
            "y": 1,
            "z": 2,
            "elements": [
                "contenttweaker:arkforcefieldcontrolblock@0"
            ]
        },
        {
            "x": 2,
            "y": -1,
            "z": 2,
            "elements": [
                "contenttweaker:universalforcefieldcontrolblock@0"
            ]
        },
        {
            "x": -10,
            "y": -2,
            "z": 23,
            "elements": [
                "contenttweaker:universalforcefieldcontrolblock@0"
            ]
        },
        {
            "x": -14,
            "y": 1,
            "z": 17,
            "elements": [
                "contenttweaker:arkmachineblock@0"
            ]
        },
        {
            "x": -1,
            "y": -14,
            "z": 18,
            "elements": [
                "environmentaltech:pladium_tiles@0"
            ]
        },
        {
            "x": 8,
            "y": -10,
            "z": 16,
            "elements": [
                "contenttweaker:universalforcefieldcontrolblock@0"
            ]
        },
        {
            "x": 13,
            "y": -1,
            "z": 13,
            "elements": [
                "contenttweaker:universalforcefieldcontrolblock@0"
            ]
        },
        {
            "x": -1,
            "y": 10,
            "z": 25,
            "elements": [
                "environmentaltech:pladium_paver@0"
            ]
        },
        {
            "x": -3,
            "y": -2,
            "z": 29,
            "elements": [
                "environmentaltech:pladium_tiles@0"
            ]
        },
        {
            "x": 13,
            "y": 2,
            "z": 11,
            "elements": [
                "environmentaltech:pladium_tiles@0"
            ]
        },
        {
            "x": 11,
            "y": -6,
            "z": 15,
            "elements": [
                "contenttweaker:arkforcefieldcontrolblock@0"
            ]
        },
        {
            "x": 14,
            "y": -3,
            "z": 16,
            "elements": [
                "environmentaltech:pladium_tiles@0"
            ]
        },
        {
            "x": -11,
            "y": 0,
            "z": 23,
            "elements": [
                "environmentaltech:pladium_tiles@0"
            ]
        },
        {
            "x": -1,
            "y": 8,
            "z": 25,
            "elements": [
                "contenttweaker:universalforcefieldcontrolblock@0"
            ]
        },
        {
            "x": -9,
            "y": 11,
            "z": 16,
            "elements": [
                "environmentaltech:pladium_paver@0"
            ]
        },
        {
            "x": -10,
            "y": 2,
            "z": 23,
            "elements": [
                "contenttweaker:universalforcefieldcontrolblock@0"
            ]
        },
        {
            "x": 14,
            "y": -6,
            "z": 16,
            "elements": [
                "environmentaltech:pladium_paver@0"
            ]
        },
        {
            "x": -1,
            "y": 14,
            "z": 20,
            "elements": [
                "environmentaltech:pladium_paver@0"
            ]
        },
        {
            "x": 13,
            "y": 0,
            "z": 11,
            "elements": [
                "environmentaltech:pladium_tiles@0"
            ]
        },
        {
            "x": -2,
            "y": 0,
            "z": 29,
            "elements": [
                "contenttweaker:arkmachineblock@0"
            ]
        },
        {
            "x": -13,
            "y": -1,
            "z": 14,
            "elements": [
                "contenttweaker:arkforcefieldcontrolblock@0"
            ]
        },
        {
            "x": 1,
            "y": 10,
            "z": 4,
            "elements": [
                "environmentaltech:pladium_paver@0"
            ]
        },
        {
            "x": 12,
            "y": 0,
            "z": 21,
            "elements": [
                "environmentaltech:pladium_tiles@0"
            ]
        },
        {
            "x": -2,
            "y": -14,
            "z": 18,
            "elements": [
                "environmentaltech:pladium_tiles@0"
            ]
        },
        {
            "x": -3,
            "y": -1,
            "z": 29,
            "elements": [
                "environmentaltech:pladium_tiles@0"
            ]
        },
        {
            "x": 13,
            "y": 1,
            "z": 11,
            "elements": [
                "environmentaltech:pladium_tiles@0"
            ]
        },
        {
            "x": 1,
            "y": 9,
            "z": 4,
            "elements": [
                "environmentaltech:pladium_paver@0"
            ]
        },
        {
            "x": 10,
            "y": 0,
            "z": 24,
            "elements": [
                "environmentaltech:pladium_tiles@0"
            ]
        },
        {
            "x": -5,
            "y": 1,
            "z": 29,
            "elements": [
                "environmentaltech:pladium_paver@0"
            ]
        },
        {
            "x": -2,
            "y": 13,
            "z": 11,
            "elements": [
                "environmentaltech:pladium_tiles@0"
            ]
        },
        {
            "x": 14,
            "y": -5,
            "z": 16,
            "elements": [
                "environmentaltech:pladium_paver@0"
            ]
        },
        {
            "x": -1,
            "y": 14,
            "z": 13,
            "elements": [
                "contenttweaker:arkmachineblock@0"
            ]
        },
        {
            "x": 8,
            "y": 12,
            "z": 14,
            "elements": [
                "environmentaltech:pladium_paver@0"
            ]
        },
        {
            "x": 14,
            "y": 1,
            "z": 13,
            "elements": [
                "contenttweaker:arkmachineblock@0"
            ]
        },
        {
            "x": -10,
            "y": 11,
            "z": 14,
            "elements": [
                "environmentaltech:pladium_paver@0"
            ]
        },
        {
            "x": -1,
            "y": 14,
            "z": 21,
            "elements": [
                "environmentaltech:pladium_paver@0"
            ]
        },
        {
            "x": 13,
            "y": 0,
            "z": 10,
            "elements": [
                "environmentaltech:pladium_tiles@0"
            ]
        },
        {
            "x": 9,
            "y": 2,
            "z": 26,
            "elements": [
                "environmentaltech:pladium_paver@0"
            ]
        },
        {
            "x": -14,
            "y": -2,
            "z": 18,
            "elements": [
                "environmentaltech:pladium_tiles@0"
            ]
        },
        {
            "x": -2,
            "y": 1,
            "z": 2,
            "elements": [
                "contenttweaker:universalforcefieldcontrolblock@0"
            ]
        },
        {
            "x": -2,
            "y": 2,
            "z": 29,
            "elements": [
                "environmentaltech:pladium_tiles@0"
            ]
        },
        {
            "x": 1,
            "y": 0,
            "z": 1,
            "elements": [
                "environmentaltech:pladium_tiles@0"
            ]
        },
        {
            "x": 0,
            "y": -1,
            "z": 2,
            "elements": [
                "contenttweaker:arkforcefieldcontrolblock@0"
            ]
        },
        {
            "x": -10,
            "y": -3,
            "z": 7,
            "elements": [
                "contenttweaker:fallenstarforcefieldcontrolblock@0"
            ]
        },
        {
            "x": -9,
            "y": 0,
            "z": 6,
            "elements": [
                "contenttweaker:arkforcefieldcontrolblock@0"
            ]
        },
        {
            "x": 1,
            "y": -14,
            "z": 18,
            "elements": [
                "environmentaltech:pladium_tiles@0"
            ]
        },
        {
            "x": -11,
            "y": 9,
            "z": 17,
            "elements": [
                "environmentaltech:pladium@0"
            ]
        },
        {
            "x": -1,
            "y": -13,
            "z": 9,
            "elements": [
                "environmentaltech:pladium_paver@0"
            ]
        },
        {
            "x": -1,
            "y": 13,
            "z": 14,
            "elements": [
                "contenttweaker:arkforcefieldcontrolblock@0"
            ]
        },
        {
            "x": 1,
            "y": 13,
            "z": 11,
            "elements": [
                "environmentaltech:pladium_tiles@0"
            ]
        },
        {
            "x": 8,
            "y": -13,
            "z": 16,
            "elements": [
                "environmentaltech:pladium_paver@0"
            ]
        },
        {
            "x": 6,
            "y": -1,
            "z": 29,
            "elements": [
                "environmentaltech:pladium_paver@0"
            ]
        },
        {
            "x": -2,
            "y": 1,
            "z": 29,
            "elements": [
                "contenttweaker:arkmachineblock@0"
            ]
        },
        {
            "x": -1,
            "y": -14,
            "z": 9,
            "elements": [
                "environmentaltech:pladium_paver@0"
            ]
        },
        {
            "x": 0,
            "y": -7,
            "z": 26,
            "elements": [
                "contenttweaker:arkforcefieldcontrolblock@0"
            ]
        },
        {
            "x": 8,
            "y": -11,
            "z": 15,
            "elements": [
                "environmentaltech:pladium_tiles@0"
            ]
        },
        {
            "x": 12,
            "y": 0,
            "z": 22,
            "elements": [
                "environmentaltech:pladium_tiles@0"
            ]
        },
        {
            "x": -2,
            "y": -11,
            "z": 24,
            "elements": [
                "environmentaltech:pladium_paver@0"
            ]
        },
        {
            "x": -6,
            "y": 14,
            "z": 16,
            "elements": [
                "environmentaltech:pladium_paver@0"
            ]
        },
        {
            "x": -14,
            "y": 1,
            "z": 19,
            "elements": [
                "environmentaltech:pladium_paver@0"
            ]
        },
        {
            "x": 5,
            "y": -14,
            "z": 16,
            "elements": [
                "environmentaltech:pladium_paver@0"
            ]
        },
        {
            "x": -1,
            "y": 13,
            "z": 7,
            "elements": [
                "environmentaltech:pladium_paver@0"
            ]
        },
        {
            "x": 14,
            "y": -1,
            "z": 16,
            "elements": [
                "contenttweaker:arousal_building_block@0"
            ]
        },
        {
            "x": -10,
            "y": 1,
            "z": 7,
            "elements": [
                "contenttweaker:universalforcefieldcontrolblock@0"
            ]
        },
        {
            "x": -1,
            "y": -13,
            "z": 17,
            "elements": [
                "contenttweaker:universalforcefieldcontrolblock@0"
            ]
        },
        {
            "x": 8,
            "y": 10,
            "z": 14,
            "elements": [
                "contenttweaker:universalforcefieldcontrolblock@0"
            ]
        },
        {
            "x": -4,
            "y": -13,
            "z": 14,
            "elements": [
                "environmentaltech:pladium_tiles@0"
            ]
        },
        {
            "x": -13,
            "y": -1,
            "z": 16,
            "elements": [
                "contenttweaker:arkforcefieldcontrolblock@0"
            ]
        },
        {
            "x": 1,
            "y": 2,
            "z": 1,
            "elements": [
                "environmentaltech:pladium_tiles@0"
            ]
        },
        {
            "x": 1,
            "y": 12,
            "z": 24,
            "elements": [
                "environmentaltech:pladium_paver@0"
            ]
        },
        {
            "x": 8,
            "y": -12,
            "z": 16,
            "elements": [
                "environmentaltech:pladium_paver@0"
            ]
        },
        {
            "x": 14,
            "y": -2,
            "z": 16,
            "elements": [
                "contenttweaker:arkmachineblock@0"
            ]
        },
        {
            "x": 1,
            "y": 14,
            "z": 11,
            "elements": [
                "environmentaltech:pladium_paver@0"
            ]
        },
        {
            "x": -1,
            "y": 1,
            "z": 2,
            "elements": [
                "contenttweaker:arkforcefieldcontrolblock@0"
            ]
        },
        {
            "x": 0,
            "y": -12,
            "z": 8,
            "elements": [
                "environmentaltech:pladium_tiles@0"
            ]
        },
        {
            "x": -13,
            "y": -2,
            "z": 16,
            "elements": [
                "contenttweaker:universalforcefieldcontrolblock@0"
            ]
        },
        {
            "x": -1,
            "y": -1,
            "z": 2,
            "elements": [
                "contenttweaker:arkforcefieldcontrolblock@0"
            ]
        },
        {
            "x": -13,
            "y": -3,
            "z": 12,
            "elements": [
                "environmentaltech:pladium_tiles@0"
            ]
        },
        {
            "x": 0,
            "y": -9,
            "z": 26,
            "elements": [
                "environmentaltech:pladium_paver@0"
            ]
        },
        {
            "x": 14,
            "y": -1,
            "z": 10,
            "elements": [
                "environmentaltech:pladium_paver@0"
            ]
        },
        {
            "x": -14,
            "y": 1,
            "z": 12,
            "elements": [
                "environmentaltech:pladium_tiles@0"
            ]
        },
        {
            "x": -1,
            "y": 13,
            "z": 21,
            "elements": [
                "environmentaltech:pladium_paver@0"
            ]
        },
        {
            "x": -2,
            "y": 3,
            "z": 29,
            "elements": [
                "environmentaltech:pladium_tiles@0"
            ]
        },
        {
            "x": -8,
            "y": 1,
            "z": 28,
            "elements": [
                "environmentaltech:pladium_paver@0"
            ]
        },
        {
            "x": 8,
            "y": 0,
            "z": 25,
            "elements": [
                "contenttweaker:arkforcefieldcontrolblock@0"
            ]
        },
        {
            "x": 0,
            "y": 11,
            "z": 21,
            "elements": [
                "contenttweaker:arkforcefieldcontrolblock@0"
            ]
        },
        {
            "x": -2,
            "y": -1,
            "z": 2,
            "elements": [
                "contenttweaker:universalforcefieldcontrolblock@0"
            ]
        },
        {
            "x": 5,
            "y": 14,
            "z": 14,
            "elements": [
                "environmentaltech:pladium_paver@0"
            ]
        },
        {
            "x": -2,
            "y": -10,
            "z": 23,
            "elements": [
                "contenttweaker:universalforcefieldcontrolblock@0"
            ]
        },
        {
            "x": 10,
            "y": 1,
            "z": 4,
            "elements": [
                "environmentaltech:pladium_paver@0"
            ]
        },
        {
            "x": 3,
            "y": -2,
            "z": 1,
            "elements": [
                "environmentaltech:pladium_tiles@0"
            ]
        },
        {
            "x": 1,
            "y": 5,
            "z": 29,
            "elements": [
                "environmentaltech:pladium_paver@0"
            ]
        },
        {
            "x": -4,
            "y": -13,
            "z": 17,
            "elements": [
                "environmentaltech:pladium_tiles@0"
            ]
        },
        {
            "x": 1,
            "y": 14,
            "z": 10,
            "elements": [
                "environmentaltech:pladium_paver@0"
            ]
        },
        {
            "x": -13,
            "y": -1,
            "z": 9,
            "elements": [
                "environmentaltech:pladium_paver@0"
            ]
        },
        {
            "x": 0,
            "y": -13,
            "z": 19,
            "elements": [
                "environmentaltech:pladium_tiles@0"
            ]
        },
        {
            "x": 12,
            "y": 8,
            "z": 16,
            "elements": [
                "environmentaltech:pladium_paver@0"
            ]
        },
        {
            "x": -7,
            "y": -13,
            "z": 14,
            "elements": [
                "environmentaltech:pladium_paver@0"
            ]
        },
        {
            "x": -13,
            "y": 1,
            "z": 7,
            "elements": [
                "environmentaltech:pladium_paver@0"
            ]
        },
        {
            "x": -10,
            "y": -11,
            "z": 14,
            "elements": [
                "environmentaltech:pladium_paver@0"
            ]
        },
        {
            "x": 8,
            "y": -10,
            "z": 15,
            "elements": [
                "contenttweaker:arkforcefieldcontrolblock@0"
            ]
        },
        {
            "x": 9,
            "y": 11,
            "z": 16,
            "elements": [
                "environmentaltech:pladium_paver@0"
            ]
        },
        {
            "x": -13,
            "y": -4,
            "z": 16,
            "elements": [
                "environmentaltech:pladium_tiles@0"
            ]
        },
        {
            "x": -3,
            "y": 13,
            "z": 12,
            "elements": [
                "environmentaltech:pladium_tiles@0"
            ]
        },
        {
            "x": 13,
            "y": -2,
            "z": 14,
            "elements": [
                "contenttweaker:universalforcefieldcontrolblock@0"
            ]
        },
        {
            "x": 12,
            "y": 9,
            "z": 16,
            "elements": [
                "environmentaltech:pladium_paver@0"
            ]
        },
        {
            "x": 1,
            "y": 4,
            "z": 1,
            "elements": [
                "environmentaltech:pladium_paver@0"
            ]
        },
        {
            "x": -4,
            "y": 1,
            "z": 2,
            "elements": [
                "environmentaltech:pladium_tiles@0"
            ]
        },
        {
            "x": 3,
            "y": -8,
            "z": 25,
            "elements": [
                "contenttweaker:fallenstarforcefieldcontrolblock@0"
            ]
        },
        {
            "x": 1,
            "y": -7,
            "z": 2,
            "elements": [
                "environmentaltech:pladium_paver@0"
            ]
        },
        {
            "x": 14,
            "y": 0,
            "z": 14,
            "elements": [
                "contenttweaker:arousal_building_block@0"
            ]
        },
        {
            "x": -1,
            "y": -12,
            "z": 23,
            "elements": [
                "environmentaltech:pladium_paver@0"
            ]
        },
        {
            "x": 1,
            "y": 6,
            "z": 29,
            "elements": [
                "environmentaltech:pladium_paver@0"
            ]
        },
        {
            "x": -7,
            "y": 13,
            "z": 14,
            "elements": [
                "environmentaltech:pladium_paver@0"
            ]
        },
        {
            "x": 8,
            "y": 1,
            "z": 25,
            "elements": [
                "contenttweaker:universalforcefieldcontrolblock@0"
            ]
        },
        {
            "x": -11,
            "y": -2,
            "z": 6,
            "elements": [
                "environmentaltech:pladium_paver@0"
            ]
        },
        {
            "x": -2,
            "y": 9,
            "z": 4,
            "elements": [
                "environmentaltech:pladium_paver@0"
            ]
        },
        {
            "x": -6,
            "y": 13,
            "z": 16,
            "elements": [
                "environmentaltech:pladium_paver@0"
            ]
        },
        {
            "x": -10,
            "y": -8,
            "z": 13,
            "elements": [
                "contenttweaker:universalforcefieldcontrolblock@0"
            ]
        },
        {
            "x": 1,
            "y": 8,
            "z": 3,
            "elements": [
                "environmentaltech:pladium_paver@0"
            ]
        },
        {
            "x": 4,
            "y": 1,
            "z": 29,
            "elements": [
                "environmentaltech:pladium_paver@0"
            ]
        },
        {
            "x": 14,
            "y": 3,
            "z": 13,
            "elements": [
                "environmentaltech:pladium_tiles@0"
            ]
        },
        {
            "x": 9,
            "y": -1,
            "z": 4,
            "elements": [
                "environmentaltech:pladium_paver@0"
            ]
        },
        {
            "x": -13,
            "y": -4,
            "z": 13,
            "elements": [
                "environmentaltech:pladium_tiles@0"
            ]
        },
        {
            "x": 1,
            "y": -13,
            "z": 17,
            "elements": [
                "contenttweaker:universalforcefieldcontrolblock@0"
            ]
        },
        {
            "x": 9,
            "y": -2,
            "z": 26,
            "elements": [
                "environmentaltech:pladium@0"
            ]
        },
        {
            "x": 1,
            "y": 1,
            "z": 2,
            "elements": [
                "contenttweaker:arkforcefieldcontrolblock@0"
            ]
        },
        {
            "x": -1,
            "y": 12,
            "z": 6,
            "elements": [
                "environmentaltech:pladium_paver@0"
            ]
        },
        {
            "x": -13,
            "y": -6,
            "z": 16,
            "elements": [
                "environmentaltech:pladium_paver@0"
            ]
        },
        {
            "x": 8,
            "y": -10,
            "z": 13,
            "elements": [
                "contenttweaker:universalforcefieldcontrolblock@0"
            ]
        },
        {
            "x": 1,
            "y": 9,
            "z": 3,
            "elements": [
                "environmentaltech:pladium_paver@0"
            ]
        },
        {
            "x": 1,
            "y": -1,
            "z": 2,
            "elements": [
                "contenttweaker:arkforcefieldcontrolblock@0"
            ]
        },
        {
            "x": 13,
            "y": -4,
            "z": 14,
            "elements": [
                "environmentaltech:pladium_tiles@0"
            ]
        },
        {
            "x": -13,
            "y": -7,
            "z": 14,
            "elements": [
                "environmentaltech:pladium_paver@0"
            ]
        },
        {
            "x": -10,
            "y": 0,
            "z": 6,
            "elements": [
                "environmentaltech:pladium_tiles@0"
            ]
        },
        {
            "x": -1,
            "y": -10,
            "z": 23,
            "elements": [
                "contenttweaker:universalforcefieldcontrolblock@0"
            ]
        },
        {
            "x": -4,
            "y": 13,
            "z": 14,
            "elements": [
                "environmentaltech:pladium_tiles@0"
            ]
        },
        {
            "x": -3,
            "y": -13,
            "z": 12,
            "elements": [
                "environmentaltech:pladium_tiles@0"
            ]
        },
        {
            "x": -8,
            "y": -10,
            "z": 18,
            "elements": [
                "contenttweaker:fallenstarforcefieldcontrolblock@0"
            ]
        },
        {
            "x": -1,
            "y": -7,
            "z": 28,
            "elements": [
                "environmentaltech:pladium_paver@0"
            ]
        },
        {
            "x": -11,
            "y": 9,
            "z": 14,
            "elements": [
                "environmentaltech:pladium_paver@0"
            ]
        },
        {
            "x": 10,
            "y": -1,
            "z": 23,
            "elements": [
                "contenttweaker:universalforcefieldcontrolblock@0"
            ]
        },
        {
            "x": 14,
            "y": 2,
            "z": 14,
            "elements": [
                "contenttweaker:arkmachineblock@0"
            ]
        },
        {
            "x": 1,
            "y": -11,
            "z": 24,
            "elements": [
                "environmentaltech:pladium_paver@0"
            ]
        },
        {
            "x": 9,
            "y": 12,
            "z": 16,
            "elements": [
                "environmentaltech:pladium_paver@0"
            ]
        },
        {
            "x": 1,
            "y": 6,
            "z": 1,
            "elements": [
                "environmentaltech:pladium_paver@0"
            ]
        },
        {
            "x": 1,
            "y": -12,
            "z": 6,
            "elements": [
                "environmentaltech:pladium_paver@0"
            ]
        },
        {
            "x": 8,
            "y": 3,
            "z": 25,
            "elements": [
                "contenttweaker:fallenstarforcefieldcontrolblock@0"
            ]
        },
        {
            "x": -3,
            "y": -2,
            "z": 1,
            "elements": [
                "environmentaltech:pladium_tiles@0"
            ]
        },
        {
            "x": -3,
            "y": 0,
            "z": 1,
            "elements": [
                "environmentaltech:pladium_tiles@0"
            ]
        },
        {
            "x": 3,
            "y": -2,
            "z": 29,
            "elements": [
                "environmentaltech:pladium_tiles@0"
            ]
        },
        {
            "x": -2,
            "y": -13,
            "z": 19,
            "elements": [
                "environmentaltech:pladium_tiles@0"
            ]
        },
        {
            "x": -8,
            "y": 10,
            "z": 18,
            "elements": [
                "contenttweaker:fallenstarforcefieldcontrolblock@0"
            ]
        },
        {
            "x": -14,
            "y": 0,
            "z": 18,
            "elements": [
                "environmentaltech:pladium_tiles@0"
            ]
        },
        {
            "x": -13,
            "y": -8,
            "z": 16,
            "elements": [
                "environmentaltech:pladium_paver@0"
            ]
        },
        {
            "x": -11,
            "y": 1,
            "z": 5,
            "elements": [
                "environmentaltech:pladium_paver@0"
            ]
        },
        {
            "x": 7,
            "y": 0,
            "z": 3,
            "elements": [
                "environmentaltech:pladium_tiles@0"
            ]
        },
        {
            "x": 0,
            "y": 2,
            "z": 1,
            "elements": [
                "environmentaltech:pladium_tiles@0"
            ]
        },
        {
            "x": 8,
            "y": 2,
            "z": 25,
            "elements": [
                "contenttweaker:universalforcefieldcontrolblock@0"
            ]
        },
        {
            "x": -1,
            "y": 4,
            "z": 1,
            "elements": [
                "environmentaltech:pladium_paver@0"
            ]
        },
        {
            "x": -11,
            "y": -1,
            "z": 24,
            "elements": [
                "environmentaltech:pladium_paver@0"
            ]
        },
        {
            "x": 3,
            "y": -3,
            "z": 2,
            "elements": [
                "environmentaltech:pladium_tiles@0"
            ]
