{
    "registryname": "SuperentropyCalculus",
    "localizedname": "超熵演算机",
    "requires-blueprint": false,
    "parts": [
        {
            "x": -2,
            "y": -12,
            "z": 15,
            "elements": [
                "enderio:block_enlightened_fused_quartz@0"
            ]
        },
        {
            "x": -3,
            "y": 0,
            "z": 5,
            "elements": [
                "contenttweaker:extrememachineblock@0"
            ]
        },
        {
            "x": -1,
            "y": 8,
            "z": 17,
            "elements": [
                "modularmachinery:blockcasing@4"
            ]
        },
        {
            "x": 0,
            "y": -2,
            "z": 0,
            "elements": [
                "enderio:block_enlightened_fused_quartz@0"
            ]
        },
        {
            "x": -1,
            "y": 2,
            "z": 0,
            "elements": [
                "modularmachinery:blockcasing@4"
            ]
        },
        {
            "x": 1,
            "y": -14,
            "z": 15,
            "elements": [
                "extendedcrafting:trimmed@0"
            ]
        },
        {
            "x": -1,
            "y": 0,
            "z": 19,
            "elements": [
                "contenttweaker:crystalmatrixforcefieldcontrolblock@0"
            ]
        },
        {
            "x": -1,
            "y": 2,
            "z": 28,
            "elements": [
                "modularmachinery:blockcasing@4"
            ]
        },
        {
            "x": 1,
            "y": 14,
            "z": 16,
            "elements": [
                "ic2:resource@13"
            ]
        },
        {
            "x": 0,
            "y": -9,
            "z": 21,
            "elements": [
                "contenttweaker:extrememachineblock@0"
            ]
        },
        {
            "x": -13,
            "y": 1,
            "z": 16,
            "elements": [
                "ic2:resource@13"
            ]
        },
        {
            "x": -2,
            "y": -7,
            "z": 16,
            "elements": [
                "modularmachinery:blockcasing@4"
            ]
        },
        {
            "x": -5,
            "y": 0,
            "z": 15,
            "elements": [
                "contenttweaker:fixed_star_alloys_coil@0"
            ]
        },
        {
            "x": -1,
            "y": 6,
            "z": 17,
            "elements": [
                "modularmachinery:blockcasing@4"
            ]
        },
        {
            "x": -6,
            "y": 2,
            "z": 15,
            "elements": [
                "enderio:block_enlightened_fused_quartz@0"
            ]
        },
        {
            "x": -9,
            "y": -2,
            "z": 15,
            "elements": [
                "enderio:block_enlightened_fused_quartz@0"
            ]
        },
        {
            "x": -2,
            "y": 15,
            "z": 16,
            "elements": [
                "modularmachinery:blockcasing@4"
            ]
        },
        {
            "x": -8,
            "y": 6,
            "z": 15,
            "elements": [
                "contenttweaker:extrememachineblock@0"
            ]
        },
        {
            "x": 1,
            "y": -13,
            "z": 16,
            "elements": [
                "ic2:resource@13"
            ]
        },
        {
            "x": -2,
            "y": -8,
            "z": 15,
            "elements": [
                "enderio:block_enlightened_fused_quartz@0"
            ]
        },
        {
            "x": 5,
            "y": 0,
            "z": 17,
            "elements": [
                "contenttweaker:extrememachineblock@0"
            ]
        },
        {
            "x": -14,
            "y": -2,
            "z": 14,
            "elements": [
                "modularmachinery:blockcasing@4"
            ]
        },
        {
            "x": 13,
            "y": 2,
            "z": 16,
            "elements": [
                "modularmachinery:blockcasing@4"
            ]
        },
        {
            "x": -1,
            "y": 7,
            "z": 17,
            "elements": [
                "modularmachinery:blockcasing@4"
            ]
        },
        {
            "x": 2,
            "y": 0,
            "z": 0,
            "elements": [
                "enderio:block_enlightened_fused_quartz@0"
            ]
        },
        {
            "x": 0,
            "y": -12,
            "z": 15,
            "elements": [
                "contenttweaker:fixed_star_alloys_coil@0"
            ]
        },
        {
            "x": 0,
            "y": -4,
            "z": 5,
            "elements": [
                "contenttweaker:extrememachineblock@0"
            ]
        },
        {
            "x": -1,
            "y": -2,
            "z": 5,
            "elements": [
                "modularmachinery:blockcasing@4"
            ]
        },
        {
            "x": 1,
            "y": 2,
            "z": 0,
            "elements": [
                "modularmachinery:blockcasing@4"
            ]
        },
        {
            "x": -1,
            "y": -14,
            "z": 15,
            "elements": [
                "extendedcrafting:trimmed@0"
            ]
        },
        {
            "x": -2,
            "y": -15,
            "z": 16,
            "elements": [
                "modularmachinery:blockcasing@4"
            ]
        },
        {
            "x": -5,
            "y": -1,
            "z": 16,
            "elements": [
                "contenttweaker:neutronforcefieldcontrolblock@0"
            ]
        },
        {
            "x": 13,
            "y": 0,
            "z": 16,
            "elements": [
                "extendedcrafting:trimmed@0"
            ]
        },
        {
            "x": 2,
            "y": 1,
            "z": 28,
            "elements": [
                "modularmachinery:blockcasing@4"
            ]
        },
        {
            "x": -7,
            "y": 0,
            "z": 15,
            "elements": [
                "contenttweaker:fixed_star_alloys_coil@0"
            ]
        },
        {
            "x": 1,
            "y": -9,
            "z": 16,
            "elements": [
                "ic2:resource@13"
            ]
        },
        {
            "x": 14,
            "y": -1,
            "z": 14,
            "elements": [
                "ic2:resource@13"
            ]
        },
        {
            "x": -8,
            "y": 2,
            "z": 15,
            "elements": [
                "enderio:block_enlightened_fused_quartz@0"
            ]
        },
        {
            "x": 0,
            "y": -1,
            "z": 11,
            "elements": [
                "contenttweaker:crystalmatrixforcefieldcontrolblock@0"
            ]
        },
        {
            "x": -11,
            "y": -1,
            "z": 16,
            "elements": [
                "ic2:resource@13"
            ]
        },
        {
            "x": 0,
            "y": 2,
            "z": 5,
            "elements": [
                "contenttweaker:extrememachineblock"
            ]
        },
        {
            "x": 12,
            "y": -2,
            "z": 16,
            "elements": [
                "modularmachinery:blockcasing@4"
            ]
        },
        {
            "x": -7,
            "y": -2,
            "z": 15,
            "elements": [
                "enderio:block_enlightened_fused_quartz@0"
            ]
        },
        {
            "x": -2,
            "y": 11,
            "z": 16,
            "elements": [
                "modularmachinery:blockcasing@4"
            ]
        },
        {
            "x": -3,
            "y": -10,
            "z": 15,
            "elements": [
                "contenttweaker:extrememachineblock@0"
            ]
        },
        {
            "x": 1,
            "y": -2,
            "z": 5,
            "elements": [
                "modularmachinery:blockcasing@4"
            ]
        },
        {
            "x": -13,
            "y": 1,
            "z": 13,
            "elements": [
                "modularmachinery:blockcasing@4"
            ]
        },
        {
            "x": -2,
            "y": 7,
            "z": 16,
            "elements": [
                "modularmachinery:blockcasing@4"
            ]
        },
        {
            "x": 1,
            "y": 5,
            "z": 16,
            "elements": [
                "contenttweaker:crystalmatrixforcefieldcontrolblock@0"
            ]
        },
        {
            "x": 2,
            "y": -1,
            "z": 4,
            "elements": [
                "modularmachinery:blockcasing@4"
            ]
        },
        {
            "x": 8,
            "y": 1,
            "z": 17,
            "elements": [
                "modularmachinery:blockcasing@4"
            ]
        },
        {
            "x": -1,
            "y": -2,
            "z": 22,
            "elements": [
                "modularmachinery:blockcasing@4"
            ]
        },
        {
            "x": 0,
            "y": 1,
            "z": 4,
            "elements": [
                "extendedcrafting:trimmed@1"
            ]
        },
        {
            "x": 0,
            "y": 6,
            "z": 7,
            "elements": [
                "contenttweaker:extrememachineblock@0"
            ]
        },
        {
            "x": -1,
            "y": 15,
            "z": 17,
            "elements": [
                "modularmachinery:blockcasing@4"
            ]
        },
        {
            "x": 1,
            "y": -5,
            "z": 16,
            "elements": [
                "contenttweaker:fallenstarforcefieldcontrolblock@0"
            ]
        },
        {
            "x": -9,
            "y": 0,
            "z": 15,
            "elements": [
                "contenttweaker:fixed_star_alloys_coil@0"
            ]
        },
        {
            "x": 2,
            "y": -8,
            "z": 15,
            "elements": [
                "enderio:block_enlightened_fused_quartz@0"
            ]
        },
        {
            "x": -1,
            "y": -1,
            "z": 29,
            "elements": [
                "ic2:resource@13"
            ]
        },
        {
            "x": -13,
            "y": -2,
            "z": 15,
            "elements": [
                "enderio:block_enlightened_fused_quartz@0"
            ]
        },
        {
            "x": -1,
            "y": 14,
            "z": 17,
            "elements": [
                "modularmachinery:blockcasing@4"
            ]
        },
        {
            "x": -1,
            "y": -10,
            "z": 15,
            "elements": [
                "extendedcrafting:trimmed@1"
            ]
        },
        {
            "x": -2,
            "y": 0,
            "z": 0,
            "elements": [
                "enderio:block_enlightened_fused_quartz@0"
            ]
        },
        {
            "x": -1,
            "y": 0,
            "z": 22,
            "elements": [
                "extendedcrafting:trimmed@2"
            ]
        },
        {
            "x": -1,
            "y": 0,
            "z": 5,
            "elements": [
                "extendedcrafting:trimmed@1"
            ]
        },
        {
            "x": 6,
            "y": 0,
            "z": 7,
            "elements": [
                "contenttweaker:extrememachineblock@0"
            ]
        },
        {
            "x": -1,
            "y": 1,
            "z": 26,
            "elements": [
                "ic2:resource@13"
            ]
        },
        {
            "x": -1,
            "y": 5,
            "z": 16,
            "elements": [
                "contenttweaker:crystalmatrixforcefieldcontrolblock@0"
            ]
        },
        {
            "x": 10,
            "y": -1,
            "z": 17,
            "elements": [
                "modularmachinery:blockcasing@4"
            ]
        },
        {
            "x": 1,
            "y": -2,
            "z": 22,
            "elements": [
                "modularmachinery:blockcasing@4"
            ]
        },
        {
            "x": 0,
            "y": 0,
            "z": 10,
            "elements": [
                "contenttweaker:fixed_star_alloys_coil@0"
            ]
        },
        {
            "x": -1,
            "y": 12,
            "z": 17,
            "elements": [
                "modularmachinery:blockcasing@4"
            ]
        },
        {
            "x": -1,
            "y": 0,
            "z": 26,
            "elements": [
                "extendedcrafting:trimmed@1"
            ]
        },
        {
            "x": -14,
            "y": -1,
            "z": 13,
            "elements": [
                "modularmachinery:blockcasing@4"
            ]
        },
        {
            "x": -12,
            "y": 2,
            "z": 15,
            "elements": [
                "enderio:block_enlightened_fused_quartz@0"
            ]
        },
        {
            "x": 6,
            "y": 0,
            "z": 6,
            "elements": [
                "contenttweaker:extrememachineblock@0"
            ]
        },
        {
            "x": 2,
            "y": -1,
            "z": 7,
            "elements": [
                "modularmachinery:blockcasing@4"
            ]
        },
        {
            "x": -3,
            "y": 0,
            "z": 15,
            "elements": [
                "contenttweaker:las_yio_large_lasers@1"
            ]
        },
        {
            "x": 1,
            "y": 1,
            "z": 9,
            "elements": [
                "ic2:resource@13"
            ]
        },
        {
            "x": 0,
            "y": 2,
            "z": 7,
            "elements": [
                "enderio:block_enlightened_fused_quartz@0"
            ]
        },
        {
            "x": -1,
            "y": 10,
            "z": 17,
            "elements": [
                "modularmachinery:blockcasing@4"
            ]
        },
        {
            "x": -10,
            "y": -4,
            "z": 15,
            "elements": [
                "contenttweaker:extrememachineblock@0"
            ]
        },
        {
            "x": 1,
            "y": 2,
            "z": 23,
            "elements": [
                "modularmachinery:blockcasing@4"
            ]
        },
        {
            "x": -1,
            "y": -6,
            "z": 15,
            "elements": [
                "extendedcrafting:trimmed@3"
            ]
        },
        {
            "x": -1,
            "y": 11,
            "z": 17,
            "elements": [
                "modularmachinery:blockcasing@4"
            ]
        },
        {
            "x": 2,
            "y": -12,
            "z": 15,
            "elements": [
                "enderio:block_enlightened_fused_quartz@0"
            ]
        },
        {
            "x": 1,
            "y": -1,
            "z": 19,
            "elements": [
                "contenttweaker:extrememachineblock@0"
            ]
        },
        {
            "x": 11,
            "y": 0,
            "z": 17,
            "elements": [
                "enderio:block_enlightened_fused_quartz@0"
            ]
        },
        {
            "x": 0,
            "y": 1,
            "z": 8,
            "elements": [
                "extendedcrafting:trimmed@2"
            ]
        },
        {
            "x": -1,
            "y": 1,
            "z": 19,
            "elements": [
                "contenttweaker:extrememachineblock@0"
            ]
        },
        {
            "x": 0,
            "y": 15,
            "z": 13,
            "elements": [
                "enderio:block_enlightened_fused_quartz@0"
            ]
        },
        {
            "x": 0,
            "y": -2,
            "z": 23,
            "elements": [
                "enderio:block_enlightened_fused_quartz@0"
            ]
        },
        {
            "x": 12,
            "y": 0,
            "z": 13,
            "elements": [
                "enderio:block_enlightened_fused_quartz@0"
            ]
        },
        {
            "x": -2,
            "y": 1,
            "z": 23,
            "elements": [
                "modularmachinery:blockcasing@4"
            ]
        },
        {
            "x": 11,
            "y": -2,
            "z": 14,
            "elements": [
                "modularmachinery:blockcasing@4"
            ]
        },
        {
            "x": 5,
            "y": 0,
            "z": 24,
            "elements": [
                "contenttweaker:extrememachineblock@0"
            ]
        },
        {
            "x": 11,
            "y": -1,
            "z": 13,
            "elements": [
                "modularmachinery:blockcasing@4"
            ]
        },
        {
            "x": 2,
            "y": 0,
            "z": 27,
            "elements": [
                "enderio:block_enlightened_fused_quartz@0"
            ]
        },
        {
            "x": 0,
            "y": 13,
            "z": 13,
            "elements": [
                "enderio:block_enlightened_fused_quartz@0"
            ]
        },
        {
            "x": -1,
            "y": 2,
            "z": 27,
            "elements": [
                "modularmachinery:blockcasing@4"
            ]
        },
        {
            "x": -5,
            "y": 1,
            "z": 16,
            "elements": [
                "contenttweaker:neutronforcefieldcontrolblock@0"
            ]
        },
        {
            "x": 8,
            "y": -1,
            "z": 14,
            "elements": [
                "ic2:resource@13"
            ]
        },
        {
            "x": 0,
            "y": 2,
            "z": 8,
            "elements": [
                "enderio:block_enlightened_fused_quartz@0"
            ]
        },
        {
            "x": 8,
            "y": 1,
            "z": 14,
            "elements": [
                "ic2:resource@13"
            ]
        },
        {
            "x": 0,
            "y": 12,
            "z": 13,
            "elements": [
                "enderio:block_enlightened_fused_quartz@0"
            ]
        },
        {
            "x": 0,
            "y": 11,
            "z": 13,
            "elements": [
                "enderio:block_enlightened_fused_quartz@0"
            ]
        },
        {
            "x": -13,
            "y": 0,
            "z": 15,
            "elements": [
                "contenttweaker:fixed_star_alloys_coil@0"
            ]
        },
        {
            "x": 10,
            "y": -2,
            "z": 14,
            "elements": [
                "modularmachinery:blockcasing@4"
            ]
        },
        {
            "x": -9,
            "y": -1,
            "z": 16,
            "elements": [
                "ic2:resource@13"
            ]
        },
        {
            "x": -1,
            "y": -2,
            "z": 8,
            "elements": [
                "modularmachinery:blockcasing@4"
            ]
        },
        {
            "x": 2,
            "y": -1,
            "z": 21,
            "elements": [
                "modularmachinery:blockcasing@4"
            ]
        },
        {
            "x": -1,
            "y": 8,
            "z": 15,
            "elements": [
                "extendedcrafting:trimmed@2"
            ]
        },
        {
            "x": 2,
            "y": -15,
            "z": 16,
            "elements": [
                "modularmachinery:blockcasing@4"
            ]
        },
        {
            "x": -2,
            "y": 0,
            "z": 23,
            "elements": [
                "enderio:block_enlightened_fused_quartz@0"
            ]
        },
        {
            "x": 0,
            "y": -4,
            "z": 25,
            "elements": [
                "contenttweaker:extrememachineblock@0"
            ]
        },
        {
            "x": 12,
            "y": 1,
            "z": 13,
            "elements": [
                "modularmachinery:blockcasing@4"
            ]
        },
        {
            "x": 6,
            "y": 0,
            "z": 13,
            "elements": [
                "enderio:block_enlightened_fused_quartz@0"
            ]
        },
        {
            "x": 0,
            "y": 12,
            "z": 14,
            "elements": [
                "extendedcrafting:trimmed@0"
            ]
        },
        {
            "x": 2,
            "y": 1,
            "z": 24,
            "elements": [
                "modularmachinery:blockcasing@4"
            ]
        },
        {
            "x": -2,
            "y": 1,
            "z": 4,
            "elements": [
                "modularmachinery:blockcasing@4"
            ]
        },
        {
            "x": 3,
            "y": 0,
            "z": 5,
            "elements": [
                "contenttweaker:extrememachineblock@0"
            ]
        },
        {
            "x": 0,
            "y": -6,
            "z": 23,
            "elements": [
                "contenttweaker:extrememachineblock@0"
            ]
        },
        {
            "x": -2,
            "y": -1,
            "z": 27,
            "elements": [
                "modularmachinery:blockcasing@4"
            ]
        },
        {
            "x": 0,
            "y": 9,
            "z": 13,
            "elements": [
                "enderio:block_enlightened_fused_quartz@0"
            ]
        },
        {
            "x": -1,
            "y": 4,
            "z": 15,
            "elements": [
                "contenttweaker:fallenstarforcefieldcontrolblock@0"
            ]
        },
        {
            "x": 5,
            "y": -1,
            "z": 13,
            "elements": [
                "contenttweaker:extrememachineblock@0"
            ]
        },
        {
            "x": 5,
            "y": 1,
            "z": 13,
            "elements": [
                "contenttweaker:extrememachineblock@0"
            ]
        },
        {
            "x": 1,
            "y": 2,
            "z": 10,
            "elements": [
                "contenttweaker:extrememachineblock@0"
            ]
        },
        {
            "x": -11,
            "y": 1,
            "z": 16,
            "elements": [
                "ic2:resource@13"
            ]
        },
        {
            "x": -1,
            "y": -1,
            "z": 8,
            "elements": [
                "ic2:resource@13"
            ]
        },
        {
            "x": 0,
            "y": 14,
            "z": 14,
            "elements": [
                "extendedcrafting:trimmed@0"
            ]
        },
        {
            "x": -1,
            "y": 1,
            "z": 27,
            "elements": [
                "ic2:resource@13"
            ]
        },
        {
            "x": 0,
            "y": 7,
            "z": 13,
            "elements": [
                "enderio:block_enlightened_fused_quartz@0"
            ]
        },
        {
            "x": 0,
            "y": -7,
            "z": 16,
            "elements": [
                "extendedcrafting:trimmed@2"
            ]
        },
        {
            "x": -15,
            "y": 0,
            "z": 15,
            "elements": [
                "modularmachinery:blockenergyinputhatch"
            ]
        },
        {
            "x": 1,
            "y": 2,
            "z": 3,
            "elements": [
                "modularmachinery:blockcasing@4"
            ]
        },
        {
            "x": 0,
            "y": 13,
            "z": 14,
            "elements": [
                "extendedcrafting:trimmed@0"
            ]
        },
        {
            "x": 0,
            "y": 8,
            "z": 13,
            "elements": [
                "enderio:block_enlightened_fused_quartz@0"
            ]
        },
        {
            "x": 6,
            "y": 1,
            "z": 13,
            "elements": [
                "modularmachinery:blockcasing@4"
            ]
        },
        {
            "x": -2,
            "y": -1,
            "z": 4,
            "elements": [
                "modularmachinery:blockcasing@4"
            ]
        },
        {
            "x": 2,
            "y": -11,
            "z": 16,
            "elements": [
                "modularmachinery:blockcasing@4"
            ]
        },
        {
            "x": -4,
            "y": 10,
            "z": 15,
            "elements": [
                "contenttweaker:extrememachineblock@0"
            ]
        },
        {
            "x": 8,
            "y": 0,
            "z": 13,
            "elements": [
                "enderio:block_enlightened_fused_quartz@0"
            ]
        },
        {
            "x": 0,
            "y": -15,
            "z": 16,
            "elements": [
                "extendedcrafting:trimmed@0"
            ]
        },
        {
            "x": 12,
            "y": 0,
            "z": 14,
            "elements": [
                "extendedcrafting:trimmed@0"
            ]
        },
        {
            "x": 0,
            "y": -2,
            "z": 10,
            "elements": [
                "contenttweaker:extrememachineblock@0"
            ]
        },
        {
            "x": 0,
            "y": 0,
            "z": 3,
            "elements": [
                "contenttweaker:fixed_star_alloys_coil@0"
            ]
        },
        {
            "x": -2,
            "y": 0,
            "z": 10,
            "elements": [
                "contenttweaker:extrememachineblock@0"
            ]
        },
        {
            "x": 0,
            "y": -1,
            "z": 24,
            "elements": [
                "extendedcrafting:trimmed@1"
            ]
        },
        {
            "x": 0,
            "y": 8,
            "z": 14,
            "elements": [
                "extendedcrafting:trimmed@2"
            ]
        },
        {
            "x": 0,
            "y": 1,
            "z": 11,
            "elements": [
                "contenttweaker:crystalmatrixforcefieldcontrolblock@0"
            ]
        },
        {
            "x": -9,
            "y": 1,
            "z": 16,
            "elements": [
                "ic2:resource@13"
            ]
        },
        {
            "x": 11,
            "y": 1,
            "z": 13,
            "elements": [
                "modularmachinery:blockcasing@4"
            ]
        },
        {
            "x": 0,
            "y": 0,
            "z": 20,
            "elements": [
                "contenttweaker:fixed_star_alloys_coil@0"
            ]
        },
        {
            "x": -10,
            "y": 2,
            "z": 15,
            "elements": [
                "contenttweaker:extrememachineblock"
            ]
        },
        {
            "x": 12,
            "y": 1,
            "z": 14,
            "elements": [
                "ic2:resource@13"
            ]
        },
        {
            "x": 1,
            "y": -6,
            "z": 15,
            "elements": [
                "extendedcrafting:trimmed@3"
            ]
        },
        {
            "x": -5,
            "y": -2,
            "z": 15,
            "elements": [
                "contenttweaker:extrememachineblock@0"
            ]
        },
        {
            "x": 6,
            "y": 0,
            "z": 14,
            "elements": [
                "extendedcrafting:trimmed@3"
            ]
        },
        {
            "x": 0,
            "y": 10,
            "z": 14,
            "elements": [
                "extendedcrafting:trimmed@1"
            ]
        },
        {
            "x": 0,
            "y": 9,
            "z": 14,
            "elements": [
                "extendedcrafting:trimmed@1"
            ]
        },
        {
            "x": 10,
            "y": -1,
            "z": 13,
            "elements": [
                "modularmachinery:blockcasing@4"
            ]
        },
        {
            "x": -1,
            "y": 1,
            "z": 9,
            "elements": [
                "ic2:resource@13"
            ]
        },
        {
            "x": 12,
            "y": 2,
            "z": 14,
            "elements": [
                "modularmachinery:blockcasing@4"
            ]
        },
        {
            "x": 0,
            "y": -11,
            "z": 16,
            "elements": [
                "extendedcrafting:trimmed@1"
            ]
        },
        {
            "x": -1,
            "y": -9,
            "z": 16,
            "elements": [
                "ic2:resource@13"
            ]
        },
        {
            "x": 0,
            "y": -1,
            "z": 4,
            "elements": [
                "extendedcrafting:trimmed@1"
            ]
        },
        {
            "x": 5,
            "y": -2,
            "z": 14,
            "elements": [
                "contenttweaker:extrememachineblock@0"
            ]
        },
        {
            "x": -1,
            "y": 2,
            "z": 26,
            "elements": [
                "modularmachinery:blockcasing@4"
            ]
        },
        {
            "x": 1,
            "y": -1,
            "z": 26,
            "elements": [
                "ic2:resource@13"
            ]
        },
        {
            "x": 2,
            "y": 1,
            "z": 4,
            "elements": [
                "modularmachinery:blockcasing@4"
            ]
        },
        {
            "x": 0,
            "y": 4,
            "z": 14,
            "elements": [
                "contenttweaker:fallenstarforcefieldcontrolblock@0"
            ]
        },
        {
            "x": -1,
            "y": 2,
            "z": 3,
            "elements": [
                "modularmachinery:blockcasing@4"
            ]
        },
        {
            "x": -2,
            "y": 0,
            "z": 3,
            "elements": [
                "enderio:block_enlightened_fused_quartz@0"
            ]
        },
        {
            "x": -2,
            "y": 1,
            "z": 24,
            "elements": [
                "modularmachinery:blockcasing@4"
            ]
        },
        {
            "x": -7,
            "y": 1,
            "z": 16,
            "elements": [
                "ic2:resource@13"
            ]
        },
        {
            "x": 5,
            "y": 0,
            "z": 15,
            "elements": [
                "contenttweaker:fixed_star_alloys_coil@0"
            ]
        },
        {
            "x": 0,
            "y": -2,
            "z": 3,
            "elements": [
                "enderio:block_enlightened_fused_quartz@0"
            ]
        },
        {
            "x": 1,
            "y": 0,
            "z": 25,
            "elements": [
                "extendedcrafting:trimmed@1"
            ]
        },
        {
            "x": 6,
            "y": 1,
            "z": 14,
            "elements": [
                "ic2:resource@13"
            ]
        },
        {
            "x": 0,
            "y": 5,
            "z": 14,
            "elements": [
                "extendedcrafting:trimmed@4"
            ]
        },
        {
            "x": -7,
            "y": 8,
            "z": 15,
            "elements": [
                "contenttweaker:extrememachineblock@0"
            ]
        },
        {
            "x": -2,
            "y": 0,
            "z": 24,
            "elements": [
                "enderio:block_enlightened_fused_quartz@0"
            ]
        },
        {
            "x": -11,
            "y": -2,
            "z": 15,
            "elements": [
                "enderio:block_enlightened_fused_quartz@0"
            ]
        },
        {
            "x": -1,
            "y": 0,
            "z": 28,
            "elements": [
                "extendedcrafting:trimmed@0"
            ]
        },
        {
            "x": 0,
            "y": -5,
            "z": 24,
            "elements": [
                "contenttweaker:extrememachineblock@0"
            ]
        },
        {
            "x": -7,
            "y": -1,
            "z": 16,
            "elements": [
                "ic2:resource@13"
            ]
        },
        {
            "x": 6,
            "y": 2,
            "z": 14,
            "elements": [
                "modularmachinery:blockcasing@4"
            ]
        },
        {
            "x": 2,
            "y": 6,
            "z": 15,
            "elements": [
                "enderio:block_enlightened_fused_quartz@0"
            ]
        },
        {
            "x": 14,
            "y": 1,
            "z": 17,
            "elements": [
                "modularmachinery:blockcasing@4"
            ]
        },
        {
            "x": -1,
            "y": -13,
            "z": 16,
            "elements": [
                "ic2:resource@13"
            ]
        },
        {
            "x": 0,
            "y": 1,
            "z": 21,
            "elements": [
                "extendedcrafting:trimmed@3"
            ]
        },
        {
            "x": 1,
            "y": -10,
            "z": 15,
            "elements": [
                "extendedcrafting:trimmed@1"
            ]
        },
        {
            "x": 0,
            "y": 6,
            "z": 14,
            "elements": [
                "extendedcrafting:trimmed@3"
            ]
        },
        {
            "x": -2,
            "y": -1,
            "z": 28,
            "elements": [
                "modularmachinery:blockcasing@4"
            ]
        },
        {
            "x": -2,
            "y": -11,
            "z": 16,
            "elements": [
                "modularmachinery:blockcasing@4"
            ]
        },
        {
            "x": 1,
            "y": -1,
            "z": 9,
            "elements": [
                "ic2:resource@13"
            ]
        },
        {
            "x": -1,
            "y": -1,
            "z": 19,
            "elements": [
                "contenttweaker:extrememachineblock@0"
            ]
        },
        {
            "x": 0,
            "y": 8,
            "z": 9,
            "elements": [
                "contenttweaker:extrememachineblock@0"
            ]
        },
        {
            "x": 5,
            "y": -2,
            "z": 16,
            "elements": [
                "contenttweaker:extrememachineblock@0"
            ]
        },
        {
            "x": 5,
            "y": -1,
            "z": 15,
            "elements": [
                "extendedcrafting:trimmed@4"
            ]
        },
        {
            "x": 2,
            "y": -5,
            "z": 14,
            "elements": [
                "contenttweaker:extrememachineblock@0"
            ]
        },
        {
            "x": -12,
            "y": 0,
            "z": 13,
            "elements": [
                "enderio:block_enlightened_fused_quartz@0"
            ]
        },
        {
            "x": 0,
            "y": -9,
            "z": 17,
            "elements": [
                "enderio:block_enlightened_fused_quartz@0"
            ]
        },
        {
            "x": -12,
            "y": -1,
            "z": 17,
            "elements": [
                "modularmachinery:blockcasing@4"
            ]
        },
        {
            "x": 1,
            "y": -11,
            "z": 17,
            "elements": [
                "modularmachinery:blockcasing@4"
            ]
        },
        {
            "x": 5,
            "y": -1,
            "z": 16,
            "elements": [
                "contenttweaker:neutronforcefieldcontrolblock@0"
            ]
        },
        {
            "x": 5,
            "y": -2,
            "z": 15,
            "elements": [
                "contenttweaker:extrememachineblock@0"
            ]
        },
        {
            "x": 6,
            "y": 1,
            "z": 15,
            "elements": [
                "extendedcrafting:trimmed@3"
            ]
        },
        {
            "x": -1,
            "y": -8,
            "z": 13,
            "elements": [
                "modularmachinery:blockcasing@4"
            ]
        },
        {
            "x": 6,
            "y": 0,
            "z": 16,
            "elements": [
                "extendedcrafting:trimmed@3"
            ]
        },
        {
            "x": 2,
            "y": 1,
            "z": 21,
            "elements": [
                "modularmachinery:blockcasing@4"
            ]
        },
        {
            "x": 0,
            "y": 4,
            "z": 16,
            "elements": [
                "contenttweaker:fallenstarforcefieldcontrolblock@0"
            ]
        },
        {
            "x": 11,
            "y": -1,
            "z": 16,
            "elements": [
                "ic2:resource@13"
            ]
        },
        {
            "x": -1,
            "y": 0,
            "z": 21,
            "elements": [
                "extendedcrafting:trimmed@3"
            ]
        },
        {
            "x": 0,
            "y": 9,
            "z": 20,
            "elements": [
                "contenttweaker:extrememachineblock@0"
            ]
        },
        {
            "x": 0,
            "y": 7,
            "z": 16,
            "elements": [
                "extendedcrafting:trimmed@2"
            ]
        },
        {
            "x": -6,
            "y": 2,
            "z": 16,
            "elements": [
                "modularmachinery:blockcasing@4"
            ]
        },
        {
            "x": 2,
            "y": -9,
            "z": 14,
            "elements": [
                "modularmachinery:blockcasing@4"
            ]
        },
        {
            "x": 0,
            "y": -13,
            "z": 17,
            "elements": [
                "enderio:block_enlightened_fused_quartz@0"
            ]
        },
        {
            "x": -14,
            "y": 1,
            "z": 17,
            "elements": [
                "modularmachinery:blockcasing@4"
            ]
        },
        {
            "x": 11,
            "y": -2,
            "z": 16,
            "elements": [
                "modularmachinery:blockcasing@4"
            ]
        },
        {
            "x": -12,
            "y": 1,
            "z": 14,
            "elements": [
                "ic2:resource@13"
            ]
        },
        {
            "x": 9,
            "y": 0,
            "z": 15,
            "elements": [
                "contenttweaker:fixed_star_alloys_coil@0"
            ]
        },
        {
            "x": 6,
            "y": 2,
            "z": 15,
            "elements": [
                "enderio:block_enlightened_fused_quartz@0"
            ]
        },
        {
            "x": 0,
            "y": 2,
            "z": 9,
            "elements": [
                "enderio:block_enlightened_fused_quartz@0"
            ]
        },
        {
            "x": 0,
            "y": 6,
            "z": 16,
            "elements": [
                "extendedcrafting:trimmed@3"
            ]
        },
        {
            "x": 1,
            "y": 0,
            "z": 8,
            "elements": [
                "extendedcrafting:trimmed@2"
            ]
        },
        {
            "x": 1,
            "y": -7,
            "z": 17,
            "elements": [
                "modularmachinery:blockcasing@4"
            ]
        },
        {
            "x": -2,
            "y": -1,
            "z": 24,
            "elements": [
                "modularmachinery:blockcasing@4"
            ]
        },
        {
            "x": 2,
            "y": 1,
            "z": 7,
            "elements": [
                "modularmachinery:blockcasing@4"
            ]
        },
        {
            "x": -1,
            "y": -4,
            "z": 16,
            "elements": [
                "contenttweaker:extrememachineblock@0"
            ]
        },
        {
            "x": -2,
            "y": 0,
            "z": 29,
            "elements": [
                "enderio:block_enlightened_fused_quartz@0"
            ]
        },
        {
            "x": -1,
            "y": 2,
            "z": 21,
            "elements": [
                "modularmachinery:blockcasing@4"
            ]
        },
        {
            "x": -1,
            "y": -5,
            "z": 16,
            "elements": [
                "contenttweaker:fallenstarforcefieldcontrolblock@0"
            ]
        },
        {
            "x": 2,
            "y": 0,
            "z": 6,
            "elements": [
                "enderio:block_enlightened_fused_quartz@0"
            ]
        },
        {
            "x": -1,
            "y": 2,
            "z": 6,
            "elements": [
                "modularmachinery:blockcasing@4"
            ]
        },
        {
            "x": -2,
            "y": -1,
            "z": 7,
            "elements": [
                "modularmachinery:blockcasing@4"
            ]
        },
        {
            "x": 0,
            "y": 8,
            "z": 16,
            "elements": [
                "extendedcrafting:trimmed@2"
            ]
        },
        {
            "x": 12,
            "y": 0,
            "z": 16,
            "elements": [
                "extendedcrafting:trimmed@0"
            ]
        },
        {
            "x": 1,
            "y": 1,
            "z": 26,
            "elements": [
                "ic2:resource@13"
            ]
        },
        {
            "x": -1,
            "y": -6,
            "z": 16,
            "elements": [
                "ic2:resource@13"
            ]
        },
        {
            "x": -1,
            "y": 14,
            "z": 13,
            "elements": [
                "modularmachinery:blockcasing@4"
            ]
        },
        {
            "x": 0,
            "y": 15,
            "z": 15,
            "elements": [
                "modularmachinery:blockinputbus",
                "modularmachinery:blockmepatternprovider"
            ]
        },
        {
            "x": -1,
            "y": -2,
            "z": 9,
            "elements": [
                "modularmachinery:blockcasing@4"
            ]
        },
        {
            "x": 0,
            "y": 9,
            "z": 21,
            "elements": [
                "contenttweaker:extrememachineblock@0"
            ]
        },
        {
            "x": 15,
            "y": 1,
            "z": 16,
            "elements": [
                "ic2:resource@13"
            ]
        },
        {
            "x": -1,
            "y": -15,
            "z": 17,
            "elements": [
                "modularmachinery:blockcasing@4"
            ]
        },
        {
            "x": 1,
            "y": 0,
            "z": 1,
            "elements": [
                "extendedcrafting:trimmed@0"
            ]
        },
        {
            "x": -8,
            "y": -1,
            "z": 17,
            "elements": [
                "modularmachinery:blockcasing@4"
            ]
        },
        {
            "x": -1,
            "y": 0,
            "z": 8,
            "elements": [
                "extendedcrafting:trimmed@2"
            ]
        },
        {
            "x": 0,
            "y": 8,
            "z": 21,
            "elements": [
                "contenttweaker:extrememachineblock@0"
            ]
        },
        {
            "x": 12,
            "y": 2,
            "z": 16,
            "elements": [
                "modularmachinery:blockcasing@4"
            ]
        },
        {
            "x": -2,
            "y": -1,
            "z": 25,
            "elements": [
                "modularmachinery:blockcasing@4"
            ]
        },
        {
            "x": 4,
            "y": -1,
            "z": 14,
            "elements": [
                "contenttweaker:extrememachineblock@0"
            ]
        },
        {
            "x": -12,
            "y": 0,
            "z": 16,
            "elements": [
                "extendedcrafting:trimmed@0"
            ]
        },
        {
            "x": -8,
            "y": 1,
            "z": 17,
            "elements": [
                "modularmachinery:blockcasing@4"
            ]
        },
        {
            "x": -1,
            "y": 0,
            "z": 25,
            "elements": [
                "extendedcrafting:trimmed@1"
            ]
        },
        {
            "x": 2,
            "y": -7,
            "z": 16,
            "elements": [
                "modularmachinery:blockcasing@4"
            ]
        },
        {
            "x": 2,
            "y": 5,
            "z": 14,
            "elements": [
                "contenttweaker:extrememachineblock@0"
            ]
        },
        {
            "x": 1,
            "y": -2,
            "z": 25,
            "elements": [
                "modularmachinery:blockcasing@4"
            ]
        },
        {
            "x": -13,
            "y": -1,
            "z": 16,
            "elements": [
                "ic2:resource@13"
            ]
        },
        {
            "x": 0,
            "y": 0,
            "z": 9,
            "elements": [
                "contenttweaker:fixed_star_alloys_coil@0"
            ]
        },
        {
            "x": -1,
            "y": 1,
            "z": 2,
            "elements": [
                "ic2:resource@13"
            ]
        },
        {
            "x": -1,
            "y": 1,
            "z": 25,
            "elements": [
                "ic2:resource@13"
            ]
        },
        {
            "x": -1,
            "y": -1,
            "z": 2,
            "elements": [
                "ic2:resource@13"
            ]
        },
        {
            "x": -13,
            "y": -2,
            "z": 16,
            "elements": [
                "modularmachinery:blockcasing@4"
            ]
        },
        {
            "x": -1,
            "y": 11,
            "z": 14,
            "elements": [
                "ic2:resource@13"
            ]
        },
        {
            "x": -1,
            "y": 10,
            "z": 13,
            "elements": [
                "modularmachinery:blockcasing@4"
            ]
        },
        {
            "x": -1,
            "y": -1,
            "z": 9,
            "elements": [
                "ic2:resource@13"
            ]
        },
        {
            "x": 1,
            "y": -15,
            "z": 17,
            "elements": [
                "modularmachinery:blockcasing@4"
            ]
        },
        {
            "x": -6,
            "y": 0,
            "z": 23,
            "elements": [
                "contenttweaker:extrememachineblock@0"
            ]
        },
        {
            "x": -1,
            "y": 6,
            "z": 13,
            "elements": [
                "modularmachinery:blockcasing@4"
            ]
        },
        {
            "x": 11,
            "y": 2,
            "z": 14,
            "elements": [
                "modularmachinery:blockcasing@4"
            ]
        },
        {
            "x": -10,
            "y": 1,
            "z": 17,
            "elements": [
                "modularmachinery:blockcasing@4"
            ]
        },
        {
            "x": -6,
            "y": -1,
            "z": 17,
            "elements": [
                "modularmachinery:blockcasing@4"
            ]
        },
        {
            "x": -15,
            "y": 1,
            "z": 16,
            "elements": [
                "ic2:resource@13"
            ]
        },
        {
            "x": 2,
            "y": 0,
            "z": 20,
            "elements": [
                "contenttweaker:extrememachineblock@0"
            ]
        },
        {
            "x": 1,
            "y": 1,
            "z": 2,
            "elements": [
                "ic2:resource@13"
            ]
        },
        {
            "x": -1,
            "y": -15,
            "z": 14,
            "elements": [
                "ic2:resource@13"
            ]
        },
        {
            "x": -1,
            "y": 7,
            "z": 14,
            "elements": [
                "ic2:resource@13"
            ]
        },
        {
            "x": 1,
            "y": -1,
            "z": 2,
            "elements": [
                "ic2:resource@13"
            ]
        },
        {
            "x": 2,
            "y": 9,
            "z": 14,
            "elements": [
                "modularmachinery:blockcasing@4"
            ]
        },
        {
            "x": 11,
            "y": 0,
            "z": 14,
            "elements": [
                "extendedcrafting:trimmed@1"
            ]
        },
        {
            "x": 1,
            "y": 2,
            "z": 30,
            "elements": [
                "modularmachinery:blockcasing@4"
            ]
        },
        {
            "x": 0,
            "y": -8,
            "z": 8,
            "elements": [
                "contenttweaker:extrememachineblock@0"
            ]
        },
        {
            "x": 0,
            "y": 3,
            "z": 15,
            "elements": [
                "draconicevolution:reactor_component@1"
            ]
        },
        {
            "x": 0,
            "y": 2,
            "z": 1,
            "elements": [
                "enderio:block_enlightened_fused_quartz@0"
            ]
        },
        {
            "x": 0,
            "y": -2,
            "z": 30,
            "elements": [
                "enderio:block_enlightened_fused_quartz@0"
            ]
        },
        {
            "x": -8,
            "y": -1,
            "z": 14,
            "elements": [
                "ic2:resource@13"
            ]
        },
        {
            "x": -6,
            "y": 1,
            "z": 14,
            "elements": [
                "ic2:resource@13"
            ]
        },
        {
            "x": -1,
            "y": 1,
            "z": 20,
            "elements": [
                "contenttweaker:neutronforcefieldcontrolblock@0"
            ]
        },
        {
            "x": 3,
            "y": 0,
            "z": 15,
            "elements": [
                "contenttweaker:las_yio_large_lasers@3"
            ]
        },
        {
            "x": -2,
            "y": 1,
            "z": 30,
            "elements": [
                "modularmachinery:blockcasing@4"
            ]
        },
        {
            "x": 0,
            "y": -1,
            "z": 7,
            "elements": [
                "extendedcrafting:trimmed@2"
            ]
        },
        {
            "x": -1,
            "y": 2,
            "z": 20,
            "elements": [
                "contenttweaker:extrememachineblock@0"
            ]
        },
        {
            "x": -6,
            "y": 9,
            "z": 15,
            "elements": [
                "contenttweaker:extrememachineblock@0"
            ]
        },
        {
            "x": 1,
            "y": -15,
            "z": 14,
            "elements": [
                "ic2:resource@13"
            ]
        },
        {
            "x": 0,
            "y": 0,
            "z": 6,
            "elements": [
                "contenttweaker:fixed_star_alloys_coil@0"
            ]
        },
        {
            "x": 0,
            "y": 5,
            "z": 15,
            "elements": [
                "contenttweaker:fixed_star_alloys_coil@0"
            ]
        },
        {
            "x": 0,
            "y": -13,
            "z": 14,
            "elements": [
                "extendedcrafting:trimmed@0"
            ]
        },
        {
            "x": 0,
            "y": 6,
            "z": 15,
            "elements": [
                "contenttweaker:fixed_star_alloys_coil@0"
            ]
        },
        {
            "x": 0,
            "y": -14,
            "z": 13,
            "elements": [
                "enderio:block_enlightened_fused_quartz@0"
            ]
        },
        {
            "x": 0,
            "y": 2,
            "z": 22,
            "elements": [
                "enderio:block_enlightened_fused_quartz@0"
            ]
        },
        {
            "x": 1,
            "y": 1,
            "z": 29,
            "elements": [
                "ic2:resource@13"
            ]
        },
        {
            "x": -2,
            "y": -9,
            "z": 14,
            "elements": [
                "modularmachinery:blockcasing@4"
            ]
        },
        {
            "x": -1,
            "y": -11,
            "z": 14,
            "elements": [
                "ic2:resource@13"
            ]
        },
        {
            "x": -1,
            "y": 0,
            "z": 1,
            "elements": [
                "extendedcrafting:trimmed@0"
            ]
        },
        {
            "x": 6,
            "y": -1,
            "z": 17,
            "elements": [
                "modularmachinery:blockcasing@4"
            ]
        },
        {
            "x": -1,
            "y": -2,
            "z": 1,
            "elements": [
                "modularmachinery:blockcasing@4"
            ]
        },
        {
            "x": -1,
            "y": -7,
            "z": 14,
            "elements": [
                "ic2:resource@13"
            ]
        },
        {
            "x": -10,
            "y": -1,
            "z": 14,
            "elements": [
                "ic2:resource@13"
            ]
        },
        {
            "x": -2,
            "y": 0,
            "z": 30,
            "elements": [
                "enderio:block_enlightened_fused_quartz@0"
            ]
        },
        {
            "x": -4,
            "y": 1,
            "z": 14,
            "elements": [
                "contenttweaker:extrememachineblock@0"
            ]
        },
        {
            "x": -10,
            "y": 0,
            "z": 13,
            "elements": [
                "contenttweaker:extrememachineblock@0"
            ]
        },
        {
            "x": 10,
            "y": 0,
            "z": 17,
            "elements": [
                "contenttweaker:extrememachineblock@0"
            ]
        },
        {
            "x": 5,
            "y": -9,
            "z": 15,
            "elements": [
                "contenttweaker:extrememachineblock@0"
            ]
        },
        {
            "x": 1,
            "y": -8,
            "z": 13,
            "elements": [
                "modularmachinery:blockcasing@4"
            ]
        },
        {
            "x": 1,
            "y": 7,
            "z": 17,
            "elements": [
                "modularmachinery:blockcasing@4"
            ]
        },
        {
            "x": 2,
            "y": -13,
            "z": 14,
            "elements": [
                "modularmachinery:blockcasing@4"
            ]
        },
        {
            "x": -6,
            "y": 0,
            "z": 6,
            "elements": [
                "contenttweaker:extrememachineblock@0"
            ]
        },
        {
            "x": 0,
            "y": 1,
            "z": 22,
            "elements": [
                "extendedcrafting:trimmed@2"
            ]
        },
        {
            "x": -2,
            "y": -1,
            "z": 20,
            "elements": [
                "contenttweaker:extrememachineblock@0"
            ]
        },
        {
            "x": 1,
            "y": -2,
            "z": 1,
            "elements": [
                "modularmachinery:blockcasing@4"
            ]
        },
        {
            "x": 0,
            "y": 14,
            "z": 15,
            "elements": [
                "contenttweaker:fixed_star_alloys_coil@0"
            ]
        },
        {
            "x": 1,
            "y": -7,
            "z": 14,
            "elements": [
                "ic2:resource@13"
            ]
        },
        {
            "x": 0,
            "y": 12,
            "z": 16,
            "elements": [
                "extendedcrafting:trimmed@0"
            ]
        },
        {
            "x": 12,
            "y": 2,
            "z": 15,
            "elements": [
                "enderio:block_enlightened_fused_quartz@0"
            ]
        },
        {
            "x": 1,
            "y": 0,
            "z": 5,
            "elements": [
                "extendedcrafting:trimmed@1"
            ]
        },
        {
            "x": 0,
            "y": 11,
            "z": 15,
            "elements": [
                "contenttweaker:fixed_star_alloys_coil@0"
            ]
        },
        {
            "x": -10,
            "y": 1,
            "z": 14,
            "elements": [
                "ic2:resource@13"
            ]
        },
        {
            "x": -2,
            "y": -5,
            "z": 14,
            "elements": [
                "contenttweaker:extrememachineblock@0"
            ]
        },
        {
            "x": 1,
            "y": -2,
            "z": 8,
            "elements": [
                "modularmachinery:blockcasing@4"
            ]
        },
        {
            "x": 0,
            "y": 13,
            "z": 15,
            "elements": [
                "contenttweaker:fixed_star_alloys_coil@0"
            ]
        },
        {
            "x": -4,
            "y": -1,
            "z": 14,
            "elements": [
                "contenttweaker:extrememachineblock@0"
            ]
        },
        {
            "x": -8,
            "y": 0,
            "z": 13,
            "elements": [
                "enderio:block_enlightened_fused_quartz@0"
            ]
        },
        {
            "x": 15,
            "y": 0,
            "z": 15,
            "elements": [
                "modularmachinery:blockenergyinputhatch"
            ]
        },
        {
            "x": -2,
            "y": 0,
            "z": 27,
            "elements": [
                "enderio:block_enlightened_fused_quartz@0"
            ]
        },
        {
            "x": 1,
            "y": 1,
            "z": 5,
            "elements": [
                "ic2:resource@13"
            ]
        },
        {
            "x": 0,
            "y": 1,
            "z": 28,
            "elements": [
                "extendedcrafting:trimmed@0"
            ]
        },
        {
            "x": -2,
            "y": 1,
            "z": 7,
            "elements": [
                "modularmachinery:blockcasing@4"
            ]
        },
        {
            "x": 0,
            "y": 10,
            "z": 16,
            "elements": [
                "extendedcrafting:trimmed@1"
            ]
        },
        {
            "x": 6,
            "y": 9,
            "z": 15,
            "elements": [
                "contenttweaker:extrememachineblock@0"
            ]
        },
        {
            "x": -2,
            "y": -1,
            "z": 21,
            "elements": [
                "modularmachinery:blockcasing@4"
            ]
        },
        {
            "x": 0,
            "y": -6,
            "z": 13,
            "elements": [
                "enderio:block_enlightened_fused_quartz@0"
            ]
        },
        {
            "x": 1,
            "y": -12,
            "z": 13,
            "elements": [
                "modularmachinery:blockcasing@4"
            ]
        },
        {
            "x": -1,
            "y": 2,
            "z": 23,
            "elements": [
                "modularmachinery:blockcasing@4"
            ]
        },
        {
            "x": 0,
            "y": -1,
            "z": 5,
            "elements": [
                "extendedcrafting:trimmed@1"
            ]
        },
        {
            "x": 0,
            "y": 11,
            "z": 16,
            "elements": [
                "extendedcrafting:trimmed@1"
            ]
        },
        {
            "x": 2,
            "y": 0,
            "z": 23,
            "elements": [
                "enderio:block_enlightened_fused_quartz@0"
            ]
        },
        {
            "x": 11,
            "y": -1,
            "z": 15,
            "elements": [
                "extendedcrafting:trimmed@1"
            ]
        },
        {
            "x": 0,
            "y": 7,
            "z": 15,
            "elements": [
                "contenttweaker:fixed_star_alloys_coil@0"
            ]
        },
        {
            "x": -14,
            "y": -1,
            "z": 14,
            "elements": [
                "ic2:resource@13"
            ]
        },
        {
            "x": 9,
            "y": 1,
            "z": 16,
            "elements": [
                "ic2:resource@13"
            ]
        },
        {
            "x": -14,
            "y": -1,
            "z": 17,
            "elements": [
                "modularmachinery:blockcasing@4"
            ]
        },
        {
            "x": -6,
            "y": 0,
            "z": 13,
            "elements": [
                "enderio:block_enlightened_fused_quartz@0"
            ]
        },
        {
            "x": 6,
            "y": 2,
            "z": 16,
            "elements": [
                "modularmachinery:blockcasing@4"
            ]
        },
        {
            "x": 11,
            "y": -2,
            "z": 15,
            "elements": [
                "enderio:block_enlightened_fused_quartz@0"
            ]
        },
        {
            "x": 0,
            "y": -10,
            "z": 13,
            "elements": [
                "contenttweaker:extrememachineblock@0"
            ]
        },
        {
            "x": 12,
            "y": 1,
            "z": 15,
            "elements": [
                "extendedcrafting:trimmed@0"
            ]
        },
        {
            "x": 0,
            "y": 1,
            "z": 7,
            "elements": [
                "extendedcrafting:trimmed@2"
            ]
        },
        {
            "x": -2,
            "y": 0,
            "z": 6,
            "elements": [
                "enderio:block_enlightened_fused_quartz@0"
            ]
        },
        {
            "x": 0,
            "y": 15,
            "z": 16,
            "elements": [
                "modularmachinery:blockinputbus",
                "modularmachinery:blockmepatternprovider"
            ]
        },
        {
            "x": 0,
            "y": -5,
            "z": 17,
            "elements": [
                "contenttweaker:extrememachineblock@0"
            ]
        },
        {
            "x": 0,
            "y": 9,
            "z": 15,
            "elements": [
                "contenttweaker:fixed_star_alloys_coil@0"
            ]
        },
        {
            "x": -1,
            "y": -12,
            "z": 13,
            "elements": [
                "modularmachinery:blockcasing@4"
            ]
        },
        {
            "x": -2,
            "y": -13,
            "z": 14,
            "elements": [
                "modularmachinery:blockcasing@4"
            ]
        },
        {
            "x": 0,
            "y": 10,
            "z": 15,
            "elements": [
                "contenttweaker:fixed_star_alloys_coil@0"
            ]
        },
        {
            "x": 0,
            "y": 14,
            "z": 16,
            "elements": [
                "extendedcrafting:trimmed@0"
            ]
        },
        {
            "x": 1,
            "y": -11,
            "z": 14,
            "elements": [
                "ic2:resource@13"
            ]
        },
        {
            "x": -2,
            "y": -10,
            "z": 16,
            "elements": [
                "modularmachinery:blockcasing@4"
            ]
        },
        {
            "x": -2,
            "y": -9,
            "z": 15,
            "elements": [
                "enderio:block_enlightened_fused_quartz@0"
            ]
        },
        {
            "x": 1,
            "y": 15,
            "z": 16,
            "elements": [
                "ic2:resource@13"
            ]
        },
        {
            "x": 1,
            "y": -12,
            "z": 16,
            "elements": [
                "ic2:resource@13"
            ]
        },
        {
            "x": 1,
            "y": -11,
            "z": 15,
            "elements": [
                "extendedcrafting:trimmed@1"
            ]
        },
        {
            "x": -6,
            "y": -1,
            "z": 15,
            "elements": [
                "extendedcrafting:trimmed@3"
            ]
        },
        {
            "x": 0,
            "y": -1,
            "z": 0,
            "elements": [
                "extendedcrafting:trimmed@0"
            ]
        },
        {
            "x": -8,
            "y": 1,
            "z": 15,
            "elements": [
                "extendedcrafting:trimmed@2"
            ]
        },
        {
            "x": -14,
            "y": -2,
            "z": 16,
            "elements": [
                "modularmachinery:blockcasing@4"
            ]
        },
        {
            "x": -5,
            "y": 0,
            "z": 6,
            "elements": [
                "contenttweaker:extrememachineblock@0"
            ]
        },
        {
            "x": 7,
            "y": 1,
            "z": 13,
            "elements": [
                "modularmachinery:blockcasing@4"
            ]
        },
        {
            "x": 1,
            "y": 5,
            "z": 13,
            "elements": [
                "contenttweaker:extrememachineblock@0"
            ]
        },
        {
            "x": 12,
            "y": 0,
            "z": 17,
            "elements": [
                "enderio:block_enlightened_fused_quartz@0"
            ]
        },
        {
            "x": 8,
            "y": 0,
            "z": 22,
            "elements": [
                "contenttweaker:extrememachineblock@0"
            ]
        },
        {
            "x": 0,
            "y": 10,
            "z": 18,
            "elements": [
                "contenttweaker:extrememachineblock@0"
            ]
        },
        {
            "x": -14,
            "y": 2,
            "z": 14,
            "elements": [
                "modularmachinery:blockcasing@4"
            ]
        },
        {
            "x": 0,
            "y": -5,
            "z": 6,
            "elements": [
                "contenttweaker:extrememachineblock@0"
            ]
        },
        {
            "x": 0,
            "y": 8,
            "z": 17,
            "elements": [
                "enderio:block_enlightened_fused_quartz@0"
            ]
        },
        {
            "x": 0,
            "y": -9,
            "z": 10,
            "elements": [
                "contenttweaker:extrememachineblock@0"
            ]
        },
        {
            "x": -2,
            "y": 1,
            "z": 0,
            "elements": [
                "modularmachinery:blockcasing@4"
            ]
        },
        {
            "x": -2,
            "y": 6,
            "z": 14,
            "elements": [
                "modularmachinery:blockcasing@4"
            ]
        },
        {
            "x": 0,
            "y": -6,
            "z": 6,
            "elements": [
                "contenttweaker:extrememachineblock@0"
            ]
        },
        {
            "x": -2,
            "y": -13,
            "z": 15,
            "elements": [
                "enderio:block_enlightened_fused_quartz@0"
            ]
        },
        {
            "x": -2,
            "y": 1,
            "z": 5,
            "elements": [
                "modularmachinery:blockcasing@4"
            ]
        },
        {
            "x": -1,
            "y": -15,
            "z": 15,
            "elements": [
                "extendedcrafting:trimmed@0"
            ]
        },
        {
            "x": -2,
            "y": -14,
            "z": 16,
            "elements": [
                "modularmachinery:blockcasing@4"
            ]
        },
        {
            "x": 1,
            "y": 1,
            "z": 28,
            "elements": [
                "ic2:resource@13"
            ]
        },
        {
            "x": 1,
            "y": 5,
            "z": 14,
            "elements": [
                "contenttweaker:crystalmatrixforcefieldcontrolblock@0"
            ]
        },
        {
            "x": -2,
            "y": 12,
            "z": 16,
            "elements": [
                "modularmachinery:blockcasing@4"
            ]
        },
        {
            "x": -2,
            "y": -1,
            "z": 10,
            "elements": [
                "contenttweaker:extrememachineblock@0"
            ]
        },
        {
            "x": -1,
            "y": -2,
            "z": 24,
            "elements": [
                "modularmachinery:blockcasing@4"
            ]
        },
        {
            "x": 13,
            "y": 1,
            "z": 16,
            "elements": [
                "ic2:resource@13"
            ]
        },
        {
            "x": 14,
            "y": -1,
            "z": 17,
            "elements": [
                "modularmachinery:blockcasing@4"
            ]
        },
        {
            "x": 1,
            "y": 0,
            "z": 6,
            "elements": [
                "extendedcrafting:trimmed@1"
            ]
        },
        {
            "x": -1,
            "y": -11,
            "z": 15,
            "elements": [
                "extendedcrafting:trimmed@1"
            ]
        },
        {
            "x": -2,
            "y": -6,
            "z": 16,
            "elements": [
                "modularmachinery:blockcasing@4"
            ]
        },
        {
            "x": 1,
            "y": -8,
            "z": 16,
            "elements": [
                "ic2:resource@13"
            ]
        },
        {
            "x": -2,
            "y": -1,
            "z": 0,
            "elements": [
                "modularmachinery:blockcasing@4"
            ]
        },
        {
            "x": -15,
            "y": -2,
            "z": 14,
            "elements": [
                "modularmachinery:blockcasing@4"
            ]
        },
        {
            "x": -6,
            "y": 1,
            "z": 15,
            "elements": [
                "extendedcrafting:trimmed@3"
            ]
        },
        {
            "x": 13,
            "y": 1,
            "z": 13,
            "elements": [
                "modularmachinery:blockcasing@4"
            ]
        },
        {
            "x": -8,
            "y": -1,
            "z": 15,
            "elements": [
                "extendedcrafting:trimmed@2"
            ]
        },
        {
            "x": -10,
            "y": 0,
            "z": 16,
            "elements": [
                "extendedcrafting:trimmed@1"
            ]
        },
        {
            "x": 12,
            "y": -1,
            "z": 16,
            "elements": [
                "ic2:resource@13"
            ]
        },
        {
            "x": -4,
            "y": 0,
            "z": 16,
            "elements": [
                "contenttweaker:crystalmatrixforcefieldcontrolblock@0"
            ]
        },
        {
            "x": 15,
            "y": -2,
            "z": 14,
            "elements": [
                "modularmachinery:blockcasing@4"
            ]
        },
        {
            "x": -2,
            "y": 10,
            "z": 14,
            "elements": [
                "modularmachinery:blockcasing@4"
            ]
        },
        {
            "x": 1,
            "y": 9,
            "z": 13,
            "elements": [
                "modularmachinery:blockcasing@4"
            ]
        },
        {
            "x": -13,
            "y": 2,
            "z": 16,
            "elements": [
                "modularmachinery:blockcasing@4"
            ]
        },
        {
            "x": -1,
            "y": -1,
            "z": 27,
            "elements": [
                "ic2:resource@13"
            ]
        },
        {
            "x": 0,
            "y": 12,
            "z": 17,
            "elements": [
                "enderio:block_enlightened_fused_quartz@0"
            ]
        },
        {
            "x": 1,
            "y": 4,
            "z": 14,
            "elements": [
                "contenttweaker:extrememachineblock@0"
            ]
        },
        {
            "x": 1,
            "y": 6,
            "z": 16,
            "elements": [
                "ic2:resource@13"
            ]
        },
        {
            "x": 0,
            "y": -1,
            "z": 6,
            "elements": [
                "extendedcrafting:trimmed@1"
            ]
        },
        {
            "x": 0,
            "y": -2,
            "z": 6,
            "elements": [
                "enderio:block_enlightened_fused_quartz@0"
            ]
        },
        {
            "x": 0,
            "y": -13,
            "z": 15,
            "elements": [
                "contenttweaker:fixed_star_alloys_coil@0"
            ]
        },
        {
            "x": 1,
            "y": -15,
            "z": 15,
            "elements": [
                "extendedcrafting:trimmed@0"
            ]
        },
        {
            "x": 0,
            "y": 7,
            "z": 23,
            "elements": [
                "contenttweaker:extrememachineblock@0"
            ]
        },
        {
            "x": 8,
            "y": 0,
            "z": 8,
            "elements": [
                "contenttweaker:extrememachineblock@0"
            ]
        },
        {
            "x": 0,
            "y": 1,
            "z": 5,
            "elements": [
                "extendedcrafting:trimmed@1"
            ]
        },
        {
            "x": 8,
            "y": -1,
            "z": 17,
            "elements": [
                "modularmachinery:blockcasing@4"
            ]
        },
        {
            "x": -1,
            "y": -2,
            "z": 29,
            "elements": [
                "modularmachinery:blockcasing@4"
            ]
        },
        {
            "x": 2,
            "y": -9,
            "z": 15,
            "elements": [
                "enderio:block_enlightened_fused_quartz@0"
            ]
        },
        {
            "x": -1,
            "y": -7,
            "z": 15,
            "elements": [
                "extendedcrafting:trimmed@2"
            ]
        },
        {
            "x": -12,
            "y": -1,
            "z": 14,
            "elements": [
                "ic2:resource@13"
            ]
        },
        {
            "x": 1,
            "y": 0,
            "z": 9,
            "elements": [
                "extendedcrafting:trimmed@3"
            ]
        },
        {
            "x": -1,
            "y": -1,
            "z": 22,
            "elements": [
                "ic2:resource@13"
            ]
        },
        {
            "x": 0,
            "y": 2,
            "z": 24,
            "elements": [
                "enderio:block_enlightened_fused_quartz@0"
            ]
        },
        {
            "x": 0,
            "y": 1,
            "z": 24,
            "elements": [
                "extendedcrafting:trimmed@1"
            ]
        },
        {
            "x": 0,
            "y": -8,
            "z": 14,
            "elements": [
                "extendedcrafting:trimmed@2"
            ]
        },
        {
            "x": -9,
            "y": -2,
            "z": 14,
            "elements": [
                "modularmachinery:blockcasing@4"
            ]
        },
        {
            "x": 15,
            "y": -1,
            "z": 13,
            "elements": [
                "modularmachinery:blockcasing@4"
            ]
        },
        {
            "x": -10,
            "y": -1,
            "z": 15,
            "elements": [
                "extendedcrafting:trimmed@1"
            ]
        },
        {
            "x": 0,
            "y": 2,
            "z": 4,
            "elements": [
                "enderio:block_enlightened_fused_quartz@0"
            ]
        },
        {
            "x": -11,
            "y": 0,
            "z": 14,
            "elements": [
                "extendedcrafting:trimmed@1"
            ]
        },
        {
            "x": 1,
            "y": -4,
            "z": 16,
            "elements": [
                "contenttweaker:extrememachineblock@0"
            ]
        },
        {
            "x": -12,
            "y": 1,
            "z": 15,
            "elements": [
                "extendedcrafting:trimmed@0"
            ]
        },
        {
            "x": 1,
            "y": 2,
            "z": 6,
            "elements": [
                "modularmachinery:blockcasing@4"
            ]
        },
        {
            "x": 0,
            "y": -7,
            "z": 14,
            "elements": [
                "extendedcrafting:trimmed@2"
            ]
        },
        {
            "x": 1,
            "y": 1,
            "z": 27,
            "elements": [
                "ic2:resource@13"
            ]
        },
        {
            "x": 9,
            "y": 1,
            "z": 17,
            "elements": [
                "modularmachinery:blockcasing@4"
            ]
        },
        {
            "x": 1,
            "y": 10,
            "z": 17,
            "elements": [
                "modularmachinery:blockcasing@4"
            ]
        },
        {
            "x": -11,
            "y": 1,
            "z": 14,
            "elements": [
                "ic2:resource@13"
            ]
        },
        {
            "x": 1,
            "y": 0,
            "z": 28,
            "elements": [
                "extendedcrafting:trimmed@0"
            ]
        },
        {
            "x": -2,
            "y": 8,
            "z": 16,
            "elements": [
                "modularmachinery:blockcasing@4"
            ]
        },
        {
            "x": 2,
            "y": -13,
            "z": 15,
            "elements": [
                "enderio:block_enlightened_fused_quartz@0"
            ]
        },
        {
            "x": 2,
            "y": 1,
            "z": 0,
            "elements": [
                "modularmachinery:blockcasing@4"
            ]
        },
        {
            "x": -1,
            "y": -1,
            "z": 24,
            "elements": [
                "ic2:resource@13"
            ]
        },
        {
            "x": 0,
            "y": -1,
            "z": 28,
            "elements": [
                "extendedcrafting:trimmed@0"
            ]
        },
        {
            "x": 2,
            "y": 1,
            "z": 5,
            "elements": [
                "modularmachinery:blockcasing@4"
            ]
        },
        {
            "x": 2,
            "y": -1,
            "z": 10,
            "elements": [
                "contenttweaker:extrememachineblock@0"
            ]
        },
        {
            "x": -5,
            "y": 0,
            "z": 14,
            "elements": [
                "extendedcrafting:trimmed@4"
            ]
        },
        {
            "x": -8,
            "y": 2,
            "z": 14,
            "elements": [
                "modularmachinery:blockcasing@4"
            ]
        },
        {
            "x": 0,
            "y": -5,
            "z": 14,
            "elements": [
                "extendedcrafting:trimmed@4"
            ]
        },
        {
            "x": 0,
            "y": 5,
            "z": 24,
            "elements": [
                "contenttweaker:extrememachineblock@0"
            ]
        },
        {
            "x": 0,
            "y": 1,
            "z": 10,
            "elements": [
                "extendedcrafting:trimmed@4"
            ]
        },
        {
            "x": 0,
            "y": -9,
            "z": 20,
            "elements": [
                "contenttweaker:extrememachineblock@0"
            ]
        },
        {
            "x": -6,
            "y": -1,
            "z": 14,
            "elements": [
                "ic2:resource@13"
            ]
        },
        {
            "x": 6,
            "y": 0,
            "z": 17,
            "elements": [
                "enderio:block_enlightened_fused_quartz@0"
            ]
        },
        {
            "x": -4,
            "y": -1,
            "z": 15,
            "elements": [
                "contenttweaker:crystalmatrixforcefieldcontrolblock@0"
            ]
        },
        {
            "x": 1,
            "y": -1,
            "z": 22,
            "elements": [
                "ic2:resource@13"
            ]
        },
        {
            "x": -14,
            "y": 0,
            "z": 13,
            "elements": [
                "enderio:block_enlightened_fused_quartz@0"
            ]
        },
        {
            "x": -1,
            "y": 1,
            "z": 22,
            "elements": [
                "ic2:resource@13"
            ]
        },
        {
            "x": 0,
            "y": -4,
            "z": 14,
            "elements": [
                "contenttweaker:universalforcefieldcontrolblock@0"
            ]
        },
        {
            "x": 0,
            "y": 6,
            "z": 24,
            "elements": [
                "contenttweaker:extrememachineblock@0"
            ]
        },
        {
            "x": 0,
            "y": -10,
            "z": 11,
            "elements": [
                "contenttweaker:extrememachineblock@0"
            ]
        },
        {
            "x": -1,
            "y": -1,
            "z": 23,
            "elements": [
                "ic2:resource@13"
            ]
        },
        {
            "x": -2,
            "y": -1,
            "z": 5,
            "elements": [
                "modularmachinery:blockcasing@4"
            ]
        },
        {
            "x": -5,
            "y": 1,
            "z": 14,
            "elements": [
                "contenttweaker:neutronforcefieldcontrolblock@0"
            ]
        },
        {
            "x": 0,
            "y": -9,
            "z": 14,
            "elements": [
                "extendedcrafting:trimmed@1"
            ]
        },
        {
            "x": 1,
            "y": 14,
            "z": 17,
            "elements": [
                "modularmachinery:blockcasing@4"
            ]
        },
        {
            "x": -8,
            "y": 0,
            "z": 21,
            "elements": [
                "contenttweaker:extrememachineblock@0"
            ]
        },
        {
            "x": -15,
            "y": -1,
            "z": 13,
            "elements": [
                "modularmachinery:blockcasing@4"
            ]
        },
        {
            "x": 1,
            "y": 1,
            "z": 3,
            "elements": [
                "ic2:resource@13"
            ]
        },
        {
            "x": -12,
            "y": 0,
            "z": 17,
            "elements": [
                "enderio:block_enlightened_fused_quartz@0"
            ]
        },
        {
            "x": 2,
            "y": 1,
            "z": 2,
            "elements": [
                "modularmachinery:blockcasing@4"
            ]
        },
        {
            "x": -1,
            "y": -1,
            "z": 26,
            "elements": [
                "ic2:resource@13"
            ]
        },
        {
            "x": -2,
            "y": 1,
            "z": 25,
            "elements": [
                "modularmachinery:blockcasing@4"
            ]
        },
        {
            "x": 2,
            "y": 11,
            "z": 14,
            "elements": [
                "modularmachinery:blockcasing@4"
            ]
        },
        {
            "x": 0,
            "y": 1,
            "z": 26,
            "elements": [
                "extendedcrafting:trimmed@1"
            ]
        },
        {
            "x": -14,
            "y": -1,
            "z": 15,
            "elements": [
                "extendedcrafting:trimmed@0"
            ]
        },
        {
            "x": -1,
            "y": 0,
            "z": 4,
            "elements": [
                "extendedcrafting:trimmed@1"
            ]
        },
        {
            "x": 0,
            "y": -6,
            "z": 16,
            "elements": [
                "extendedcrafting:trimmed@3"
            ]
        },
        {
            "x": 2,
            "y": 14,
            "z": 14,
            "elements": [
                "modularmachinery:blockcasing@4"
            ]
        },
        {
            "x": -6,
            "y": -2,
            "z": 16,
            "elements": [
                "modularmachinery:blockcasing@4"
            ]
        },
        {
            "x": 2,
            "y": 0,
            "z": 2,
            "elements": [
                "enderio:block_enlightened_fused_quartz@0"
            ]
        },
        {
            "x": -1,
            "y": 7,
            "z": 15,
            "elements": [
                "extendedcrafting:trimmed@2"
            ]
        },
        {
            "x": 1,
            "y": -2,
            "z": 4,
            "elements": [
                "modularmachinery:blockcasing@4"
            ]
        },
        {
            "x": -11,
            "y": 2,
            "z": 16,
            "elements": [
                "modularmachinery:blockcasing@4"
            ]
        },
        {
            "x": 2,
            "y": 13,
            "z": 14,
            "elements": [
                "modularmachinery:blockcasing@4"
            ]
        },
        {
            "x": 0,
            "y": -8,
            "z": 9,
            "elements": [
                "contenttweaker:extrememachineblock@0"
            ]
        },
        {
            "x": 0,
            "y": 0,
            "z": 26,
            "elements": [
                "contenttweaker:fixed_star_alloys_coil@0"
            ]
        },
        {
            "x": 7,
            "y": 1,
            "z": 14,
            "elements": [
                "ic2:resource@13"
            ]
        },
        {
            "x": 2,
            "y": -14,
            "z": 16,
            "elements": [
                "modularmachinery:blockcasing@4"
            ]
        },
        {
            "x": 9,
            "y": -2,
            "z": 14,
            "elements": [
                "modularmachinery:blockcasing@4"
            ]
        },
        {
            "x": 0,
            "y": -10,
            "z": 16,
            "elements": [
                "extendedcrafting:trimmed@1"
            ]
        },
        {
            "x": -6,
            "y": 0,
            "z": 17,
            "elements": [
                "enderio:block_enlightened_fused_quartz@0"
            ]
        },
        {
            "x": 7,
            "y": 0,
            "z": 14,
            "elements": [
                "extendedcrafting:trimmed@2"
            ]
        },
        {
            "x": 15,
            "y": -2,
            "z": 15,
            "elements": [
                "enderio:block_enlightened_fused_quartz@0"
            ]
        },
        {
            "x": -10,
            "y": -1,
            "z": 17,
            "elements": [
                "modularmachinery:blockcasing@4"
            ]
        },
        {
            "x": 0,
            "y": 0,
            "z": 18,
            "elements": [
                "contenttweaker:las_yio_large_lasers@0"
            ]
        },
        {
            "x": -12,
            "y": -2,
            "z": 16,
            "elements": [
                "modularmachinery:blockcasing@4"
            ]
        },
        {
            "x": 6,
            "y": -1,
            "z": 14,
            "elements": [
                "ic2:resource@13"
            ]
        },
        {
            "x": -1,
            "y": -8,
            "z": 17,
            "elements": [
                "modularmachinery:blockcasing@4"
            ]
        },
        {
            "x": -1,
            "y": -2,
            "z": 4,
            "elements": [
                "modularmachinery:blockcasing@4"
            ]
        },
        {
            "x": 0,
            "y": 9,
            "z": 10,
            "elements": [
                "contenttweaker:extrememachineblock@0"
            ]
        },
        {
            "x": -5,
            "y": 2,
            "z": 16,
            "elements": [
                "contenttweaker:extrememachineblock@0"
            ]
        },
        {
            "x": 2,
            "y": 15,
            "z": 14,
            "elements": [
                "modularmachinery:blockcasing@4"
            ]
        },
        {
            "x": 10,
            "y": 2,
            "z": 14,
            "elements": [
                "modularmachinery:blockcasing@4"
            ]
        },
        {
            "x": 2,
            "y": -1,
            "z": 5,
            "elements": [
                "modularmachinery:blockcasing@4"
            ]
        },
        {
            "x": -9,
            "y": 1,
            "z": 17,
            "elements": [
                "modularmachinery:blockcasing@4"
            ]
        },
        {
            "x": 10,
            "y": 0,
            "z": 12,
            "elements": [
                "contenttweaker:extrememachineblock@0"
            ]
        },
        {
            "x": 1,
            "y": 2,
            "z": 26,
            "elements": [
                "modularmachinery:blockcasing@4"
            ]
        },
        {
            "x": -2,
            "y": 1,
            "z": 10,
            "elements": [
                "contenttweaker:extrememachineblock@0"
            ]
        },
        {
            "x": 0,
            "y": -14,
            "z": 16,
            "elements": [
                "extendedcrafting:trimmed@0"
            ]
        },
        {
            "x": 0,
            "y": -1,
            "z": 10,
            "elements": [
                "extendedcrafting:trimmed@4"
            ]
        },
        {
            "x": 13,
            "y": 1,
            "z": 14,
            "elements": [
                "ic2:resource@13"
            ]
        },
        {
            "x": -1,
            "y": -1,
            "z": 3,
            "elements": [
                "ic2:resource@13"
            ]
        },
        {
            "x": 1,
            "y": 9,
            "z": 14,
            "elements": [
                "ic2:resource@13"
            ]
        },
        {
            "x": -1,
            "y": -8,
            "z": 16,
            "elements": [
                "ic2:resource@13"
            ]
        },
        {
            "x": 15,
            "y": 1,
            "z": 17,
            "elements": [
                "modularmachinery:blockcasing@4"
            ]
        },
        {
            "x": -4,
            "y": 1,
            "z": 15,
            "elements": [
                "contenttweaker:crystalmatrixforcefieldcontrolblock@0"
            ]
        },
        {
            "x": -10,
            "y": -2,
            "z": 16,
            "elements": [
                "modularmachinery:blockcasing@4"
            ]
        },
        {
            "x": -2,
            "y": 14,
            "z": 14,
            "elements": [
                "modularmachinery:blockcasing@4"
            ]
        },
        {
            "x": 12,
            "y": -1,
            "z": 14,
            "elements": [
                "ic2:resource@13"
            ]
        },
        {
            "x": -6,
            "y": 0,
            "z": 16,
            "elements": [
                "extendedcrafting:trimmed@3"
            ]
        },
        {
            "x": -7,
            "y": 2,
            "z": 16,
            "elements": [
                "modularmachinery:blockcasing@4"
            ]
        },
        {
            "x": 1,
            "y": 7,
            "z": 14,
            "elements": [
                "ic2:resource@13"
            ]
        },
        {
            "x": 0,
            "y": 0,
            "z": 11,
            "elements": [
                "contenttweaker:fallenstarforcefieldcontrolblock@0"
            ]
        },
        {
            "x": 1,
            "y": 13,
            "z": 13,
            "elements": [
                "modularmachinery:blockcasing@4"
            ]
        },
        {
            "x": -15,
            "y": 1,
            "z": 17,
            "elements": [
                "modularmachinery:blockcasing@4"
            ]
        },
        {
            "x": 13,
            "y": 0,
            "z": 14,
            "elements": [
                "extendedcrafting:trimmed@0"
            ]
        },
        {
            "x": 0,
            "y": 1,
            "z": 20,
            "elements": [
                "extendedcrafting:trimmed@4"
            ]
        },
        {
            "x": 1,
            "y": 8,
            "z": 14,
            "elements": [
                "ic2:resource@13"
            ]
        },
        {
            "x": -1,
            "y": -12,
            "z": 16,
            "elements": [
                "ic2:resource@13"
            ]
        },
        {
            "x": 1,
            "y": -7,
            "z": 15,
            "elements": [
                "extendedcrafting:trimmed@2"
            ]
        },
        {
            "x": -1,
            "y": 1,
            "z": 3,
            "elements": [
                "ic2:resource@13"
            ]
        },
        {
            "x": 10,
            "y": 0,
            "z": 13,
            "elements": [
                "contenttweaker:extrememachineblock@0"
            ]
        },
        {
            "x": 1,
            "y": 13,
            "z": 14,
            "elements": [
                "ic2:resource@13"
            ]
        },
        {
            "x": -1,
            "y": 0,
            "z": 9,
            "elements": [
                "extendedcrafting:trimmed@3"
            ]
        },
        {
            "x": 1,
            "y": -2,
            "z": 9,
            "elements": [
                "modularmachinery:blockcasing@4"
            ]
        },
        {
            "x": 1,
            "y": 15,
            "z": 14,
            "elements": [
                "ic2:resource@13"
            ]
        },
        {
            "x": -10,
            "y": 1,
            "z": 15,
            "elements": [
                "extendedcrafting:trimmed@1"
            ]
        },
        {
            "x": 0,
            "y": -1,
            "z": 25,
            "elements": [
                "extendedcrafting:trimmed@1"
            ]
        },
        {
            "x": 9,
            "y": -1,
            "z": 13,
            "elements": [
                "modularmachinery:blockcasing@4"
            ]
        },
        {
            "x": -8,
            "y": -2,
            "z": 16,
            "elements": [
                "modularmachinery:blockcasing@4"
            ]
        },
        {
            "x": -2,
            "y": -5,
            "z": 15,
            "elements": [
                "contenttweaker:extrememachineblock@0"
            ]
        },
        {
            "x": 1,
            "y": 0,
            "z": 4,
            "elements": [
                "extendedcrafting:trimmed@1"
            ]
        },
        {
            "x": -8,
            "y": 0,
            "z": 16,
            "elements": [
                "extendedcrafting:trimmed@2"
            ]
        },
        {
            "x": 0,
            "y": 0,
            "z": 21,
            "elements": [
                "contenttweaker:fixed_star_alloys_coil@0"
            ]
        },
        {
            "x": 2,
            "y": 5,
            "z": 15,
            "elements": [
                "contenttweaker:extrememachineblock@0"
            ]
        },
        {
            "x": 1,
            "y": 12,
            "z": 14,
            "elements": [
                "ic2:resource@13"
            ]
        },
        {
            "x": 4,
            "y": -1,
            "z": 15,
            "elements": [
                "contenttweaker:crystalmatrixforcefieldcontrolblock@0"
            ]
        },
        {
            "x": -9,
            "y": 2,
            "z": 16,
            "elements": [
                "modularmachinery:blockcasing@4"
            ]
        },
        {
            "x": 2,
            "y": -1,
            "z": 20,
            "elements": [
                "contenttweaker:extrememachineblock@0"
            ]
        },
        {
            "x": 1,
            "y": 11,
            "z": 14,
            "elements": [
                "ic2:resource@13"
            ]
        },
        {
            "x": -13,
            "y": -1,
            "z": 13,
            "elements": [
                "modularmachinery:blockcasing@4"
            ]
        },
        {
            "x": -1,
            "y": 12,
            "z": 15,
            "elements": [
                "extendedcrafting:trimmed@0"
            ]
        },
        {
            "x": 1,
            "y": 0,
            "z": 22,
            "elements": [
                "extendedcrafting:trimmed@2"
            ]
        },
        {
            "x": -1,
            "y": 2,
            "z": 7,
            "elements": [
                "modularmachinery:blockcasing@4"
            ]
        },
        {
            "x": -9,
            "y": 1,
            "z": 13,
            "elements": [
                "modularmachinery:blockcasing@4"
            ]
        },
        {
            "x": 0,
            "y": 0,
            "z": 30,
            "elements": [
                "modularmachinery:blockfluidinputhatch",
                "modularmachinery:blockmefluidinputbus"
            ]
        },
        {
            "x": 11,
            "y": 0,
            "z": 15,
            "elements": [
                "contenttweaker:fixed_star_alloys_coil@0"
            ]
        },
        {
            "x": 2,
            "y": -1,
            "z": 25,
            "elements": [
                "modularmachinery:blockcasing@4"
            ]
        },
        {
            "x": -13,
            "y": -2,
            "z": 14,
            "elements": [
                "modularmachinery:blockcasing@4"
            ]
        },
        {
            "x": 1,
            "y": 1,
            "z": 22,
            "elements": [
                "ic2:resource@13"
            ]
        },
        {
            "x": -15,
            "y": 0,
            "z": 14,
            "elements": [
                "extendedcrafting:trimmed@0"
            ]
        },
        {
            "x": 1,
            "y": 2,
            "z": 22,
            "elements": [
                "modularmachinery:blockcasing@4"
            ]
        },
        {
            "x": 1,
            "y": 15,
            "z": 15,
            "elements": [
                "modularmachinery:blockinputbus",
