{
    "registryname": "Terrace",
    "localizedname": "玉京台",
    "parts": [
        {
            "x": -3,
            "y": 2,
            "z": 0,
            "elements": [
                "minecraft:wool@14"
            ]
        },
        {
            "x": 2,
            "y": 0,
            "z": 0,
            "elements": [
                "minecraft:wool@14"
            ]
        },
        {
            "x": 3,
            "y": -1,
            "z": -2,
            "elements": [
                "minecraft:log@0"
            ]
        },
        {
            "x": -4,
            "y": -2,
            "z": -5,
            "elements": [
                "modularmachinery:blockoutputbus",
                "modularmachinery:blockmeitemoutputbus"
            ]
        },
        {
            "x": -2,
            "y": -2,
            "z": 0,
            "elements": [
                "minecraft:wool@14"
            ]
        },
        {
            "x": 1,
            "y": 2,
            "z": 0,
            "elements": [
                "minecraft:wool@14"
            ]
        },
        {
            "x": -2,
            "y": -2,
            "z": -7,
            "elements": [
                "minecraft:log@0"
            ]
        },
        {
            "x": -2,
            "y": -3,
            "z": -7,
            "elements": [
                "minecraft:log@0"
            ]
        },
        {
            "x": -4,
            "y": -1,
            "z": -5,
            "elements": [
                "minecraft:log@0"
            ]
        },
        {
            "x": -4,
            "y": -3,
            "z": -5,
            "elements": [
                "minecraft:log@0"
            ]
        },
        {
            "x": 3,
            "y": -2,
            "z": -2,
            "elements": [
                "minecraft:log@0"
            ]
        },
        {
            "x": -2,
            "y": -1,
            "z": 0,
            "elements": [
                "minecraft:wool@14"
            ]
        },
        {
            "x": 1,
            "y": 1,
            "z": 0,
            "elements": [
                "minecraft:wool@14"
            ]
        },
        {
            "x": -4,
            "y": -3,
            "z": -2,
            "elements": [
                "minecraft:log@0"
            ]
        },
        {
            "x": -2,
            "y": -1,
            "z": -7,
            "elements": [
                "minecraft:log@0"
            ]
        },
        {
            "x": 1,
            "y": -3,
            "z": 0,
            "elements": [
                "minecraft:wool@14"
            ]
        },
        {
            "x": 1,
            "y": -3,
            "z": -7,
            "elements": [
                "minecraft:log@0"
            ]
        },
        {
            "x": -3,
            "y": 0,
            "z": 0,
            "elements": [
                "minecraft:wool@14"
            ]
        },
        {
            "x": -1,
            "y": 0,
            "z": 0,
            "elements": [
                "modularmachinery:blockenergyinputhatch"
            ]
        },
        {
            "x": 1,
            "y": 0,
            "z": 0,
            "elements": [
                "minecraft:wool@14"
            ]
        },
        {
            "x": 1,
            "y": -2,
            "z": 0,
            "elements": [
                "minecraft:wool@14"
            ]
        },
        {
            "x": 0,
            "y": 2,
            "z": 0,
            "elements": [
                "minecraft:wool@14"
            ]
        },
        {
            "x": -2,
            "y": 2,
            "z": 0,
            "elements": [
                "minecraft:wool@14"
            ]
        },
        {
            "x": 3,
            "y": -1,
            "z": -5,
            "elements": [
                "minecraft:log@0"
            ]
        },
        {
            "x": 1,
            "y": -2,
            "z": -7,
            "elements": [
                "minecraft:log@0"
            ]
        },
        {
            "x": 2,
            "y": 2,
            "z": 0,
            "elements": [
                "minecraft:wool@14"
            ]
        },
        {
            "x": 4,
            "y": -4,
            "z": -7,
            "elements": [
                "minecraft:air@0"
            ]
        },
        {
            "x": -4,
            "y": -2,
            "z": -2,
            "elements": [
                "minecraft:log@0"
            ]
        },
        {
            "x": 1,
            "y": -1,
            "z": 0,
            "elements": [
                "minecraft:wool@14"
            ]
        },
        {
            "x": 1,
            "y": -1,
            "z": -7,
            "elements": [
                "minecraft:log@0"
            ]
        },
        {
            "x": -2,
            "y": 1,
            "z": 0,
            "elements": [
                "minecraft:wool@14"
            ]
        },
        {
            "x": 3,
            "y": -3,
            "z": -5,
            "elements": [
                "minecraft:log@0"
            ]
        },
        {
            "x": -2,
            "y": -3,
            "z": 0,
            "elements": [
                "minecraft:wool@14"
            ]
        },
        {
            "x": 3,
            "y": -2,
            "z": -5,
            "elements": [
                "modularmachinery:blockinputbus",
                "modularmachinery:blockmeiteminputbus"
            ]
        },
        {
            "x": 3,
            "y": -3,
            "z": -2,
            "elements": [
                "minecraft:log@0"
            ]
        },
        {
            "x": -4,
            "y": -1,
            "z": -2,
            "elements": [
                "minecraft:log@0"
            ]
        },
        {
            "x": -2,
            "y": 0,
            "z": 0,
            "elements": [
                "minecraft:wool@14"
            ]
        },
        {
            "x": -1,
            "y": 2,
            "z": 0,
            "elements": [
                "minecraft:wool@14"
            ]
        }
    ]}