{
    "registryname":"TheGateOfPlanck",
    "localizedname":"普朗克之门",
    "requires-blueprint": false,
    "color": "FFFFFF",
    "modifiers": [
        {
            "elements": "contenttweaker:fallenstarforcefieldcontrolblock",
            "x": 0,
            "y": 0,
            "z": 7,
            "description": "星辰陨落！配方时间减半。换结构最中间的即可",
            "modifier": {
                "target": "modularmachinery:duration",
                "io": "input",
                "operation": 1,
                "multiplier": 0.5
            }
        },
        {
            "elements": "contenttweaker:arkforcefieldcontrolblock",
            "x": 0,
            "y": 0,
            "z": 7,
            "description": "银河新星！配方时间降低到原来的1/4。换结构最中间的即可",
            "modifier": {
                "target": "modularmachinery:duration",
                "io": "input",
                "operation": 1,
                "multiplier": 0.25
            }
        }
    ],
    "parts": [
        {
            "x": 0,
            "y": -2,
            "z": 0,
            "elements": [
                "contenttweaker:extrememachineblock@0"
            ]
        },
        {
            "x": 1,
            "y": 0,
            "z": 14,
            "elements": [
                "contenttweaker:extrememachineblock@0"
            ]
        },
        {
            "x": 0,
            "y": -1,
            "z": 0,
            "elements": [
                "modularmachinery:blockoutputbus",
                "modularmachinery:blockmeitemoutputbus"
            ]
        },
        {
            "x": -1,
            "y": 1,
            "z": 0,
            "elements": [
                "modularmachinery:blockupgradebus"
            ]
        },
        {
            "x": -3,
            "y": 7,
            "z": 7,
            "elements": [
                "contenttweaker:extrememachineblock@0"
            ]
        },
        {
            "x": 0,
            "y": -1,
            "z": 14,
            "elements": [
                "contenttweaker:extrememachineblock@0"
            ]
        },
        {
            "x": 3,
            "y": -7,
            "z": 0,
            "elements": [
                "contenttweaker:arousal_building_block@0"
            ]
        },
        {
            "x": -4,
            "y": 7,
            "z": 0,
            "elements": [
                "contenttweaker:arousal_building_block@0"
            ]
        },
        {
            "x": 1,
            "y": 0,
            "z": 0,
            "elements": [
                "modularmachinery:blockfluidinputhatch",
                "modularmachinery:blockmefluidinputbus",
                "modularmachinery:blockmepatternprovider"
            ]
        },
        {
            "x": -3,
            "y": 7,
            "z": 0,
            "elements": [
                "contenttweaker:arousal_building_block@0"
            ]
        },
        {
            "x": 2,
            "y": -7,
            "z": 0,
            "elements": [
                "contenttweaker:arousal_building_block@0"
            ]
        },
        {
            "x": 7,
            "y": 0,
            "z": 13,
            "elements": [
                "contenttweaker:extrememachineblock@0"
            ]
        },
        {
            "x": 0,
            "y": -4,
            "z": 0,
            "elements": [
                "contenttweaker:extrememachineblock@0"
            ]
        },
        {
            "x": -3,
            "y": 7,
            "z": 14,
            "elements": [
                "contenttweaker:arousal_building_block@0"
            ]
        },
        {
            "x": 0,
            "y": 7,
            "z": 4,
            "elements": [
                "contenttweaker:extrememachineblock@0"
            ]
        },
        {
            "x": 1,
            "y": -1,
            "z": 0,
            "elements": [
                "modularmachinery:blockfluidoutputhatch",
                "modularmachinery:blockmefluidoutputbus"
            ]
        },
        {
            "x": 7,
            "y": 7,
            "z": 2,
            "elements": [
                "contenttweaker:arousal_building_block@0"
            ]
        },
        {
            "x": -2,
            "y": 2,
            "z": 5,
            "elements": [
                "contenttweaker:extrememachineblock@0"
            ]
        },
        {
            "x": 0,
            "y": 7,
            "z": 3,
            "elements": [
                "contenttweaker:extrememachineblock@0"
            ]
        },
        {
            "x": 0,
            "y": -3,
            "z": 0,
            "elements": [
                "contenttweaker:extrememachineblock@0"
            ]
        },
        {
            "x": -7,
            "y": 7,
            "z": 5,
            "elements": [
                "contenttweaker:arousal_building_block@0"
            ]
        },
        {
            "x": 0,
            "y": 3,
            "z": 14,
            "elements": [
                "contenttweaker:extrememachineblock@0"
            ]
        },
        {
            "x": -3,
            "y": -7,
            "z": 7,
            "elements": [
                "contenttweaker:extrememachineblock@0"
            ]
        },
        {
            "x": 2,
            "y": 0,
            "z": 0,
            "elements": [
                "contenttweaker:extrememachineblock@0"
            ]
        },
        {
            "x": -2,
            "y": 7,
            "z": 0,
            "elements": [
                "contenttweaker:arousal_building_block@0"
            ]
        },
        {
            "x": 1,
            "y": -7,
            "z": 0,
            "elements": [
                "contenttweaker:arousal_building_block@0"
            ]
        },
        {
            "x": 3,
            "y": 3,
            "z": 4,
            "elements": [
                "contenttweaker:extrememachineblock@0"
            ]
        },
        {
            "x": -2,
            "y": 7,
            "z": 14,
            "elements": [
                "contenttweaker:arousal_building_block@0"
            ]
        },
        {
            "x": 3,
            "y": 7,
            "z": 7,
            "elements": [
                "contenttweaker:extrememachineblock@0"
            ]
        },
        {
            "x": 1,
            "y": 1,
            "z": 0,
            "elements": [
                "modularmachinery:blockupgradebus"
            ]
        },
        {
            "x": -5,
            "y": -5,
            "z": 12,
            "elements": [
                "contenttweaker:extrememachineblock@0"
            ]
        },
        {
            "x": -6,
            "y": -7,
            "z": 7,
            "elements": [
                "contenttweaker:extrememachineblock@0"
            ]
        },
        {
            "x": 1,
            "y": 1,
            "z": 6,
            "elements": [
                "contenttweaker:extrememachineblock@0"
            ]
        },
        {
            "x": -1,
            "y": 0,
            "z": 0,
            "elements": [
                "modularmachinery:blockinputbus",
                "modularmachinery:blockmeiteminputbus",
                "modularmachinery:blockmepatternprovider"
            ]
        },
        {
            "x": 6,
            "y": 7,
            "z": 7,
            "elements": [
                "contenttweaker:extrememachineblock@0"
            ]
        },
        {
            "x": -5,
            "y": 7,
            "z": 14,
            "elements": [
                "contenttweaker:arousal_building_block@0"
            ]
        },
        {
            "x": -7,
            "y": -7,
            "z": 4,
            "elements": [
                "contenttweaker:arousal_building_block@0"
            ]
        },
        {
            "x": 0,
            "y": -7,
            "z": 5,
            "elements": [
                "contenttweaker:extrememachineblock@0"
            ]
        },
        {
            "x": 0,
            "y": 0,
            "z": 5,
            "elements": [
                "contenttweaker:extrememachineblock@0"
            ]
        },
        {
            "x": -7,
            "y": 7,
            "z": 10,
            "elements": [
                "contenttweaker:arousal_building_block@0"
            ]
        },
        {
            "x": -7,
            "y": 0,
            "z": 10,
            "elements": [
                "contenttweaker:extrememachineblock@0"
            ]
        },
        {
            "x": 4,
            "y": 0,
            "z": 14,
            "elements": [
                "contenttweaker:extrememachineblock@0"
            ]
        },
        {
            "x": -7,
            "y": -7,
            "z": 11,
            "elements": [
                "contenttweaker:arousal_building_block@0"
            ]
        },
        {
            "x": -5,
            "y": 7,
            "z": 0,
            "elements": [
                "contenttweaker:arousal_building_block@0"
            ]
        },
        {
            "x": 4,
            "y": -7,
            "z": 0,
            "elements": [
                "contenttweaker:arousal_building_block@0"
            ]
        },
        {
            "x": -7,
            "y": 0,
            "z": 5,
            "elements": [
                "contenttweaker:extrememachineblock@0"
            ]
        },
        {
            "x": 7,
            "y": 0,
            "z": 6,
            "elements": [
                "contenttweaker:extrememachineblock@0"
            ]
        },
        {
            "x": 4,
            "y": 0,
            "z": 0,
            "elements": [
                "contenttweaker:extrememachineblock@0"
            ]
        },
        {
            "x": -7,
            "y": 6,
            "z": 0,
            "elements": [
                "contenttweaker:arousal_building_block@0"
            ]
        },
        {
            "x": -3,
            "y": 3,
            "z": 4,
            "elements": [
                "contenttweaker:extrememachineblock@0"
            ]
        },
        {
            "x": -7,
            "y": -7,
            "z": 1,
            "elements": [
                "contenttweaker:arousal_building_block@0"
            ]
        },
        {
            "x": 6,
            "y": -6,
            "z": 13,
            "elements": [
                "contenttweaker:extrememachineblock@0"
            ]
        },
        {
            "x": -2,
            "y": 2,
            "z": 9,
            "elements": [
                "contenttweaker:extrememachineblock@0"
            ]
        },
        {
            "x": -7,
            "y": 5,
            "z": 0,
            "elements": [
                "contenttweaker:arousal_building_block@0"
            ]
        },
        {
            "x": 0,
            "y": -7,
            "z": 11,
            "elements": [
                "contenttweaker:extrememachineblock@0"
            ]
        },
        {
            "x": -6,
            "y": -7,
            "z": 14,
            "elements": [
                "contenttweaker:arousal_building_block@0"
            ]
        },
        {
            "x": 7,
            "y": -7,
            "z": 0,
            "elements": [
                "contenttweaker:crystalmatrixforcefieldcontrolblock"
            ]
        },
        {
            "x": 0,
            "y": -7,
            "z": 14,
            "elements": [
                "contenttweaker:crystalmatrixforcefieldcontrolblock"
            ]
        },
        {
            "x": 0,
            "y": 6,
            "z": 7,
            "elements": [
                "contenttweaker:extrememachineblock@0"
            ]
        },
        {
            "x": 5,
            "y": 0,
            "z": 0,
            "elements": [
                "contenttweaker:extrememachineblock@0"
            ]
        },
        {
            "x": -2,
            "y": 0,
            "z": 14,
            "elements": [
                "contenttweaker:extrememachineblock@0"
            ]
        },
        {
            "x": 7,
            "y": -6,
            "z": 0,
            "elements": [
                "contenttweaker:arousal_building_block@0"
            ]
        },
        {
            "x": 2,
            "y": 2,
            "z": 5,
            "elements": [
                "contenttweaker:extrememachineblock@0"
            ]
        },
        {
            "x": 0,
            "y": 7,
            "z": 7,
            "elements": [
                "contenttweaker:crystalmatrixforcefieldcontrolblock"
            ]
        },
        {
            "x": 0,
            "y": -6,
            "z": 14,
            "elements": [
                "contenttweaker:extrememachineblock@0"
            ]
        },
        {
            "x": 7,
            "y": -5,
            "z": 0,
            "elements": [
                "contenttweaker:arousal_building_block@0"
            ]
        },
        {
            "x": 0,
            "y": 0,
            "z": 4,
            "elements": [
                "contenttweaker:extrememachineblock@0"
            ]
        },
        {
            "x": -2,
            "y": 0,
            "z": 0,
            "elements": [
                "contenttweaker:extrememachineblock@0"
            ]
        },
        {
            "x": -7,
            "y": 7,
            "z": 0,
            "elements": [
                "contenttweaker:crystalmatrixforcefieldcontrolblock"
            ]
        },
        {
            "x": 6,
            "y": -7,
            "z": 0,
            "elements": [
                "contenttweaker:arousal_building_block@0"
            ]
        },
        {
            "x": 3,
            "y": -7,
            "z": 14,
            "elements": [
                "contenttweaker:arousal_building_block@0"
            ]
        },
        {
            "x": 7,
            "y": -4,
            "z": 0,
            "elements": [
                "contenttweaker:arousal_building_block@0"
            ]
        },
        {
            "x": -5,
            "y": 0,
            "z": 14,
            "elements": [
                "contenttweaker:extrememachineblock@0"
            ]
        },
        {
            "x": 7,
            "y": -7,
            "z": 12,
            "elements": [
                "contenttweaker:arousal_building_block@0"
            ]
        },
        {
            "x": 2,
            "y": 7,
            "z": 0,
            "elements": [
                "contenttweaker:arousal_building_block@0"
            ]
        },
        {
            "x": -3,
            "y": -7,
            "z": 0,
            "elements": [
                "contenttweaker:arousal_building_block@0"
            ]
        },
        {
            "x": 6,
            "y": 0,
            "z": 7,
            "elements": [
                "contenttweaker:extrememachineblock@0"
            ]
        },
        {
            "x": 7,
            "y": -3,
            "z": 0,
            "elements": [
                "contenttweaker:arousal_building_block@0"
            ]
        },
        {
            "x": 0,
            "y": 4,
            "z": 7,
            "elements": [
                "contenttweaker:extrememachineblock@0"
            ]
        },
        {
            "x": -4,
            "y": -4,
            "z": 11,
            "elements": [
                "contenttweaker:extrememachineblock@0"
            ]
        },
        {
            "x": 0,
            "y": -5,
            "z": 14,
            "elements": [
                "contenttweaker:extrememachineblock@0"
            ]
        },
        {
            "x": 7,
            "y": -7,
            "z": 5,
            "elements": [
                "contenttweaker:arousal_building_block@0"
            ]
        },
        {
            "x": -3,
            "y": 3,
            "z": 10,
            "elements": [
                "contenttweaker:extrememachineblock@0"
            ]
        },
        {
            "x": 0,
            "y": 0,
            "z": 10,
            "elements": [
                "contenttweaker:extrememachineblock@0"
            ]
        },
        {
            "x": 0,
            "y": -6,
            "z": 0,
            "elements": [
                "contenttweaker:extrememachineblock@0"
            ]
        },
        {
            "x": 0,
            "y": 7,
            "z": 5,
            "elements": [
                "contenttweaker:extrememachineblock@0"
            ]
        },
        {
            "x": 6,
            "y": -7,
            "z": 7,
            "elements": [
                "contenttweaker:extrememachineblock@0"
            ]
        },
        {
            "x": 7,
            "y": 0,
            "z": 9,
            "elements": [
                "contenttweaker:extrememachineblock@0"
            ]
        },
        {
            "x": 3,
            "y": 0,
            "z": 7,
            "elements": [
                "contenttweaker:extrememachineblock@0"
            ]
        },
        {
            "x": 0,
            "y": 5,
            "z": 7,
            "elements": [
                "contenttweaker:extrememachineblock@0"
            ]
        },
        {
            "x": -5,
            "y": 0,
            "z": 0,
            "elements": [
                "contenttweaker:extrememachineblock@0"
            ]
        },
        {
            "x": 0,
            "y": -4,
            "z": 14,
            "elements": [
                "contenttweaker:extrememachineblock@0"
            ]
        },
        {
            "x": 0,
            "y": -5,
            "z": 0,
            "elements": [
                "contenttweaker:extrememachineblock@0"
            ]
        },
        {
            "x": -1,
            "y": 7,
            "z": 0,
            "elements": [
                "contenttweaker:arousal_building_block@0"
            ]
        },
        {
            "x": 0,
            "y": -7,
            "z": 0,
            "elements": [
                "contenttweaker:crystalmatrixforcefieldcontrolblock"
            ]
        },
        {
            "x": -2,
            "y": -2,
            "z": 5,
            "elements": [
                "contenttweaker:extrememachineblock@0"
            ]
        },
        {
            "x": 0,
            "y": -2,
            "z": 14,
            "elements": [
                "contenttweaker:extrememachineblock@0"
            ]
        },
        {
            "x": 0,
            "y": -3,
            "z": 14,
            "elements": [
                "contenttweaker:extrememachineblock@0"
            ]
        },
        {
            "x": 0,
            "y": 2,
            "z": 7,
            "elements": [
                "contenttweaker:extrememachineblock@0"
            ]
        },
        {
            "x": 0,
            "y": 7,
            "z": 6,
            "elements": [
                "contenttweaker:extrememachineblock@0"
            ]
        },
        {
            "x": 6,
            "y": -7,
            "z": 14,
            "elements": [
                "contenttweaker:arousal_building_block@0"
            ]
        },
        {
            "x": 0,
            "y": 3,
            "z": 7,
            "elements": [
                "contenttweaker:extrememachineblock@0"
            ]
        },
        {
            "x": -7,
            "y": -7,
            "z": 5,
            "elements": [
                "contenttweaker:arousal_building_block@0"
            ]
        },
        {
            "x": 7,
            "y": 2,
            "z": 7,
            "elements": [
                "contenttweaker:extrememachineblock@0"
            ]
        },
        {
            "x": 0,
            "y": 7,
            "z": 10,
            "elements": [
                "contenttweaker:extrememachineblock@0"
            ]
        },
        {
            "x": -5,
            "y": -7,
            "z": 0,
            "elements": [
                "contenttweaker:arousal_building_block@0"
            ]
        },
        {
            "x": 4,
            "y": 7,
            "z": 0,
            "elements": [
                "contenttweaker:arousal_building_block@0"
            ]
        },
        {
            "x": -7,
            "y": 7,
            "z": 2,
            "elements": [
                "contenttweaker:arousal_building_block@0"
            ]
        },
        {
            "x": 7,
            "y": 7,
            "z": 6,
            "elements": [
                "contenttweaker:arousal_building_block@0"
            ]
        },
        {
            "x": 3,
            "y": -3,
            "z": 10,
            "elements": [
                "contenttweaker:extrememachineblock@0"
            ]
        },
        {
            "x": 7,
            "y": 2,
            "z": 0,
            "elements": [
                "contenttweaker:arousal_building_block@0"
            ]
        },
        {
            "x": 5,
            "y": 7,
            "z": 7,
            "elements": [
                "contenttweaker:extrememachineblock@0"
            ]
        },
        {
            "x": 7,
            "y": -1,
            "z": 0,
            "elements": [
                "contenttweaker:arousal_building_block@0"
            ]
        },
        {
            "x": 4,
            "y": 7,
            "z": 14,
            "elements": [
                "contenttweaker:arousal_building_block@0"
            ]
        },
        {
            "x": -7,
            "y": 7,
            "z": 9,
            "elements": [
                "contenttweaker:arousal_building_block@0"
            ]
        },
        {
            "x": 7,
            "y": 5,
            "z": 14,
            "elements": [
                "contenttweaker:arousal_building_block@0"
            ]
        },
        {
            "x": 7,
            "y": 3,
            "z": 7,
            "elements": [
                "contenttweaker:extrememachineblock@0"
            ]
        },
        {
            "x": 7,
            "y": 1,
            "z": 0,
            "elements": [
                "contenttweaker:arousal_building_block@0"
            ]
        },
        {
            "x": -7,
            "y": 0,
            "z": 0,
            "elements": [
                "contenttweaker:crystalmatrixforcefieldcontrolblock"
            ]
        },
        {
            "x": 7,
            "y": 6,
            "z": 14,
            "elements": [
                "contenttweaker:arousal_building_block@0"
            ]
        },
        {
            "x": 7,
            "y": -2,
            "z": 0,
            "elements": [
                "contenttweaker:arousal_building_block@0"
            ]
        },
        {
            "x": 7,
            "y": -7,
            "z": 13,
            "elements": [
                "contenttweaker:arousal_building_block@0"
            ]
        },
        {
            "x": 7,
            "y": 4,
            "z": 7,
            "elements": [
                "contenttweaker:extrememachineblock@0"
            ]
        },
        {
            "x": 7,
            "y": 3,
            "z": 14,
            "elements": [
                "contenttweaker:arousal_building_block@0"
            ]
        },
        {
            "x": 4,
            "y": 7,
            "z": 7,
            "elements": [
                "contenttweaker:extrememachineblock@0"
            ]
        },
        {
            "x": 7,
            "y": 5,
            "z": 7,
            "elements": [
                "contenttweaker:extrememachineblock@0"
            ]
        },
        {
            "x": 7,
            "y": 4,
            "z": 0,
            "elements": [
                "contenttweaker:arousal_building_block@0"
            ]
        },
        {
            "x": 5,
            "y": 7,
            "z": 14,
            "elements": [
                "contenttweaker:arousal_building_block@0"
            ]
        },
        {
            "x": 7,
            "y": 4,
            "z": 14,
            "elements": [
                "contenttweaker:arousal_building_block@0"
            ]
        },
        {
            "x": 7,
            "y": 3,
            "z": 0,
            "elements": [
                "contenttweaker:arousal_building_block@0"
            ]
        },
        {
            "x": 7,
            "y": 1,
            "z": 14,
            "elements": [
                "contenttweaker:arousal_building_block@0"
            ]
        },
        {
            "x": 0,
            "y": -7,
            "z": 9,
            "elements": [
                "contenttweaker:extrememachineblock@0"
            ]
        },
        {
            "x": -7,
            "y": 7,
            "z": 4,
            "elements": [
                "contenttweaker:arousal_building_block@0"
            ]
        },
        {
            "x": 7,
            "y": 0,
            "z": 14,
            "elements": [
                "contenttweaker:crystalmatrixforcefieldcontrolblock"
            ]
        },
        {
            "x": 6,
            "y": 7,
            "z": 14,
            "elements": [
                "contenttweaker:arousal_building_block@0"
            ]
        },
        {
            "x": 7,
            "y": 2,
            "z": 14,
            "elements": [
                "contenttweaker:arousal_building_block@0"
            ]
        },
        {
            "x": 5,
            "y": 5,
            "z": 2,
            "elements": [
                "contenttweaker:extrememachineblock@0"
            ]
        },
        {
            "x": -4,
            "y": -4,
            "z": 3,
            "elements": [
                "contenttweaker:extrememachineblock@0"
            ]
        },
        {
            "x": -1,
            "y": -1,
            "z": 8,
            "elements": [
                "contenttweaker:extrememachineblock@0"
            ]
        },
        {
            "x": 7,
            "y": 0,
            "z": 0,
            "elements": [
                "contenttweaker:crystalmatrixforcefieldcontrolblock"
            ]
        },
        {
            "x": 2,
            "y": -2,
            "z": 5,
            "elements": [
                "contenttweaker:extrememachineblock@0"
            ]
        },
        {
            "x": -7,
            "y": 4,
            "z": 0,
            "elements": [
                "contenttweaker:arousal_building_block@0"
            ]
        },
        {
            "x": 0,
            "y": 7,
            "z": 13,
            "elements": [
                "contenttweaker:extrememachineblock@0"
            ]
        },
        {
            "x": 7,
            "y": 0,
            "z": 7,
            "elements": [
                "contenttweaker:crystalmatrixforcefieldcontrolblock"
            ]
        },
        {
            "x": -7,
            "y": 1,
            "z": 0,
            "elements": [
                "contenttweaker:arousal_building_block@0"
            ]
        },
        {
            "x": 3,
            "y": 7,
            "z": 14,
            "elements": [
                "contenttweaker:arousal_building_block@0"
            ]
        },
        {
            "x": -7,
            "y": 3,
            "z": 0,
            "elements": [
                "contenttweaker:arousal_building_block@0"
            ]
        },
        {
            "x": 0,
            "y": 0,
            "z": 8,
            "elements": [
                "contenttweaker:extrememachineblock@0"
            ]
        },
        {
            "x": 5,
            "y": 5,
            "z": 12,
            "elements": [
                "contenttweaker:extrememachineblock@0"
            ]
        },
        {
            "x": -4,
            "y": 0,
            "z": 0,
            "elements": [
                "contenttweaker:extrememachineblock@0"
            ]
        },
        {
            "x": 7,
            "y": 1,
            "z": 7,
            "elements": [
                "contenttweaker:extrememachineblock@0"
            ]
        },
        {
            "x": -7,
            "y": 2,
            "z": 0,
            "elements": [
                "contenttweaker:arousal_building_block@0"
            ]
        },
        {
            "x": -5,
            "y": -5,
            "z": 2,
            "elements": [
                "contenttweaker:extrememachineblock@0"
            ]
        },
        {
            "x": 0,
            "y": -7,
            "z": 4,
            "elements": [
                "contenttweaker:extrememachineblock@0"
            ]
        },
        {
            "x": -7,
            "y": 0,
            "z": 9,
            "elements": [
                "contenttweaker:extrememachineblock@0"
            ]
        },
        {
            "x": 0,
            "y": 7,
            "z": 14,
            "elements": [
                "contenttweaker:crystalmatrixforcefieldcontrolblock"
            ]
        },
        {
            "x": 7,
            "y": 7,
            "z": 13,
            "elements": [
                "contenttweaker:arousal_building_block@0"
            ]
        },
        {
            "x": 0,
            "y": 0,
            "z": 3,
            "elements": [
                "contenttweaker:extrememachineblock@0"
            ]
        },
        {
            "x": 6,
            "y": 6,
            "z": 1,
            "elements": [
                "contenttweaker:extrememachineblock@0"
            ]
        },
        {
            "x": 0,
            "y": -7,
            "z": 3,
            "elements": [
                "contenttweaker:extrememachineblock@0"
            ]
        },
        {
            "x": 7,
            "y": 7,
            "z": 12,
            "elements": [
                "contenttweaker:arousal_building_block@0"
            ]
        },
        {
            "x": -2,
            "y": -7,
            "z": 0,
            "elements": [
                "contenttweaker:arousal_building_block@0"
            ]
        },
        {
            "x": 1,
            "y": 7,
            "z": 0,
            "elements": [
                "contenttweaker:arousal_building_block@0"
            ]
        },
        {
            "x": -7,
            "y": -7,
            "z": 8,
            "elements": [
                "contenttweaker:arousal_building_block@0"
            ]
        },
        {
            "x": 6,
            "y": 0,
            "z": 14,
            "elements": [
                "contenttweaker:extrememachineblock@0"
            ]
        },
        {
            "x": 1,
            "y": 7,
            "z": 14,
            "elements": [
                "contenttweaker:arousal_building_block@0"
            ]
        },
        {
            "x": 0,
            "y": 0,
            "z": 11,
            "elements": [
                "contenttweaker:extrememachineblock@0"
            ]
        },
        {
            "x": -3,
            "y": -3,
            "z": 4,
            "elements": [
                "contenttweaker:extrememachineblock@0"
            ]
        },
        {
            "x": 7,
            "y": 5,
            "z": 0,
            "elements": [
                "contenttweaker:arousal_building_block@0"
            ]
        },
        {
            "x": 7,
            "y": 7,
            "z": 7,
            "elements": [
                "contenttweaker:crystalmatrixforcefieldcontrolblock"
            ]
        },
        {
            "x": 3,
            "y": 0,
            "z": 14,
            "elements": [
                "contenttweaker:extrememachineblock@0"
            ]
        },
        {
            "x": 0,
            "y": 4,
            "z": 14,
            "elements": [
                "contenttweaker:extrememachineblock@0"
            ]
        },
        {
            "x": 6,
            "y": 6,
            "z": 13,
            "elements": [
                "contenttweaker:extrememachineblock@0"
            ]
        },
        {
            "x": 7,
            "y": 6,
            "z": 0,
            "elements": [
                "contenttweaker:arousal_building_block@0"
            ]
        },
        {
            "x": -7,
            "y": 7,
            "z": 3,
            "elements": [
                "contenttweaker:arousal_building_block@0"
            ]
        },
        {
            "x": 7,
            "y": -7,
            "z": 2,
            "elements": [
                "contenttweaker:arousal_building_block@0"
            ]
        },
        {
            "x": -3,
            "y": -3,
            "z": 10,
            "elements": [
                "contenttweaker:extrememachineblock@0"
            ]
        },
        {
            "x": 7,
            "y": 6,
            "z": 7,
            "elements": [
                "contenttweaker:extrememachineblock@0"
            ]
        },
        {
            "x": -2,
            "y": -2,
            "z": 9,
            "elements": [
                "contenttweaker:extrememachineblock@0"
            ]
        },
        {
            "x": -7,
            "y": 0,
            "z": 2,
            "elements": [
                "contenttweaker:extrememachineblock@0"
            ]
        },
        {
            "x": 0,
            "y": 5,
            "z": 14,
            "elements": [
                "contenttweaker:extrememachineblock@0"
            ]
        },
        {
            "x": 7,
            "y": 7,
            "z": 0,
            "elements": [
                "contenttweaker:crystalmatrixforcefieldcontrolblock"
            ]
        },
        {
            "x": -7,
            "y": -7,
            "z": 2,
            "elements": [
                "contenttweaker:arousal_building_block@0"
            ]
        },
        {
            "x": -4,
            "y": 4,
            "z": 3,
            "elements": [
                "contenttweaker:extrememachineblock@0"
            ]
        },
        {
            "x": 0,
            "y": 7,
            "z": 11,
            "elements": [
                "contenttweaker:extrememachineblock@0"
            ]
        },
        {
            "x": 7,
            "y": 7,
            "z": 14,
            "elements": [
                "contenttweaker:crystalmatrixforcefieldcontrolblock"
            ]
        },
        {
            "x": 0,
            "y": -7,
            "z": 10,
            "elements": [
                "contenttweaker:extrememachineblock@0"
            ]
        },
        {
            "x": 3,
            "y": -3,
            "z": 4,
            "elements": [
                "contenttweaker:extrememachineblock@0"
            ]
        },
        {
            "x": 0,
            "y": 6,
            "z": 14,
            "elements": [
                "contenttweaker:extrememachineblock@0"
            ]
        },
        {
            "x": 7,
            "y": 0,
            "z": 12,
            "elements": [
                "contenttweaker:extrememachineblock@0"
            ]
        },
        {
            "x": 0,
            "y": 7,
            "z": 8,
            "elements": [
                "contenttweaker:extrememachineblock@0"
            ]
        },
        {
            "x": -4,
            "y": 7,
            "z": 14,
            "elements": [
                "contenttweaker:arousal_building_block@0"
            ]
        },
        {
            "x": -7,
            "y": 1,
            "z": 7,
            "elements": [
                "contenttweaker:extrememachineblock@0"
            ]
        },
        {
            "x": 5,
            "y": -7,
            "z": 14,
            "elements": [
                "contenttweaker:arousal_building_block@0"
            ]
        },
        {
            "x": 7,
            "y": 0,
            "z": 4,
            "elements": [
                "contenttweaker:extrememachineblock@0"
            ]
        },
        {
            "x": 2,
            "y": 2,
            "z": 9,
            "elements": [
                "contenttweaker:extrememachineblock@0"
            ]
        },
        {
            "x": 0,
            "y": -7,
            "z": 8,
            "elements": [
                "contenttweaker:extrememachineblock@0"
            ]
        },
        {
            "x": 0,
            "y": 7,
            "z": 9,
            "elements": [
                "contenttweaker:extrememachineblock@0"
            ]
        },
        {
            "x": 4,
            "y": -7,
            "z": 7,
            "elements": [
                "contenttweaker:extrememachineblock@0"
            ]
        },
        {
            "x": -7,
            "y": 0,
            "z": 7,
            "elements": [
                "contenttweaker:crystalmatrixforcefieldcontrolblock"
            ]
        },
        {
            "x": 0,
            "y": 7,
            "z": 2,
            "elements": [
                "contenttweaker:extrememachineblock@0"
            ]
        },
        {
            "x": -7,
            "y": 0,
            "z": 4,
            "elements": [
                "contenttweaker:extrememachineblock@0"
            ]
        },
        {
            "x": 7,
            "y": 7,
            "z": 10,
            "elements": [
                "contenttweaker:arousal_building_block@0"
            ]
        },
        {
            "x": 7,
            "y": 0,
            "z": 11,
            "elements": [
                "contenttweaker:extrememachineblock@0"
            ]
        },
        {
            "x": 2,
            "y": 0,
            "z": 14,
            "elements": [
                "contenttweaker:extrememachineblock@0"
            ]
        },
        {
            "x": 4,
            "y": -7,
            "z": 14,
            "elements": [
                "contenttweaker:arousal_building_block@0"
            ]
        },
        {
            "x": 7,
            "y": -1,
            "z": 7,
            "elements": [
                "contenttweaker:extrememachineblock@0"
            ]
        },
        {
            "x": -4,
            "y": 7,
            "z": 7,
            "elements": [
                "contenttweaker:extrememachineblock@0"
            ]
        },
        {
            "x": 2,
            "y": 0,
            "z": 7,
            "elements": [
                "contenttweaker:extrememachineblock@0"
            ]
        },
        {
            "x": 7,
            "y": -7,
            "z": 3,
            "elements": [
                "contenttweaker:arousal_building_block@0"
            ]
        },
        {
            "x": 5,
            "y": -5,
            "z": 2,
            "elements": [
                "contenttweaker:extrememachineblock@0"
            ]
        },
        {
            "x": 7,
            "y": -7,
            "z": 4,
            "elements": [
                "contenttweaker:arousal_building_block@0"
            ]
        },
        {
            "x": -7,
            "y": 0,
            "z": 3,
            "elements": [
                "contenttweaker:extrememachineblock@0"
            ]
        },
        {
            "x": 4,
            "y": 4,
            "z": 11,
            "elements": [
                "contenttweaker:extrememachineblock@0"
            ]
        },
        {
            "x": -1,
            "y": 0,
            "z": 14,
            "elements": [
                "contenttweaker:extrememachineblock@0"
            ]
        },
        {
            "x": 7,
            "y": 0,
            "z": 1,
            "elements": [
                "contenttweaker:extrememachineblock@0"
            ]
        },
        {
            "x": 7,
            "y": 7,
            "z": 5,
            "elements": [
                "contenttweaker:arousal_building_block@0"
            ]
        },
        {
            "x": 7,
            "y": -7,
            "z": 14,
            "elements": [
                "contenttweaker:crystalmatrixforcefieldcontrolblock"
            ]
        },
        {
            "x": -1,
            "y": 0,
            "z": 7,
            "elements": [
                "contenttweaker:extrememachineblock@0"
            ]
        },
        {
            "x": -7,
            "y": -7,
            "z": 13,
            "elements": [
                "contenttweaker:arousal_building_block@0"
            ]
        },
        {
            "x": 0,
            "y": 0,
            "z": 12,
            "elements": [
                "contenttweaker:extrememachineblock@0"
            ]
        },
        {
            "x": 7,
            "y": -6,
            "z": 14,
            "elements": [
                "contenttweaker:arousal_building_block@0"
            ]
        },
        {
            "x": 1,
            "y": -1,
            "z": 6,
            "elements": [
                "contenttweaker:extrememachineblock@0"
            ]
        },
        {
            "x": -6,
            "y": -6,
            "z": 1,
            "elements": [
                "contenttweaker:extrememachineblock@0"
            ]
        },
        {
            "x": 0,
            "y": 0,
            "z": 2,
            "elements": [
                "contenttweaker:extrememachineblock@0"
            ]
        },
        {
            "x": 2,
            "y": -7,
            "z": 14,
            "elements": [
                "contenttweaker:arousal_building_block@0"
            ]
        },
        {
            "x": -1,
            "y": 1,
            "z": 8,
            "elements": [
                "contenttweaker:extrememachineblock@0"
            ]
        },
        {
            "x": -7,
            "y": 3,
            "z": 7,
            "elements": [
                "contenttweaker:extrememachineblock@0"
            ]
        },
        {
            "x": -7,
            "y": 4,
            "z": 7,
            "elements": [
                "contenttweaker:extrememachineblock@0"
            ]
        },
        {
            "x": 2,
            "y": -2,
            "z": 9,
            "elements": [
                "contenttweaker:extrememachineblock@0"
            ]
        },
        {
            "x": -7,
            "y": 2,
            "z": 7,
            "elements": [
                "contenttweaker:extrememachineblock@0"
            ]
        },
        {
            "x": 7,
            "y": -7,
            "z": 7,
            "elements": [
                "contenttweaker:crystalmatrixforcefieldcontrolblock"
            ]
        },
        {
            "x": 4,
            "y": -4,
            "z": 3,
            "elements": [
                "contenttweaker:extrememachineblock@0"
            ]
        },
        {
            "x": -7,
            "y": 5,
            "z": 7,
            "elements": [
                "contenttweaker:extrememachineblock@0"
            ]
        },
        {
            "x": -4,
            "y": 0,
            "z": 7,
            "elements": [
                "contenttweaker:extrememachineblock@0"
            ]
        },
        {
            "x": 7,
            "y": -2,
            "z": 14,
            "elements": [
                "contenttweaker:arousal_building_block@0"
            ]
        },
        {
            "x": 5,
            "y": 0,
            "z": 14,
            "elements": [
                "contenttweaker:extrememachineblock@0"
            ]
        },
        {
            "x": 1,
            "y": 7,
            "z": 7,
            "elements": [
                "contenttweaker:extrememachineblock@0"
            ]
        },
        {
            "x": 1,
            "y": 0,
            "z": 1,
            "elements": [
                "contenttweaker:extrememachineblock@0"
            ]
        },
        {
            "x": 7,
            "y": -5,
            "z": 7,
            "elements": [
                "contenttweaker:extrememachineblock@0"
            ]
        },
        {
            "x": 7,
            "y": -3,
            "z": 14,
            "elements": [
                "contenttweaker:arousal_building_block@0"
            ]
        },
        {
            "x": -7,
            "y": -6,
            "z": 14,
            "elements": [
                "contenttweaker:arousal_building_block@0"
            ]
        },
        {
            "x": 7,
            "y": -6,
            "z": 7,
            "elements": [
                "contenttweaker:extrememachineblock@0"
            ]
        },
        {
            "x": 7,
            "y": 7,
            "z": 4,
            "elements": [
                "contenttweaker:arousal_building_block@0"
            ]
        },
        {
            "x": 1,
            "y": 1,
            "z": 1,
            "elements": [
                "contenttweaker:extrememachineblock@0"
            ]
        },
        {
            "x": 0,
            "y": 0,
            "z": 13,
            "elements": [
                "contenttweaker:extrememachineblock@0"
            ]
        },
        {
            "x": 5,
            "y": -5,
            "z": 12,
            "elements": [
                "contenttweaker:extrememachineblock@0"
            ]
        },
        {
            "x": 7,
            "y": -7,
            "z": 6,
            "elements": [
                "contenttweaker:arousal_building_block@0"
            ]
        },
        {
            "x": 7,
            "y": -3,
            "z": 7,
            "elements": [
                "contenttweaker:extrememachineblock@0"
            ]
        },
        {
            "x": 7,
            "y": -4,
            "z": 14,
            "elements": [
                "contenttweaker:arousal_building_block@0"
            ]
        },
        {
            "x": -7,
            "y": 7,
            "z": 14,
            "elements": [
                "contenttweaker:crystalmatrixforcefieldcontrolblock"
            ]
        },
        {
            "x": 5,
            "y": 0,
            "z": 7,
            "elements": [
                "contenttweaker:extrememachineblock@0"
            ]
        },
        {
            "x": 0,
            "y": 0,
            "z": 9,
            "elements": [
                "contenttweaker:extrememachineblock@0"
            ]
        },
        {
            "x": 7,
            "y": -4,
            "z": 7,
            "elements": [
                "contenttweaker:extrememachineblock@0"
            ]
        },
        {
            "x": 7,
            "y": -5,
            "z": 14,
            "elements": [
                "contenttweaker:arousal_building_block@0"
            ]
        },
        {
            "x": 7,
            "y": 0,
            "z": 10,
            "elements": [
                "contenttweaker:extrememachineblock@0"
            ]
        },
        {
            "x": -7,
            "y": -7,
            "z": 7,
            "elements": [
                "contenttweaker:crystalmatrixforcefieldcontrolblock"
            ]
        },
        {
            "x": -7,
            "y": -7,
            "z": 14,
            "elements": [
                "contenttweaker:crystalmatrixforcefieldcontrolblock"
            ]
        },
        {
            "x": 0,
            "y": 7,
            "z": 12,
            "elements": [
                "contenttweaker:extrememachineblock@0"
            ]
        },
        {
            "x": 7,
            "y": 7,
            "z": 11,
            "elements": [
                "contenttweaker:arousal_building_block@0"
            ]
        },
        {
            "x": 2,
            "y": 7,
            "z": 14,
            "elements": [
                "contenttweaker:arousal_building_block@0"
            ]
        },
        {
            "x": -1,
            "y": 7,
            "z": 7,
            "elements": [
                "contenttweaker:extrememachineblock@0"
            ]
        },
        {
            "x": -7,
            "y": 7,
            "z": 8,
            "elements": [
                "contenttweaker:arousal_building_block@0"
            ]
        },
        {
            "x": 6,
            "y": -6,
            "z": 1,
            "elements": [
                "contenttweaker:extrememachineblock@0"
            ]
        },
        {
            "x": 7,
            "y": -2,
            "z": 7,
            "elements": [
                "contenttweaker:extrememachineblock@0"
            ]
        },
        {
            "x": 7,
            "y": 7,
            "z": 1,
            "elements": [
                "contenttweaker:arousal_building_block@0"
            ]
        },
        {
            "x": -7,
            "y": -7,
            "z": 6,
            "elements": [
                "contenttweaker:arousal_building_block@0"
            ]
        },
        {
            "x": -5,
            "y": 5,
            "z": 2,
            "elements": [
                "contenttweaker:extrememachineblock@0"
            ]
        },
        {
            "x": -7,
            "y": -7,
            "z": 9,
            "elements": [
                "contenttweaker:arousal_building_block@0"
            ]
        },
        {
            "x": 4,
            "y": 4,
            "z": 3,
            "elements": [
                "contenttweaker:extrememachineblock@0"
            ]
        },
        {
            "x": -1,
            "y": 7,
            "z": 14,
            "elements": [
                "contenttweaker:arousal_building_block@0"
            ]
        },
        {
            "x": 2,
            "y": 7,
            "z": 7,
            "elements": [
                "contenttweaker:extrememachineblock@0"
            ]
        },
        {
            "x": 3,
            "y": 3,
            "z": 10,
            "elements": [
                "contenttweaker:extrememachineblock@0"
            ]
        },
        {
            "x": -5,
            "y": -7,
            "z": 7,
            "elements": [
                "contenttweaker:extrememachineblock@0"
            ]
        },
        {
            "x": 7,
            "y": -1,
            "z": 14,
            "elements": [
                "contenttweaker:arousal_building_block@0"
            ]
        },
        {
            "x": -7,
            "y": 0,
            "z": 14,
            "elements": [
                "contenttweaker:crystalmatrixforcefieldcontrolblock"
            ]
        },
        {
            "x": -7,
            "y": -7,
            "z": 3,
            "elements": [
                "contenttweaker:arousal_building_block@0"
            ]
        },
        {
            "x": -3,
            "y": -7,
            "z": 14,
            "elements": [
                "contenttweaker:arousal_building_block@0"
            ]
        },
        {
            "x": -7,
            "y": -1,
            "z": 7,
            "elements": [
                "contenttweaker:extrememachineblock@0"
            ]
        },
        {
            "x": 7,
            "y": 0,
            "z": 3,
            "elements": [
                "contenttweaker:extrememachineblock@0"
            ]
        },
        {
            "x": -7,
            "y": -4,
            "z": 0,
            "elements": [
                "contenttweaker:arousal_building_block@0"
            ]
        },
        {
            "x": -7,
            "y": -7,
            "z": 12,
            "elements": [
                "contenttweaker:arousal_building_block@0"
            ]
        },
        {
            "x": -7,
            "y": 7,
            "z": 11,
            "elements": [
                "contenttweaker:arousal_building_block@0"
            ]
        },
        {
            "x": 1,
            "y": 0,
            "z": 7,
            "elements": [
                "contenttweaker:extrememachineblock@0"
            ]
        },
        {
            "x": -6,
            "y": 6,
            "z": 1,
            "elements": [
                "contenttweaker:extrememachineblock@0"
            ]
        },
        {
            "x": -1,
            "y": -1,
            "z": 6,
            "elements": [
                "contenttweaker:extrememachineblock@0"
            ]
        },
        {
            "x": -7,
            "y": -2,
            "z": 7,
            "elements": [
                "contenttweaker:extrememachineblock@0"
            ]
        },
        {
            "x": -7,
            "y": 0,
            "z": 11,
            "elements": [
                "contenttweaker:extrememachineblock@0"
            ]
        },
        {
            "x": 7,
            "y": 7,
            "z": 8,
            "elements": [
                "contenttweaker:arousal_building_block@0"
            ]
        },
        {
            "x": -4,
            "y": -7,
            "z": 7,
            "elements": [
                "contenttweaker:extrememachineblock@0"
            ]
        },
        {
            "x": -7,
            "y": -3,
            "z": 0,
            "elements": [
                "contenttweaker:arousal_building_block@0"
            ]
        },
        {
            "x": -6,
            "y": 0,
            "z": 14,
            "elements": [
                "contenttweaker:extrememachineblock@0"
            ]
        },
        {
            "x": 0,
            "y": -1,
            "z": 7,
            "elements": [
                "contenttweaker:extrememachineblock@0"
            ]
        },
        {
            "x": 7,
            "y": -7,
            "z": 11,
            "elements": [
                "contenttweaker:arousal_building_block@0"
            ]
        },
        {
            "x": -7,
            "y": -1,
            "z": 14,
            "elements": [
                "contenttweaker:arousal_building_block@0"
            ]
        },
        {
            "x": -4,
            "y": -7,
            "z": 14,
            "elements": [
                "contenttweaker:arousal_building_block@0"
            ]
        },
        {
            "x": -7,
            "y": 2,
            "z": 14,
            "elements": [
                "contenttweaker:arousal_building_block@0"
            ]
        },
        {
            "x": -7,
            "y": -2,
            "z": 0,
            "elements": [
                "contenttweaker:arousal_building_block@0"
            ]
        },
        {
            "x": 5,
            "y": 7,
            "z": 0,
            "elements": [
                "contenttweaker:arousal_building_block@0"
            ]
        },
        {
            "x": -6,
            "y": -7,
            "z": 0,
            "elements": [
                "contenttweaker:arousal_building_block@0"
            ]
        },
        {
            "x": 0,
            "y": 0,
            "z": 6,
            "elements": [
                "contenttweaker:extrememachineblock@0"
            ]
        },
        {
            "x": -5,
            "y": 5,
            "z": 12,
            "elements": [
                "contenttweaker:extrememachineblock@0"
            ]
        },
        {
            "x": 0,
            "y": -7,
            "z": 1,
            "elements": [
                "contenttweaker:extrememachineblock@0"
            ]
        },
        {
            "x": 0,
            "y": 0,
            "z": 1,
            "elements": [
                "contenttweaker:crystalmatrixforcefieldcontrolblock"
            ]
        },
        {
            "x": -7,
            "y": 1,
            "z": 14,
            "elements": [
                "contenttweaker:arousal_building_block@0"
            ]
        },
        {
            "x": 7,
            "y": 7,
            "z": 9,
            "elements": [
                "contenttweaker:arousal_building_block@0"
            ]
        },
        {
            "x": 5,
            "y": -7,
            "z": 7,
            "elements": [
                "contenttweaker:extrememachineblock@0"
            ]
        },
        {
            "x": -7,
            "y": -1,
            "z": 0,
            "elements": [
                "contenttweaker:arousal_building_block@0"
            ]
        },
        {
            "x": -6,
            "y": 0,
            "z": 0,
            "elements": [
                "contenttweaker:extrememachineblock@0"
            ]
        },
        {
            "x": 0,
            "y": 1,
            "z": 1,
            "elements": [
                "contenttweaker:extrememachineblock@0"
            ]
        },
        {
            "x": -6,
            "y": 0,
            "z": 7,
            "elements": [
                "contenttweaker:extrememachineblock@0"
            ]
        },
        {
            "x": 0,
            "y": -2,
            "z": 7,
            "elements": [
                "contenttweaker:extrememachineblock@0"
            ]
        },
        {
            "x": 0,
            "y": -7,
            "z": 2,
            "elements": [
                "contenttweaker:extrememachineblock@0"
            ]
        },
        {
            "x": -1,
            "y": 0,
            "z": 1,
            "elements": [
                "contenttweaker:extrememachineblock@0"
            ]
        },
        {
            "x": -1,
            "y": -7,
            "z": 14,
            "elements": [
                "contenttweaker:arousal_building_block@0"
            ]
        },
        {
            "x": -4,
            "y": 4,
            "z": 11,
            "elements": [
                "contenttweaker:extrememachineblock@0"
            ]
        },
        {
            "x": -7,
            "y": 4,
            "z": 14,
            "elements": [
                "contenttweaker:arousal_building_block@0"
            ]
        },
        {
            "x": 6,
            "y": 7,
            "z": 0,
            "elements": [
                "contenttweaker:arousal_building_block@0"
            ]
        },
        {
            "x": -7,
            "y": -7,
            "z": 0,
            "elements": [
                "contenttweaker:crystalmatrixforcefieldcontrolblock"
            ]
        },
        {
            "x": -7,
            "y": -6,
            "z": 7,
            "elements": [
                "contenttweaker:extrememachineblock@0"
            ]
        },
        {
            "x": -7,
            "y": -3,
            "z": 14,
            "elements": [
                "contenttweaker:arousal_building_block@0"
            ]
        },
        {
            "x": 2,
            "y": -7,
            "z": 7,
            "elements": [
                "contenttweaker:extrememachineblock@0"
            ]
        },
        {
            "x": -7,
            "y": 0,
            "z": 6,
            "elements": [
                "contenttweaker:extrememachineblock@0"
            ]
        },
        {
            "x": -7,
            "y": 6,
            "z": 14,
            "elements": [
                "contenttweaker:arousal_building_block@0"
            ]
        },
        {
            "x": -1,
            "y": -1,
            "z": 1,
            "elements": [
                "contenttweaker:extrememachineblock@0"
            ]
        },
        {
            "x": -5,
            "y": 7,
            "z": 7,
            "elements": [
                "contenttweaker:extrememachineblock@0"
            ]
        },
        {
            "x": -7,
            "y": 3,
            "z": 14,
            "elements": [
                "contenttweaker:arousal_building_block@0"
            ]
        },
        {
            "x": -7,
            "y": -2,
            "z": 14,
            "elements": [
                "contenttweaker:arousal_building_block@0"
            ]
        },
        {
            "x": -1,
            "y": 1,
            "z": 1,
            "elements": [
                "contenttweaker:extrememachineblock@0"
            ]
        },
        {
            "x": -7,
            "y": -5,
            "z": 7,
            "elements": [
                "contenttweaker:extrememachineblock@0"
            ]
        },
        {
            "x": 7,
            "y": -7,
            "z": 10,
            "elements": [
                "contenttweaker:arousal_building_block@0"
            ]
        },
        {
            "x": -4,
            "y": -7,
            "z": 0,
            "elements": [
                "contenttweaker:arousal_building_block@0"
            ]
        },
        {
            "x": -7,
            "y": -4,
            "z": 7,
            "elements": [
                "contenttweaker:extrememachineblock@0"
            ]
        },
        {
            "x": 3,
            "y": 7,
            "z": 0,
            "elements": [
                "contenttweaker:arousal_building_block@0"
            ]
        },
        {
            "x": -4,
            "y": 0,
            "z": 14,
            "elements": [
                "contenttweaker:extrememachineblock@0"
            ]
        },
        {
            "x": -7,
            "y": -5,
            "z": 14,
            "elements": [
                "contenttweaker:arousal_building_block@0"
            ]
        },
        {
            "x": -7,
            "y": -5,
            "z": 0,
            "elements": [
                "contenttweaker:arousal_building_block@0"
            ]
        },
        {
            "x": -6,
            "y": -6,
            "z": 13,
            "elements": [
                "contenttweaker:extrememachineblock@0"
            ]
        },
        {
            "x": -7,
            "y": -7,
            "z": 10,
            "elements": [
                "contenttweaker:arousal_building_block@0"
            ]
        },
        {
            "x": -7,
            "y": 0,
            "z": 8,
            "elements": [
                "contenttweaker:extrememachineblock@0"
            ]
        },
        {
            "x": 0,
            "y": -7,
            "z": 12,
            "elements": [
                "contenttweaker:extrememachineblock@0"
            ]
        },
        {
            "x": 0,
            "y": -1,
            "z": 1,
            "elements": [
                "contenttweaker:extrememachineblock@0"
            ]
        },
        {
            "x": -7,
            "y": -4,
            "z": 14,
            "elements": [
                "contenttweaker:arousal_building_block@0"
            ]
        },
        {
            "x": -2,
            "y": 7,
            "z": 7,
            "elements": [
                "contenttweaker:extrememachineblock@0"
            ]
        },
        {
            "x": 4,
            "y": 0,
            "z": 7,
            "elements": [
                "contenttweaker:extrememachineblock@0"
            ]
        },
        {
            "x": -7,
            "y": -3,
            "z": 7,
            "elements": [
                "contenttweaker:extrememachineblock@0"
            ]
        },
        {
            "x": -7,
            "y": -6,
            "z": 0,
            "elements": [
                "contenttweaker:arousal_building_block@0"
            ]
        },
        {
            "x": -7,
            "y": 5,
            "z": 14,
            "elements": [
                "contenttweaker:arousal_building_block@0"
            ]
        },
        {
            "x": -1,
            "y": -7,
            "z": 7,
            "elements": [
                "contenttweaker:extrememachineblock@0"
            ]
        },
        {
            "x": -7,
            "y": 7,
            "z": 13,
            "elements": [
                "contenttweaker:arousal_building_block@0"
            ]
        },
        {
            "x": -1,
            "y": -7,
            "z": 0,
            "elements": [
                "contenttweaker:arousal_building_block@0"
            ]
        },
        {
            "x": 0,
            "y": 7,
            "z": 0,
            "elements": [
                "contenttweaker:crystalmatrixforcefieldcontrolblock"
            ]
        },
        {
            "x": 1,
            "y": -7,
            "z": 14,
            "elements": [
                "contenttweaker:arousal_building_block@0"
            ]
        },
        {
            "x": -3,
            "y": 0,
            "z": 14,
            "elements": [
                "contenttweaker:extrememachineblock@0"
            ]
        },
        {
            "x": -7,
            "y": 0,
            "z": 1,
            "elements": [
                "contenttweaker:extrememachineblock@0"
            ]
        },
        {
            "x": 7,
            "y": 7,
            "z": 3,
            "elements": [
                "contenttweaker:arousal_building_block@0"
            ]
        },
        {
            "x": -7,
            "y": 6,
            "z": 7,
            "elements": [
                "contenttweaker:extrememachineblock@0"
            ]
        },
        {
            "x": -3,
            "y": 0,
            "z": 7,
            "elements": [
                "contenttweaker:extrememachineblock@0"
            ]
        },
        {
            "x": 1,
            "y": -1,
            "z": 1,
            "elements": [
                "contenttweaker:extrememachineblock@0"
            ]
        },
        {
            "x": 0,
            "y": -7,
            "z": 7,
            "elements": [
                "contenttweaker:crystalmatrixforcefieldcontrolblock"
            ]
        },
        {
            "x": -7,
            "y": 7,
            "z": 7,
            "elements": [
                "contenttweaker:crystalmatrixforcefieldcontrolblock"
            ]
        },
        {
            "x": 7,
            "y": 0,
            "z": 8,
            "elements": [
                "contenttweaker:extrememachineblock@0"
            ]
        },
        {
            "x": -1,
            "y": 1,
            "z": 6,
            "elements": [
                "contenttweaker:extrememachineblock@0"
            ]
        },
        {
            "x": -3,
            "y": 0,
            "z": 0,
            "elements": [
                "contenttweaker:extrememachineblock@0"
            ]
        },
        {
            "x": 1,
            "y": -1,
            "z": 8,
            "elements": [
                "contenttweaker:extrememachineblock@0"
            ]
        },
        {
            "x": -6,
            "y": 6,
            "z": 13,
            "elements": [
                "contenttweaker:extrememachineblock@0"
            ]
        },
        {
            "x": 1,
            "y": 1,
            "z": 8,
            "elements": [
                "contenttweaker:extrememachineblock@0"
            ]
        },
        {
            "x": 0,
            "y": 6,
            "z": 0,
            "elements": [
                "contenttweaker:extrememachineblock@0"
            ]
        },
        {
            "x": -2,
            "y": 0,
            "z": 7,
            "elements": [
                "contenttweaker:extrememachineblock@0"
            ]
        },
        {
            "x": 1,
            "y": -7,
            "z": 7,
            "elements": [
                "contenttweaker:extrememachineblock@0"
            ]
        },
        {
            "x": 0,
            "y": -7,
            "z": 13,
            "elements": [
                "contenttweaker:extrememachineblock@0"
            ]
        },
        {
            "x": 7,
            "y": 0,
            "z": 2,
            "elements": [
                "contenttweaker:extrememachineblock@0"
            ]
        },
        {
            "x": 0,
            "y": 5,
            "z": 0,
            "elements": [
                "contenttweaker:extrememachineblock@0"
            ]
        },
        {
            "x": -6,
            "y": 7,
            "z": 14,
            "elements": [
                "contenttweaker:arousal_building_block@0"
            ]
        },
        {
            "x": 7,
            "y": -7,
            "z": 1,
            "elements": [
                "contenttweaker:arousal_building_block@0"
            ]
        },
        {
            "x": 6,
            "y": 0,
            "z": 0,
            "elements": [
                "contenttweaker:extrememachineblock@0"
            ]
        },
        {
            "x": 0,
            "y": -7,
            "z": 6,
            "elements": [
                "contenttweaker:extrememachineblock@0"
            ]
        },
        {
            "x": 0,
            "y": 7,
            "z": 1,
            "elements": [
                "contenttweaker:extrememachineblock@0"
            ]
        },
        {
            "x": 0,
            "y": 4,
            "z": 0,
            "elements": [
                "contenttweaker:extrememachineblock@0"
            ]
        },
        {
            "x": -7,
            "y": 7,
            "z": 6,
            "elements": [
                "contenttweaker:arousal_building_block@0"
            ]
        },
        {
            "x": 0,
            "y": 2,
            "z": 14,
            "elements": [
                "contenttweaker:extrememachineblock@0"
            ]
        },
        {
            "x": -7,
            "y": 0,
            "z": 12,
            "elements": [
                "contenttweaker:extrememachineblock@0"
            ]
        },
        {
            "x": 0,
            "y": -3,
            "z": 7,
            "elements": [
                "contenttweaker:extrememachineblock@0"
            ]
        },
        {
            "x": 7,
            "y": -7,
            "z": 9,
            "elements": [
                "contenttweaker:arousal_building_block@0"
            ]
        },
        {
            "x": 7,
            "y": 0,
            "z": 5,
            "elements": [
                "contenttweaker:extrememachineblock@0"
            ]
        },
        {
            "x": 4,
            "y": -4,
            "z": 11,
            "elements": [
                "contenttweaker:extrememachineblock@0"
            ]
        },
        {
            "x": -7,
            "y": 7,
            "z": 12,
            "elements": [
                "contenttweaker:arousal_building_block@0"
            ]
        },
        {
            "x": 0,
            "y": 3,
            "z": 0,
            "elements": [
                "contenttweaker:extrememachineblock@0"
            ]
        },
        {
            "x": 0,
            "y": -4,
            "z": 7,
            "elements": [
                "contenttweaker:extrememachineblock@0"
            ]
        },
        {
            "x": 0,
            "y": 1,
            "z": 14,
            "elements": [
                "contenttweaker:extrememachineblock@0"
            ]
        },
        {
            "x": -2,
            "y": -7,
            "z": 7,
            "elements": [
                "contenttweaker:extrememachineblock@0"
            ]
        },
        {
            "x": -5,
            "y": 0,
            "z": 7,
            "elements": [
                "contenttweaker:extrememachineblock@0"
            ]
        },
        {
            "x": 5,
            "y": -7,
            "z": 0,
            "elements": [
                "contenttweaker:arousal_building_block@0"
            ]
        },
        {
            "x": -6,
            "y": 7,
            "z": 0,
            "elements": [
                "contenttweaker:arousal_building_block@0"
            ]
        },
        {
            "x": 0,
            "y": -6,
            "z": 7,
            "elements": [
                "contenttweaker:extrememachineblock@0"
            ]
        },
        {
            "x": -7,
            "y": 7,
            "z": 1,
            "elements": [
                "contenttweaker:arousal_building_block@0"
            ]
        },
        {
            "x": 3,
            "y": 0,
            "z": 0,
            "elements": [
                "contenttweaker:extrememachineblock@0"
            ]
        },
        {
            "x": -2,
            "y": -7,
            "z": 14,
            "elements": [
                "contenttweaker:arousal_building_block@0"
            ]
        },
        {
            "x": 0,
            "y": 2,
            "z": 0,
            "elements": [
                "contenttweaker:extrememachineblock@0"
            ]
        },
        {
            "x": 0,
            "y": 1,
            "z": 7,
            "elements": [
                "contenttweaker:extrememachineblock@0"
            ]
        },
        {
            "x": 0,
            "y": 0,
            "z": 14,
            "elements": [
                "contenttweaker:crystalmatrixforcefieldcontrolblock"
            ]
        },
        {
            "x": 0,
            "y": 1,
            "z": 0,
            "elements": [
                "modularmachinery:blockenergyinputhatch"
            ]
        },
        {
            "x": 3,
            "y": -7,
            "z": 7,
            "elements": [
                "contenttweaker:extrememachineblock@0"
            ]
        },
        {
            "x": -1,
            "y": -1,
            "z": 0,
            "elements": [
                "modularmachinery:blockfluidoutputhatch",
                "modularmachinery:blockmefluidoutputbus"
            ]
        },
        {
            "x": 0,
            "y": 0,
            "z": 7,
            "elements": [
                "contenttweaker:crystalmatrixforcefieldcontrolblock"
            ]
        },
        {
            "x": 0,
            "y": -5,
            "z": 7,
            "elements": [
                "contenttweaker:extrememachineblock@0"
            ]
        },
        {
            "x": -7,
            "y": 0,
            "z": 13,
            "elements": [
                "contenttweaker:extrememachineblock@0"
            ]
        },
        {
            "x": -6,
            "y": 7,
            "z": 7,
            "elements": [
                "contenttweaker:extrememachineblock@0"
            ]
        },
        {
            "x": -5,
            "y": -7,
            "z": 14,
            "elements": [
                "contenttweaker:arousal_building_block@0"
            ]
        },
        {
            "x": 7,
            "y": -7,
            "z": 8,
            "elements": [
                "contenttweaker:arousal_building_block@0"
            ]
        }
    ]}