{
    "registryname": "UniversalAssembly", 
    "localizedname": "寰宇装配机", 
    "requires-blueprint": false,
    "color": "FFDAB9",
    "modifiers": [
        {
            "elements": "contenttweaker:arkforcefieldcontrolblock",
            "x": 0,
            "y": 0,
            "z": 9,
            "description": "方舟之力铸就的矩阵让我们得以更加精细地控制力场，配方速度额外减免60%(更换最中心的寰宇力场控制矩阵即可)",
            "modifier": [
                {
                    "target": "modularmachinery:duration",
                    "io":"input",
                    "operation": 1,
                    "multiplier": 0.4
                }
            ]
        }
    ],
    "parts": [
        {
            "x": 0,
            "y": 0,
            "z": 0,
            "elements": [
                "modularmachinery:blockcontroller"
            ]
        },
        {
            "x": -9,
            "y": -1,
            "z": 6,
            "elements": [
                "contenttweaker:extrememachineblock@0"
            ]
        },
        {
            "x": -2,
            "y": 7,
            "z": 13,
            "elements": [
                "contenttweaker:extrememachineblock@0"
            ]
        },
        {
            "x": -4,
            "y": -8,
            "z": 11,
            "elements": [
                "contenttweaker:extrememachineblock@0"
            ]
        },
        {
            "x": -1,
            "y": 2,
            "z": 0,
            "elements": [
                "contenttweaker:extrememachineblock@0"
            ]
        },
        {
            "x": 0,
            "y": -2,
            "z": 0,
            "elements": [
                "contenttweaker:neutronforcefieldcontrolblock@0"
            ]
        },
        {
            "x": 1,
            "y": 9,
            "z": 12,
            "elements": [
                "contenttweaker:extrememachineblock@0"
            ]
        },
        {
            "x": 5,
            "y": 1,
            "z": 1,
            "elements": [
                "contenttweaker:extrememachineblock@0"
            ]
        },
        {
            "x": 3,
            "y": 2,
            "z": 17,
            "elements": [
                "contenttweaker:extrememachineblock@0"
            ]
        },
        {
            "x": 1,
            "y": -4,
            "z": 0,
            "elements": [
                "contenttweaker:extrememachineblock@0"
            ]
        },
        {
            "x": -8,
            "y": 5,
            "z": 10,
            "elements": [
                "contenttweaker:extrememachineblock@0"
            ]
        },
        {
            "x": 5,
            "y": 0,
            "z": 1,
            "elements": [
                "contenttweaker:extrememachineblock@0"
            ]
        },
        {
            "x": 1,
            "y": -9,
            "z": 10,
            "elements": [
                "contenttweaker:crystalmatrixforcefieldcontrolblock@0"
            ]
        },
        {
            "x": -2,
            "y": 8,
            "z": 13,
            "elements": [
                "contenttweaker:extrememachineblock@0"
            ]
        },
        {
            "x": 7,
            "y": 2,
            "z": 13,
            "elements": [
                "contenttweaker:extrememachineblock@0"
            ]
        },
        {
            "x": -6,
            "y": -2,
            "z": 15,
            "elements": [
                "contenttweaker:extrememachineblock@0"
            ]
        },
        {
            "x": 6,
            "y": -7,
            "z": 9,
            "elements": [
                "avaritia:block_resource@2"
            ]
        },
        {
            "x": -1,
            "y": 1,
            "z": 0,
            "elements": [
                "contenttweaker:crystalmatrixforcefieldcontrolblock@0"
            ]
        },
        {
            "x": 0,
            "y": -1,
            "z": 0,
            "elements": [
                "modularmachinery:blockoutputbus",
                "modularmachinery:blockmeitemoutputbus"
            ]
        },
        {
            "x": 4,
            "y": 1,
            "z": 18,
            "elements": [
                "contenttweaker:extrememachineblock@0"
            ]
        },
        {
            "x": 4,
            "y": -2,
            "z": 17,
            "elements": [
                "contenttweaker:extrememachineblock@0"
            ]
        },
        {
            "x": -4,
            "y": -7,
            "z": 11,
            "elements": [
                "contenttweaker:extrememachineblock@0"
            ]
        },
        {
            "x": 1,
            "y": -1,
            "z": 0,
            "elements": [
                "contenttweaker:crystalmatrixforcefieldcontrolblock@0"
            ]
        },
        {
            "x": 1,
            "y": -3,
            "z": 0,
            "elements": [
                "contenttweaker:extrememachineblock@0"
            ]
        },
        {
            "x": -9,
            "y": -4,
            "z": 9,
            "elements": [
                "contenttweaker:extrememachineblock@0"
            ]
        },
        {
            "x": 1,
            "y": -2,
            "z": 0,
            "elements": [
                "contenttweaker:extrememachineblock@0"
            ]
        },
        {
            "x": 2,
            "y": 4,
            "z": 17,
            "elements": [
                "contenttweaker:extrememachineblock@0"
            ]
        },
        {
            "x": 0,
            "y": -9,
            "z": 6,
            "elements": [
                "contenttweaker:extrememachineblock@0"
            ]
        },
        {
            "x": 1,
            "y": 0,
            "z": 0,
            "elements": [
                "modularmachinery:blockinputbus",
                "modularmachinery:blockmepatternprovider"
            ]
        },
        {
            "x": -2,
            "y": 1,
            "z": 0,
            "elements": [
                "contenttweaker:extrememachineblock@0"
            ]
        },
        {
            "x": 5,
            "y": -1,
            "z": 1,
            "elements": [
                "contenttweaker:extrememachineblock@0"
            ]
        },
        {
            "x": -2,
            "y": 2,
            "z": 0,
            "elements": [
                "contenttweaker:extrememachineblock@0"
            ]
        },
        {
            "x": 1,
            "y": -9,
            "z": 5,
            "elements": [
                "contenttweaker:extrememachineblock@0"
            ]
        },
        {
            "x": -3,
            "y": 8,
            "z": 7,
            "elements": [
                "contenttweaker:extrememachineblock@0"
            ]
        },
        {
            "x": 5,
            "y": 1,
            "z": 17,
            "elements": [
                "contenttweaker:extrememachineblock@0"
            ]
        },
        {
            "x": 0,
            "y": -9,
            "z": 10,
            "elements": [
                "contenttweaker:neutronforcefieldcontrolblock@0"
            ]
        },
        {
            "x": -7,
            "y": -2,
            "z": 4,
            "elements": [
                "contenttweaker:extrememachineblock@0"
            ]
        },
        {
            "x": 0,
            "y": 8,
            "z": 4,
            "elements": [
                "contenttweaker:extrememachineblock@0"
            ]
        },
        {
            "x": -7,
            "y": 6,
            "z": 10,
            "elements": [
                "avaritia:block_resource@2"
            ]
        },
        {
            "x": -6,
            "y": 2,
            "z": 15,
            "elements": [
                "contenttweaker:extrememachineblock@0"
            ]
        },
        {
            "x": 2,
            "y": 3,
            "z": 17,
            "elements": [
                "contenttweaker:extrememachineblock@0"
            ]
        },
        {
            "x": -8,
            "y": -2,
            "z": 12,
            "elements": [
                "contenttweaker:extrememachineblock@0"
            ]
        },
        {
            "x": 2,
            "y": -7,
            "z": 5,
            "elements": [
                "contenttweaker:extrememachineblock@0"
            ]
        },
        {
            "x": -1,
            "y": 4,
            "z": 0,
            "elements": [
                "contenttweaker:extrememachineblock@0"
            ]
        },
        {
            "x": 0,
            "y": -4,
            "z": 0,
            "elements": [
                "contenttweaker:extrememachineblock@0"
            ]
        },
        {
            "x": 9,
            "y": 0,
            "z": 7,
            "elements": [
                "contenttweaker:neutronforcefieldcontrolblock@0"
            ]
        },
        {
            "x": -6,
            "y": -6,
            "z": 7,
            "elements": [
                "contenttweaker:extrememachineblock@0"
            ]
        },
        {
            "x": 1,
            "y": -9,
            "z": 12,
            "elements": [
                "contenttweaker:extrememachineblock@0"
            ]
        },
        {
            "x": -7,
            "y": -4,
            "z": 11,
            "elements": [
                "contenttweaker:extrememachineblock@0"
            ]
        },
        {
            "x": 2,
            "y": 4,
            "z": 1,
            "elements": [
                "contenttweaker:extrememachineblock@0"
            ]
        },
        {
            "x": -1,
            "y": 3,
            "z": 0,
            "elements": [
                "contenttweaker:extrememachineblock@0"
            ]
        },
        {
            "x": 5,
            "y": 0,
            "z": 17,
            "elements": [
                "contenttweaker:extrememachineblock@0"
            ]
        },
        {
            "x": 0,
            "y": 7,
            "z": 3,
            "elements": [
                "avaritia:block_resource@2"
            ]
        },
        {
            "x": 0,
            "y": -3,
            "z": 0,
            "elements": [
                "contenttweaker:extrememachineblock@0"
            ]
        },
        {
            "x": 8,
            "y": -2,
            "z": 7,
            "elements": [
                "contenttweaker:extrememachineblock@0"
            ]
        },
        {
            "x": -3,
            "y": -8,
            "z": 7,
            "elements": [
                "contenttweaker:extrememachineblock@0"
            ]
        },
        {
            "x": 2,
            "y": -8,
            "z": 5,
            "elements": [
                "contenttweaker:extrememachineblock@0"
            ]
        },
        {
            "x": 2,
            "y": 2,
            "z": 17,
            "elements": [
                "contenttweaker:extrememachineblock@0"
            ]
        },
        {
            "x": 9,
            "y": 1,
            "z": 7,
            "elements": [
                "contenttweaker:extrememachineblock@0"
            ]
        },
        {
            "x": -2,
            "y": 9,
            "z": 9,
            "elements": [
                "contenttweaker:neutronforcefieldcontrolblock@0"
            ]
        },
        {
            "x": 5,
            "y": 8,
            "z": 8,
            "elements": [
                "contenttweaker:extrememachineblock@0"
            ]
        },
        {
            "x": 2,
            "y": 0,
            "z": 0,
            "elements": [
                "contenttweaker:neutronforcefieldcontrolblock@0"
            ]
        },
        {
            "x": 9,
            "y": 2,
            "z": 7,
            "elements": [
                "contenttweaker:extrememachineblock@0"
            ]
        },
        {
            "x": 0,
            "y": -9,
            "z": 5,
            "elements": [
                "contenttweaker:extrememachineblock@0"
            ]
        },
        {
            "x": 1,
            "y": -7,
            "z": 16,
            "elements": [
                "avaritia:block_resource@2"
            ]
        },
        {
            "x": 1,
            "y": 2,
            "z": 0,
            "elements": [
                "contenttweaker:extrememachineblock@0"
            ]
        },
        {
            "x": -2,
            "y": -2,
            "z": 0,
            "elements": [
                "contenttweaker:extrememachineblock@0"
            ]
        },
        {
            "x": -9,
            "y": 1,
            "z": 11,
            "elements": [
                "contenttweaker:extrememachineblock@0"
            ]
        },
        {
            "x": -2,
            "y": -5,
            "z": 16,
            "elements": [
                "contenttweaker:extrememachineblock@0"
            ]
        },
        {
            "x": -8,
            "y": 2,
            "z": 6,
            "elements": [
                "contenttweaker:extrememachineblock@0"
            ]
        },
        {
            "x": -2,
            "y": 7,
            "z": 14,
            "elements": [
                "contenttweaker:extrememachineblock@0"
            ]
        },
        {
            "x": 2,
            "y": -8,
            "z": 11,
            "elements": [
                "contenttweaker:extrememachineblock@0"
            ]
        },
        {
            "x": -1,
            "y": -9,
            "z": 10,
            "elements": [
                "contenttweaker:crystalmatrixforcefieldcontrolblock@0"
            ]
        },
        {
            "x": 1,
            "y": 1,
            "z": 0,
            "elements": [
                "contenttweaker:crystalmatrixforcefieldcontrolblock@0"
            ]
        },
        {
            "x": -2,
            "y": -1,
            "z": 0,
            "elements": [
                "contenttweaker:extrememachineblock@0"
            ]
        },
        {
            "x": -5,
            "y": 7,
            "z": 11,
            "elements": [
                "contenttweaker:extrememachineblock@0"
            ]
        },
        {
            "x": -5,
            "y": -8,
            "z": 9,
            "elements": [
                "contenttweaker:extrememachineblock@0"
            ]
        },
        {
            "x": -9,
            "y": 0,
            "z": 11,
            "elements": [
                "contenttweaker:neutronforcefieldcontrolblock@0"
            ]
        },
        {
            "x": -6,
            "y": -7,
            "z": 7,
            "elements": [
                "contenttweaker:extrememachineblock@0"
            ]
        },
        {
            "x": 2,
            "y": 9,
            "z": 8,
            "elements": [
                "contenttweaker:extrememachineblock@0"
            ]
        },
        {
            "x": -7,
            "y": -5,
            "z": 11,
            "elements": [
                "contenttweaker:extrememachineblock@0"
            ]
        },
        {
            "x": -1,
            "y": 0,
            "z": 0,
            "elements": [
                "modularmachinery:blockfluidinputhatch",
                "modularmachinery:blockmepatternprovider"
            ]
        },
        {
            "x": 1,
            "y": 7,
            "z": 16,
            "elements": [
                "avaritia:block_resource@2"
            ]
        },
        {
            "x": -7,
            "y": 0,
            "z": 15,
            "elements": [
                "avaritia:block_resource@2"
            ]
        },
        {
            "x": 10,
            "y": 10,
            "z": 19,
            "elements": [
                "minecraft:air@0"
            ]
        },
        {
            "x": -8,
            "y": -5,
            "z": 9,
            "elements": [
                "contenttweaker:extrememachineblock@0"
            ]
        },
        {
            "x": 2,
            "y": -9,
            "z": 10,
            "elements": [
                "contenttweaker:extrememachineblock@0"
            ]
        },
        {
            "x": -7,
            "y": 7,
            "z": 10,
            "elements": [
                "avaritia:block_resource@2"
            ]
        },
        {
            "x": -9,
            "y": -3,
            "z": 9,
            "elements": [
                "contenttweaker:extrememachineblock@0"
            ]
        },
        {
            "x": 1,
            "y": 4,
            "z": 0,
            "elements": [
                "contenttweaker:extrememachineblock@0"
            ]
        },
        {
            "x": 1,
            "y": 9,
            "z": 13,
            "elements": [
                "contenttweaker:extrememachineblock@0"
            ]
        },
        {
            "x": 2,
            "y": 7,
            "z": 4,
            "elements": [
                "contenttweaker:extrememachineblock@0"
            ]
        },
        {
            "x": -7,
            "y": 1,
            "z": 15,
            "elements": [
                "avaritia:block_resource@2"
            ]
        },
        {
            "x": 9,
            "y": -4,
            "z": 8,
            "elements": [
                "contenttweaker:extrememachineblock@0"
            ]
        },
        {
            "x": 1,
            "y": 6,
            "z": 16,
            "elements": [
                "avaritia:block_resource@2"
            ]
        },
        {
            "x": -9,
            "y": 2,
            "z": 11,
            "elements": [
                "contenttweaker:extrememachineblock@0"
            ]
        },
        {
            "x": -9,
            "y": -2,
            "z": 9,
            "elements": [
                "contenttweaker:neutronforcefieldcontrolblock@0"
            ]
        },
        {
            "x": 1,
            "y": 3,
            "z": 0,
            "elements": [
                "contenttweaker:extrememachineblock@0"
            ]
        },
        {
            "x": 3,
            "y": 8,
            "z": 7,
            "elements": [
                "contenttweaker:extrememachineblock@0"
            ]
        },
        {
            "x": 6,
            "y": 6,
            "z": 7,
            "elements": [
                "contenttweaker:extrememachineblock@0"
            ]
        },
        {
            "x": -2,
            "y": -4,
            "z": 16,
            "elements": [
                "contenttweaker:extrememachineblock@0"
            ]
        },
        {
            "x": -4,
            "y": 2,
            "z": 16,
            "elements": [
                "contenttweaker:extrememachineblock@0"
            ]
        },
        {
            "x": -7,
            "y": -1,
            "z": 15,
            "elements": [
                "avaritia:block_resource@2"
            ]
        },
        {
            "x": -6,
            "y": -2,
            "z": 3,
            "elements": [
                "contenttweaker:extrememachineblock@0"
            ]
        },
        {
            "x": -9,
            "y": 3,
            "z": 10,
            "elements": [
                "contenttweaker:extrememachineblock@0"
            ]
        },
        {
            "x": 4,
            "y": 0,
            "z": 0,
            "elements": [
                "contenttweaker:extrememachineblock@0"
            ]
        },
        {
            "x": -8,
            "y": 3,
            "z": 11,
            "elements": [
                "contenttweaker:extrememachineblock@0"
            ]
        },
        {
            "x": 9,
            "y": -3,
            "z": 8,
            "elements": [
                "contenttweaker:extrememachineblock@0"
            ]
        },
        {
            "x": 3,
            "y": 9,
            "z": 8,
            "elements": [
                "contenttweaker:extrememachineblock@0"
            ]
        },
        {
            "x": -1,
            "y": -7,
            "z": 15,
            "elements": [
                "avaritia:block_resource@2"
            ]
        },
        {
            "x": 3,
            "y": -1,
            "z": 0,
            "elements": [
                "contenttweaker:extrememachineblock@0"
            ]
        },
        {
            "x": -9,
            "y": 4,
            "z": 10,
            "elements": [
                "contenttweaker:extrememachineblock@0"
            ]
        },
        {
            "x": 0,
            "y": 9,
            "z": 7,
            "elements": [
                "contenttweaker:neutronforcefieldcontrolblock@0"
            ]
        },
        {
            "x": -4,
            "y": 1,
            "z": 0,
            "elements": [
                "contenttweaker:extrememachineblock@0"
            ]
        },
        {
            "x": 9,
            "y": 4,
            "z": 8,
            "elements": [
                "contenttweaker:extrememachineblock@0"
            ]
        },
        {
            "x": -2,
            "y": 8,
            "z": 12,
            "elements": [
                "contenttweaker:extrememachineblock@0"
            ]
        },
        {
            "x": 4,
            "y": -9,
            "z": 10,
            "elements": [
                "contenttweaker:extrememachineblock@0"
            ]
        },
        {
            "x": 9,
            "y": 3,
            "z": 8,
            "elements": [
                "contenttweaker:extrememachineblock@0"
            ]
        },
        {
            "x": -7,
            "y": 2,
            "z": 5,
            "elements": [
                "contenttweaker:extrememachineblock@0"
            ]
        },
        {
            "x": -9,
            "y": 2,
            "z": 10,
            "elements": [
                "contenttweaker:extrememachineblock@0"
            ]
        },
        {
            "x": -8,
            "y": 2,
            "z": 11,
            "elements": [
                "contenttweaker:extrememachineblock@0"
            ]
        },
        {
            "x": 1,
            "y": -9,
            "z": 11,
            "elements": [
                "contenttweaker:extrememachineblock@0"
            ]
        },
        {
            "x": 0,
            "y": -8,
            "z": 14,
            "elements": [
                "contenttweaker:extrememachineblock@0"
            ]
        },
        {
            "x": 9,
            "y": -2,
            "z": 8,
            "elements": [
                "contenttweaker:extrememachineblock@0"
            ]
        },
        {
            "x": 1,
            "y": 9,
            "z": 9,
            "elements": [
                "contenttweaker:neutronforcefieldcontrolblock@0"
            ]
        },
        {
            "x": 2,
            "y": -2,
            "z": 18,
            "elements": [
                "contenttweaker:extrememachineblock@0"
            ]
        },
        {
            "x": -2,
            "y": 8,
            "z": 6,
            "elements": [
                "contenttweaker:extrememachineblock@0"
            ]
        },
        {
            "x": 0,
            "y": 1,
            "z": 18,
            "elements": [
                "contenttweaker:neutronforcefieldcontrolblock@0"
            ]
        },
        {
            "x": -2,
            "y": -7,
            "z": 5,
            "elements": [
                "contenttweaker:extrememachineblock@0"
            ]
        },
        {
            "x": -6,
            "y": 6,
            "z": 11,
            "elements": [
                "contenttweaker:extrememachineblock@0"
            ]
        },
        {
            "x": 2,
            "y": -1,
            "z": 18,
            "elements": [
                "contenttweaker:extrememachineblock@0"
            ]
        },
        {
            "x": 9,
            "y": 2,
            "z": 8,
            "elements": [
                "contenttweaker:extrememachineblock@0"
            ]
        },
        {
            "x": 2,
            "y": 2,
            "z": 0,
            "elements": [
                "contenttweaker:extrememachineblock@0"
            ]
        },
        {
            "x": -9,
            "y": 0,
            "z": 10,
            "elements": [
                "contenttweaker:neutronforcefieldcontrolblock@0"
            ]
        },
        {
            "x": 9,
            "y": 1,
            "z": 8,
            "elements": [
                "contenttweaker:crystalmatrixforcefieldcontrolblock@0"
            ]
        },
        {
            "x": 0,
            "y": 4,
            "z": 18,
            "elements": [
                "contenttweaker:extrememachineblock@0"
            ]
        },
        {
            "x": 9,
            "y": -1,
            "z": 8,
            "elements": [
                "contenttweaker:crystalmatrixforcefieldcontrolblock@0"
            ]
        },
        {
            "x": 9,
            "y": -4,
            "z": 9,
            "elements": [
                "contenttweaker:extrememachineblock@0"
            ]
        },
        {
            "x": 4,
            "y": -1,
            "z": 0,
            "elements": [
                "contenttweaker:extrememachineblock@0"
            ]
        },
        {
            "x": -9,
            "y": -11,
            "z": -1,
            "elements": [
                "minecraft:air@0"
            ]
        },
        {
            "x": 3,
            "y": 0,
            "z": 18,
            "elements": [
                "contenttweaker:extrememachineblock@0"
            ]
        },
        {
            "x": -2,
            "y": -8,
            "z": 5,
            "elements": [
                "contenttweaker:extrememachineblock@0"
            ]
        },
        {
            "x": 0,
            "y": 2,
            "z": 18,
            "elements": [
                "contenttweaker:neutronforcefieldcontrolblock@0"
            ]
        },
        {
            "x": 2,
            "y": 1,
            "z": 0,
            "elements": [
                "contenttweaker:extrememachineblock@0"
            ]
        },
        {
            "x": -3,
            "y": -1,
            "z": 0,
            "elements": [
                "contenttweaker:extrememachineblock@0"
            ]
        },
        {
            "x": 6,
            "y": 7,
            "z": 8,
            "elements": [
                "avaritia:block_resource@2"
            ]
        },
        {
            "x": -5,
            "y": -7,
            "z": 11,
            "elements": [
                "contenttweaker:extrememachineblock@0"
            ]
        },
        {
            "x": 6,
            "y": -6,
            "z": 7,
            "elements": [
                "contenttweaker:extrememachineblock@0"
            ]
        },
        {
            "x": 0,
            "y": 3,
            "z": 18,
            "elements": [
                "contenttweaker:extrememachineblock@0"
            ]
        },
        {
            "x": -9,
            "y": 1,
            "z": 10,
            "elements": [
                "contenttweaker:crystalmatrixforcefieldcontrolblock@0"
            ]
        },
        {
            "x": 1,
            "y": -6,
            "z": 16,
            "elements": [
                "avaritia:block_resource@2"
            ]
        },
        {
            "x": -5,
            "y": -8,
            "z": 10,
            "elements": [
                "contenttweaker:extrememachineblock@0"
            ]
        },
        {
            "x": -2,
            "y": 0,
            "z": 0,
            "elements": [
                "contenttweaker:neutronforcefieldcontrolblock@0"
            ]
        },
        {
            "x": 8,
            "y": -1,
            "z": 4,
            "elements": [
                "contenttweaker:extrememachineblock@0"
            ]
        },
        {
            "x": 8,
            "y": -3,
            "z": 7,
            "elements": [
                "contenttweaker:extrememachineblock@0"
            ]
        },
        {
            "x": 3,
            "y": 1,
            "z": 18,
            "elements": [
                "contenttweaker:extrememachineblock@0"
            ]
        },
        {
            "x": -9,
            "y": -2,
            "z": 7,
            "elements": [
                "contenttweaker:extrememachineblock@0"
            ]
        },
        {
            "x": 6,
            "y": 2,
            "z": 3,
            "elements": [
                "contenttweaker:extrememachineblock@0"
            ]
        },
        {
            "x": -9,
            "y": -1,
            "z": 7,
            "elements": [
                "contenttweaker:extrememachineblock@0"
            ]
        },
        {
            "x": 0,
            "y": 9,
            "z": 6,
            "elements": [
                "contenttweaker:extrememachineblock@0"
            ]
        },
        {
            "x": -2,
            "y": -8,
            "z": 11,
            "elements": [
                "contenttweaker:extrememachineblock@0"
            ]
        },
        {
            "x": -6,
            "y": 7,
            "z": 10,
            "elements": [
                "avaritia:block_resource@2"
            ]
        },
        {
            "x": -8,
            "y": 4,
            "z": 11,
            "elements": [
                "contenttweaker:extrememachineblock@0"
            ]
        },
        {
            "x": 8,
            "y": -4,
            "z": 7,
            "elements": [
                "contenttweaker:extrememachineblock@0"
            ]
        },
        {
            "x": -8,
            "y": 1,
            "z": 14,
            "elements": [
                "contenttweaker:extrememachineblock@0"
            ]
        },
        {
            "x": -5,
            "y": 8,
            "z": 9,
            "elements": [
                "contenttweaker:extrememachineblock@0"
            ]
        },
        {
            "x": -1,
            "y": -9,
            "z": 11,
            "elements": [
                "contenttweaker:extrememachineblock@0"
            ]
        },
        {
            "x": 9,
            "y": -2,
            "z": 9,
            "elements": [
                "contenttweaker:neutronforcefieldcontrolblock@0"
            ]
        },
        {
            "x": -8,
            "y": -5,
            "z": 10,
            "elements": [
                "contenttweaker:extrememachineblock@0"
            ]
        },
        {
            "x": -4,
            "y": -2,
            "z": 1,
            "elements": [
                "contenttweaker:extrememachineblock@0"
            ]
        },
        {
            "x": 9,
            "y": -3,
            "z": 9,
            "elements": [
                "contenttweaker:extrememachineblock@0"
            ]
        },
        {
            "x": 8,
            "y": 5,
            "z": 8,
            "elements": [
                "contenttweaker:extrememachineblock@0"
            ]
        },
        {
            "x": -8,
            "y": -2,
            "z": 5,
            "elements": [
                "contenttweaker:extrememachineblock@0"
            ]
        },
        {
            "x": -1,
            "y": -5,
            "z": 1,
            "elements": [
                "contenttweaker:extrememachineblock@0"
            ]
        },
        {
            "x": -3,
            "y": -8,
            "z": 11,
            "elements": [
                "contenttweaker:extrememachineblock@0"
            ]
        },
        {
            "x": 5,
            "y": -1,
            "z": 17,
            "elements": [
                "contenttweaker:extrememachineblock@0"
            ]
        },
        {
            "x": 9,
            "y": -1,
            "z": 9,
            "elements": [
                "contenttweaker:neutronforcefieldcontrolblock@0"
            ]
        },
        {
            "x": 1,
            "y": 9,
            "z": 6,
            "elements": [
                "contenttweaker:extrememachineblock@0"
            ]
        },
        {
            "x": -2,
            "y": 5,
            "z": 16,
            "elements": [
                "contenttweaker:extrememachineblock@0"
            ]
        },
        {
            "x": -2,
            "y": -9,
            "z": 10,
            "elements": [
                "contenttweaker:extrememachineblock@0"
            ]
        },
        {
            "x": 0,
            "y": -9,
            "z": 11,
            "elements": [
                "contenttweaker:neutronforcefieldcontrolblock@0"
            ]
        },
        {
            "x": -2,
            "y": 4,
            "z": 16,
            "elements": [
                "contenttweaker:extrememachineblock@0"
            ]
        },
        {
            "x": -8,
            "y": 0,
            "z": 14,
            "elements": [
                "contenttweaker:extrememachineblock@0"
            ]
        },
        {
            "x": -3,
            "y": 9,
            "z": 10,
            "elements": [
                "contenttweaker:extrememachineblock@0"
            ]
        },
        {
            "x": -1,
            "y": -4,
            "z": 18,
            "elements": [
                "contenttweaker:extrememachineblock@0"
            ]
        },
        {
            "x": 1,
            "y": -1,
            "z": 18,
            "elements": [
                "contenttweaker:crystalmatrixforcefieldcontrolblock@0"
            ]
        },
        {
            "x": 1,
            "y": -9,
            "z": 9,
            "elements": [
                "contenttweaker:neutronforcefieldcontrolblock@0"
            ]
        },
        {
            "x": -2,
            "y": 6,
            "z": 3,
            "elements": [
                "contenttweaker:extrememachineblock@0"
            ]
        },
        {
            "x": 2,
            "y": 8,
            "z": 12,
            "elements": [
                "contenttweaker:extrememachineblock@0"
            ]
        },
        {
            "x": -8,
            "y": 5,
            "z": 9,
            "elements": [
                "contenttweaker:extrememachineblock@0"
            ]
        },
        {
            "x": 0,
            "y": 9,
            "z": 11,
            "elements": [
                "contenttweaker:neutronforcefieldcontrolblock@0"
            ]
        },
        {
            "x": -1,
            "y": 4,
            "z": 18,
            "elements": [
                "contenttweaker:extrememachineblock@0"
            ]
        },
        {
            "x": 5,
            "y": 7,
            "z": 7,
            "elements": [
                "contenttweaker:extrememachineblock@0"
            ]
        },
        {
            "x": 0,
            "y": 9,
            "z": 5,
            "elements": [
                "contenttweaker:extrememachineblock@0"
            ]
        },
        {
            "x": -7,
            "y": 7,
            "z": 9,
            "elements": [
                "avaritia:block_resource@2"
            ]
        },
        {
            "x": -4,
            "y": -2,
            "z": 17,
            "elements": [
                "contenttweaker:extrememachineblock@0"
            ]
        },
        {
            "x": 6,
            "y": -2,
            "z": 3,
            "elements": [
                "contenttweaker:extrememachineblock@0"
            ]
        },
        {
            "x": 9,
            "y": -2,
            "z": 7,
            "elements": [
                "contenttweaker:extrememachineblock@0"
            ]
        },
        {
            "x": -1,
            "y": -8,
            "z": 4,
            "elements": [
                "contenttweaker:extrememachineblock@0"
            ]
        },
        {
            "x": 2,
            "y": 0,
            "z": 18,
            "elements": [
                "contenttweaker:neutronforcefieldcontrolblock@0"
            ]
        },
        {
            "x": 4,
            "y": 8,
            "z": 7,
            "elements": [
                "contenttweaker:extrememachineblock@0"
            ]
        },
        {
            "x": 0,
            "y": -6,
            "z": 16,
            "elements": [
                "avaritia:block_resource@2"
            ]
        },
        {
            "x": 8,
            "y": -1,
            "z": 14,
            "elements": [
                "contenttweaker:extrememachineblock@0"
            ]
        },
        {
            "x": 4,
            "y": -2,
            "z": 2,
            "elements": [
                "contenttweaker:extrememachineblock@0"
            ]
        },
        {
            "x": -1,
            "y": 3,
            "z": 18,
            "elements": [
                "contenttweaker:extrememachineblock@0"
            ]
        },
        {
            "x": -2,
            "y": -2,
            "z": 18,
            "elements": [
                "contenttweaker:extrememachineblock@0"
            ]
        },
        {
            "x": -4,
            "y": 1,
            "z": 18,
            "elements": [
                "contenttweaker:extrememachineblock@0"
            ]
        },
        {
            "x": 7,
            "y": 4,
            "z": 7,
            "elements": [
                "contenttweaker:extrememachineblock@0"
            ]
        },
        {
            "x": 8,
            "y": 1,
            "z": 14,
            "elements": [
                "contenttweaker:extrememachineblock@0"
            ]
        },
        {
            "x": -1,
            "y": 7,
            "z": 15,
            "elements": [
                "avaritia:block_resource@2"
            ]
        },
        {
            "x": 0,
            "y": -9,
            "z": 9,
            "elements": [
                "contenttweaker:fallenstarforcefieldcontrolblock@0"
            ]
        },
        {
            "x": -2,
            "y": 9,
            "z": 10,
            "elements": [
                "contenttweaker:extrememachineblock@0"
            ]
        },
        {
            "x": -2,
            "y": -1,
            "z": 18,
            "elements": [
                "contenttweaker:extrememachineblock@0"
            ]
        },
        {
            "x": -1,
            "y": 6,
            "z": 2,
            "elements": [
                "avaritia:block_resource@2"
            ]
        },
        {
            "x": 4,
            "y": 7,
            "z": 7,
            "elements": [
                "contenttweaker:extrememachineblock@0"
            ]
        },
        {
            "x": 1,
            "y": -3,
            "z": 18,
            "elements": [
                "contenttweaker:extrememachineblock@0"
            ]
        },
        {
            "x": 7,
            "y": 5,
            "z": 7,
            "elements": [
                "contenttweaker:extrememachineblock@0"
            ]
        },
        {
            "x": -6,
            "y": -1,
            "z": 16,
            "elements": [
                "avaritia:block_resource@2"
            ]
        },
        {
            "x": -7,
            "y": 6,
            "z": 9,
            "elements": [
                "avaritia:block_resource@2"
            ]
        },
        {
            "x": -1,
            "y": 0,
            "z": 18,
            "elements": [
                "contenttweaker:neutronforcefieldcontrolblock@0"
            ]
        },
        {
            "x": -1,
            "y": 7,
            "z": 2,
            "elements": [
                "avaritia:block_resource@2"
            ]
        },
        {
            "x": -6,
            "y": 7,
            "z": 8,
            "elements": [
                "avaritia:block_resource@2"
            ]
        },
        {
            "x": 3,
            "y": 8,
            "z": 11,
            "elements": [
                "contenttweaker:extrememachineblock@0"
            ]
        },
        {
            "x": 1,
            "y": -2,
            "z": 18,
            "elements": [
                "contenttweaker:extrememachineblock@0"
            ]
        },
        {
            "x": 6,
            "y": 6,
            "z": 11,
            "elements": [
                "contenttweaker:extrememachineblock@0"
            ]
        },
        {
            "x": 8,
            "y": -5,
            "z": 8,
            "elements": [
                "contenttweaker:extrememachineblock@0"
            ]
        },
        {
            "x": 6,
            "y": -7,
            "z": 10,
            "elements": [
                "avaritia:block_resource@2"
            ]
        },
        {
            "x": -1,
            "y": -7,
            "z": 3,
            "elements": [
                "avaritia:block_resource@2"
            ]
        },
        {
            "x": 5,
            "y": -8,
            "z": 8,
            "elements": [
                "contenttweaker:extrememachineblock@0"
            ]
        },
        {
            "x": -9,
            "y": 4,
            "z": 8,
            "elements": [
                "contenttweaker:extrememachineblock@0"
            ]
        },
        {
            "x": 9,
            "y": 0,
            "z": 6,
            "elements": [
                "contenttweaker:extrememachineblock@0"
            ]
        },
        {
            "x": -9,
            "y": 3,
            "z": 8,
            "elements": [
                "contenttweaker:extrememachineblock@0"
            ]
        },
        {
            "x": 3,
            "y": -9,
            "z": 9,
            "elements": [
                "contenttweaker:extrememachineblock@0"
            ]
        },
        {
            "x": -1,
            "y": 1,
            "z": 18,
            "elements": [
                "contenttweaker:crystalmatrixforcefieldcontrolblock@0"
            ]
        },
        {
            "x": 8,
            "y": -3,
            "z": 11,
            "elements": [
                "contenttweaker:extrememachineblock@0"
            ]
        },
        {
            "x": -9,
            "y": -2,
            "z": 11,
            "elements": [
                "contenttweaker:extrememachineblock@0"
            ]
        },
        {
            "x": -1,
            "y": -1,
            "z": 18,
            "elements": [
                "contenttweaker:crystalmatrixforcefieldcontrolblock@0"
            ]
        },
        {
            "x": -1,
            "y": -5,
            "z": 17,
            "elements": [
                "contenttweaker:extrememachineblock@0"
            ]
        },
        {
            "x": 2,
            "y": 4,
            "z": 2,
            "elements": [
                "contenttweaker:extrememachineblock@0"
            ]
        },
        {
            "x": -7,
            "y": -1,
            "z": 3,
            "elements": [
                "avaritia:block_resource@2"
            ]
        },
        {
            "x": 7,
            "y": -2,
            "z": 5,
            "elements": [
                "contenttweaker:extrememachineblock@0"
            ]
        },
        {
            "x": -9,
            "y": -1,
            "z": 11,
            "elements": [
                "contenttweaker:extrememachineblock@0"
            ]
        },
        {
            "x": 0,
            "y": 9,
            "z": 13,
            "elements": [
                "contenttweaker:extrememachineblock@0"
            ]
        },
        {
            "x": 1,
            "y": -8,
            "z": 4,
            "elements": [
                "contenttweaker:extrememachineblock@0"
            ]
        },
        {
            "x": 7,
            "y": 2,
            "z": 14,
            "elements": [
                "contenttweaker:extrememachineblock@0"
            ]
        },
        {
            "x": 9,
            "y": -1,
            "z": 6,
            "elements": [
                "contenttweaker:extrememachineblock@0"
            ]
        },
        {
            "x": -1,
            "y": 2,
            "z": 18,
            "elements": [
                "contenttweaker:extrememachineblock@0"
            ]
        },
        {
            "x": 0,
            "y": 0,
            "z": 18,
            "elements": [
                "contenttweaker:fallenstarforcefieldcontrolblock@0"
            ]
        },
        {
            "x": 9,
            "y": 1,
            "z": 6,
            "elements": [
                "contenttweaker:extrememachineblock@0"
            ]
        },
        {
            "x": 5,
            "y": 2,
            "z": 2,
            "elements": [
                "contenttweaker:extrememachineblock@0"
            ]
        },
        {
            "x": -6,
            "y": -7,
            "z": 11,
            "elements": [
                "contenttweaker:extrememachineblock@0"
            ]
        },
        {
            "x": 8,
            "y": -4,
            "z": 11,
            "elements": [
                "contenttweaker:extrememachineblock@0"
            ]
        },
        {
            "x": -9,
            "y": 1,
            "z": 8,
            "elements": [
                "contenttweaker:crystalmatrixforcefieldcontrolblock@0"
            ]
        },
        {
            "x": 9,
            "y": 0,
            "z": 8,
            "elements": [
                "contenttweaker:neutronforcefieldcontrolblock@0"
            ]
        },
        {
            "x": 1,
            "y": -4,
            "z": 18,
            "elements": [
                "contenttweaker:extrememachineblock@0"
            ]
        },
        {
            "x": 2,
            "y": -7,
            "z": 4,
            "elements": [
                "contenttweaker:extrememachineblock@0"
            ]
        },
        {
            "x": 8,
            "y": 2,
            "z": 12,
            "elements": [
                "contenttweaker:extrememachineblock@0"
            ]
        },
        {
            "x": 8,
            "y": 2,
            "z": 5,
            "elements": [
                "contenttweaker:extrememachineblock@0"
            ]
        },
        {
            "x": -2,
            "y": -9,
            "z": 9,
            "elements": [
                "contenttweaker:neutronforcefieldcontrolblock@0"
            ]
        },
        {
            "x": 7,
            "y": -2,
            "z": 13,
            "elements": [
                "contenttweaker:extrememachineblock@0"
            ]
        },
        {
            "x": 0,
            "y": 9,
            "z": 10,
            "elements": [
                "contenttweaker:neutronforcefieldcontrolblock@0"
            ]
        },
        {
            "x": -6,
            "y": -6,
            "z": 11,
            "elements": [
                "contenttweaker:extrememachineblock@0"
            ]
        },
        {
            "x": -5,
            "y": 2,
            "z": 16,
            "elements": [
                "contenttweaker:extrememachineblock@0"
            ]
        },
        {
            "x": 0,
            "y": -7,
            "z": 16,
            "elements": [
                "avaritia:block_resource@2"
            ]
        },
        {
            "x": -1,
            "y": 9,
            "z": 5,
            "elements": [
                "contenttweaker:extrememachineblock@0"
            ]
        },
        {
            "x": 2,
            "y": 7,
            "z": 5,
            "elements": [
                "contenttweaker:extrememachineblock@0"
            ]
        },
        {
            "x": -6,
            "y": 7,
            "z": 9,
            "elements": [
                "avaritia:block_resource@2"
            ]
        },
        {
            "x": 8,
            "y": -2,
            "z": 6,
            "elements": [
                "contenttweaker:extrememachineblock@0"
            ]
        },
        {
            "x": -1,
            "y": -3,
            "z": 18,
            "elements": [
                "contenttweaker:extrememachineblock@0"
            ]
        },
        {
            "x": -6,
            "y": 2,
            "z": 3,
            "elements": [
                "contenttweaker:extrememachineblock@0"
            ]
        },
        {
            "x": -9,
            "y": 2,
            "z": 8,
            "elements": [
                "contenttweaker:extrememachineblock@0"
            ]
        },
        {
            "x": 4,
            "y": 1,
            "z": 0,
            "elements": [
                "contenttweaker:extrememachineblock@0"
            ]
        },
        {
            "x": 9,
            "y": -1,
            "z": 7,
            "elements": [
                "contenttweaker:extrememachineblock@0"
            ]
        },
        {
            "x": 2,
            "y": 8,
            "z": 5,
            "elements": [
                "contenttweaker:extrememachineblock@0"
            ]
        },
        {
            "x": 2,
            "y": 5,
            "z": 2,
            "elements": [
                "contenttweaker:extrememachineblock@0"
            ]
        },
        {
            "x": -1,
            "y": 9,
            "z": 12,
            "elements": [
                "contenttweaker:extrememachineblock@0"
            ]
        },
        {
            "x": -4,
            "y": 0,
            "z": 0,
            "elements": [
                "contenttweaker:extrememachineblock@0"
            ]
        },
        {
            "x": -8,
            "y": 0,
            "z": 4,
            "elements": [
                "contenttweaker:extrememachineblock@0"
            ]
        },
        {
            "x": -1,
            "y": -2,
            "z": 18,
            "elements": [
                "contenttweaker:extrememachineblock@0"
            ]
        },
        {
            "x": -3,
            "y": -9,
            "z": 9,
            "elements": [
                "contenttweaker:extrememachineblock@0"
            ]
        },
        {
            "x": -1,
            "y": 8,
            "z": 4,
            "elements": [
                "contenttweaker:extrememachineblock@0"
            ]
        },
        {
            "x": 8,
            "y": -2,
            "z": 13,
            "elements": [
                "contenttweaker:extrememachineblock@0"
            ]
        },
        {
            "x": -6,
            "y": -7,
            "z": 9,
            "elements": [
                "avaritia:block_resource@2"
            ]
        },
        {
            "x": -9,
            "y": -4,
            "z": 10,
            "elements": [
                "contenttweaker:extrememachineblock@0"
            ]
        },
        {
            "x": -1,
            "y": -7,
            "z": 16,
            "elements": [
                "avaritia:block_resource@2"
            ]
        },
        {
            "x": -6,
            "y": -7,
            "z": 10,
            "elements": [
                "avaritia:block_resource@2"
            ]
        },
        {
            "x": -3,
            "y": -9,
            "z": 10,
            "elements": [
                "contenttweaker:extrememachineblock@0"
            ]
        },
        {
            "x": -9,
            "y": -3,
            "z": 10,
            "elements": [
                "contenttweaker:extrememachineblock@0"
            ]
        },
        {
            "x": 0,
            "y": 9,
            "z": 8,
            "elements": [
                "contenttweaker:neutronforcefieldcontrolblock@0"
            ]
        },
        {
            "x": 0,
            "y": -7,
            "z": 3,
            "elements": [
                "avaritia:block_resource@2"
            ]
        },
        {
            "x": 0,
            "y": 8,
            "z": 14,
            "elements": [
                "contenttweaker:extrememachineblock@0"
            ]
        },
        {
            "x": 2,
            "y": 7,
            "z": 13,
            "elements": [
                "contenttweaker:extrememachineblock@0"
            ]
        },
        {
            "x": -6,
            "y": 0,
            "z": 16,
            "elements": [
                "avaritia:block_resource@2"
            ]
        },
        {
            "x": -9,
            "y": -2,
            "z": 10,
            "elements": [
                "contenttweaker:extrememachineblock@0"
            ]
        },
        {
            "x": 8,
            "y": 2,
            "z": 13,
            "elements": [
                "contenttweaker:extrememachineblock@0"
            ]
        },
        {
            "x": 3,
            "y": -8,
            "z": 11,
            "elements": [
                "contenttweaker:extrememachineblock@0"
            ]
        },
        {
            "x": 7,
            "y": -1,
            "z": 2,
            "elements": [
                "avaritia:block_resource@2"
            ]
        },
        {
            "x": -7,
            "y": -7,
            "z": 8,
            "elements": [
                "avaritia:block_resource@2"
            ]
        },
        {
            "x": 4,
            "y": -9,
            "z": 9,
            "elements": [
                "contenttweaker:extrememachineblock@0"
            ]
        },
        {
            "x": -1,
            "y": 5,
            "z": 17,
            "elements": [
                "contenttweaker:extrememachineblock@0"
            ]
        },
        {
            "x": -9,
            "y": 0,
            "z": 8,
            "elements": [
                "contenttweaker:neutronforcefieldcontrolblock@0"
            ]
        },
        {
            "x": 2,
            "y": -4,
            "z": 17,
            "elements": [
                "contenttweaker:extrememachineblock@0"
            ]
        },
        {
            "x": 2,
            "y": 8,
            "z": 13,
            "elements": [
                "contenttweaker:extrememachineblock@0"
            ]
        },
        {
            "x": 0,
            "y": -8,
            "z": 4,
            "elements": [
                "contenttweaker:extrememachineblock@0"
            ]
        },
        {
            "x": 9,
            "y": 1,
            "z": 12,
            "elements": [
                "contenttweaker:extrememachineblock@0"
            ]
        },
        {
            "x": -8,
            "y": 1,
            "z": 4,
            "elements": [
                "contenttweaker:extrememachineblock@0"
            ]
        },
        {
            "x": -9,
            "y": -1,
            "z": 9,
            "elements": [
                "contenttweaker:neutronforcefieldcontrolblock@0"
            ]
        },
        {
            "x": -9,
            "y": -1,
            "z": 10,
            "elements": [
                "contenttweaker:crystalmatrixforcefieldcontrolblock@0"
            ]
        },
        {
            "x": 2,
            "y": -6,
            "z": 3,
            "elements": [
                "contenttweaker:extrememachineblock@0"
            ]
        },
        {
            "x": -5,
            "y": 8,
            "z": 10,
            "elements": [
                "contenttweaker:extrememachineblock@0"
            ]
        },
        {
            "x": 1,
            "y": 8,
            "z": 14,
            "elements": [
                "contenttweaker:extrememachineblock@0"
            ]
        },
        {
            "x": -7,
            "y": -2,
            "z": 5,
            "elements": [
                "contenttweaker:extrememachineblock@0"
            ]
        },
        {
            "x": -6,
            "y": 1,
            "z": 16,
            "elements": [
                "avaritia:block_resource@2"
            ]
        },
        {
            "x": 2,
            "y": -3,
            "z": 17,
            "elements": [
                "contenttweaker:extrememachineblock@0"
            ]
        },
        {
            "x": -7,
            "y": -6,
            "z": 8,
            "elements": [
                "avaritia:block_resource@2"
            ]
        },
        {
            "x": -5,
            "y": -2,
            "z": 16,
            "elements": [
                "contenttweaker:extrememachineblock@0"
            ]
        },
        {
            "x": -3,
            "y": 9,
            "z": 8,
            "elements": [
                "contenttweaker:extrememachineblock@0"
            ]
        },
        {
            "x": 9,
            "y": 0,
            "z": 12,
            "elements": [
                "contenttweaker:extrememachineblock@0"
            ]
        },
        {
            "x": -9,
            "y": -4,
            "z": 8,
            "elements": [
                "contenttweaker:extrememachineblock@0"
            ]
        },
        {
            "x": -7,
            "y": 0,
            "z": 16,
            "elements": [
                "avaritia:block_resource@2"
            ]
        },
        {
            "x": -9,
            "y": 0,
            "z": 5,
            "elements": [
                "contenttweaker:extrememachineblock@0"
            ]
        },
        {
            "x": 8,
            "y": 4,
            "z": 7,
            "elements": [
                "contenttweaker:extrememachineblock@0"
            ]
        },
        {
            "x": 1,
            "y": -7,
            "z": 15,
            "elements": [
                "avaritia:block_resource@2"
            ]
        },
        {
            "x": 3,
            "y": -9,
            "z": 10,
            "elements": [
                "contenttweaker:extrememachineblock@0"
            ]
        },
        {
            "x": 2,
            "y": -2,
            "z": 17,
            "elements": [
                "contenttweaker:extrememachineblock@0"
            ]
        },
        {
            "x": 0,
            "y": 5,
            "z": 17,
            "elements": [
                "contenttweaker:extrememachineblock@0"
            ]
        },
        {
            "x": 2,
            "y": 2,
            "z": 18,
            "elements": [
                "contenttweaker:extrememachineblock@0"
            ]
        },
        {
            "x": -3,
            "y": 2,
            "z": 17,
            "elements": [
                "contenttweaker:extrememachineblock@0"
            ]
        },
        {
            "x": 9,
            "y": -1,
            "z": 13,
            "elements": [
                "contenttweaker:extrememachineblock@0"
            ]
        },
        {
            "x": -9,
            "y": 1,
            "z": 5,
            "elements": [
                "contenttweaker:extrememachineblock@0"
            ]
        },
        {
            "x": -2,
            "y": -6,
            "z": 15,
            "elements": [
                "contenttweaker:extrememachineblock@0"
            ]
        },
        {
            "x": 9,
            "y": 1,
            "z": 13,
            "elements": [
                "contenttweaker:extrememachineblock@0"
            ]
        },
        {
            "x": -7,
            "y": 1,
            "z": 16,
            "elements": [
                "avaritia:block_resource@2"
            ]
        },
        {
            "x": 8,
            "y": 2,
            "z": 7,
            "elements": [
                "contenttweaker:extrememachineblock@0"
            ]
        },
        {
            "x": -1,
            "y": -9,
            "z": 5,
            "elements": [
                "contenttweaker:extrememachineblock@0"
            ]
        },
        {
            "x": 2,
            "y": 1,
            "z": 18,
            "elements": [
                "contenttweaker:extrememachineblock@0"
            ]
        },
        {
            "x": 9,
            "y": 0,
            "z": 13,
            "elements": [
                "contenttweaker:extrememachineblock@0"
            ]
        },
        {
            "x": -7,
            "y": 0,
            "z": 2,
            "elements": [
                "avaritia:block_resource@2"
            ]
        },
        {
            "x": 4,
            "y": -1,
            "z": 18,
            "elements": [
                "contenttweaker:extrememachineblock@0"
            ]
        },
        {
            "x": 9,
            "y": -1,
            "z": 12,
            "elements": [
                "contenttweaker:extrememachineblock@0"
            ]
        },
        {
            "x": -7,
            "y": -1,
            "z": 16,
            "elements": [
                "avaritia:block_resource@2"
            ]
        },
        {
            "x": -7,
            "y": 1,
            "z": 2,
            "elements": [
                "avaritia:block_resource@2"
            ]
        },
        {
            "x": 6,
            "y": -6,
            "z": 11,
            "elements": [
                "contenttweaker:extrememachineblock@0"
            ]
        },
        {
            "x": -7,
            "y": -1,
            "z": 2,
            "elements": [
                "avaritia:block_resource@2"
            ]
        },
        {
            "x": 2,
            "y": 6,
            "z": 15,
            "elements": [
                "contenttweaker:extrememachineblock@0"
            ]
        },
        {
            "x": 8,
            "y": 3,
            "z": 7,
            "elements": [
                "contenttweaker:extrememachineblock@0"
            ]
        },
        {
            "x": -1,
            "y": 9,
            "z": 8,
            "elements": [
                "contenttweaker:crystalmatrixforcefieldcontrolblock@0"
            ]
        },
        {
            "x": 5,
            "y": -7,
            "z": 11,
            "elements": [
                "contenttweaker:extrememachineblock@0"
            ]
        },
        {
            "x": 1,
            "y": -7,
            "z": 3,
            "elements": [
                "avaritia:block_resource@2"
            ]
        },
        {
            "x": -3,
            "y": 8,
            "z": 11,
            "elements": [
                "contenttweaker:extrememachineblock@0"
            ]
        },
        {
            "x": -4,
            "y": 8,
            "z": 7,
            "elements": [
                "contenttweaker:extrememachineblock@0"
            ]
        },
        {
            "x": -4,
            "y": -2,
            "z": 2,
            "elements": [
                "contenttweaker:extrememachineblock@0"
            ]
        },
        {
            "x": -6,
            "y": 0,
            "z": 2,
            "elements": [
                "avaritia:block_resource@2"
            ]
        },
        {
            "x": 0,
            "y": 6,
            "z": 2,
            "elements": [
                "avaritia:block_resource@2"
            ]
        },
        {
            "x": 5,
            "y": -2,
            "z": 16,
            "elements": [
                "contenttweaker:extrememachineblock@0"
            ]
        },
        {
            "x": -7,
            "y": 1,
            "z": 3,
            "elements": [
                "avaritia:block_resource@2"
            ]
        },
        {
            "x": -9,
            "y": 1,
            "z": 13,
            "elements": [
                "contenttweaker:extrememachineblock@0"
            ]
        },
        {
            "x": 3,
            "y": -9,
            "z": 8,
            "elements": [
                "contenttweaker:extrememachineblock@0"
            ]
        },
        {
            "x": -9,
            "y": 0,
            "z": 12,
            "elements": [
                "contenttweaker:extrememachineblock@0"
            ]
        },
        {
            "x": 2,
            "y": 8,
            "z": 6,
            "elements": [
                "contenttweaker:extrememachineblock@0"
            ]
        },
        {
            "x": -6,
            "y": 1,
            "z": 2,
            "elements": [
                "avaritia:block_resource@2"
            ]
        },
        {
            "x": -1,
            "y": 9,
            "z": 6,
            "elements": [
                "contenttweaker:extrememachineblock@0"
            ]
        },
        {
            "x": 9,
            "y": 1,
            "z": 10,
            "elements": [
                "contenttweaker:crystalmatrixforcefieldcontrolblock@0"
            ]
        },
        {
            "x": 4,
            "y": -7,
            "z": 7,
            "elements": [
                "contenttweaker:extrememachineblock@0"
            ]
        },
        {
            "x": 7,
            "y": 6,
            "z": 10,
            "elements": [
                "avaritia:block_resource@2"
            ]
        },
        {
            "x": -3,
            "y": 9,
            "z": 9,
            "elements": [
                "contenttweaker:extrememachineblock@0"
            ]
        },
        {
            "x": -9,
            "y": -1,
            "z": 8,
            "elements": [
                "contenttweaker:crystalmatrixforcefieldcontrolblock@0"
            ]
        },
        {
            "x": -4,
            "y": 9,
            "z": 8,
            "elements": [
                "contenttweaker:extrememachineblock@0"
            ]
        },
        {
            "x": 2,
            "y": -8,
            "z": 12,
            "elements": [
                "contenttweaker:extrememachineblock@0"
            ]
        },
        {
            "x": 4,
            "y": -8,
            "z": 7,
            "elements": [
                "contenttweaker:extrememachineblock@0"
            ]
        },
        {
            "x": -1,
            "y": -7,
            "z": 2,
            "elements": [
                "avaritia:block_resource@2"
            ]
        },
        {
            "x": -2,
            "y": -5,
            "z": 2,
            "elements": [
                "contenttweaker:extrememachineblock@0"
            ]
        },
        {
            "x": 0,
            "y": 7,
            "z": 2,
            "elements": [
                "avaritia:block_resource@2"
            ]
        },
        {
            "x": 8,
            "y": 5,
            "z": 10,
            "elements": [
                "contenttweaker:extrememachineblock@0"
            ]
        },
        {
            "x": 7,
            "y": 7,
            "z": 10,
            "elements": [
                "avaritia:block_resource@2"
            ]
        },
        {
            "x": 9,
            "y": -2,
            "z": 11,
            "elements": [
                "contenttweaker:extrememachineblock@0"
            ]
        },
        {
            "x": -2,
            "y": -4,
            "z": 17,
            "elements": [
                "contenttweaker:extrememachineblock@0"
            ]
        },
        {
            "x": -8,
            "y": -2,
            "z": 7,
            "elements": [
                "contenttweaker:extrememachineblock@0"
            ]
        },
        {
            "x": -9,
            "y": -2,
            "z": 8,
            "elements": [
                "contenttweaker:extrememachineblock@0"
            ]
        },
        {
            "x": 9,
            "y": 2,
            "z": 10,
            "elements": [
                "contenttweaker:extrememachineblock@0"
            ]
        },
        {
            "x": -2,
            "y": -6,
            "z": 2,
            "elements": [
                "contenttweaker:extrememachineblock@0"
            ]
        },
        {
            "x": -5,
            "y": -2,
            "z": 2,
            "elements": [
                "contenttweaker:extrememachineblock@0"
            ]
        },
        {
            "x": 7,
            "y": 2,
            "z": 4,
            "elements": [
                "contenttweaker:extrememachineblock@0"
            ]
        },
        {
            "x": -9,
            "y": 0,
            "z": 13,
            "elements": [
                "contenttweaker:extrememachineblock@0"
            ]
        },
        {
            "x": -2,
            "y": -3,
            "z": 17,
            "elements": [
                "contenttweaker:extrememachineblock@0"
            ]
        },
        {
            "x": 6,
            "y": 1,
            "z": 16,
            "elements": [
                "avaritia:block_resource@2"
            ]
        },
        {
            "x": 6,
            "y": 0,
            "z": 16,
            "elements": [
                "avaritia:block_resource@2"
            ]
        },
        {
            "x": -8,
            "y": -1,
            "z": 4,
            "elements": [
                "contenttweaker:extrememachineblock@0"
            ]
        },
        {
            "x": -7,
            "y": -2,
            "z": 13,
            "elements": [
                "contenttweaker:extrememachineblock@0"
            ]
        },
        {
            "x": -9,
            "y": -3,
            "z": 8,
            "elements": [
                "contenttweaker:extrememachineblock@0"
            ]
        },
        {
            "x": 9,
            "y": 4,
            "z": 10,
            "elements": [
                "contenttweaker:extrememachineblock@0"
            ]
        },
        {
            "x": 9,
            "y": 3,
            "z": 10,
            "elements": [
                "contenttweaker:extrememachineblock@0"
            ]
        },
        {
            "x": -1,
            "y": -9,
            "z": 13,
            "elements": [
                "contenttweaker:extrememachineblock@0"
            ]
        },
        {
            "x": -4,
            "y": 7,
            "z": 7,
            "elements": [
                "contenttweaker:extrememachineblock@0"
            ]
        },
        {
            "x": 9,
            "y": -1,
            "z": 11,
            "elements": [
                "contenttweaker:extrememachineblock@0"
            ]
        },
        {
            "x": 8,
            "y": 2,
            "z": 6,
            "elements": [
                "contenttweaker:extrememachineblock@0"
            ]
        },
        {
            "x": -5,
            "y": -1,
            "z": 17,
            "elements": [
                "contenttweaker:extrememachineblock@0"
            ]
        },
        {
            "x": -7,
            "y": 0,
            "z": 3,
            "elements": [
                "avaritia:block_resource@2"
            ]
        },
        {
            "x": 9,
            "y": -3,
            "z": 10,
            "elements": [
                "contenttweaker:extrememachineblock@0"
            ]
        },
        {
            "x": 0,
            "y": 7,
            "z": 16,
            "elements": [
                "avaritia:block_resource@2"
            ]
        },
        {
            "x": 6,
            "y": 7,
            "z": 10,
            "elements": [
                "avaritia:block_resource@2"
            ]
        },
        {
            "x": -3,
            "y": -9,
            "z": 8,
            "elements": [
                "contenttweaker:extrememachineblock@0"
            ]
        },
        {
            "x": 1,
            "y": 8,
            "z": 4,
            "elements": [
                "contenttweaker:extrememachineblock@0"
            ]
        },
        {
            "x": -6,
            "y": -7,
            "z": 8,
            "elements": [
                "avaritia:block_resource@2"
            ]
        },
        {
            "x": 2,
            "y": -8,
            "z": 13,
            "elements": [
                "contenttweaker:extrememachineblock@0"
            ]
        },
        {
            "x": -2,
            "y": -2,
            "z": 17,
            "elements": [
                "contenttweaker:extrememachineblock@0"
            ]
        },
        {
            "x": 7,
            "y": -1,
            "z": 15,
            "elements": [
                "avaritia:block_resource@2"
            ]
        },
        {
            "x": -2,
            "y": -6,
            "z": 3,
            "elements": [
                "contenttweaker:extrememachineblock@0"
            ]
        },
        {
            "x": 6,
            "y": 2,
            "z": 15,
            "elements": [
                "contenttweaker:extrememachineblock@0"
            ]
        },
        {
            "x": 9,
            "y": -4,
            "z": 10,
            "elements": [
                "contenttweaker:extrememachineblock@0"
            ]
        },
        {
            "x": 2,
            "y": 8,
            "z": 11,
            "elements": [
                "contenttweaker:extrememachineblock@0"
            ]
        },
        {
            "x": 0,
            "y": 6,
            "z": 16,
            "elements": [
                "avaritia:block_resource@2"
            ]
        },
        {
            "x": 8,
            "y": -5,
            "z": 9,
            "elements": [
                "contenttweaker:extrememachineblock@0"
            ]
        },
        {
            "x": 8,
            "y": -2,
            "z": 12,
            "elements": [
                "contenttweaker:extrememachineblock@0"
            ]
        },
        {
            "x": 3,
            "y": 9,
            "z": 10,
            "elements": [
                "contenttweaker:extrememachineblock@0"
            ]
        },
        {
            "x": 7,
            "y": -2,
            "z": 4,
            "elements": [
                "contenttweaker:extrememachineblock@0"
            ]
        },
        {
            "x": -1,
            "y": 9,
            "z": 9,
            "elements": [
                "contenttweaker:neutronforcefieldcontrolblock@0"
            ]
        },
        {
            "x": -4,
            "y": -2,
            "z": 16,
            "elements": [
                "contenttweaker:extrememachineblock@0"
            ]
        },
        {
            "x": 2,
            "y": -7,
            "z": 14,
            "elements": [
                "contenttweaker:extrememachineblock@0"
            ]
        },
        {
            "x": -4,
            "y": -9,
            "z": 8,
            "elements": [
                "contenttweaker:extrememachineblock@0"
            ]
        },
        {
            "x": 2,
            "y": -4,
            "z": 2,
            "elements": [
                "contenttweaker:extrememachineblock@0"
            ]
        },
        {
            "x": 1,
            "y": 9,
            "z": 11,
            "elements": [
                "contenttweaker:extrememachineblock@0"
            ]
        },
        {
            "x": 9,
            "y": -1,
            "z": 10,
            "elements": [
                "contenttweaker:crystalmatrixforcefieldcontrolblock@0"
            ]
        },
        {
            "x": -7,
            "y": 4,
            "z": 7,
            "elements": [
                "contenttweaker:extrememachineblock@0"
            ]
        },
        {
            "x": 4,
            "y": 7,
            "z": 11,
            "elements": [
                "contenttweaker:extrememachineblock@0"
            ]
        },
        {
            "x": 1,
            "y": 9,
            "z": 10,
            "elements": [
                "contenttweaker:crystalmatrixforcefieldcontrolblock@0"
            ]
        },
        {
            "x": -1,
            "y": -6,
            "z": 16,
            "elements": [
                "avaritia:block_resource@2"
            ]
        },
        {
            "x": 8,
            "y": -2,
            "z": 11,
            "elements": [
                "contenttweaker:extrememachineblock@0"
            ]
        },
        {
            "x": -4,
            "y": 2,
            "z": 17,
            "elements": [
                "contenttweaker:extrememachineblock@0"
            ]
        },
        {
            "x": 9,
            "y": -2,
            "z": 10,
            "elements": [
                "contenttweaker:extrememachineblock@0"
            ]
        },
        {
            "x": -4,
            "y": 9,
            "z": 9,
            "elements": [
                "contenttweaker:extrememachineblock@0"
            ]
        },
        {
            "x": 9,
            "y": 0,
            "z": 10,
            "elements": [
                "contenttweaker:neutronforcefieldcontrolblock@0"
            ]
        },
        {
            "x": 5,
            "y": -2,
            "z": 2,
            "elements": [
                "contenttweaker:extrememachineblock@0"
            ]
        },
        {
            "x": -7,
            "y": 5,
            "z": 7,
            "elements": [
                "contenttweaker:extrememachineblock@0"
            ]
        },
        {
            "x": 2,
            "y": -7,
            "z": 13,
            "elements": [
                "contenttweaker:extrememachineblock@0"
            ]
        },
        {
            "x": 7,
            "y": -1,
            "z": 3,
            "elements": [
                "avaritia:block_resource@2"
            ]
        },
        {
            "x": 2,
            "y": 6,
            "z": 3,
            "elements": [
                "contenttweaker:extrememachineblock@0"
            ]
        },
        {
            "x": -5,
            "y": 8,
            "z": 8,
            "elements": [
                "contenttweaker:extrememachineblock@0"
            ]
        },
        {
            "x": 7,
            "y": 1,
            "z": 15,
            "elements": [
                "avaritia:block_resource@2"
            ]
        },
        {
            "x": -9,
            "y": 1,
            "z": 6,
            "elements": [
                "contenttweaker:extrememachineblock@0"
            ]
        },
        {
            "x": -3,
            "y": 1,
            "z": 18,
            "elements": [
                "contenttweaker:extrememachineblock@0"
            ]
        },
        {
            "x": 9,
            "y": 1,
            "z": 5,
            "elements": [
                "contenttweaker:extrememachineblock@0"
            ]
        },
        {
            "x": 5,
            "y": 7,
            "z": 11,
            "elements": [
                "contenttweaker:extrememachineblock@0"
            ]
        },
        {
            "x": -1,
            "y": -9,
            "z": 8,
            "elements": [
                "contenttweaker:crystalmatrixforcefieldcontrolblock@0"
            ]
        },
        {
            "x": 7,
            "y": -2,
            "z": 14,
            "elements": [
                "contenttweaker:extrememachineblock@0"
            ]
        },
        {
            "x": -9,
            "y": 4,
            "z": 9,
            "elements": [
                "contenttweaker:extrememachineblock@0"
            ]
        },
        {
            "x": 2,
            "y": -6,
            "z": 2,
            "elements": [
                "contenttweaker:extrememachineblock@0"
            ]
        },
        {
            "x": 7,
            "y": -5,
            "z": 7,
            "elements": [
                "contenttweaker:extrememachineblock@0"
            ]
        },
        {
            "x": -1,
            "y": 7,
            "z": 3,
            "elements": [
                "avaritia:block_resource@2"
            ]
        },
        {
            "x": 9,
            "y": 0,
            "z": 5,
            "elements": [
                "contenttweaker:extrememachineblock@0"
            ]
        },
        {
            "x": -9,
            "y": 0,
            "z": 6,
            "elements": [
                "contenttweaker:extrememachineblock@0"
            ]
        },
        {
            "x": 4,
            "y": 2,
            "z": 1,
            "elements": [
                "contenttweaker:extrememachineblock@0"
            ]
        },
        {
            "x": 4,
            "y": 8,
            "z": 11,
            "elements": [
                "contenttweaker:extrememachineblock@0"
            ]
        },
        {
            "x": 5,
            "y": -8,
            "z": 9,
            "elements": [
                "contenttweaker:extrememachineblock@0"
            ]
        },
        {
            "x": -9,
            "y": 3,
            "z": 9,
            "elements": [
                "contenttweaker:extrememachineblock@0"
            ]
        },
        {
            "x": 2,
            "y": -5,
            "z": 2,
            "elements": [
                "contenttweaker:extrememachineblock@0"
            ]
        },
        {
            "x": 7,
            "y": 0,
            "z": 15,
            "elements": [
                "avaritia:block_resource@2"
            ]
        },
        {
            "x": -1,
            "y": 9,
            "z": 13,
            "elements": [
                "contenttweaker:extrememachineblock@0"
            ]
        },
        {
            "x": -4,
            "y": -9,
            "z": 9,
            "elements": [
                "contenttweaker:extrememachineblock@0"
            ]
        },
        {
            "x": 8,
            "y": 2,
            "z": 11,
            "elements": [
                "contenttweaker:extrememachineblock@0"
            ]
        },
        {
            "x": 1,
            "y": 9,
            "z": 7,
            "elements": [
                "contenttweaker:extrememachineblock@0"
            ]
        },
        {
            "x": 0,
            "y": 0,
            "z": 9,
            "elements": [
                "contenttweaker:universalforcefieldcontrolblock@0"
            ]
        },
        {
            "x": -9,
            "y": 2,
            "z": 9,
            "elements": [
                "contenttweaker:neutronforcefieldcontrolblock@0"
            ]
        },
        {
            "x": 1,
            "y": -6,
            "z": 2,
            "elements": [
                "avaritia:block_resource@2"
            ]
        },
        {
            "x": 8,
            "y": -2,
            "z": 5,
            "elements": [
                "contenttweaker:extrememachineblock@0"
            ]
        },
        {
            "x": 2,
            "y": -9,
            "z": 8,
            "elements": [
                "contenttweaker:extrememachineblock@0"
            ]
        },
        {
            "x": -9,
            "y": 1,
            "z": 9,
            "elements": [
                "contenttweaker:neutronforcefieldcontrolblock@0"
            ]
        },
        {
            "x": 7,
            "y": -4,
            "z": 7,
            "elements": [
                "contenttweaker:extrememachineblock@0"
            ]
        },
        {
            "x": 2,
            "y": 9,
            "z": 9,
            "elements": [
                "contenttweaker:neutronforcefieldcontrolblock@0"
            ]
        },
        {
            "x": 8,
            "y": 3,
            "z": 11,
            "elements": [
                "contenttweaker:extrememachineblock@0"
            ]
        },
        {
            "x": -2,
            "y": 4,
            "z": 1,
            "elements": [
                "contenttweaker:extrememachineblock@0"
            ]
        },
        {
            "x": 6,
            "y": -2,
            "z": 15,
            "elements": [
                "contenttweaker:extrememachineblock@0"
            ]
        },
        {
            "x": -2,
            "y": -7,
            "z": 4,
            "elements": [
                "contenttweaker:extrememachineblock@0"
            ]
        },
        {
            "x": -1,
            "y": -9,
            "z": 9,
            "elements": [
                "contenttweaker:neutronforcefieldcontrolblock@0"
            ]
        },
        {
            "x": 9,
            "y": 2,
            "z": 11,
            "elements": [
                "contenttweaker:extrememachineblock@0"
            ]
        },
        {
            "x": 3,
            "y": -2,
            "z": 1,
            "elements": [
                "contenttweaker:extrememachineblock@0"
            ]
        },
        {
            "x": -8,
            "y": -4,
            "z": 7,
            "elements": [
                "contenttweaker:extrememachineblock@0"
            ]
        },
        {
            "x": 1,
            "y": 5,
            "z": 1,
            "elements": [
                "contenttweaker:extrememachineblock@0"
            ]
        },
        {
            "x": -5,
            "y": 0,
            "z": 1,
            "elements": [
                "contenttweaker:extrememachineblock@0"
            ]
        },
        {
            "x": -9,
            "y": 0,
            "z": 9,
            "elements": [
                "contenttweaker:fallenstarforcefieldcontrolblock@0"
            ]
        },
        {
            "x": -2,
            "y": 5,
            "z": 2,
            "elements": [
                "contenttweaker:extrememachineblock@0"
            ]
        },
        {
            "x": -8,
            "y": 5,
            "z": 8,
            "elements": [
                "contenttweaker:extrememachineblock@0"
            ]
        },
        {
            "x": -5,
            "y": 1,
            "z": 1,
            "elements": [
                "contenttweaker:extrememachineblock@0"
            ]
        },
        {
            "x": 2,
            "y": -5,
            "z": 16,
            "elements": [
                "contenttweaker:extrememachineblock@0"
            ]
        },
        {
            "x": 2,
            "y": 7,
            "z": 14,
            "elements": [
                "contenttweaker:extrememachineblock@0"
            ]
        },
        {
            "x": 1,
            "y": -9,
            "z": 8,
            "elements": [
                "contenttweaker:crystalmatrixforcefieldcontrolblock@0"
            ]
        },
        {
            "x": 1,
            "y": 7,
            "z": 3,
            "elements": [
                "avaritia:block_resource@2"
            ]
        },
        {
            "x": -2,
            "y": 4,
            "z": 2,
            "elements": [
                "contenttweaker:extrememachineblock@0"
            ]
        },
        {
            "x": -7,
            "y": 7,
            "z": 8,
            "elements": [
                "avaritia:block_resource@2"
            ]
        },
        {
            "x": -8,
            "y": -3,
            "z": 7,
            "elements": [
                "contenttweaker:extrememachineblock@0"
            ]
        },
        {
            "x": 8,
            "y": -5,
            "z": 10,
            "elements": [
                "contenttweaker:extrememachineblock@0"
            ]
        },
        {
            "x": -4,
            "y": 0,
            "z": 18,
            "elements": [
                "contenttweaker:extrememachineblock@0"
            ]
        },
        {
            "x": 0,
            "y": 9,
            "z": 12,
            "elements": [
                "contenttweaker:extrememachineblock@0"
            ]
        },
        {
            "x": 2,
            "y": 8,
            "z": 7,
            "elements": [
                "contenttweaker:extrememachineblock@0"
            ]
        },
        {
            "x": 8,
            "y": 4,
            "z": 11,
            "elements": [
                "contenttweaker:extrememachineblock@0"
            ]
        },
        {
            "x": 1,
            "y": -7,
            "z": 2,
            "elements": [
                "avaritia:block_resource@2"
            ]
        },
        {
            "x": 1,
            "y": 7,
            "z": 15,
            "elements": [
                "avaritia:block_resource@2"
            ]
        },
        {
            "x": 7,
            "y": 4,
            "z": 11,
            "elements": [
                "contenttweaker:extrememachineblock@0"
            ]
        },
        {
            "x": -7,
            "y": -7,
            "z": 9,
            "elements": [
                "avaritia:block_resource@2"
            ]
        },
        {
            "x": -1,
            "y": 9,
            "z": 7,
            "elements": [
                "contenttweaker:extrememachineblock@0"
            ]
        },
        {
            "x": 2,
            "y": -9,
            "z": 9,
            "elements": [
                "contenttweaker:neutronforcefieldcontrolblock@0"
            ]
        },
        {
            "x": 9,
            "y": 0,
            "z": 11,
            "elements": [
                "contenttweaker:neutronforcefieldcontrolblock@0"
            ]
        },
        {
            "x": 0,
            "y": -9,
            "z": 8,
            "elements": [
                "contenttweaker:neutronforcefieldcontrolblock@0"
            ]
        },
        {
            "x": -5,
            "y": 0,
            "z": 17,
            "elements": [
                "contenttweaker:extrememachineblock@0"
            ]
        },
        {
            "x": -2,
            "y": -4,
            "z": 2,
            "elements": [
                "contenttweaker:extrememachineblock@0"
            ]
        },
        {
            "x": 7,
            "y": 5,
            "z": 11,
            "elements": [
                "contenttweaker:extrememachineblock@0"
            ]
        },
        {
            "x": -4,
            "y": -1,
            "z": 18,
            "elements": [
                "contenttweaker:extrememachineblock@0"
            ]
        },
        {
            "x": -1,
            "y": -6,
            "z": 2,
            "elements": [
                "avaritia:block_resource@2"
            ]
        },
        {
            "x": 8,
            "y": 0,
            "z": 14,
            "elements": [
                "contenttweaker:extrememachineblock@0"
            ]
        },
        {
            "x": -2,
            "y": 7,
            "z": 4,
            "elements": [
                "contenttweaker:extrememachineblock@0"
            ]
        },
        {
            "x": 9,
            "y": 1,
            "z": 11,
            "elements": [
                "contenttweaker:extrememachineblock@0"
            ]
        },
        {
            "x": -7,
            "y": -6,
            "z": 9,
            "elements": [
                "avaritia:block_resource@2"
            ]
        },
        {
            "x": -5,
            "y": -7,
            "z": 7,
            "elements": [
                "contenttweaker:extrememachineblock@0"
            ]
        },
        {
            "x": -7,
            "y": 6,
            "z": 8,
            "elements": [
                "avaritia:block_resource@2"
            ]
        },
        {
            "x": -5,
            "y": 1,
            "z": 17,
            "elements": [
                "contenttweaker:extrememachineblock@0"
            ]
        },
        {
            "x": 4,
            "y": 9,
            "z": 10,
            "elements": [
                "contenttweaker:extrememachineblock@0"
            ]
        },
        {
            "x": -3,
            "y": 0,
            "z": 18,
            "elements": [
                "contenttweaker:extrememachineblock@0"
            ]
        },
        {
            "x": -7,
            "y": 2,
            "z": 4,
            "elements": [
                "contenttweaker:extrememachineblock@0"
            ]
        },
        {
            "x": 7,
            "y": 6,
            "z": 9,
            "elements": [
                "avaritia:block_resource@2"
            ]
        },
        {
            "x": 2,
            "y": -4,
            "z": 16,
            "elements": [
                "contenttweaker:extrememachineblock@0"
            ]
        },
        {
            "x": -1,
            "y": 8,
            "z": 14,
            "elements": [
                "contenttweaker:extrememachineblock@0"
            ]
        },
        {
            "x": -4,
            "y": 2,
            "z": 2,
            "elements": [
                "contenttweaker:extrememachineblock@0"
            ]
        },
        {
            "x": 1,
            "y": 1,
            "z": 18,
            "elements": [
                "contenttweaker:crystalmatrixforcefieldcontrolblock@0"
            ]
        },
        {
            "x": -1,
            "y": 5,
            "z": 1,
            "elements": [
                "contenttweaker:extrememachineblock@0"
            ]
        },
        {
            "x": 5,
            "y": -8,
            "z": 10,
            "elements": [
                "contenttweaker:extrememachineblock@0"
            ]
        },
        {
            "x": 0,
            "y": -5,
            "z": 1,
            "elements": [
                "contenttweaker:extrememachineblock@0"
            ]
        },
        {
            "x": -8,
            "y": 3,
            "z": 7,
            "elements": [
                "contenttweaker:extrememachineblock@0"
            ]
        },
        {
            "x": 7,
            "y": -5,
            "z": 11,
            "elements": [
                "contenttweaker:extrememachineblock@0"
            ]
        },
        {
            "x": 2,
            "y": -4,
            "z": 1,
            "elements": [
                "contenttweaker:extrememachineblock@0"
            ]
        },
        {
            "x": -3,
            "y": -2,
            "z": 1,
            "elements": [
                "contenttweaker:extrememachineblock@0"
            ]
        },
        {
            "x": 4,
            "y": -8,
            "z": 11,
            "elements": [
                "contenttweaker:extrememachineblock@0"
            ]
        },
        {
            "x": 7,
            "y": 0,
            "z": 3,
            "elements": [
                "avaritia:block_resource@2"
            ]
        },
        {
            "x": -8,
            "y": -1,
            "z": 14,
            "elements": [
                "contenttweaker:extrememachineblock@0"
            ]
        },
        {
            "x": -8,
            "y": 2,
            "z": 7,
            "elements": [
                "contenttweaker:extrememachineblock@0"
            ]
        },
        {
            "x": 1,
            "y": 5,
            "z": 17,
            "elements": [
                "contenttweaker:extrememachineblock@0"
            ]
        },
        {
            "x": 2,
            "y": -3,
            "z": 1,
            "elements": [
                "contenttweaker:extrememachineblock@0"
            ]
        },
        {
            "x": -4,
            "y": -8,
            "z": 7,
            "elements": [
                "contenttweaker:extrememachineblock@0"
            ]
        },
        {
            "x": 7,
            "y": 7,
            "z": 8,
            "elements": [
                "avaritia:block_resource@2"
            ]
        },
        {
            "x": -9,
            "y": -1,
            "z": 12,
            "elements": [
                "contenttweaker:extrememachineblock@0"
            ]
        },
        {
            "x": 4,
            "y": -7,
            "z": 11,
            "elements": [
                "contenttweaker:extrememachineblock@0"
            ]
        },
        {
            "x": -5,
            "y": -8,
            "z": 8,
            "elements": [
                "contenttweaker:extrememachineblock@0"
            ]
        },
        {
            "x": -5,
            "y": 2,
            "z": 2,
            "elements": [
                "contenttweaker:extrememachineblock@0"
            ]
        },
        {
            "x": -4,
            "y": -7,
            "z": 7,
            "elements": [
                "contenttweaker:extrememachineblock@0"
            ]
        },
        {
            "x": 2,
            "y": -2,
            "z": 1,
            "elements": [
                "contenttweaker:extrememachineblock@0"
            ]
        },
        {
            "x": 4,
            "y": 9,
            "z": 8,
            "elements": [
                "contenttweaker:extrememachineblock@0"
            ]
        },
        {
            "x": 9,
            "y": 4,
            "z": 9,
            "elements": [
                "contenttweaker:extrememachineblock@0"
            ]
        },
        {
            "x": -1,
            "y": 7,
            "z": 16,
            "elements": [
                "avaritia:block_resource@2"
            ]
        },
        {
            "x": -7,
            "y": 2,
            "z": 14,
            "elements": [
                "contenttweaker:extrememachineblock@0"
            ]
        },
        {
            "x": 3,
            "y": -2,
            "z": 17,
            "elements": [
                "contenttweaker:extrememachineblock@0"
            ]
        },
        {
            "x": 7,
            "y": 6,
            "z": 8,
            "elements": [
                "avaritia:block_resource@2"
            ]
        },
        {
            "x": 1,
            "y": 9,
            "z": 5,
            "elements": [
                "contenttweaker:extrememachineblock@0"
            ]
        },
        {
            "x": -2,
            "y": -9,
            "z": 8,
            "elements": [
                "contenttweaker:extrememachineblock@0"
            ]
        },
        {
            "x": -8,
            "y": -5,
            "z": 8,
            "elements": [
                "contenttweaker:extrememachineblock@0"
            ]
        },
        {
            "x": -3,
            "y": 2,
            "z": 1,
            "elements": [
                "contenttweaker:extrememachineblock@0"
            ]
        },
        {
            "x": -7,
            "y": 4,
            "z": 11,
            "elements": [
                "contenttweaker:extrememachineblock@0"
            ]
        },
        {
            "x": -9,
            "y": 2,
            "z": 7,
            "elements": [
                "contenttweaker:extrememachineblock@0"
            ]
        },
        {
            "x": 7,
            "y": 7,
            "z": 9,
            "elements": [
                "avaritia:block_resource@2"
            ]
        },
        {
            "x": -8,
            "y": 4,
            "z": 7,
            "elements": [
                "contenttweaker:extrememachineblock@0"
            ]
        },
        {
            "x": -1,
            "y": 6,
            "z": 16,
            "elements": [
                "avaritia:block_resource@2"
            ]
        },
        {
            "x": 8,
            "y": 5,
            "z": 9,
            "elements": [
                "contenttweaker:extrememachineblock@0"
            ]
        },
        {
            "x": 5,
