{
    "registryname": "enderman",
    "localizedname": "小黑塔工厂",
    "failure-action": "still",
    "requires-blueprint": false,
    "has-factory": true,
    "parts": [
        {
            "x": 0,
            "y": 0,
            "z": 0,

            "elements": [
                "modularmachinery:blockfactorycontroller@2"
            ]
        },
        {
            "x": 0,
            "y": 0,
            "z": 6,
            "elements": [
                "futuremc:smooth_stone@0"
            ]
        },
        {
            "x": 1,
            "y": 0,
            "z": 6,
            "elements": [
                "futuremc:smooth_stone@0"
            ]
        },
        {
            "x": -1,
            "y": 0,
            "z": 6,
            "elements": [
                "futuremc:smooth_stone@0"
            ]
        },
        {
            "x": 10,
            "y": 24,
            "z": -6,
            "elements": [
                "futuremc:smooth_stone@0"
            ]
        },
        {
            "x": -2,
            "y": 24,
            "z": -13,
            "elements": [
                "futuremc:smooth_stone@0"
            ]
        },
        {
            "x": -3,
            "y": 0,
            "z": 5,
            "elements": [
                "futuremc:smooth_stone@0"
            ]
        },
        {
            "x": 15,
            "y": 24,
            "z": 11,
            "elements": [
                "futuremc:smooth_stone@0"
            ]
        },
        {
            "x": -15,
            "y": 24,
            "z": 5,
            "elements": [
                "futuremc:smooth_stone@0"
            ]
        },
        {
            "x": 3,
            "y": 24,
            "z": 14,
            "elements": [
                "futuremc:smooth_stone@0"
            ]
        },
        {
            "x": -2,
            "y": 4,
            "z": 0,
            "elements": [
                "minecraft:carpet@0"
            ]
        },
        {
            "x": -8,
            "y": 24,
            "z": -11,
            "elements": [
                "futuremc:smooth_stone@0"
            ]
        },
        {
            "x": -3,
            "y": 24,
            "z": 8,
            "elements": [
                "futuremc:smooth_stone@0"
            ]
        },
        {
            "x": -4,
            "y": 4,
            "z": 5,
            "elements": [
                "minecraft:carpet@0"
            ]
        },
        {
            "x": -13,
            "y": 24,
            "z": 0,
            "elements": [
                "futuremc:smooth_stone@0"
            ]
        },
        {
            "x": -6,
            "y": 24,
            "z": 6,
            "elements": [
                "futuremc:smooth_stone@0"
            ]
        },
        {
            "x": 6,
            "y": 24,
            "z": 13,
            "elements": [
                "futuremc:smooth_stone@0"
            ]
        },
        {
            "x": -11,
            "y": 24,
            "z": -11,
            "elements": [
                "futuremc:smooth_stone@0"
            ]
        },
        {
            "x": 10,
            "y": 24,
            "z": -8,
            "elements": [
                "futuremc:smooth_stone@0"
            ]
        },
        {
            "x": 13,
            "y": 24,
            "z": -6,
            "elements": [
                "futuremc:smooth_stone@0"
            ]
        },
        {
            "x": -2,
            "y": 21,
            "z": 2,
            "elements": [
                "futuremc:smooth_stone@0"
            ]
        },
        {
            "x": 0,
            "y": 9,
            "z": 4,
            "elements": [
                "futuremc:smooth_stone@0"
            ]
        },
        {
            "x": 0,
            "y": 24,
            "z": 8,
            "elements": [
                "futuremc:smooth_stone@0"
            ]
        },
        {
            "x": 1,
            "y": 0,
            "z": 0,
            "elements": [
                "futuremc:smooth_stone@0"
            ]
        },
        {
            "x": 15,
            "y": 24,
            "z": 12,
            "elements": [
                "futuremc:smooth_stone@0"
            ]
        },
        {
            "x": -5,
            "y": 24,
            "z": -13,
            "elements": [
                "futuremc:smooth_stone@0"
            ]
        },
        {
            "x": 7,
            "y": 24,
            "z": -6,
            "elements": [
                "futuremc:smooth_stone@0"
            ]
        },
        {
            "x": 13,
            "y": 24,
            "z": 1,
            "elements": [
                "futuremc:smooth_stone@0"
            ]
        },
        {
            "x": -2,
            "y": 24,
            "z": -9,
            "elements": [
                "futuremc:smooth_stone@0"
            ]
        },
        {
            "x": -2,
            "y": 0,
            "z": 5,
            "elements": [
                "futuremc:smooth_stone@0"
            ]
        },
        {
            "x": -1,
            "y": 4,
            "z": 0,
            "elements": [
                "minecraft:carpet@0"
            ]
        },
        {
            "x": -1,
            "y": 15,
            "z": 4,
            "elements": [
                "futuremc:smooth_stone@0"
            ]
        },
        {
            "x": -5,
            "y": 24,
            "z": -11,
            "elements": [
                "futuremc:smooth_stone@0"
            ]
        },
        {
            "x": 9,
            "y": 24,
            "z": 13,
            "elements": [
                "futuremc:smooth_stone@0"
            ]
        },
        {
            "x": 7,
            "y": 24,
            "z": -8,
            "elements": [
                "futuremc:smooth_stone@0"
            ]
        },
        {
            "x": -9,
            "y": 24,
            "z": -1,
            "elements": [
                "futuremc:smooth_stone@0"
            ]
        },
        {
            "x": -12,
            "y": 24,
            "z": 7,
            "elements": [
                "futuremc:smooth_stone@0"
            ]
        },
        {
            "x": -3,
            "y": 24,
            "z": 6,
            "elements": [
                "futuremc:smooth_stone@0"
            ]
        },
        {
            "x": -11,
            "y": 24,
            "z": -12,
            "elements": [
                "futuremc:smooth_stone@0"
            ]
        },
        {
            "x": -12,
            "y": 24,
            "z": 14,
            "elements": [
                "futuremc:smooth_stone@0"
            ]
        },
        {
            "x": 6,
            "y": 24,
            "z": 9,
            "elements": [
                "futuremc:smooth_stone@0"
            ]
        },
        {
            "x": 12,
            "y": 24,
            "z": 11,
            "elements": [
                "futuremc:smooth_stone@0"
            ]
        },
        {
            "x": -12,
            "y": 24,
            "z": 0,
            "elements": [
                "futuremc:smooth_stone@0"
            ]
        },
        {
            "x": 2,
            "y": 0,
            "z": 0,

            "elements": [
                "modularmachinery:blockinputbus",
                "modularmachinery:blockmepatternprovider",
                "modularmachinery:blockmeiteminputbus"
            ]
        },
        {
            "x": -4,
            "y": 24,
            "z": -4,
            "elements": [
                "futuremc:smooth_stone@0"
            ]
        },
        {
            "x": 3,
            "y": 24,
            "z": 8,
            "elements": [
                "futuremc:smooth_stone@0"
            ]
        },
        {
            "x": 3,
            "y": 3,
            "z": 4,
            "elements": [
                "futuremc:smooth_stone@0"
            ]
        },
        {
            "x": -12,
            "y": 24,
            "z": 3,
            "elements": [
                "futuremc:smooth_stone@0"
            ]
        },
        {
            "x": -4,
            "y": 4,
            "z": 0,
            "elements": [
                "minecraft:carpet@0"
            ]
        },
        {
            "x": 10,
            "y": 24,
            "z": 1,
            "elements": [
                "futuremc:smooth_stone@0"
            ]
        },
        {
            "x": 4,
            "y": 24,
            "z": -13,
            "elements": [
                "futuremc:smooth_stone@0"
            ]
        },
        {
            "x": 15,
            "y": 24,
            "z": 13,
            "elements": [
                "futuremc:smooth_stone@0"
            ]
        },
        {
            "x": -12,
            "y": 24,
            "z": 6,
            "elements": [
                "futuremc:smooth_stone@0"
            ]
        },
        {
            "x": -14,
            "y": 24,
            "z": -12,
            "elements": [
                "futuremc:smooth_stone@0"
            ]
        },
        {
            "x": -15,
            "y": 24,
            "z": 7,
            "elements": [
                "futuremc:smooth_stone@0"
            ]
        },
        {
            "x": -15,
            "y": 24,
            "z": 0,
            "elements": [
                "futuremc:smooth_stone@0"
            ]
        },
        {
            "x": 15,
            "y": 24,
            "z": 16,
            "elements": [
                "futuremc:smooth_stone@0"
            ]
        },
        {
            "x": -15,
            "y": 24,
            "z": 14,
            "elements": [
                "futuremc:smooth_stone@0"
            ]
        },
        {
            "x": -15,
            "y": 24,
            "z": 10,
            "elements": [
                "futuremc:smooth_stone@0"
            ]
        },
        {
            "x": 2,
            "y": 9,
            "z": 4,
            "elements": [
                "futuremc:smooth_stone@0"
            ]
        },
        {
            "x": -6,
            "y": 24,
            "z": -1,
            "elements": [
                "futuremc:smooth_stone@0"
            ]
        },
        {
            "x": 0,
            "y": 24,
            "z": 13,
            "elements": [
                "futuremc:smooth_stone@0"
            ]
        },
        {
            "x": -14,
            "y": 24,
            "z": 5,
            "elements": [
                "futuremc:smooth_stone@0"
            ]
        },
        {
            "x": 0,
            "y": 24,
            "z": -8,
            "elements": [
                "futuremc:smooth_stone@0"
            ]
        },
        {
            "x": 9,
            "y": 24,
            "z": 11,
            "elements": [
                "futuremc:smooth_stone@0"
            ]
        },
        {
            "x": -1,
            "y": 0,
            "z": 0,
            "elements": [
                "futuremc:smooth_stone@0"
            ]
        },
        {
            "x": -2,
            "y": 24,
            "z": 16,
            "elements": [
                "futuremc:smooth_stone@0"
            ]
        },
        {
            "x": -2,
            "y": 18,
            "z": 2,
            "elements": [
                "futuremc:smooth_stone@0"
            ]
        },
        {
            "x": 1,
            "y": 24,
            "z": -6,
            "elements": [
                "futuremc:smooth_stone@0"
            ]
        },
        {
            "x": 0,
            "y": 0,
            "z": 5,

            "elements": [
                "futuremc:smooth_stone@0"
            ]
        },
        {
            "x": -6,
            "y": 24,
            "z": 8,
            "elements": [
                "futuremc:smooth_stone@0"
            ]
        },
        {
            "x": -3,
            "y": 4,
            "z": 5,
            "elements": [
                "minecraft:carpet@0"
            ]
        },
        {
            "x": 1,
            "y": 4,
            "z": 0,
            "elements": [
                "minecraft:carpet@0"
            ]
        },
        {
            "x": -2,
            "y": 6,
            "z": 0,
            "elements": [
                "futuremc:smooth_stone@0"
            ]
        },
        {
            "x": 3,
            "y": 0,
            "z": 3,
            "elements": [
                "futuremc:smooth_stone@0"
            ]
        },
        {
            "x": -14,
            "y": 24,
            "z": -11,
            "elements": [
                "futuremc:smooth_stone@0"
            ]
        },
        {
            "x": -11,
            "y": 24,
            "z": -13,
            "elements": [
                "futuremc:smooth_stone@0"
            ]
        },
        {
            "x": 3,
            "y": 5,
            "z": 4,
            "elements": [
                "minecraft:carpet@0"
            ]
        },
        {
            "x": 3,
            "y": 24,
            "z": 6,
            "elements": [
                "futuremc:smooth_stone@0"
            ]
        },
        {
            "x": 1,
            "y": 24,
            "z": -8,
            "elements": [
                "futuremc:smooth_stone@0"
            ]
        },
        {
            "x": 13,
            "y": 24,
            "z": -13,
            "elements": [
                "futuremc:smooth_stone@0"
            ]
        },
        {
            "x": -10,
            "y": 24,
            "z": 0,
            "elements": [
                "futuremc:smooth_stone@0"
            ]
        },
        {
            "x": 8,
            "y": 24,
            "z": 4,
            "elements": [
                "futuremc:smooth_stone@0"
            ]
        },
        {
            "x": 13,
            "y": 24,
            "z": -7,
            "elements": [
                "futuremc:smooth_stone@0"
            ]
        },
        {
            "x": 9,
            "y": 24,
            "z": 6,
            "elements": [
                "futuremc:smooth_stone@0"
            ]
        },
        {
            "x": 1,
            "y": 24,
            "z": 8,
            "elements": [
                "futuremc:smooth_stone@0"
            ]
        },
        {
            "x": -6,
            "y": 24,
            "z": 3,
            "elements": [
                "futuremc:smooth_stone@0"
            ]
        },
        {
            "x": 4,
            "y": 0,
            "z": 0,
            "elements": [
                "futuremc:smooth_stone@0"
            ]
        },
        {
            "x": 1,
            "y": 24,
            "z": 16,
            "elements": [
                "futuremc:smooth_stone@0"
            ]
        },
        {
            "x": 6,
            "y": 24,
            "z": 7,
            "elements": [
                "futuremc:smooth_stone@0"
            ]
        },
        {
            "x": 15,
            "y": 24,
            "z": -5,
            "elements": [
                "futuremc:smooth_stone@0"
            ]
        },
        {
            "x": 1,
            "y": 24,
            "z": -9,
            "elements": [
                "futuremc:smooth_stone@0"
            ]
        },
        {
            "x": 0,
            "y": 4,
            "z": 5,
            "elements": [
                "minecraft:carpet@0"
            ]
        },
        {
            "x": 2,
            "y": 4,
            "z": 0,
            "elements": [
                "minecraft:carpet@0"
            ]
        },
        {
            "x": -9,
            "y": 24,
            "z": 14,
            "elements": [
                "futuremc:smooth_stone@0"
            ]
        },
        {
            "x": 3,
            "y": 4,
            "z": -1,
            "elements": [
                "minecraft:carpet@0"
            ]
        },
        {
            "x": -3,
            "y": 3,
            "z": 4,
            "elements": [
                "futuremc:smooth_stone@0"
            ]
        },
        {
            "x": -2,
            "y": 24,
            "z": -6,
            "elements": [
                "futuremc:smooth_stone@0"
            ]
        },
        {
            "x": 2,
            "y": 24,
            "z": -4,
            "elements": [
                "futuremc:smooth_stone@0"
            ]
        },
        {
            "x": 0,
            "y": 1,
            "z": 4,
            "elements": [
                "minecraft:carpet@1"
            ]
        },
        {
            "x": 6,
            "y": 24,
            "z": -8,
            "elements": [
                "futuremc:smooth_stone@0"
            ]
        },
        {
            "x": 10,
            "y": 24,
            "z": -3,
            "elements": [
                "futuremc:smooth_stone@0"
            ]
        },
        {
            "x": 3,
            "y": 5,
            "z": -1,
            "elements": [
                "minecraft:carpet@0"
            ]
        },
        {
            "x": -9,
            "y": 24,
            "z": 7,
            "elements": [
                "futuremc:smooth_stone@0"
            ]
        },
        {
            "x": 11,
            "y": 24,
            "z": 11,
            "elements": [
                "futuremc:smooth_stone@0"
            ]
        },
        {
            "x": -12,
            "y": 24,
            "z": 5,
            "elements": [
                "futuremc:smooth_stone@0"
            ]
        },
        {
            "x": 6,
            "y": 24,
            "z": 14,
            "elements": [
                "futuremc:smooth_stone@0"
            ]
        },
        {
            "x": 6,
            "y": 24,
            "z": 6,
            "elements": [
                "futuremc:smooth_stone@0"
            ]
        },
        {
            "x": 5,
            "y": 24,
            "z": 4,
            "elements": [
                "futuremc:smooth_stone@0"
            ]
        },
        {
            "x": -9,
            "y": 24,
            "z": 0,
            "elements": [
                "futuremc:smooth_stone@0"
            ]
        },
        {
            "x": 3,
            "y": 24,
            "z": 9,
            "elements": [
                "futuremc:smooth_stone@0"
            ]
        },
        {
            "x": -14,
            "y": 24,
            "z": -13,
            "elements": [
                "futuremc:smooth_stone@0"
            ]
        },
        {
            "x": 3,
            "y": 24,
            "z": -2,
            "elements": [
                "futuremc:smooth_stone@0"
            ]
        },
        {
            "x": -9,
            "y": 24,
            "z": 3,
            "elements": [
                "futuremc:smooth_stone@0"
            ]
        },
        {
            "x": 0,
            "y": 24,
            "z": 14,
            "elements": [
                "futuremc:smooth_stone@0"
            ]
        },
        {
            "x": -3,
            "y": 5,
            "z": 4,
            "elements": [
                "minecraft:carpet@0"
            ]
        },
        {
            "x": -1,
            "y": 4,
            "z": 5,
            "elements": [
                "minecraft:carpet@0"
            ]
        },
        {
            "x": -9,
            "y": 24,
            "z": -11,
            "elements": [
                "futuremc:smooth_stone@0"
            ]
        },
        {
            "x": 2,
            "y": 0,
            "z": 5,
            "elements": [
                "futuremc:smooth_stone@0"
            ]
        },
        {
            "x": 13,
            "y": 24,
            "z": -3,
            "elements": [
                "futuremc:smooth_stone@0"
            ]
        },
        {
            "x": -5,
            "y": 24,
            "z": -6,
            "elements": [
                "futuremc:smooth_stone@0"
            ]
        },
        {
            "x": -12,
            "y": 24,
            "z": -11,
            "elements": [
                "futuremc:smooth_stone@0"
            ]
        },
        {
            "x": 3,
            "y": 24,
            "z": 12,
            "elements": [
                "futuremc:smooth_stone@0"
            ]
        },
        {
            "x": 4,
            "y": 24,
            "z": 16,
            "elements": [
                "futuremc:smooth_stone@0"
            ]
        },
        {
            "x": -14,
            "y": 24,
            "z": 10,
            "elements": [
                "futuremc:smooth_stone@0"
            ]
        },
        {
            "x": 2,
            "y": 24,
            "z": 4,
            "elements": [
                "futuremc:smooth_stone@0"
            ]
        },
        {
            "x": -14,
            "y": 24,
            "z": -9,
            "elements": [
                "futuremc:smooth_stone@0"
            ]
        },
        {
            "x": 3,
            "y": 24,
            "z": -8,
            "elements": [
                "futuremc:smooth_stone@0"
            ]
        },
        {
            "x": -2,
            "y": 0,
            "z": 0,

            "elements": [
                "modularmachinery:blockoutputbus",
                "modularmachinery:blockmeitemoutputbus"
            ]
        },
        {
            "x": 11,
            "y": 24,
            "z": 4,
            "elements": [
                "futuremc:smooth_stone@0"
            ]
        },
        {
            "x": -3,
            "y": 24,
            "z": 14,
            "elements": [
                "futuremc:smooth_stone@0"
            ]
        },
        {
            "x": 1,
            "y": 24,
            "z": -12,
            "elements": [
                "futuremc:smooth_stone@0"
            ]
        },
        {
            "x": -1,
            "y": 12,
            "z": 0,
            "elements": [
                "futuremc:smooth_stone@0"
            ]
        },
        {
            "x": 6,
            "y": 24,
            "z": -2,
            "elements": [
                "futuremc:smooth_stone@0"
            ]
        },
        {
            "x": -5,
            "y": 24,
            "z": -9,
            "elements": [
                "futuremc:smooth_stone@0"
            ]
        },
        {
            "x": 3,
            "y": 24,
            "z": 16,
            "elements": [
                "futuremc:smooth_stone@0"
            ]
        },
        {
            "x": 6,
            "y": 24,
            "z": 12,
            "elements": [
                "futuremc:smooth_stone@0"
            ]
        },
        {
            "x": 3,
            "y": 4,
            "z": 3,
            "elements": [
                "minecraft:carpet@0"
            ]
        },
        {
            "x": -1,
            "y": 0,
            "z": 5,

            "elements": [
                "futuremc:smooth_stone@0"
            ]
        },
        {
            "x": -12,
            "y": 24,
            "z": 13,
            "elements": [
                "futuremc:smooth_stone@0"
            ]
        },
        {
            "x": -1,
            "y": 6,
            "z": 0,
            "elements": [
                "futuremc:smooth_stone@0"
            ]
        },
        {
            "x": -11,
            "y": 24,
            "z": 10,
            "elements": [
                "futuremc:smooth_stone@0"
            ]
        },
        {
            "x": -7,
            "y": 24,
            "z": -4,
            "elements": [
                "futuremc:smooth_stone@0"
            ]
        },
        {
            "x": -2,
            "y": 24,
            "z": 2,
            "elements": [
                "futuremc:smooth_stone@0"
            ]
        },
        {
            "x": 9,
            "y": 24,
            "z": 9,
            "elements": [
                "futuremc:smooth_stone@0"
            ]
        },
        {
            "x": 13,
            "y": 24,
            "z": 11,
            "elements": [
                "futuremc:smooth_stone@0"
            ]
        },
        {
            "x": 0,
            "y": 5,
            "z": 4,
            "elements": [
                "minecraft:carpet@0"
            ]
        },
        {
            "x": -2,
            "y": 24,
            "z": -12,
            "elements": [
                "futuremc:smooth_stone@0"
            ]
        },
        {
            "x": -1,
            "y": 21,
            "z": 4,
            "elements": [
                "futuremc:smooth_stone@0"
            ]
        },
        {
            "x": 4,
            "y": 24,
            "z": -8,
            "elements": [
                "futuremc:smooth_stone@0"
            ]
        },
        {
            "x": -7,
            "y": 24,
            "z": 3,
            "elements": [
                "futuremc:smooth_stone@0"
            ]
        },
        {
            "x": 15,
            "y": 24,
            "z": -10,
            "elements": [
                "futuremc:smooth_stone@0"
            ]
        },
        {
            "x": 0,
            "y": 3,
            "z": 4,
            "elements": [
                "futuremc:smooth_stone@0"
            ]
        },
        {
            "x": -8,
            "y": 24,
            "z": -9,
            "elements": [
                "futuremc:smooth_stone@0"
            ]
        },
        {
            "x": 0,
            "y": 4,
            "z": -1,
            "elements": [
                "minecraft:carpet@0"
            ]
        },
        {
            "x": -4,
            "y": 0,
            "z": 5,
            "elements": [
                "futuremc:smooth_stone@0"
            ]
        },
        {
            "x": -6,
            "y": 24,
            "z": 14,
            "elements": [
                "futuremc:smooth_stone@0"
            ]
        },
        {
            "x": 3,
            "y": 5,
            "z": 6,
            "elements": [
                "minecraft:carpet@0"
            ]
        },
        {
            "x": -1,
            "y": 24,
            "z": -4,
            "elements": [
                "futuremc:smooth_stone@0"
            ]
        },
        {
            "x": 10,
            "y": 24,
            "z": -7,
            "elements": [
                "futuremc:smooth_stone@0"
            ]
        },
        {
            "x": -2,
            "y": 24,
            "z": 8,
            "elements": [
                "futuremc:smooth_stone@0"
            ]
        },
        {
            "x": 1,
            "y": 24,
            "z": -13,
            "elements": [
                "futuremc:smooth_stone@0"
            ]
        },
        {
            "x": -9,
            "y": 24,
            "z": 6,
            "elements": [
                "futuremc:smooth_stone@0"
            ]
        },
        {
            "x": 11,
            "y": 24,
            "z": -3,
            "elements": [
                "futuremc:smooth_stone@0"
            ]
        },
        {
            "x": 12,
            "y": 24,
            "z": 9,
            "elements": [
                "futuremc:smooth_stone@0"
            ]
        },
        {
            "x": 2,
            "y": 6,
            "z": 0,
            "elements": [
                "futuremc:smooth_stone@0"
            ]
        },
        {
            "x": -10,
            "y": 24,
            "z": -11,
            "elements": [
                "futuremc:smooth_stone@0"
            ]
        },
        {
            "x": 3,
            "y": 0,
            "z": -1,
            "elements": [
                "futuremc:smooth_stone@0"
            ]
        },
        {
            "x": 3,
            "y": 3,
            "z": 6,
            "elements": [
                "futuremc:smooth_stone@0"
            ]
        },
        {
            "x": -6,
            "y": 24,
            "z": 7,
            "elements": [
                "futuremc:smooth_stone@0"
            ]
        },
        {
            "x": -6,
            "y": 24,
            "z": 0,
            "elements": [
                "futuremc:smooth_stone@0"
            ]
        },
        {
            "x": 14,
            "y": 24,
            "z": 11,
            "elements": [
                "futuremc:smooth_stone@0"
            ]
        },
        {
            "x": 3,
            "y": 4,
            "z": 6,
            "elements": [
                "minecraft:carpet@0"
            ]
        },
        {
            "x": 3,
            "y": 3,
            "z": -1,
            "elements": [
                "futuremc:smooth_stone@0"
            ]
        },
        {
            "x": 0,
            "y": 5,
            "z": -1,
            "elements": [
                "minecraft:carpet@0"
            ]
        },
        {
            "x": 3,
            "y": 24,
            "z": 13,
            "elements": [
                "futuremc:smooth_stone@0"
            ]
        },
        {
            "x": 1,
            "y": 12,
            "z": 0,
            "elements": [
                "futuremc:smooth_stone@0"
            ]
        },
        {
            "x": 11,
            "y": 24,
            "z": -5,
            "elements": [
                "futuremc:smooth_stone@0"
            ]
        },
        {
            "x": -2,
            "y": 5,
            "z": 4,
            "elements": [
                "minecraft:carpet@0"
            ]
        },
        {
            "x": -10,
            "y": 24,
            "z": 17,
            "elements": [
                "futuremc:smooth_stone@0"
            ]
        },
        {
            "x": -2,
            "y": 6,
            "z": 3,
            "elements": [
                "futuremc:smooth_stone@0"
            ]
        },
        {
            "x": -10,
            "y": 24,
            "z": 3,
            "elements": [
                "futuremc:smooth_stone@0"
            ]
        },
        {
            "x": -4,
            "y": 1,
            "z": 4,
            "elements": [
                "minecraft:stone_slab@0"
            ]
        },
        {
            "x": 4,
            "y": 0,
            "z": 3,
            "elements": [
                "futuremc:smooth_stone@0"
            ]
        },
        {
            "x": 1,
            "y": 24,
            "z": -7,
            "elements": [
                "futuremc:smooth_stone@0"
            ]
        },
        {
            "x": -9,
            "y": 24,
            "z": 10,
            "elements": [
                "futuremc:smooth_stone@0"
            ]
        },
        {
            "x": 0,
            "y": 24,
            "z": -2,
            "elements": [
                "futuremc:smooth_stone@0"
            ]
        },
        {
            "x": -13,
            "y": 24,
            "z": -4,
            "elements": [
                "futuremc:smooth_stone@0"
            ]
        },
        {
            "x": 14,
            "y": 24,
            "z": -3,
            "elements": [
                "futuremc:smooth_stone@0"
            ]
        },
        {
            "x": 13,
            "y": 24,
            "z": 16,
            "elements": [
                "futuremc:smooth_stone@0"
            ]
        },
        {
            "x": 15,
            "y": 24,
            "z": 9,
            "elements": [
                "futuremc:smooth_stone@0"
            ]
        },
        {
            "x": 0,
            "y": 24,
            "z": 12,
            "elements": [
                "futuremc:smooth_stone@0"
            ]
        },
        {
            "x": -2,
            "y": 18,
            "z": 0,
            "elements": [
                "futuremc:smooth_stone@0"
            ]
        },
        {
            "x": -5,
            "y": 24,
            "z": 0,
            "elements": [
                "futuremc:smooth_stone@0"
            ]
        },
        {
            "x": -11,
            "y": 24,
            "z": 15,
            "elements": [
                "futuremc:smooth_stone@0"
            ]
        },
        {
            "x": 13,
            "y": 24,
            "z": -10,
            "elements": [
                "futuremc:smooth_stone@0"
            ]
        },
        {
            "x": 4,
            "y": 24,
            "z": 2,
            "elements": [
                "futuremc:smooth_stone@0"
            ]
        },
        {
            "x": -13,
            "y": 24,
            "z": 3,
            "elements": [
                "futuremc:smooth_stone@0"
            ]
        },
        {
            "x": -11,
            "y": 24,
            "z": -9,
            "elements": [
                "futuremc:smooth_stone@0"
            ]
        },
        {
            "x": -10,
            "y": 24,
            "z": -9,
            "elements": [
                "futuremc:smooth_stone@0"
            ]
        },
        {
            "x": -2,
            "y": 3,
            "z": 4,
            "elements": [
                "futuremc:smooth_stone@0"
            ]
        },
        {
            "x": 3,
            "y": 24,
            "z": 7,
            "elements": [
                "futuremc:smooth_stone@0"
            ]
        },
        {
            "x": 14,
            "y": 24,
            "z": 4,
            "elements": [
                "futuremc:smooth_stone@0"
            ]
        },
        {
            "x": 4,
            "y": 24,
            "z": -12,
            "elements": [
                "futuremc:smooth_stone@0"
            ]
        },
        {
            "x": 3,
            "y": 4,
            "z": 5,
            "elements": [
                "minecraft:carpet@0"
            ]
        },
        {
            "x": -1,
            "y": 1,
            "z": 4,
            "elements": [
                "minecraft:carpet@1"
            ]
        },
        {
            "x": -2,
            "y": 4,
            "z": 3,
            "elements": [
                "minecraft:carpet@0"
            ]
        },
        {
            "x": 14,
            "y": 24,
            "z": 9,
            "elements": [
                "futuremc:smooth_stone@0"
            ]
        },
        {
            "x": -10,
            "y": 24,
            "z": -4,
            "elements": [
                "futuremc:smooth_stone@0"
            ]
        },
        {
            "x": -9,
            "y": 24,
            "z": -2,
            "elements": [
                "futuremc:smooth_stone@0"
            ]
        },
        {
            "x": -14,
            "y": 24,
            "z": 15,
            "elements": [
                "futuremc:smooth_stone@0"
            ]
        },
        {
            "x": 1,
            "y": 0,
            "z": 3,

            "elements": [
                "futuremc:smooth_stone@0"
            ]
        },
        {
            "x": -9,
            "y": 24,
            "z": 12,
            "elements": [
                "futuremc:smooth_stone@0"
            ]
        },
        {
            "x": -1,
            "y": 24,
            "z": 17,
            "elements": [
                "futuremc:smooth_stone@0"
            ]
        },
        {
            "x": -9,
            "y": 24,
            "z": -9,
            "elements": [
                "futuremc:smooth_stone@0"
            ]
        },
        {
            "x": 15,
            "y": 24,
            "z": 4,
            "elements": [
                "futuremc:smooth_stone@0"
            ]
        },
        {
            "x": 13,
            "y": 24,
            "z": 2,
            "elements": [
                "futuremc:smooth_stone@0"
            ]
        },
        {
            "x": -4,
            "y": 5,
            "z": 4,
            "elements": [
                "minecraft:carpet@0"
            ]
        },
        {
            "x": 2,
            "y": 4,
            "z": 5,
            "elements": [
                "minecraft:carpet@0"
            ]
        },
        {
            "x": 13,
            "y": 24,
            "z": -12,
            "elements": [
                "futuremc:smooth_stone@0"
            ]
        },
        {
            "x": 4,
            "y": 4,
            "z": 0,
            "elements": [
                "minecraft:carpet@0"
            ]
        },
        {
            "x": 3,
            "y": 0,
            "z": 5,
            "elements": [
                "futuremc:smooth_stone@0"
            ]
        },
        {
            "x": -11,
            "y": 24,
            "z": -4,
            "elements": [
                "futuremc:smooth_stone@0"
            ]
        },
        {
            "x": 13,
            "y": 24,
            "z": 9,
            "elements": [
                "futuremc:smooth_stone@0"
            ]
        },
        {
            "x": -13,
            "y": 24,
            "z": 15,
            "elements": [
                "futuremc:smooth_stone@0"
            ]
        },
        {
            "x": -13,
            "y": 24,
            "z": -11,
            "elements": [
                "futuremc:smooth_stone@0"
            ]
        },
        {
            "x": -6,
            "y": 24,
            "z": -2,
            "elements": [
                "futuremc:smooth_stone@0"
            ]
        },
        {
            "x": 10,
            "y": 24,
            "z": 2,
            "elements": [
                "futuremc:smooth_stone@0"
            ]
        },
        {
            "x": 7,
            "y": 24,
            "z": 16,
            "elements": [
                "futuremc:smooth_stone@0"
            ]
        },
        {
            "x": -6,
            "y": 24,
            "z": 12,
            "elements": [
                "futuremc:smooth_stone@0"
            ]
        },
        {
            "x": -4,
            "y": 24,
            "z": 17,
            "elements": [
                "futuremc:smooth_stone@0"
            ]
        },
        {
            "x": -9,
            "y": 24,
            "z": 13,
            "elements": [
                "futuremc:smooth_stone@0"
            ]
        },
        {
            "x": -7,
            "y": 24,
            "z": 17,
            "elements": [
                "futuremc:smooth_stone@0"
            ]
        },
        {
            "x": -7,
            "y": 24,
            "z": -11,
            "elements": [
                "futuremc:smooth_stone@0"
            ]
        },
        {
            "x": -3,
            "y": 24,
            "z": -2,
            "elements": [
                "futuremc:smooth_stone@0"
            ]
        },
        {
            "x": 10,
            "y": 24,
            "z": -12,
            "elements": [
                "futuremc:smooth_stone@0"
            ]
        },
        {
            "x": -4,
            "y": 3,
            "z": 4,
            "elements": [
                "futuremc:smooth_stone@0"
            ]
        },
        {
            "x": 3,
            "y": 24,
            "z": 1,
            "elements": [
                "futuremc:smooth_stone@0"
            ]
        },
        {
            "x": -12,
            "y": 24,
            "z": -4,
            "elements": [
                "futuremc:smooth_stone@0"
            ]
        },
        {
            "x": -12,
            "y": 24,
            "z": 10,
            "elements": [
                "futuremc:smooth_stone@0"
            ]
        },
        {
            "x": -2,
            "y": 24,
            "z": -7,
            "elements": [
                "futuremc:smooth_stone@0"
            ]
        },
        {
            "x": 6,
            "y": 24,
            "z": 16,
            "elements": [
                "futuremc:smooth_stone@0"
            ]
        },
        {
            "x": 7,
            "y": 24,
            "z": 2,
            "elements": [
                "futuremc:smooth_stone@0"
            ]
        },
        {
            "x": -4,
            "y": 0,
            "z": 0,
            "elements": [
                "futuremc:smooth_stone@0"
            ]
        },
        {
            "x": -3,
            "y": 24,
            "z": 12,
            "elements": [
                "futuremc:smooth_stone@0"
            ]
        },
        {
            "x": -12,
            "y": 24,
            "z": -9,
            "elements": [
                "futuremc:smooth_stone@0"
            ]
        },
        {
            "x": 1,
            "y": 24,
            "z": -1,
            "elements": [
                "futuremc:smooth_stone@0"
            ]
        },
        {
            "x": 3,
            "y": 24,
            "z": -1,
            "elements": [
                "futuremc:smooth_stone@0"
            ]
        },
        {
            "x": 13,
            "y": 24,
            "z": 4,
            "elements": [
                "futuremc:smooth_stone@0"
            ]
        },
        {
            "x": -7,
            "y": 24,
            "z": -9,
            "elements": [
                "futuremc:smooth_stone@0"
            ]
        },
        {
            "x": -2,
            "y": 24,
            "z": 0,
            "elements": [
                "futuremc:smooth_stone@0"
            ]
        },
        {
            "x": -6,
            "y": 24,
            "z": 13,
            "elements": [
                "futuremc:smooth_stone@0"
            ]
        },
        {
            "x": 7,
            "y": 24,
            "z": -12,
            "elements": [
                "futuremc:smooth_stone@0"
            ]
        },
        {
            "x": -8,
            "y": 24,
            "z": 2,
            "elements": [
                "futuremc:smooth_stone@0"
            ]
        },
        {
            "x": 4,
            "y": 24,
            "z": 1,
            "elements": [
                "futuremc:smooth_stone@0"
            ]
        },
        {
            "x": -3,
            "y": 4,
            "z": 3,
            "elements": [
                "minecraft:carpet@0"
            ]
        },
        {
            "x": -4,
            "y": 24,
            "z": 5,
            "elements": [
                "futuremc:smooth_stone@0"
            ]
        },
        {
            "x": 3,
            "y": 24,
            "z": 11,
            "elements": [
                "futuremc:smooth_stone@0"
            ]
        },
        {
            "x": -4,
            "y": 24,
            "z": -11,
            "elements": [
                "futuremc:smooth_stone@0"
            ]
        },
        {
            "x": 1,
            "y": 6,
            "z": 0,
            "elements": [
                "futuremc:smooth_stone@0"
            ]
        },
        {
            "x": -9,
            "y": 24,
            "z": -4,
            "elements": [
                "futuremc:smooth_stone@0"
            ]
        },
        {
            "x": 0,
            "y": 0,
            "z": 3,

            "elements": [
                "futuremc:smooth_stone@0"
            ]
        },
        {
            "x": 11,
            "y": 24,
            "z": 9,
            "elements": [
                "futuremc:smooth_stone@0"
            ]
        },
        {
            "x": 2,
            "y": 24,
            "z": 17,
            "elements": [
                "futuremc:smooth_stone@0"
            ]
        },
        {
            "x": 2,
            "y": 5,
            "z": 4,
            "elements": [
                "minecraft:carpet@0"
            ]
        },
        {
            "x": -14,
            "y": 24,
            "z": 3,
            "elements": [
                "futuremc:smooth_stone@0"
            ]
        },
        {
            "x": 0,
            "y": 24,
            "z": -1,
            "elements": [
                "futuremc:smooth_stone@0"
            ]
        },
        {
            "x": 9,
            "y": 24,
            "z": 16,
            "elements": [
                "futuremc:smooth_stone@0"
            ]
        },
        {
            "x": -4,
            "y": 24,
            "z": 12,
            "elements": [
                "futuremc:smooth_stone@0"
            ]
        },
        {
            "x": 8,
            "y": 24,
            "z": -5,
            "elements": [
                "futuremc:smooth_stone@0"
            ]
        },
        {
            "x": 6,
            "y": 24,
            "z": -1,
            "elements": [
                "futuremc:smooth_stone@0"
            ]
        },
        {
            "x": -1,
            "y": 24,
            "z": -11,
            "elements": [
                "futuremc:smooth_stone@0"
            ]
        },
        {
            "x": -2,
            "y": 12,
            "z": 0,
            "elements": [
                "futuremc:smooth_stone@0"
            ]
        },
        {
            "x": -6,
            "y": 24,
            "z": -9,
            "elements": [
                "futuremc:smooth_stone@0"
            ]
        },
        {
            "x": -3,
            "y": 24,
            "z": 13,
            "elements": [
                "futuremc:smooth_stone@0"
            ]
        },
        {
            "x": -13,
            "y": 24,
            "z": 17,
            "elements": [
                "futuremc:smooth_stone@0"
            ]
        },
        {
            "x": 2,
            "y": 3,
            "z": 4,
            "elements": [
                "futuremc:smooth_stone@0"
            ]
        },
        {
            "x": 8,
            "y": 24,
            "z": -12,
            "elements": [
                "futuremc:smooth_stone@0"
            ]
        },
        {
            "x": 7,
            "y": 24,
            "z": -13,
            "elements": [
                "futuremc:smooth_stone@0"
            ]
        },
        {
            "x": -6,
            "y": 24,
            "z": 10,
            "elements": [
                "futuremc:smooth_stone@0"
            ]
        },
        {
            "x": 12,
            "y": 24,
            "z": 16,
            "elements": [
                "futuremc:smooth_stone@0"
            ]
        },
        {
            "x": 1,
            "y": 18,
            "z": 0,
            "elements": [
                "futuremc:smooth_stone@0"
            ]
        },
        {
            "x": 4,
            "y": 24,
            "z": -7,
            "elements": [
                "futuremc:smooth_stone@0"
            ]
        },
        {
            "x": 10,
            "y": 24,
            "z": 9,
            "elements": [
                "futuremc:smooth_stone@0"
            ]
        },
        {
            "x": 10,
            "y": 24,
            "z": -13,
            "elements": [
                "futuremc:smooth_stone@0"
            ]
        },
        {
            "x": -6,
            "y": 24,
            "z": -4,
            "elements": [
                "futuremc:smooth_stone@0"
            ]
        },
        {
            "x": -8,
            "y": 24,
            "z": 0,
            "elements": [
                "futuremc:smooth_stone@0"
            ]
        },
        {
            "x": -13,
            "y": 24,
            "z": 5,
            "elements": [
                "futuremc:smooth_stone@0"
            ]
        },
        {
            "x": -3,
            "y": 0,
            "z": 3,
            "elements": [
                "futuremc:smooth_stone@0"
            ]
        },
        {
            "x": 10,
            "y": 24,
            "z": -10,
            "elements": [
                "futuremc:smooth_stone@0"
            ]
        },
        {
            "x": 10,
            "y": 24,
            "z": 4,
            "elements": [
                "futuremc:smooth_stone@0"
            ]
        },
        {
            "x": 8,
            "y": 24,
            "z": 11,
            "elements": [
                "futuremc:smooth_stone@0"
            ]
        },
        {
            "x": -1,
            "y": 9,
            "z": 4,
            "elements": [
                "futuremc:smooth_stone@0"
            ]
        },
        {
            "x": 0,
            "y": 24,
            "z": 7,
            "elements": [
                "futuremc:smooth_stone@0"
            ]
        },
        {
            "x": -1,
            "y": 3,
            "z": 4,
            "elements": [
                "futuremc:smooth_stone@0"
            ]
        },
        {
            "x": -3,
            "y": 24,
            "z": 10,
            "elements": [
                "futuremc:smooth_stone@0"
            ]
        },
        {
            "x": 4,
            "y": 24,
            "z": -6,
            "elements": [
                "futuremc:smooth_stone@0"
            ]
        },
        {
            "x": 7,
            "y": 24,
            "z": -7,
            "elements": [
                "futuremc:smooth_stone@0"
            ]
        },
        {
            "x": -2,
            "y": 24,
            "z": -11,
            "elements": [
                "futuremc:smooth_stone@0"
            ]
        },
        {
            "x": 5,
            "y": 24,
            "z": 11,
            "elements": [
                "futuremc:smooth_stone@0"
            ]
        },
        {
            "x": -2,
            "y": 24,
            "z": 1,
            "elements": [
                "futuremc:smooth_stone@0"
            ]
        },
        {
            "x": 0,
            "y": 24,
            "z": 6,
            "elements": [
                "futuremc:smooth_stone@0"
            ]
        },
        {
            "x": 7,
            "y": 24,
            "z": -10,
            "elements": [
                "futuremc:smooth_stone@0"
            ]
        },
        {
            "x": -10,
            "y": 24,
            "z": 5,
            "elements": [
                "futuremc:smooth_stone@0"
            ]
        },
        {
            "x": -13,
            "y": 24,
            "z": -9,
            "elements": [
                "futuremc:smooth_stone@0"
            ]
        },
        {
            "x": -2,
            "y": 0,
            "z": 3,
            "elements": [
                "futuremc:smooth_stone@0"
            ]
        },
        {
            "x": -3,
            "y": 24,
            "z": 7,
            "elements": [
                "futuremc:smooth_stone@0"
            ]
        },
        {
            "x": -15,
            "y": 24,
            "z": -4,
            "elements": [
                "futuremc:smooth_stone@0"
            ]
        },
        {
            "x": -11,
            "y": 24,
            "z": 0,
            "elements": [
                "futuremc:smooth_stone@0"
            ]
        },
        {
            "x": 11,
            "y": 24,
            "z": 16,
            "elements": [
                "futuremc:smooth_stone@0"
            ]
        },
        {
            "x": 3,
            "y": 4,
            "z": -2,
            "elements": [
                "minecraft:carpet@0"
            ]
        },
        {
            "x": -1,
            "y": 5,
            "z": 4,
            "elements": [
                "minecraft:carpet@0"
            ]
        },
        {
            "x": 9,
            "y": 24,
            "z": -2,
            "elements": [
                "futuremc:smooth_stone@0"
            ]
        },
        {
            "x": 7,
            "y": 24,
            "z": 1,
            "elements": [
                "futuremc:smooth_stone@0"
            ]
        },
        {
            "x": -4,
            "y": 4,
            "z": 3,
            "elements": [
                "minecraft:carpet@0"
            ]
        },
        {
            "x": 14,
            "y": 24,
            "z": -5,
            "elements": [
                "futuremc:smooth_stone@0"
            ]
        },
        {
            "x": -2,
            "y": 21,
            "z": 1,
            "elements": [
                "futuremc:smooth_stone@0"
            ]
        },
        {
            "x": 1,
            "y": 1,
            "z": 4,
            "elements": [
                "minecraft:carpet@1"
            ]
        },
        {
            "x": 3,
            "y": 5,
            "z": -2,
            "elements": [
                "minecraft:carpet@0"
            ]
        },
        {
            "x": -14,
            "y": 24,
            "z": 0,
            "elements": [
                "futuremc:smooth_stone@0"
            ]
        },
        {
            "x": -5,
            "y": 24,
            "z": 2,
            "elements": [
                "futuremc:smooth_stone@0"
            ]
        },
        {
            "x": 6,
            "y": 24,
            "z": 11,
            "elements": [
                "futuremc:smooth_stone@0"
            ]
        },
        {
            "x": -1,
            "y": 0,
            "z": 3,

            "elements": [
                "futuremc:smooth_stone@0"
            ]
        },
        {
            "x": 13,
            "y": 24,
            "z": -8,
            "elements": [
                "futuremc:smooth_stone@0"
            ]
        },
        {
            "x": 5,
            "y": 24,
            "z": 17,
            "elements": [
                "futuremc:smooth_stone@0"
            ]
        },
        {
            "x": -9,
            "y": 24,
            "z": 8,
            "elements": [
                "futuremc:smooth_stone@0"
            ]
        },
        {
            "x": -3,
            "y": 24,
            "z": -1,
            "elements": [
                "futuremc:smooth_stone@0"
            ]
        },
        {
            "x": 12,
            "y": 24,
            "z": -2,
            "elements": [
                "futuremc:smooth_stone@0"
            ]
        },
        {
            "x": -15,
            "y": 24,
            "z": 3,
            "elements": [
                "futuremc:smooth_stone@0"
            ]
        },
        {
            "x": -7,
            "y": 24,
            "z": 12,
            "elements": [
                "futuremc:smooth_stone@0"
            ]
        },
        {
            "x": -8,
            "y": 24,
            "z": 15,
            "elements": [
                "futuremc:smooth_stone@0"
            ]
        },
        {
            "x": -7,
            "y": 24,
            "z": 5,
            "elements": [
                "futuremc:smooth_stone@0"
            ]
        },
        {
            "x": 10,
            "y": 24,
            "z": 16,
            "elements": [
                "futuremc:smooth_stone@0"
            ]
        },
        {
            "x": 1,
            "y": 3,
            "z": 4,
            "elements": [
                "futuremc:smooth_stone@0"
            ]
        },
        {
            "x": 3,
            "y": 3,
            "z": 2,
            "elements": [
                "futuremc:smooth_stone@0"
            ]
        },
        {
            "x": 2,
            "y": 24,
            "z": 0,
            "elements": [
                "futuremc:smooth_stone@0"
            ]
        },
        {
            "x": 4,
            "y": 1,
            "z": 4,
            "elements": [
                "minecraft:stone_slab@0"
            ]
        },
        {
            "x": -10,
            "y": 24,
            "z": 13,
            "elements": [
                "futuremc:smooth_stone@0"
            ]
        },
        {
            "x": 7,
            "y": 24,
            "z": -1,
            "elements": [
                "futuremc:smooth_stone@0"
            ]
        },
        {
            "x": -3,
            "y": 24,
            "z": -9,
            "elements": [
                "futuremc:smooth_stone@0"
            ]
        },
        {
            "x": 10,
            "y": 24,
            "z": 7,
            "elements": [
                "futuremc:smooth_stone@0"
            ]
        },
        {
            "x": 8,
            "y": 24,
            "z": 12,
            "elements": [
                "futuremc:smooth_stone@0"
            ]
        },
        {
            "x": -2,
            "y": 12,
            "z": 1,
            "elements": [
                "futuremc:smooth_stone@0"
            ]
        },
        {
            "x": -2,
            "y": 24,
            "z": 3,
            "elements": [
                "futuremc:smooth_stone@0"
            ]
        },
        {
            "x": 13,
            "y": 24,
            "z": 17,
            "elements": [
                "futuremc:smooth_stone@0"
            ]
        },
        {
            "x": 3,
            "y": 0,
            "z": -2,
            "elements": [
                "futuremc:smooth_stone@0"
            ]
        },
        {
            "x": 1,
            "y": 4,
            "z": 4,
            "elements": [
                "minecraft:carpet@0"
            ]
        },
        {
            "x": -8,
            "y": 24,
            "z": -2,
            "elements": [
                "futuremc:smooth_stone@0"
            ]
        },
        {
            "x": 7,
            "y": 24,
            "z": 9,
            "elements": [
                "futuremc:smooth_stone@0"
            ]
        },
        {
            "x": 6,
            "y": 24,
            "z": -3,
            "elements": [
                "futuremc:smooth_stone@0"
            ]
        },
        {
            "x": -8,
            "y": 24,
            "z": 1,
            "elements": [
                "futuremc:smooth_stone@0"
            ]
        },
        {
            "x": -4,
            "y": 24,
            "z": -12,
            "elements": [
                "futuremc:smooth_stone@0"
            ]
        },
        {
            "x": 1,
            "y": 4,
            "z": -2,
            "elements": [
                "minecraft:carpet@0"
            ]
        },
        {
            "x": -3,
            "y": 24,
            "z": 15,
            "elements": [
                "futuremc:smooth_stone@0"
            ]
        },
        {
            "x": 12,
            "y": 24,
            "z": 2,
            "elements": [
                "futuremc:smooth_stone@0"
            ]
        },
        {
            "x": 9,
            "y": 24,
            "z": -4,
            "elements": [
                "futuremc:smooth_stone@0"
            ]
        },
        {
            "x": -7,
            "y": 24,
            "z": 13,
            "elements": [
                "futuremc:smooth_stone@0"
            ]
        },
        {
            "x": 4,
            "y": 24,
            "z": 14,
            "elements": [
                "futuremc:smooth_stone@0"
            ]
        },
        {
            "x": 10,
            "y": 24,
            "z": -1,
            "elements": [
                "futuremc:smooth_stone@0"
            ]
        },
        {
            "x": 14,
            "y": 24,
            "z": 17,
            "elements": [
                "futuremc:smooth_stone@0"
            ]
        },
        {
            "x": -2,
            "y": 24,
            "z": 10,
            "elements": [
                "futuremc:smooth_stone@0"
            ]
        },
        {
            "x": -5,
            "y": 24,
            "z": 3,
            "elements": [
                "futuremc:smooth_stone@0"
            ]
        },
        {
            "x": 1,
            "y": 6,
            "z": 4,
            "elements": [
                "futuremc:smooth_stone@0"
            ]
        },
        {
            "x": 7,
            "y": 24,
            "z": 17,
            "elements": [
                "futuremc:smooth_stone@0"
            ]
        },
        {
            "x": -1,
            "y": 24,
            "z": 12,
            "elements": [
                "futuremc:smooth_stone@0"
            ]
        },
        {
            "x": 14,
            "y": 24,
            "z": -13,
            "elements": [
                "futuremc:smooth_stone@0"
            ]
        },
        {
            "x": -1,
            "y": 24,
            "z": 5,
            "elements": [
                "futuremc:smooth_stone@0"
            ]
        },
        {
            "x": -2,
            "y": 9,
            "z": 2,
            "elements": [
                "futuremc:smooth_stone@0"
            ]
        },
        {
            "x": 0,
            "y": 24,
            "z": -7,
            "elements": [
                "futuremc:smooth_stone@0"
            ]
        },
        {
            "x": 4,
            "y": 0,
            "z": -2,
            "elements": [
                "futuremc:smooth_stone@0"
            ]
        },
        {
            "x": 6,
            "y": 24,
            "z": -10,
            "elements": [
                "futuremc:smooth_stone@0"
            ]
        },
        {
            "x": -3,
            "y": 24,
            "z": 1,
            "elements": [
                "futuremc:smooth_stone@0"
            ]
        },
        {
            "x": 1,
            "y": 5,
            "z": 4,
            "elements": [
                "minecraft:carpet@0"
            ]
        },
        {
            "x": 9,
            "y": 24,
            "z": -3,
            "elements": [
                "futuremc:smooth_stone@0"
            ]
        },
        {
            "x": 2,
            "y": 5,
            "z": -1,
            "elements": [
                "minecraft:carpet@0"
            ]
        },
        {
            "x": -6,
            "y": 24,
            "z": 15,
            "elements": [
                "futuremc:smooth_stone@0"
            ]
        },
        {
            "x": 4,
            "y": 0,
            "z": 4,
            "elements": [
                "futuremc:smooth_stone@0"
            ]
        },
        {
            "x": 5,
            "y": 24,
            "z": -12,
            "elements": [
                "futuremc:smooth_stone@0"
            ]
        },
        {
            "x": -2,
            "y": 15,
            "z": 2,
            "elements": [
                "futuremc:smooth_stone@0"
            ]
        },
        {
            "x": 0,
            "y": 24,
            "z": -3,
            "elements": [
                "futuremc:smooth_stone@0"
            ]
        },
        {
            "x": 5,
            "y": 24,
            "z": -5,
            "elements": [
                "futuremc:smooth_stone@0"
            ]
        },
        {
            "x": 4,
            "y": 24,
            "z": 7,
            "elements": [
                "futuremc:smooth_stone@0"
            ]
        },
        {
            "x": 1,
            "y": 24,
            "z": 14,
            "elements": [
                "futuremc:smooth_stone@0"
            ]
        },
        {
            "x": 1,
            "y": 24,
            "z": 10,
            "elements": [
                "futuremc:smooth_stone@0"
            ]
        },
        {
            "x": -1,
            "y": 4,
            "z": 6,
            "elements": [
                "minecraft:carpet@0"
            ]
        },
        {
            "x": 9,
            "y": 24,
            "z": -1,
            "elements": [
                "futuremc:smooth_stone@0"
            ]
        },
        {
            "x": -3,
            "y": 3,
            "z": 2,
            "elements": [
                "futuremc:smooth_stone@0"
            ]
        },
        {
            "x": 2,
            "y": 24,
            "z": 5,
            "elements": [
                "futuremc:smooth_stone@0"
            ]
        },
        {
            "x": -14,
            "y": 24,
            "z": -2,
            "elements": [
                "futuremc:smooth_stone@0"
            ]
        },
        {
            "x": -3,
            "y": 0,
            "z": -2,
            "elements": [
                "futuremc:smooth_stone@0"
            ]
        },
        {
            "x": -8,
            "y": 24,
            "z": 4,
            "elements": [
                "futuremc:smooth_stone@0"
            ]
        },
        {
            "x": 0,
            "y": 1,
            "z": 2,
            "elements": [
                "minecraft:carpet@0"
            ]
        },
        {
            "x": -2,
            "y": 21,
            "z": 3,
            "elements": [
                "futuremc:smooth_stone@0"
            ]
        },
        {
            "x": 3,
            "y": 24,
            "z": -7,
            "elements": [
                "futuremc:smooth_stone@0"
            ]
        },
        {
            "x": 2,
            "y": 24,
            "z": 12,
            "elements": [
                "futuremc:smooth_stone@0"
            ]
        },
        {
            "x": 11,
            "y": 24,
            "z": -13,
            "elements": [
                "futuremc:smooth_stone@0"
            ]
        },
        {
            "x": 3,
            "y": 24,
            "z": -10,
            "elements": [
                "futuremc:smooth_stone@0"
            ]
        },
        {
            "x": -12,
            "y": 24,
            "z": 8,
            "elements": [
                "futuremc:smooth_stone@0"
            ]
        },
        {
            "x": 4,
            "y": 24,
            "z": 17,
            "elements": [
                "futuremc:smooth_stone@0"
            ]
        },
        {
            "x": -2,
            "y": 12,
            "z": 4,
            "elements": [
                "futuremc:smooth_stone@0"
            ]
        },
        {
            "x": -6,
            "y": 24,
            "z": 1,
            "elements": [
                "futuremc:smooth_stone@0"
            ]
        },
        {
            "x": 12,
            "y": 24,
            "z": -4,
            "elements": [
                "futuremc:smooth_stone@0"
            ]
        },
        {
            "x": 2,
            "y": 24,
            "z": -5,
            "elements": [
                "futuremc:smooth_stone@0"
            ]
        },
        {
            "x": 7,
            "y": 24,
            "z": 4,
            "elements": [
                "futuremc:smooth_stone@0"
            ]
        },
        {
            "x": 4,
            "y": 5,
            "z": 4,
            "elements": [
                "minecraft:carpet@0"
            ]
        },
        {
            "x": 1,
            "y": 24,
            "z": 7,
            "elements": [
                "futuremc:smooth_stone@0"
            ]
        },
        {
            "x": 2,
            "y": 24,
            "z": -12,
            "elements": [
                "futuremc:smooth_stone@0"
            ]
        },
        {
            "x": 4,
            "y": 3,
            "z": 4,
            "elements": [
                "futuremc:smooth_stone@0"
            ]
        },
        {
            "x": -11,
            "y": 24,
            "z": 3,
            "elements": [
                "futuremc:smooth_stone@0"
            ]
        },
        {
            "x": -13,
            "y": 24,
            "z": 6,
            "elements": [
                "futuremc:smooth_stone@0"
            ]
        },
        {
            "x": 4,
            "y": 4,
            "z": 4,
            "elements": [
                "minecraft:carpet@0"
            ]
        },
        {
            "x": 2,
            "y": 0,
            "z": 6,
            "elements": [
                "futuremc:smooth_stone@0"
            ]
        },
        {
            "x": -13,
            "y": 24,
            "z": 8,
            "elements": [
                "futuremc:smooth_stone@0"
            ]
        },
        {
            "x": 4,
            "y": 4,
            "z": 1,
            "elements": [
                "minecraft:carpet@0"
            ]
        },
        {
            "x": -11,
            "y": 24,
            "z": -2,
            "elements": [
                "futuremc:smooth_stone@0"
            ]
        },
        {
            "x": 4,
            "y": 24,
            "z": 3,
            "elements": [
                "futuremc:smooth_stone@0"
            ]
        },
        {
            "x": 1,
            "y": 9,
            "z": 4,
            "elements": [
                "futuremc:smooth_stone@0"
            ]
        },
        {
            "x": 15,
            "y": 24,
            "z": -3,
            "elements": [
                "futuremc:smooth_stone@0"
            ]
        },
        {
            "x": 5,
            "y": 24,
            "z": 12,
            "elements": [
                "futuremc:smooth_stone@0"
            ]
        },
        {
            "x": -5,
            "y": 24,
            "z": 1,
            "elements": [
                "futuremc:smooth_stone@0"
            ]
        },
        {
            "x": -2,
            "y": 18,
            "z": 1,
            "elements": [
                "futuremc:smooth_stone@0"
            ]
        },
        {
            "x": 4,
            "y": 5,
            "z": -1,
            "elements": [
                "minecraft:carpet@0"
            ]
        },
        {
            "x": -1,
            "y": 24,
            "z": -12,
            "elements": [
                "futuremc:smooth_stone@0"
            ]
        },
        {
            "x": -4,
            "y": 5,
            "z": 2,
            "elements": [
                "minecraft:carpet@0"
            ]
        },
        {
            "x": 15,
            "y": 24,
            "z": 2,
            "elements": [
                "futuremc:smooth_stone@0"
            ]
        },
        {
            "x": -5,
            "y": 24,
            "z": 10,
            "elements": [
                "futuremc:smooth_stone@0"
            ]
        },
        {
            "x": 4,
            "y": 24,
            "z": 5,
            "elements": [
                "futuremc:smooth_stone@0"
            ]
        },
        {
            "x": -14,
            "y": 24,
            "z": 4,
            "elements": [
                "futuremc:smooth_stone@0"
            ]
        },
        {
            "x": -2,
            "y": 15,
            "z": 4,
            "elements": [
                "futuremc:smooth_stone@0"
            ]
        },
        {
            "x": -2,
            "y": 1,
            "z": 2,
            "elements": [
                "minecraft:carpet@1"
            ]
        },
        {
            "x": -6,
            "y": 24,
            "z": -3,
            "elements": [
                "futuremc:smooth_stone@0"
            ]
        },
        {
            "x": -10,
            "y": 24,
            "z": 6,
            "elements": [
                "futuremc:smooth_stone@0"
            ]
        },
        {
            "x": -1,
            "y": 0,
            "z": -2,
            "elements": [
                "futuremc:smooth_stone@0"
            ]
        },
        {
            "x": 1,
            "y": 0,
            "z": 1,

            "elements": [
                "futuremc:smooth_stone@0"
            ]
        },
        {
            "x": 10,
            "y": 24,
            "z": 17,
            "elements": [
                "futuremc:smooth_stone@0"
            ]
        },
        {
            "x": -12,
            "y": 24,
            "z": -2,
            "elements": [
                "futuremc:smooth_stone@0"
            ]
        },
        {
            "x": -2,
            "y": 6,
            "z": 1,
            "elements": [
                "futuremc:smooth_stone@0"
            ]
        },
        {
            "x": -3,
            "y": 24,
            "z": -7,
            "elements": [
                "futuremc:smooth_stone@0"
            ]
        },
        {
            "x": 0,
            "y": 24,
            "z": -5,
            "elements": [
                "futuremc:smooth_stone@0"
            ]
        },
        {
            "x": -3,
            "y": 4,
            "z": -2,
            "elements": [
                "minecraft:carpet@0"
            ]
        },
        {
            "x": 9,
            "y": 24,
            "z": -10,
            "elements": [
                "futuremc:smooth_stone@0"
            ]
        },
        {
            "x": -15,
            "y": 24,
            "z": -9,
            "elements": [
                "futuremc:smooth_stone@0"
            ]
        },
        {
            "x": -3,
            "y": 24,
            "z": -3,
            "elements": [
                "futuremc:smooth_stone@0"
            ]
        },
        {
            "x": 11,
            "y": 24,
            "z": -6,
            "elements": [
                "futuremc:smooth_stone@0"
            ]
        },
        {
            "x": -2,
            "y": 3,
            "z": 2,
            "elements": [
                "futuremc:smooth_stone@0"
            ]
        },
        {
            "x": 7,
            "y": 24,
            "z": 7,
            "elements": [
                "futuremc:smooth_stone@0"
            ]
        },
        {
            "x": -2,
            "y": 18,
            "z": 4,
            "elements": [
                "futuremc:smooth_stone@0"
            ]
        },
        {
            "x": -3,
            "y": 5,
            "z": 2,
            "elements": [
                "minecraft:carpet@0"
            ]
        },
        {
            "x": -13,
            "y": 24,
            "z": -2,
            "elements": [
                "futuremc:smooth_stone@0"
            ]
        },
        {
            "x": -12,
            "y": 24,
            "z": 16,
            "elements": [
                "futuremc:smooth_stone@0"
            ]
        },
        {
            "x": -2,
            "y": 12,
            "z": 3,
            "elements": [
                "futuremc:smooth_stone@0"
            ]
        },
        {
            "x": 4,
            "y": 0,
            "z": 1,
            "elements": [
                "futuremc:smooth_stone@0"
            ]
        },
        {
            "x": 11,
            "y": 24,
            "z": 17,
            "elements": [
                "futuremc:smooth_stone@0"
            ]
        },
        {
            "x": 1,
            "y": 12,
            "z": 4,
            "elements": [
                "futuremc:smooth_stone@0"
            ]
        },
        {
            "x": -15,
            "y": 24,
            "z": -12,
            "elements": [
                "futuremc:smooth_stone@0"
            ]
        },
        {
            "x": 0,
            "y": 0,
            "z": -2,
            "elements": [
                "futuremc:smooth_stone@0"
            ]
        },
        {
            "x": -1,
            "y": 1,
            "z": 2,
            "elements": [
                "minecraft:carpet@0"
            ]
        },
        {
            "x": -7,
            "y": 24,
            "z": 6,
            "elements": [
                "futuremc:smooth_stone@0"
            ]
        },
        {
            "x": -15,
            "y": 24,
            "z": 8,
            "elements": [
                "futuremc:smooth_stone@0"
            ]
        },
        {
            "x": -5,
            "y": 24,
            "z": 5,
            "elements": [
                "futuremc:smooth_stone@0"
            ]
        },
        {
            "x": 10,
            "y": 24,
            "z": 3,
            "elements": [
                "futuremc:smooth_stone@0"
            ]
        },
        {
            "x": -2,
            "y": 4,
            "z": 1,
            "elements": [
                "minecraft:carpet@0"
            ]
        },
        {
            "x": -15,
            "y": 24,
            "z": 16,
            "elements": [
                "futuremc:smooth_stone@0"
            ]
        },
        {
            "x": -2,
            "y": 18,
            "z": 3,
            "elements": [
                "futuremc:smooth_stone@0"
            ]
        },
        {
            "x": -2,
            "y": 4,
            "z": -2,
            "elements": [
                "minecraft:carpet@0"
            ]
        },
        {
            "x": 7,
            "y": 24,
            "z": 14,
            "elements": [
                "futuremc:smooth_stone@0"
            ]
        },
        {
            "x": 14,
            "y": 24,
            "z": -6,
            "elements": [
                "futuremc:smooth_stone@0"
            ]
        },
        {
            "x": -8,
            "y": 24,
            "z": 3,
            "elements": [
                "futuremc:smooth_stone@0"
            ]
        },
        {
            "x": -4,
            "y": 1,
            "z": -1,
            "elements": [
                "minecraft:stone_slab@0"
            ]
        },
        {
            "x": 1,
            "y": 18,
            "z": 4,
            "elements": [
                "futuremc:smooth_stone@0"
            ]
        },
        {
            "x": 9,
            "y": 24,
            "z": -5,
            "elements": [
                "futuremc:smooth_stone@0"
            ]
        },
        {
            "x": 12,
            "y": 24,
            "z": -6,
            "elements": [
                "futuremc:smooth_stone@0"
            ]
        },
        {
            "x": 6,
            "y": 24,
            "z": -11,
            "elements": [
                "futuremc:smooth_stone@0"
            ]
        },
        {
            "x": -2,
            "y": 5,
            "z": 2,
            "elements": [
                "minecraft:carpet@0"
            ]
        },
        {
            "x": -2,
            "y": 24,
            "z": 11,
            "elements": [
                "futuremc:smooth_stone@0"
            ]
        },
        {
            "x": -8,
            "y": 24,
            "z": 6,
            "elements": [
                "futuremc:smooth_stone@0"
            ]
        },
        {
            "x": -4,
            "y": 1,
            "z": 2,
            "elements": [
                "minecraft:stone_slab@0"
            ]
        },
        {
            "x": -5,
            "y": 24,
            "z": 4,
            "elements": [
                "futuremc:smooth_stone@0"
            ]
        },
        {
            "x": 7,
            "y": 24,
            "z": 3,
            "elements": [
                "futuremc:smooth_stone@0"
            ]
        },
        {
            "x": 8,
            "y": 24,
            "z": 17,
            "elements": [
                "futuremc:smooth_stone@0"
            ]
        },
        {
            "x": 1,
            "y": 0,
            "z": -2,
            "elements": [
                "futuremc:smooth_stone@0"
            ]
        },
        {
            "x": 12,
            "y": 24,
            "z": -3,
            "elements": [
                "futuremc:smooth_stone@0"
            ]
        },
        {
            "x": -10,
            "y": 24,
            "z": -2,
            "elements": [
                "futuremc:smooth_stone@0"
            ]
        },
        {
            "x": 4,
            "y": 5,
            "z": 3,
            "elements": [
                "minecraft:carpet@0"
            ]
        },
        {
            "x": -2,
            "y": 24,
            "z": 5,
            "elements": [
                "futuremc:smooth_stone@0"
            ]
        },
        {
            "x": 2,
            "y": 4,
            "z": 6,
            "elements": [
                "minecraft:carpet@0"
            ]
        },
        {
            "x": -2,
            "y": 9,
            "z": 4,
            "elements": [
                "futuremc:smooth_stone@0"
            ]
        },
        {
            "x": 2,
            "y": 3,
            "z": -1,
            "elements": [
                "futuremc:smooth_stone@0"
            ]
        },
        {
            "x": 4,
            "y": 24,
            "z": -1,
            "elements": [
                "futuremc:smooth_stone@0"
            ]
        },
        {
            "x": -2,
            "y": 15,
            "z": 3,
            "elements": [
                "futuremc:smooth_stone@0"
            ]
        },
        {
            "x": 14,
            "y": 24,
            "z": 2,
            "elements": [
                "futuremc:smooth_stone@0"
            ]
        },
        {
            "x": 4,
            "y": 4,
            "z": 3,
            "elements": [
                "minecraft:carpet@0"
            ]
        },
        {
            "x": 6,
            "y": 24,
            "z": -5,
            "elements": [
                "futuremc:smooth_stone@0"
            ]
        },
        {
            "x": -4,
            "y": 3,
            "z": -1,
            "elements": [
                "futuremc:smooth_stone@0"
            ]
        },
        {
            "x": -4,
            "y": 3,
            "z": 2,
            "elements": [
                "futuremc:smooth_stone@0"
            ]
        },
        {
            "x": 1,
            "y": 1,
            "z": 2,
            "elements": [
                "minecraft:carpet@0"
            ]
        },
        {
            "x": 1,
            "y": 15,
            "z": 4,
            "elements": [
                "futuremc:smooth_stone@0"
            ]
        },
        {
            "x": -11,
            "y": 24,
            "z": 4,
            "elements": [
                "futuremc:smooth_stone@0"
            ]
        },
        {
            "x": -13,
            "y": 24,
            "z": 13,
            "elements": [
                "futuremc:smooth_stone@0"
            ]
        },
        {
            "x": -8,
            "y": 24,
            "z": 10,
            "elements": [
                "futuremc:smooth_stone@0"
            ]
        },
        {
            "x": -2,
            "y": 0,
            "z": -2,
            "elements": [
                "futuremc:smooth_stone@0"
            ]
        },
        {
            "x": 13,
            "y": 24,
            "z": 14,
            "elements": [
                "futuremc:smooth_stone@0"
            ]
        },
        {
            "x": -13,
            "y": 24,
            "z": -12,
            "elements": [
                "futuremc:smooth_stone@0"
            ]
        },
        {
            "x": -2,
            "y": 21,
            "z": 4,
            "elements": [
                "futuremc:smooth_stone@0"
            ]
        },
        {
            "x": 1,
            "y": 24,
            "z": 5,
            "elements": [
                "futuremc:smooth_stone@0"
            ]
        },
        {
            "x": -15,
            "y": 24,
            "z": -2,
            "elements": [
                "futuremc:smooth_stone@0"
            ]
        },
        {
            "x": 6,
            "y": 24,
            "z": -4,
            "elements": [
                "futuremc:smooth_stone@0"
            ]
        },
        {
            "x": 15,
            "y": 24,
            "z": -4,
            "elements": [
                "futuremc:smooth_stone@0"
            ]
        },
        {
            "x": 3,
            "y": 24,
            "z": -5,
            "elements": [
                "futuremc:smooth_stone@0"
            ]
        },
        {
            "x": 4,
            "y": 3,
            "z": 3,
            "elements": [
                "futuremc:smooth_stone@0"
            ]
        },
        {
            "x": -6,
            "y": 24,
            "z": -7,
            "elements": [
                "futuremc:smooth_stone@0"
            ]
        },
        {
            "x": -3,
            "y": 0,
            "z": 1,
            "elements": [
                "futuremc:smooth_stone@0"
            ]
        },
        {
            "x": 12,
            "y": 24,
            "z": -10,
            "elements": [
                "futuremc:smooth_stone@0"
            ]
        },
        {
            "x": 0,
            "y": 4,
            "z": -2,
            "elements": [
                "minecraft:carpet@0"
            ]
        },
        {
            "x": -3,
            "y": 4,
            "z": 6,
            "elements": [
                "minecraft:carpet@0"
            ]
        },
        {
            "x": -14,
            "y": 24,
            "z": -7,
            "elements": [
                "futuremc:smooth_stone@0"
            ]
        },
        {
            "x": -3,
            "y": 24,
            "z": 16,
            "elements": [
                "futuremc:smooth_stone@0"
            ]
        },
        {
            "x": 0,
            "y": 24,
            "z": 15,
            "elements": [
                "futuremc:smooth_stone@0"
            ]
        },
        {
            "x": 0,
            "y": 24,
            "z": -11,
            "elements": [
                "futuremc:smooth_stone@0"
            ]
        },
        {
            "x": 4,
            "y": 4,
            "z": 5,
            "elements": [
                "minecraft:carpet@0"
            ]
        },
        {
            "x": -3,
            "y": 3,
            "z": -1,
            "elements": [
                "futuremc:smooth_stone@0"
            ]
        },
        {
            "x": -14,
            "y": 24,
            "z": 6,
            "elements": [
                "futuremc:smooth_stone@0"
            ]
        },
        {
            "x": 15,
            "y": 24,
            "z": -1,
            "elements": [
                "futuremc:smooth_stone@0"
            ]
        },
        {
            "x": 3,
            "y": 0,
            "z": 6,
            "elements": [
                "futuremc:smooth_stone@0"
            ]
        },
        {
            "x": -3,
            "y": 24,
            "z": -10,
            "elements": [
                "futuremc:smooth_stone@0"
            ]
        },
        {
            "x": -1,
            "y": 5,
            "z": -1,
            "elements": [
                "minecraft:carpet@0"
            ]
        },
        {
            "x": -14,
            "y": 24,
            "z": 8,
            "elements": [
                "futuremc:smooth_stone@0"
            ]
        },
        {
            "x": 6,
            "y": 24,
            "z": 17,
            "elements": [
                "futuremc:smooth_stone@0"
            ]
        },
        {
            "x": -12,
            "y": 24,
            "z": -12,
            "elements": [
                "futuremc:smooth_stone@0"
            ]
        },
        {
            "x": 2,
            "y": 12,
            "z": 0,
            "elements": [
                "futuremc:smooth_stone@0"
            ]
        },
        {
            "x": 1,
            "y": 24,
            "z": 4,
            "elements": [
                "futuremc:smooth_stone@0"
            ]
        },
        {
            "x": -8,
            "y": 24,
            "z": 5,
            "elements": [
                "futuremc:smooth_stone@0"
            ]
        },
        {
            "x": 7,
            "y": 24,
            "z": 11,
            "elements": [
                "futuremc:smooth_stone@0"
            ]
        },
        {
            "x": 4,
            "y": 3,
            "z": 5,
            "elements": [
                "futuremc:smooth_stone@0"
            ]
        },
        {
            "x": 0,
            "y": 3,
            "z": -1,
            "elements": [
                "futuremc:smooth_stone@0"
            ]
        },
        {
            "x": -1,
            "y": 15,
            "z": 0,
            "elements": [
                "futuremc:smooth_stone@0"
            ]
        },
        {
            "x": 10,
            "y": 24,
            "z": 14,
            "elements": [
                "futuremc:smooth_stone@0"
            ]
        },
        {
            "x": 1,
            "y": 21,
            "z": 4,
            "elements": [
                "futuremc:smooth_stone@0"
            ]
        },
        {
            "x": -2,
            "y": 24,
            "z": 9,
            "elements": [
                "futuremc:smooth_stone@0"
            ]
        },
        {
            "x": -14,
            "y": 24,
            "z": 1,
            "elements": [
                "futuremc:smooth_stone@0"
            ]
        },
        {
            "x": -15,
            "y": 24,
            "z": -7,
            "elements": [
                "futuremc:smooth_stone@0"
            ]
        },
        {
            "x": 11,
            "y": 24,
            "z": 0,
            "elements": [
                "futuremc:smooth_stone@0"
            ]
        },
        {
            "x": 0,
            "y": 24,
            "z": 16,
            "elements": [
                "futuremc:smooth_stone@0"
            ]
        },
        {
            "x": -8,
            "y": 24,
            "z": 8,
            "elements": [
                "futuremc:smooth_stone@0"
            ]
        },
        {
            "x": 3,
            "y": 24,
            "z": -11,
            "elements": [
                "futuremc:smooth_stone@0"
            ]
        },
        {
            "x": 7,
            "y": 24,
            "z": 12,
            "elements": [
                "futuremc:smooth_stone@0"
            ]
        },
        {
            "x": 2,
            "y": 9,
            "z": 0,
            "elements": [
                "futuremc:smooth_stone@0"
            ]
        },
        {
            "x": 15,
            "y": 24,
            "z": -8,
            "elements": [
                "futuremc:smooth_stone@0"
            ]
        },
        {
            "x": -15,
            "y": 24,
            "z": 13,
            "elements": [
                "futuremc:smooth_stone@0"
            ]
        },
        {
            "x": 12,
            "y": 24,
            "z": -5,
            "elements": [
                "futuremc:smooth_stone@0"
            ]
        },
        {
            "x": -11,
            "y": 24,
            "z": 6,
            "elements": [
                "futuremc:smooth_stone@0"
            ]
        },
        {
            "x": -4,
            "y": 0,
            "z": -2,
            "elements": [
                "futuremc:smooth_stone@0"
            ]
        },
        {
            "x": 0,
            "y": 0,
            "z": 1,

            "elements": [
                "futuremc:smooth_stone@0"
            ]
        },
        {
            "x": 4,
            "y": 5,
            "z": 5,
            "elements": [
                "minecraft:carpet@0"
            ]
        },
        {
            "x": 4,
            "y": 24,
            "z": 11,
            "elements": [
                "futuremc:smooth_stone@0"
            ]
        },
        {
            "x": -2,
            "y": 24,
            "z": 4,
            "elements": [
                "futuremc:smooth_stone@0"
            ]
        },
        {
            "x": -11,
            "y": 24,
            "z": 8,
            "elements": [
                "futuremc:smooth_stone@0"
            ]
        },
        {
            "x": 0,
            "y": 2,
            "z": 6,

            "elements": [
                "modularmachinery:blocksmartinterface"
            ]
        },
        {
            "x": 2,
            "y": 4,
            "z": -2,
            "elements": [
                "minecraft:carpet@0"
            ]
        },
        {
            "x": -8,
            "y": 24,
            "z": -7,
            "elements": [
                "futuremc:smooth_stone@0"
            ]
        },
        {
            "x": -3,
            "y": 24,
            "z": -12,
            "elements": [
                "futuremc:smooth_stone@0"
            ]
        },
        {
            "x": 11,
            "y": 24,
            "z": 14,
            "elements": [
                "futuremc:smooth_stone@0"
            ]
        },
        {
            "x": -11,
            "y": 24,
            "z": 1,
            "elements": [
                "futuremc:smooth_stone@0"
            ]
        },
        {
            "x": -1,
            "y": 0,
            "z": 1,

            "elements": [
                "futuremc:smooth_stone@0"
            ]
        },
        {
            "x": -13,
            "y": 24,
            "z": 1,
            "elements": [
                "futuremc:smooth_stone@0"
            ]
        },
        {
            "x": -3,
            "y": 24,
            "z": 9,
            "elements": [
                "futuremc:smooth_stone@0"
            ]
        },
        {
            "x": -4,
            "y": 24,
            "z": 0,
            "elements": [
                "futuremc:smooth_stone@0"
            ]
        },
        {
            "x": -5,
            "y": 24,
            "z": 8,
            "elements": [
                "futuremc:smooth_stone@0"
            ]
        },
        {
            "x": -6,
            "y": 24,
            "z": -11,
            "elements": [
                "futuremc:smooth_stone@0"
            ]
        },
        {
            "x": 12,
            "y": 24,
            "z": 7,
            "elements": [
                "futuremc:smooth_stone@0"
            ]
        },
        {
            "x": -9,
            "y": 24,
            "z": 16,
            "elements": [
                "futuremc:smooth_stone@0"
            ]
        },
        {
            "x": 10,
            "y": 24,
            "z": 12,
            "elements": [
                "futuremc:smooth_stone@0"
            ]
        },
        {
            "x": 15,
            "y": 24,
            "z": 17,
            "elements": [
                "futuremc:smooth_stone@0"
            ]
        },
        {
            "x": -3,
            "y": 5,
            "z": -1,
            "elements": [
                "minecraft:carpet@0"
            ]
        },
        {
            "x": -3,
            "y": 4,
            "z": 1,
            "elements": [
                "minecraft:carpet@0"
            ]
        },
        {
            "x": 1,
            "y": 24,
            "z": 11,
            "elements": [
                "futuremc:smooth_stone@0"
            ]
        },
        {
            "x": -5,
            "y": 24,
            "z": -7,
            "elements": [
                "futuremc:smooth_stone@0"
            ]
        },
        {
            "x": -2,
            "y": 3,
            "z": -1,
            "elements": [
                "futuremc:smooth_stone@0"
            ]
        },
        {
            "x": -7,
            "y": 24,
            "z": 0,
            "elements": [
                "futuremc:smooth_stone@0"
            ]
        },
        {
            "x": -6,
            "y": 24,
            "z": -12,
            "elements": [
                "futuremc:smooth_stone@0"
            ]
        },
        {
            "x": -1,
            "y": 4,
            "z": -2,
            "elements": [
                "minecraft:carpet@0"
            ]
        },
        {
            "x": 15,
            "y": 24,
            "z": -6,
            "elements": [
                "futuremc:smooth_stone@0"
            ]
        },
        {
            "x": 12,
            "y": 24,
            "z": 14,
            "elements": [
                "futuremc:smooth_stone@0"
            ]
        },
        {
            "x": -2,
            "y": 0,
            "z": 1,
            "elements": [
                "futuremc:smooth_stone@0"
            ]
        },
        {
            "x": 4,
            "y": 24,
            "z": 10,
            "elements": [
                "futuremc:smooth_stone@0"
            ]
        },
        {
            "x": 0,
            "y": 4,
            "z": 6,
            "elements": [
                "minecraft:carpet@0"
            ]
        },
        {
            "x": 7,
            "y": 24,
            "z": 10,
            "elements": [
                "futuremc:smooth_stone@0"
            ]
        },
        {
            "x": 3,
            "y": 24,
            "z": 15,
            "elements": [
                "futuremc:smooth_stone@0"
            ]
        },
        {
            "x": 9,
            "y": 24,
            "z": 7,
            "elements": [
                "futuremc:smooth_stone@0"
            ]
        },
        {
            "x": -5,
            "y": 24,
            "z": 11,
            "elements": [
                "futuremc:smooth_stone@0"
            ]
        },
        {
            "x": -4,
            "y": 5,
            "z": -1,
            "elements": [
                "minecraft:carpet@0"
            ]
        },
        {
            "x": -4,
            "y": 4,
            "z": 1,
            "elements": [
                "minecraft:carpet@0"
            ]
        },
        {
            "x": 9,
            "y": 24,
            "z": -8,
            "elements": [
                "futuremc:smooth_stone@0"
            ]
        },
        {
            "x": 4,
            "y": 24,
            "z": -9,
            "elements": [
                "futuremc:smooth_stone@0"
            ]
        },
        {
            "x": 13,
            "y": 24,
            "z": 12,
            "elements": [
                "futuremc:smooth_stone@0"
            ]
        },
        {
            "x": 12,
            "y": 24,
            "z": 17,
            "elements": [
                "futuremc:smooth_stone@0"
            ]
        },
        {
            "x": 3,
            "y": 24,
            "z": -4,
            "elements": [
                "futuremc:smooth_stone@0"
            ]
        },
        {
            "x": 0,
            "y": 24,
            "z": -10,
            "elements": [
                "futuremc:smooth_stone@0"
            ]
        },
        {
            "x": 7,
            "y": 24,
            "z": -9,
            "elements": [
                "futuremc:smooth_stone@0"
            ]
        },
        {
            "x": 2,
            "y": 0,
            "z": -2,
            "elements": [
                "futuremc:smooth_stone@0"
            ]
        },
        {
            "x": 9,
            "y": 24,
            "z": 17,
            "elements": [
                "futuremc:smooth_stone@0"
            ]
        },
        {
            "x": -12,
            "y": 24,
            "z": 15,
            "elements": [
                "futuremc:smooth_stone@0"
            ]
        },
        {
            "x": -1,
            "y": 18,
            "z": 0,
            "elements": [
                "futuremc:smooth_stone@0"
            ]
        },
        {
            "x": 2,
            "y": 15,
            "z": 0,
            "elements": [
                "futuremc:smooth_stone@0"
            ]
        },
        {
            "x": -9,
            "y": 24,
            "z": -12,
            "elements": [
                "futuremc:smooth_stone@0"
            ]
        },
        {
            "x": -1,
