{
    "registryname": "9x_neutron_platemk1",
    "localizedname": "§e压缩§7中子素吸吸积盘§2MK1",
    "failure-action": "still",
    "has-factory": true,
    "requires-blueprint": false,
    "color": "DDE6DF",
    "parts": [
        {
            "x": 0,
            "y": 7,
            "z": 9,
            "elements": [
                "nuclearcraft:ingot_block@9"
            ]
        },
        {
            "x": -4,
            "y": 2,
            "z": 3,
            "elements": [
                "ic2:fence@0"
            ]
        },
        {
            "x": -4,
            "y": 2,
            "z": 2,
            "elements": [
                "ic2:fence@0"
            ]
        },
        {
            "x": 1,
            "y": 8,
            "z": 10,
            "elements": [
                "nuclearcraft:ingot_block@9"
            ]
        },
        {
            "x": -1,
            "y": 6,
            "z": 2,
            "elements": [
                "chisel:blockiron@4"
            ]
        },
        {
            "x": -1,
            "y": 6,
            "z": 3,
            "elements": [
                "chisel:blockiron@4"
            ]
        },
        {
            "x": -1,
            "y": 6,
            "z": 8,
            "elements": [
                "nuclearcraft:ingot_block@9"
            ]
        },
        {
            "x": 0,
            "y": 7,
            "z": -4,
            "elements": [
                "nuclearcraft:ingot_block@9"
            ]
        },
        {
            "x": -1,
            "y": 6,
            "z": 9,
            "elements": [
                "chisel:blockaluminum@6"
            ]
        },
        {
            "x": -1,
            "y": 6,
            "z": 7,
            "elements": [
                "nuclearcraft:ingot_block@9"
            ]
        },
        {
            "x": -1,
            "y": 6,
            "z": -4,
            "elements": [
                "chisel:blockaluminum@6"
            ]
        },
        {
            "x": -1,
            "y": 6,
            "z": -3,
            "elements": [
                "nuclearcraft:ingot_block@9"
            ]
        },
        {
            "x": -1,
            "y": 6,
            "z": -2,
            "elements": [
                "nuclearcraft:ingot_block@9"
            ]
        },
        {
            "x": -2,
            "y": 4,
            "z": 6,
            "elements": [
                "chisel:blockaluminum@6"
            ]
        },
        {
            "x": -2,
            "y": 4,
            "z": 5,
            "elements": [
                "chisel:blockaluminum@6"
            ]
        },
        {
            "x": -2,
            "y": 4,
            "z": 0,
            "elements": [
                "chisel:blockaluminum@6"
            ]
        },
        {
            "x": -2,
            "y": 4,
            "z": -1,
            "elements": [
                "chisel:blockaluminum@6"
            ]
        },
        {
            "x": -2,
            "y": 4,
            "z": 2,
            "elements": [
                "chisel:blockiron@4"
            ]
        },
        {
            "x": -2,
            "y": 4,
            "z": 1,
            "elements": [
                "chisel:blockaluminum@6"
            ]
        },
        {
            "x": -2,
            "y": 4,
            "z": 4,
            "elements": [
                "chisel:blockaluminum@6"
            ]
        },
        {
            "x": -2,
            "y": 4,
            "z": 3,
            "elements": [
                "chisel:blockiron@4"
            ]
        },
        {
            "x": 0,
            "y": 8,
            "z": -5,
            "elements": [
                "nuclearcraft:ingot_block@9"
            ]
        },
        {
            "x": -9,
            "y": 8,
            "z": 5,
            "elements": [
                "nuclearcraft:ingot_block@9"
            ]
        },
        {
            "x": -9,
            "y": 8,
            "z": 4,
            "elements": [
                "nuclearcraft:ingot_block@9"
            ]
        },
        {
            "x": -9,
            "y": 8,
            "z": 6,
            "elements": [
                "nuclearcraft:ingot_block@9"
            ]
        },
        {
            "x": -9,
            "y": 8,
            "z": 1,
            "elements": [
                "nuclearcraft:ingot_block@9"
            ]
        },
        {
            "x": -9,
            "y": 8,
            "z": 0,
            "elements": [
                "nuclearcraft:ingot_block@9"
            ]
        },
        {
            "x": -9,
            "y": 8,
            "z": 3,
            "elements": [
                "nuclearcraft:ingot_block@9"
            ]
        },
        {
            "x": -9,
            "y": 8,
            "z": 2,
            "elements": [
                "nuclearcraft:ingot_block@9"
            ]
        },
        {
            "x": -2,
            "y": 5,
            "z": 1,
            "elements": [
                "nuclearcraft:ingot_block@9"
            ]
        },
        {
            "x": 1,
            "y": 7,
            "z": 9,
            "elements": [
                "nuclearcraft:ingot_block@9"
            ]
        },
        {
            "x": -2,
            "y": 5,
            "z": 0,
            "elements": [
                "nuclearcraft:ingot_block@9"
            ]
        },
        {
            "x": -2,
            "y": 5,
            "z": 3,
            "elements": [
                "chisel:blockiron@4"
            ]
        },
        {
            "x": -2,
            "y": 5,
            "z": 2,
            "elements": [
                "chisel:blockiron@4"
            ]
        },
        {
            "x": -2,
            "y": 5,
            "z": -3,
            "elements": [
                "chisel:blockaluminum@6"
            ]
        },
        {
            "x": -2,
            "y": 5,
            "z": -1,
            "elements": [
                "nuclearcraft:ingot_block@9"
            ]
        },
        {
            "x": -2,
            "y": 5,
            "z": -2,
            "elements": [
                "chisel:blockaluminum@6"
            ]
        },
        {
            "x": -2,
            "y": 5,
            "z": 8,
            "elements": [
                "chisel:blockaluminum@6"
            ]
        },
        {
            "x": -2,
            "y": 5,
            "z": 5,
            "elements": [
                "nuclearcraft:ingot_block@9"
            ]
        },
        {
            "x": -2,
            "y": 5,
            "z": 4,
            "elements": [
                "nuclearcraft:ingot_block@9"
            ]
        },
        {
            "x": -2,
            "y": 5,
            "z": 7,
            "elements": [
                "chisel:blockaluminum@6"
            ]
        },
        {
            "x": -2,
            "y": 5,
            "z": 6,
            "elements": [
                "nuclearcraft:ingot_block@9"
            ]
        },
        {
            "x": 0,
            "y": 8,
            "z": 10,
            "elements": [
                "nuclearcraft:ingot_block@9"
            ]
        },
        {
            "x": 2,
            "y": 8,
            "z": -5,
            "elements": [
                "nuclearcraft:ingot_block@9"
            ]
        },
        {
            "x": -2,
            "y": 6,
            "z": 3,
            "elements": [
                "chisel:blockiron@4"
            ]
        },
        {
            "x": 2,
            "y": 8,
            "z": 10,
            "elements": [
                "nuclearcraft:ingot_block@9"
            ]
        },
        {
            "x": -2,
            "y": 6,
            "z": 8,
            "elements": [
                "nuclearcraft:ingot_block@9"
            ]
        },
        {
            "x": -2,
            "y": 6,
            "z": 7,
            "elements": [
                "nuclearcraft:ingot_block@9"
            ]
        },
        {
            "x": -2,
            "y": 6,
            "z": 9,
            "elements": [
                "chisel:blockaluminum@6"
            ]
        },
        {
            "x": 1,
            "y": 7,
            "z": -4,
            "elements": [
                "nuclearcraft:ingot_block@9"
            ]
        },
        {
            "x": -2,
            "y": 3,
            "z": 3,
            "elements": [
                "chisel:blockiron@4"
            ]
        },
        {
            "x": -2,
            "y": 3,
            "z": 2,
            "elements": [
                "chisel:blockiron@4"
            ]
        },
        {
            "x": -4,
            "y": 4,
            "z": 3,
            "elements": [
                "chisel:blockaluminum@6"
            ]
        },
        {
            "x": -2,
            "y": 3,
            "z": 5,
            "elements": [
                "ic2:fence@0"
            ]
        },
        {
            "x": -4,
            "y": 4,
            "z": 2,
            "elements": [
                "chisel:blockaluminum@6"
            ]
        },
        {
            "x": -2,
            "y": 3,
            "z": 0,
            "elements": [
                "ic2:fence@0"
            ]
        },
        {
            "x": 1,
            "y": 6,
            "z": 8,
            "elements": [
                "nuclearcraft:ingot_block@9"
            ]
        },
        {
            "x": 1,
            "y": 6,
            "z": 7,
            "elements": [
                "nuclearcraft:ingot_block@9"
            ]
        },
        {
            "x": -4,
            "y": 1,
            "z": 2,
            "elements": [
                "ic2:fence@0"
            ]
        },
        {
            "x": -4,
            "y": 1,
            "z": 3,
            "elements": [
                "ic2:fence@0"
            ]
        },
        {
            "x": 1,
            "y": 6,
            "z": -2,
            "elements": [
                "nuclearcraft:ingot_block@9"
            ]
        },
        {
            "x": 1,
            "y": 6,
            "z": -3,
            "elements": [
                "nuclearcraft:ingot_block@9"
            ]
        },
        {
            "x": -1,
            "y": 5,
            "z": 2,
            "elements": [
                "chisel:blockiron@4"
            ]
        },
        {
            "x": -1,
            "y": 5,
            "z": 1,
            "elements": [
                "nuclearcraft:ingot_block@9"
            ]
        },
        {
            "x": -1,
            "y": 5,
            "z": 0,
            "elements": [
                "nuclearcraft:ingot_block@9"
            ]
        },
        {
            "x": -1,
            "y": 5,
            "z": -1,
            "elements": [
                "nuclearcraft:ingot_block@9"
            ]
        },
        {
            "x": -1,
            "y": 5,
            "z": -2,
            "elements": [
                "chisel:blockaluminum@6"
            ]
        },
        {
            "x": -1,
            "y": 5,
            "z": -3,
            "elements": [
                "chisel:blockaluminum@6"
            ]
        },
        {
            "x": -3,
            "y": 4,
            "z": 3,
            "elements": [
                "chisel:blockaluminum@6"
            ]
        },
        {
            "x": -3,
            "y": 4,
            "z": 2,
            "elements": [
                "chisel:blockaluminum@6"
            ]
        },
        {
            "x": -8,
            "y": 8,
            "z": -3,
            "elements": [
                "nuclearcraft:ingot_block@9"
            ]
        },
        {
            "x": -8,
            "y": 8,
            "z": -2,
            "elements": [
                "nuclearcraft:ingot_block@9"
            ]
        },
        {
            "x": -2,
            "y": 15,
            "z": 3,
            "elements": [
                "modularmachinery:blockcasing@1"
            ]
        },
        {
            "x": -2,
            "y": 15,
            "z": 2,
            "elements": [
                "modularmachinery:blockcasing@1"
            ]
        },
        {
            "x": -1,
            "y": 8,
            "z": -5,
            "elements": [
                "nuclearcraft:ingot_block@9"
            ]
        },
        {
            "x": -1,
            "y": 8,
            "z": 2,
            "elements": [
                "chisel:blockiron@4"
            ]
        },
        {
            "x": -2,
            "y": 6,
            "z": -4,
            "elements": [
                "chisel:blockaluminum@6"
            ]
        },
        {
            "x": -1,
            "y": 8,
            "z": 3,
            "elements": [
                "chisel:blockiron@4"
            ]
        },
        {
            "x": -2,
            "y": 6,
            "z": -2,
            "elements": [
                "nuclearcraft:ingot_block@9"
            ]
        },
        {
            "x": -2,
            "y": 6,
            "z": -3,
            "elements": [
                "nuclearcraft:ingot_block@9"
            ]
        },
        {
            "x": 0,
            "y": 4,
            "z": 3,
            "elements": [
                "chisel:blockaluminum@6"
            ]
        },
        {
            "x": -2,
            "y": 6,
            "z": 2,
            "elements": [
                "chisel:blockiron@4"
            ]
        },
        {
            "x": -8,
            "y": 8,
            "z": 7,
            "elements": [
                "nuclearcraft:ingot_block@9"
            ]
        },
        {
            "x": -8,
            "y": 8,
            "z": 8,
            "elements": [
                "nuclearcraft:ingot_block@9"
            ]
        },
        {
            "x": -1,
            "y": 8,
            "z": 10,
            "elements": [
                "nuclearcraft:ingot_block@9"
            ]
        },
        {
            "x": -1,
            "y": 5,
            "z": 8,
            "elements": [
                "chisel:blockaluminum@6"
            ]
        },
        {
            "x": -1,
            "y": 5,
            "z": 7,
            "elements": [
                "chisel:blockaluminum@6"
            ]
        },
        {
            "x": -1,
            "y": 5,
            "z": 6,
            "elements": [
                "nuclearcraft:ingot_block@9"
            ]
        },
        {
            "x": -1,
            "y": 5,
            "z": 5,
            "elements": [
                "nuclearcraft:ingot_block@9"
            ]
        },
        {
            "x": -1,
            "y": 5,
            "z": 4,
            "elements": [
                "nuclearcraft:ingot_block@9"
            ]
        },
        {
            "x": -1,
            "y": 5,
            "z": 3,
            "elements": [
                "chisel:blockiron@4"
            ]
        },
        {
            "x": -8,
            "y": 7,
            "z": 2,
            "elements": [
                "nuclearcraft:ingot_block@9"
            ]
        },
        {
            "x": -3,
            "y": 0,
            "z": 2,
            "elements": [
                "chisel:blockiron@4"
            ]
        },
        {
            "x": -3,
            "y": 0,
            "z": 3,
            "elements": [
                "chisel:blockiron@4"
            ]
        },
        {
            "x": -8,
            "y": 7,
            "z": 3,
            "elements": [
                "nuclearcraft:ingot_block@9"
            ]
        },
        {
            "x": -8,
            "y": 7,
            "z": 0,
            "elements": [
                "nuclearcraft:ingot_block@9"
            ]
        },
        {
            "x": -2,
            "y": 8,
            "z": -5,
            "elements": [
                "nuclearcraft:ingot_block@9"
            ]
        },
        {
            "x": -3,
            "y": 0,
            "z": 5,
            "elements": [
                "chisel:blockiron@4"
            ]
        },
        {
            "x": -8,
            "y": 7,
            "z": 1,
            "elements": [
                "nuclearcraft:ingot_block@9"
            ]
        },
        {
            "x": -8,
            "y": 7,
            "z": 6,
            "elements": [
                "nuclearcraft:ingot_block@9"
            ]
        },
        {
            "x": -8,
            "y": 7,
            "z": 4,
            "elements": [
                "nuclearcraft:ingot_block@9"
            ]
        },
        {
            "x": -8,
            "y": 7,
            "z": 5,
            "elements": [
                "nuclearcraft:ingot_block@9"
            ]
        },
        {
            "x": -1,
            "y": 9,
            "z": 3,
            "elements": [
                "chisel:blockiron@4"
            ]
        },
        {
            "x": -1,
            "y": 9,
            "z": 2,
            "elements": [
                "chisel:blockiron@4"
            ]
        },
        {
            "x": -2,
            "y": 8,
            "z": 10,
            "elements": [
                "nuclearcraft:ingot_block@9"
            ]
        },
        {
            "x": -2,
            "y": 1,
            "z": 5,
            "elements": [
                "ic2:fence@0"
            ]
        },
        {
            "x": -2,
            "y": 1,
            "z": 2,
            "elements": [
                "chisel:blockiron@4"
            ]
        },
        {
            "x": -2,
            "y": 1,
            "z": 3,
            "elements": [
                "chisel:blockiron@4"
            ]
        },
        {
            "x": -2,
            "y": 1,
            "z": 0,
            "elements": [
                "ic2:fence@0"
            ]
        },
        {
            "x": -2,
            "y": 8,
            "z": 2,
            "elements": [
                "chisel:blockiron@4"
            ]
        },
        {
            "x": -2,
            "y": 8,
            "z": 3,
            "elements": [
                "chisel:blockiron@4"
            ]
        },
        {
            "x": -3,
            "y": 0,
            "z": 0,
            "elements": [
                "item_out"
            ]
        },
        {
            "x": -1,
            "y": 3,
            "z": 3,
            "elements": [
                "chisel:blockiron@4"
            ]
        },
        {
            "x": -1,
            "y": 3,
            "z": 2,
            "elements": [
                "chisel:blockiron@4"
            ]
        },
        {
            "x": -1,
            "y": 3,
            "z": 0,
            "elements": [
                "ic2:fence@0"
            ]
        },
        {
            "x": -2,
            "y": 14,
            "z": 2,
            "elements": [
                "avaritia:block_resource@0"
            ]
        },
        {
            "x": -1,
            "y": 3,
            "z": 5,
            "elements": [
                "ic2:fence@0"
            ]
        },
        {
            "x": -2,
            "y": 14,
            "z": 3,
            "elements": [
                "avaritia:block_resource@0"
            ]
        },
        {
            "x": -8,
            "y": 7,
            "z": -1,
            "elements": [
                "nuclearcraft:ingot_block@9"
            ]
        },
        {
            "x": -2,
            "y": 7,
            "z": 10,
            "elements": [
                "chisel:blockaluminum@6"
            ]
        },
        {
            "x": -2,
            "y": 7,
            "z": 9,
            "elements": [
                "nuclearcraft:ingot_block@9"
            ]
        },
        {
            "x": -2,
            "y": 7,
            "z": 3,
            "elements": [
                "chisel:blockiron@4"
            ]
        },
        {
            "x": -2,
            "y": 7,
            "z": 2,
            "elements": [
                "chisel:blockiron@4"
            ]
        },
        {
            "x": -1,
            "y": 15,
            "z": 2,
            "elements": [
                "modularmachinery:blockcasing@1"
            ]
        },
        {
            "x": -2,
            "y": 7,
            "z": -5,
            "elements": [
                "chisel:blockaluminum@6"
            ]
        },
        {
            "x": -2,
            "y": 7,
            "z": -4,
            "elements": [
                "nuclearcraft:ingot_block@9"
            ]
        },
        {
            "x": -1,
            "y": 15,
            "z": 3,
            "elements": [
                "modularmachinery:blockcasing@1"
            ]
        },
        {
            "x": -8,
            "y": 6,
            "z": 3,
            "elements": [
                "chisel:blockaluminum@6"
            ]
        },
        {
            "x": -8,
            "y": 6,
            "z": 2,
            "elements": [
                "chisel:blockaluminum@6"
            ]
        },
        {
            "x": 0,
            "y": 5,
            "z": 2,
            "elements": [
                "nuclearcraft:ingot_block@9"
            ]
        },
        {
            "x": 0,
            "y": 5,
            "z": 3,
            "elements": [
                "nuclearcraft:ingot_block@9"
            ]
        },
        {
            "x": 0,
            "y": 5,
            "z": 4,
            "elements": [
                "nuclearcraft:ingot_block@9"
            ]
        },
        {
            "x": 0,
            "y": 5,
            "z": 5,
            "elements": [
                "nuclearcraft:ingot_block@9"
            ]
        },
        {
            "x": 0,
            "y": 5,
            "z": 6,
            "elements": [
                "nuclearcraft:ingot_block@9"
            ]
        },
        {
            "x": 3,
            "y": 7,
            "z": 8,
            "elements": [
                "nuclearcraft:ingot_block@9"
            ]
        },
        {
            "x": -7,
            "y": 8,
            "z": -4,
            "elements": [
                "nuclearcraft:ingot_block@9"
            ]
        },
        {
            "x": -7,
            "y": 8,
            "z": -3,
            "elements": [
                "nuclearcraft:ingot_block@9"
            ]
        },
        {
            "x": 3,
            "y": 7,
            "z": -3,
            "elements": [
                "nuclearcraft:ingot_block@9"
            ]
        },
        {
            "x": 0,
            "y": 5,
            "z": -1,
            "elements": [
                "nuclearcraft:ingot_block@9"
            ]
        },
        {
            "x": 0,
            "y": 5,
            "z": 0,
            "elements": [
                "nuclearcraft:ingot_block@9"
            ]
        },
        {
            "x": 0,
            "y": 5,
            "z": 1,
            "elements": [
                "nuclearcraft:ingot_block@9"
            ]
        },
        {
            "x": -7,
            "y": 8,
            "z": 8,
            "elements": [
                "nuclearcraft:ingot_block@9"
            ]
        },
        {
            "x": -7,
            "y": 8,
            "z": 9,
            "elements": [
                "nuclearcraft:ingot_block@9"
            ]
        },
        {
            "x": -3,
            "y": 6,
            "z": -2,
            "elements": [
                "nuclearcraft:ingot_block@9"
            ]
        },
        {
            "x": -3,
            "y": 6,
            "z": -3,
            "elements": [
                "nuclearcraft:ingot_block@9"
            ]
        },
        {
            "x": -2,
            "y": 2,
            "z": 0,
            "elements": [
                "ic2:fence@0"
            ]
        },
        {
            "x": -2,
            "y": 2,
            "z": 2,
            "elements": [
                "chisel:blockiron@4"
            ]
        },
        {
            "x": -3,
            "y": 6,
            "z": 8,
            "elements": [
                "nuclearcraft:ingot_block@9"
            ]
        },
        {
            "x": -3,
            "y": 6,
            "z": 7,
            "elements": [
                "nuclearcraft:ingot_block@9"
            ]
        },
        {
            "x": -2,
            "y": 2,
            "z": 3,
            "elements": [
                "chisel:blockiron@4"
            ]
        },
        {
            "x": -2,
            "y": 2,
            "z": 5,
            "elements": [
                "ic2:fence@0"
            ]
        },
        {
            "x": -3,
            "y": 5,
            "z": 0,
            "elements": [
                "nuclearcraft:ingot_block@9"
            ]
        },
        {
            "x": -3,
            "y": 5,
            "z": -1,
            "elements": [
                "nuclearcraft:ingot_block@9"
            ]
        },
        {
            "x": -3,
            "y": 5,
            "z": 4,
            "elements": [
                "nuclearcraft:ingot_block@9"
            ]
        },
        {
            "x": -3,
            "y": 5,
            "z": 3,
            "elements": [
                "nuclearcraft:ingot_block@9"
            ]
        },
        {
            "x": -3,
            "y": 5,
            "z": 2,
            "elements": [
                "nuclearcraft:ingot_block@9"
            ]
        },
        {
            "x": -3,
            "y": 5,
            "z": 1,
            "elements": [
                "nuclearcraft:ingot_block@9"
            ]
        },
        {
            "x": 3,
            "y": 6,
            "z": -1,
            "elements": [
                "nuclearcraft:ingot_block@9"
            ]
        },
        {
            "x": 3,
            "y": 6,
            "z": -2,
            "elements": [
                "nuclearcraft:ingot_block@9"
            ]
        },
        {
            "x": 3,
            "y": 6,
            "z": 1,
            "elements": [
                "nuclearcraft:ingot_block@9"
            ]
        },
        {
            "x": -2,
            "y": 13,
            "z": 2,
            "elements": [
                "avaritia:block_resource@0"
            ]
        },
        {
            "x": 3,
            "y": 6,
            "z": 0,
            "elements": [
                "nuclearcraft:ingot_block@9"
            ]
        },
        {
            "x": -2,
            "y": 13,
            "z": 3,
            "elements": [
                "avaritia:block_resource@0"
            ]
        },
        {
            "x": 3,
            "y": 6,
            "z": 3,
            "elements": [
                "nuclearcraft:ingot_block@9"
            ]
        },
        {
            "x": 3,
            "y": 6,
            "z": 2,
            "elements": [
                "nuclearcraft:ingot_block@9"
            ]
        },
        {
            "x": 3,
            "y": 6,
            "z": 5,
            "elements": [
                "nuclearcraft:ingot_block@9"
            ]
        },
        {
            "x": 3,
            "y": 6,
            "z": 4,
            "elements": [
                "nuclearcraft:ingot_block@9"
            ]
        },
        {
            "x": -1,
            "y": 4,
            "z": -1,
            "elements": [
                "chisel:blockaluminum@6"
            ]
        },
        {
            "x": -1,
            "y": 4,
            "z": 3,
            "elements": [
                "chisel:blockiron@4"
            ]
        },
        {
            "x": -1,
            "y": 4,
            "z": 2,
            "elements": [
                "chisel:blockiron@4"
            ]
        },
        {
            "x": -1,
            "y": 4,
            "z": 1,
            "elements": [
                "chisel:blockaluminum@6"
            ]
        },
        {
            "x": -1,
            "y": 4,
            "z": 0,
            "elements": [
                "chisel:blockaluminum@6"
            ]
        },
        {
            "x": -1,
            "y": 4,
            "z": 6,
            "elements": [
                "chisel:blockaluminum@6"
            ]
        },
        {
            "x": -3,
            "y": 5,
            "z": 6,
            "elements": [
                "nuclearcraft:ingot_block@9"
            ]
        },
        {
            "x": -1,
            "y": 4,
            "z": 5,
            "elements": [
                "chisel:blockaluminum@6"
            ]
        },
        {
            "x": -1,
            "y": 4,
            "z": 4,
            "elements": [
                "chisel:blockaluminum@6"
            ]
        },
        {
            "x": -3,
            "y": 5,
            "z": 5,
            "elements": [
                "nuclearcraft:ingot_block@9"
            ]
        },
        {
            "x": 0,
            "y": 6,
            "z": -3,
            "elements": [
                "nuclearcraft:ingot_block@9"
            ]
        },
        {
            "x": 0,
            "y": 6,
            "z": -2,
            "elements": [
                "nuclearcraft:ingot_block@9"
            ]
        },
        {
            "x": 0,
            "y": 6,
            "z": 7,
            "elements": [
                "nuclearcraft:ingot_block@9"
            ]
        },
        {
            "x": 0,
            "y": 6,
            "z": 8,
            "elements": [
                "nuclearcraft:ingot_block@9"
            ]
        },
        {
            "x": 4,
            "y": 8,
            "z": -3,
            "elements": [
                "nuclearcraft:ingot_block@9"
            ]
        },
        {
            "x": 4,
            "y": 8,
            "z": -4,
            "elements": [
                "nuclearcraft:ingot_block@9"
            ]
        },
        {
            "x": -1,
            "y": 10,
            "z": 2,
            "elements": [
                "chisel:blockiron@4"
            ]
        },
        {
            "x": -1,
            "y": 10,
            "z": 3,
            "elements": [
                "chisel:blockiron@4"
            ]
        },
        {
            "x": 4,
            "y": 8,
            "z": 9,
            "elements": [
                "nuclearcraft:ingot_block@9"
            ]
        },
        {
            "x": 4,
            "y": 8,
            "z": 8,
            "elements": [
                "nuclearcraft:ingot_block@9"
            ]
        },
        {
            "x": 2,
            "y": 4,
            "z": 2,
            "elements": [
                "chisel:blockaluminum@6"
            ]
        },
        {
            "x": 2,
            "y": 4,
            "z": 3,
            "elements": [
                "chisel:blockaluminum@6"
            ]
        },
        {
            "x": -6,
            "y": 5,
            "z": 2,
            "elements": [
                "chisel:blockaluminum@6"
            ]
        },
        {
            "x": -6,
            "y": 5,
            "z": 3,
            "elements": [
                "chisel:blockaluminum@6"
            ]
        },
        {
            "x": 1,
            "y": 8,
            "z": -5,
            "elements": [
                "nuclearcraft:ingot_block@9"
            ]
        },
        {
            "x": -5,
            "y": 7,
            "z": 9,
            "elements": [
                "nuclearcraft:ingot_block@9"
            ]
        },
        {
            "x": 3,
            "y": 6,
            "z": 7,
            "elements": [
                "nuclearcraft:ingot_block@9"
            ]
        },
        {
            "x": 3,
            "y": 6,
            "z": 6,
            "elements": [
                "nuclearcraft:ingot_block@9"
            ]
        },
        {
            "x": -5,
            "y": 7,
            "z": -4,
            "elements": [
                "nuclearcraft:ingot_block@9"
            ]
        },
        {
            "x": -4,
            "y": 3,
            "z": 2,
            "elements": [
                "ic2:fence@0"
            ]
        },
        {
            "x": -4,
            "y": 3,
            "z": 3,
            "elements": [
                "ic2:fence@0"
            ]
        },
        {
            "x": 6,
            "y": 8,
            "z": -1,
            "elements": [
                "nuclearcraft:ingot_block@9"
            ]
        },
        {
            "x": 6,
            "y": 8,
            "z": 0,
            "elements": [
                "nuclearcraft:ingot_block@9"
            ]
        },
        {
            "x": 6,
            "y": 8,
            "z": 5,
            "elements": [
                "nuclearcraft:ingot_block@9"
            ]
        },
        {
            "x": -6,
            "y": 6,
            "z": 7,
            "elements": [
                "nuclearcraft:ingot_block@9"
            ]
        },
        {
            "x": 6,
            "y": 8,
            "z": 6,
            "elements": [
                "nuclearcraft:ingot_block@9"
            ]
        },
        {
            "x": 6,
            "y": 8,
            "z": 3,
            "elements": [
                "nuclearcraft:ingot_block@9"
            ]
        },
        {
            "x": -7,
            "y": 5,
            "z": 2,
            "elements": [
                "chisel:blockaluminum@6"
            ]
        },
        {
            "x": 6,
            "y": 8,
            "z": 4,
            "elements": [
                "nuclearcraft:ingot_block@9"
            ]
        },
        {
            "x": 6,
            "y": 8,
            "z": 1,
            "elements": [
                "nuclearcraft:ingot_block@9"
            ]
        },
        {
            "x": -7,
            "y": 5,
            "z": 3,
            "elements": [
                "chisel:blockaluminum@6"
            ]
        },
        {
            "x": 6,
            "y": 8,
            "z": 2,
            "elements": [
                "nuclearcraft:ingot_block@9"
            ]
        },
        {
            "x": 0,
            "y": 0,
            "z": 3,
            "elements": [
                "chisel:blockiron@4"
            ]
        },
        {
            "x": 4,
            "y": 5,
            "z": 3,
            "elements": [
                "chisel:blockaluminum@6"
            ]
        },
        {
            "x": 0,
            "y": 0,
            "z": 5,
            "elements": [
                "chisel:blockiron@4"
            ]
        },
        {
            "x": 4,
            "y": 5,
            "z": 2,
            "elements": [
                "chisel:blockaluminum@6"
            ]
        },
        {
            "x": 0,
            "y": 0,
            "z": 2,
            "elements": [
                "chisel:blockiron@4"
            ]
        },
        {
            "x": 1,
            "y": 2,
            "z": 3,
            "elements": [
                "ic2:fence@0"
            ]
        },
        {
            "x": 1,
            "y": 2,
            "z": 2,
            "elements": [
                "ic2:fence@0"
            ]
        },
        {
            "x": -6,
            "y": 6,
            "z": 1,
            "elements": [
                "nuclearcraft:ingot_block@9"
            ]
        },
        {
            "x": -2,
            "y": 11,
            "z": 2,
            "elements": [
                "chisel:blockiron@4"
            ]
        },
        {
            "x": -6,
            "y": 6,
            "z": 2,
            "elements": [
                "nuclearcraft:ingot_block@9"
            ]
        },
        {
            "x": -2,
            "y": 11,
            "z": 3,
            "elements": [
                "chisel:blockiron@4"
            ]
        },
        {
            "x": -4,
            "y": 8,
            "z": 10,
            "elements": [
                "nuclearcraft:ingot_block@9"
            ]
        },
        {
            "x": -6,
            "y": 6,
            "z": -1,
            "elements": [
                "nuclearcraft:ingot_block@9"
            ]
        },
        {
            "x": -6,
            "y": 6,
            "z": 0,
            "elements": [
                "nuclearcraft:ingot_block@9"
            ]
        },
        {
            "x": 5,
            "y": 7,
            "z": 0,
            "elements": [
                "nuclearcraft:ingot_block@9"
            ]
        },
        {
            "x": -6,
            "y": 6,
            "z": 5,
            "elements": [
                "nuclearcraft:ingot_block@9"
            ]
        },
        {
            "x": 5,
            "y": 7,
            "z": -1,
            "elements": [
                "nuclearcraft:ingot_block@9"
            ]
        },
        {
            "x": -6,
            "y": 6,
            "z": 6,
            "elements": [
                "nuclearcraft:ingot_block@9"
            ]
        },
        {
            "x": 5,
            "y": 7,
            "z": 2,
            "elements": [
                "nuclearcraft:ingot_block@9"
            ]
        },
        {
            "x": -6,
            "y": 6,
            "z": 3,
            "elements": [
                "nuclearcraft:ingot_block@9"
            ]
        },
        {
            "x": 5,
            "y": 7,
            "z": 1,
            "elements": [
                "nuclearcraft:ingot_block@9"
            ]
        },
        {
            "x": -6,
            "y": 6,
            "z": 4,
            "elements": [
                "nuclearcraft:ingot_block@9"
            ]
        },
        {
            "x": 5,
            "y": 7,
            "z": 4,
            "elements": [
                "nuclearcraft:ingot_block@9"
            ]
        },
        {
            "x": 5,
            "y": 7,
            "z": 3,
            "elements": [
                "nuclearcraft:ingot_block@9"
            ]
        },
        {
            "x": 5,
            "y": 7,
            "z": 6,
            "elements": [
                "nuclearcraft:ingot_block@9"
            ]
        },
        {
            "x": 5,
            "y": 7,
            "z": 5,
            "elements": [
                "nuclearcraft:ingot_block@9"
            ]
        },
        {
            "x": -6,
            "y": 6,
            "z": -2,
            "elements": [
                "nuclearcraft:ingot_block@9"
            ]
        },
        {
            "x": 3,
            "y": 5,
            "z": 3,
            "elements": [
                "chisel:blockaluminum@6"
            ]
        },
        {
            "x": 3,
            "y": 5,
            "z": 2,
            "elements": [
                "chisel:blockaluminum@6"
            ]
        },
        {
            "x": 6,
            "y": 7,
            "z": 2,
            "elements": [
                "chisel:blockaluminum@6"
            ]
        },
        {
            "x": 6,
            "y": 7,
            "z": 3,
            "elements": [
                "chisel:blockaluminum@6"
            ]
        },
        {
            "x": -6,
            "y": 7,
            "z": 8,
            "elements": [
                "nuclearcraft:ingot_block@9"
            ]
        },
        {
            "x": 1,
            "y": 1,
            "z": 3,
            "elements": [
                "ic2:fence@0"
            ]
        },
        {
            "x": 1,
            "y": 1,
            "z": 2,
            "elements": [
                "ic2:fence@0"
            ]
        },
        {
            "x": -5,
            "y": 8,
            "z": 10,
            "elements": [
                "nuclearcraft:ingot_block@9"
            ]
        },
        {
            "x": -6,
            "y": 7,
            "z": -3,
            "elements": [
                "nuclearcraft:ingot_block@9"
            ]
        },
        {
            "x": -5,
            "y": 8,
            "z": -5,
            "elements": [
                "nuclearcraft:ingot_block@9"
            ]
        },
        {
            "x": 4,
            "y": 6,
            "z": 6,
            "elements": [
                "nuclearcraft:ingot_block@9"
            ]
        },
        {
            "x": 4,
            "y": 6,
            "z": 5,
            "elements": [
                "nuclearcraft:ingot_block@9"
            ]
        },
        {
            "x": 4,
            "y": 6,
            "z": 0,
            "elements": [
                "nuclearcraft:ingot_block@9"
            ]
        },
        {
            "x": 4,
            "y": 6,
            "z": -1,
            "elements": [
                "nuclearcraft:ingot_block@9"
            ]
        },
        {
            "x": -1,
            "y": 12,
            "z": 2,
            "elements": [
                "chisel:blockiron@4"
            ]
        },
        {
            "x": 4,
            "y": 6,
            "z": 4,
            "elements": [
                "nuclearcraft:ingot_block@9"
            ]
        },
        {
            "x": 4,
            "y": 6,
            "z": 3,
            "elements": [
                "nuclearcraft:ingot_block@9"
            ]
        },
        {
            "x": -1,
            "y": 12,
            "z": 3,
            "elements": [
                "chisel:blockiron@4"
            ]
        },
        {
            "x": 4,
            "y": 6,
            "z": 2,
            "elements": [
                "nuclearcraft:ingot_block@9"
            ]
        },
        {
            "x": 4,
            "y": 6,
            "z": 1,
            "elements": [
                "nuclearcraft:ingot_block@9"
            ]
        },
        {
            "x": 1,
            "y": 0,
            "z": 5,
            "elements": [
                "chisel:blockiron@4"
            ]
        },
        {
            "x": 1,
            "y": 0,
            "z": 4,
            "elements": [
                "chisel:blockiron@4"
            ]
        },
        {
            "x": 1,
            "y": 0,
            "z": 3,
            "elements": [
                "chisel:technical@2"
            ]
        },
        {
            "x": 1,
            "y": 0,
            "z": 2,
            "elements": [
                "chisel:technical@2"
            ]
        },
        {
            "x": 4,
            "y": 7,
            "z": 7,
            "elements": [
                "nuclearcraft:ingot_block@9"
            ]
        },
        {
            "x": -4,
            "y": 7,
            "z": 9,
            "elements": [
                "nuclearcraft:ingot_block@9"
            ]
        },
        {
            "x": 1,
            "y": 0,
            "z": 1,
            "elements": [
                "chisel:blockiron@4"
            ]
        },
        {
            "x": 1,
            "y": 0,
            "z": 0,
            "elements": [
                "modularmachinery:blockupgradebus@0"
            ]
        },
        {
            "x": -1,
            "y": 14,
            "z": 3,
            "elements": [
                "avaritia:block_resource@0"
            ]
        },
        {
            "x": -1,
            "y": 14,
            "z": 2,
            "elements": [
                "avaritia:block_resource@0"
            ]
        },
        {
            "x": -4,
            "y": 7,
            "z": -4,
            "elements": [
                "nuclearcraft:ingot_block@9"
            ]
        },
        {
            "x": -5,
            "y": 6,
            "z": -3,
            "elements": [
                "nuclearcraft:ingot_block@9"
            ]
        },
        {
            "x": -1,
            "y": 11,
            "z": 3,
            "elements": [
                "chisel:blockiron@4"
            ]
        },
        {
            "x": -1,
            "y": 11,
            "z": 2,
            "elements": [
                "chisel:blockiron@4"
            ]
        },
        {
            "x": -5,
            "y": 6,
            "z": -2,
            "elements": [
                "nuclearcraft:ingot_block@9"
            ]
        },
        {
            "x": -5,
            "y": 6,
            "z": -1,
            "elements": [
                "nuclearcraft:ingot_block@9"
            ]
        },
        {
            "x": 1,
            "y": 3,
            "z": 3,
            "elements": [
                "ic2:fence@0"
            ]
        },
        {
            "x": -5,
            "y": 6,
            "z": 6,
            "elements": [
                "nuclearcraft:ingot_block@9"
            ]
        },
        {
            "x": -5,
            "y": 6,
            "z": 7,
            "elements": [
                "nuclearcraft:ingot_block@9"
            ]
        },
        {
            "x": 4,
            "y": 7,
            "z": -2,
            "elements": [
                "nuclearcraft:ingot_block@9"
            ]
        },
        {
            "x": -5,
            "y": 6,
            "z": 8,
            "elements": [
                "nuclearcraft:ingot_block@9"
            ]
        },
        {
            "x": -2,
            "y": 0,
            "z": 3,
            "elements": [
                "chisel:blockiron@4"
            ]
        },
        {
            "x": 2,
            "y": 5,
            "z": 4,
            "elements": [
                "nuclearcraft:ingot_block@9"
            ]
        },
        {
            "x": 2,
            "y": 5,
            "z": 5,
            "elements": [
                "nuclearcraft:ingot_block@9"
            ]
        },
        {
            "x": -2,
            "y": 0,
            "z": 4,
            "elements": [
                "chisel:blockiron@4"
            ]
        },
        {
            "x": -2,
            "y": 0,
            "z": 1,
            "elements": [
                "chisel:blockiron@4"
            ]
        },
        {
            "x": -2,
            "y": 0,
            "z": 2,
            "elements": [
                "chisel:blockiron@4"
            ]
        },
        {
            "x": 2,
            "y": 5,
            "z": 0,
            "elements": [
                "nuclearcraft:ingot_block@9"
            ]
        },
        {
            "x": 1,
            "y": 3,
            "z": 2,
            "elements": [
                "ic2:fence@0"
            ]
        },
        {
            "x": 2,
            "y": 5,
            "z": 1,
            "elements": [
                "nuclearcraft:ingot_block@9"
            ]
        },
        {
            "x": -2,
            "y": 0,
            "z": 5,
            "elements": [
                "chisel:technical@2"
            ]
        },
        {
            "x": 2,
            "y": 5,
            "z": 2,
            "elements": [
                "nuclearcraft:ingot_block@9"
            ]
        },
        {
            "x": 2,
            "y": 5,
            "z": 3,
            "elements": [
                "nuclearcraft:ingot_block@9"
            ]
        },
        {
            "x": -7,
            "y": 7,
            "z": -2,
            "elements": [
                "nuclearcraft:ingot_block@9"
            ]
        },
        {
            "x": -2,
            "y": 0,
            "z": 0,
            "elements": [
                "chisel:technical@2"
            ]
        },
        {
            "x": 5,
            "y": 6,
            "z": 3,
            "elements": [
                "chisel:blockaluminum@6"
            ]
        },
        {
            "x": 5,
            "y": 6,
            "z": 2,
            "elements": [
                "chisel:blockaluminum@6"
            ]
        },
        {
            "x": -2,
            "y": 12,
            "z": 2,
            "elements": [
                "chisel:blockiron@4"
            ]
        },
        {
            "x": -4,
            "y": 8,
            "z": -5,
            "elements": [
                "nuclearcraft:ingot_block@9"
            ]
        },
        {
            "x": -2,
            "y": 12,
            "z": 3,
            "elements": [
                "chisel:blockiron@4"
            ]
        },
        {
            "x": -7,
            "y": 7,
            "z": 7,
            "elements": [
                "nuclearcraft:ingot_block@9"
            ]
        },
        {
            "x": -1,
            "y": 2,
            "z": 0,
            "elements": [
                "ic2:fence@0"
            ]
        },
        {
            "x": -1,
            "y": 2,
            "z": 5,
            "elements": [
                "ic2:fence@0"
            ]
        },
        {
            "x": -1,
            "y": 2,
            "z": 3,
            "elements": [
                "chisel:blockiron@4"
            ]
        },
        {
            "x": -1,
            "y": 2,
            "z": 2,
            "elements": [
                "chisel:blockiron@4"
            ]
        },
        {
            "x": -2,
            "y": 9,
            "z": 2,
            "elements": [
                "chisel:blockiron@4"
            ]
        },
        {
            "x": -2,
            "y": 9,
            "z": 3,
            "elements": [
                "chisel:blockiron@4"
            ]
        },
        {
            "x": 1,
            "y": 5,
            "z": 3,
            "elements": [
                "nuclearcraft:ingot_block@9"
            ]
        },
        {
            "x": 1,
            "y": 5,
            "z": 4,
            "elements": [
                "nuclearcraft:ingot_block@9"
            ]
        },
        {
            "x": 1,
            "y": 5,
            "z": 1,
            "elements": [
                "nuclearcraft:ingot_block@9"
            ]
        },
        {
            "x": 1,
            "y": 5,
            "z": 2,
            "elements": [
                "nuclearcraft:ingot_block@9"
            ]
        },
        {
            "x": 1,
            "y": 5,
            "z": 5,
            "elements": [
                "nuclearcraft:ingot_block@9"
            ]
        },
        {
            "x": 1,
            "y": 5,
            "z": 6,
            "elements": [
                "nuclearcraft:ingot_block@9"
            ]
        },
        {
            "x": -5,
            "y": 4,
            "z": 2,
            "elements": [
                "chisel:blockaluminum@6"
            ]
        },
        {
            "x": -5,
            "y": 4,
            "z": 3,
            "elements": [
                "chisel:blockaluminum@6"
            ]
        },
        {
            "x": 2,
            "y": 6,
            "z": 7,
            "elements": [
                "nuclearcraft:ingot_block@9"
            ]
        },
        {
            "x": 2,
            "y": 6,
            "z": 8,
            "elements": [
                "nuclearcraft:ingot_block@9"
            ]
        },
        {
            "x": 0,
            "y": 4,
            "z": 2,
            "elements": [
                "chisel:blockaluminum@6"
            ]
        },
        {
            "x": 2,
            "y": 6,
            "z": -1,
            "elements": [
                "nuclearcraft:ingot_block@9"
            ]
        },
        {
            "x": -3,
            "y": 7,
            "z": -4,
            "elements": [
                "nuclearcraft:ingot_block@9"
            ]
        },
        {
            "x": 1,
            "y": 5,
            "z": -1,
            "elements": [
                "nuclearcraft:ingot_block@9"
            ]
        },
        {
            "x": 1,
            "y": 5,
            "z": 0,
            "elements": [
                "nuclearcraft:ingot_block@9"
            ]
        },
        {
            "x": 2,
            "y": 6,
            "z": 6,
            "elements": [
                "nuclearcraft:ingot_block@9"
            ]
        },
        {
            "x": -4,
            "y": 5,
            "z": 0,
            "elements": [
                "nuclearcraft:ingot_block@9"
            ]
        },
        {
            "x": -4,
            "y": 5,
            "z": 1,
            "elements": [
                "nuclearcraft:ingot_block@9"
            ]
        },
        {
            "x": 3,
            "y": 8,
            "z": -4,
            "elements": [
                "nuclearcraft:ingot_block@9"
            ]
        },
        {
            "x": -4,
            "y": 5,
            "z": -1,
            "elements": [
                "nuclearcraft:ingot_block@9"
            ]
        },
        {
            "x": -4,
            "y": 5,
            "z": 4,
            "elements": [
                "nuclearcraft:ingot_block@9"
            ]
        },
        {
            "x": -4,
            "y": 5,
            "z": 5,
            "elements": [
                "nuclearcraft:ingot_block@9"
            ]
        },
        {
            "x": -3,
            "y": 7,
            "z": 9,
            "elements": [
                "nuclearcraft:ingot_block@9"
            ]
        },
        {
            "x": -4,
            "y": 5,
            "z": 2,
            "elements": [
                "nuclearcraft:ingot_block@9"
            ]
        },
        {
            "x": 2,
            "y": 6,
            "z": -3,
            "elements": [
                "nuclearcraft:ingot_block@9"
            ]
        },
        {
            "x": -4,
            "y": 5,
            "z": 3,
            "elements": [
                "nuclearcraft:ingot_block@9"
            ]
        },
        {
            "x": 2,
            "y": 6,
            "z": -2,
            "elements": [
                "nuclearcraft:ingot_block@9"
            ]
        },
        {
            "x": -4,
            "y": 5,
            "z": 6,
            "elements": [
                "nuclearcraft:ingot_block@9"
            ]
        },
        {
            "x": 3,
            "y": 8,
            "z": 9,
            "elements": [
                "nuclearcraft:ingot_block@9"
            ]
        },
        {
            "x": -5,
            "y": 5,
            "z": 0,
            "elements": [
                "nuclearcraft:ingot_block@9"
            ]
        },
        {
            "x": -5,
            "y": 5,
            "z": 1,
            "elements": [
                "nuclearcraft:ingot_block@9"
            ]
        },
        {
            "x": -5,
            "y": 5,
            "z": 2,
            "elements": [
                "nuclearcraft:ingot_block@9"
            ]
        },
        {
            "x": -5,
            "y": 5,
            "z": 3,
            "elements": [
                "nuclearcraft:ingot_block@9"
            ]
        },
        {
            "x": -5,
            "y": 5,
            "z": 4,
            "elements": [
                "nuclearcraft:ingot_block@9"
            ]
        },
        {
            "x": -5,
            "y": 5,
            "z": 5,
            "elements": [
                "nuclearcraft:ingot_block@9"
            ]
        },
        {
            "x": 1,
            "y": 4,
            "z": 2,
            "elements": [
                "chisel:blockaluminum@6"
            ]
        },
        {
            "x": 1,
            "y": 4,
            "z": 3,
            "elements": [
                "chisel:blockaluminum@6"
            ]
        },
        {
            "x": -6,
            "y": 8,
            "z": -4,
            "elements": [
                "nuclearcraft:ingot_block@9"
            ]
        },
        {
            "x": -3,
            "y": 8,
            "z": 10,
            "elements": [
                "nuclearcraft:ingot_block@9"
            ]
        },
        {
            "x": -1,
            "y": 1,
            "z": 5,
            "elements": [
                "ic2:fence@0"
            ]
        },
        {
            "x": -1,
            "y": 1,
            "z": 3,
            "elements": [
                "chisel:blockiron@4"
            ]
        },
        {
            "x": -1,
            "y": 1,
            "z": 2,
            "elements": [
                "chisel:blockiron@4"
            ]
        },
        {
            "x": -1,
            "y": 1,
            "z": 0,
            "elements": [
                "ic2:fence@0"
            ]
        },
        {
            "x": -6,
            "y": 8,
            "z": 9,
            "elements": [
                "nuclearcraft:ingot_block@9"
            ]
        },
        {
            "x": 5,
            "y": 8,
            "z": 7,
            "elements": [
                "nuclearcraft:ingot_block@9"
            ]
        },
        {
            "x": 5,
            "y": 8,
            "z": 8,
            "elements": [
                "nuclearcraft:ingot_block@9"
            ]
        },
        {
            "x": 5,
            "y": 8,
            "z": -2,
            "elements": [
                "nuclearcraft:ingot_block@9"
            ]
        },
        {
            "x": -9,
            "y": 7,
            "z": 2,
            "elements": [
                "chisel:blockaluminum@6"
            ]
        },
        {
            "x": -9,
            "y": 7,
            "z": 3,
            "elements": [
                "chisel:blockaluminum@6"
            ]
        },
        {
            "x": -2,
            "y": 10,
            "z": 2,
            "elements": [
                "chisel:blockiron@4"
            ]
        },
        {
            "x": -2,
            "y": 10,
            "z": 3,
            "elements": [
                "chisel:blockiron@4"
            ]
        },
        {
            "x": -1,
            "y": 7,
            "z": 3,
            "elements": [
                "chisel:blockiron@4"
            ]
        },
        {
            "x": -1,
            "y": 7,
            "z": 2,
            "elements": [
                "chisel:blockiron@4"
            ]
        },
        {
            "x": 5,
            "y": 8,
            "z": -3,
            "elements": [
                "nuclearcraft:ingot_block@9"
            ]
        },
        {
            "x": -9,
            "y": 8,
            "z": -1,
            "elements": [
                "nuclearcraft:ingot_block@9"
            ]
        },
        {
            "x": -1,
            "y": 7,
            "z": 9,
            "elements": [
                "nuclearcraft:ingot_block@9"
            ]
        },
        {
            "x": -1,
            "y": 7,
            "z": 10,
            "elements": [
                "chisel:blockaluminum@6"
            ]
        },
        {
            "x": -7,
            "y": 6,
            "z": 0,
            "elements": [
                "nuclearcraft:ingot_block@9"
            ]
        },
        {
            "x": -7,
            "y": 6,
            "z": 1,
            "elements": [
                "nuclearcraft:ingot_block@9"
            ]
        },
        {
            "x": -7,
            "y": 6,
            "z": 2,
            "elements": [
                "nuclearcraft:ingot_block@9"
            ]
        },
        {
            "x": -7,
            "y": 6,
            "z": 3,
            "elements": [
                "nuclearcraft:ingot_block@9"
            ]
        },
        {
            "x": -7,
            "y": 6,
            "z": 4,
            "elements": [
                "nuclearcraft:ingot_block@9"
            ]
        },
        {
            "x": -7,
            "y": 6,
            "z": 5,
            "elements": [
                "nuclearcraft:ingot_block@9"
            ]
        },
        {
            "x": -7,
            "y": 6,
            "z": 6,
            "elements": [
                "nuclearcraft:ingot_block@9"
            ]
        },
        {
            "x": -1,
            "y": 7,
            "z": -5,
            "elements": [
                "chisel:blockaluminum@6"
            ]
        },
        {
            "x": -1,
            "y": 7,
            "z": -4,
            "elements": [
                "nuclearcraft:ingot_block@9"
            ]
        },
        {
            "x": -3,
            "y": 8,
            "z": -5,
            "elements": [
                "nuclearcraft:ingot_block@9"
            ]
        },
        {
            "x": -1,
            "y": 0,
            "z": 3,
            "elements": [
                "chisel:blockiron@4"
            ]
        },
        {
            "x": 2,
            "y": 7,
            "z": 9,
            "elements": [
                "nuclearcraft:ingot_block@9"
            ]
        },
        {
            "x": -1,
            "y": 0,
            "z": 2,
            "elements": [
                "chisel:blockiron@4"
            ]
        },
        {
            "x": -1,
            "y": 0,
            "z": 1,
            "elements": [
                "chisel:blockiron@4"
            ]
        },
        {
            "x": -1,
            "y": 0,
            "z": 0,
            "elements": [
                "chisel:technical@2"
            ]
        },
        {
            "x": -1,
            "y": 0,
            "z": 5,
            "elements": [
                "chisel:technical@2"
            ]
        },
        {
            "x": -1,
            "y": 0,
            "z": 4,
            "elements": [
                "chisel:blockiron@4"
            ]
        },
        {
            "x": -4,
            "y": 6,
            "z": 8,
            "elements": [
                "nuclearcraft:ingot_block@9"
            ]
        },
        {
            "x": -7,
            "y": 6,
            "z": -1,
            "elements": [
                "nuclearcraft:ingot_block@9"
            ]
        },
        {
            "x": -4,
            "y": 6,
            "z": 7,
            "elements": [
                "nuclearcraft:ingot_block@9"
            ]
        },
        {
            "x": -4,
            "y": 6,
            "z": -2,
            "elements": [
                "nuclearcraft:ingot_block@9"
            ]
        },
        {
            "x": -4,
            "y": 6,
            "z": -3,
            "elements": [
                "nuclearcraft:ingot_block@9"
            ]
        },
        {
            "x": -1,
            "y": 13,
            "z": 3,
            "elements": [
                "avaritia:block_resource@0"
            ]
        },
        {
            "x": -1,
            "y": 13,
            "z": 2,
            "elements": [
                "avaritia:block_resource@0"
            ]
        },
        {
            "x": -4,
            "y": 0,
            "z": 1,
            "elements": [
                "chisel:blockiron@4"
            ]
        },
        {
            "x": -4,
            "y": 0,
            "z": 2,
            "elements": [
                "chisel:technical@2"
            ]
        },
        {
            "x": -4,
            "y": 0,
            "z": 0,
            "elements": [
                "chisel:blockiron@4"
            ]
        },
        {
            "x": -4,
            "y": 0,
            "z": 5,
            "elements": [
                "chisel:blockiron@4"
            ]
        },
        {
            "x": -4,
            "y": 0,
            "z": 3,
            "elements": [
                "chisel:technical@2"
            ]
        },
        {
            "x": -4,
            "y": 0,
            "z": 4,
            "elements": [
                "chisel:blockiron@4"
            ]
        },
        {
            "x": 2,
            "y": 7,
            "z": -4,
            "elements": [
                "nuclearcraft:ingot_block@9"
            ]
        }
    ]}