{
    "registryname": "vacuum_dryer_mkii",
    "localizedname": "真空干燥炉MKII",
    "failure-action": "still",
    "requires-blueprint": false,
    "has-factory": true,
    "parts": [
        {
            "x": 0,
            "y": 0,
            "z": 0,
            "elements": [
                "modularmachinery:vacuum_dryer_mkii_factory_controller@2"
            ]
        },
        {
            "x": -8,
            "y": 0,
            "z": 15,
            "elements": [
                "modularmachinery:blockcasing@4"
            ]
        },
        {
            "x": -5,
            "y": 4,
            "z": 10,
            "elements": [
                "chisel:technical1@3"
            ]
        },
        {
            "x": -2,
            "y": -1,
            "z": 12,
            "elements": [
                "advancedrocketry:blastbrick@0"
            ]
        },
        {
            "x": -3,
            "y": 0,
            "z": 5,
            "elements": [
                "advancedrocketry:blastbrick@0"
            ]
        },
        {
            "x": 6,
            "y": 4,
            "z": 7,
            "elements": [
                "chisel:technical1@3"
            ]
        },
        {
            "x": 7,
            "y": 4,
            "z": 2,
            "elements": [
                "chisel:technical1@3"
            ]
        },
        {
            "x": -7,
            "y": -1,
            "z": 11,
            "elements": [
                "modularmachinery:blockcasing@0"
            ]
        },
        {
            "x": -6,
            "y": 0,
            "z": 10,
            "elements": [
                "mekanism:basicblock2@5"
            ]
        },
        {
            "x": -4,
            "y": 4,
            "z": 5,
            "elements": [
                "chisel:technical@8"
            ]
        },
        {
            "x": 8,
            "y": -1,
            "z": 7,
            "elements": [
                "modularmachinery:blockcasing@4"
            ]
        },
        {
            "x": 1,
            "y": 0,
            "z": 0,
            "elements": [
                "modularmachinery:blockinputbus",
                "modularmachinery:blockmepatternprovider",
                "modularmachinery:blockmeiteminputbus"
            ]
        },
        {
            "x": -6,
            "y": 4,
            "z": 10,
            "elements": [
                "chisel:technical1@3"
            ]
        },
        {
            "x": -5,
            "y": 0,
            "z": 15,
            "elements": [
                "chisel:blocksteel@6"
            ]
        },
        {
            "x": 6,
            "y": 4,
            "z": 3,
            "elements": [
                "chisel:technical1@3"
            ]
        },
        {
            "x": -2,
            "y": 0,
            "z": 5,
            "elements": [
                "mekanism:basicblock2@5"
            ]
        },
        {
            "x": -5,
            "y": 4,
            "z": 5,
            "elements": [
                "chisel:technical1@3"
            ]
        },
        {
            "x": -5,
            "y": 0,
            "z": 10,
            "elements": [
                "advancedrocketry:blastbrick@0"
            ]
        },
        {
            "x": -8,
            "y": 4,
            "z": 15,
            "elements": [
                "chisel:technicalnew@2"
            ]
        },
        {
            "x": 3,
            "y": -1,
            "z": 9,
            "elements": [
                "modularmachinery:blockcasing@0"
            ]
        },
        {
            "x": 0,
            "y": 3,
            "z": 14,
            "elements": [
                "modularmachinery:blockcasing@1"
            ]
        },
        {
            "x": -7,
            "y": 4,
            "z": 10,
            "elements": [
                "chisel:technical1@3"
            ]
        },
        {
            "x": 6,
            "y": 3,
            "z": 1,
            "elements": [
                "modularmachinery:blockcasing@1"
            ]
        },
        {
            "x": -1,
            "y": -1,
            "z": 11,
            "elements": [
                "modularmachinery:blockcasing@0"
            ]
        },
        {
            "x": -5,
            "y": 0,
            "z": 5,
            "elements": [
                "advancedrocketry:blastbrick@0"
            ]
        },
        {
            "x": -8,
            "y": -2,
            "z": 15,
            "elements": [
                "chisel:blocksteel@4"
            ]
        },
        {
            "x": -6,
            "y": 4,
            "z": 5,
            "elements": [
                "chisel:technical1@3"
            ]
        },
        {
            "x": 6,
            "y": 2,
            "z": 1,
            "elements": [
                "modularmachinery:blockcasing@1"
            ]
        },
        {
            "x": -4,
            "y": 0,
            "z": 10,
            "elements": [
                "mekanism:basicblock2@5"
            ]
        },
        {
            "x": -1,
            "y": 0,
            "z": 0,
            "elements": [
                "modularmachinery:blockoutputbus",
                "modularmachinery:blockmeitemoutputbus"
            ]
        },
        {
            "x": 6,
            "y": 1,
            "z": 1,
            "elements": [
                "modularmachinery:blockcasing@1"
            ]
        },
        {
            "x": -8,
            "y": 2,
            "z": 15,
            "elements": [
                "modularmachinery:blockcasing@4"
            ]
        },
        {
            "x": 6,
            "y": 0,
            "z": 1,
            "elements": [
                "modularmachinery:blockcasing@0"
            ]
        },
        {
            "x": -4,
            "y": 4,
            "z": 10,
            "elements": [
                "chisel:technical@8"
            ]
        },
        {
            "x": 0,
            "y": -1,
            "z": 11,
            "elements": [
                "advancedrocketry:blastbrick@0"
            ]
        },
        {
            "x": 0,
            "y": 0,
            "z": 5,
            "elements": [
                "mekanism:basicblock2@5"
            ]
        },
        {
            "x": 0,
            "y": 4,
            "z": 3,
            "elements": [
                "chisel:technical1@3"
            ]
        },
        {
            "x": -7,
            "y": 0,
            "z": 10,
            "elements": [
                "advancedrocketry:blastbrick@0"
            ]
        },
        {
            "x": 5,
            "y": -1,
            "z": 4,
            "elements": [
                "modularmachinery:blockcasing@0"
            ]
        },
        {
            "x": -3,
            "y": 4,
            "z": 5,
            "elements": [
                "chisel:technical1@4"
            ]
        },
        {
            "x": -7,
            "y": -2,
            "z": 15,
            "elements": [
                "chisel:blocksteel@6"
            ]
        },
        {
            "x": 3,
            "y": 0,
            "z": 3,
            "elements": [
                "advancedrocketry:blastbrick@0"
            ]
        },
        {
            "x": -7,
            "y": 0,
            "z": 5,
            "elements": [
                "advancedrocketry:blastbrick@0"
            ]
        },
        {
            "x": -8,
            "y": 3,
            "z": 11,
            "elements": [
                "chisel:glass@6"
            ]
        },
        {
            "x": -3,
            "y": -1,
            "z": 11,
            "elements": [
                "modularmachinery:blockcasing@0"
            ]
        },
        {
            "x": 5,
            "y": -1,
            "z": 7,
            "elements": [
                "modularmachinery:blockcasing@0"
            ]
        },
        {
            "x": 0,
            "y": 4,
            "z": 5,
            "elements": [
                "chisel:technical1@3"
            ]
        },
        {
            "x": 2,
            "y": -1,
            "z": 4,
            "elements": [
                "advancedrocketry:blastbrick@0"
            ]
        },
        {
            "x": -1,
            "y": -1,
            "z": 4,
            "elements": [
                "modularmachinery:blockcasing@0"
            ]
        },
        {
            "x": 2,
            "y": 0,
            "z": 12,
            "elements": [
                "mekanism:basicblock2@5"
            ]
        },
        {
            "x": 0,
            "y": -1,
            "z": 9,
            "elements": [
                "advancedrocketry:blastbrick@0"
            ]
        },
        {
            "x": -8,
            "y": 0,
            "z": 3,
            "elements": [
                "modularmachinery:blockcasing@2"
            ]
        },
        {
            "x": 3,
            "y": 4,
            "z": 7,
            "elements": [
                "chisel:glass@6"
            ]
        },
        {
            "x": -1,
            "y": 4,
            "z": 12,
            "elements": [
                "chisel:technical1@3"
            ]
        },
        {
            "x": 5,
            "y": 0,
            "z": 0,
            "elements": [
                "chisel:blocksteel@6"
            ]
        },
        {
            "x": -8,
            "y": 1,
            "z": 11,
            "elements": [
                "chisel:glass@6"
            ]
        },
        {
            "x": -1,
            "y": 4,
            "z": 5,
            "elements": [
                "chisel:technical1@3"
            ]
        },
        {
            "x": -6,
            "y": -1,
            "z": 11,
            "elements": [
                "advancedrocketry:blastbrick@0"
            ]
        },
        {
            "x": 2,
            "y": 0,
            "z": 5,
            "elements": [
                "mekanism:basicblock2@5"
            ]
        },
        {
            "x": -4,
            "y": -1,
            "z": 4,
            "elements": [
                "advancedrocketry:blastbrick@0"
            ]
        },
        {
            "x": -8,
            "y": 2,
            "z": 3,
            "elements": [
                "chisel:glass@6"
            ]
        },
        {
            "x": -8,
            "y": 4,
            "z": 0,
            "elements": [
                "chisel:technicalnew@2"
            ]
        },
        {
            "x": -1,
            "y": 0,
            "z": 5,
            "elements": [
                "advancedrocketry:blastbrick@0"
            ]
        },
        {
            "x": 6,
            "y": -1,
            "z": 9,
            "elements": [
                "advancedrocketry:blastbrick@0"
            ]
        },
        {
            "x": -3,
            "y": 4,
            "z": 10,
            "elements": [
                "chisel:technical1@4"
            ]
        },
        {
            "x": 4,
            "y": -1,
            "z": 12,
            "elements": [
                "advancedrocketry:blastbrick@0"
            ]
        },
        {
            "x": 6,
            "y": 0,
            "z": 7,
            "elements": [
                "mekanism:basicblock2@5"
            ]
        },
        {
            "x": 3,
            "y": 4,
            "z": 3,
            "elements": [
                "chisel:technical1@4"
            ]
        },
        {
            "x": -5,
            "y": -1,
            "z": 11,
            "elements": [
                "modularmachinery:blockcasing@0"
            ]
        },
        {
            "x": -6,
            "y": 2,
            "z": 1,
            "elements": [
                "modularmachinery:blockcasing@1"
            ]
        },
        {
            "x": 0,
            "y": 4,
            "z": 7,
            "elements": [
                "chisel:technical1@3"
            ]
        },
        {
            "x": -7,
            "y": -1,
            "z": 4,
            "elements": [
                "modularmachinery:blockcasing@0"
            ]
        },
        {
            "x": 0,
            "y": 0,
            "z": 10,
            "elements": [
                "mekanism:basicblock2@5"
            ]
        },
        {
            "x": 6,
            "y": 0,
            "z": 3,
            "elements": [
                "mekanism:basicblock2@5"
            ]
        },
        {
            "x": 3,
            "y": 0,
            "z": 7,
            "elements": [
                "modularmachinery:blockcasing@3"
            ]
        },
        {
            "x": 0,
            "y": 4,
            "z": 10,
            "elements": [
                "chisel:technical1@3"
            ]
        },
        {
            "x": -5,
            "y": 0,
            "z": 0,
            "elements": [
                "chisel:blocksteel@6"
            ]
        },
        {
            "x": -6,
            "y": 3,
            "z": 1,
            "elements": [
                "modularmachinery:blockcasing@1"
            ]
        },
        {
            "x": 5,
            "y": -1,
            "z": 6,
            "elements": [
                "modularmachinery:blockcasing@0"
            ]
        },
        {
            "x": 6,
            "y": 0,
            "z": 6,
            "elements": [
                "mekanism:basicblock2@5"
            ]
        },
        {
            "x": -6,
            "y": 0,
            "z": 1,
            "elements": [
                "modularmachinery:blockcasing@0"
            ]
        },
        {
            "x": 2,
            "y": -1,
            "z": 7,
            "elements": [
                "advancedrocketry:blastbrick@0"
            ]
        },
        {
            "x": -4,
            "y": 0,
            "z": 5,
            "elements": [
                "mekanism:basicblock2@5"
            ]
        },
        {
            "x": 1,
            "y": -1,
            "z": 12,
            "elements": [
                "modularmachinery:blockcasing@0"
            ]
        },
        {
            "x": -4,
            "y": -1,
            "z": 11,
            "elements": [
                "advancedrocketry:blastbrick@0"
            ]
        },
        {
            "x": -7,
            "y": 4,
            "z": 5,
            "elements": [
                "chisel:technical1@3"
            ]
        },
        {
            "x": -6,
            "y": 1,
            "z": 1,
            "elements": [
                "modularmachinery:blockcasing@1"
            ]
        },
        {
            "x": -1,
            "y": 0,
            "z": 12,
            "elements": [
                "mekanism:basicblock2@5"
            ]
        },
        {
            "x": -3,
            "y": 0,
            "z": 10,
            "elements": [
                "advancedrocketry:blastbrick@0"
            ]
        },
        {
            "x": 3,
            "y": 4,
            "z": 6,
            "elements": [
                "chisel:technical1@4"
            ]
        },
        {
            "x": 6,
            "y": 3,
            "z": 14,
            "elements": [
                "modularmachinery:blockcasing@1"
            ]
        },
        {
            "x": 2,
            "y": -1,
            "z": 8,
            "elements": [
                "advancedrocketry:blastbrick@0"
            ]
        },
        {
            "x": 8,
            "y": 0,
            "z": 0,
            "elements": [
                "modularmachinery:blockcasing@4"
            ]
        },
        {
            "x": 1,
            "y": 4,
            "z": 3,
            "elements": [
                "chisel:technical1@3"
            ]
        },
        {
            "x": 7,
            "y": 2,
            "z": 0,
            "elements": [
                "chisel:technical@4"
            ]
        },
        {
            "x": -8,
            "y": -2,
            "z": 0,
            "elements": [
                "chisel:blocksteel@4"
            ]
        },
        {
            "x": 5,
            "y": 0,
            "z": 5,
            "elements": [
                "advancedrocketry:blastbrick@0"
            ]
        },
        {
            "x": -4,
            "y": -1,
            "z": 9,
            "elements": [
                "advancedrocketry:blastbrick@0"
            ]
        },
        {
            "x": 4,
            "y": 0,
            "z": 3,
            "elements": [
                "mekanism:basicblock2@5"
            ]
        },
        {
            "x": -5,
            "y": -1,
            "z": 4,
            "elements": [
                "modularmachinery:blockcasing@0"
            ]
        },
        {
            "x": 3,
            "y": 0,
            "z": 8,
            "elements": [
                "modularmachinery:blockcasing@3"
            ]
        },
        {
            "x": -3,
            "y": 4,
            "z": 8,
            "elements": [
                "chisel:glass@6"
            ]
        },
        {
            "x": 6,
            "y": 4,
            "z": 14,
            "elements": [
                "chisel:technical@1"
            ]
        },
        {
            "x": 7,
            "y": -2,
            "z": 0,
            "elements": [
                "chisel:blocksteel@6"
            ]
        },
        {
            "x": -8,
            "y": 2,
            "z": 0,
            "elements": [
                "modularmachinery:blockcasing@4"
            ]
        },
        {
            "x": 8,
            "y": 1,
            "z": 14,
            "elements": [
                "chisel:technicalnew@4"
            ]
        },
        {
            "x": 3,
            "y": 4,
            "z": 5,
            "elements": [
                "chisel:technical1@4"
            ]
        },
        {
            "x": 5,
            "y": -1,
            "z": 8,
            "elements": [
                "modularmachinery:blockcasing@0"
            ]
        },
        {
            "x": 7,
            "y": -1,
            "z": 12,
            "elements": [
                "modularmachinery:blockcasing@0"
            ]
        },
        {
            "x": -2,
            "y": 4,
            "z": 3,
            "elements": [
                "chisel:technical1@4"
            ]
        },
        {
            "x": 7,
            "y": 4,
            "z": 0,
            "elements": [
                "chisel:technicalnew@2"
            ]
        },
        {
            "x": 6,
            "y": 0,
            "z": 5,
            "elements": [
                "mekanism:basicblock2@5"
            ]
        },
        {
            "x": -5,
            "y": -1,
            "z": 9,
            "elements": [
                "modularmachinery:blockcasing@0"
            ]
        },
        {
            "x": 8,
            "y": 2,
            "z": 14,
            "elements": [
                "chisel:technicalnew@4"
            ]
        },
        {
            "x": 1,
            "y": 0,
            "z": 3,
            "elements": [
                "mekanism:basicblock2@5"
            ]
        },
        {
            "x": 5,
            "y": 0,
            "z": 12,
            "elements": [
                "advancedrocketry:blastbrick@0"
            ]
        },
        {
            "x": 0,
            "y": 4,
            "z": 8,
            "elements": [
                "chisel:technical1@3"
            ]
        },
        {
            "x": 6,
            "y": 0,
            "z": 8,
            "elements": [
                "mekanism:basicblock2@5"
            ]
        },
        {
            "x": 1,
            "y": 4,
            "z": 10,
            "elements": [
                "chisel:technical1@3"
            ]
        },
        {
            "x": 3,
            "y": 0,
            "z": 10,
            "elements": [
                "advancedrocketry:blastbrick@0"
            ]
        },
        {
            "x": 2,
            "y": 4,
            "z": 12,
            "elements": [
                "chisel:technical1@4"
            ]
        },
        {
            "x": 6,
            "y": 0,
            "z": 13,
            "elements": [
                "advancedrocketry:blastbrick@0"
            ]
        },
        {
            "x": 8,
            "y": -1,
            "z": 8,
            "elements": [
                "modularmachinery:blockcasing@4"
            ]
        },
        {
            "x": 2,
            "y": 4,
            "z": 5,
            "elements": [
                "chisel:technical1@4"
            ]
        },
        {
            "x": -6,
            "y": -1,
            "z": 9,
            "elements": [
                "advancedrocketry:blastbrick@0"
            ]
        },
        {
            "x": -6,
            "y": 0,
            "z": 8,
            "elements": [
                "mekanism:basicblock2@5"
            ]
        },
        {
            "x": 3,
            "y": 0,
            "z": 5,
            "elements": [
                "advancedrocketry:blastbrick@0"
            ]
        },
        {
            "x": -8,
            "y": 4,
            "z": 3,
            "elements": [
                "chisel:technical@1"
            ]
        },
        {
            "x": -8,
            "y": 1,
            "z": 9,
            "elements": [
                "chisel:glass@6"
            ]
        },
        {
            "x": 8,
            "y": 1,
            "z": 12,
            "elements": [
                "chisel:glass@6"
            ]
        },
        {
            "x": 5,
            "y": -1,
            "z": 13,
            "elements": [
                "modularmachinery:blockcasing@0"
            ]
        },
        {
            "x": -3,
            "y": -1,
            "z": 4,
            "elements": [
                "modularmachinery:blockcasing@0"
            ]
        },
        {
            "x": -6,
            "y": 0,
            "z": 3,
            "elements": [
                "mekanism:basicblock2@5"
            ]
        },
        {
            "x": 6,
            "y": 4,
            "z": 6,
            "elements": [
                "chisel:technical1@3"
            ]
        },
        {
            "x": -7,
            "y": -1,
            "z": 8,
            "elements": [
                "modularmachinery:blockcasing@0"
            ]
        },
        {
            "x": 8,
            "y": 0,
            "z": 12,
            "elements": [
                "modularmachinery:blockcasing@2"
            ]
        },
        {
            "x": 4,
            "y": 0,
            "z": 10,
            "elements": [
                "mekanism:basicblock2@5"
            ]
        },
        {
            "x": 4,
            "y": 4,
            "z": 10,
            "elements": [
                "chisel:technical@8"
            ]
        },
        {
            "x": 5,
            "y": 0,
            "z": 13,
            "elements": [
                "advancedrocketry:blastbrick@0"
            ]
        },
        {
            "x": 8,
            "y": 2,
            "z": 12,
            "elements": [
                "chisel:glass@6"
            ]
        },
        {
            "x": -1,
            "y": -1,
            "z": 8,
            "elements": [
                "modularmachinery:blockcasing@0"
            ]
        },
        {
            "x": 8,
            "y": 2,
            "z": 5,
            "elements": [
                "chisel:glass@6"
            ]
        },
        {
            "x": 6,
            "y": 4,
            "z": 8,
            "elements": [
                "chisel:technical1@3"
            ]
        },
        {
            "x": 5,
            "y": 4,
            "z": 12,
            "elements": [
                "chisel:technical1@3"
            ]
        },
        {
            "x": -7,
            "y": 4,
            "z": 0,
            "elements": [
                "chisel:technicalnew@2"
            ]
        },
        {
            "x": 5,
            "y": 4,
            "z": 5,
            "elements": [
                "chisel:technical1@3"
            ]
        },
        {
            "x": 3,
            "y": 4,
            "z": 13,
            "elements": [
                "chisel:technical1@4"
            ]
        },
        {
            "x": 4,
            "y": -1,
            "z": 13,
            "elements": [
                "modularmachinery:blockcasing@0"
            ]
        },
        {
            "x": 8,
            "y": 0,
            "z": 5,
            "elements": [
                "modularmachinery:blockcasing@2"
            ]
        },
        {
            "x": -3,
            "y": -1,
            "z": 9,
            "elements": [
                "modularmachinery:blockcasing@0"
            ]
        },
        {
            "x": 1,
            "y": 0,
            "z": 10,
            "elements": [
                "advancedrocketry:blastbrick@0"
            ]
        },
        {
            "x": 0,
            "y": 0,
            "z": 8,
            "elements": [
                "mekanism:basicblock2@5"
            ]
        },
        {
            "x": 8,
            "y": 3,
            "z": 12,
            "elements": [
                "chisel:glass@6"
            ]
        },
        {
            "x": -2,
            "y": -1,
            "z": 4,
            "elements": [
                "advancedrocketry:blastbrick@0"
            ]
        },
        {
            "x": -8,
            "y": 3,
            "z": 9,
            "elements": [
                "chisel:glass@6"
            ]
        },
        {
            "x": -5,
            "y": 0,
            "z": 3,
            "elements": [
                "advancedrocketry:blastbrick@0"
            ]
        },
        {
            "x": -7,
            "y": 2,
            "z": 0,
            "elements": [
                "chisel:technical@4"
            ]
        },
        {
            "x": 8,
            "y": 4,
            "z": 5,
            "elements": [
                "chisel:technical@1"
            ]
        },
        {
            "x": 8,
            "y": 0,
            "z": 13,
            "elements": [
                "modularmachinery:blockcasing@2"
            ]
        },
        {
            "x": -7,
            "y": 2,
            "z": 15,
            "elements": [
                "chisel:technical@4"
            ]
        },
        {
            "x": 8,
            "y": 4,
            "z": 12,
            "elements": [
                "chisel:technical@1"
            ]
        },
        {
            "x": -3,
            "y": 4,
            "z": 3,
            "elements": [
                "chisel:technical1@4"
            ]
        },
        {
            "x": 7,
            "y": -1,
            "z": 13,
            "elements": [
                "modularmachinery:blockcasing@0"
            ]
        },
        {
            "x": -6,
            "y": 4,
            "z": 3,
            "elements": [
                "chisel:technical1@3"
            ]
        },
        {
            "x": 0,
            "y": 0,
            "z": 3,
            "elements": [
                "mekanism:basicblock2@5"
            ]
        },
        {
            "x": -2,
            "y": 0,
            "z": 10,
            "elements": [
                "mekanism:basicblock2@5"
            ]
        },
        {
            "x": -7,
            "y": 4,
            "z": 15,
            "elements": [
                "chisel:technicalnew@2"
            ]
        },
        {
            "x": 2,
            "y": -1,
            "z": 11,
            "elements": [
                "advancedrocketry:blastbrick@0"
            ]
        },
        {
            "x": 3,
            "y": 3,
            "z": 14,
            "elements": [
                "modularmachinery:blockcasing@1"
            ]
        },
        {
            "x": -2,
            "y": 4,
            "z": 10,
            "elements": [
                "chisel:technical1@4"
            ]
        },
        {
            "x": -6,
            "y": 0,
            "z": 5,
            "elements": [
                "mekanism:basicblock2@5"
            ]
        },
        {
            "x": 8,
            "y": 2,
            "z": 13,
            "elements": [
                "chisel:glass@6"
            ]
        },
        {
            "x": 5,
            "y": 4,
            "z": 13,
            "elements": [
                "chisel:technical1@3"
            ]
        },
        {
            "x": 6,
            "y": 0,
            "z": 14,
            "elements": [
                "modularmachinery:blockcasing@0"
            ]
        },
        {
            "x": 8,
            "y": 4,
            "z": 13,
            "elements": [
                "chisel:technical@1"
            ]
        },
        {
            "x": -8,
            "y": 1,
            "z": 4,
            "elements": [
                "chisel:glass@6"
            ]
        },
        {
            "x": 3,
            "y": 4,
            "z": 14,
            "elements": [
                "chisel:technical@1"
            ]
        },
        {
            "x": 8,
            "y": 1,
            "z": 13,
            "elements": [
                "chisel:glass@6"
            ]
        },
        {
            "x": -3,
            "y": 0,
            "z": 3,
            "elements": [
                "mekanism:basicblock2@5"
            ]
        },
        {
            "x": 5,
            "y": -1,
            "z": 11,
            "elements": [
                "modularmachinery:blockcasing@0"
            ]
        },
        {
            "x": 6,
            "y": 4,
            "z": 1,
            "elements": [
                "chisel:technical@1"
            ]
        },
        {
            "x": 3,
            "y": -1,
            "z": 11,
            "elements": [
                "modularmachinery:blockcasing@0"
            ]
        },
        {
            "x": 3,
            "y": 4,
            "z": 8,
            "elements": [
                "chisel:glass@6"
            ]
        },
        {
            "x": 6,
            "y": 4,
            "z": 12,
            "elements": [
                "chisel:technical1@3"
            ]
        },
        {
            "x": 0,
            "y": -1,
            "z": 4,
            "elements": [
                "advancedrocketry:blastbrick@0"
            ]
        },
        {
            "x": -8,
            "y": 0,
            "z": 10,
            "elements": [
                "modularmachinery:blockcasing@2"
            ]
        },
        {
            "x": 3,
            "y": 0,
            "z": 14,
            "elements": [
                "modularmachinery:blockcasing@0"
            ]
        },
        {
            "x": -5,
            "y": 4,
            "z": 3,
            "elements": [
                "chisel:technical1@3"
            ]
        },
        {
            "x": 0,
            "y": 4,
            "z": 14,
            "elements": [
                "chisel:technical@1"
            ]
        },
        {
            "x": 8,
            "y": 3,
            "z": 13,
            "elements": [
                "chisel:glass@6"
            ]
        },
        {
            "x": -2,
            "y": 0,
            "z": 3,
            "elements": [
                "mekanism:basicblock2@5"
            ]
        },
        {
            "x": 5,
            "y": 0,
            "z": 15,
            "elements": [
                "chisel:blocksteel@6"
            ]
        },
        {
            "x": -2,
            "y": -1,
            "z": 9,
            "elements": [
                "advancedrocketry:blastbrick@0"
            ]
        },
        {
            "x": 6,
            "y": 1,
            "z": 14,
            "elements": [
                "modularmachinery:blockcasing@1"
            ]
        },
        {
            "x": -8,
            "y": 4,
            "z": 10,
            "elements": [
                "chisel:technical@1"
            ]
        },
        {
            "x": -8,
            "y": 3,
            "z": 4,
            "elements": [
                "chisel:glass@6"
            ]
        },
        {
            "x": 1,
            "y": -1,
            "z": 4,
            "elements": [
                "modularmachinery:blockcasing@0"
            ]
        },
        {
            "x": -4,
            "y": 4,
            "z": 3,
            "elements": [
                "chisel:technical@8"
            ]
        },
        {
            "x": 3,
            "y": 2,
            "z": 14,
            "elements": [
                "modularmachinery:blockcasing@1"
            ]
        },
        {
            "x": -1,
            "y": 0,
            "z": 3,
            "elements": [
                "advancedrocketry:blastbrick@0"
            ]
        },
        {
            "x": -6,
            "y": -1,
            "z": 4,
            "elements": [
                "advancedrocketry:blastbrick@0"
            ]
        },
        {
            "x": 6,
            "y": 2,
            "z": 14,
            "elements": [
                "modularmachinery:blockcasing@1"
            ]
        },
        {
            "x": -7,
            "y": -1,
            "z": 2,
            "elements": [
                "modularmachinery:blockcasing@0"
            ]
        },
        {
            "x": 6,
            "y": 4,
            "z": 13,
            "elements": [
                "chisel:technical1@3"
            ]
        },
        {
            "x": -8,
            "y": 2,
            "z": 10,
            "elements": [
                "chisel:glass@6"
            ]
        },
        {
            "x": 3,
            "y": 1,
            "z": 14,
            "elements": [
                "modularmachinery:blockcasing@1"
            ]
        },
        {
            "x": 1,
            "y": -1,
            "z": 9,
            "elements": [
                "modularmachinery:blockcasing@0"
            ]
        },
        {
            "x": 1,
            "y": -1,
            "z": 7,
            "elements": [
                "modularmachinery:blockcasing@0"
            ]
        },
        {
            "x": -8,
            "y": 2,
            "z": 1,
            "elements": [
                "chisel:technicalnew@4"
            ]
        },
        {
            "x": 8,
            "y": -3,
            "z": 15,
            "elements": [
                "chisel:blocksteel@4"
            ]
        },
        {
            "x": -8,
            "y": 0,
            "z": 8,
            "elements": [
                "modularmachinery:blockcasing@2"
            ]
        },
        {
            "x": 4,
            "y": 0,
            "z": 11,
            "elements": [
                "mekanism:basicblock2@5"
            ]
        },
        {
            "x": 6,
            "y": -1,
            "z": 4,
            "elements": [
                "advancedrocketry:blastbrick@0"
            ]
        },
        {
            "x": 7,
            "y": 0,
            "z": 4,
            "elements": [
                "advancedrocketry:blastbrick@0"
            ]
        },
        {
            "x": 1,
            "y": 4,
            "z": 4,
            "elements": [
                "chisel:technical1@3"
            ]
        },
        {
            "x": -8,
            "y": 2,
            "z": 8,
            "elements": [
                "chisel:glass@6"
            ]
        },
        {
            "x": -4,
            "y": -1,
            "z": 2,
            "elements": [
                "modularmachinery:blockcasing@0"
            ]
        },
        {
            "x": -1,
            "y": 3,
            "z": 14,
            "elements": [
                "chisel:technicalnew@4"
            ]
        },
        {
            "x": 3,
            "y": 4,
            "z": 9,
            "elements": [
                "chisel:technical1@4"
            ]
        },
        {
            "x": 8,
            "y": 4,
            "z": 6,
            "elements": [
                "chisel:technical@1"
            ]
        },
        {
            "x": 2,
            "y": 1,
            "z": 14,
            "elements": [
                "chisel:technical@4"
            ]
        },
        {
            "x": 8,
            "y": 1,
            "z": 7,
            "elements": [
                "chisel:glass@6"
            ]
        },
        {
            "x": 7,
            "y": 4,
            "z": 1,
            "elements": [
                "chisel:technical@1"
            ]
        },
        {
            "x": 8,
            "y": 0,
            "z": 6,
            "elements": [
                "modularmachinery:blockcasing@2"
            ]
        },
        {
            "x": -1,
            "y": -1,
            "z": 12,
            "elements": [
                "advancedrocketry:blastbrick@0"
            ]
        },
        {
            "x": -8,
            "y": 0,
            "z": 1,
            "elements": [
                "modularmachinery:blockcasing@0"
            ]
        },
        {
            "x": 1,
            "y": 4,
            "z": 11,
            "elements": [
                "chisel:technical1@3"
            ]
        },
        {
            "x": 7,
            "y": 0,
            "z": 11,
            "elements": [
                "advancedrocketry:blastbrick@0"
            ]
        },
        {
            "x": -8,
            "y": -1,
            "z": 7,
            "elements": [
                "modularmachinery:blockcasing@4"
            ]
        },
        {
            "x": 3,
            "y": -1,
            "z": 4,
            "elements": [
                "modularmachinery:blockcasing@0"
            ]
        },
        {
            "x": -5,
            "y": 0,
            "z": 8,
            "elements": [
                "modularmachinery:blockcasing@3"
            ]
        },
        {
            "x": -8,
            "y": 4,
            "z": 8,
            "elements": [
                "chisel:technical@1"
            ]
        },
        {
            "x": -2,
            "y": 0,
            "z": 8,
            "elements": [
                "mekanism:basicblock2@5"
            ]
        },
        {
            "x": -5,
            "y": -1,
            "z": 2,
            "elements": [
                "modularmachinery:blockcasing@0"
            ]
        },
        {
            "x": 8,
            "y": 2,
            "z": 6,
            "elements": [
                "chisel:glass@6"
            ]
        },
        {
            "x": 7,
            "y": -1,
            "z": 7,
            "elements": [
                "modularmachinery:blockcasing@0"
            ]
        },
        {
            "x": 5,
            "y": 4,
            "z": 6,
            "elements": [
                "chisel:technical1@3"
            ]
        },
        {
            "x": 4,
            "y": 0,
            "z": 4,
            "elements": [
                "mekanism:basicblock2@5"
            ]
        },
        {
            "x": 4,
            "y": 4,
            "z": 11,
            "elements": [
                "chisel:technical@8"
            ]
        },
        {
            "x": -1,
            "y": 4,
            "z": 6,
            "elements": [
                "chisel:technical1@3"
            ]
        },
        {
            "x": 3,
            "y": 0,
            "z": 9,
            "elements": [
                "advancedrocketry:blastbrick@0"
            ]
        },
        {
            "x": 7,
            "y": 0,
            "z": 1,
            "elements": [
                "modularmachinery:blockcasing@0"
            ]
        },
        {
            "x": -5,
            "y": -1,
            "z": 7,
            "elements": [
                "modularmachinery:blockcasing@0"
            ]
        },
        {
            "x": 2,
            "y": -1,
            "z": 2,
            "elements": [
                "modularmachinery:blockcasing@0"
            ]
        },
        {
            "x": 1,
            "y": 0,
            "z": 8,
            "elements": [
                "modularmachinery:blockcasing@3"
            ]
        },
        {
            "x": -1,
            "y": 4,
            "z": 8,
            "elements": [
                "chisel:technical1@3"
            ]
        },
        {
            "x": 2,
            "y": -1,
            "z": 9,
            "elements": [
                "advancedrocketry:blastbrick@0"
            ]
        },
        {
            "x": 6,
            "y": -1,
            "z": 11,
            "elements": [
                "advancedrocketry:blastbrick@0"
            ]
        },
        {
            "x": 5,
            "y": -1,
            "z": 2,
            "elements": [
                "modularmachinery:blockcasing@0"
            ]
        },
        {
            "x": 5,
            "y": -1,
            "z": 12,
            "elements": [
                "modularmachinery:blockcasing@0"
            ]
        },
        {
            "x": 4,
            "y": 4,
            "z": 4,
            "elements": [
                "chisel:technical@8"
            ]
        },
        {
            "x": 8,
            "y": -1,
            "z": 15,
            "elements": [
                "chisel:blocksteel@4"
            ]
        },
        {
            "x": 2,
            "y": 0,
            "z": 6,
            "elements": [
                "mekanism:basicblock2@5"
            ]
        },
        {
            "x": -2,
            "y": -1,
            "z": 7,
            "elements": [
                "advancedrocketry:blastbrick@0"
            ]
        },
        {
            "x": 7,
            "y": 2,
            "z": 1,
            "elements": [
                "immersiveengineering:metal_decoration0@7"
            ]
        },
        {
            "x": 4,
            "y": 4,
            "z": 1,
            "elements": [
                "chisel:technical@1"
            ]
        },
        {
            "x": 6,
            "y": 0,
            "z": 9,
            "elements": [
                "mekanism:basicblock2@5"
            ]
        },
        {
            "x": 5,
            "y": -1,
            "z": 9,
            "elements": [
                "modularmachinery:blockcasing@0"
            ]
        },
        {
            "x": 8,
            "y": -2,
            "z": 15,
            "elements": [
                "chisel:blocksteel@4"
            ]
        },
        {
            "x": -1,
            "y": 1,
            "z": 14,
            "elements": [
                "chisel:technicalnew@4"
            ]
        },
        {
            "x": -3,
            "y": 0,
            "z": 13,
            "elements": [
                "advancedrocketry:blastbrick@0"
            ]
        },
        {
            "x": -2,
            "y": 4,
            "z": 8,
            "elements": [
                "chisel:glass@6"
            ]
        },
        {
            "x": 0,
            "y": 4,
            "z": 9,
            "elements": [
                "chisel:technical1@3"
            ]
        },
        {
            "x": 7,
            "y": 4,
            "z": 10,
            "elements": [
                "chisel:technical1@3"
            ]
        },
        {
            "x": 2,
            "y": 3,
            "z": 14,
            "elements": [
                "chisel:technical@4"
            ]
        },
        {
            "x": 2,
            "y": -1,
            "z": 12,
            "elements": [
                "advancedrocketry:blastbrick@0"
            ]
        },
        {
            "x": 2,
            "y": 4,
            "z": 13,
            "elements": [
                "chisel:technical1@4"
            ]
        },
        {
            "x": -5,
            "y": 4,
            "z": 1,
            "elements": [
                "chisel:technical@1"
            ]
        },
        {
            "x": 1,
            "y": 0,
            "z": 1,
            "elements": [
                "modularmachinery:blockcasing@0"
            ]
        },
        {
            "x": 0,
            "y": -1,
            "z": 2,
            "elements": [
                "modularmachinery:blockcasing@0"
            ]
        },
        {
            "x": -1,
            "y": 0,
            "z": 8,
            "elements": [
                "modularmachinery:blockcasing@3"
            ]
        },
        {
            "x": 4,
            "y": 2,
            "z": 1,
            "elements": [
                "chisel:technicalnew@4"
            ]
        },
        {
            "x": 6,
            "y": 4,
            "z": 10,
            "elements": [
                "chisel:technical1@3"
            ]
        },
        {
            "x": 0,
            "y": 0,
            "z": 13,
            "elements": [
                "advancedrocketry:blastbrick@0"
            ]
        },
        {
            "x": -7,
            "y": 4,
            "z": 8,
            "elements": [
                "chisel:technical1@3"
            ]
        },
        {
            "x": 6,
            "y": 0,
            "z": 10,
            "elements": [
                "mekanism:basicblock2@5"
            ]
        },
        {
            "x": -3,
            "y": 4,
            "z": 13,
            "elements": [
                "chisel:technical1@4"
            ]
        },
        {
            "x": 3,
            "y": 0,
            "z": 13,
            "elements": [
                "advancedrocketry:blastbrick@0"
            ]
        },
        {
            "x": 4,
            "y": -1,
            "z": 7,
            "elements": [
                "advancedrocketry:blastbrick@0"
            ]
        },
        {
            "x": 0,
            "y": 0,
            "z": 9,
            "elements": [
                "mekanism:basicblock2@5"
            ]
        },
        {
            "x": 1,
            "y": 2,
            "z": 1,
            "elements": [
                "chisel:technicalnew@4"
            ]
        },
        {
            "x": 4,
            "y": 0,
            "z": 1,
            "elements": [
                "modularmachinery:blockcasing@0"
            ]
        },
        {
            "x": -1,
            "y": -1,
            "z": 2,
            "elements": [
                "modularmachinery:blockcasing@0"
            ]
        },
        {
            "x": -2,
            "y": 4,
            "z": 1,
            "elements": [
                "chisel:technical@1"
            ]
        },
        {
            "x": 7,
            "y": 0,
            "z": 10,
            "elements": [
                "advancedrocketry:blastbrick@0"
            ]
        },
        {
            "x": -4,
            "y": 3,
            "z": 14,
            "elements": [
                "chisel:technicalnew@4"
            ]
        },
        {
            "x": 8,
            "y": 3,
            "z": 0,
            "elements": [
                "modularmachinery:blockcasing@4"
            ]
        },
        {
            "x": -4,
            "y": 4,
            "z": 8,
            "elements": [
                "chisel:technical@8"
            ]
        },
        {
            "x": 5,
            "y": 1,
            "z": 14,
            "elements": [
                "chisel:technical@4"
            ]
        },
        {
            "x": -1,
            "y": -1,
            "z": 9,
            "elements": [
                "modularmachinery:blockcasing@0"
            ]
        },
        {
            "x": 5,
            "y": 0,
            "z": 6,
            "elements": [
                "advancedrocketry:blastbrick@0"
            ]
        },
        {
            "x": 2,
            "y": 0,
            "z": 13,
            "elements": [
                "advancedrocketry:blastbrick@0"
            ]
        },
        {
            "x": -5,
            "y": 0,
            "z": 1,
            "elements": [
                "modularmachinery:blockcasing@0"
            ]
        },
        {
            "x": -2,
            "y": -1,
            "z": 2,
            "elements": [
                "modularmachinery:blockcasing@0"
            ]
        },
        {
            "x": 7,
            "y": 4,
            "z": 4,
            "elements": [
                "chisel:technical1@3"
            ]
        },
        {
            "x": 0,
            "y": 4,
            "z": 13,
            "elements": [
                "chisel:technical1@3"
            ]
        },
        {
            "x": 1,
            "y": 4,
            "z": 1,
            "elements": [
                "chisel:technical@1"
            ]
        },
        {
            "x": -3,
            "y": 0,
            "z": 8,
            "elements": [
                "modularmachinery:blockcasing@3"
            ]
        },
        {
            "x": 8,
            "y": 4,
            "z": 0,
            "elements": [
                "chisel:technicalnew@2"
            ]
        },
        {
            "x": 8,
            "y": 4,
            "z": 14,
            "elements": [
                "chisel:technicalnew@4"
            ]
        },
        {
            "x": 2,
            "y": 4,
            "z": 6,
            "elements": [
                "chisel:technical1@4"
            ]
        },
        {
            "x": -5,
            "y": 4,
            "z": 8,
            "elements": [
                "chisel:technical1@3"
            ]
        },
        {
            "x": -6,
            "y": 0,
            "z": 9,
            "elements": [
                "mekanism:basicblock2@5"
            ]
        },
        {
            "x": 6,
            "y": -1,
            "z": 3,
            "elements": [
                "advancedrocketry:blastbrick@0"
            ]
        },
        {
            "x": 7,
            "y": 4,
            "z": 11,
            "elements": [
                "chisel:technical1@3"
            ]
        },
        {
            "x": 5,
            "y": 3,
            "z": 14,
            "elements": [
                "chisel:technical@4"
            ]
        },
        {
            "x": 4,
            "y": 4,
            "z": 3,
            "elements": [
                "chisel:technical@8"
            ]
        },
        {
            "x": 1,
            "y": -1,
            "z": 2,
            "elements": [
                "modularmachinery:blockcasing@0"
            ]
        },
        {
            "x": -8,
            "y": 4,
            "z": 1,
            "elements": [
                "chisel:technicalnew@4"
            ]
        },
        {
            "x": -1,
            "y": 4,
            "z": 13,
            "elements": [
                "chisel:technical1@3"
            ]
        },
        {
            "x": -5,
            "y": 2,
            "z": 1,
            "elements": [
                "chisel:technical@4"
            ]
        },
        {
            "x": 5,
            "y": -1,
            "z": 10,
            "elements": [
                "modularmachinery:blockcasing@0"
            ]
        },
        {
            "x": 8,
            "y": 2,
            "z": 0,
            "elements": [
                "modularmachinery:blockcasing@4"
            ]
        },
        {
            "x": -4,
            "y": 0,
            "z": 8,
            "elements": [
                "mekanism:basicblock2@5"
            ]
        },
        {
            "x": -7,
            "y": -1,
            "z": 9,
            "elements": [
                "modularmachinery:blockcasing@0"
            ]
        },
        {
            "x": -8,
            "y": 0,
            "z": 0,
            "elements": [
                "modularmachinery:blockcasing@4"
            ]
        },
        {
            "x": 3,
            "y": 4,
            "z": 10,
            "elements": [
                "chisel:technical1@4"
            ]
        },
        {
            "x": 8,
            "y": 1,
            "z": 0,
            "elements": [
                "modularmachinery:blockcasing@4"
            ]
        },
        {
            "x": -6,
            "y": 4,
            "z": 8,
            "elements": [
                "chisel:technical1@3"
            ]
        },
        {
            "x": -3,
            "y": 4,
            "z": 6,
            "elements": [
                "chisel:technical1@4"
            ]
        },
        {
            "x": -3,
            "y": 0,
            "z": 1,
            "elements": [
                "modularmachinery:blockcasing@0"
            ]
        },
        {
            "x": 4,
            "y": 4,
            "z": 5,
            "elements": [
                "chisel:technical@8"
            ]
        },
        {
            "x": -8,
            "y": 3,
            "z": 7,
            "elements": [
                "chisel:glass@6"
            ]
        },
        {
            "x": -7,
            "y": -1,
            "z": 7,
            "elements": [
                "modularmachinery:blockcasing@0"
            ]
        },
        {
            "x": 0,
            "y": 2,
            "z": 1,
            "elements": [
                "modularmachinery:blockcasing@1"
            ]
        },
        {
            "x": 7,
            "y": 0,
            "z": 3,
            "elements": [
                "advancedrocketry:blastbrick@0"
            ]
        },
        {
            "x": 3,
            "y": 0,
            "z": 6,
            "elements": [
                "advancedrocketry:blastbrick@0"
            ]
        },
        {
            "x": -6,
            "y": 1,
            "z": 14,
            "elements": [
                "modularmachinery:blockcasing@1"
            ]
        },
        {
            "x": -1,
            "y": 4,
            "z": 1,
            "elements": [
                "chisel:technical@1"
            ]
        },
        {
            "x": -4,
            "y": 0,
            "z": 13,
            "elements": [
                "advancedrocketry:blastbrick@0"
            ]
        },
        {
            "x": 0,
            "y": -1,
            "z": 7,
            "elements": [
                "advancedrocketry:blastbrick@0"
            ]
        },
        {
            "x": -6,
            "y": 4,
            "z": 6,
            "elements": [
                "chisel:technical1@3"
            ]
        },
        {
            "x": -7,
            "y": 4,
            "z": 13,
            "elements": [
                "chisel:technical1@3"
            ]
        },
        {
            "x": -6,
            "y": 4,
            "z": 1,
            "elements": [
                "chisel:technical@1"
            ]
        },
        {
            "x": 0,
            "y": 0,
            "z": 6,
            "elements": [
                "mekanism:basicblock2@5"
            ]
        },
        {
            "x": 0,
            "y": 0,
            "z": 1,
            "elements": [
                "modularmachinery:blockcasing@0"
            ]
        },
        {
            "x": -3,
            "y": 2,
            "z": 1,
            "elements": [
                "modularmachinery:blockcasing@1"
            ]
        },
        {
            "x": 3,
            "y": -1,
            "z": 2,
            "elements": [
                "modularmachinery:blockcasing@0"
            ]
        },
        {
            "x": -7,
            "y": 1,
            "z": 14,
            "elements": [
                "immersiveengineering:metal_decoration0@7"
            ]
        },
        {
            "x": -8,
            "y": 3,
            "z": 14,
            "elements": [
                "chisel:technicalnew@4"
            ]
        },
        {
            "x": -1,
            "y": 0,
            "z": 1,
            "elements": [
                "modularmachinery:blockcasing@0"
            ]
        },
        {
            "x": -1,
            "y": 0,
            "z": 13,
            "elements": [
                "advancedrocketry:blastbrick@0"
            ]
        },
        {
            "x": 7,
            "y": 4,
            "z": 8,
            "elements": [
                "chisel:technical1@3"
            ]
        },
        {
            "x": 0,
            "y": -1,
            "z": 12,
            "elements": [
                "advancedrocketry:blastbrick@0"
            ]
        },
        {
            "x": -8,
            "y": 1,
            "z": 12,
            "elements": [
                "chisel:glass@6"
            ]
        },
        {
            "x": -4,
            "y": 4,
            "z": 13,
            "elements": [
                "chisel:technical@8"
            ]
        },
        {
            "x": 3,
            "y": -1,
            "z": 7,
            "elements": [
                "modularmachinery:blockcasing@0"
            ]
        },
        {
            "x": 7,
            "y": 4,
            "z": 3,
            "elements": [
                "chisel:technical1@3"
            ]
        },
        {
            "x": -2,
            "y": 2,
            "z": 1,
            "elements": [
                "chisel:technical@4"
            ]
        },
        {
            "x": -8,
            "y": 1,
            "z": 2,
            "elements": [
                "chisel:glass@6"
            ]
        },
        {
            "x": -6,
            "y": -1,
            "z": 2,
            "elements": [
                "modularmachinery:blockcasing@0"
            ]
        },
        {
            "x": -7,
            "y": 0,
            "z": 6,
            "elements": [
                "advancedrocketry:blastbrick@0"
            ]
        },
        {
            "x": -3,
            "y": 4,
            "z": 1,
            "elements": [
                "chisel:technical@1"
            ]
        },
        {
            "x": -4,
            "y": 1,
            "z": 14,
            "elements": [
                "chisel:technicalnew@4"
            ]
        },
        {
            "x": -7,
            "y": 3,
            "z": 14,
            "elements": [
                "immersiveengineering:metal_decoration0@7"
            ]
        },
        {
            "x": -8,
            "y": 0,
            "z": 5,
            "elements": [
                "modularmachinery:blockcasing@2"
            ]
        },
        {
            "x": -2,
            "y": 0,
            "z": 1,
            "elements": [
                "modularmachinery:blockcasing@0"
            ]
        },
        {
            "x": -3,
            "y": -1,
            "z": 12,
            "elements": [
                "modularmachinery:blockcasing@0"
            ]
        },
        {
            "x": 0,
            "y": 4,
            "z": 6,
            "elements": [
                "chisel:technical1@3"
            ]
        },
        {
            "x": -8,
            "y": 3,
            "z": 12,
            "elements": [
                "chisel:glass@6"
            ]
        },
        {
            "x": -1,
            "y": 2,
            "z": 1,
            "elements": [
                "chisel:technicalnew@4"
            ]
        },
        {
            "x": -4,
            "y": 4,
            "z": 1,
            "elements": [
                "chisel:technical@1"
            ]
        },
        {
            "x": -8,
            "y": 3,
            "z": 2,
            "elements": [
                "chisel:glass@6"
            ]
        },
        {
            "x": -7,
            "y": 0,
            "z": 8,
            "elements": [
                "advancedrocketry:blastbrick@0"
            ]
        },
        {
            "x": -3,
            "y": -1,
            "z": 2,
            "elements": [
                "modularmachinery:blockcasing@0"
            ]
        },
        {
            "x": -8,
            "y": 2,
            "z": 5,
            "elements": [
                "chisel:glass@6"
            ]
        },
        {
            "x": -6,
            "y": 0,
            "z": 6,
            "elements": [
                "mekanism:basicblock2@5"
            ]
        },
        {
            "x": -8,
            "y": 1,
            "z": 5,
            "elements": [
                "chisel:glass@6"
            ]
        },
        {
            "x": -6,
            "y": -1,
            "z": 12,
            "elements": [
                "advancedrocketry:blastbrick@0"
            ]
        },
        {
            "x": -6,
            "y": 4,
            "z": 13,
            "elements": [
                "chisel:technical1@3"
            ]
        },
        {
            "x": 1,
            "y": 4,
            "z": 8,
            "elements": [
                "chisel:technical1@3"
            ]
        },
        {
            "x": -8,
            "y": 3,
            "z": 5,
            "elements": [
                "chisel:glass@6"
            ]
        },
        {
            "x": -7,
            "y": 0,
            "z": 1,
            "elements": [
                "modularmachinery:blockcasing@0"
            ]
        },
        {
            "x": 1,
            "y": 0,
            "z": 5,
            "elements": [
                "advancedrocketry:blastbrick@0"
            ]
        },
        {
            "x": -1,
            "y": 0,
            "z": 6,
            "elements": [
                "advancedrocketry:blastbrick@0"
            ]
        },
        {
            "x": -7,
            "y": 4,
            "z": 6,
            "elements": [
                "chisel:technical1@3"
            ]
        },
        {
            "x": -3,
            "y": -1,
            "z": 7,
            "elements": [
                "modularmachinery:blockcasing@0"
            ]
        },
        {
            "x": -4,
            "y": 2,
            "z": 1,
            "elements": [
                "chisel:technicalnew@4"
            ]
        },
        {
            "x": -8,
            "y": 4,
            "z": 5,
            "elements": [
                "chisel:technical@1"
            ]
        },
        {
            "x": 3,
            "y": 4,
            "z": 1,
            "elements": [
                "chisel:technical@1"
            ]
        },
        {
            "x": -8,
            "y": 0,
            "z": 13,
            "elements": [
                "modularmachinery:blockcasing@2"
            ]
        },
        {
            "x": 7,
            "y": 0,
            "z": 8,
            "elements": [
                "advancedrocketry:blastbrick@0"
            ]
        },
        {
            "x": -5,
            "y": -1,
            "z": 12,
            "elements": [
                "advancedrocketry:blastbrick@0"
            ]
        },
        {
            "x": 7,
            "y": 4,
            "z": 5,
            "elements": [
                "chisel:technical1@3"
            ]
        },
        {
            "x": -4,
            "y": 0,
            "z": 1,
            "elements": [
                "modularmachinery:blockcasing@0"
            ]
        },
        {
            "x": -7,
            "y": 2,
            "z": 1,
            "elements": [
                "immersiveengineering:metal_decoration0@7"
            ]
        },
        {
            "x": 4,
            "y": 4,
            "z": 8,
            "elements": [
                "chisel:technical@8"
            ]
        },
        {
            "x": -2,
            "y": 4,
            "z": 6,
            "elements": [
                "chisel:technical1@4"
            ]
        },
        {
            "x": -4,
            "y": -1,
            "z": 7,
            "elements": [
                "advancedrocketry:blastbrick@0"
            ]
        },
        {
            "x": -3,
            "y": 1,
            "z": 14,
            "elements": [
                "modularmachinery:blockcasing@1"
            ]
        },
        {
            "x": 2,
            "y": 0,
            "z": 8,
            "elements": [
                "mekanism:basicblock2@5"
            ]
        },
        {
            "x": -4,
            "y": 0,
            "z": 6,
            "elements": [
                "mekanism:basicblock2@5"
            ]
        },
        {
            "x": 6,
            "y": 4,
            "z": 9,
            "elements": [
                "chisel:technical1@3"
            ]
        },
        {
            "x": -8,
            "y": 2,
            "z": 13,
            "elements": [
                "chisel:glass@6"
            ]
        },
        {
            "x": 0,
            "y": -1,
            "z": 5,
            "elements": [
                "advancedrocketry:blastbrick@0"
            ]
        },
        {
            "x": -5,
            "y": 0,
            "z": 13,
            "elements": [
                "advancedrocketry:blastbrick@0"
            ]
        },
        {
            "x": -4,
            "y": -1,
            "z": 12,
            "elements": [
                "advancedrocketry:blastbrick@0"
            ]
        },
        {
            "x": -1,
            "y": -1,
            "z": 7,
            "elements": [
                "modularmachinery:blockcasing@0"
            ]
        },
        {
            "x": -5,
            "y": 4,
            "z": 6,
            "elements": [
                "chisel:technical1@3"
            ]
        },
        {
            "x": 6,
            "y": -1,
            "z": 2,
            "elements": [
                "modularmachinery:blockcasing@0"
            ]
        },
        {
            "x": -7,
            "y": 4,
            "z": 1,
            "elements": [
                "chisel:technical@1"
            ]
        },
        {
            "x": -8,
            "y": 4,
            "z": 13,
            "elements": [
                "chisel:technical@1"
            ]
        },
        {
            "x": -3,
            "y": 0,
            "z": 6,
            "elements": [
                "advancedrocketry:blastbrick@0"
            ]
        },
        {
            "x": -2,
            "y": 4,
            "z": 5,
            "elements": [
                "chisel:technical1@4"
            ]
        },
        {
            "x": 3,
            "y": 0,
            "z": 1,
            "elements": [
                "modularmachinery:blockcasing@0"
            ]
        },
        {
            "x": 7,
            "y": 0,
            "z": 5,
            "elements": [
                "advancedrocketry:blastbrick@0"
            ]
        },
        {
            "x": 2,
            "y": 2,
            "z": 1,
            "elements": [
                "chisel:technical@4"
            ]
        },
        {
            "x": 5,
            "y": 0,
            "z": 8,
            "elements": [
                "modularmachinery:blockcasing@3"
            ]
        },
        {
            "x": 3,
            "y": -1,
            "z": 5,
            "elements": [
                "modularmachinery:blockcasing@0"
            ]
        },
        {
            "x": -6,
            "y": 0,
            "z": 13,
            "elements": [
                "advancedrocketry:blastbrick@0"
            ]
        },
        {
            "x": 0,
            "y": 1,
            "z": 14,
            "elements": [
                "modularmachinery:blockcasing@1"
            ]
        },
        {
            "x": -3,
            "y": 3,
            "z": 14,
            "elements": [
                "modularmachinery:blockcasing@1"
            ]
        },
        {
            "x": -7,
            "y": -1,
            "z": 12,
            "elements": [
                "modularmachinery:blockcasing@0"
            ]
        },
        {
            "x": -4,
            "y": 4,
            "z": 6,
            "elements": [
                "chisel:technical@8"
            ]
        },
        {
            "x": 2,
            "y": 4,
            "z": 8,
            "elements": [
                "chisel:glass@6"
            ]
        },
        {
            "x": 4,
            "y": 0,
            "z": 5,
            "elements": [
                "mekanism:basicblock2@5"
            ]
        },
        {
            "x": -2,
            "y": 0,
            "z": 6,
            "elements": [
                "mekanism:basicblock2@5"
            ]
        },
        {
            "x": 1,
            "y": 4,
            "z": 5,
            "elements": [
                "chisel:technical1@3"
            ]
        },
        {
            "x": -6,
            "y": -1,
            "z": 7,
            "elements": [
                "advancedrocketry:blastbrick@0"
            ]
        },
        {
            "x": 2,
            "y": 0,
            "z": 1,
            "elements": [
                "modularmachinery:blockcasing@0"
            ]
        },
        {
            "x": 3,
            "y": 2,
            "z": 1,
            "elements": [
                "modularmachinery:blockcasing@1"
            ]
        },
        {
            "x": -7,
            "y": 0,
            "z": 13,
            "elements": [
                "advancedrocketry:blastbrick@0"
            ]
        },
        {
            "x": 0,
            "y": 4,
            "z": 1,
            "elements": [
                "chisel:technical@1"
            ]
        },
        {
            "x": -6,
            "y": 3,
            "z": 14,
            "elements": [
                "modularmachinery:blockcasing@1"
            ]
        },
        {
            "x": 4,
            "y": 0,
            "z": 8,
            "elements": [
                "mekanism:basicblock2@5"
            ]
        },
        {
            "x": 6,
            "y": -1,
            "z": 5,
            "elements": [
                "advancedrocketry:blastbrick@0"
            ]
        },
        {
            "x": 4,
            "y": 0,
            "z": 13,
            "elements": [
                "advancedrocketry:blastbrick@0"
            ]
        },
        {
            "x": 5,
            "y": 4,
            "z": 8,
            "elements": [
                "chisel:technical1@3"
            ]
        },
        {
            "x": -2,
            "y": 4,
            "z": 11,
            "elements": [
                "chisel:technical1@4"
            ]
        },
        {
            "x": 8,
            "y": 1,
            "z": 8,
            "elements": [
                "chisel:glass@6"
            ]
        },
        {
            "x": 8,
            "y": 2,
            "z": 8,
            "elements": [
                "chisel:glass@6"
            ]
        },
        {
            "x": 5,
            "y": 1,
            "z": 1,
            "elements": [
                "chisel:technical@4"
            ]
        },
        {
            "x": 4,
            "y": 4,
            "z": 12,
            "elements": [
                "chisel:technical@8"
            ]
        },
        {
            "x": 1,
            "y": 0,
            "z": 14,
            "elements": [
                "modularmachinery:blockcasing@0"
            ]
        },
        {
            "x": -8,
            "y": 3,
            "z": 15,
            "elements": [
                "modularmachinery:blockcasing@4"
            ]
        },
        {
            "x": 8,
            "y": 3,
            "z": 1,
            "elements": [
                "chisel:technicalnew@4"
            ]
        },
        {
            "x": 5,
            "y": 0,
            "z": 1,
            "elements": [
                "modularmachinery:blockcasing@0"
            ]
        },
        {
            "x": 3,
            "y": -1,
            "z": 13,
            "elements": [
                "modularmachinery:blockcasing@0"
            ]
        },
        {
            "x": -2,
            "y": 4,
            "z": 13,
            "elements": [
                "chisel:technical1@4"
            ]
        },
        {
            "x": -6,
            "y": -1,
            "z": 15,
            "elements": [
                "chisel:blocksteel@6"
            ]
        },
        {
            "x": 1,
            "y": 0,
            "z": 11,
            "elements": [
                "advancedrocketry:blastbrick@0"
            ]
        },
        {
            "x": -1,
            "y": 1,
            "z": 0,
            "elements": [
                "modularmachinery:blockfluidoutputhatch",
                "modularmachinery:blockmefluidoutputbus"
            ]
        },
        {
            "x": -8,
            "y": 1,
            "z": 15,
            "elements": [
                "modularmachinery:blockcasing@4"
            ]
        },
        {
            "x": -2,
            "y": 4,
            "z": 14,
            "elements": [
                "chisel:technical@1"
            ]
        },
        {
            "x": 8,
            "y": 2,
            "z": 1,
            "elements": [
                "chisel:technicalnew@4"
            ]
        },
        {
            "x": -5,
            "y": 0,
            "z": 6,
            "elements": [
                "advancedrocketry:blastbrick@0"
            ]
        },
        {
            "x": -3,
            "y": -1,
            "z": 5,
            "elements": [
                "modularmachinery:blockcasing@0"
            ]
        },
        {
            "x": -4,
            "y": -1,
            "z": 10,
            "elements": [
                "advancedrocketry:blastbrick@0"
            ]
        },
        {
            "x": 5,
            "y": 3,
            "z": 1,
            "elements": [
                "chisel:technical@4"
            ]
        },
        {
            "x": 8,
            "y": 4,
            "z": 8,
            "elements": [
                "chisel:technical@1"
            ]
        },
        {
            "x": -6,
            "y": -1,
            "z": 6,
            "elements": [
                "advancedrocketry:blastbrick@0"
            ]
        },
        {
            "x": 8,
            "y": 1,
            "z": 1,
            "elements": [
                "chisel:technicalnew@4"
            ]
        },
        {
            "x": 7,
            "y": 0,
            "z": 13,
            "elements": [
                "advancedrocketry:blastbrick@0"
            ]
        },
        {
            "x": -8,
            "y": 1,
            "z": 6,
            "elements": [
                "chisel:glass@6"
            ]
        },
        {
            "x": 6,
            "y": 4,
            "z": 4,
            "elements": [
                "chisel:technical1@3"
            ]
        },
        {
            "x": 1,
            "y": 2,
            "z": 14,
            "elements": [
                "chisel:technicalnew@4"
            ]
        },
        {
            "x": 2,
            "y": 4,
            "z": 1,
            "elements": [
                "chisel:technical@1"
            ]
        },
        {
            "x": 1,
            "y": 4,
            "z": 13,
            "elements": [
                "chisel:technical1@3"
            ]
        },
        {
            "x": 6,
            "y": -1,
            "z": 13,
            "elements": [
                "modularmachinery:blockcasing@0"
            ]
        },
        {
            "x": -2,
            "y": 1,
            "z": 0,
            "elements": [
                "modularmachinery:blockupgradebus"
            ]
        },
        {
            "x": 8,
            "y": 0,
            "z": 1,
            "elements": [
                "modularmachinery:blockcasing@0"
            ]
        },
        {
            "x": -8,
            "y": 0,
            "z": 6,
            "elements": [
                "modularmachinery:blockcasing@2"
            ]
        },
        {
            "x": 8,
            "y": 3,
            "z": 8,
            "elements": [
                "chisel:glass@6"
            ]
        },
        {
            "x": -4,
            "y": -1,
            "z": 5,
            "elements": [
                "advancedrocketry:blastbrick@0"
            ]
        },
        {
            "x": 5,
            "y": 2,
            "z": 1,
            "elements": [
                "chisel:technical@4"
            ]
        },
        {
            "x": 4,
            "y": 0,
            "z": 9,
            "elements": [
                "mekanism:basicblock2@5"
            ]
        },
        {
            "x": 1,
            "y": 1,
            "z": 14,
            "elements": [
                "chisel:technicalnew@4"
            ]
        },
        {
            "x": -5,
            "y": -1,
            "z": 10,
            "elements": [
                "modularmachinery:blockcasing@0"
            ]
        },
        {
            "x": -8,
            "y": -3,
            "z": 15,
            "elements": [
                "chisel:blocksteel@4"
            ]
        },
        {
            "x": -2,
            "y": -1,
            "z": 10,
            "elements": [
                "advancedrocketry:blastbrick@0"
            ]
        },
        {
            "x": -3,
            "y": -1,
            "z": 13,
            "elements": [
                "modularmachinery:blockcasing@0"
            ]
        },
        {
            "x": -8,
            "y": 2,
            "z": 6,
            "elements": [
                "chisel:glass@6"
            ]
        },
        {
            "x": 3,
            "y": 4,
            "z": 4,
            "elements": [
                "chisel:technical1@4"
            ]
        },
        {
            "x": 4,
            "y": 4,
            "z": 13,
            "elements": [
                "chisel:technical@8"
            ]
        },
        {
            "x": 1,
            "y": 0,
            "z": 6,
            "elements": [
                "advancedrocketry:blastbrick@0"
            ]
        },
        {
            "x": 1,
            "y": 1,
            "z": 0,
            "elements": [
                "modularmachinery:blockfluidinputhatch",
                "modularmachinery:blockmefluidinputbus"
            ]
        },
        {
            "x": -1,
            "y": -1,
            "z": 5,
            "elements": [
                "modularmachinery:blockcasing@0"
            ]
        },
        {
            "x": -8,
            "y": 3,
            "z": 6,
            "elements": [
                "chisel:glass@6"
            ]
        },
        {
            "x": -2,
            "y": 0,
            "z": 13,
            "elements": [
                "advancedrocketry:blastbrick@0"
            ]
        },
        {
            "x": 5,
            "y": 4,
            "z": 1,
            "elements": [
                "chisel:technical@1"
            ]
        },
        {
            "x": -8,
            "y": -1,
            "z": 15,
            "elements": [
                "chisel:blocksteel@4"
            ]
        },
        {
            "x": 4,
            "y": 1,
            "z": 14,
            "elements": [
                "chisel:technicalnew@4"
            ]
        },
        {
            "x": -5,
            "y": 4,
            "z": 13,
            "elements": [
                "chisel:technical1@3"
            ]
        },
        {
            "x": 1,
            "y": 3,
            "z": 14,
            "elements": [
                "chisel:technicalnew@4"
            ]
        },
        {
            "x": 2,
            "y": -1,
            "z": 3,
            "elements": [
                "advancedrocketry:blastbrick@0"
            ]
        },
        {
            "x": 7,
            "y": -1,
            "z": 8,
            "elements": [
                "modularmachinery:blockcasing@0"
            ]
        },
        {
            "x": -5,
            "y": 4,
            "z": 11,
            "elements": [
                "chisel:technical1@3"
            ]
        },
        {
            "x": 4,
            "y": 0,
            "z": 14,
            "elements": [
                "modularmachinery:blockcasing@0"
            ]
        },
        {
            "x": -8,
            "y": 4,
            "z": 6,
            "elements": [
                "chisel:technical@1"
            ]
        },
        {
            "x": -6,
            "y": -1,
            "z": 5,
            "elements": [
                "advancedrocketry:blastbrick@0"
            ]
        },
        {
            "x": 1,
            "y": 4,
            "z": 14,
            "elements": [
                "chisel:technical@1"
            ]
        },
        {
            "x": -2,
            "y": 0,
            "z": 11,
            "elements": [
                "mekanism:basicblock2@5"
            ]
        },
        {
            "x": -7,
            "y": -1,
            "z": 10,
            "elements": [
                "modularmachinery:blockcasing@0"
            ]
        },
        {
            "x": 0,
            "y": -1,
            "z": 6,
            "elements": [
                "advancedrocketry:blastbrick@0"
            ]
        },
        {
            "x": 8,
            "y": 0,
            "z": 8,
            "elements": [
                "modularmachinery:blockcasing@2"
            ]
        },
        {
            "x": -2,
            "y": 3,
            "z": 14,
            "elements": [
                "chisel:technical@4"
            ]
        },
        {
            "x": 6,
            "y": 0,
            "z": 4,
            "elements": [
                "mekanism:basicblock2@5"
            ]
        },
        {
            "x": 7,
            "y": 0,
            "z": 6,
            "elements": [
                "advancedrocketry:blastbrick@0"
            ]
        },
        {
            "x": 1,
            "y": 4,
            "z": 6,
            "elements": [
                "chisel:technical1@3"
            ]
        },
        {
            "x": -2,
            "y": 2,
            "z": 14,
            "elements": [
                "chisel:technical@4"
            ]
        },
        {
            "x": 1,
            "y": 0,
            "z": 9,
            "elements": [
                "advancedrocketry:blastbrick@0"
            ]
        },
        {
            "x": -4,
            "y": 1,
            "z": 0,
            "elements": [
                "chisel:blocksteel@6"
            ]
        },
        {
            "x": -6,
            "y": 4,
            "z": 11,
            "elements": [
                "chisel:technical1@3"
            ]
        },
        {
            "x": -5,
            "y": 4,
            "z": 14,
            "elements": [
                "chisel:technical@1"
            ]
        },
        {
            "x": -3,
            "y": 4,
            "z": 4,
            "elements": [
                "chisel:technical1@4"
            ]
        },
        {
            "x": -3,
            "y": 0,
            "z": 11,
            "elements": [
                "advancedrocketry:blastbrick@0"
            ]
        },
        {
            "x": -8,
            "y": 2,
            "z": 11,
            "elements": [
                "chisel:glass@6"
            ]
        },
        {
            "x": 1,
            "y": -1,
            "z": 5,
            "elements": [
                "modularmachinery:blockcasing@0"
            ]
        },
        {
            "x": 4,
            "y": 4,
            "z": 6,
            "elements": [
                "chisel:technical@8"
            ]
        },
        {
            "x": -2,
            "y": 1,
            "z": 14,
            "elements": [
                "chisel:technical@4"
            ]
        },
        {
            "x": 7,
            "y": 4,
            "z": 9,
            "elements": [
                "chisel:technical1@3"
            ]
        },
        {
            "x": -5,
            "y": 3,
            "z": 14,
            "elements": [
                "chisel:technical@4"
            ]
        },
        {
            "x": 3,
            "y": -1,
            "z": 6,
            "elements": [
                "modularmachinery:blockcasing@0"
            ]
        },
        {
            "x": 3,
            "y": 0,
            "z": 4,
            "elements": [
                "advancedrocketry:blastbrick@0"
            ]
        },
        {
            "x": 3,
            "y": -1,
            "z": 12,
            "elements": [
                "advancedrocketry:blastbrick@0"
            ]
        },
        {
            "x": -2,
            "y": 0,
            "z": 14,
            "elements": [
                "modularmachinery:blockcasing@0"
            ]
        },
        {
            "x": -1,
            "y": -1,
            "z": 10,
            "elements": [
                "modularmachinery:blockcasing@0"
            ]
        },
        {
            "x": -3,
            "y": 0,
            "z": 4,
            "elements": [
                "advancedrocketry:blastbrick@0"
            ]
        },
        {
            "x": -8,
            "y": 1,
            "z": 3,
            "elements": [
                "chisel:glass@6"
            ]
        },
        {
            "x": 4,
            "y": 0,
            "z": 6,
            "elements": [
                "mekanism:basicblock2@5"
            ]
        },
        {
            "x": 4,
            "y": 2,
            "z": 14,
            "elements": [
                "chisel:technicalnew@4"
            ]
        },
        {
            "x": -2,
            "y": 4,
            "z": 9,
            "elements": [
                "chisel:technical1@4"
            ]
        },
        {
            "x": 2,
            "y": 1,
            "z": 0,
            "elements": [
                "modularmachinery:blockparallelcontroller"
            ]
        },
        {
            "x": 1,
            "y": 0,
            "z": 12,
            "elements": [
                "advancedrocketry:blastbrick@0"
            ]
        },
        {
            "x": -8,
            "y": 0,
            "z": 11,
            "elements": [
                "modularmachinery:blockcasing@2"
            ]
        },
        {
            "x": 0,
            "y": 0,
            "z": 4,
            "elements": [
                "mekanism:basicblock2@5"
            ]
        },
        {
            "x": -6,
            "y": 4,
            "z": 4,
            "elements": [
                "chisel:technical1@3"
            ]
        },
        {
            "x": 6,
            "y": -1,
            "z": 6,
            "elements": [
                "advancedrocketry:blastbrick@0"
            ]
        },
        {
            "x": 5,
            "y": -1,
            "z": 3,
            "elements": [
                "advancedrocketry:blastbrick@0"
            ]
        },
        {
            "x": 2,
            "y": -1,
            "z": 10,
            "elements": [
                "advancedrocketry:blastbrick@0"
            ]
        },
        {
            "x": -5,
            "y": 0,
            "z": 14,
            "elements": [
                "modularmachinery:blockcasing@0"
            ]
        },
        {
            "x": -8,
            "y": 2,
            "z": 14,
            "elements": [
                "chisel:technicalnew@4"
            ]
        },
        {
            "x": -6,
            "y": 0,
            "z": 4,
            "elements": [
                "mekanism:basicblock2@5"
            ]
        },
        {
            "x": -8,
            "y": 4,
            "z": 11,
            "elements": [
                "chisel:technical@1"
            ]
        },
        {
            "x": -8,
            "y": 3,
            "z": 0,
            "elements": [
                "modularmachinery:blockcasing@4"
            ]
        },
        {
            "x": -5,
            "y": -1,
            "z": 5,
            "elements": [
                "modularmachinery:blockcasing@0"
            ]
        },
        {
            "x": -8,
            "y": 1,
            "z": 14,
            "elements": [
                "chisel:technicalnew@4"
            ]
        },
        {
            "x": -5,
            "y": 0,
            "z": 11,
            "elements": [
                "advancedrocketry:blastbrick@0"
            ]
        },
        {
            "x": 7,
            "y": 0,
            "z": 9,
            "elements": [
                "advancedrocketry:blastbrick@0"
            ]
        },
        {
            "x": -6,
            "y": -1,
            "z": 0,
            "elements": [
                "chisel:blocksteel@6"
            ]
        },
        {
            "x": 4,
            "y": 0,
            "z": 12,
            "elements": [
                "mekanism:basicblock2@5"
            ]
        },
        {
            "x": 1,
            "y": 4,
            "z": 9,
            "elements": [
                "chisel:technical1@3"
            ]
        },
        {
            "x": -2,
            "y": 4,
            "z": 12,
            "elements": [
                "chisel:technical1@4"
            ]
        },
        {
            "x": 1,
            "y": 4,
            "z": 12,
            "elements": [
                "chisel:technical1@3"
            ]
        },
        {
            "x": -5,
            "y": 2,
            "z": 14,
            "elements": [
                "chisel:technical@4"
            ]
        },
        {
            "x": -8,
            "y": 1,
            "z": 7,
            "elements": [
                "chisel:glass@6"
            ]
        },
        {
            "x": 0,
            "y": -1,
            "z": 13,
            "elements": [
                "modularmachinery:blockcasing@0"
            ]
        },
        {
            "x": -2,
            "y": -1,
            "z": 5,
            "elements": [
                "advancedrocketry:blastbrick@0"
            ]
        },
        {
            "x": -5,
            "y": 1,
            "z": 14,
            "elements": [
                "chisel:technical@4"
            ]
        },
        {
            "x": 0,
            "y": 4,
            "z": 4,
            "elements": [
                "chisel:technical1@3"
            ]
        },
        {
            "x": -8,
            "y": 0,
            "z": 7,
            "elements": [
                "modularmachinery:blockcasing@2"
            ]
        },
        {
            "x": -6,
            "y": 0,
            "z": 11,
            "elements": [
                "mekanism:basicblock2@5"
            ]
        },
        {
            "x": 8,
            "y": 4,
            "z": 1,
            "elements": [
                "chisel:technicalnew@4"
            ]
        },
        {
            "x": 1,
            "y": 0,
            "z": 13,
            "elements": [
                "advancedrocketry:blastbrick@0"
            ]
        },
        {
            "x": 4,
            "y": 4,
            "z": 9,
            "elements": [
                "chisel:technical@8"
            ]
        },
        {
            "x": -8,
            "y": 0,
            "z": 14,
            "elements": [
                "modularmachinery:blockcasing@0"
            ]
        },
        {
            "x": 6,
            "y": 4,
            "z": 11,
            "elements": [
                "chisel:technical1@3"
            ]
        },
        {
            "x": -4,
            "y": 0,
            "z": 4,
            "elements": [
                "mekanism:basicblock2@5"
            ]
        },
        {
            "x": 3,
            "y": -1,
            "z": 3,
            "elements": [
                "modularmachinery:blockcasing@0"
            ]
        },
        {
            "x": 6,
            "y": -1,
            "z": 12,
            "elements": [
                "advancedrocketry:blastbrick@0"
            ]
        },
        {
            "x": -8,
            "y": 1,
            "z": 0,
            "elements": [
                "modularmachinery:blockcasing@4"
            ]
        },
        {
            "x": 4,
            "y": -1,
            "z": 2,
            "elements": [
                "modularmachinery:blockcasing@0"
            ]
        },
        {
            "x": -3,
            "y": 0,
            "z": 9,
            "elements": [
                "advancedrocketry:blastbrick@0"
            ]
        },
        {
            "x": -5,
            "y": 4,
            "z": 9,
            "elements": [
                "chisel:technical1@3"
            ]
        },
        {
            "x": -1,
            "y": 0,
            "z": 4,
            "elements": [
                "advancedrocketry:blastbrick@0"
            ]
        },
        {
            "x": -8,
            "y": -1,
            "z": 0,
            "elements": [
                "chisel:blocksteel@4"
            ]
        },
        {
            "x": -7,
            "y": 4,
            "z": 4,
            "elements": [
                "chisel:technical1@3"
            ]
        },
        {
            "x": 5,
            "y": -1,
            "z": 5,
            "elements": [
                "modularmachinery:blockcasing@0"
            ]
        },
        {
            "x": 2,
            "y": 0,
            "z": 2,
            "elements": [
                "advancedrocketry:blastbrick@0"
            ]
        },
        {
            "x": 3,
            "y": -1,
            "z": 10,
            "elements": [
                "modularmachinery:blockcasing@0"
            ]
        },
        {
            "x": 7,
            "y": 4,
            "z": 7,
            "elements": [
                "chisel:technical1@3"
            ]
        },
        {
            "x": 7,
            "y": 3,
            "z": 14,
            "elements": [
                "immersiveengineering:metal_decoration0@7"
            ]
        },
        {
            "x": 0,
            "y": -1,
            "z": 3,
            "elements": [
                "advancedrocketry:blastbrick@0"
            ]
        },
        {
            "x": 8,
            "y": 4,
            "z": 2,
            "elements": [
                "chisel:technical@1"
            ]
        },
        {
            "x": -4,
            "y": 0,
            "z": 9,
            "elements": [
                "mekanism:basicblock2@5"
            ]
        },
        {
            "x": -2,
            "y": 4,
            "z": 4,
            "elements": [
                "chisel:technical1@4"
            ]
        },
        {
            "x": -6,
            "y": 4,
            "z": 9,
            "elements": [
                "chisel:technical1@3"
            ]
        },
        {
            "x": 7,
            "y": 4,
            "z": 14,
            "elements": [
                "chisel:technical@1"
            ]
        },
        {
            "x": -8,
            "y": -3,
            "z": 0,
            "elements": [
                "chisel:blocksteel@4"
            ]
        },
        {
            "x": -7,
            "y": 4,
            "z": 2,
            "elements": [
                "chisel:technical1@3"
            ]
        },
        {
            "x": 4,
            "y": -1,
            "z": 5,
            "elements": [
                "advancedrocketry:blastbrick@0"
            ]
        },
        {
            "x": 7,
            "y": 3,
            "z": 0,
            "elements": [
                "chisel:technical@4"
            ]
        },
        {
            "x": 7,
            "y": 1,
            "z": 14,
            "elements": [
                "immersiveengineering:metal_decoration0@7"
            ]
        },
        {
            "x": -5,
            "y": 0,
            "z": 9,
            "elements": [
                "advancedrocketry:blastbrick@0"
            ]
        },
        {
            "x": 4,
            "y": 3,
            "z": 14,
            "elements": [
                "chisel:technicalnew@4"
            ]
        },
        {
            "x": 4,
            "y": 4,
            "z": 7,
            "elements": [
                "chisel:technical@8"
            ]
        },
        {
            "x": 8,
            "y": 1,
            "z": 2,
            "elements": [
                "chisel:glass@6"
            ]
        },
        {
            "x": -8,
            "y": 3,
            "z": 3,
            "elements": [
                "chisel:glass@6"
            ]
        },
        {
            "x": 2,
            "y": 4,
            "z": 2,
            "elements": [
                "chisel:technical1@4"
            ]
        },
        {
            "x": -8,
            "y": 2,
            "z": 9,
            "elements": [
                "chisel:glass@6"
            ]
        },
        {
            "x": 5,
            "y": 4,
            "z": 2,
            "elements": [
                "chisel:technical1@3"
            ]
        },
        {
            "x": -7,
            "y": -1,
            "z": 3,
            "elements": [
                "modularmachinery:blockcasing@0"
            ]
        },
        {
            "x": 6,
            "y": -1,
            "z": 10,
            "elements": [
                "advancedrocketry:blastbrick@0"
            ]
        },
        {
            "x": 7,
            "y": 0,
            "z": 14,
            "elements": [
                "modularmachinery:blockcasing@0"
            ]
        },
        {
            "x": 6,
            "y": 0,
            "z": 11,
            "elements": [
                "mekanism:basicblock2@5"
            ]
        },
        {
            "x": -3,
            "y": 4,
            "z": 9,
            "elements": [
                "chisel:technical1@4"
            ]
        },
        {
            "x": -5,
            "y": 4,
            "z": 4,
            "elements": [
                "chisel:technical1@3"
            ]
        },
        {
            "x": 7,
            "y": 2,
            "z": 14,
            "elements": [
                "immersiveengineering:metal_decoration0@7"
            ]
        },
        {
            "x": 4,
            "y": 4,
            "z": 14,
            "elements": [
                "chisel:technical@1"
            ]
        },
        {
            "x": 8,
            "y": 0,
            "z": 2,
            "elements": [
                "modularmachinery:blockcasing@2"
            ]
        },
        {
            "x": 8,
            "y": 3,
            "z": 2,
            "elements": [
                "chisel:glass@6"
            ]
        },
        {
            "x": 7,
            "y": -1,
            "z": 5,
            "elements": [
                "modularmachinery:blockcasing@0"
            ]
        },
        {
            "x": 3,
            "y": 4,
            "z": 11,
            "elements": [
                "chisel:technical1@4"
            ]
