{
    "registryname": "oil_pyrolyse_oven_mk1",
    "localizedname": "基础热解炉",
    "requires-blueprint": false,
    "parts": [
        {
            "x": 0,
            "y": 0,
            "z": 0,
            "elements": [
                "modularmachinery:blockcontroller@2"
            ]
        },
        {
            "x": -1,
            "y": 0,
            "z": 1,
            "elements": [
                "nuclearcraft:turbine_dynamo_coil@4"
            ]
        },
        {
            "x": 2,
            "y": 0,
            "z": 0,
            "elements": [
                "mekanism:plasticblock@15"
            ]
        },
        {
            "x": -2,
            "y": 0,
            "z": 2,
            "elements": [
                "mekanism:plasticblock@15"
            ]
        },
        {
            "x": 2,
            "y": 1,
            "z": 2,
            "elements": [
        "modularmachinery:blockcasing",
        "modularmachinery:blockinputbus",
        "modularmachinery:blockmeiteminputbus",
        "modularmachinery:blockmeitemoutputbus",
        "modularmachinery:blockenergyinputhatch",
        "modularmachinery:blockfluidinputhatch",
        "modularmachinery:blockfluidoutputhatch",
        "modularmachinery:blockmefluidinputbus",
        "modularmachinery:blockmefluidoutputbus",
        "modularmachinery:blockoutputbus",
        "mekanism:plasticblock@15"
            ]
        },
        {
            "x": 0,
            "y": 1,
            "z": 2,
            "elements": [
        "modularmachinery:blockcasing",
        "modularmachinery:blockinputbus",
        "modularmachinery:blockmeiteminputbus",
        "modularmachinery:blockmeitemoutputbus",
        "modularmachinery:blockenergyinputhatch",
        "modularmachinery:blockfluidinputhatch",
        "modularmachinery:blockfluidoutputhatch",
        "modularmachinery:blockmefluidinputbus",
        "modularmachinery:blockmefluidoutputbus",
        "modularmachinery:blockoutputbus",
        "mekanism:plasticblock@15"
            ]
        },
        {
            "x": -2,
            "y": 1,
            "z": 2,
            "elements": [
        "modularmachinery:blockcasing",
        "modularmachinery:blockinputbus",
        "modularmachinery:blockmeiteminputbus",
        "modularmachinery:blockmeitemoutputbus",
        "modularmachinery:blockenergyinputhatch",
        "modularmachinery:blockfluidinputhatch",
        "modularmachinery:blockfluidoutputhatch",
        "modularmachinery:blockmefluidinputbus",
        "modularmachinery:blockmefluidoutputbus",
        "modularmachinery:blockoutputbus",
        "mekanism:plasticblock@15"
            ]
        },
        {
            "x": 2,
            "y": -1,
            "z": 2,
            "elements": [
        "modularmachinery:blockcasing",
        "modularmachinery:blockinputbus",
        "modularmachinery:blockmeiteminputbus",
        "modularmachinery:blockmeitemoutputbus",
        "modularmachinery:blockenergyinputhatch",
        "modularmachinery:blockfluidinputhatch",
        "modularmachinery:blockfluidoutputhatch",
        "modularmachinery:blockmefluidinputbus",
        "modularmachinery:blockmefluidoutputbus",
        "modularmachinery:blockoutputbus",
        "mekanism:plasticblock@15"
            ]
        },
        {
            "x": 0,
            "y": -1,
            "z": 2,
            "elements": [
        "modularmachinery:blockcasing",
        "modularmachinery:blockinputbus",
        "modularmachinery:blockmeiteminputbus",
        "modularmachinery:blockmeitemoutputbus",
        "modularmachinery:blockenergyinputhatch",
        "modularmachinery:blockfluidinputhatch",
        "modularmachinery:blockfluidoutputhatch",
        "modularmachinery:blockmefluidinputbus",
        "modularmachinery:blockmefluidoutputbus",
        "modularmachinery:blockoutputbus",
        "mekanism:plasticblock@15"
            ]
        },
        {
            "x": -2,
            "y": -1,
            "z": 2,
            "elements": [
        "modularmachinery:blockcasing",
        "modularmachinery:blockinputbus",
        "modularmachinery:blockmeiteminputbus",
        "modularmachinery:blockmeitemoutputbus",
        "modularmachinery:blockenergyinputhatch",
        "modularmachinery:blockfluidinputhatch",
        "modularmachinery:blockfluidoutputhatch",
        "modularmachinery:blockmefluidinputbus",
        "modularmachinery:blockmefluidoutputbus",
        "modularmachinery:blockoutputbus",
        "mekanism:plasticblock@15"
            ]
        },
        {
            "x": -2,
            "y": -1,
            "z": 0,
            "elements": [
        "modularmachinery:blockcasing",
        "modularmachinery:blockinputbus",
        "modularmachinery:blockmeiteminputbus",
        "modularmachinery:blockmeitemoutputbus",
        "modularmachinery:blockenergyinputhatch",
        "modularmachinery:blockfluidinputhatch",
        "modularmachinery:blockfluidoutputhatch",
        "modularmachinery:blockmefluidinputbus",
        "modularmachinery:blockmefluidoutputbus",
        "modularmachinery:blockoutputbus",
        "mekanism:plasticblock@15"
            ]
        },
        {
            "x": 0,
            "y": -1,
            "z": 0,
            "elements": [
        "modularmachinery:blockcasing",
        "modularmachinery:blockinputbus",
        "modularmachinery:blockmeiteminputbus",
        "modularmachinery:blockmeitemoutputbus",
        "modularmachinery:blockenergyinputhatch",
        "modularmachinery:blockfluidinputhatch",
        "modularmachinery:blockfluidoutputhatch",
        "modularmachinery:blockmefluidinputbus",
        "modularmachinery:blockmefluidoutputbus",
        "modularmachinery:blockoutputbus",
        "mekanism:plasticblock@15"
            ]
        },
        {
            "x": 1,
            "y": 0,
            "z": 1,
            "elements": [
                "nuclearcraft:turbine_dynamo_coil@4"
            ]
        },
        {
            "x": -1,
            "y": 1,
            "z": 0,
            "elements": [
                "nuclearcraft:turbine_dynamo_coil@4"
            ]
        },
        {
            "x": 1,
            "y": -1,
            "z": 1,
            "elements": [
                "nuclearcraft:turbine_dynamo_coil@4"
            ]
        },
        {
            "x": 1,
            "y": 1,
            "z": 0,
            "elements": [
                "nuclearcraft:turbine_dynamo_coil@4"
            ]
        },
        {
            "x": -1,
            "y": -1,
            "z": 1,
            "elements": [
                "nuclearcraft:turbine_dynamo_coil@4"
            ]
        },
        {
            "x": 1,
            "y": 1,
            "z": 1,
            "elements": [
                "nuclearcraft:turbine_dynamo_coil@4"
            ]
        },
        {
            "x": 2,
            "y": 0,
            "z": 2,
            "elements": [
                "mekanism:plasticblock@15"
            ]
        },
        {
            "x": -1,
            "y": 1,
            "z": 1,
            "elements": [
                "nuclearcraft:turbine_dynamo_coil@4"
            ]
        },
        {
            "x": 0,
            "y": 0,
            "z": 2,
            "elements": [
                "mekanism:plasticblock@15"
            ]
        },
        {
            "x": -1,
            "y": 0,
            "z": 0,
            "elements": [
                "nuclearcraft:turbine_dynamo_coil@4"
            ]
        },
        {
            "x": -2,
            "y": 0,
            "z": 1,
            "elements": [
                "mekanism:plasticblock@15"
            ]
        },
        {
            "x": 1,
            "y": 0,
            "z": 0,
            "elements": [
                "nuclearcraft:turbine_dynamo_coil@4"
            ]
        },
        {
            "x": 1,
            "y": 1,
            "z": 2,
            "elements": [
                "nuclearcraft:turbine_dynamo_coil@4"
            ]
        },
        {
            "x": -1,
            "y": 1,
            "z": 2,
            "elements": [
                "nuclearcraft:turbine_dynamo_coil@4"
            ]
        },
        {
            "x": 1,
            "y": -1,
            "z": 2,
            "elements": [
                "nuclearcraft:turbine_dynamo_coil@4"
            ]
        },
        {
            "x": -1,
            "y": -1,
            "z": 2,
            "elements": [
                "nuclearcraft:turbine_dynamo_coil@4"
            ]
        },
        {
            "x": -1,
            "y": -1,
            "z": 0,
            "elements": [
                "nuclearcraft:turbine_dynamo_coil@4"
            ]
        },
        {
            "x": 1,
            "y": -1,
            "z": 0,
            "elements": [
                "nuclearcraft:turbine_dynamo_coil@4"
            ]
        },
        {
            "x": 2,
            "y": 0,
            "z": 1,
            "elements": [
                "mekanism:plasticblock@15"
            ]
        },
        {
            "x": 2,
            "y": -1,
            "z": 0,
            "elements": [
        "modularmachinery:blockcasing",
        "modularmachinery:blockinputbus",
        "modularmachinery:blockmeiteminputbus",
        "modularmachinery:blockmeitemoutputbus",
        "modularmachinery:blockenergyinputhatch",
        "modularmachinery:blockfluidinputhatch",
        "modularmachinery:blockfluidoutputhatch",
        "modularmachinery:blockmefluidinputbus",
        "modularmachinery:blockmefluidoutputbus",
        "modularmachinery:blockoutputbus",
        "mekanism:plasticblock@15"
            ]
        },
        {
            "x": 0,
            "y": 0,
            "z": 1,
            "elements": [
                "mekanism:plasticblock@15"
            ]
        },
        {
            "x": -2,
            "y": 1,
            "z": 0,
            "elements": [
        "modularmachinery:blockcasing",
        "modularmachinery:blockinputbus",
        "modularmachinery:blockmeiteminputbus",
        "modularmachinery:blockmeitemoutputbus",
        "modularmachinery:blockenergyinputhatch",
        "modularmachinery:blockfluidinputhatch",
        "modularmachinery:blockfluidoutputhatch",
        "modularmachinery:blockmefluidinputbus",
        "modularmachinery:blockmefluidoutputbus",
        "modularmachinery:blockoutputbus",
        "mekanism:plasticblock@15"
            ]
        },
        {
            "x": 0,
            "y": -1,
            "z": 1,
            "elements": [
                "mekanism:plasticblock@15"
            ]
        },
        {
            "x": 0,
            "y": 1,
            "z": 0,
            "elements": [
        "modularmachinery:blockcasing",
        "modularmachinery:blockinputbus",
        "modularmachinery:blockmeiteminputbus",
        "modularmachinery:blockmeitemoutputbus",
        "modularmachinery:blockenergyinputhatch",
        "modularmachinery:blockfluidinputhatch",
        "modularmachinery:blockfluidoutputhatch",
        "modularmachinery:blockmefluidinputbus",
        "modularmachinery:blockmefluidoutputbus",
        "modularmachinery:blockoutputbus",
        "mekanism:plasticblock@15"
            ]
        },
        {
            "x": -2,
            "y": -1,
            "z": 1,
            "elements": [
                "mekanism:plasticblock@15"
            ]
        },
        {
            "x": 2,
            "y": 1,
            "z": 0,
            "elements": [
        "modularmachinery:blockcasing",
        "modularmachinery:blockinputbus",
        "modularmachinery:blockmeiteminputbus",
        "modularmachinery:blockmeitemoutputbus",
        "modularmachinery:blockenergyinputhatch",
        "modularmachinery:blockfluidinputhatch",
        "modularmachinery:blockfluidoutputhatch",
        "modularmachinery:blockmefluidinputbus",
        "modularmachinery:blockmefluidoutputbus",
        "modularmachinery:blockoutputbus",
        "mekanism:plasticblock@15"
            ]
        },
        {
            "x": 1,
            "y": 0,
            "z": 2,
            "elements": [
                "nuclearcraft:turbine_dynamo_coil@4"
            ]
        },
        {
            "x": -1,
            "y": 0,
            "z": 2,
            "elements": [
                "nuclearcraft:turbine_dynamo_coil@4"
            ]
        },
        {
            "x": 2,
            "y": 1,
            "z": 1,
            "elements": [
                "mekanism:plasticblock@15"
            ]
        },
        {
            "x": 0,
            "y": 1,
            "z": 1,
            "elements": [
                "mekanism:plasticblock@15"
            ]
        },
        {
            "x": -2,
            "y": 0,
            "z": 0,
            "elements": [
                "mekanism:plasticblock@15"
            ]
        },
        {
            "x": 2,
            "y": -1,
            "z": 1,
            "elements": [
                "mekanism:plasticblock@15"
            ]
        },
        {
            "x": -2,
            "y": 1,
            "z": 1,
            "elements": [
                "mekanism:plasticblock@15"
            ]
        }
    ]}