{
    "registryname": "light_dreameater",
    "localizedname": "§a光§b之§c蚀§d梦§e者",
    "requires-blueprint": false,
    "parts": [
        {
            "x": 0,
            "y": 0,
            "z": 0,
            "elements": [
                "modularmachinery:blockcontroller@2"
            ]
        },
        {
            "x": -1,
            "y": 2,
            "z": 0,
            "elements": [
                "mekanism:plasticblock@15"
            ]
        },
        {
            "x": 0,
            "y": -2,
            "z": 0,
            "elements": [
                "mekanism:plasticblock@15"
            ]
        },
        {
            "x": -2,
            "y": -6,
            "z": 10,
            "elements": [
                "enderio:block_enlightened_fused_quartz@0"
            ]
        },
        {
            "x": -9,
            "y": 0,
            "z": 20,
            "elements": [
                "rpsideas:dark_plate@0"
            ]
        },
        {
            "x": -4,
            "y": -2,
            "z": 10,
            "elements": [
                "enderio:block_enlightened_fused_quartz@0"
            ]
        },
        {
            "x": -7,
            "y": -1,
            "z": 11,
            "elements": [
                "nuclearcraft:turbine_dynamo_coil@4"
            ]
        },
        {
            "x": -6,
            "y": 0,
            "z": 10,
            "elements": [
                "nuclearcraft:turbine_dynamo_coil@4"
            ]
        },
        {
            "x": -1,
            "y": 0,
            "z": 19,
            "elements": [
                "nuclearcraft:turbine_dynamo_coil@4"
            ]
        },
        {
            "x": -8,
            "y": 9,
            "z": 11,
            "elements": [
                "rpsideas:dark_plate@0"
            ]
        },
        {
            "x": -5,
            "y": 2,
            "z": 10,
            "elements": [
                "enderio:block_enlightened_fused_quartz@0"
            ]
        },
        {
            "x": -2,
            "y": 5,
            "z": 11,
            "elements": [
                "enderio:block_enlightened_fused_quartz@0"
            ]
        },
        {
            "x": 5,
            "y": -9,
            "z": 11,
            "elements": [
                "rpsideas:dark_plate@0"
            ]
        },
        {
            "x": -2,
            "y": -8,
            "z": 10,
            "elements": [
                "enderio:block_enlightened_fused_quartz@0"
            ]
        },
        {
            "x": 1,
            "y": -10,
            "z": 10,
            "elements": [
                "mekanism:plasticblock@15"
            ]
        },
        {
            "x": 0,
            "y": 9,
            "z": 4,
            "elements": [
                "rpsideas:dark_plate@0"
            ]
        },
        {
            "x": -10,
            "y": -3,
            "z": 11,
            "elements": [
                "mekanism:plasticblock@15"
            ]
        },
        {
            "x": 1,
            "y": 0,
            "z": 0,
            "selector-tag": "left",
            "elements": [
                "item_in"
            ]
        },
        {
            "x": 1,
            "y": -2,
            "z": 0,
            "elements": [
                "mekanism:plasticblock@15"
            ]
        },
        {
            "x": -5,
            "y": -2,
            "z": 10,
            "elements": [
                "enderio:block_enlightened_fused_quartz@0"
            ]
        },
        {
            "x": -10,
            "y": 3,
            "z": 12,
            "elements": [
                "mekanism:plasticblock@15"
            ]
        },
        {
            "x": -2,
            "y": 7,
            "z": 11,
            "elements": [
                "enderio:block_enlightened_fused_quartz@0"
            ]
        },
        {
            "x": 9,
            "y": 0,
            "z": 7,
            "elements": [
                "rpsideas:dark_plate@0"
            ]
        },
        {
            "x": -8,
            "y": -2,
            "z": 12,
            "elements": [
                "enderio:block_enlightened_fused_quartz@0"
            ]
        },
        {
            "x": -2,
            "y": 0,
            "z": 5,
            "elements": [
                "enderio:block_enlightened_fused_quartz@0"
            ]
        },
        {
            "x": 1,
            "y": -9,
            "z": 12,
            "elements": [
                "nuclearcraft:turbine_dynamo_coil@4"
            ]
        },
        {
            "x": -10,
            "y": 0,
            "z": 12,
            "elements": [
                "mekanism:plasticblock@15"
            ]
        },
        {
            "x": -5,
            "y": 9,
            "z": 11,
            "elements": [
                "rpsideas:dark_plate@0"
            ]
        },
        {
            "x": -10,
            "y": -1,
            "z": 11,
            "elements": [
                "mekanism:plasticblock@15"
            ]
        },
        {
            "x": 1,
            "y": 5,
            "z": 9,
            "elements": [
                "enderio:block_enlightened_fused_quartz@0"
            ]
        },
        {
            "x": -6,
            "y": 2,
            "z": 10,
            "elements": [
                "enderio:block_enlightened_fused_quartz@0"
            ]
        },
        {
            "x": -10,
            "y": 2,
            "z": 12,
            "elements": [
                "mekanism:plasticblock@15"
            ]
        },
        {
            "x": 2,
            "y": -9,
            "z": 11,
            "elements": [
                "chisel:factory1@4"
            ]
        },
        {
            "x": 0,
            "y": -10,
            "z": 10,
            "elements": [
                "mekanism:plasticblock@15"
            ]
        },
        {
            "x": -1,
            "y": -8,
            "z": 10,
            "elements": [
                "nuclearcraft:turbine_dynamo_coil@4"
            ]
        },
        {
            "x": -10,
            "y": 1,
            "z": 12,
            "elements": [
                "mekanism:plasticblock@15"
            ]
        },
        {
            "x": -1,
            "y": -7,
            "z": 11,
            "elements": [
                "nuclearcraft:turbine_dynamo_coil@4"
            ]
        },
        {
            "x": 3,
            "y": -1,
            "z": 9,
            "elements": [
                "enderio:block_enlightened_fused_quartz@0"
            ]
        },
        {
            "x": -8,
            "y": -1,
            "z": 12,
            "elements": [
                "nuclearcraft:turbine_dynamo_coil@4"
            ]
        },
        {
            "x": 0,
            "y": 3,
            "z": 14,
            "elements": [
                "chisel:laboratory@6"
            ]
        },
        {
            "x": 1,
            "y": -8,
            "z": 12,
            "elements": [
                "nuclearcraft:turbine_dynamo_coil@4"
            ]
        },
        {
            "x": 2,
            "y": 0,
            "z": 0,
            "elements": [
                "mekanism:plasticblock@15"
            ]
        },
        {
            "x": 2,
            "y": 1,
            "z": 17,
            "elements": [
                "enderio:block_enlightened_fused_quartz@0"
            ]
        },
        {
            "x": 1,
            "y": -10,
            "z": 12,
            "elements": [
                "mekanism:plasticblock@15"
            ]
        },
        {
            "x": 0,
            "y": -3,
            "z": 11,
            "elements": [
                "nuclearcraft:turbine_dynamo_coil@4"
            ]
        },
        {
            "x": 1,
            "y": 2,
            "z": 0,
            "elements": [
                "mekanism:plasticblock@15"
            ]
        },
        {
            "x": -1,
            "y": -2,
            "z": 5,
            "elements": [
                "enderio:block_enlightened_fused_quartz@0"
            ]
        },
        {
            "x": -2,
            "y": -2,
            "z": 10,
            "elements": [
                "enderio:block_enlightened_fused_quartz@0"
            ]
        },
        {
            "x": -9,
            "y": 1,
            "z": 11,
            "elements": [
                "nuclearcraft:turbine_dynamo_coil@4"
            ]
        },
        {
            "x": 9,
            "y": 0,
            "z": 3,
            "elements": [
                "rpsideas:dark_plate@0"
            ]
        },
        {
            "x": -7,
            "y": 2,
            "z": 10,
            "elements": [
                "enderio:block_enlightened_fused_quartz@0"
            ]
        },
        {
            "x": -5,
            "y": -9,
            "z": 11,
            "elements": [
                "rpsideas:dark_plate@0"
            ]
        },
        {
            "x": 2,
            "y": 0,
            "z": 17,
            "elements": [
                "enderio:block_enlightened_fused_quartz@0"
            ]
        },
        {
            "x": -1,
            "y": -10,
            "z": 10,
            "elements": [
                "mekanism:plasticblock@15"
            ]
        },
        {
            "x": -9,
            "y": 3,
            "z": 11,
            "elements": [
                "rpsideas:dark_plate@0"
            ]
        },
        {
            "x": -3,
            "y": 3,
            "z": 11,
            "elements": [
                "chisel:laboratory@6"
            ]
        },
        {
            "x": 2,
            "y": -7,
            "z": 11,
            "elements": [
                "enderio:block_enlightened_fused_quartz@0"
            ]
        },
        {
            "x": -1,
            "y": 0,
            "z": 0,
            "selector-tag": "right",
            "elements": [
                "item_in"
            ]
        },
        {
            "x": 2,
            "y": -5,
            "z": 11,
            "elements": [
                "enderio:block_enlightened_fused_quartz@0"
            ]
        },
        {
            "x": -2,
            "y": -10,
            "z": 12,
            "elements": [
                "mekanism:plasticblock@15"
            ]
        },
        {
            "x": -7,
            "y": 0,
            "z": 10,
            "elements": [
                "nuclearcraft:turbine_dynamo_coil@4"
            ]
        },
        {
            "x": 1,
            "y": -2,
            "z": 17,
            "elements": [
                "enderio:block_enlightened_fused_quartz@0"
            ]
        },
        {
            "x": 0,
            "y": 2,
            "z": 5,
            "elements": [
                "enderio:block_enlightened_fused_quartz@0"
            ]
        },
        {
            "x": -7,
            "y": -2,
            "z": 10,
            "elements": [
                "enderio:block_enlightened_fused_quartz@0"
            ]
        },
        {
            "x": -2,
            "y": -4,
            "z": 10,
            "elements": [
                "enderio:block_enlightened_fused_quartz@0"
            ]
        },
        {
            "x": -4,
            "y": -9,
            "z": 11,
            "elements": [
                "rpsideas:dark_plate@0"
            ]
        },
        {
            "x": -4,
            "y": 2,
            "z": 10,
            "elements": [
                "enderio:block_enlightened_fused_quartz@0"
            ]
        },
        {
            "x": -2,
            "y": 3,
            "z": 11,
            "elements": [
                "enderio:block_enlightened_fused_quartz@0"
            ]
        },
        {
            "x": 2,
            "y": -10,
            "z": 10,
            "elements": [
                "mekanism:plasticblock@15"
            ]
        },
        {
            "x": 2,
            "y": -6,
            "z": 10,
            "elements": [
                "enderio:block_enlightened_fused_quartz@0"
            ]
        },
        {
            "x": 1,
            "y": -2,
            "z": 5,
            "elements": [
                "enderio:block_enlightened_fused_quartz@0"
            ]
        },
        {
            "x": 1,
            "y": -8,
            "z": 10,
            "elements": [
                "nuclearcraft:turbine_dynamo_coil@4"
            ]
        },
        {
            "x": 2,
            "y": -1,
            "z": 4,
            "elements": [
                "enderio:block_enlightened_fused_quartz@0"
            ]
        },
        {
            "x": 0,
            "y": 9,
            "z": 7,
            "elements": [
                "rpsideas:dark_plate@0"
            ]
        },
        {
            "x": -8,
            "y": -2,
            "z": 10,
            "elements": [
                "enderio:block_enlightened_fused_quartz@0"
            ]
        },
        {
            "x": -5,
            "y": 0,
            "z": 20,
            "elements": [
                "rpsideas:dark_plate@3"
            ]
        },
        {
            "x": -10,
            "y": 0,
            "z": 10,
            "elements": [
                "mekanism:plasticblock@15"
            ]
        },
        {
            "x": 0,
            "y": 1,
            "z": 4,
            "elements": [
                "nuclearcraft:turbine_dynamo_coil@4"
            ]
        },
        {
            "x": 0,
            "y": -6,
            "z": 20,
            "elements": [
                "rpsideas:dark_plate@0"
            ]
        },
        {
            "x": 1,
            "y": -9,
            "z": 11,
            "elements": [
                "nuclearcraft:turbine_dynamo_coil@4"
            ]
        },
        {
            "x": -9,
            "y": 2,
            "z": 10,
            "elements": [
                "chisel:factory1@4"
            ]
        },
        {
            "x": 2,
            "y": 1,
            "z": 19,
            "elements": [
                "enderio:block_enlightened_fused_quartz@0"
            ]
        },
        {
            "x": -2,
            "y": 1,
            "z": 9,
            "elements": [
                "enderio:block_enlightened_fused_quartz@0"
            ]
        },
        {
            "x": 1,
            "y": 9,
            "z": 9,
            "elements": [
                "chisel:factory1@4"
            ]
        },
        {
            "x": -3,
            "y": -3,
            "z": 11,
            "elements": [
                "chisel:laboratory@6"
            ]
        },
        {
            "x": 7,
            "y": 1,
            "z": 9,
            "elements": [
                "enderio:block_enlightened_fused_quartz@0"
            ]
        },
        {
            "x": 0,
            "y": -5,
            "z": 11,
            "elements": [
                "nuclearcraft:turbine_dynamo_coil@4"
            ]
        },
        {
            "x": -8,
            "y": 1,
            "z": 11,
            "elements": [
                "nuclearcraft:turbine_dynamo_coil@4"
            ]
        },
        {
            "x": -2,
            "y": 3,
            "z": 9,
            "elements": [
                "chisel:laboratory@6"
            ]
        },
        {
            "x": 2,
            "y": -8,
            "z": 10,
            "elements": [
                "enderio:block_enlightened_fused_quartz@0"
            ]
        },
        {
            "x": -9,
            "y": 0,
            "z": 10,
            "elements": [
                "nuclearcraft:turbine_dynamo_coil@4"
            ]
        },
        {
            "x": -8,
            "y": 0,
            "z": 20,
            "elements": [
                "rpsideas:dark_plate@0"
            ]
        },
        {
            "x": -6,
            "y": -1,
            "z": 11,
            "elements": [
                "nuclearcraft:turbine_dynamo_coil@4"
            ]
        },
        {
            "x": -9,
            "y": 9,
            "z": 11,
            "elements": [
                "rpsideas:dark_plate@0"
            ]
        },
        {
            "x": 2,
            "y": 0,
            "z": 5,
            "elements": [
                "enderio:block_enlightened_fused_quartz@0"
            ]
        },
        {
            "x": -10,
            "y": 2,
            "z": 10,
            "elements": [
                "mekanism:plasticblock@15"
            ]
        },
        {
            "x": -9,
            "y": 0,
            "z": 15,
            "elements": [
                "rpsideas:dark_plate@0"
            ]
        },
        {
            "x": -2,
            "y": -9,
            "z": 11,
            "elements": [
                "chisel:factory1@4"
            ]
        },
        {
            "x": 0,
            "y": -3,
            "z": 9,
            "elements": [
                "enderio:block_enlightened_fused_quartz@0"
            ]
        },
        {
            "x": 2,
            "y": 1,
            "z": 16,
            "elements": [
                "enderio:block_enlightened_fused_quartz@0"
            ]
        },
        {
            "x": 2,
            "y": 3,
            "z": 12,
            "elements": [
                "enderio:block_enlightened_fused_quartz@0"
            ]
        },
        {
            "x": -2,
            "y": -1,
            "z": 16,
            "elements": [
                "enderio:block_enlightened_fused_quartz@0"
            ]
        },
        {
            "x": 0,
            "y": -8,
            "z": 20,
            "elements": [
                "rpsideas:dark_plate@0"
            ]
        },
        {
            "x": 2,
            "y": 2,
            "z": 12,
            "elements": [
                "enderio:block_enlightened_fused_quartz@0"
            ]
        },
        {
            "x": -2,
            "y": 0,
            "z": 0,
            "elements": [
                "mekanism:plasticblock@15"
            ]
        },
        {
            "x": 1,
            "y": 3,
            "z": 9,
            "elements": [
                "enderio:block_enlightened_fused_quartz@0"
            ]
        },
        {
            "x": 4,
            "y": 1,
            "z": 9,
            "elements": [
                "enderio:block_enlightened_fused_quartz@0"
            ]
        },
        {
            "x": -2,
            "y": 0,
            "z": 15,
            "elements": [
                "enderio:block_enlightened_fused_quartz@0"
            ]
        },
        {
            "x": 6,
            "y": -1,
            "z": 9,
            "elements": [
                "enderio:block_enlightened_fused_quartz@0"
            ]
        },
        {
            "x": 0,
            "y": 9,
            "z": 6,
            "elements": [
                "rpsideas:dark_plate@0"
            ]
        },
        {
            "x": -1,
            "y": 0,
            "z": 5,
            "elements": [
                "nuclearcraft:turbine_dynamo_coil@4"
            ]
        },
        {
            "x": -1,
            "y": 2,
            "z": 5,
            "elements": [
                "enderio:block_enlightened_fused_quartz@0"
            ]
        },
        {
            "x": -3,
            "y": 2,
            "z": 10,
            "elements": [
                "enderio:block_enlightened_fused_quartz@0"
            ]
        },
        {
            "x": -9,
            "y": 7,
            "z": 11,
            "elements": [
                "rpsideas:dark_plate@0"
            ]
        },
        {
            "x": -1,
            "y": -9,
            "z": 11,
            "elements": [
                "nuclearcraft:turbine_dynamo_coil@4"
            ]
        },
        {
            "x": 4,
            "y": -2,
            "z": 12,
            "elements": [
                "enderio:block_enlightened_fused_quartz@0"
            ]
        },
        {
            "x": 2,
            "y": -2,
            "z": 10,
            "elements": [
                "enderio:block_enlightened_fused_quartz@0"
            ]
        },
        {
            "x": -2,
            "y": -7,
            "z": 11,
            "elements": [
                "enderio:block_enlightened_fused_quartz@0"
            ]
        },
        {
            "x": -2,
            "y": -1,
            "z": 19,
            "elements": [
                "enderio:block_enlightened_fused_quartz@0"
            ]
        },
        {
            "x": 2,
            "y": -1,
            "z": 7,
            "elements": [
                "enderio:block_enlightened_fused_quartz@0"
            ]
        },
        {
            "x": 9,
            "y": -1,
            "z": 9,
            "elements": [
                "chisel:factory1@4"
            ]
        },
        {
            "x": -6,
            "y": 1,
            "z": 11,
            "elements": [
                "nuclearcraft:turbine_dynamo_coil@4"
            ]
        },
        {
            "x": 0,
            "y": 2,
            "z": 7,
            "elements": [
                "enderio:block_enlightened_fused_quartz@0"
            ]
        },
        {
            "x": 2,
            "y": -4,
            "z": 10,
            "elements": [
                "enderio:block_enlightened_fused_quartz@0"
            ]
        },
        {
            "x": -1,
            "y": 2,
            "z": 19,
            "elements": [
                "enderio:block_enlightened_fused_quartz@0"
            ]
        },
        {
            "x": 2,
            "y": 0,
            "z": 19,
            "elements": [
                "enderio:block_enlightened_fused_quartz@0"
            ]
        },
        {
            "x": 1,
            "y": 7,
            "z": 9,
            "elements": [
                "enderio:block_enlightened_fused_quartz@0"
            ]
        },
        {
            "x": 1,
            "y": -2,
            "z": 19,
            "elements": [
                "enderio:block_enlightened_fused_quartz@0"
            ]
        },
        {
            "x": -2,
            "y": -10,
            "z": 10,
            "elements": [
                "mekanism:plasticblock@15"
            ]
        },
        {
            "x": -9,
            "y": 5,
            "z": 11,
            "elements": [
                "rpsideas:dark_plate@0"
            ]
        },
        {
            "x": -9,
            "y": 0,
            "z": 3,
            "elements": [
                "rpsideas:dark_plate@0"
            ]
        },
        {
            "x": -2,
            "y": -5,
            "z": 11,
            "elements": [
                "enderio:block_enlightened_fused_quartz@0"
            ]
        },
        {
            "x": 1,
            "y": -1,
            "z": 19,
            "elements": [
                "nuclearcraft:turbine_dynamo_coil@4"
            ]
        },
        {
            "x": -1,
            "y": 1,
            "z": 19,
            "elements": [
                "nuclearcraft:turbine_dynamo_coil@4"
            ]
        },
        {
            "x": 1,
            "y": -9,
            "z": 9,
            "elements": [
                "chisel:factory1@4"
            ]
        },
        {
            "x": 5,
            "y": 2,
            "z": 12,
            "elements": [
                "enderio:block_enlightened_fused_quartz@0"
            ]
        },
        {
            "x": 2,
            "y": -1,
            "z": 8,
            "elements": [
                "enderio:block_enlightened_fused_quartz@0"
            ]
        },
        {
            "x": 2,
            "y": 8,
            "z": 12,
            "elements": [
                "enderio:block_enlightened_fused_quartz@0"
            ]
        },
        {
            "x": -1,
            "y": -5,
            "z": 9,
            "elements": [
                "enderio:block_enlightened_fused_quartz@0"
            ]
        },
        {
            "x": -6,
            "y": -9,
            "z": 11,
            "elements": [
                "rpsideas:dark_plate@0"
            ]
        },
        {
            "x": -4,
            "y": -1,
            "z": 9,
            "elements": [
                "enderio:block_enlightened_fused_quartz@0"
            ]
        },
        {
            "x": 0,
            "y": 8,
            "z": 10,
            "elements": [
                "nuclearcraft:turbine_dynamo_coil@4"
            ]
        },
        {
            "x": -3,
            "y": -9,
            "z": 11,
            "elements": [
                "rpsideas:dark_plate@0"
            ]
        },
        {
            "x": 3,
            "y": 0,
            "z": 8,
            "elements": [
                "chisel:laboratory@6"
            ]
        },
        {
            "x": -9,
            "y": -5,
            "z": 11,
            "elements": [
                "rpsideas:dark_plate@0"
            ]
        },
        {
            "x": -3,
            "y": 10,
            "z": 10,
            "elements": [
                "mekanism:plasticblock@15"
            ]
        },
        {
            "x": 2,
            "y": 0,
            "z": 18,
            "elements": [
                "enderio:block_enlightened_fused_quartz@0"
            ]
        },
        {
            "x": 3,
            "y": 2,
            "z": 10,
            "elements": [
                "enderio:block_enlightened_fused_quartz@0"
            ]
        },
        {
            "x": 9,
            "y": 6,
            "z": 11,
            "elements": [
                "rpsideas:dark_plate@0"
            ]
        },
        {
            "x": 0,
            "y": 2,
            "z": 8,
            "elements": [
                "enderio:block_enlightened_fused_quartz@0"
            ]
        },
        {
            "x": -6,
            "y": 1,
            "z": 9,
            "elements": [
                "enderio:block_enlightened_fused_quartz@0"
            ]
        },
        {
            "x": -3,
            "y": 1,
            "z": 8,
            "elements": [
                "chisel:laboratory@6"
            ]
        },
        {
            "x": 3,
            "y": 9,
            "z": 11,
            "elements": [
                "rpsideas:dark_plate@0"
            ]
        },
        {
            "x": 0,
            "y": -9,
            "z": 9,
            "elements": [
                "chisel:factory1@4"
            ]
        },
        {
            "x": -1,
            "y": -7,
            "z": 9,
            "elements": [
                "enderio:block_enlightened_fused_quartz@0"
            ]
        },
        {
            "x": -2,
            "y": -1,
            "z": 18,
            "elements": [
                "enderio:block_enlightened_fused_quartz@0"
            ]
        },
        {
            "x": 2,
            "y": -1,
            "z": 21,
            "elements": [
                "mekanism:plasticblock@15"
            ]
        },
        {
            "x": 0,
            "y": 3,
            "z": 8,
            "elements": [
                "chisel:laboratory@6"
            ]
        },
        {
            "x": 9,
            "y": 0,
            "z": 14,
            "elements": [
                "rpsideas:dark_plate@0"
            ]
        },
        {
            "x": -9,
            "y": -9,
            "z": 11,
            "elements": [
                "rpsideas:dark_plate@0"
            ]
        },
        {
            "x": -1,
            "y": -2,
            "z": 8,
            "elements": [
                "enderio:block_enlightened_fused_quartz@0"
            ]
        },
        {
            "x": -5,
            "y": 1,
            "z": 9,
            "elements": [
                "enderio:block_enlightened_fused_quartz@0"
            ]
        },
        {
            "x": -9,
            "y": -7,
            "z": 11,
            "elements": [
                "rpsideas:dark_plate@0"
            ]
        },
        {
            "x": 2,
            "y": -2,
            "z": 8,
            "elements": [
                "chisel:laboratory@6"
            ]
        },
        {
            "x": 3,
            "y": -2,
            "z": 10,
            "elements": [
                "enderio:block_enlightened_fused_quartz@0"
            ]
        },
        {
            "x": -5,
            "y": -1,
            "z": 9,
            "elements": [
                "enderio:block_enlightened_fused_quartz@0"
            ]
        },
        {
            "x": -1,
            "y": 0,
            "z": 18,
            "elements": [
                "nuclearcraft:turbine_dynamo_coil@4"
            ]
        },
        {
            "x": -2,
            "y": 1,
            "z": 16,
            "elements": [
                "enderio:block_enlightened_fused_quartz@0"
            ]
        },
        {
            "x": 1,
            "y": 0,
            "z": 3,
            "elements": [
                "nuclearcraft:turbine_dynamo_coil@4"
            ]
        },
        {
            "x": -2,
            "y": 10,
            "z": 10,
            "elements": [
                "mekanism:plasticblock@15"
            ]
        },
        {
            "x": 7,
            "y": -2,
            "z": 12,
            "elements": [
                "enderio:block_enlightened_fused_quartz@0"
            ]
        },
        {
            "x": 1,
            "y": -2,
            "z": 18,
            "elements": [
                "enderio:block_enlightened_fused_quartz@0"
            ]
        },
        {
            "x": -1,
            "y": -3,
            "z": 8,
            "elements": [
                "chisel:laboratory@6"
            ]
        },
        {
            "x": 0,
            "y": 6,
            "z": 10,
            "elements": [
                "nuclearcraft:turbine_dynamo_coil@4"
            ]
        },
        {
            "x": 9,
            "y": 4,
            "z": 11,
            "elements": [
                "rpsideas:dark_plate@0"
            ]
        },
        {
            "x": 2,
            "y": 4,
            "z": 12,
            "elements": [
                "enderio:block_enlightened_fused_quartz@0"
            ]
        },
        {
            "x": 5,
            "y": 1,
            "z": 13,
            "elements": [
                "enderio:block_enlightened_fused_quartz@0"
            ]
        },
        {
            "x": 9,
            "y": 0,
            "z": 6,
            "elements": [
                "rpsideas:dark_plate@0"
            ]
        },
        {
            "x": -3,
            "y": 0,
            "z": 20,
            "elements": [
                "rpsideas:dark_plate@0"
            ]
        },
        {
            "x": -2,
            "y": 1,
            "z": 4,
            "elements": [
                "enderio:block_enlightened_fused_quartz@0"
            ]
        },
        {
            "x": 6,
            "y": 0,
            "z": 13,
            "elements": [
                "enderio:block_enlightened_fused_quartz@0"
            ]
        },
        {
            "x": 2,
            "y": 10,
            "z": 12,
            "elements": [
                "mekanism:plasticblock@15"
            ]
        },
        {
            "x": 5,
            "y": -1,
            "z": 13,
            "elements": [
                "enderio:block_enlightened_fused_quartz@0"
            ]
        },
        {
            "x": 0,
            "y": -7,
            "z": 9,
            "elements": [
                "enderio:block_enlightened_fused_quartz@0"
            ]
        },
        {
            "x": 8,
            "y": 1,
            "z": 12,
            "elements": [
                "nuclearcraft:turbine_dynamo_coil@4"
            ]
        },
        {
            "x": -6,
            "y": -1,
            "z": 9,
            "elements": [
                "enderio:block_enlightened_fused_quartz@0"
            ]
        },
        {
            "x": -1,
            "y": -2,
            "z": 20,
            "elements": [
                "chisel:factory1@4"
            ]
        },
        {
            "x": -6,
            "y": 9,
            "z": 11,
            "elements": [
                "rpsideas:dark_plate@0"
            ]
        },
        {
            "x": -9,
            "y": -1,
            "z": 11,
            "elements": [
                "nuclearcraft:turbine_dynamo_coil@4"
            ]
        },
        {
            "x": 0,
            "y": 9,
            "z": 13,
            "elements": [
                "chisel:factory1@4"
            ]
        },
        {
            "x": -8,
            "y": 1,
            "z": 9,
            "elements": [
                "enderio:block_enlightened_fused_quartz@0"
            ]
        },
        {
            "x": 6,
            "y": -2,
            "z": 10,
            "elements": [
                "enderio:block_enlightened_fused_quartz@0"
            ]
        },
        {
            "x": -2,
            "y": 8,
            "z": 10,
            "elements": [
                "enderio:block_enlightened_fused_quartz@0"
            ]
        },
        {
            "x": -1,
            "y": 2,
            "z": 18,
            "elements": [
                "enderio:block_enlightened_fused_quartz@0"
            ]
        },
        {
            "x": 2,
            "y": 5,
            "z": 12,
            "elements": [
                "enderio:block_enlightened_fused_quartz@0"
            ]
        },
        {
            "x": 3,
            "y": -9,
            "z": 11,
            "elements": [
                "rpsideas:dark_plate@0"
            ]
        },
        {
            "x": 6,
            "y": 1,
            "z": 11,
            "elements": [
                "nuclearcraft:turbine_dynamo_coil@4"
            ]
        },
        {
            "x": 0,
            "y": -9,
            "z": 16,
            "elements": [
                "rpsideas:dark_plate@0"
            ]
        },
        {
            "x": 0,
            "y": 10,
            "z": 13,
            "elements": [
                "mekanism:plasticblock@15"
            ]
        },
        {
            "x": 9,
            "y": 0,
            "z": 8,
            "elements": [
                "rpsideas:dark_plate@0"
            ]
        },
        {
            "x": 8,
            "y": 0,
            "z": 12,
            "elements": [
                "nuclearcraft:turbine_dynamo_coil@4"
            ]
        },
        {
            "x": 8,
            "y": 2,
            "z": 12,
            "elements": [
                "enderio:block_enlightened_fused_quartz@0"
            ]
        },
        {
            "x": 5,
            "y": 0,
            "z": 13,
            "elements": [
                "enderio:block_enlightened_fused_quartz@0"
            ]
        },
        {
            "x": 2,
            "y": 9,
            "z": 12,
            "elements": [
                "chisel:factory1@4"
            ]
        },
        {
            "x": 0,
            "y": 7,
            "z": 13,
            "elements": [
                "enderio:block_enlightened_fused_quartz@0"
            ]
        },
        {
            "x": 1,
            "y": -2,
            "z": 15,
            "elements": [
                "enderio:block_enlightened_fused_quartz@0"
            ]
        },
        {
            "x": -1,
            "y": 8,
            "z": 12,
            "elements": [
                "nuclearcraft:turbine_dynamo_coil@4"
            ]
        },
        {
            "x": 0,
            "y": 10,
            "z": 10,
            "elements": [
                "mekanism:plasticblock@15"
            ]
        },
        {
            "x": 2,
            "y": 6,
            "z": 12,
            "elements": [
                "enderio:block_enlightened_fused_quartz@0"
            ]
        },
        {
            "x": 1,
            "y": 2,
            "z": 3,
            "elements": [
                "enderio:block_enlightened_fused_quartz@0"
            ]
        },
        {
            "x": -3,
            "y": -1,
            "z": 9,
            "elements": [
                "enderio:block_enlightened_fused_quartz@0"
            ]
        },
        {
            "x": 0,
            "y": -5,
            "z": 9,
            "elements": [
                "enderio:block_enlightened_fused_quartz@0"
            ]
        },
        {
            "x": 0,
            "y": 8,
            "z": 13,
            "elements": [
                "enderio:block_enlightened_fused_quartz@0"
            ]
        },
        {
            "x": 4,
            "y": -1,
            "z": 13,
            "elements": [
                "enderio:block_enlightened_fused_quartz@0"
            ]
        },
        {
            "x": 9,
            "y": 8,
            "z": 11,
            "elements": [
                "rpsideas:dark_plate@0"
            ]
        },
        {
            "x": -1,
            "y": 10,
            "z": 12,
            "elements": [
                "mekanism:plasticblock@15"
            ]
        },
        {
            "x": 0,
            "y": 0,
            "z": 8,
            "elements": [
                "nuclearcraft:turbine_dynamo_coil@4"
            ]
        },
        {
            "x": 6,
            "y": 1,
            "z": 13,
            "elements": [
                "enderio:block_enlightened_fused_quartz@0"
            ]
        },
        {
            "x": -2,
            "y": -1,
            "z": 4,
            "elements": [
                "enderio:block_enlightened_fused_quartz@0"
            ]
        },
        {
            "x": 1,
            "y": 8,
            "z": 10,
            "elements": [
                "nuclearcraft:turbine_dynamo_coil@4"
            ]
        },
        {
            "x": 4,
            "y": 2,
            "z": 10,
            "elements": [
                "enderio:block_enlightened_fused_quartz@0"
            ]
        },
        {
            "x": 2,
            "y": 7,
            "z": 12,
            "elements": [
                "enderio:block_enlightened_fused_quartz@0"
            ]
        },
        {
            "x": -3,
            "y": 1,
            "z": 9,
            "elements": [
                "enderio:block_enlightened_fused_quartz@0"
            ]
        },
        {
            "x": -1,
            "y": 9,
            "z": 12,
            "elements": [
                "nuclearcraft:turbine_dynamo_coil@4"
            ]
        },
        {
            "x": -9,
            "y": -3,
            "z": 11,
            "elements": [
                "rpsideas:dark_plate@0"
            ]
        },
        {
            "x": -1,
            "y": 2,
            "z": 15,
            "elements": [
                "enderio:block_enlightened_fused_quartz@0"
            ]
        },
        {
            "x": -2,
            "y": 6,
            "z": 10,
            "elements": [
                "enderio:block_enlightened_fused_quartz@0"
            ]
        },
        {
            "x": -1,
            "y": 3,
            "z": 9,
            "elements": [
                "enderio:block_enlightened_fused_quartz@0"
            ]
        },
        {
            "x": 8,
            "y": 0,
            "z": 13,
            "elements": [
                "enderio:block_enlightened_fused_quartz@0"
            ]
        },
        {
            "x": 3,
            "y": 0,
            "z": 20,
            "elements": [
                "rpsideas:dark_plate@0"
            ]
        },
        {
            "x": 9,
            "y": 2,
            "z": 12,
            "elements": [
                "chisel:factory1@4"
            ]
        },
        {
            "x": 2,
            "y": -3,
            "z": 11,
            "elements": [
                "enderio:block_enlightened_fused_quartz@0"
            ]
        },
        {
            "x": 10,
            "y": -1,
            "z": 12,
            "elements": [
                "mekanism:plasticblock@15"
            ]
        },
        {
            "x": -1,
            "y": 2,
            "z": 17,
            "elements": [
                "enderio:block_enlightened_fused_quartz@0"
            ]
        },
        {
            "x": -3,
            "y": 1,
            "z": 21,
            "elements": [
                "mekanism:plasticblock@15"
            ]
        },
        {
            "x": 7,
            "y": -1,
            "z": 13,
            "elements": [
                "enderio:block_enlightened_fused_quartz@0"
            ]
        },
        {
            "x": -1,
            "y": -1,
            "z": 21,
            "elements": [
                "mekanism:plasticblock@15"
            ]
        },
        {
            "x": -10,
            "y": 1,
            "z": 9,
            "elements": [
                "mekanism:plasticblock@15"
            ]
        },
        {
            "x": 3,
            "y": 3,
            "z": 11,
            "elements": [
                "chisel:laboratory@6"
            ]
        },
        {
            "x": -8,
            "y": -1,
            "z": 9,
            "elements": [
                "enderio:block_enlightened_fused_quartz@0"
            ]
        },
        {
            "x": -3,
            "y": -10,
            "z": 10,
            "elements": [
                "mekanism:plasticblock@15"
            ]
        },
        {
            "x": 0,
            "y": 9,
            "z": 8,
            "elements": [
                "rpsideas:dark_plate@0"
            ]
        },
        {
            "x": 2,
            "y": 10,
            "z": 13,
            "elements": [
                "mekanism:plasticblock@15"
            ]
        },
        {
            "x": 10,
            "y": -2,
            "z": 12,
            "elements": [
                "mekanism:plasticblock@15"
            ]
        },
        {
            "x": 0,
            "y": 2,
            "z": 20,
            "elements": [
                "chisel:factory1@4"
            ]
        },
        {
            "x": 9,
            "y": -9,
            "z": 11,
            "elements": [
                "rpsideas:dark_plate@0"
            ]
        },
        {
            "x": -9,
            "y": 0,
            "z": 2,
            "elements": [
                "rpsideas:dark_plate@0"
            ]
        },
        {
            "x": -9,
            "y": -2,
            "z": 10,
            "elements": [
                "chisel:factory1@4"
            ]
        },
        {
            "x": -2,
            "y": 4,
            "z": 10,
            "elements": [
                "enderio:block_enlightened_fused_quartz@0"
            ]
        },
        {
            "x": 0,
            "y": -9,
            "z": 4,
            "elements": [
                "rpsideas:dark_plate@0"
            ]
        },
        {
            "x": 10,
            "y": -3,
            "z": 12,
            "elements": [
                "mekanism:plasticblock@15"
            ]
        },
        {
            "x": -1,
            "y": -3,
            "z": 21,
            "elements": [
                "mekanism:plasticblock@15"
            ]
        },
        {
            "x": -9,
            "y": 0,
            "z": 8,
            "elements": [
                "rpsideas:dark_plate@0"
            ]
        },
        {
            "x": 0,
            "y": 2,
            "z": 3,
            "elements": [
                "enderio:block_enlightened_fused_quartz@0"
            ]
        },
        {
            "x": -9,
            "y": -1,
            "z": 9,
            "elements": [
                "chisel:factory1@4"
            ]
        },
        {
            "x": 1,
            "y": -5,
            "z": 9,
            "elements": [
                "enderio:block_enlightened_fused_quartz@0"
            ]
        },
        {
            "x": 0,
            "y": 10,
            "z": 14,
            "elements": [
                "mekanism:plasticblock@15"
            ]
        },
        {
            "x": 0,
            "y": 9,
            "z": 14,
            "elements": [
                "rpsideas:dark_plate@0"
            ]
        },
        {
            "x": 0,
            "y": 8,
            "z": 20,
            "elements": [
                "rpsideas:dark_plate@0"
            ]
        },
        {
            "x": 9,
            "y": 1,
            "z": 12,
            "elements": [
                "nuclearcraft:turbine_dynamo_coil@4"
            ]
        },
        {
            "x": 0,
            "y": 10,
            "z": 8,
            "elements": [
                "mekanism:plasticblock@15"
            ]
        },
        {
            "x": 10,
            "y": -1,
            "z": 13,
            "elements": [
                "mekanism:plasticblock@15"
            ]
        },
        {
            "x": 8,
            "y": 1,
            "z": 13,
            "elements": [
                "enderio:block_enlightened_fused_quartz@0"
            ]
        },
        {
            "x": -10,
            "y": -1,
            "z": 8,
            "elements": [
                "mekanism:plasticblock@15"
            ]
        },
        {
            "x": 2,
            "y": 0,
            "z": 15,
            "elements": [
                "enderio:block_enlightened_fused_quartz@0"
            ]
        },
        {
            "x": 6,
            "y": -9,
            "z": 11,
            "elements": [
                "rpsideas:dark_plate@0"
            ]
        },
        {
            "x": 0,
            "y": 3,
            "z": 11,
            "elements": [
                "nuclearcraft:turbine_dynamo_coil@4"
            ]
        },
        {
            "x": -2,
            "y": 2,
            "z": 10,
            "elements": [
                "enderio:block_enlightened_fused_quartz@0"
            ]
        },
        {
            "x": 9,
            "y": 0,
            "z": 12,
            "elements": [
                "nuclearcraft:turbine_dynamo_coil@4"
            ]
        },
        {
            "x": 10,
            "y": -2,
            "z": 13,
            "elements": [
                "mekanism:plasticblock@15"
            ]
        },
        {
            "x": 0,
            "y": -6,
            "z": 10,
            "elements": [
                "nuclearcraft:turbine_dynamo_coil@4"
            ]
        },
        {
            "x": -9,
            "y": 0,
            "z": 5,
            "elements": [
                "rpsideas:dark_plate@0"
            ]
        },
        {
            "x": 0,
            "y": -1,
            "z": 4,
            "elements": [
                "nuclearcraft:turbine_dynamo_coil@4"
            ]
        },
        {
            "x": -8,
            "y": 0,
            "z": 10,
            "elements": [
                "nuclearcraft:turbine_dynamo_coil@4"
            ]
        },
        {
            "x": 3,
            "y": 0,
            "z": 14,
            "elements": [
                "chisel:laboratory@6"
            ]
        },
        {
            "x": 2,
            "y": 1,
            "z": 4,
            "elements": [
                "enderio:block_enlightened_fused_quartz@0"
            ]
        },
        {
            "x": -6,
            "y": -2,
            "z": 10,
            "elements": [
                "enderio:block_enlightened_fused_quartz@0"
            ]
        },
        {
            "x": 1,
            "y": -3,
            "z": 9,
            "elements": [
                "enderio:block_enlightened_fused_quartz@0"
            ]
        },
        {
            "x": 0,
            "y": 6,
            "z": 20,
            "elements": [
                "rpsideas:dark_plate@0"
            ]
        },
        {
            "x": -1,
            "y": 2,
            "z": 3,
            "elements": [
                "enderio:block_enlightened_fused_quartz@0"
            ]
        },
        {
            "x": 0,
            "y": 5,
            "z": 11,
            "elements": [
                "nuclearcraft:turbine_dynamo_coil@4"
            ]
        },
        {
            "x": 0,
            "y": 3,
            "z": 21,
            "elements": [
                "mekanism:plasticblock@15"
            ]
        },
        {
            "x": 2,
            "y": -1,
            "z": 14,
            "elements": [
                "enderio:block_enlightened_fused_quartz@0"
            ]
        },
        {
            "x": 9,
            "y": 1,
            "z": 13,
            "elements": [
                "chisel:factory1@4"
            ]
        },
        {
            "x": 0,
            "y": -8,
            "z": 10,
            "elements": [
                "nuclearcraft:turbine_dynamo_coil@4"
            ]
        },
        {
            "x": -2,
            "y": 0,
            "z": 3,
            "elements": [
                "enderio:block_enlightened_fused_quartz@0"
            ]
        },
        {
            "x": 3,
            "y": -10,
            "z": 10,
            "elements": [
                "mekanism:plasticblock@15"
            ]
        },
        {
            "x": -4,
            "y": 1,
            "z": 9,
            "elements": [
                "enderio:block_enlightened_fused_quartz@0"
            ]
        },
        {
            "x": -2,
            "y": -1,
            "z": 9,
            "elements": [
                "enderio:block_enlightened_fused_quartz@0"
            ]
        },
        {
            "x": 0,
            "y": -2,
            "z": 3,
            "elements": [
                "enderio:block_enlightened_fused_quartz@0"
            ]
        },
        {
            "x": 2,
            "y": 1,
            "z": 18,
            "elements": [
                "enderio:block_enlightened_fused_quartz@0"
            ]
        },
        {
            "x": 9,
            "y": 0,
            "z": 13,
            "elements": [
                "chisel:factory1@4"
            ]
        },
        {
            "x": 3,
            "y": -3,
            "z": 11,
            "elements": [
                "chisel:laboratory@6"
            ]
        },
        {
            "x": -3,
            "y": -2,
            "z": 10,
            "elements": [
                "enderio:block_enlightened_fused_quartz@0"
            ]
        },
        {
            "x": 1,
            "y": -7,
            "z": 9,
            "elements": [
                "enderio:block_enlightened_fused_quartz@0"
            ]
        },
        {
            "x": -3,
            "y": 9,
            "z": 11,
            "elements": [
                "rpsideas:dark_plate@0"
            ]
        },
        {
            "x": -6,
            "y": 0,
            "z": 20,
            "elements": [
                "rpsideas:dark_plate@3"
            ]
        },
        {
            "x": 3,
            "y": 1,
            "z": 8,
            "elements": [
                "chisel:laboratory@6"
            ]
        },
        {
            "x": 3,
            "y": 10,
            "z": 12,
            "elements": [
                "mekanism:plasticblock@15"
            ]
        },
        {
            "x": -1,
            "y": 0,
            "z": 3,
            "elements": [
                "nuclearcraft:turbine_dynamo_coil@4"
            ]
        },
        {
            "x": -2,
            "y": -3,
            "z": 9,
            "elements": [
                "chisel:laboratory@6"
            ]
        },
        {
            "x": 8,
            "y": -1,
            "z": 13,
            "elements": [
                "enderio:block_enlightened_fused_quartz@0"
            ]
        },
        {
            "x": -8,
            "y": 2,
            "z": 10,
            "elements": [
                "enderio:block_enlightened_fused_quartz@0"
            ]
        },
        {
            "x": 0,
            "y": 1,
            "z": 21,
            "elements": [
                "mekanism:plasticblock@15"
            ]
        },
        {
            "x": -1,
            "y": -2,
            "z": 3,
            "elements": [
                "enderio:block_enlightened_fused_quartz@0"
            ]
        },
        {
            "x": 8,
            "y": -9,
            "z": 11,
            "elements": [
                "rpsideas:dark_plate@0"
            ]
        },
        {
            "x": 3,
            "y": 1,
            "z": 14,
            "elements": [
                "chisel:laboratory@6"
            ]
        },
        {
            "x": 10,
            "y": 2,
            "z": 10,
            "elements": [
                "mekanism:plasticblock@15"
            ]
        },
        {
            "x": -7,
            "y": 1,
            "z": 9,
            "elements": [
                "enderio:block_enlightened_fused_quartz@0"
            ]
        },
        {
            "x": 0,
            "y": 4,
            "z": 20,
            "elements": [
                "rpsideas:dark_plate@0"
            ]
        },
        {
            "x": 1,
            "y": 6,
            "z": 11,
            "elements": [
                "nuclearcraft:turbine_dynamo_coil@4"
            ]
        },
        {
            "x": 0,
            "y": 2,
            "z": 16,
            "elements": [
                "enderio:block_enlightened_fused_quartz@0"
            ]
        },
        {
            "x": -1,
            "y": -1,
            "z": 19,
            "elements": [
                "nuclearcraft:turbine_dynamo_coil@4"
            ]
        },
        {
            "x": 0,
            "y": 8,
            "z": 9,
            "elements": [
                "enderio:block_enlightened_fused_quartz@0"
            ]
        },
        {
            "x": 0,
            "y": 5,
            "z": 2,
            "elements": [
                "rpsideas:dark_plate@0"
            ]
        },
        {
            "x": 2,
            "y": 2,
            "z": 21,
            "elements": [
                "mekanism:plasticblock@15"
            ]
        },
        {
            "x": 7,
            "y": 2,
            "z": 11,
            "elements": [
                "enderio:block_enlightened_fused_quartz@0"
            ]
        },
        {
            "x": -3,
            "y": 3,
            "z": 12,
            "elements": [
                "chisel:laboratory@6"
            ]
        },
        {
            "x": 1,
            "y": 7,
            "z": 11,
            "elements": [
                "nuclearcraft:turbine_dynamo_coil@4"
            ]
        },
        {
            "x": -1,
            "y": -6,
            "z": 13,
            "elements": [
                "enderio:block_enlightened_fused_quartz@0"
            ]
        },
        {
            "x": 4,
            "y": 0,
            "z": 11,
            "elements": [
                "nuclearcraft:turbine_dynamo_coil@4"
            ]
        },
        {
            "x": 0,
            "y": 5,
            "z": 9,
            "elements": [
                "enderio:block_enlightened_fused_quartz@0"
            ]
        },
        {
            "x": 0,
            "y": -9,
            "z": 17,
            "elements": [
                "rpsideas:dark_plate@0"
            ]
        },
        {
            "x": 2,
            "y": -9,
            "z": 12,
            "elements": [
                "chisel:factory1@4"
            ]
        },
        {
            "x": 10,
            "y": 3,
            "z": 10,
            "elements": [
                "mekanism:plasticblock@15"
            ]
        },
        {
            "x": 0,
            "y": 7,
            "z": 9,
            "elements": [
                "enderio:block_enlightened_fused_quartz@0"
            ]
        },
        {
            "x": 9,
            "y": 1,
            "z": 10,
            "elements": [
                "nuclearcraft:turbine_dynamo_coil@4"
            ]
        },
        {
            "x": 0,
            "y": 6,
            "z": 9,
            "elements": [
                "enderio:block_enlightened_fused_quartz@0"
            ]
        },
        {
            "x": 10,
            "y": 0,
            "z": 10,
            "elements": [
                "mekanism:plasticblock@15"
            ]
        },
        {
            "x": -2,
            "y": 1,
            "z": 19,
            "elements": [
                "enderio:block_enlightened_fused_quartz@0"
            ]
        },
        {
            "x": 2,
            "y": 1,
            "z": 14,
            "elements": [
                "enderio:block_enlightened_fused_quartz@0"
            ]
        },
        {
            "x": 0,
            "y": 7,
            "z": 2,
            "elements": [
                "rpsideas:dark_plate@0"
            ]
        },
        {
            "x": -1,
            "y": 3,
            "z": 14,
            "elements": [
                "chisel:laboratory@6"
            ]
        },
        {
            "x": 9,
            "y": -2,
            "z": 11,
            "elements": [
                "chisel:factory1@4"
            ]
        },
        {
            "x": 2,
            "y": -10,
            "z": 13,
            "elements": [
                "mekanism:plasticblock@15"
            ]
        },
        {
            "x": 3,
            "y": 1,
            "z": 9,
            "elements": [
                "enderio:block_enlightened_fused_quartz@0"
            ]
        },
        {
            "x": 9,
            "y": 2,
            "z": 10,
            "elements": [
                "chisel:factory1@4"
            ]
        },
        {
            "x": 2,
            "y": 0,
            "z": 21,
            "elements": [
                "mekanism:plasticblock@15"
            ]
        },
        {
            "x": -1,
            "y": -8,
            "z": 13,
            "elements": [
                "enderio:block_enlightened_fused_quartz@0"
            ]
        },
        {
            "x": 4,
            "y": 2,
            "z": 11,
            "elements": [
                "enderio:block_enlightened_fused_quartz@0"
            ]
        },
        {
            "x": 2,
            "y": -7,
            "z": 12,
            "elements": [
                "enderio:block_enlightened_fused_quartz@0"
            ]
        },
        {
            "x": 9,
            "y": -3,
            "z": 11,
            "elements": [
                "rpsideas:dark_plate@0"
            ]
        },
        {
            "x": 3,
            "y": 2,
            "z": 9,
            "elements": [
                "chisel:laboratory@6"
            ]
        },
        {
            "x": -2,
            "y": 0,
            "z": 8,
            "elements": [
                "enderio:block_enlightened_fused_quartz@0"
            ]
        },
        {
            "x": -9,
            "y": 0,
            "z": 13,
            "elements": [
                "chisel:factory1@4"
            ]
        },
        {
            "x": 10,
            "y": 1,
            "z": 10,
            "elements": [
                "mekanism:plasticblock@15"
            ]
        },
        {
            "x": 2,
            "y": 1,
            "z": 21,
            "elements": [
                "mekanism:plasticblock@15"
            ]
        },
        {
            "x": 9,
            "y": -1,
            "z": 11,
            "elements": [
                "nuclearcraft:turbine_dynamo_coil@4"
            ]
        },
        {
            "x": 2,
            "y": -1,
            "z": 16,
            "elements": [
                "enderio:block_enlightened_fused_quartz@0"
            ]
        },
        {
            "x": 0,
            "y": 2,
            "z": 9,
            "elements": [
                "enderio:block_enlightened_fused_quartz@0"
            ]
        },
        {
            "x": 2,
            "y": -5,
            "z": 12,
            "elements": [
                "enderio:block_enlightened_fused_quartz@0"
            ]
        },
        {
            "x": 7,
            "y": 1,
            "z": 11,
            "elements": [
                "nuclearcraft:turbine_dynamo_coil@4"
            ]
        },
        {
            "x": -9,
            "y": 0,
            "z": 18,
            "elements": [
                "rpsideas:dark_plate@0"
            ]
        },
        {
            "x": 6,
            "y": -2,
            "z": 11,
            "elements": [
                "enderio:block_enlightened_fused_quartz@0"
            ]
        },
        {
            "x": 0,
            "y": -1,
            "z": 19,
            "elements": [
                "nuclearcraft:turbine_dynamo_coil@4"
            ]
        },
        {
            "x": 9,
            "y": -4,
            "z": 11,
            "elements": [
                "rpsideas:dark_plate@0"
            ]
        },
        {
            "x": -1,
            "y": 0,
            "z": 21,
            "elements": [
                "mekanism:plasticblock@15"
            ]
        },
        {
            "x": 0,
            "y": 9,
            "z": 20,
            "elements": [
                "rpsideas:dark_plate@0"
            ]
        },
        {
            "x": 3,
            "y": 10,
            "z": 10,
            "elements": [
                "mekanism:plasticblock@15"
            ]
        },
        {
            "x": 8,
            "y": -1,
            "z": 12,
            "elements": [
                "nuclearcraft:turbine_dynamo_coil@4"
            ]
        },
        {
            "x": -3,
            "y": 2,
            "z": 13,
            "elements": [
                "chisel:laboratory@6"
            ]
        },
        {
            "x": 2,
            "y": 1,
            "z": 7,
            "elements": [
                "enderio:block_enlightened_fused_quartz@0"
            ]
        },
        {
            "x": 1,
            "y": -1,
            "z": 21,
            "elements": [
                "mekanism:plasticblock@15"
            ]
        },
        {
            "x": 5,
            "y": 0,
            "z": 20,
            "elements": [
                "rpsideas:dark_plate@0"
            ]
        },
        {
            "x": -2,
            "y": 2,
            "z": 8,
            "elements": [
                "chisel:laboratory@6"
            ]
        },
        {
            "x": 3,
            "y": 0,
            "z": 9,
            "elements": [
                "enderio:block_enlightened_fused_quartz@0"
            ]
        },
        {
            "x": 1,
            "y": 10,
            "z": 11,
            "elements": [
                "mekanism:plasticblock@15"
            ]
        },
        {
            "x": 9,
            "y": -5,
            "z": 11,
            "elements": [
                "rpsideas:dark_plate@0"
            ]
        },
        {
            "x": -1,
            "y": -4,
            "z": 13,
            "elements": [
                "enderio:block_enlightened_fused_quartz@0"
            ]
        },
        {
            "x": 2,
            "y": -1,
            "z": 2,
            "elements": [
                "chisel:factory1@4"
            ]
        },
        {
            "x": 0,
            "y": 1,
            "z": 2,
            "elements": [
                "nuclearcraft:turbine_dynamo_coil@4"
            ]
        },
        {
            "x": 0,
            "y": -2,
            "z": 8,
            "elements": [
                "enderio:block_enlightened_fused_quartz@0"
            ]
        },
        {
            "x": 9,
            "y": 0,
            "z": 15,
            "elements": [
                "rpsideas:dark_plate@0"
            ]
        },
        {
            "x": -10,
            "y": -2,
            "z": 13,
            "elements": [
                "mekanism:plasticblock@15"
            ]
        },
        {
            "x": 3,
            "y": 3,
            "z": 12,
            "elements": [
                "chisel:laboratory@6"
            ]
        },
        {
            "x": -2,
            "y": -1,
            "z": 14,
            "elements": [
                "enderio:block_enlightened_fused_quartz@0"
            ]
        },
        {
            "x": 9,
            "y": -6,
            "z": 11,
            "elements": [
                "rpsideas:dark_plate@0"
            ]
        },
        {
            "x": 1,
            "y": -2,
            "z": 6,
            "elements": [
                "enderio:block_enlightened_fused_quartz@0"
            ]
        },
        {
            "x": -1,
            "y": 1,
            "z": 21,
            "elements": [
                "mekanism:plasticblock@15"
            ]
        },
        {
            "x": 1,
            "y": -3,
            "z": 14,
            "elements": [
                "chisel:laboratory@6"
            ]
        },
        {
            "x": 0,
            "y": 1,
            "z": 19,
            "elements": [
                "nuclearcraft:turbine_dynamo_coil@4"
            ]
        },
        {
            "x": 1,
            "y": -2,
            "z": 21,
            "elements": [
                "mekanism:plasticblock@15"
            ]
        },
        {
            "x": 2,
            "y": -1,
            "z": 9,
            "elements": [
                "enderio:block_enlightened_fused_quartz@0"
            ]
        },
        {
            "x": -2,
            "y": -1,
            "z": 17,
            "elements": [
                "enderio:block_enlightened_fused_quartz@0"
            ]
        },
        {
            "x": 0,
            "y": 9,
            "z": 16,
            "elements": [
                "rpsideas:dark_plate@0"
            ]
        },
        {
            "x": 6,
            "y": -1,
            "z": 11,
            "elements": [
                "nuclearcraft:turbine_dynamo_coil@4"
            ]
        },
        {
            "x": 0,
            "y": 3,
            "z": 9,
            "elements": [
                "enderio:block_enlightened_fused_quartz@0"
            ]
        },
        {
            "x": 9,
            "y": -7,
            "z": 11,
            "elements": [
                "rpsideas:dark_plate@0"
            ]
        },
        {
            "x": 7,
            "y": 2,
            "z": 10,
            "elements": [
                "enderio:block_enlightened_fused_quartz@0"
            ]
        },
        {
            "x": 0,
            "y": 3,
            "z": 2,
            "elements": [
                "rpsideas:dark_plate@0"
            ]
        },
        {
            "x": 1,
            "y": 9,
            "z": 11,
            "elements": [
                "nuclearcraft:turbine_dynamo_coil@4"
            ]
        },
        {
            "x": 9,
            "y": -1,
            "z": 10,
            "elements": [
                "nuclearcraft:turbine_dynamo_coil@4"
            ]
        },
        {
            "x": -1,
            "y": 2,
            "z": 21,
            "elements": [
                "mekanism:plasticblock@15"
            ]
        },
        {
            "x": 2,
            "y": -2,
            "z": 9,
            "elements": [
                "chisel:laboratory@6"
            ]
        },
        {
            "x": -2,
            "y": -1,
            "z": 7,
            "elements": [
                "enderio:block_enlightened_fused_quartz@0"
            ]
        },
        {
            "x": 2,
            "y": 0,
            "z": 6,
            "elements": [
                "enderio:block_enlightened_fused_quartz@0"
            ]
        },
        {
            "x": -1,
            "y": 2,
            "z": 6,
            "elements": [
                "enderio:block_enlightened_fused_quartz@0"
            ]
        },
        {
            "x": 1,
            "y": -3,
            "z": 21,
            "elements": [
                "mekanism:plasticblock@15"
            ]
        },
        {
            "x": 2,
            "y": -3,
            "z": 9,
            "elements": [
                "chisel:laboratory@6"
            ]
        },
        {
            "x": 9,
            "y": -8,
            "z": 11,
            "elements": [
                "rpsideas:dark_plate@0"
            ]
        },
        {
            "x": 6,
            "y": 0,
            "z": 20,
            "elements": [
                "rpsideas:dark_plate@0"
            ]
        },
        {
            "x": 6,
            "y": 0,
            "z": 9,
            "elements": [
                "enderio:block_enlightened_fused_quartz@0"
            ]
        },
        {
            "x": -1,
            "y": -2,
            "z": 13,
            "elements": [
                "enderio:block_enlightened_fused_quartz@0"
            ]
        },
        {
            "x": 1,
            "y": 8,
            "z": 11,
            "elements": [
                "nuclearcraft:turbine_dynamo_coil@4"
            ]
        },
        {
            "x": -1,
            "y": 3,
            "z": 21,
            "elements": [
                "mekanism:plasticblock@15"
            ]
        },
        {
            "x": 5,
            "y": -1,
            "z": 9,
            "elements": [
                "enderio:block_enlightened_fused_quartz@0"
            ]
        },
        {
            "x": -3,
            "y": 0,
            "z": 13,
            "elements": [
                "enderio:block_enlightened_fused_quartz@0"
            ]
        },
        {
            "x": 9,
            "y": 0,
            "z": 10,
            "elements": [
                "nuclearcraft:turbine_dynamo_coil@4"
            ]
        },
        {
            "x": 0,
            "y": 4,
            "z": 9,
            "elements": [
                "enderio:block_enlightened_fused_quartz@0"
            ]
        },
        {
            "x": 9,
            "y": -2,
            "z": 10,
            "elements": [
                "chisel:factory1@4"
            ]
        },
        {
            "x": -1,
            "y": 2,
            "z": 8,
            "elements": [
                "enderio:block_enlightened_fused_quartz@0"
            ]
        },
        {
            "x": -1,
            "y": -2,
            "z": 9,
            "elements": [
                "enderio:block_enlightened_fused_quartz@0"
            ]
        },
        {
            "x": 1,
            "y": 9,
            "z": 10,
            "elements": [
                "nuclearcraft:turbine_dynamo_coil@4"
            ]
        },
        {
            "x": 3,
            "y": 2,
            "z": 13,
            "elements": [
                "chisel:laboratory@6"
            ]
        },
        {
            "x": 8,
            "y": -2,
            "z": 11,
            "elements": [
                "enderio:block_enlightened_fused_quartz@0"
            ]
        },
        {
            "x": 4,
            "y": 9,
            "z": 11,
            "elements": [
                "rpsideas:dark_plate@0"
            ]
        },
        {
            "x": 6,
            "y": 2,
            "z": 10,
            "elements": [
                "enderio:block_enlightened_fused_quartz@0"
            ]
        },
        {
            "x": 1,
            "y": 10,
            "z": 10,
            "elements": [
                "mekanism:plasticblock@15"
            ]
        },
        {
            "x": -2,
            "y": 1,
            "z": 2,
            "elements": [
                "chisel:factory1@4"
            ]
        },
        {
            "x": -2,
            "y": -2,
            "z": 8,
            "elements": [
                "chisel:laboratory@6"
            ]
        },
        {
            "x": 8,
            "y": -1,
            "z": 10,
            "elements": [
                "nuclearcraft:turbine_dynamo_coil@4"
            ]
        },
        {
            "x": 1,
            "y": 0,
            "z": 1,
            "elements": [
                "mekanism:plasticblock@15"
            ]
        },
        {
            "x": -1,
            "y": 8,
            "z": 13,
            "elements": [
                "enderio:block_enlightened_fused_quartz@0"
            ]
        },
        {
            "x": -1,
            "y": -3,
            "z": 9,
            "elements": [
                "enderio:block_enlightened_fused_quartz@0"
            ]
        },
        {
            "x": -9,
            "y": 0,
            "z": 6,
            "elements": [
                "rpsideas:dark_plate@0"
            ]
        },
        {
            "x": 0,
            "y": -1,
            "z": 2,
            "elements": [
                "nuclearcraft:turbine_dynamo_coil@4"
            ]
        },
        {
            "x": 8,
            "y": -2,
            "z": 10,
            "elements": [
                "enderio:block_enlightened_fused_quartz@0"
            ]
        },
        {
            "x": 8,
            "y": -1,
            "z": 11,
            "elements": [
                "nuclearcraft:turbine_dynamo_coil@4"
            ]
        },
        {
            "x": 0,
            "y": 2,
            "z": 13,
            "elements": [
                "enderio:block_enlightened_fused_quartz@0"
            ]
        },
        {
            "x": 6,
            "y": 0,
            "z": 10,
            "elements": [
                "nuclearcraft:turbine_dynamo_coil@4"
            ]
        },
        {
            "x": 2,
            "y": -3,
            "z": 12,
            "elements": [
                "enderio:block_enlightened_fused_quartz@0"
            ]
        },
        {
            "x": 7,
            "y": 9,
            "z": 11,
            "elements": [
                "rpsideas:dark_plate@0"
            ]
        },
        {
            "x": 3,
            "y": 0,
            "z": 13,
            "elements": [
                "enderio:block_enlightened_fused_quartz@0"
            ]
        },
        {
            "x": 1,
            "y": 2,
            "z": 1,
            "elements": [
                "mekanism:plasticblock@15"
            ]
        },
        {
            "x": 0,
            "y": -9,
            "z": 19,
            "elements": [
                "rpsideas:dark_plate@0"
            ]
        },
        {
            "x": -1,
            "y": 1,
            "z": 2,
            "elements": [
                "nuclearcraft:turbine_dynamo_coil@4"
            ]
        },
        {
            "x": -9,
            "y": 1,
            "z": 9,
            "elements": [
                "chisel:factory1@4"
            ]
        },
        {
            "x": -1,
            "y": -1,
            "z": 2,
            "elements": [
                "nuclearcraft:turbine_dynamo_coil@4"
            ]
        },
        {
            "x": -1,
            "y": -10,
            "z": 8,
            "elements": [
                "mekanism:plasticblock@15"
            ]
        },
        {
            "x": 0,
            "y": -3,
            "z": 2,
            "elements": [
                "rpsideas:dark_plate@0"
            ]
        },
        {
            "x": 7,
            "y": 0,
            "z": 10,
            "elements": [
                "nuclearcraft:turbine_dynamo_coil@4"
            ]
        },
        {
            "x": 8,
            "y": 0,
            "z": 20,
            "elements": [
                "rpsideas:dark_plate@0"
            ]
        },
        {
            "x": -1,
            "y": 10,
            "z": 13,
            "elements": [
                "mekanism:plasticblock@15"
            ]
        },
        {
            "x": 0,
            "y": 7,
            "z": 12,
            "elements": [
                "nuclearcraft:turbine_dynamo_coil@4"
            ]
        },
        {
            "x": -1,
            "y": -2,
            "z": 16,
            "elements": [
                "enderio:block_enlightened_fused_quartz@0"
            ]
        },
        {
            "x": 2,
            "y": 0,
            "z": 13,
            "elements": [
                "enderio:block_enlightened_fused_quartz@0"
            ]
        },
        {
            "x": 9,
            "y": 2,
            "z": 11,
            "elements": [
                "chisel:factory1@4"
            ]
        },
        {
            "x": -1,
            "y": -9,
            "z": 9,
            "elements": [
                "chisel:factory1@4"
            ]
        },
        {
            "x": 0,
            "y": 9,
            "z": 19,
            "elements": [
                "rpsideas:dark_plate@0"
            ]
        },
        {
            "x": -9,
            "y": 0,
            "z": 9,
            "elements": [
                "chisel:factory1@4"
            ]
        },
        {
            "x": 3,
            "y": 0,
            "z": 21,
            "elements": [
                "mekanism:plasticblock@15"
            ]
        },
        {
            "x": -1,
            "y": 6,
            "z": 13,
            "elements": [
                "enderio:block_enlightened_fused_quartz@0"
            ]
        },
        {
            "x": 10,
            "y": 0,
            "z": 11,
            "elements": [
                "mekanism:plasticblock@15"
            ]
        },
        {
            "x": -2,
            "y": -1,
            "z": 2,
            "elements": [
                "chisel:factory1@4"
            ]
        },
        {
            "x": 0,
            "y": 4,
            "z": 13,
            "elements": [
                "enderio:block_enlightened_fused_quartz@0"
            ]
        },
        {
            "x": -3,
            "y": 0,
            "z": 8,
            "elements": [
                "chisel:laboratory@6"
            ]
        },
        {
            "x": 9,
            "y": 3,
            "z": 11,
            "elements": [
                "rpsideas:dark_plate@0"
            ]
        },
        {
            "x": 2,
            "y": -10,
            "z": 9,
            "elements": [
                "mekanism:plasticblock@15"
            ]
        },
        {
            "x": -10,
            "y": -3,
            "z": 12,
            "elements": [
                "mekanism:plasticblock@15"
            ]
        },
        {
            "x": -10,
            "y": -1,
            "z": 9,
            "elements": [
                "mekanism:plasticblock@15"
            ]
        },
        {
            "x": 10,
            "y": 1,
            "z": 11,
            "elements": [
                "mekanism:plasticblock@15"
            ]
        },
        {
            "x": -1,
            "y": -8,
            "z": 9,
            "elements": [
                "enderio:block_enlightened_fused_quartz@0"
            ]
        },
        {
            "x": 0,
            "y": 9,
            "z": 12,
            "elements": [
                "nuclearcraft:turbine_dynamo_coil@4"
            ]
        },
        {
            "x": -10,
            "y": -2,
            "z": 9,
            "elements": [
                "mekanism:plasticblock@15"
            ]
        },
        {
            "x": 3,
            "y": 1,
            "z": 21,
            "elements": [
                "mekanism:plasticblock@15"
            ]
        },
        {
            "x": 0,
            "y": -10,
            "z": 8,
            "elements": [
                "mekanism:plasticblock@15"
            ]
        },
        {
            "x": 10,
            "y": 2,
            "z": 11,
            "elements": [
                "mekanism:plasticblock@15"
            ]
        },
        {
            "x": 2,
            "y": -2,
            "z": 13,
            "elements": [
                "chisel:laboratory@6"
            ]
        },
        {
            "x": -6,
            "y": 0,
            "z": 9,
            "elements": [
                "enderio:block_enlightened_fused_quartz@0"
            ]
        },
        {
            "x": 2,
            "y": 2,
            "z": 13,
            "elements": [
                "chisel:laboratory@6"
            ]
        },
        {
            "x": 2,
            "y": 0,
            "z": 20,
            "elements": [
                "chisel:factory1@4"
            ]
        },
        {
            "x": -1,
            "y": -4,
            "z": 9,
            "elements": [
                "enderio:block_enlightened_fused_quartz@0"
            ]
        },
        {
            "x": 0,
            "y": 0,
            "z": 16,
            "elements": [
                "nuclearcraft:turbine_dynamo_coil@4"
            ]
        },
        {
            "x": 1,
            "y": 1,
            "z": 2,
            "elements": [
                "nuclearcraft:turbine_dynamo_coil@4"
            ]
        },
        {
            "x": 1,
            "y": -1,
            "z": 2,
            "elements": [
                "nuclearcraft:turbine_dynamo_coil@4"
            ]
        },
        {
            "x": 0,
            "y": 6,
            "z": 13,
            "elements": [
                "enderio:block_enlightened_fused_quartz@0"
            ]
        },
        {
            "x": -1,
            "y": 4,
            "z": 13,
            "elements": [
                "enderio:block_enlightened_fused_quartz@0"
            ]
        },
        {
            "x": 10,
            "y": 3,
            "z": 11,
            "elements": [
                "mekanism:plasticblock@15"
            ]
        },
        {
            "x": 5,
            "y": -2,
            "z": 10,
            "elements": [
                "enderio:block_enlightened_fused_quartz@0"
            ]
        },
        {
            "x": -1,
            "y": -10,
            "z": 9,
            "elements": [
                "mekanism:plasticblock@15"
            ]
        },
        {
            "x": -7,
            "y": -1,
            "z": 9,
            "elements": [
                "enderio:block_enlightened_fused_quartz@0"
            ]
        },
        {
            "x": 3,
            "y": 3,
            "z": 10,
            "elements": [
                "chisel:laboratory@6"
            ]
        },
        {
            "x": 2,
            "y": 1,
            "z": 20,
            "elements": [
                "chisel:factory1@4"
            ]
        },
        {
            "x": 9,
            "y": 1,
            "z": 11,
            "elements": [
                "nuclearcraft:turbine_dynamo_coil@4"
            ]
        },
        {
            "x": -10,
            "y": -1,
            "z": 12,
            "elements": [
                "mekanism:plasticblock@15"
            ]
        },
        {
            "x": 1,
            "y": -10,
            "z": 8,
            "elements": [
                "mekanism:plasticblock@15"
            ]
        },
        {
            "x": -1,
            "y": 0,
            "z": 20,
            "elements": [
                "nuclearcraft:turbine_dynamo_coil@4"
            ]
        },
        {
            "x": -3,
            "y": 0,
            "z": 1,
            "elements": [
                "mekanism:plasticblock@15"
            ]
        },
        {
            "x": -1,
            "y": 2,
            "z": 13,
            "elements": [
                "enderio:block_enlightened_fused_quartz@0"
            ]
        },
        {
            "x": 0,
            "y": 0,
            "z": 15,
            "elements": [
                "nuclearcraft:turbine_dynamo_coil@4"
            ]
        },
        {
            "x": 0,
            "y": 2,
            "z": 1,
            "elements": [
                "mekanism:plasticblock@15"
            ]
        },
        {
            "x": 1,
            "y": -2,
            "z": 20,
            "elements": [
                "chisel:factory1@4"
            ]
        },
        {
            "x": 10,
            "y": 1,
            "z": 9,
            "elements": [
                "mekanism:plasticblock@15"
            ]
        },
        {
            "x": 1,
            "y": -1,
            "z": 20,
            "elements": [
                "nuclearcraft:turbine_dynamo_coil@4"
            ]
        },
        {
            "x": -1,
            "y": 1,
            "z": 20,
            "elements": [
                "nuclearcraft:turbine_dynamo_coil@4"
            ]
        },
        {
            "x": -1,
            "y": -2,
            "z": 6,
            "elements": [
                "enderio:block_enlightened_fused_quartz@0"
            ]
        },
        {
            "x": 1,
            "y": -4,
            "z": 13,
            "elements": [
                "enderio:block_enlightened_fused_quartz@0"
            ]
        },
        {
            "x": 2,
            "y": -1,
            "z": 15,
            "elements": [
                "enderio:block_enlightened_fused_quartz@0"
            ]
        },
        {
            "x": -4,
            "y": 0,
            "z": 13,
            "elements": [
                "enderio:block_enlightened_fused_quartz@0"
            ]
        },
        {
            "x": 10,
            "y": 2,
            "z": 9,
            "elements": [
                "mekanism:plasticblock@15"
            ]
        },
        {
            "x": -9,
            "y": -1,
            "z": 12,
            "elements": [
                "nuclearcraft:turbine_dynamo_coil@4"
            ]
        },
        {
            "x": 0,
            "y": 2,
            "z": 15,
            "elements": [
                "enderio:block_enlightened_fused_quartz@0"
            ]
        },
        {
            "x": -1,
            "y": -2,
            "z": 15,
            "elements": [
                "enderio:block_enlightened_fused_quartz@0"
            ]
        },
        {
            "x": 2,
            "y": -2,
            "z": 1,
            "elements": [
                "mekanism:plasticblock@15"
            ]
        },
        {
            "x": -1,
            "y": 2,
            "z": 20,
            "elements": [
                "chisel:factory1@4"
            ]
        },
        {
            "x": 0,
            "y": -9,
            "z": 2,
            "elements": [
                "rpsideas:dark_plate@0"
            ]
        },
        {
            "x": 0,
            "y": 0,
            "z": 6,
            "elements": [
                "nuclearcraft:turbine_dynamo_coil@4"
            ]
        },
        {
            "x": 0,
            "y": 0,
            "z": 1,
            "elements": [
                "mekanism:plasticblock@15"
            ]
        },
        {
            "x": -4,
            "y": 0,
            "z": 20,
            "elements": [
                "rpsideas:dark_plate@3"
            ]
        },
        {
            "x": -2,
            "y": 3,
            "z": 12,
            "elements": [
                "enderio:block_enlightened_fused_quartz@0"
            ]
        },
        {
            "x": 1,
            "y": -2,
            "z": 13,
            "elements": [
                "enderio:block_enlightened_fused_quartz@0"
            ]
        },
        {
            "x": 0,
            "y": 2,
            "z": 6,
            "elements": [
                "enderio:block_enlightened_fused_quartz@0"
            ]
        },
        {
            "x": -1,
            "y": 0,
            "z": 1,
            "elements": [
                "mekanism:plasticblock@15"
            ]
        },
        {
            "x": 0,
            "y": -7,
            "z": 2,
            "elements": [
                "rpsideas:dark_plate@0"
            ]
        },
        {
            "x": -10,
            "y": -2,
            "z": 10,
            "elements": [
                "mekanism:plasticblock@15"
            ]
        },
        {
            "x": -8,
            "y": 1,
            "z": 12,
            "elements": [
                "nuclearcraft:turbine_dynamo_coil@4"
            ]
        },
        {
            "x": -1,
            "y": -2,
            "z": 1,
            "elements": [
                "mekanism:plasticblock@15"
            ]
        },
        {
            "x": -2,
            "y": 2,
            "z": 1,
            "elements": [
                "mekanism:plasticblock@15"
            ]
        },
        {
            "x": -10,
            "y": -1,
            "z": 14,
            "elements": [
                "mekanism:plasticblock@15"
            ]
        },
        {
            "x": 1,
            "y": -6,
            "z": 13,
            "elements": [
                "enderio:block_enlightened_fused_quartz@0"
            ]
        },
        {
            "x": 0,
            "y": -9,
            "z": 12,
            "elements": [
                "nuclearcraft:turbine_dynamo_coil@4"
            ]
        },
        {
            "x": 1,
            "y": 10,
            "z": 8,
            "elements": [
                "mekanism:plasticblock@15"
            ]
        },
        {
            "x": -10,
            "y": 0,
            "z": 13,
            "elements": [
                "mekanism:plasticblock@15"
            ]
        },
        {
            "x": 0,
            "y": -2,
            "z": 18,
            "elements": [
                "enderio:block_enlightened_fused_quartz@0"
            ]
        },
        {
            "x": -2,
            "y": -2,
            "z": 13,
            "elements": [
                "chisel:laboratory@6"
            ]
        },
        {
            "x": 0,
            "y": -5,
            "z": 2,
            "elements": [
                "rpsideas:dark_plate@0"
            ]
        },
        {
            "x": -10,
            "y": -1,
            "z": 10,
            "elements": [
                "mekanism:plasticblock@15"
            ]
        },
        {
            "x": -2,
            "y": 0,
            "z": 1,
            "elements": [
                "mekanism:plasticblock@15"
            ]
        },
        {
            "x": 0,
            "y": -2,
            "z": 1,
            "elements": [
                "mekanism:plasticblock@15"
            ]
        },
        {
            "x": -1,
            "y": 2,
            "z": 1,
            "elements": [
                "mekanism:plasticblock@15"
            ]
        },
        {
            "x": 1,
            "y": -8,
            "z": 13,
            "elements": [
                "enderio:block_enlightened_fused_quartz@0"
            ]
        },
        {
            "x": 0,
            "y": -7,
            "z": 12,
            "elements": [
                "nuclearcraft:turbine_dynamo_coil@4"
            ]
        },
        {
            "x": -10,
            "y": -3,
            "z": 10,
            "elements": [
                "mekanism:plasticblock@15"
            ]
        },
        {
            "x": 1,
            "y": 0,
            "z": 18,
            "elements": [
                "nuclearcraft:turbine_dynamo_coil@4"
            ]
        },
        {
            "x": -3,
            "y": -3,
            "z": 12,
            "elements": [
                "chisel:laboratory@6"
            ]
        },
        {
            "x": -2,
            "y": -1,
            "z": 20,
            "elements": [
                "chisel:factory1@4"
            ]
        },
        {
            "x": -10,
            "y": 2,
            "z": 13,
            "elements": [
                "mekanism:plasticblock@15"
            ]
        },
        {
            "x": 6,
            "y": 1,
            "z": 9,
            "elements": [
                "enderio:block_enlightened_fused_quartz@0"
            ]
        },
        {
            "x": 1,
            "y": -2,
            "z": 1,
            "elements": [
                "mekanism:plasticblock@15"
            ]
        },
        {
            "x": 8,
            "y": -1,
            "z": 9,
            "elements": [
                "enderio:block_enlightened_fused_quartz@0"
            ]
        },
        {
            "x": 1,
            "y": -10,
            "z": 13,
            "elements": [
                "mekanism:plasticblock@15"
            ]
        },
        {
            "x": 0,
            "y": -9,
            "z": 7,
            "elements": [
                "rpsideas:dark_plate@0"
            ]
        },
        {
            "x": 0,
            "y": -8,
            "z": 13,
            "elements": [
                "enderio:block_enlightened_fused_quartz@0"
            ]
        },
        {
            "x": -1,
            "y": -3,
            "z": 14,
            "elements": [
                "chisel:laboratory@6"
            ]
        },
        {
            "x": 1,
            "y": 0,
            "z": 5,
            "elements": [
                "nuclearcraft:turbine_dynamo_coil@4"
            ]
        },
        {
            "x": 1,
            "y": 2,
            "z": 5,
            "elements": [
                "enderio:block_enlightened_fused_quartz@0"
            ]
        },
        {
            "x": 1,
            "y": -2,
            "z": 8,
            "elements": [
                "enderio:block_enlightened_fused_quartz@0"
            ]
        },
        {
            "x": -10,
            "y": 1,
            "z": 14,
            "elements": [
                "mekanism:plasticblock@15"
            ]
        },
        {
            "x": 9,
            "y": 0,
            "z": 9,
            "elements": [
                "chisel:factory1@4"
            ]
        },
        {
            "x": -8,
            "y": 0,
            "z": 13,
            "elements": [
                "enderio:block_enlightened_fused_quartz@0"
            ]
        },
        {
            "x": -2,
            "y": -9,
            "z": 12,
            "elements": [
                "chisel:factory1@4"
            ]
        },
        {
            "x": 0,
            "y": -1,
            "z": 17,
            "elements": [
                "nuclearcraft:turbine_dynamo_coil@4"
            ]
        },
        {
            "x": -2,
            "y": 0,
            "z": 18,
            "elements": [
                "enderio:block_enlightened_fused_quartz@0"
            ]
        },
        {
            "x": -2,
            "y": -10,
            "z": 13,
            "elements": [
                "mekanism:plasticblock@15"
            ]
        },
        {
            "x": -2,
            "y": 1,
            "z": 7,
            "elements": [
                "enderio:block_enlightened_fused_quartz@0"
            ]
        },
        {
            "x": -2,
            "y": -2,
            "z": 1,
            "elements": [
                "mekanism:plasticblock@15"
            ]
        },
        {
            "x": 0,
            "y": -2,
            "z": 5,
            "elements": [
                "enderio:block_enlightened_fused_quartz@0"
            ]
        },
        {
            "x": -2,
            "y": -1,
            "z": 21,
            "elements": [
                "mekanism:plasticblock@15"
            ]
        },
        {
            "x": 0,
            "y": -6,
            "z": 13,
            "elements": [
                "enderio:block_enlightened_fused_quartz@0"
            ]
        },
        {
            "x": -2,
            "y": -7,
            "z": 12,
            "elements": [
                "enderio:block_enlightened_fused_quartz@0"
            ]
        },
        {
            "x": -3,
            "y": 1,
            "z": 14,
            "elements": [
                "chisel:laboratory@6"
            ]
        },
        {
            "x": -3,
            "y": -2,
            "z": 13,
            "elements": [
                "chisel:laboratory@6"
            ]
        },
        {
            "x": 2,
            "y": 0,
            "z": 8,
            "elements": [
                "enderio:block_enlightened_fused_quartz@0"
            ]
        },
        {
            "x": -2,
            "y": -5,
            "z": 12,
            "elements": [
                "enderio:block_enlightened_fused_quartz@0"
            ]
        },
        {
            "x": 0,
            "y": -1,
            "z": 5,
            "elements": [
                "nuclearcraft:turbine_dynamo_coil@4"
            ]
        },
        {
            "x": -5,
            "y": 0,
            "z": 13,
            "elements": [
                "enderio:block_enlightened_fused_quartz@0"
            ]
        },
        {
            "x": 1,
            "y": 2,
            "z": 8,
            "elements": [
                "enderio:block_enlightened_fused_quartz@0"
            ]
        },
        {
            "x": -2,
            "y": -2,
            "z": 21,
            "elements": [
                "mekanism:plasticblock@15"
            ]
        },
        {
            "x": -1,
            "y": -10,
            "z": 13,
            "elements": [
                "mekanism:plasticblock@15"
            ]
        },
        {
            "x": -2,
            "y": 1,
            "z": 17,
            "elements": [
                "enderio:block_enlightened_fused_quartz@0"
            ]
        },
        {
            "x": -10,
            "y": 0,
            "z": 8,
            "elements": [
                "mekanism:plasticblock@15"
            ]
        },
        {
            "x": -2,
            "y": 9,
            "z": 11,
            "elements": [
                "chisel:factory1@4"
            ]
        },
        {
            "x": -7,
            "y": 0,
            "z": 20,
            "elements": [
                "rpsideas:dark_plate@0"
            ]
        },
        {
            "x": 3,
            "y": 0,
            "z": 1,
            "elements": [
                "mekanism:plasticblock@15"
            ]
        },
        {
            "x": 9,
            "y": 0,
            "z": 16,
            "elements": [
                "rpsideas:dark_plate@0"
            ]
        },
        {
            "x": 2,
            "y": 2,
            "z": 1,
            "elements": [
                "mekanism:plasticblock@15"
            ]
        },
        {
            "x": -6,
            "y": 0,
            "z": 13,
            "elements": [
                "enderio:block_enlightened_fused_quartz@0"
            ]
        },
        {
            "x": 2,
            "y": 2,
            "z": 8,
            "elements": [
                "chisel:laboratory@6"
            ]
        },
        {
            "x": -2,
            "y": 8,
            "z": 11,
            "elements": [
                "enderio:block_enlightened_fused_quartz@0"
            ]
        },
        {
            "x": -2,
            "y": -3,
            "z": 12,
            "elements": [
                "enderio:block_enlightened_fused_quartz@0"
            ]
        },
        {
