{
    "registryname": "Stellar_Firmament_Anchor",
    "localizedname": "§9「永曜」§c星穹之锚",
    "failure-action": "still",
    "requires-blueprint": false,
    "color": "11131A",
    "parts": [
        {
            "x": 0,
            "y": 0,
            "z": 0,
            "elements": [
                "modularmachinery:blockcontroller@2"
            ]
        },
        {
            "x": -9,
            "y": 0,
            "z": 20,
            "elements": [
                "contenttweaker:arkforcefieldcontrolblock@0"
            ]
        },
        {
            "x": 10,
            "y": -1,
            "z": 22,
            "elements": [
                "contenttweaker:arkforcefieldcontrolblock@0"
            ]
        },
        {
            "x": -7,
            "y": 1,
            "z": 21,
            "elements": [
                "contenttweaker:arkforcefieldcontrolblock@0"
            ]
        },
        {
            "x": 8,
            "y": 1,
            "z": 22,
            "elements": [
                "contenttweaker:arkforcefieldcontrolblock@0"
            ]
        },
        {
            "x": 5,
            "y": -1,
            "z": 1,
            "elements": [
                "contenttweaker:arkforcefieldcontrolblock@0"
            ]
        },
        {
            "x": 1,
            "y": 0,
            "z": 0,
            "elements": [
                "casings_all",
                "modularmachinery:blockmepatternprovider@0"
            ]
        },
        {
            "x": -13,
            "y": 1,
            "z": 16,
            "elements": [
                "contenttweaker:arkforcefieldcontrolblock@0"
            ]
        },
        {
            "x": -12,
            "y": 1,
            "z": 11,
            "elements": [
                "contenttweaker:arkforcefieldcontrolblock@0"
            ]
        },
        {
            "x": -12,
            "y": -1,
            "z": 9,
            "elements": [
                "contenttweaker:arkforcefieldcontrolblock@0"
            ]
        },
        {
            "x": 9,
            "y": 0,
            "z": 7,
            "elements": [
                "contenttweaker:arkforcefieldcontrolblock@0"
            ]
        },
        {
            "x": -13,
            "y": 1,
            "z": 9,
            "elements": [
                "contenttweaker:arkforcefieldcontrolblock@0"
            ]
        },
        {
            "x": -10,
            "y": 1,
            "z": 16,
            "elements": [
                "contenttweaker:arkforcefieldcontrolblock@0"
            ]
        },
        {
            "x": 9,
            "y": 1,
            "z": 7,
            "elements": [
                "contenttweaker:arkforcefieldcontrolblock@0"
            ]
        },
        {
            "x": 2,
            "y": 0,
            "z": 0,
            "elements": [
                "contenttweaker:arkforcefieldcontrolblock@0"
            ]
        },
        {
            "x": 6,
            "y": 1,
            "z": 4,
            "elements": [
                "contenttweaker:arkforcefieldcontrolblock@0"
            ]
        },
        {
            "x": 4,
            "y": 1,
            "z": 23,
            "elements": [
                "contenttweaker:arkforcefieldcontrolblock@0"
            ]
        },
        {
            "x": 9,
            "y": 0,
            "z": 3,
            "elements": [
                "contenttweaker:arkforcefieldcontrolblock@0"
            ]
        },
        {
            "x": 4,
            "y": -1,
            "z": 23,
            "elements": [
                "contenttweaker:arkforcefieldcontrolblock@0"
            ]
        },
        {
            "x": 5,
            "y": 0,
            "z": 23,
            "elements": [
                "contenttweaker:arkforcefieldcontrolblock@0"
            ]
        },
        {
            "x": 13,
            "y": 0,
            "z": 16,
            "elements": [
                "contenttweaker:arkforcefieldcontrolblock@0"
            ]
        },
        {
            "x": -9,
            "y": 1,
            "z": 4,
            "elements": [
                "contenttweaker:arkforcefieldcontrolblock@0"
            ]
        },
        {
            "x": -11,
            "y": -1,
            "z": 12,
            "elements": [
                "contenttweaker:arkforcefieldcontrolblock@0"
            ]
        },
        {
            "x": -1,
            "y": 0,
            "z": 0,
            "elements": [
                "casings_all",
                "modularmachinery:blockmepatternprovider@0"
            ]
        },
        {
            "x": 5,
            "y": 1,
            "z": 23,
            "elements": [
                "contenttweaker:arkforcefieldcontrolblock@0"
            ]
        },
        {
            "x": 6,
            "y": 0,
            "z": 1,
            "elements": [
                "contenttweaker:arkforcefieldcontrolblock@0"
            ]
        },
        {
            "x": 6,
            "y": 1,
            "z": 1,
            "elements": [
                "contenttweaker:arkforcefieldcontrolblock@0"
            ]
        },
        {
            "x": -10,
            "y": 0,
            "z": 20,
            "elements": [
                "contenttweaker:space_time_coil@0"
            ]
        },
        {
            "x": -11,
            "y": -1,
            "z": 16,
            "elements": [
                "contenttweaker:arkforcefieldcontrolblock@0"
            ]
        },
        {
            "x": 5,
            "y": -1,
            "z": 4,
            "elements": [
                "contenttweaker:arkforcefieldcontrolblock@0"
            ]
        },
        {
            "x": 3,
            "y": -1,
            "z": 23,
            "elements": [
                "contenttweaker:arkforcefieldcontrolblock@0"
            ]
        },
        {
            "x": 3,
            "y": 0,
            "z": 3,
            "elements": [
                "contenttweaker:arkforcefieldcontrolblock@0"
            ]
        },
        {
            "x": -11,
            "y": 1,
            "z": 9,
            "elements": [
                "contenttweaker:arkforcefieldcontrolblock@0"
            ]
        },
        {
            "x": 11,
            "y": 1,
            "z": 19,
            "elements": [
                "contenttweaker:arkforcefieldcontrolblock@0"
            ]
        },
        {
            "x": -11,
            "y": -1,
            "z": 9,
            "elements": [
                "contenttweaker:arkforcefieldcontrolblock@0"
            ]
        },
        {
            "x": 11,
            "y": 0,
            "z": 19,
            "elements": [
                "contenttweaker:arkforcefieldcontrolblock@0"
            ]
        },
        {
            "x": -10,
            "y": -1,
            "z": 4,
            "elements": [
                "contenttweaker:arkforcefieldcontrolblock@0"
            ]
        },
        {
            "x": 4,
            "y": 0,
            "z": 23,
            "elements": [
                "contenttweaker:arkforcefieldcontrolblock@0"
            ]
        },
        {
            "x": 6,
            "y": -1,
            "z": 23,
            "elements": [
                "contenttweaker:arkforcefieldcontrolblock@0"
            ]
        },
        {
            "x": -7,
            "y": 0,
            "z": 5,
            "elements": [
                "contenttweaker:arkforcefieldcontrolblock@0"
            ]
        },
        {
            "x": 4,
            "y": 0,
            "z": 0,
            "elements": [
                "contenttweaker:arkforcefieldcontrolblock@0"
            ]
        },
        {
            "x": -13,
            "y": 1,
            "z": 13,
            "elements": [
                "contenttweaker:arkforcefieldcontrolblock@0"
            ]
        },
        {
            "x": -13,
            "y": 0,
            "z": 12,
            "elements": [
                "contenttweaker:arkforcefieldcontrolblock@0"
            ]
        },
        {
            "x": -11,
            "y": 1,
            "z": 21,
            "elements": [
                "contenttweaker:arkforcefieldcontrolblock@0"
            ]
        },
        {
            "x": -9,
            "y": -1,
            "z": 21,
            "elements": [
                "contenttweaker:arkforcefieldcontrolblock@0"
            ]
        },
        {
            "x": -12,
            "y": 0,
            "z": 15,
            "elements": [
                "contenttweaker:space_time_coil@0"
            ]
        },
        {
            "x": -10,
            "y": 0,
            "z": 10,
            "elements": [
                "contenttweaker:arkforcefieldcontrolblock@0"
            ]
        },
        {
            "x": 7,
            "y": 0,
            "z": 23,
            "elements": [
                "contenttweaker:space_time_coil@0"
            ]
        },
        {
            "x": 12,
            "y": 1,
            "z": 8,
            "elements": [
                "contenttweaker:arkforcefieldcontrolblock@0"
            ]
        },
        {
            "x": 10,
            "y": -1,
            "z": 19,
            "elements": [
                "contenttweaker:arkforcefieldcontrolblock@0"
            ]
        },
        {
            "x": -8,
            "y": 0,
            "z": 3,
            "elements": [
                "contenttweaker:arkforcefieldcontrolblock@0"
            ]
        },
        {
            "x": -13,
            "y": 1,
            "z": 12,
            "elements": [
                "contenttweaker:arkforcefieldcontrolblock@0"
            ]
        },
        {
            "x": 9,
            "y": -1,
            "z": 23,
            "elements": [
                "contenttweaker:arkforcefieldcontrolblock@0"
            ]
        },
        {
            "x": -10,
            "y": -1,
            "z": 21,
            "elements": [
                "contenttweaker:arkforcefieldcontrolblock@0"
            ]
        },
        {
            "x": 7,
            "y": 1,
            "z": 23,
            "elements": [
                "contenttweaker:arkforcefieldcontrolblock@0"
            ]
        },
        {
            "x": 9,
            "y": 1,
            "z": 8,
            "elements": [
                "contenttweaker:arkforcefieldcontrolblock@0"
            ]
        },
        {
            "x": -4,
            "y": 1,
            "z": 26,
            "elements": [
                "contenttweaker:arkforcefieldcontrolblock@0"
            ]
        },
        {
            "x": -8,
            "y": 0,
            "z": 20,
            "elements": [
                "contenttweaker:arkforcefieldcontrolblock@0"
            ]
        },
        {
            "x": -10,
            "y": 1,
            "z": 21,
            "elements": [
                "contenttweaker:arkforcefieldcontrolblock@0"
            ]
        },
        {
            "x": -13,
            "y": 0,
            "z": 13,
            "elements": [
                "contenttweaker:arkforcefieldcontrolblock@0"
            ]
        },
        {
            "x": -11,
            "y": 0,
            "z": 20,
            "elements": [
                "contenttweaker:arkforcefieldcontrolblock@0"
            ]
        },
        {
            "x": -4,
            "y": 0,
            "z": 26,
            "elements": [
                "contenttweaker:arkforcefieldcontrolblock@0"
            ]
        },
        {
            "x": -2,
            "y": 0,
            "z": 0,
            "elements": [
                "contenttweaker:arkforcefieldcontrolblock@0"
            ]
        },
        {
            "x": 8,
            "y": -1,
            "z": 4,
            "elements": [
                "contenttweaker:arkforcefieldcontrolblock@0"
            ]
        },
        {
            "x": -11,
            "y": -1,
            "z": 21,
            "elements": [
                "contenttweaker:arkforcefieldcontrolblock@0"
            ]
        },
        {
            "x": -1,
            "y": 1,
            "z": 26,
            "elements": [
                "contenttweaker:arkforcefieldcontrolblock@0"
            ]
        },
        {
            "x": 10,
            "y": -1,
            "z": 17,
            "elements": [
                "contenttweaker:arkforcefieldcontrolblock@0"
            ]
        },
        {
            "x": -7,
            "y": -1,
            "z": 4,
            "elements": [
                "contenttweaker:arkforcefieldcontrolblock@0"
            ]
        },
        {
            "x": 6,
            "y": 0,
            "z": 3,
            "elements": [
                "contenttweaker:space_time_coil@0"
            ]
        },
        {
            "x": -1,
            "y": 0,
            "z": 26,
            "elements": [
                "contenttweaker:arkforcefieldcontrolblock@0"
            ]
        },
        {
            "x": -6,
            "y": 0,
            "z": 1,
            "elements": [
                "contenttweaker:arkforcefieldcontrolblock@0"
            ]
        },
        {
            "x": 9,
            "y": 1,
            "z": 4,
            "elements": [
                "contenttweaker:arkforcefieldcontrolblock@0"
            ]
        },
        {
            "x": 11,
            "y": 1,
            "z": 17,
            "elements": [
                "contenttweaker:arkforcefieldcontrolblock@0"
            ]
        },
        {
            "x": 11,
            "y": -1,
            "z": 8,
            "elements": [
                "contenttweaker:arkforcefieldcontrolblock@0"
            ]
        },
        {
            "x": -8,
            "y": -1,
            "z": 21,
            "elements": [
                "contenttweaker:arkforcefieldcontrolblock@0"
            ]
        },
        {
            "x": -8,
            "y": 1,
            "z": 21,
            "elements": [
                "contenttweaker:arkforcefieldcontrolblock@0"
            ]
        },
        {
            "x": -2,
            "y": -1,
            "z": 26,
            "elements": [
                "contenttweaker:arkforcefieldcontrolblock@0"
            ]
        },
        {
            "x": -4,
            "y": -1,
            "z": 1,
            "elements": [
                "contenttweaker:arkforcefieldcontrolblock@0"
            ]
        },
        {
            "x": -6,
            "y": 1,
            "z": 1,
            "elements": [
                "contenttweaker:arkforcefieldcontrolblock@0"
            ]
        },
        {
            "x": -6,
            "y": 1,
            "z": 4,
            "elements": [
                "contenttweaker:arkforcefieldcontrolblock@0"
            ]
        },
        {
            "x": -9,
            "y": 0,
            "z": 3,
            "elements": [
                "contenttweaker:arkforcefieldcontrolblock@0"
            ]
        },
        {
            "x": 11,
            "y": 0,
            "z": 17,
            "elements": [
                "contenttweaker:space_time_coil@0"
            ]
        },
        {
            "x": 12,
            "y": 0,
            "z": 8,
            "elements": [
                "contenttweaker:arkforcefieldcontrolblock@0"
            ]
        },
        {
            "x": 13,
            "y": -1,
            "z": 15,
            "elements": [
                "contenttweaker:arkforcefieldcontrolblock@0"
            ]
        },
        {
            "x": 12,
            "y": 0,
            "z": 11,
            "elements": [
                "contenttweaker:space_time_coil@0"
            ]
        },
        {
            "x": 4,
            "y": 1,
            "z": 24,
            "elements": [
                "contenttweaker:arkforcefieldcontrolblock@0"
            ]
        },
        {
            "x": -2,
            "y": 0,
            "z": 25,
            "elements": [
                "contenttweaker:space_time_coil@0"
            ]
        },
        {
            "x": 12,
            "y": 0,
            "z": 13,
            "elements": [
                "contenttweaker:space_time_coil@0"
            ]
        },
        {
            "x": -7,
            "y": 0,
            "z": 22,
            "elements": [
                "contenttweaker:arkforcefieldcontrolblock@0"
            ]
        },
        {
            "x": 4,
            "y": 0,
            "z": 3,
            "elements": [
                "contenttweaker:arkforcefieldcontrolblock@0"
            ]
        },
        {
            "x": 5,
            "y": 0,
            "z": 24,
            "elements": [
                "contenttweaker:space_time_coil@0"
            ]
        },
        {
            "x": -5,
            "y": -1,
            "z": 4,
            "elements": [
                "contenttweaker:arkforcefieldcontrolblock@0"
            ]
        },
        {
            "x": 11,
            "y": -1,
            "z": 13,
            "elements": [
                "contenttweaker:arkforcefieldcontrolblock@0"
            ]
        },
        {
            "x": 4,
            "y": -1,
            "z": 24,
            "elements": [
                "contenttweaker:arkforcefieldcontrolblock@0"
            ]
        },
        {
            "x": 5,
            "y": 1,
            "z": 24,
            "elements": [
                "contenttweaker:arkforcefieldcontrolblock@0"
            ]
        },
        {
            "x": -5,
            "y": 0,
            "z": 25,
            "elements": [
                "contenttweaker:arkforcefieldcontrolblock@0"
            ]
        },
        {
            "x": -5,
            "y": 0,
            "z": 23,
            "elements": [
                "contenttweaker:arkforcefieldcontrolblock@0"
            ]
        },
        {
            "x": -5,
            "y": 1,
            "z": 23,
            "elements": [
                "contenttweaker:arkforcefieldcontrolblock@0"
            ]
        },
        {
            "x": -13,
            "y": 0,
            "z": 15,
            "elements": [
                "contenttweaker:arkforcefieldcontrolblock@0"
            ]
        },
        {
            "x": -6,
            "y": 0,
            "z": 22,
            "elements": [
                "contenttweaker:arkforcefieldcontrolblock@0"
            ]
        },
        {
            "x": 4,
            "y": 0,
            "z": 24,
            "elements": [
                "contenttweaker:space_time_coil@0"
            ]
        },
        {
            "x": -6,
            "y": -1,
            "z": 23,
            "elements": [
                "contenttweaker:arkforcefieldcontrolblock@0"
            ]
        },
        {
            "x": 3,
            "y": -1,
            "z": 24,
            "elements": [
                "contenttweaker:arkforcefieldcontrolblock@0"
            ]
        },
        {
            "x": 12,
            "y": 1,
            "z": 13,
            "elements": [
                "contenttweaker:arkforcefieldcontrolblock@0"
            ]
        },
        {
            "x": 6,
            "y": -1,
            "z": 24,
            "elements": [
                "contenttweaker:arkforcefieldcontrolblock@0"
            ]
        },
        {
            "x": 9,
            "y": 0,
            "z": 6,
            "elements": [
                "contenttweaker:arkforcefieldcontrolblock@0"
            ]
        },
        {
            "x": 2,
            "y": 1,
            "z": 24,
            "elements": [
                "contenttweaker:arkforcefieldcontrolblock@0"
            ]
        },
        {
            "x": -4,
            "y": 0,
            "z": 25,
            "elements": [
                "contenttweaker:arkforcefieldcontrolblock@0"
            ]
        },
        {
            "x": -7,
            "y": -1,
            "z": 21,
            "elements": [
                "contenttweaker:arkforcefieldcontrolblock@0"
            ]
        },
        {
            "x": -12,
            "y": -1,
            "z": 16,
            "elements": [
                "contenttweaker:arkforcefieldcontrolblock@0"
            ]
        },
        {
            "x": -9,
            "y": 1,
            "z": 21,
            "elements": [
                "contenttweaker:arkforcefieldcontrolblock@0"
            ]
        },
        {
            "x": 7,
            "y": 0,
            "z": 24,
            "elements": [
                "contenttweaker:arkforcefieldcontrolblock@0"
            ]
        },
        {
            "x": 9,
            "y": 1,
            "z": 6,
            "elements": [
                "contenttweaker:arkforcefieldcontrolblock@0"
            ]
        },
        {
            "x": -3,
            "y": -1,
            "z": 23,
            "elements": [
                "contenttweaker:arkforcefieldcontrolblock@0"
            ]
        },
        {
            "x": -9,
            "y": 1,
            "z": 8,
            "elements": [
                "contenttweaker:arkforcefieldcontrolblock@0"
            ]
        },
        {
            "x": 9,
            "y": 0,
            "z": 8,
            "elements": [
                "contenttweaker:arkforcefieldcontrolblock@0"
            ]
        },
        {
            "x": -6,
            "y": 0,
            "z": 3,
            "elements": [
                "contenttweaker:space_time_coil@0"
            ]
        },
        {
            "x": -11,
            "y": 1,
            "z": 16,
            "elements": [
                "contenttweaker:arkforcefieldcontrolblock@0"
            ]
        },
        {
            "x": 11,
            "y": 0,
            "z": 12,
            "elements": [
                "contenttweaker:arkforcefieldcontrolblock@0"
            ]
        },
        {
            "x": 7,
            "y": 1,
            "z": 24,
            "elements": [
                "contenttweaker:arkforcefieldcontrolblock@0"
            ]
        },
        {
            "x": -12,
            "y": 0,
            "z": 7,
            "elements": [
                "contenttweaker:arkforcefieldcontrolblock@0"
            ]
        },
        {
            "x": -12,
            "y": 1,
            "z": 7,
            "elements": [
                "contenttweaker:arkforcefieldcontrolblock@0"
            ]
        },
        {
            "x": 13,
            "y": -1,
            "z": 12,
            "elements": [
                "contenttweaker:arkforcefieldcontrolblock@0"
            ]
        },
        {
            "x": 2,
            "y": 0,
            "z": 24,
            "elements": [
                "contenttweaker:arkforcefieldcontrolblock@0"
            ]
        },
        {
            "x": 11,
            "y": 1,
            "z": 12,
            "elements": [
                "contenttweaker:arkforcefieldcontrolblock@0"
            ]
        },
        {
            "x": 8,
            "y": 0,
            "z": 5,
            "elements": [
                "contenttweaker:arkforcefieldcontrolblock@0"
            ]
        },
        {
            "x": 8,
            "y": -1,
            "z": 6,
            "elements": [
                "contenttweaker:arkforcefieldcontrolblock@0"
            ]
        },
        {
            "x": -5,
            "y": 0,
            "z": 3,
            "elements": [
                "contenttweaker:arkforcefieldcontrolblock@0"
            ]
        },
        {
            "x": 1,
            "y": -1,
            "z": 24,
            "elements": [
                "contenttweaker:arkforcefieldcontrolblock@0"
            ]
        },
        {
            "x": -4,
            "y": 0,
            "z": 0,
            "elements": [
                "contenttweaker:arkforcefieldcontrolblock@0"
            ]
        },
        {
            "x": 11,
            "y": -1,
            "z": 14,
            "elements": [
                "contenttweaker:arkforcefieldcontrolblock@0"
            ]
        },
        {
            "x": 8,
            "y": 1,
            "z": 24,
            "elements": [
                "contenttweaker:arkforcefieldcontrolblock@0"
            ]
        },
        {
            "x": -12,
            "y": 0,
            "z": 8,
            "elements": [
                "contenttweaker:arkforcefieldcontrolblock@0"
            ]
        },
        {
            "x": -11,
            "y": 1,
            "z": 11,
            "elements": [
                "contenttweaker:arkforcefieldcontrolblock@0"
            ]
        },
        {
            "x": -10,
            "y": -1,
            "z": 16,
            "elements": [
                "contenttweaker:arkforcefieldcontrolblock@0"
            ]
        },
        {
            "x": 1,
            "y": 0,
            "z": 24,
            "elements": [
                "contenttweaker:arkforcefieldcontrolblock@0"
            ]
        },
        {
            "x": 12,
            "y": 0,
            "z": 7,
            "elements": [
                "contenttweaker:arkforcefieldcontrolblock@0"
            ]
        },
        {
            "x": -10,
            "y": 1,
            "z": 9,
            "elements": [
                "contenttweaker:arkforcefieldcontrolblock@0"
            ]
        },
        {
            "x": 12,
            "y": 1,
            "z": 7,
            "elements": [
                "contenttweaker:arkforcefieldcontrolblock@0"
            ]
        },
        {
            "x": 12,
            "y": 0,
            "z": 14,
            "elements": [
                "contenttweaker:space_time_coil@0"
            ]
        },
        {
            "x": 11,
            "y": -1,
            "z": 6,
            "elements": [
                "contenttweaker:arkforcefieldcontrolblock@0"
            ]
        },
        {
            "x": 0,
            "y": -1,
            "z": 24,
            "elements": [
                "contenttweaker:arkforcefieldcontrolblock@0"
            ]
        },
        {
            "x": -9,
            "y": -1,
            "z": 4,
            "elements": [
                "contenttweaker:arkforcefieldcontrolblock@0"
            ]
        },
        {
            "x": 11,
            "y": 1,
            "z": 13,
            "elements": [
                "contenttweaker:arkforcefieldcontrolblock@0"
            ]
        },
        {
            "x": 6,
            "y": -1,
            "z": 25,
            "elements": [
                "contenttweaker:arkforcefieldcontrolblock@0"
            ]
        },
        {
            "x": 7,
            "y": -1,
            "z": 24,
            "elements": [
                "contenttweaker:arkforcefieldcontrolblock@0"
            ]
        },
        {
            "x": 12,
            "y": 1,
            "z": 14,
            "elements": [
                "contenttweaker:arkforcefieldcontrolblock@0"
            ]
        },
        {
            "x": -9,
            "y": 0,
            "z": 8,
            "elements": [
                "contenttweaker:arkforcefieldcontrolblock@0"
            ]
        },
        {
            "x": -5,
            "y": 1,
            "z": 4,
            "elements": [
                "contenttweaker:arkforcefieldcontrolblock@0"
            ]
        },
        {
            "x": 1,
            "y": 1,
            "z": 24,
            "elements": [
                "contenttweaker:arkforcefieldcontrolblock@0"
            ]
        },
        {
            "x": 8,
            "y": -1,
            "z": 20,
            "elements": [
                "contenttweaker:arkforcefieldcontrolblock@0"
            ]
        },
        {
            "x": -10,
            "y": 0,
            "z": 22,
            "elements": [
                "contenttweaker:arkforcefieldcontrolblock@0"
            ]
        },
        {
            "x": 11,
            "y": 0,
            "z": 13,
            "elements": [
                "contenttweaker:arkforcefieldcontrolblock@0"
            ]
        },
        {
            "x": 4,
            "y": -1,
            "z": 26,
            "elements": [
                "contenttweaker:arkforcefieldcontrolblock@0"
            ]
        },
        {
            "x": 11,
            "y": -1,
            "z": 12,
            "elements": [
                "contenttweaker:arkforcefieldcontrolblock@0"
            ]
        },
        {
            "x": 8,
            "y": 0,
            "z": 24,
            "elements": [
                "contenttweaker:arkforcefieldcontrolblock@0"
            ]
        },
        {
            "x": -8,
            "y": 1,
            "z": 4,
            "elements": [
                "contenttweaker:arkforcefieldcontrolblock@0"
            ]
        },
        {
            "x": -10,
            "y": -1,
            "z": 8,
            "elements": [
                "contenttweaker:arkforcefieldcontrolblock@0"
            ]
        },
        {
            "x": -3,
            "y": 0,
            "z": 3,
            "elements": [
                "contenttweaker:arkforcefieldcontrolblock@0"
            ]
        },
        {
            "x": 11,
            "y": 1,
            "z": 18,
            "elements": [
                "contenttweaker:arkforcefieldcontrolblock@0"
            ]
        },
        {
            "x": 11,
            "y": -1,
            "z": 7,
            "elements": [
                "contenttweaker:arkforcefieldcontrolblock@0"
            ]
        },
        {
            "x": 12,
            "y": 0,
            "z": 12,
            "elements": [
                "contenttweaker:space_time_coil@0"
            ]
        },
        {
            "x": -9,
            "y": 0,
            "z": 5,
            "elements": [
                "contenttweaker:space_time_coil@0"
            ]
        },
        {
            "x": 11,
            "y": 0,
            "z": 18,
            "elements": [
                "contenttweaker:space_time_coil@0"
            ]
        },
        {
            "x": 1,
            "y": -1,
            "z": 26,
            "elements": [
                "contenttweaker:arkforcefieldcontrolblock@0"
            ]
        },
        {
            "x": -9,
            "y": 0,
            "z": 22,
            "elements": [
                "contenttweaker:arkforcefieldcontrolblock@0"
            ]
        },
        {
            "x": 11,
            "y": -1,
            "z": 20,
            "elements": [
                "contenttweaker:arkforcefieldcontrolblock@0"
            ]
        },
        {
            "x": 9,
            "y": 1,
            "z": 20,
            "elements": [
                "contenttweaker:arkforcefieldcontrolblock@0"
            ]
        },
        {
            "x": 11,
            "y": 0,
            "z": 21,
            "elements": [
                "contenttweaker:arkforcefieldcontrolblock@0"
            ]
        },
        {
            "x": 2,
            "y": 1,
            "z": 26,
            "elements": [
                "contenttweaker:arkforcefieldcontrolblock@0"
            ]
        },
        {
            "x": 12,
            "y": 1,
            "z": 12,
            "elements": [
                "contenttweaker:arkforcefieldcontrolblock@0"
            ]
        },
        {
            "x": -2,
            "y": 1,
            "z": 24,
            "elements": [
                "contenttweaker:arkforcefieldcontrolblock@0"
            ]
        },
        {
            "x": 10,
            "y": -1,
            "z": 18,
            "elements": [
                "contenttweaker:arkforcefieldcontrolblock@0"
            ]
        },
        {
            "x": 1,
            "y": 0,
            "z": 25,
            "elements": [
                "contenttweaker:space_time_coil@0"
            ]
        },
        {
            "x": -2,
            "y": 0,
            "z": 24,
            "elements": [
                "contenttweaker:arkforcefieldcontrolblock@0"
            ]
        },
        {
            "x": -12,
            "y": -1,
            "z": 11,
            "elements": [
                "contenttweaker:arkforcefieldcontrolblock@0"
            ]
        },
        {
            "x": 13,
            "y": -1,
            "z": 17,
            "elements": [
                "contenttweaker:arkforcefieldcontrolblock@0"
            ]
        },
        {
            "x": -11,
            "y": 0,
            "z": 10,
            "elements": [
                "contenttweaker:arkforcefieldcontrolblock@0"
            ]
        },
        {
            "x": -6,
            "y": -1,
            "z": 4,
            "elements": [
                "contenttweaker:arkforcefieldcontrolblock@0"
            ]
        },
        {
            "x": -7,
            "y": -1,
            "z": 2,
            "elements": [
                "contenttweaker:arkforcefieldcontrolblock@0"
            ]
        },
        {
            "x": -3,
            "y": -1,
            "z": 24,
            "elements": [
                "contenttweaker:arkforcefieldcontrolblock@0"
            ]
        },
        {
            "x": 2,
            "y": 0,
            "z": 26,
            "elements": [
                "contenttweaker:arkforcefieldcontrolblock@0"
            ]
        },
        {
            "x": -12,
            "y": 1,
            "z": 8,
            "elements": [
                "contenttweaker:arkforcefieldcontrolblock@0"
            ]
        },
        {
            "x": -8,
            "y": 0,
            "z": 23,
            "elements": [
                "contenttweaker:arkforcefieldcontrolblock@0"
            ]
        },
        {
            "x": 11,
            "y": 0,
            "z": 6,
            "elements": [
                "contenttweaker:arkforcefieldcontrolblock@0"
            ]
        },
        {
            "x": 9,
            "y": 0,
            "z": 21,
            "elements": [
                "contenttweaker:space_time_coil@0"
            ]
        },
        {
            "x": 12,
            "y": -1,
            "z": 10,
            "elements": [
                "contenttweaker:arkforcefieldcontrolblock@0"
            ]
        },
        {
            "x": 6,
            "y": -1,
            "z": 4,
            "elements": [
                "contenttweaker:arkforcefieldcontrolblock@0"
            ]
        },
        {
            "x": 7,
            "y": 0,
            "z": 4,
            "elements": [
                "contenttweaker:arkforcefieldcontrolblock@0"
            ]
        },
        {
            "x": -12,
            "y": 0,
            "z": 13,
            "elements": [
                "contenttweaker:space_time_coil@0"
            ]
        },
        {
            "x": -6,
            "y": 1,
            "z": 2,
            "elements": [
                "contenttweaker:arkforcefieldcontrolblock@0"
            ]
        },
        {
            "x": -12,
            "y": -1,
            "z": 17,
            "elements": [
                "contenttweaker:arkforcefieldcontrolblock@0"
            ]
        },
        {
            "x": -4,
            "y": -1,
            "z": 2,
            "elements": [
                "contenttweaker:arkforcefieldcontrolblock@0"
            ]
        },
        {
            "x": 9,
            "y": 1,
            "z": 21,
            "elements": [
                "contenttweaker:arkforcefieldcontrolblock@0"
            ]
        },
        {
            "x": 11,
            "y": -1,
            "z": 21,
            "elements": [
                "contenttweaker:arkforcefieldcontrolblock@0"
            ]
        },
        {
            "x": 12,
            "y": -1,
            "z": 11,
            "elements": [
                "contenttweaker:arkforcefieldcontrolblock@0"
            ]
        },
        {
            "x": 10,
            "y": 0,
            "z": 10,
            "elements": [
                "contenttweaker:arkforcefieldcontrolblock@0"
            ]
        },
        {
            "x": -4,
            "y": 1,
            "z": 24,
            "elements": [
                "contenttweaker:arkforcefieldcontrolblock@0"
            ]
        },
        {
            "x": 7,
            "y": 1,
            "z": 4,
            "elements": [
                "contenttweaker:arkforcefieldcontrolblock@0"
            ]
        },
        {
            "x": 8,
            "y": 0,
            "z": 6,
            "elements": [
                "contenttweaker:arkforcefieldcontrolblock@0"
            ]
        },
        {
            "x": -12,
            "y": 0,
            "z": 9,
            "elements": [
                "contenttweaker:arkforcefieldcontrolblock@0"
            ]
        },
        {
            "x": 11,
            "y": -1,
            "z": 10,
            "elements": [
                "contenttweaker:arkforcefieldcontrolblock@0"
            ]
        },
        {
            "x": 3,
            "y": 1,
            "z": 2,
            "elements": [
                "contenttweaker:arkforcefieldcontrolblock@0"
            ]
        },
        {
            "x": 0,
            "y": -1,
            "z": 26,
            "elements": [
                "contenttweaker:arkforcefieldcontrolblock@0"
            ]
        },
        {
            "x": 10,
            "y": 1,
            "z": 10,
            "elements": [
                "contenttweaker:arkforcefieldcontrolblock@0"
            ]
        },
        {
            "x": -5,
            "y": -1,
            "z": 24,
            "elements": [
                "contenttweaker:arkforcefieldcontrolblock@0"
            ]
        },
        {
            "x": -5,
            "y": -1,
            "z": 2,
            "elements": [
                "contenttweaker:arkforcefieldcontrolblock@0"
            ]
        },
        {
            "x": 10,
            "y": -1,
            "z": 21,
            "elements": [
                "contenttweaker:arkforcefieldcontrolblock@0"
            ]
        },
        {
            "x": -9,
            "y": 0,
            "z": 18,
            "elements": [
                "contenttweaker:arkforcefieldcontrolblock@0"
            ]
        },
        {
            "x": -11,
            "y": 1,
            "z": 17,
            "elements": [
                "contenttweaker:arkforcefieldcontrolblock@0"
            ]
        },
        {
            "x": 11,
            "y": -1,
            "z": 16,
            "elements": [
                "contenttweaker:arkforcefieldcontrolblock@0"
            ]
        },
        {
            "x": -12,
            "y": 1,
            "z": 14,
            "elements": [
                "contenttweaker:arkforcefieldcontrolblock@0"
            ]
        },
        {
            "x": -3,
            "y": -1,
            "z": 26,
            "elements": [
                "contenttweaker:arkforcefieldcontrolblock@0"
            ]
        },
        {
            "x": 2,
            "y": -1,
            "z": 2,
            "elements": [
                "contenttweaker:arkforcefieldcontrolblock@0"
            ]
        },
        {
            "x": 0,
            "y": 1,
            "z": 2,
            "elements": [
                "contenttweaker:arkforcefieldcontrolblock@0"
            ]
        },
        {
            "x": 4,
            "y": 0,
            "z": 25,
            "elements": [
                "contenttweaker:arkforcefieldcontrolblock@0"
            ]
        },
        {
            "x": 4,
            "y": -1,
            "z": 25,
            "elements": [
                "contenttweaker:arkforcefieldcontrolblock@0"
            ]
        },
        {
            "x": -2,
            "y": -1,
            "z": 24,
            "elements": [
                "contenttweaker:arkforcefieldcontrolblock@0"
            ]
        },
        {
            "x": 13,
            "y": -1,
            "z": 13,
            "elements": [
                "contenttweaker:arkforcefieldcontrolblock@0"
            ]
        },
        {
            "x": 4,
            "y": 1,
            "z": 25,
            "elements": [
                "contenttweaker:arkforcefieldcontrolblock@0"
            ]
        },
        {
            "x": 12,
            "y": 0,
            "z": 10,
            "elements": [
                "contenttweaker:space_time_coil@0"
            ]
        },
        {
            "x": 13,
            "y": 0,
            "z": 11,
            "elements": [
                "contenttweaker:arkforcefieldcontrolblock@0"
            ]
        },
        {
            "x": 5,
            "y": -1,
            "z": 2,
            "elements": [
                "contenttweaker:arkforcefieldcontrolblock@0"
            ]
        },
        {
            "x": -13,
            "y": -1,
            "z": 14,
            "elements": [
                "contenttweaker:arkforcefieldcontrolblock@0"
            ]
        },
        {
            "x": 12,
            "y": 1,
            "z": 16,
            "elements": [
                "contenttweaker:arkforcefieldcontrolblock@0"
            ]
        },
        {
            "x": -2,
            "y": 1,
            "z": 26,
            "elements": [
                "contenttweaker:arkforcefieldcontrolblock@0"
            ]
        },
        {
            "x": 5,
            "y": 0,
            "z": 25,
            "elements": [
                "contenttweaker:arkforcefieldcontrolblock@0"
            ]
        },
        {
            "x": -3,
            "y": 1,
            "z": 2,
            "elements": [
                "contenttweaker:arkforcefieldcontrolblock@0"
            ]
        },
        {
            "x": 3,
            "y": -1,
            "z": 25,
            "elements": [
                "contenttweaker:arkforcefieldcontrolblock@0"
            ]
        },
        {
            "x": 13,
            "y": 1,
            "z": 11,
            "elements": [
                "contenttweaker:arkforcefieldcontrolblock@0"
            ]
        },
        {
            "x": 1,
            "y": 1,
            "z": 26,
            "elements": [
                "contenttweaker:arkforcefieldcontrolblock@0"
            ]
        },
        {
            "x": 12,
            "y": 0,
            "z": 16,
            "elements": [
                "contenttweaker:space_time_coil@0"
            ]
        },
        {
            "x": 12,
            "y": 1,
            "z": 10,
            "elements": [
                "contenttweaker:arkforcefieldcontrolblock@0"
            ]
        },
        {
            "x": -1,
            "y": 1,
            "z": 24,
            "elements": [
                "contenttweaker:arkforcefieldcontrolblock@0"
            ]
        },
        {
            "x": 5,
            "y": 1,
            "z": 25,
            "elements": [
                "contenttweaker:arkforcefieldcontrolblock@0"
            ]
        },
        {
            "x": -12,
            "y": 1,
            "z": 16,
            "elements": [
                "contenttweaker:arkforcefieldcontrolblock@0"
            ]
        },
        {
            "x": 2,
            "y": 0,
            "z": 25,
            "elements": [
                "contenttweaker:space_time_coil@0"
            ]
        },
        {
            "x": -10,
            "y": 0,
            "z": 18,
            "elements": [
                "contenttweaker:arkforcefieldcontrolblock@0"
            ]
        },
        {
            "x": 11,
            "y": 1,
            "z": 20,
            "elements": [
                "contenttweaker:arkforcefieldcontrolblock@0"
            ]
        },
        {
            "x": 13,
            "y": 0,
            "z": 10,
            "elements": [
                "contenttweaker:arkforcefieldcontrolblock@0"
            ]
        },
        {
            "x": -2,
            "y": 1,
            "z": 2,
            "elements": [
                "contenttweaker:arkforcefieldcontrolblock@0"
            ]
        },
        {
            "x": 1,
            "y": 0,
            "z": 1,
            "elements": [
                "contenttweaker:space_time_coil@0"
            ]
        },
        {
            "x": -9,
            "y": 0,
            "z": 6,
            "elements": [
                "contenttweaker:arkforcefieldcontrolblock@0"
            ]
        },
        {
            "x": 13,
            "y": 1,
            "z": 10,
            "elements": [
                "contenttweaker:arkforcefieldcontrolblock@0"
            ]
        },
        {
            "x": -8,
            "y": -1,
            "z": 24,
            "elements": [
                "contenttweaker:arkforcefieldcontrolblock@0"
            ]
        },
        {
            "x": 0,
            "y": -1,
            "z": 2,
            "elements": [
                "contenttweaker:arkforcefieldcontrolblock@0"
            ]
        },
        {
            "x": -13,
            "y": -1,
            "z": 12,
            "elements": [
                "contenttweaker:arkforcefieldcontrolblock@0"
            ]
        },
        {
            "x": -11,
            "y": -1,
            "z": 7,
            "elements": [
                "contenttweaker:arkforcefieldcontrolblock@0"
            ]
        },
        {
            "x": -2,
            "y": -1,
            "z": 25,
            "elements": [
                "contenttweaker:arkforcefieldcontrolblock@0"
            ]
        },
        {
            "x": 7,
            "y": -1,
            "z": 21,
            "elements": [
                "contenttweaker:arkforcefieldcontrolblock@0"
            ]
        },
        {
            "x": -12,
            "y": 0,
            "z": 16,
            "elements": [
                "contenttweaker:space_time_coil@0"
            ]
        },
        {
            "x": 11,
            "y": 0,
            "z": 20,
            "elements": [
                "contenttweaker:arkforcefieldcontrolblock@0"
            ]
        },
        {
            "x": 2,
            "y": 1,
            "z": 25,
            "elements": [
                "contenttweaker:arkforcefieldcontrolblock@0"
            ]
        },
        {
            "x": 12,
            "y": 0,
            "z": 19,
            "elements": [
                "contenttweaker:arkforcefieldcontrolblock@0"
            ]
        },
        {
            "x": -1,
            "y": 0,
            "z": 25,
            "elements": [
                "contenttweaker:space_time_coil@0"
            ]
        },
        {
            "x": -9,
            "y": 0,
            "z": 23,
            "elements": [
                "contenttweaker:arkforcefieldcontrolblock@0"
            ]
        },
        {
            "x": -12,
            "y": -1,
            "z": 19,
            "elements": [
                "contenttweaker:arkforcefieldcontrolblock@0"
            ]
        },
        {
            "x": -13,
            "y": -1,
            "z": 16,
            "elements": [
                "contenttweaker:arkforcefieldcontrolblock@0"
            ]
        },
        {
            "x": 4,
            "y": 0,
            "z": 1,
            "elements": [
                "contenttweaker:arkforcefieldcontrolblock@0"
            ]
        },
        {
            "x": -10,
            "y": 1,
            "z": 7,
            "elements": [
                "contenttweaker:arkforcefieldcontrolblock@0"
            ]
        },
        {
            "x": 8,
            "y": 1,
            "z": 20,
            "elements": [
                "contenttweaker:arkforcefieldcontrolblock@0"
            ]
        },
        {
            "x": -1,
            "y": 1,
            "z": 2,
            "elements": [
                "contenttweaker:arkforcefieldcontrolblock@0"
            ]
        },
        {
            "x": -1,
            "y": 1,
            "z": 25,
            "elements": [
                "contenttweaker:arkforcefieldcontrolblock@0"
            ]
        },
        {
            "x": -1,
            "y": -1,
            "z": 2,
            "elements": [
                "contenttweaker:arkforcefieldcontrolblock@0"
            ]
        },
        {
            "x": 1,
            "y": -1,
            "z": 25,
            "elements": [
                "contenttweaker:arkforcefieldcontrolblock@0"
            ]
        },
        {
            "x": -12,
            "y": -1,
            "z": 12,
            "elements": [
                "contenttweaker:arkforcefieldcontrolblock@0"
            ]
        },
        {
            "x": 8,
            "y": 0,
            "z": 20,
            "elements": [
                "contenttweaker:arkforcefieldcontrolblock@0"
            ]
        },
        {
            "x": -7,
            "y": 1,
            "z": 24,
            "elements": [
                "contenttweaker:arkforcefieldcontrolblock@0"
            ]
        },
        {
            "x": 10,
            "y": 1,
            "z": 4,
            "elements": [
                "contenttweaker:arkforcefieldcontrolblock@0"
            ]
        },
        {
            "x": -5,
            "y": 0,
            "z": 1,
            "elements": [
                "contenttweaker:arkforcefieldcontrolblock@0"
            ]
        },
        {
            "x": -6,
            "y": 0,
            "z": 23,
            "elements": [
                "contenttweaker:space_time_coil@0"
            ]
        },
        {
            "x": -13,
            "y": -1,
            "z": 9,
            "elements": [
                "contenttweaker:arkforcefieldcontrolblock@0"
            ]
        },
        {
            "x": -2,
            "y": -1,
            "z": 2,
            "elements": [
                "contenttweaker:arkforcefieldcontrolblock@0"
            ]
        },
        {
            "x": -4,
            "y": 1,
            "z": 2,
            "elements": [
                "contenttweaker:arkforcefieldcontrolblock@0"
            ]
        },
        {
            "x": -12,
            "y": 1,
            "z": 9,
            "elements": [
                "contenttweaker:arkforcefieldcontrolblock@0"
            ]
        },
        {
            "x": -10,
            "y": -1,
            "z": 9,
            "elements": [
                "contenttweaker:arkforcefieldcontrolblock@0"
            ]
        },
        {
            "x": -10,
            "y": 1,
            "z": 17,
            "elements": [
                "contenttweaker:arkforcefieldcontrolblock@0"
            ]
        },
        {
            "x": 6,
            "y": -1,
            "z": 3,
            "elements": [
                "contenttweaker:arkforcefieldcontrolblock@0"
            ]
        },
        {
            "x": 9,
            "y": -1,
            "z": 4,
            "elements": [
                "contenttweaker:arkforcefieldcontrolblock@0"
            ]
        },
        {
            "x": 8,
            "y": 0,
            "z": 21,
            "elements": [
                "contenttweaker:arkforcefieldcontrolblock@0"
            ]
        },
        {
            "x": 1,
            "y": 1,
            "z": 2,
            "elements": [
                "contenttweaker:arkforcefieldcontrolblock@0"
            ]
        },
        {
            "x": 10,
            "y": -1,
            "z": 20,
            "elements": [
                "contenttweaker:arkforcefieldcontrolblock@0"
            ]
        },
        {
            "x": 1,
            "y": -1,
            "z": 2,
            "elements": [
                "contenttweaker:arkforcefieldcontrolblock@0"
            ]
        },
        {
            "x": 11,
            "y": 0,
            "z": 14,
            "elements": [
                "contenttweaker:arkforcefieldcontrolblock@0"
            ]
        },
        {
            "x": -10,
            "y": 0,
            "z": 6,
            "elements": [
                "contenttweaker:space_time_coil@0"
            ]
        },
        {
            "x": -11,
            "y": -1,
            "z": 17,
            "elements": [
                "contenttweaker:arkforcefieldcontrolblock@0"
            ]
        },
        {
            "x": 10,
            "y": 0,
            "z": 4,
            "elements": [
                "contenttweaker:arkforcefieldcontrolblock@0"
            ]
        },
        {
            "x": 11,
            "y": -1,
            "z": 11,
            "elements": [
                "contenttweaker:arkforcefieldcontrolblock@0"
            ]
        },
        {
            "x": 8,
            "y": -1,
            "z": 21,
            "elements": [
                "contenttweaker:arkforcefieldcontrolblock@0"
            ]
        },
        {
            "x": -12,
            "y": 1,
            "z": 12,
            "elements": [
                "contenttweaker:arkforcefieldcontrolblock@0"
            ]
        },
        {
            "x": 8,
            "y": 1,
            "z": 21,
            "elements": [
                "contenttweaker:arkforcefieldcontrolblock@0"
            ]
        },
        {
            "x": 12,
            "y": -1,
            "z": 9,
            "elements": [
                "contenttweaker:arkforcefieldcontrolblock@0"
            ]
        },
        {
            "x": -3,
            "y": 0,
            "z": 1,
            "elements": [
                "contenttweaker:space_time_coil@0"
            ]
        },
        {
            "x": -9,
            "y": 1,
            "z": 19,
            "elements": [
                "contenttweaker:arkforcefieldcontrolblock@0"
            ]
        },
        {
            "x": -9,
            "y": -1,
            "z": 19,
            "elements": [
                "contenttweaker:arkforcefieldcontrolblock@0"
            ]
        },
        {
            "x": 7,
            "y": 0,
            "z": 3,
            "elements": [
                "contenttweaker:space_time_coil@0"
            ]
        },
        {
            "x": 10,
            "y": 1,
            "z": 9,
            "elements": [
                "contenttweaker:arkforcefieldcontrolblock@0"
            ]
        },
        {
            "x": -11,
            "y": 1,
            "z": 5,
            "elements": [
                "contenttweaker:arkforcefieldcontrolblock@0"
            ]
        },
        {
            "x": 12,
            "y": 1,
            "z": 18,
            "elements": [
                "contenttweaker:arkforcefieldcontrolblock@0"
            ]
        },
        {
            "x": 13,
            "y": 0,
            "z": 9,
            "elements": [
                "contenttweaker:arkforcefieldcontrolblock@0"
            ]
        },
        {
            "x": 12,
            "y": -1,
            "z": 18,
            "elements": [
                "contenttweaker:arkforcefieldcontrolblock@0"
            ]
        },
        {
            "x": 11,
            "y": -1,
            "z": 9,
            "elements": [
                "contenttweaker:arkforcefieldcontrolblock@0"
            ]
        },
        {
            "x": -10,
            "y": 1,
            "z": 19,
            "elements": [
                "contenttweaker:arkforcefieldcontrolblock@0"
            ]
        },
        {
            "x": 3,
            "y": -1,
            "z": 2,
            "elements": [
                "contenttweaker:arkforcefieldcontrolblock@0"
            ]
        },
        {
            "x": 0,
            "y": 0,
            "z": 1,
            "elements": [
                "contenttweaker:space_time_coil@0"
            ]
        },
        {
            "x": 9,
            "y": 1,
            "z": 22,
            "elements": [
                "contenttweaker:arkforcefieldcontrolblock@0"
            ]
        },
        {
            "x": -13,
            "y": -1,
            "z": 10,
            "elements": [
                "contenttweaker:arkforcefieldcontrolblock@0"
            ]
        },
        {
            "x": -5,
            "y": 1,
            "z": 2,
            "elements": [
                "contenttweaker:arkforcefieldcontrolblock@0"
            ]
        },
        {
            "x": 13,
            "y": 0,
            "z": 17,
            "elements": [
                "contenttweaker:arkforcefieldcontrolblock@0"
            ]
        },
        {
            "x": 9,
            "y": 0,
            "z": 22,
            "elements": [
                "contenttweaker:arkforcefieldcontrolblock@0"
            ]
        },
        {
            "x": 12,
            "y": 0,
            "z": 9,
            "elements": [
                "contenttweaker:arkforcefieldcontrolblock@0"
            ]
        },
        {
            "x": 7,
            "y": 1,
            "z": 3,
            "elements": [
                "contenttweaker:arkforcefieldcontrolblock@0"
            ]
        },
        {
            "x": -1,
            "y": 0,
            "z": 1,
            "elements": [
                "contenttweaker:space_time_coil@0"
            ]
        },
        {
            "x": -11,
            "y": 1,
            "z": 19,
            "elements": [
                "contenttweaker:arkforcefieldcontrolblock@0"
            ]
        },
        {
            "x": -11,
            "y": -1,
            "z": 19,
            "elements": [
                "contenttweaker:arkforcefieldcontrolblock@0"
            ]
        },
        {
            "x": 8,
            "y": -1,
            "z": 22,
            "elements": [
                "contenttweaker:arkforcefieldcontrolblock@0"
            ]
        },
        {
            "x": -12,
            "y": 0,
            "z": 10,
            "elements": [
                "contenttweaker:space_time_coil@0"
            ]
        },
        {
            "x": -9,
            "y": 1,
            "z": 7,
            "elements": [
                "contenttweaker:arkforcefieldcontrolblock@0"
            ]
        },
        {
            "x": 6,
            "y": 1,
            "z": 22,
            "elements": [
                "contenttweaker:arkforcefieldcontrolblock@0"
            ]
        },
        {
            "x": -8,
            "y": 1,
            "z": 2,
            "elements": [
                "contenttweaker:arkforcefieldcontrolblock@0"
            ]
        },
        {
            "x": -6,
            "y": -1,
            "z": 2,
            "elements": [
                "contenttweaker:arkforcefieldcontrolblock@0"
            ]
        },
        {
            "x": 5,
            "y": -1,
            "z": 22,
            "elements": [
                "contenttweaker:arkforcefieldcontrolblock@0"
            ]
        },
        {
            "x": -12,
            "y": 1,
            "z": 10,
            "elements": [
                "contenttweaker:arkforcefieldcontrolblock@0"
            ]
        },
        {
            "x": 6,
            "y": 0,
            "z": 22,
            "elements": [
                "contenttweaker:arkforcefieldcontrolblock@0"
            ]
        },
        {
            "x": -11,
            "y": 1,
            "z": 12,
            "elements": [
                "contenttweaker:arkforcefieldcontrolblock@0"
            ]
        },
        {
            "x": 10,
            "y": 0,
            "z": 17,
            "elements": [
                "contenttweaker:arkforcefieldcontrolblock@0"
            ]
        },
        {
            "x": -10,
            "y": -1,
            "z": 10,
            "elements": [
                "contenttweaker:arkforcefieldcontrolblock@0"
            ]
        },
        {
            "x": -8,
            "y": 0,
            "z": 5,
            "elements": [
                "contenttweaker:arkforcefieldcontrolblock@0"
            ]
        },
        {
            "x": -2,
            "y": 0,
            "z": 1,
            "elements": [
                "contenttweaker:space_time_coil@0"
            ]
        },
        {
            "x": -10,
            "y": -1,
            "z": 7,
            "elements": [
                "contenttweaker:arkforcefieldcontrolblock@0"
            ]
        },
        {
            "x": 13,
            "y": 1,
            "z": 9,
            "elements": [
                "contenttweaker:arkforcefieldcontrolblock@0"
            ]
        },
        {
            "x": -9,
            "y": -1,
            "z": 5,
            "elements": [
                "contenttweaker:arkforcefieldcontrolblock@0"
            ]
        },
        {
            "x": -3,
            "y": -1,
            "z": 2,
            "elements": [
                "contenttweaker:arkforcefieldcontrolblock@0"
            ]
        },
        {
            "x": -11,
            "y": 0,
            "z": 13,
            "elements": [
                "contenttweaker:arkforcefieldcontrolblock@0"
            ]
        },
        {
            "x": -8,
            "y": 1,
            "z": 5,
            "elements": [
                "contenttweaker:arkforcefieldcontrolblock@0"
            ]
        },
        {
            "x": -4,
            "y": 0,
            "z": 23,
            "elements": [
                "contenttweaker:arkforcefieldcontrolblock@0"
            ]
        },
        {
            "x": 9,
            "y": -1,
            "z": 3,
            "elements": [
                "contenttweaker:arkforcefieldcontrolblock@0"
            ]
        },
        {
            "x": -11,
            "y": 0,
            "z": 5,
            "elements": [
                "contenttweaker:arkforcefieldcontrolblock@0"
            ]
        },
        {
            "x": 9,
            "y": -1,
            "z": 5,
            "elements": [
                "contenttweaker:arkforcefieldcontrolblock@0"
            ]
        },
        {
            "x": 6,
            "y": 1,
            "z": 2,
            "elements": [
                "contenttweaker:arkforcefieldcontrolblock@0"
            ]
        },
        {
            "x": 8,
            "y": -1,
            "z": 2,
            "elements": [
                "contenttweaker:arkforcefieldcontrolblock@0"
            ]
        },
        {
            "x": -8,
            "y": 1,
            "z": 24,
            "elements": [
                "contenttweaker:arkforcefieldcontrolblock@0"
            ]
        },
        {
            "x": -4,
            "y": 0,
            "z": 1,
            "elements": [
                "contenttweaker:arkforcefieldcontrolblock@0"
            ]
        },
        {
            "x": 10,
            "y": 1,
            "z": 5,
            "elements": [
                "contenttweaker:arkforcefieldcontrolblock@0"
            ]
        },
        {
            "x": -11,
            "y": -1,
            "z": 20,
            "elements": [
                "contenttweaker:arkforcefieldcontrolblock@0"
            ]
        },
        {
            "x": 7,
            "y": 1,
            "z": 2,
            "elements": [
                "contenttweaker:arkforcefieldcontrolblock@0"
            ]
        },
        {
            "x": -11,
            "y": -1,
            "z": 14,
            "elements": [
                "contenttweaker:arkforcefieldcontrolblock@0"
            ]
        },
        {
            "x": 5,
            "y": 1,
            "z": 22,
            "elements": [
                "contenttweaker:arkforcefieldcontrolblock@0"
            ]
        },
        {
            "x": 10,
            "y": 0,
            "z": 5,
            "elements": [
                "contenttweaker:arkforcefieldcontrolblock@0"
            ]
        },
        {
            "x": -8,
            "y": -1,
            "z": 20,
            "elements": [
                "contenttweaker:arkforcefieldcontrolblock@0"
            ]
        },
        {
            "x": 5,
            "y": 0,
            "z": 22,
            "elements": [
                "contenttweaker:arkforcefieldcontrolblock@0"
            ]
        },
        {
            "x": 11,
            "y": -1,
            "z": 15,
            "elements": [
                "contenttweaker:arkforcefieldcontrolblock@0"
            ]
        },
        {
            "x": 7,
            "y": 1,
            "z": 5,
            "elements": [
                "contenttweaker:arkforcefieldcontrolblock@0"
            ]
        },
        {
            "x": 8,
            "y": 1,
            "z": 23,
            "elements": [
                "contenttweaker:arkforcefieldcontrolblock@0"
            ]
        },
        {
            "x": -10,
            "y": 0,
            "z": 8,
            "elements": [
                "contenttweaker:arkforcefieldcontrolblock@0"
            ]
        },
        {
            "x": 6,
            "y": -1,
            "z": 2,
            "elements": [
                "contenttweaker:arkforcefieldcontrolblock@0"
            ]
        },
        {
            "x": 4,
            "y": 1,
            "z": 2,
            "elements": [
                "contenttweaker:arkforcefieldcontrolblock@0"
            ]
        },
        {
            "x": 12,
            "y": 1,
            "z": 9,
            "elements": [
                "contenttweaker:arkforcefieldcontrolblock@0"
            ]
        },
        {
            "x": 3,
            "y": 0,
            "z": 1,
            "elements": [
                "contenttweaker:space_time_coil@0"
            ]
        },
        {
            "x": -13,
            "y": -1,
            "z": 11,
            "elements": [
                "contenttweaker:arkforcefieldcontrolblock@0"
            ]
        },
        {
            "x": 7,
            "y": 0,
            "z": 5,
            "elements": [
                "contenttweaker:arkforcefieldcontrolblock@0"
            ]
        },
        {
            "x": -6,
            "y": -1,
            "z": 24,
            "elements": [
                "contenttweaker:arkforcefieldcontrolblock@0"
            ]
        },
        {
            "x": 7,
            "y": -1,
            "z": 23,
            "elements": [
                "contenttweaker:arkforcefieldcontrolblock@0"
            ]
        },
        {
            "x": -11,
            "y": 0,
            "z": 18,
            "elements": [
                "contenttweaker:space_time_coil@0"
            ]
        },
        {
            "x": -12,
            "y": 1,
            "z": 19,
            "elements": [
                "contenttweaker:arkforcefieldcontrolblock@0"
            ]
        },
        {
            "x": -7,
            "y": 0,
            "z": 23,
            "elements": [
                "contenttweaker:space_time_coil@0"
            ]
        },
        {
            "x": 12,
            "y": 1,
            "z": 15,
            "elements": [
                "contenttweaker:arkforcefieldcontrolblock@0"
            ]
        },
        {
            "x": 7,
            "y": -1,
            "z": 22,
            "elements": [
                "contenttweaker:arkforcefieldcontrolblock@0"
            ]
        },
        {
            "x": -10,
            "y": -1,
            "z": 19,
            "elements": [
                "contenttweaker:arkforcefieldcontrolblock@0"
            ]
        },
        {
            "x": 2,
            "y": 0,
            "z": 1,
            "elements": [
                "contenttweaker:space_time_coil@0"
            ]
        },
        {
            "x": -13,
            "y": 1,
            "z": 14,
            "elements": [
                "contenttweaker:arkforcefieldcontrolblock@0"
            ]
        },
        {
            "x": -13,
            "y": 1,
            "z": 17,
            "elements": [
                "contenttweaker:arkforcefieldcontrolblock@0"
            ]
        },
        {
            "x": 12,
            "y": 0,
            "z": 15,
            "elements": [
                "contenttweaker:space_time_coil@0"
            ]
        },
        {
            "x": -5,
            "y": 1,
            "z": 24,
            "elements": [
                "contenttweaker:arkforcefieldcontrolblock@0"
            ]
        },
        {
            "x": -9,
            "y": -1,
            "z": 6,
            "elements": [
                "contenttweaker:arkforcefieldcontrolblock@0"
            ]
        },
        {
            "x": 6,
            "y": 1,
            "z": 23,
            "elements": [
                "contenttweaker:arkforcefieldcontrolblock@0"
            ]
        },
        {
            "x": 5,
            "y": 1,
            "z": 1,
            "elements": [
                "contenttweaker:arkforcefieldcontrolblock@0"
            ]
        },
        {
            "x": -10,
            "y": -1,
            "z": 20,
            "elements": [
                "contenttweaker:arkforcefieldcontrolblock@0"
            ]
        },
        {
            "x": -11,
            "y": 0,
            "z": 9,
            "elements": [
                "contenttweaker:space_time_coil@0"
            ]
        },
        {
            "x": 12,
            "y": 1,
            "z": 17,
            "elements": [
                "contenttweaker:arkforcefieldcontrolblock@0"
            ]
        },
        {
            "x": -3,
            "y": 0,
            "z": 24,
            "elements": [
                "contenttweaker:arkforcefieldcontrolblock@0"
            ]
        },
        {
            "x": 5,
            "y": 0,
            "z": 1,
            "elements": [
                "contenttweaker:arkforcefieldcontrolblock@0"
            ]
        },
        {
            "x": 10,
            "y": -1,
            "z": 8,
            "elements": [
                "contenttweaker:arkforcefieldcontrolblock@0"
            ]
        },
        {
            "x": -1,
            "y": 1,
            "z": 0,
            "elements": [
                "contenttweaker:arkforcefieldcontrolblock@0"
            ]
        },
        {
            "x": 0,
            "y": -1,
            "z": 0,
            "elements": [
                "contenttweaker:arkforcefieldcontrolblock@0"
            ]
        },
        {
            "x": -4,
            "y": -1,
            "z": 24,
            "elements": [
                "contenttweaker:arkforcefieldcontrolblock@0"
            ]
        },
        {
            "x": 12,
            "y": 0,
            "z": 17,
            "elements": [
                "contenttweaker:arkforcefieldcontrolblock@0"
            ]
        },
        {
            "x": 8,
            "y": 0,
            "z": 22,
            "elements": [
                "contenttweaker:space_time_coil@0"
            ]
        },
        {
            "x": -9,
            "y": 1,
            "z": 20,
            "elements": [
                "contenttweaker:arkforcefieldcontrolblock@0"
            ]
        },
        {
            "x": 11,
            "y": 0,
            "z": 8,
            "elements": [
                "contenttweaker:space_time_coil@0"
            ]
        },
        {
            "x": -7,
            "y": 0,
            "z": 21,
            "elements": [
                "contenttweaker:arkforcefieldcontrolblock@0"
            ]
        },
        {
            "x": 3,
            "y": 0,
            "z": 23,
            "elements": [
                "contenttweaker:arkforcefieldcontrolblock@0"
            ]
        },
        {
            "x": 3,
            "y": 1,
            "z": 23,
            "elements": [
                "contenttweaker:arkforcefieldcontrolblock@0"
            ]
        },
        {
            "x": 13,
            "y": 0,
            "z": 12,
            "elements": [
                "contenttweaker:arkforcefieldcontrolblock@0"
            ]
        },
        {
            "x": 8,
            "y": -1,
            "z": 3,
            "elements": [
                "contenttweaker:arkforcefieldcontrolblock@0"
            ]
        },
        {
            "x": -8,
            "y": 1,
            "z": 6,
            "elements": [
                "contenttweaker:arkforcefieldcontrolblock@0"
            ]
        },
        {
            "x": -2,
            "y": 1,
            "z": 0,
            "elements": [
                "contenttweaker:arkforcefieldcontrolblock@0"
            ]
        },
        {
            "x": 11,
            "y": -1,
            "z": 17,
            "elements": [
                "contenttweaker:arkforcefieldcontrolblock@0"
            ]
        },
        {
            "x": 10,
            "y": 0,
            "z": 18,
            "elements": [
                "contenttweaker:arkforcefieldcontrolblock@0"
            ]
        },
        {
            "x": 5,
            "y": -1,
            "z": 23,
            "elements": [
                "contenttweaker:arkforcefieldcontrolblock@0"
            ]
        },
        {
            "x": 1,
            "y": -1,
            "z": 0,
            "elements": [
                "contenttweaker:arkforcefieldcontrolblock@0"
            ]
        },
        {
            "x": 6,
            "y": 0,
            "z": 23,
            "elements": [
                "contenttweaker:space_time_coil@0"
            ]
        },
        {
            "x": -8,
            "y": 0,
            "z": 6,
            "elements": [
                "contenttweaker:arkforcefieldcontrolblock@0"
            ]
        },
        {
            "x": 13,
            "y": 1,
            "z": 12,
            "elements": [
                "contenttweaker:arkforcefieldcontrolblock@0"
            ]
        },
        {
            "x": -13,
            "y": 0,
            "z": 16,
            "elements": [
                "contenttweaker:arkforcefieldcontrolblock@0"
            ]
        },
        {
            "x": -3,
            "y": 1,
            "z": 24,
            "elements": [
                "contenttweaker:arkforcefieldcontrolblock@0"
            ]
        },
        {
            "x": 9,
            "y": -1,
            "z": 18,
            "elements": [
                "contenttweaker:arkforcefieldcontrolblock@0"
            ]
        },
        {
            "x": -12,
            "y": 0,
            "z": 11,
            "elements": [
                "contenttweaker:space_time_coil@0"
            ]
        },
        {
            "x": 3,
            "y": 1,
            "z": 3,
            "elements": [
                "contenttweaker:arkforcefieldcontrolblock@0"
            ]
        },
        {
            "x": 13,
            "y": 1,
            "z": 16,
            "elements": [
                "contenttweaker:arkforcefieldcontrolblock@0"
            ]
        },
        {
            "x": 1,
            "y": 1,
            "z": 0,
            "elements": [
                "contenttweaker:arkforcefieldcontrolblock@0"
            ]
        },
        {
            "x": -2,
            "y": -1,
            "z": 0,
            "elements": [
                "contenttweaker:arkforcefieldcontrolblock@0"
            ]
        },
        {
            "x": -11,
            "y": 1,
            "z": 20,
            "elements": [
                "contenttweaker:arkforcefieldcontrolblock@0"
            ]
        },
        {
            "x": 13,
            "y": 1,
            "z": 13,
            "elements": [
                "contenttweaker:arkforcefieldcontrolblock@0"
            ]
        },
        {
            "x": -10,
            "y": 0,
            "z": 16,
            "elements": [
                "contenttweaker:arkforcefieldcontrolblock@0"
            ]
        },
        {
            "x": -6,
            "y": 1,
            "z": 24,
            "elements": [
                "contenttweaker:arkforcefieldcontrolblock@0"
            ]
        },
        {
            "x": -9,
            "y": 0,
            "z": 4,
            "elements": [
                "contenttweaker:arkforcefieldcontrolblock@0"
            ]
        },
        {
            "x": 12,
            "y": -1,
            "z": 16,
            "elements": [
                "contenttweaker:arkforcefieldcontrolblock@0"
            ]
        },
        {
            "x": -10,
            "y": 0,
            "z": 9,
            "elements": [
                "contenttweaker:arkforcefieldcontrolblock@0"
            ]
        },
        {
            "x": -6,
            "y": 0,
            "z": 24,
            "elements": [
                "contenttweaker:arkforcefieldcontrolblock@0"
            ]
        },
        {
            "x": -9,
            "y": -1,
            "z": 20,
            "elements": [
                "contenttweaker:arkforcefieldcontrolblock@0"
            ]
        },
        {
            "x": 13,
            "y": 0,
            "z": 13,
            "elements": [
                "contenttweaker:arkforcefieldcontrolblock@0"
            ]
        },
        {
            "x": -7,
            "y": -1,
            "z": 24,
            "elements": [
                "contenttweaker:arkforcefieldcontrolblock@0"
            ]
        },
        {
            "x": -13,
            "y": 0,
            "z": 9,
            "elements": [
                "contenttweaker:arkforcefieldcontrolblock@0"
            ]
        },
        {
            "x": -10,
            "y": 1,
            "z": 20,
            "elements": [
                "contenttweaker:arkforcefieldcontrolblock@0"
            ]
        },
        {
            "x": 9,
            "y": 1,
            "z": 3,
            "elements": [
                "contenttweaker:arkforcefieldcontrolblock@0"
            ]
        },
        {
            "x": 12,
            "y": -1,
            "z": 13,
            "elements": [
                "contenttweaker:arkforcefieldcontrolblock@0"
            ]
        },
        {
            "x": 6,
            "y": 0,
            "z": 4,
            "elements": [
                "contenttweaker:arkforcefieldcontrolblock@0"
            ]
        },
        {
            "x": 8,
            "y": -1,
            "z": 24,
            "elements": [
                "contenttweaker:arkforcefieldcontrolblock@0"
            ]
        },
        {
            "x": -3,
            "y": 1,
            "z": 26,
            "elements": [
                "contenttweaker:arkforcefieldcontrolblock@0"
            ]
        },
        {
            "x": -12,
            "y": -1,
            "z": 14,
            "elements": [
                "contenttweaker:arkforcefieldcontrolblock@0"
            ]
        },
        {
            "x": -11,
            "y": 1,
            "z": 7,
            "elements": [
                "contenttweaker:arkforcefieldcontrolblock@0"
            ]
        },
        {
            "x": -4,
            "y": 1,
            "z": 0,
            "elements": [
                "contenttweaker:arkforcefieldcontrolblock@0"
            ]
        },
        {
            "x": 3,
            "y": -1,
            "z": 0,
            "elements": [
                "contenttweaker:arkforcefieldcontrolblock@0"
            ]
        },
        {
            "x": 9,
            "y": 0,
            "z": 18,
            "elements": [
                "contenttweaker:arkforcefieldcontrolblock@0"
            ]
        },
        {
            "x": -9,
            "y": -1,
            "z": 3,
            "elements": [
                "contenttweaker:arkforcefieldcontrolblock@0"
            ]
        },
        {
            "x": -7,
            "y": 1,
            "z": 5,
            "elements": [
                "contenttweaker:arkforcefieldcontrolblock@0"
            ]
        },
        {
            "x": -11,
            "y": 0,
            "z": 7,
            "elements": [
                "contenttweaker:arkforcefieldcontrolblock@0"
            ]
        },
        {
            "x": 0,
            "y": 1,
            "z": 24,
            "elements": [
                "contenttweaker:arkforcefieldcontrolblock@0"
            ]
        },
        {
            "x": -11,
            "y": 0,
            "z": 21,
            "elements": [
                "contenttweaker:arkforcefieldcontrolblock@0"
            ]
        },
        {
            "x": -10,
            "y": 1,
            "z": 10,
            "elements": [
                "contenttweaker:arkforcefieldcontrolblock@0"
            ]
        },
        {
            "x": -11,
            "y": 0,
            "z": 14,
            "elements": [
                "contenttweaker:arkforcefieldcontrolblock@0"
            ]
        },
        {
            "x": -12,
            "y": 1,
            "z": 15,
            "elements": [
                "contenttweaker:arkforcefieldcontrolblock@0"
            ]
        },
        {
            "x": -3,
            "y": 0,
            "z": 26,
            "elements": [
                "contenttweaker:arkforcefieldcontrolblock@0"
            ]
        },
        {
            "x": -4,
            "y": -1,
            "z": 26,
            "elements": [
                "contenttweaker:arkforcefieldcontrolblock@0"
            ]
        },
        {
            "x": -8,
            "y": 1,
            "z": 3,
            "elements": [
                "contenttweaker:arkforcefieldcontrolblock@0"
            ]
        },
        {
            "x": 9,
            "y": -1,
            "z": 8,
            "elements": [
                "contenttweaker:arkforcefieldcontrolblock@0"
            ]
        },
        {
            "x": 0,
            "y": 0,
            "z": 24,
            "elements": [
                "contenttweaker:arkforcefieldcontrolblock@0"
            ]
        },
        {
            "x": 4,
            "y": -1,
            "z": 0,
            "elements": [
                "contenttweaker:arkforcefieldcontrolblock@0"
            ]
        },
        {
            "x": -11,
            "y": 1,
            "z": 14,
            "elements": [
                "contenttweaker:arkforcefieldcontrolblock@0"
            ]
        },
        {
            "x": -8,
            "y": -1,
            "z": 5,
            "elements": [
                "contenttweaker:arkforcefieldcontrolblock@0"
            ]
        },
        {
            "x": 2,
            "y": 1,
            "z": 0,
            "elements": [
                "contenttweaker:arkforcefieldcontrolblock@0"
            ]
        },
        {
            "x": -3,
            "y": -1,
            "z": 0,
            "elements": [
                "contenttweaker:arkforcefieldcontrolblock@0"
            ]
        },
        {
            "x": -12,
            "y": -1,
            "z": 7,
            "elements": [
                "contenttweaker:arkforcefieldcontrolblock@0"
            ]
        },
        {
            "x": -13,
            "y": -1,
            "z": 15,
            "elements": [
                "contenttweaker:arkforcefieldcontrolblock@0"
            ]
        },
        {
            "x": -1,
            "y": -1,
            "z": 24,
            "elements": [
                "contenttweaker:arkforcefieldcontrolblock@0"
            ]
        },
        {
            "x": -10,
            "y": 0,
            "z": 21,
            "elements": [
                "contenttweaker:arkforcefieldcontrolblock@0"
            ]
        },
        {
            "x": 10,
            "y": 0,
            "z": 8,
            "elements": [
                "contenttweaker:arkforcefieldcontrolblock@0"
            ]
        },
        {
            "x": -8,
            "y": 1,
            "z": 20,
            "elements": [
                "contenttweaker:arkforcefieldcontrolblock@0"
            ]
        },
        {
            "x": 5,
            "y": -1,
            "z": 3,
            "elements": [
                "contenttweaker:arkforcefieldcontrolblock@0"
            ]
        },
        {
            "x": -11,
            "y": 1,
            "z": 6,
            "elements": [
                "contenttweaker:arkforcefieldcontrolblock@0"
            ]
        },
        {
            "x": 6,
            "y": 1,
            "z": 24,
            "elements": [
                "contenttweaker:arkforcefieldcontrolblock@0"
            ]
        },
        {
            "x": -6,
            "y": 0,
            "z": 4,
            "elements": [
                "contenttweaker:arkforcefieldcontrolblock@0"
            ]
        },
        {
            "x": -9,
            "y": -1,
            "z": 7,
            "elements": [
                "contenttweaker:arkforcefieldcontrolblock@0"
            ]
        },
        {
            "x": -9,
            "y": 1,
            "z": 3,
            "elements": [
                "contenttweaker:arkforcefieldcontrolblock@0"
            ]
        },
        {
            "x": 12,
            "y": -1,
            "z": 8,
            "elements": [
                "contenttweaker:arkforcefieldcontrolblock@0"
            ]
        },
        {
            "x": 3,
            "y": 0,
            "z": 24,
            "elements": [
                "contenttweaker:arkforcefieldcontrolblock@0"
            ]
        },
        {
            "x": -11,
            "y": 0,
            "z": 6,
            "elements": [
                "contenttweaker:arkforcefieldcontrolblock@0"
            ]
        },
        {
            "x": 9,
            "y": 0,
            "z": 4,
            "elements": [
                "contenttweaker:arkforcefieldcontrolblock@0"
            ]
        },
        {
            "x": 10,
            "y": 1,
            "z": 8,
            "elements": [
                "contenttweaker:arkforcefieldcontrolblock@0"
            ]
        },
        {
            "x": 10,
            "y": 1,
            "z": 18,
            "elements": [
                "contenttweaker:arkforcefieldcontrolblock@0"
            ]
        },
        {
            "x": 2,
            "y": -1,
            "z": 24,
            "elements": [
                "contenttweaker:arkforcefieldcontrolblock@0"
            ]
        },
        {
            "x": 6,
            "y": 1,
            "z": 3,
            "elements": [
                "contenttweaker:arkforcefieldcontrolblock@0"
            ]
        },
        {
            "x": 3,
            "y": 1,
            "z": 24,
            "elements": [
                "contenttweaker:arkforcefieldcontrolblock@0"
            ]
        },
        {
            "x": 12,
            "y": 0,
            "z": 18,
            "elements": [
                "contenttweaker:arkforcefieldcontrolblock@0"
            ]
        },
        {
            "x": 10,
            "y": 0,
            "z": 9,
            "elements": [
                "contenttweaker:arkforcefieldcontrolblock@0"
            ]
        },
        {
            "x": 6,
            "y": 0,
            "z": 24,
            "elements": [
                "contenttweaker:arkforcefieldcontrolblock@0"
            ]
        },
        {
            "x": 11,
            "y": 1,
            "z": 8,
            "elements": [
                "contenttweaker:arkforcefieldcontrolblock@0"
            ]
        },
        {
            "x": 9,
            "y": 1,
            "z": 18,
            "elements": [
                "contenttweaker:arkforcefieldcontrolblock@0"
            ]
        },
        {
            "x": -8,
            "y": 0,
            "z": 21,
            "elements": [
                "contenttweaker:arkforcefieldcontrolblock@0"
            ]
        },
        {
            "x": -11,
            "y": -1,
            "z": 10,
            "elements": [
                "contenttweaker:arkforcefieldcontrolblock@0"
            ]
        },
        {
            "x": 11,
            "y": -1,
            "z": 18,
            "elements": [
                "contenttweaker:arkforcefieldcontrolblock@0"
            ]
        },
        {
            "x": 5,
            "y": -1,
            "z": 24,
            "elements": [
                "contenttweaker:arkforcefieldcontrolblock@0"
            ]
        },
        {
            "x": -12,
            "y": 0,
            "z": 17,
            "elements": [
                "contenttweaker:arkforcefieldcontrolblock@0"
            ]
        },
        {
            "x": 3,
            "y": -1,
            "z": 3,
            "elements": [
                "contenttweaker:arkforcefieldcontrolblock@0"
            ]
        },
        {
            "x": 2,
            "y": 1,
            "z": 2,
            "elements": [
                "contenttweaker:arkforcefieldcontrolblock@0"
            ]
        },
        {
            "x": -6,
            "y": -1,
            "z": 25,
            "elements": [
                "contenttweaker:arkforcefieldcontrolblock@0"
            ]
        },
        {
            "x": -10,
            "y": -1,
            "z": 5,
            "elements": [
                "contenttweaker:arkforcefieldcontrolblock@0"
            ]
        },
        {
            "x": -1,
            "y": -1,
            "z": 26,
            "elements": [
                "contenttweaker:arkforcefieldcontrolblock@0"
            ]
        },
        {
            "x": 4,
            "y": -1,
            "z": 2,
            "elements": [
                "contenttweaker:arkforcefieldcontrolblock@0"
            ]
        },
        {
            "x": 12,
            "y": 1,
            "z": 11,
            "elements": [
                "contenttweaker:arkforcefieldcontrolblock@0"
            ]
        },
        {
            "x": -12,
            "y": 1,
            "z": 17,
            "elements": [
                "contenttweaker:arkforcefieldcontrolblock@0"
            ]
        },
        {
            "x": -12,
            "y": -1,
            "z": 10,
            "elements": [
                "contenttweaker:arkforcefieldcontrolblock@0"
            ]
        },
        {
            "x": -2,
            "y": 1,
            "z": 25,
            "elements": [
                "contenttweaker:arkforcefieldcontrolblock@0"
            ]
        },
        {
            "x": 0,
            "y": 1,
            "z": 26,
            "elements": [
                "contenttweaker:arkforcefieldcontrolblock@0"
            ]
        },
        {
            "x": 4,
            "y": 1,
            "z": 3,
            "elements": [
                "contenttweaker:arkforcefieldcontrolblock@0"
            ]
        },
        {
            "x": -5,
            "y": -1,
            "z": 22,
            "elements": [
                "contenttweaker:arkforcefieldcontrolblock@0"
            ]
        },
        {
            "x": -7,
            "y": 1,
            "z": 22,
            "elements": [
                "contenttweaker:arkforcefieldcontrolblock@0"
            ]
        },
        {
            "x": 2,
            "y": 0,
            "z": 2,
            "elements": [
                "contenttweaker:arkforcefieldcontrolblock@0"
            ]
        },
        {
            "x": -6,
            "y": 1,
            "z": 22,
            "elements": [
                "contenttweaker:arkforcefieldcontrolblock@0"
            ]
        },
        {
            "x": -13,
            "y": -1,
            "z": 17,
            "elements": [
                "contenttweaker:arkforcefieldcontrolblock@0"
            ]
        },
        {
            "x": -5,
            "y": 1,
            "z": 25,
            "elements": [
                "contenttweaker:arkforcefieldcontrolblock@0"
            ]
        },
        {
            "x": -3,
            "y": -1,
            "z": 25,
            "elements": [
                "contenttweaker:arkforcefieldcontrolblock@0"
            ]
        },
        {
            "x": 0,
            "y": 0,
            "z": 26,
            "elements": [
                "contenttweaker:arkforcefieldcontrolblock@0"
            ]
        },
        {
            "x": -13,
            "y": 1,
            "z": 15,
            "elements": [
                "contenttweaker:arkforcefieldcontrolblock@0"
            ]
        },
        {
            "x": 8,
            "y": 1,
            "z": 2,
            "elements": [
                "contenttweaker:arkforcefieldcontrolblock@0"
            ]
        },
        {
            "x": 9,
            "y": 0,
            "z": 19,
            "elements": [
                "contenttweaker:arkforcefieldcontrolblock@0"
            ]
        },
        {
            "x": -5,
            "y": 1,
            "z": 3,
            "elements": [
                "contenttweaker:arkforcefieldcontrolblock@0"
            ]
        },
        {
            "x": -7,
            "y": -1,
            "z": 3,
            "elements": [
                "contenttweaker:arkforcefieldcontrolblock@0"
            ]
        },
        {
            "x": 10,
            "y": 0,
            "z": 7,
            "elements": [
                "contenttweaker:space_time_coil@0"
            ]
        },
        {
            "x": 10,
            "y": 1,
            "z": 7,
            "elements": [
                "contenttweaker:arkforcefieldcontrolblock@0"
            ]
        },
        {
            "x": 9,
            "y": -1,
            "z": 6,
            "elements": [
                "contenttweaker:arkforcefieldcontrolblock@0"
            ]
        },
        {
            "x": -4,
            "y": 1,
            "z": 25,
            "elements": [
                "contenttweaker:arkforcefieldcontrolblock@0"
            ]
        },
        {
            "x": -10,
            "y": -1,
            "z": 17,
            "elements": [
                "contenttweaker:arkforcefieldcontrolblock@0"
            ]
        },
        {
            "x": 8,
            "y": 0,
            "z": 2,
            "elements": [
                "contenttweaker:arkforcefieldcontrolblock@0"
            ]
        },
        {
            "x": -9,
            "y": 0,
            "z": 21,
            "elements": [
                "contenttweaker:space_time_coil@0"
            ]
        },
        {
            "x": -3,
            "y": 0,
            "z": 23,
            "elements": [
                "contenttweaker:arkforcefieldcontrolblock@0"
            ]
        },
        {
            "x": 7,
            "y": -1,
            "z": 5,
            "elements": [
                "contenttweaker:arkforcefieldcontrolblock@0"
            ]
        },
        {
            "x": 10,
            "y": 0,
            "z": 6,
            "elements": [
                "contenttweaker:space_time_coil@0"
            ]
        },
        {
            "x": 5,
            "y": 1,
            "z": 2,
            "elements": [
                "contenttweaker:arkforcefieldcontrolblock@0"
            ]
        },
        {
            "x": 8,
            "y": 1,
            "z": 5,
            "elements": [
                "contenttweaker:arkforcefieldcontrolblock@0"
            ]
        },
        {
            "x": -5,
            "y": -1,
            "z": 25,
            "elements": [
                "contenttweaker:arkforcefieldcontrolblock@0"
            ]
        },
        {
            "x": 2,
            "y": -1,
            "z": 26,
            "elements": [
                "contenttweaker:arkforcefieldcontrolblock@0"
            ]
        },
        {
            "x": -6,
            "y": 1,
            "z": 3,
            "elements": [
                "contenttweaker:arkforcefieldcontrolblock@0"
            ]
        },
        {
            "x": -3,
            "y": 1,
            "z": 23,
            "elements": [
                "contenttweaker:arkforcefieldcontrolblock@0"
            ]
        },
        {
            "x": -6,
            "y": -1,
            "z": 3,
            "elements": [
                "contenttweaker:arkforcefieldcontrolblock@0"
            ]
        },
        {
            "x": 10,
            "y": 1,
            "z": 6,
            "elements": [
                "contenttweaker:arkforcefieldcontrolblock@0"
            ]
        },
        {
            "x": 4,
            "y": 1,
            "z": 0,
            "elements": [
                "contenttweaker:arkforcefieldcontrolblock@0"
            ]
        },
        {
            "x": -4,
            "y": -1,
            "z": 23,
            "elements": [
                "contenttweaker:arkforcefieldcontrolblock@0"
            ]
        },
        {
            "x": 5,
            "y": 0,
            "z": 2,
            "elements": [
                "contenttweaker:space_time_coil@0"
            ]
        },
        {
            "x": -8,
            "y": -1,
            "z": 22,
            "elements": [
                "contenttweaker:arkforcefieldcontrolblock@0"
            ]
        },
        {
            "x": 9,
            "y": -1,
            "z": 7,
            "elements": [
                "contenttweaker:arkforcefieldcontrolblock@0"
            ]
        },
        {
            "x": -11,
            "y": 0,
            "z": 16,
            "elements": [
                "contenttweaker:arkforcefieldcontrolblock@0"
            ]
        },
        {
            "x": -8,
            "y": 0,
            "z": 4,
            "elements": [
                "contenttweaker:space_time_coil@0"
            ]
        },
        {
            "x": 4,
            "y": 0,
            "z": 26,
            "elements": [
                "contenttweaker:arkforcefieldcontrolblock@0"
            ]
        },
        {
            "x": -3,
            "y": 1,
            "z": 3,
            "elements": [
                "contenttweaker:arkforcefieldcontrolblock@0"
            ]
        },
        {
            "x": 13,
            "y": 1,
            "z": 14,
            "elements": [
                "contenttweaker:arkforcefieldcontrolblock@0"
            ]
        },
        {
            "x": 3,
            "y": -1,
            "z": 26,
            "elements": [
                "contenttweaker:arkforcefieldcontrolblock@0"
            ]
        },
        {
            "x": 4,
            "y": 1,
            "z": 26,
            "elements": [
                "contenttweaker:arkforcefieldcontrolblock@0"
            ]
        },
        {
            "x": 10,
            "y": 1,
            "z": 19,
            "elements": [
                "contenttweaker:arkforcefieldcontrolblock@0"
            ]
        },
        {
            "x": -7,
            "y": -1,
            "z": 5,
            "elements": [
                "contenttweaker:arkforcefieldcontrolblock@0"
            ]
        },
        {
            "x": -9,
            "y": -1,
            "z": 22,
            "elements": [
                "contenttweaker:arkforcefieldcontrolblock@0"
            ]
        },
        {
            "x": -8,
            "y": -1,
            "z": 2,
            "elements": [
                "contenttweaker:arkforcefieldcontrolblock@0"
            ]
        },
        {
            "x": 12,
            "y": -1,
            "z": 7,
            "elements": [
                "contenttweaker:arkforcefieldcontrolblock@0"
            ]
        },
        {
            "x": -11,
            "y": 0,
            "z": 11,
            "elements": [
                "contenttweaker:arkforcefieldcontrolblock@0"
            ]
        },
        {
            "x": 12,
