{
    "registryname": "ChaosReactor", 
    "localizedname": "混沌反应堆", 
    "requires-blueprint": false,
    "color": "FFDAB9",
    "parts": [
        {
            "x": 0,
            "y": -2,
            "z": 0,
            "elements": [
                "contenttweaker:extrememachineblock@0"
            ]
        },
        {
            "x": 1,
            "y": 0,
            "z": 14,
            "elements": [
                "contenttweaker:extrememachineblock@0"
            ]
        },
        {
            "x": 0,
            "y": -5,
            "z": 5,
            "elements": [
                "modularmachinery:blockcasing@0"
            ]
        },
        {
            "x": -1,
            "y": 1,
            "z": 0,
            "elements": [
                "modularmachinery:blockcasing@0"
            ]
        },
        {
            "x": 0,
            "y": -1,
            "z": 0,
            "elements": [
                "contenttweaker:extrememachineblock@0"
            ]
        },
        {
            "x": -3,
            "y": 7,
            "z": 7,
            "elements": [
                "contenttweaker:extrememachineblock@0"
            ]
        },
        {
            "x": 3,
            "y": -3,
            "z": 14,
            "elements": [
                "modularmachinery:blockcasing@0"
            ]
        },
        {
            "x": -4,
            "y": -7,
            "z": 11,
            "elements": [
                "modularmachinery:blockcasing@0"
            ]
        },
        {
            "x": 0,
            "y": -1,
            "z": 14,
            "elements": [
                "contenttweaker:extrememachineblock@0"
            ]
        },
        {
            "x": 7,
            "y": 5,
            "z": 2,
            "elements": [
                "modularmachinery:blockcasing@0"
            ]
        },
        {
            "x": -4,
            "y": 7,
            "z": 0,
            "elements": [
                "contenttweaker:extrememachineblock@0"
            ]
        },
        {
            "x": 3,
            "y": -7,
            "z": 0,
            "elements": [
                "contenttweaker:extrememachineblock@0"
            ]
        },
        {
            "x": 3,
            "y": 7,
            "z": 4,
            "elements": [
                "modularmachinery:blockcasing@0"
            ]
        },
        {
            "x": 1,
            "y": 0,
            "z": 0,
            "elements": [
                "contenttweaker:extrememachineblock@0"
            ]
        },
        {
            "x": 2,
            "y": -7,
            "z": 0,
            "elements": [
                "contenttweaker:extrememachineblock@0"
            ]
        },
        {
            "x": -3,
            "y": 7,
            "z": 0,
            "elements": [
                "contenttweaker:extrememachineblock@0"
            ]
        },
        {
            "x": -2,
            "y": 2,
            "z": 0,
            "elements": [
                "modularmachinery:blockcasing@0"
            ]
        },
        {
            "x": 7,
            "y": 0,
            "z": 13,
            "elements": [
                "contenttweaker:extrememachineblock@0"
            ]
        },
        {
            "x": 2,
            "y": -7,
            "z": 5,
            "elements": [
                "modularmachinery:blockcasing@0"
            ]
        },
        {
            "x": 0,
            "y": -4,
            "z": 0,
            "elements": [
                "contenttweaker:extrememachineblock@0"
            ]
        },
        {
            "x": -3,
            "y": 7,
            "z": 14,
            "elements": [
                "contenttweaker:extrememachineblock@0"
            ]
        },
        {
            "x": 7,
            "y": 7,
            "z": 2,
            "elements": [
                "contenttweaker:extrememachineblock@0"
            ]
        },
        {
            "x": 1,
            "y": -1,
            "z": 0,
            "elements": [
                "modularmachinery:blockcasing@0"
            ]
        },
        {
            "x": -7,
            "y": -4,
            "z": 11,
            "elements": [
                "modularmachinery:blockcasing@0"
            ]
        },
        {
            "x": 0,
            "y": 7,
            "z": 4,
            "elements": [
                "contenttweaker:extrememachineblock@0"
            ]
        },
        {
            "x": 0,
            "y": 7,
            "z": 3,
            "elements": [
                "contenttweaker:extrememachineblock@0"
            ]
        },
        {
            "x": 0,
            "y": -6,
            "z": 6,
            "elements": [
                "modularmachinery:blockcasing@0"
            ]
        },
        {
            "x": 0,
            "y": -3,
            "z": 0,
            "elements": [
                "contenttweaker:extrememachineblock@0"
            ]
        },
        {
            "x": -7,
            "y": -3,
            "z": 4,
            "elements": [
                "modularmachinery:blockcasing@0"
            ]
        },
        {
            "x": 1,
            "y": 1,
            "z": 14,
            "elements": [
                "modularmachinery:blockcasing@0"
            ]
        },
        {
            "x": -7,
            "y": 7,
            "z": 5,
            "elements": [
                "contenttweaker:extrememachineblock@0"
            ]
        },
        {
            "x": 0,
            "y": 3,
            "z": 14,
            "elements": [
                "contenttweaker:extrememachineblock@0"
            ]
        },
        {
            "x": -3,
            "y": -7,
            "z": 7,
            "elements": [
                "contenttweaker:extrememachineblock@0"
            ]
        },
        {
            "x": 1,
            "y": -7,
            "z": 0,
            "elements": [
                "contenttweaker:extrememachineblock@0"
            ]
        },
        {
            "x": 2,
            "y": 0,
            "z": 0,
            "elements": [
                "contenttweaker:extrememachineblock@0"
            ]
        },
        {
            "x": -7,
            "y": 3,
            "z": 10,
            "elements": [
                "modularmachinery:blockcasing@0"
            ]
        },
        {
            "x": -2,
            "y": 7,
            "z": 0,
            "elements": [
                "contenttweaker:extrememachineblock@0"
            ]
        },
        {
            "x": -4,
            "y": 4,
            "z": 0,
            "elements": [
                "modularmachinery:blockcasing@0"
            ]
        },
        {
            "x": 0,
            "y": -3,
            "z": 11,
            "elements": [
                "modularmachinery:blockcasing@0"
            ]
        },
        {
            "x": -2,
            "y": -2,
            "z": 0,
            "elements": [
                "modularmachinery:blockcasing@0"
            ]
        },
        {
            "x": -5,
            "y": 0,
            "z": 5,
            "elements": [
                "modularmachinery:blockcasing@0"
            ]
        },
        {
            "x": -2,
            "y": 7,
            "z": 14,
            "elements": [
                "contenttweaker:extrememachineblock@0"
            ]
        },
        {
            "x": 3,
            "y": 7,
            "z": 7,
            "elements": [
                "contenttweaker:extrememachineblock@0"
            ]
        },
        {
            "x": 0,
            "y": -4,
            "z": 11,
            "elements": [
                "avaritia:block_resource@2"
            ]
        },
        {
            "x": -5,
            "y": -7,
            "z": 12,
            "elements": [
                "modularmachinery:blockcasing@0"
            ]
        },
        {
            "x": -7,
            "y": -3,
            "z": 10,
            "elements": [
                "modularmachinery:blockcasing@0"
            ]
        },
        {
            "x": 1,
            "y": 1,
            "z": 0,
            "elements": [
                "modularmachinery:blockcasing@0"
            ]
        },
        {
            "x": 3,
            "y": -3,
            "z": 0,
            "elements": [
                "modularmachinery:blockcasing@0"
            ]
        },
        {
            "x": -4,
            "y": 0,
            "z": 10,
            "elements": [
                "modularmachinery:blockcasing@0"
            ]
        },
        {
            "x": -5,
            "y": 5,
            "z": 0,
            "elements": [
                "modularmachinery:blockcasing@0"
            ]
        },
        {
            "x": -6,
            "y": -7,
            "z": 7,
            "elements": [
                "contenttweaker:extrememachineblock@0"
            ]
        },
        {
            "x": -1,
            "y": 0,
            "z": 0,
            "elements": [
                "contenttweaker:extrememachineblock@0"
            ]
        },
        {
            "x": 0,
            "y": 4,
            "z": 3,
            "elements": [
                "avaritia:block_resource@2"
            ]
        },
        {
            "x": 4,
            "y": 0,
            "z": 14,
            "elements": [
                "contenttweaker:extrememachineblock@0"
            ]
        },
        {
            "x": -5,
            "y": 7,
            "z": 14,
            "elements": [
                "contenttweaker:extrememachineblock@0"
            ]
        },
        {
            "x": -7,
            "y": -7,
            "z": 4,
            "elements": [
                "contenttweaker:extrememachineblock@0"
            ]
        },
        {
            "x": 0,
            "y": -7,
            "z": 5,
            "elements": [
                "contenttweaker:extrememachineblock@0"
            ]
        },
        {
            "x": -7,
            "y": 7,
            "z": 10,
            "elements": [
                "contenttweaker:extrememachineblock@0"
            ]
        },
        {
            "x": 7,
            "y": -1,
            "z": 8,
            "elements": [
                "modularmachinery:blockcasing@0"
            ]
        },
        {
            "x": -7,
            "y": 0,
            "z": 10,
            "elements": [
                "contenttweaker:extrememachineblock@0"
            ]
        },
        {
            "x": 6,
            "y": 7,
            "z": 7,
            "elements": [
                "contenttweaker:extrememachineblock@0"
            ]
        },
        {
            "x": 3,
            "y": 0,
            "z": 3,
            "elements": [
                "modularmachinery:blockcasing@0"
            ]
        },
        {
            "x": -7,
            "y": -7,
            "z": 11,
            "elements": [
                "contenttweaker:extrememachineblock@0"
            ]
        },
        {
            "x": 4,
            "y": -7,
            "z": 0,
            "elements": [
                "contenttweaker:extrememachineblock@0"
            ]
        },
        {
            "x": -5,
            "y": 7,
            "z": 0,
            "elements": [
                "contenttweaker:extrememachineblock@0"
            ]
        },
        {
            "x": 0,
            "y": 3,
            "z": 3,
            "elements": [
                "modularmachinery:blockcasing@0"
            ]
        },
        {
            "x": 7,
            "y": 0,
            "z": 6,
            "elements": [
                "contenttweaker:extrememachineblock@0"
            ]
        },
        {
            "x": 6,
            "y": -7,
            "z": 13,
            "elements": [
                "modularmachinery:blockcasing@0"
            ]
        },
        {
            "x": -7,
            "y": 0,
            "z": 5,
            "elements": [
                "contenttweaker:extrememachineblock@0"
            ]
        },
        {
            "x": -5,
            "y": 5,
            "z": 14,
            "elements": [
                "modularmachinery:blockcasing@0"
            ]
        },
        {
            "x": 4,
            "y": 0,
            "z": 0,
            "elements": [
                "contenttweaker:extrememachineblock@0"
            ]
        },
        {
            "x": -7,
            "y": 6,
            "z": 0,
            "elements": [
                "contenttweaker:extrememachineblock@0"
            ]
        },
        {
            "x": -2,
            "y": 2,
            "z": 14,
            "elements": [
                "modularmachinery:blockcasing@0"
            ]
        },
        {
            "x": 6,
            "y": -6,
            "z": 0,
            "elements": [
                "modularmachinery:blockcasing@0"
            ]
        },
        {
            "x": 5,
            "y": -2,
            "z": 7,
            "elements": [
                "modularmachinery:blockcasing@0"
            ]
        },
        {
            "x": -3,
            "y": 0,
            "z": 11,
            "elements": [
                "modularmachinery:blockcasing@0"
            ]
        },
        {
            "x": -7,
            "y": 5,
            "z": 0,
            "elements": [
                "contenttweaker:extrememachineblock@0"
            ]
        },
        {
            "x": 7,
            "y": 1,
            "z": 6,
            "elements": [
                "modularmachinery:blockcasing@0"
            ]
        },
        {
            "x": -7,
            "y": 2,
            "z": 5,
            "elements": [
                "modularmachinery:blockcasing@0"
            ]
        },
        {
            "x": -6,
            "y": -7,
            "z": 14,
            "elements": [
                "contenttweaker:extrememachineblock@0"
            ]
        },
        {
            "x": -7,
            "y": -7,
            "z": 1,
            "elements": [
                "contenttweaker:extrememachineblock@0"
            ]
        },
        {
            "x": 2,
            "y": 0,
            "z": 12,
            "elements": [
                "modularmachinery:blockcasing@0"
            ]
        },
        {
            "x": 0,
            "y": -7,
            "z": 11,
            "elements": [
                "contenttweaker:extrememachineblock@0"
            ]
        },
        {
            "x": -3,
            "y": -3,
            "z": 0,
            "elements": [
                "modularmachinery:blockcasing@0"
            ]
        },
        {
            "x": 7,
            "y": -7,
            "z": 0,
            "elements": [
                "modularmachinery:blockcasing@0"
            ]
        },
        {
            "x": 3,
            "y": 4,
            "z": 7,
            "elements": [
                "modularmachinery:blockcasing@0"
            ]
        },
        {
            "x": 0,
            "y": 6,
            "z": 7,
            "elements": [
                "contenttweaker:fallenstarforcefieldcontrolblock@0"
            ]
        },
        {
            "x": 0,
            "y": -7,
            "z": 14,
            "elements": [
                "contenttweaker:extrememachineblock@0"
            ]
        },
        {
            "x": -2,
            "y": -7,
            "z": 5,
            "elements": [
                "modularmachinery:blockcasing@0"
            ]
        },
        {
            "x": 5,
            "y": 0,
            "z": 0,
            "elements": [
                "contenttweaker:extrememachineblock@0"
            ]
        },
        {
            "x": -2,
            "y": 0,
            "z": 14,
            "elements": [
                "contenttweaker:extrememachineblock@0"
            ]
        },
        {
            "x": 4,
            "y": -4,
            "z": 0,
            "elements": [
                "modularmachinery:blockcasing@0"
            ]
        },
        {
            "x": 2,
            "y": 2,
            "z": 0,
            "elements": [
                "modularmachinery:blockcasing@0"
            ]
        },
        {
            "x": 7,
            "y": -6,
            "z": 0,
            "elements": [
                "contenttweaker:extrememachineblock@0"
            ]
        },
        {
            "x": 0,
            "y": 7,
            "z": 7,
            "elements": [
                "modularmachinery:blockenergyinputhatch"
            ]
        },
        {
            "x": 0,
            "y": -6,
            "z": 14,
            "elements": [
                "contenttweaker:extrememachineblock@0"
            ]
        },
        {
            "x": 0,
            "y": 5,
            "z": 5,
            "elements": [
                "modularmachinery:blockcasing@0"
            ]
        },
        {
            "x": 7,
            "y": -5,
            "z": 0,
            "elements": [
                "contenttweaker:extrememachineblock@0"
            ]
        },
        {
            "x": -7,
            "y": -6,
            "z": 1,
            "elements": [
                "modularmachinery:blockcasing@0"
            ]
        },
        {
            "x": 6,
            "y": -7,
            "z": 0,
            "elements": [
                "contenttweaker:extrememachineblock@0"
            ]
        },
        {
            "x": 7,
            "y": 2,
            "z": 9,
            "elements": [
                "modularmachinery:blockcasing@0"
            ]
        },
        {
            "x": -7,
            "y": 7,
            "z": 0,
            "elements": [
                "modularmachinery:blockcasing@0"
            ]
        },
        {
            "x": -2,
            "y": 0,
            "z": 0,
            "elements": [
                "contenttweaker:extrememachineblock@0"
            ]
        },
        {
            "x": 3,
            "y": -7,
            "z": 14,
            "elements": [
                "contenttweaker:extrememachineblock@0"
            ]
        },
        {
            "x": 7,
            "y": -4,
            "z": 0,
            "elements": [
                "contenttweaker:extrememachineblock@0"
            ]
        },
        {
            "x": -5,
            "y": 0,
            "z": 14,
            "elements": [
                "contenttweaker:extrememachineblock@0"
            ]
        },
        {
            "x": 7,
            "y": -7,
            "z": 12,
            "elements": [
                "contenttweaker:extrememachineblock@0"
            ]
        },
        {
            "x": 2,
            "y": 7,
            "z": 0,
            "elements": [
                "contenttweaker:extrememachineblock@0"
            ]
        },
        {
            "x": -3,
            "y": -7,
            "z": 0,
            "elements": [
                "contenttweaker:extrememachineblock@0"
            ]
        },
        {
            "x": 6,
            "y": 0,
            "z": 7,
            "elements": [
                "contenttweaker:fallenstarforcefieldcontrolblock@0"
            ]
        },
        {
            "x": -3,
            "y": -3,
            "z": 14,
            "elements": [
                "modularmachinery:blockcasing@0"
            ]
        },
        {
            "x": 1,
            "y": 7,
            "z": 6,
            "elements": [
                "modularmachinery:blockcasing@0"
            ]
        },
        {
            "x": 0,
            "y": -5,
            "z": 14,
            "elements": [
                "contenttweaker:extrememachineblock@0"
            ]
        },
        {
            "x": 7,
            "y": -7,
            "z": 5,
            "elements": [
                "contenttweaker:extrememachineblock@0"
            ]
        },
        {
            "x": 7,
            "y": -3,
            "z": 0,
            "elements": [
                "contenttweaker:extrememachineblock@0"
            ]
        },
        {
            "x": 0,
            "y": -6,
            "z": 0,
            "elements": [
                "contenttweaker:extrememachineblock@0"
            ]
        },
        {
            "x": 0,
            "y": 7,
            "z": 5,
            "elements": [
                "contenttweaker:extrememachineblock@0"
            ]
        },
        {
            "x": 6,
            "y": -7,
            "z": 7,
            "elements": [
                "contenttweaker:extrememachineblock@0"
            ]
        },
        {
            "x": 7,
            "y": 0,
            "z": 9,
            "elements": [
                "contenttweaker:extrememachineblock@0"
            ]
        },
        {
            "x": -3,
            "y": 7,
            "z": 4,
            "elements": [
                "modularmachinery:blockcasing@0"
            ]
        },
        {
            "x": 6,
            "y": 1,
            "z": 7,
            "elements": [
                "modularmachinery:blockcasing@0"
            ]
        },
        {
            "x": -5,
            "y": 0,
            "z": 0,
            "elements": [
                "contenttweaker:extrememachineblock@0"
            ]
        },
        {
            "x": 0,
            "y": 4,
            "z": 10,
            "elements": [
                "modularmachinery:blockcasing@0"
            ]
        },
        {
            "x": 0,
            "y": -4,
            "z": 14,
            "elements": [
                "contenttweaker:extrememachineblock@0"
            ]
        },
        {
            "x": 0,
            "y": -5,
            "z": 0,
            "elements": [
                "contenttweaker:extrememachineblock@0"
            ]
        },
        {
            "x": 7,
            "y": -5,
            "z": 12,
            "elements": [
                "modularmachinery:blockcasing@0"
            ]
        },
        {
            "x": 0,
            "y": -7,
            "z": 0,
            "elements": [
                "contenttweaker:extrememachineblock@0"
            ]
        },
        {
            "x": -1,
            "y": 7,
            "z": 0,
            "elements": [
                "contenttweaker:extrememachineblock@0"
            ]
        },
        {
            "x": 6,
            "y": 0,
            "z": 6,
            "elements": [
                "modularmachinery:blockcasing@0"
            ]
        },
        {
            "x": 0,
            "y": -2,
            "z": 14,
            "elements": [
                "contenttweaker:extrememachineblock@0"
            ]
        },
        {
            "x": 0,
            "y": -3,
            "z": 14,
            "elements": [
                "contenttweaker:extrememachineblock@0"
            ]
        },
        {
            "x": -2,
            "y": 7,
            "z": 9,
            "elements": [
                "modularmachinery:blockcasing@0"
            ]
        },
        {
            "x": 0,
            "y": 7,
            "z": 6,
            "elements": [
                "contenttweaker:extrememachineblock@0"
            ]
        },
        {
            "x": 6,
            "y": -7,
            "z": 14,
            "elements": [
                "contenttweaker:extrememachineblock@0"
            ]
        },
        {
            "x": -3,
            "y": 7,
            "z": 10,
            "elements": [
                "modularmachinery:blockcasing@0"
            ]
        },
        {
            "x": 0,
            "y": -1,
            "z": 13,
            "elements": [
                "modularmachinery:blockcasing@0"
            ]
        },
        {
            "x": 0,
            "y": 4,
            "z": 4,
            "elements": [
                "modularmachinery:blockcasing@0"
            ]
        },
        {
            "x": 7,
            "y": 7,
            "z": 6,
            "elements": [
                "contenttweaker:extrememachineblock@0"
            ]
        },
        {
            "x": 6,
            "y": -6,
            "z": 14,
            "elements": [
                "modularmachinery:blockcasing@0"
            ]
        },
        {
            "x": 0,
            "y": 6,
            "z": 6,
            "elements": [
                "modularmachinery:blockcasing@0"
            ]
        },
        {
            "x": 1,
            "y": 0,
            "z": 13,
            "elements": [
                "modularmachinery:blockcasing@0"
            ]
        },
        {
            "x": -7,
            "y": 7,
            "z": 2,
            "elements": [
                "contenttweaker:extrememachineblock@0"
            ]
        },
        {
            "x": -7,
            "y": 3,
            "z": 4,
            "elements": [
                "modularmachinery:blockcasing@0"
            ]
        },
        {
            "x": -7,
            "y": -7,
            "z": 5,
            "elements": [
                "contenttweaker:extrememachineblock@0"
            ]
        },
        {
            "x": 7,
            "y": 2,
            "z": 7,
            "elements": [
                "contenttweaker:extrememachineblock@0"
            ]
        },
        {
            "x": 0,
            "y": 7,
            "z": 10,
            "elements": [
                "contenttweaker:extrememachineblock@0"
            ]
        },
        {
            "x": -7,
            "y": -4,
            "z": 3,
            "elements": [
                "modularmachinery:blockcasing@0"
            ]
        },
        {
            "x": 4,
            "y": 7,
            "z": 0,
            "elements": [
                "contenttweaker:extrememachineblock@0"
            ]
        },
        {
            "x": -5,
            "y": -7,
            "z": 0,
            "elements": [
                "contenttweaker:extrememachineblock@0"
            ]
        },
        {
            "x": -4,
            "y": 0,
            "z": 4,
            "elements": [
                "modularmachinery:blockcasing@0"
            ]
        },
        {
            "x": -2,
            "y": -7,
            "z": 9,
            "elements": [
                "modularmachinery:blockcasing@0"
            ]
        },
        {
            "x": 7,
            "y": -1,
            "z": 0,
            "elements": [
                "contenttweaker:extrememachineblock@0"
            ]
        },
        {
            "x": 5,
            "y": 0,
            "z": 5,
            "elements": [
                "modularmachinery:blockcasing@0"
            ]
        },
        {
            "x": 5,
            "y": 7,
            "z": 7,
            "elements": [
                "contenttweaker:extrememachineblock@0"
            ]
        },
        {
            "x": 7,
            "y": 2,
            "z": 0,
            "elements": [
                "contenttweaker:extrememachineblock@0"
            ]
        },
        {
            "x": 4,
            "y": 7,
            "z": 14,
            "elements": [
                "contenttweaker:extrememachineblock@0"
            ]
        },
        {
            "x": -7,
            "y": 7,
            "z": 9,
            "elements": [
                "contenttweaker:extrememachineblock@0"
            ]
        },
        {
            "x": 7,
            "y": 5,
            "z": 14,
            "elements": [
                "contenttweaker:extrememachineblock@0"
            ]
        },
        {
            "x": 4,
            "y": 0,
            "z": 3,
            "elements": [
                "avaritia:block_resource@2"
            ]
        },
        {
            "x": 7,
            "y": 3,
            "z": 7,
            "elements": [
                "contenttweaker:extrememachineblock@0"
            ]
        },
        {
            "x": 7,
            "y": 1,
            "z": 0,
            "elements": [
                "contenttweaker:extrememachineblock@0"
            ]
        },
        {
            "x": -4,
            "y": -7,
            "z": 3,
            "elements": [
                "modularmachinery:blockcasing@0"
            ]
        },
        {
            "x": -7,
            "y": 0,
            "z": 0,
            "elements": [
                "contenttweaker:extrememachineblock@0"
            ]
        },
        {
            "x": 7,
            "y": -2,
            "z": 0,
            "elements": [
                "contenttweaker:extrememachineblock@0"
            ]
        },
        {
            "x": 7,
            "y": 6,
            "z": 14,
            "elements": [
                "contenttweaker:extrememachineblock@0"
            ]
        },
        {
            "x": 2,
            "y": 0,
            "z": 2,
            "elements": [
                "modularmachinery:blockcasing@0"
            ]
        },
        {
            "x": 7,
            "y": -7,
            "z": 13,
            "elements": [
                "contenttweaker:extrememachineblock@0"
            ]
        },
        {
            "x": -7,
            "y": 5,
            "z": 2,
            "elements": [
                "modularmachinery:blockcasing@0"
            ]
        },
        {
            "x": -5,
            "y": -5,
            "z": 0,
            "elements": [
                "modularmachinery:blockcasing@0"
            ]
        },
        {
            "x": 7,
            "y": 4,
            "z": 7,
            "elements": [
                "contenttweaker:extrememachineblock@0"
            ]
        },
        {
            "x": 7,
            "y": 3,
            "z": 14,
            "elements": [
                "contenttweaker:extrememachineblock@0"
            ]
        },
        {
            "x": 6,
            "y": 7,
            "z": 13,
            "elements": [
                "modularmachinery:blockcasing@0"
            ]
        },
        {
            "x": 4,
            "y": 7,
            "z": 7,
            "elements": [
                "contenttweaker:extrememachineblock@0"
            ]
        },
        {
            "x": 7,
            "y": 5,
            "z": 7,
            "elements": [
                "contenttweaker:extrememachineblock@0"
            ]
        },
        {
            "x": 5,
            "y": 7,
            "z": 14,
            "elements": [
                "contenttweaker:extrememachineblock@0"
            ]
        },
        {
            "x": 7,
            "y": 4,
            "z": 0,
            "elements": [
                "contenttweaker:extrememachineblock@0"
            ]
        },
        {
            "x": 7,
            "y": -6,
            "z": 13,
            "elements": [
                "modularmachinery:blockcasing@0"
            ]
        },
        {
            "x": 6,
            "y": 0,
            "z": 8,
            "elements": [
                "modularmachinery:blockcasing@0"
            ]
        },
        {
            "x": 7,
            "y": 4,
            "z": 14,
            "elements": [
                "contenttweaker:extrememachineblock@0"
            ]
        },
        {
            "x": 6,
            "y": 6,
            "z": 14,
            "elements": [
                "modularmachinery:blockcasing@0"
            ]
        },
        {
            "x": 7,
            "y": 3,
            "z": 0,
            "elements": [
                "contenttweaker:extrememachineblock@0"
            ]
        },
        {
            "x": 7,
            "y": 1,
            "z": 14,
            "elements": [
                "contenttweaker:extrememachineblock@0"
            ]
        },
        {
            "x": -5,
            "y": 0,
            "z": 9,
            "elements": [
                "modularmachinery:blockcasing@0"
            ]
        },
        {
            "x": 4,
            "y": 4,
            "z": 7,
            "elements": [
                "avaritia:block_resource@2"
            ]
        },
        {
            "x": 0,
            "y": -7,
            "z": 9,
            "elements": [
                "contenttweaker:extrememachineblock@0"
            ]
        },
        {
            "x": -7,
            "y": 7,
            "z": 4,
            "elements": [
                "contenttweaker:extrememachineblock@0"
            ]
        },
        {
            "x": 4,
            "y": 4,
            "z": 0,
            "elements": [
                "modularmachinery:blockcasing@0"
            ]
        },
        {
            "x": 7,
            "y": 0,
            "z": 14,
            "elements": [
                "contenttweaker:extrememachineblock@0"
            ]
        },
        {
            "x": -6,
            "y": 0,
            "z": 8,
            "elements": [
                "modularmachinery:blockcasing@0"
            ]
        },
        {
            "x": 7,
            "y": -2,
            "z": 5,
            "elements": [
                "modularmachinery:blockcasing@0"
            ]
        },
        {
            "x": 7,
            "y": 2,
            "z": 14,
            "elements": [
                "contenttweaker:extrememachineblock@0"
            ]
        },
        {
            "x": 6,
            "y": 7,
            "z": 14,
            "elements": [
                "contenttweaker:extrememachineblock@0"
            ]
        },
        {
            "x": 4,
            "y": 4,
            "z": 14,
            "elements": [
                "modularmachinery:blockcasing@0"
            ]
        },
        {
            "x": 5,
            "y": 7,
            "z": 12,
            "elements": [
                "modularmachinery:blockcasing@0"
            ]
        },
        {
            "x": -7,
            "y": -1,
            "z": 8,
            "elements": [
                "modularmachinery:blockcasing@0"
            ]
        },
        {
            "x": 4,
            "y": 0,
            "z": 10,
            "elements": [
                "modularmachinery:blockcasing@0"
            ]
        },
        {
            "x": 7,
            "y": 0,
            "z": 0,
            "elements": [
                "contenttweaker:extrememachineblock@0"
            ]
        },
        {
            "x": -7,
            "y": 4,
            "z": 0,
            "elements": [
                "contenttweaker:extrememachineblock@0"
            ]
        },
        {
            "x": 0,
            "y": 7,
            "z": 13,
            "elements": [
                "contenttweaker:extrememachineblock@0"
            ]
        },
        {
            "x": 6,
            "y": -1,
            "z": 7,
            "elements": [
                "modularmachinery:blockcasing@0"
            ]
        },
        {
            "x": 7,
            "y": 0,
            "z": 7,
            "elements": [
                "modularmachinery:blockoutputbus",
                "modularmachinery:blockmeitemoutputbus"
            ]
        },
        {
            "x": -7,
            "y": 1,
            "z": 0,
            "elements": [
                "contenttweaker:extrememachineblock@0"
            ]
        },
        {
            "x": 2,
            "y": 7,
            "z": 5,
            "elements": [
                "modularmachinery:blockcasing@0"
            ]
        },
        {
            "x": 3,
            "y": 7,
            "z": 14,
            "elements": [
                "contenttweaker:extrememachineblock@0"
            ]
        },
        {
            "x": 0,
            "y": -4,
            "z": 4,
            "elements": [
                "modularmachinery:blockcasing@0"
            ]
        },
        {
            "x": 0,
            "y": -5,
            "z": 9,
            "elements": [
                "modularmachinery:blockcasing@0"
            ]
        },
        {
            "x": -7,
            "y": 3,
            "z": 0,
            "elements": [
                "contenttweaker:extrememachineblock@0"
            ]
        },
        {
            "x": 4,
            "y": 3,
            "z": 7,
            "elements": [
                "modularmachinery:blockcasing@0"
            ]
        },
        {
            "x": 5,
            "y": 7,
            "z": 2,
            "elements": [
                "modularmachinery:blockcasing@0"
            ]
        },
        {
            "x": -4,
            "y": 0,
            "z": 0,
            "elements": [
                "contenttweaker:extrememachineblock@0"
            ]
        },
        {
            "x": 7,
            "y": 1,
            "z": 7,
            "elements": [
                "contenttweaker:extrememachineblock@0"
            ]
        },
        {
            "x": -7,
            "y": 2,
            "z": 0,
            "elements": [
                "contenttweaker:extrememachineblock@0"
            ]
        },
        {
            "x": 0,
            "y": -7,
            "z": 4,
            "elements": [
                "contenttweaker:extrememachineblock@0"
            ]
        },
        {
            "x": -7,
            "y": 0,
            "z": 9,
            "elements": [
                "contenttweaker:extrememachineblock@0"
            ]
        },
        {
            "x": 0,
            "y": 7,
            "z": 14,
            "elements": [
                "contenttweaker:extrememachineblock@0"
            ]
        },
        {
            "x": 7,
            "y": 7,
            "z": 13,
            "elements": [
                "contenttweaker:extrememachineblock@0"
            ]
        },
        {
            "x": 0,
            "y": -7,
            "z": 3,
            "elements": [
                "contenttweaker:extrememachineblock@0"
            ]
        },
        {
            "x": 3,
            "y": 3,
            "z": 14,
            "elements": [
                "modularmachinery:blockcasing@0"
            ]
        },
        {
            "x": 7,
            "y": 7,
            "z": 12,
            "elements": [
                "contenttweaker:extrememachineblock@0"
            ]
        },
        {
            "x": 1,
            "y": 7,
            "z": 0,
            "elements": [
                "contenttweaker:extrememachineblock@0"
            ]
        },
        {
            "x": -2,
            "y": -7,
            "z": 0,
            "elements": [
                "contenttweaker:extrememachineblock@0"
            ]
        },
        {
            "x": -5,
            "y": -7,
            "z": 2,
            "elements": [
                "modularmachinery:blockcasing@0"
            ]
        },
        {
            "x": -7,
            "y": -7,
            "z": 8,
            "elements": [
                "contenttweaker:extrememachineblock@0"
            ]
        },
        {
            "x": 0,
            "y": -4,
            "z": 10,
            "elements": [
                "modularmachinery:blockcasing@0"
            ]
        },
        {
            "x": 3,
            "y": 0,
            "z": 11,
            "elements": [
                "modularmachinery:blockcasing@0"
            ]
        },
        {
            "x": 6,
            "y": 0,
            "z": 14,
            "elements": [
                "contenttweaker:extrememachineblock@0"
            ]
        },
        {
            "x": 1,
            "y": 7,
            "z": 14,
            "elements": [
                "contenttweaker:extrememachineblock@0"
            ]
        },
        {
            "x": 6,
            "y": 7,
            "z": 1,
            "elements": [
                "modularmachinery:blockcasing@0"
            ]
        },
        {
            "x": -4,
            "y": 7,
            "z": 3,
            "elements": [
                "modularmachinery:blockcasing@0"
            ]
        },
        {
            "x": 3,
            "y": -7,
            "z": 4,
            "elements": [
                "modularmachinery:blockcasing@0"
            ]
        },
        {
            "x": 7,
            "y": 5,
            "z": 12,
            "elements": [
                "modularmachinery:blockcasing@0"
            ]
        },
        {
            "x": -3,
            "y": 0,
            "z": 3,
            "elements": [
                "modularmachinery:blockcasing@0"
            ]
        },
        {
            "x": 0,
            "y": 3,
            "z": 11,
            "elements": [
                "modularmachinery:blockcasing@0"
            ]
        },
        {
            "x": -7,
            "y": -2,
            "z": 5,
            "elements": [
                "modularmachinery:blockcasing@0"
            ]
        },
        {
            "x": -7,
            "y": -5,
            "z": 2,
            "elements": [
                "modularmachinery:blockcasing@0"
            ]
        },
        {
            "x": 0,
            "y": 4,
            "z": 11,
            "elements": [
                "avaritia:block_resource@2"
            ]
        },
        {
            "x": 0,
            "y": 6,
            "z": 8,
            "elements": [
                "modularmachinery:blockcasing@0"
            ]
        },
        {
            "x": 7,
            "y": 5,
            "z": 0,
            "elements": [
                "contenttweaker:extrememachineblock@0"
            ]
        },
        {
            "x": 7,
            "y": 7,
            "z": 7,
            "elements": [
                "contenttweaker:extrememachineblock@0"
            ]
        },
        {
            "x": 0,
            "y": -3,
            "z": 3,
            "elements": [
                "modularmachinery:blockcasing@0"
            ]
        },
        {
            "x": 3,
            "y": 0,
            "z": 14,
            "elements": [
                "contenttweaker:extrememachineblock@0"
            ]
        },
        {
            "x": 0,
            "y": 4,
            "z": 14,
            "elements": [
                "contenttweaker:extrememachineblock@0"
            ]
        },
        {
            "x": 3,
            "y": -7,
            "z": 10,
            "elements": [
                "modularmachinery:blockcasing@0"
            ]
        },
        {
            "x": 7,
            "y": 6,
            "z": 0,
            "elements": [
                "contenttweaker:extrememachineblock@0"
            ]
        },
        {
            "x": -7,
            "y": 7,
            "z": 3,
            "elements": [
                "contenttweaker:extrememachineblock@0"
            ]
        },
        {
            "x": 7,
            "y": -7,
            "z": 2,
            "elements": [
                "contenttweaker:extrememachineblock@0"
            ]
        },
        {
            "x": 7,
            "y": 6,
            "z": 7,
            "elements": [
                "contenttweaker:extrememachineblock@0"
            ]
        },
        {
            "x": -3,
            "y": -7,
            "z": 4,
            "elements": [
                "modularmachinery:blockcasing@0"
            ]
        },
        {
            "x": 0,
            "y": 5,
            "z": 14,
            "elements": [
                "contenttweaker:extrememachineblock@0"
            ]
        },
        {
            "x": 0,
            "y": -4,
            "z": 3,
            "elements": [
                "avaritia:block_resource@2"
            ]
        },
        {
            "x": -3,
            "y": -7,
            "z": 10,
            "elements": [
                "modularmachinery:blockcasing@0"
            ]
        },
        {
            "x": -7,
            "y": 0,
            "z": 2,
            "elements": [
                "contenttweaker:extrememachineblock@0"
            ]
        },
        {
            "x": 7,
            "y": 7,
            "z": 0,
            "elements": [
                "modularmachinery:blockcasing@0"
            ]
        },
        {
            "x": 5,
            "y": -5,
            "z": 14,
            "elements": [
                "modularmachinery:blockcasing@0"
            ]
        },
        {
            "x": -7,
            "y": -7,
            "z": 2,
            "elements": [
                "contenttweaker:extrememachineblock@0"
            ]
        },
        {
            "x": -7,
            "y": 2,
            "z": 9,
            "elements": [
                "modularmachinery:blockcasing@0"
            ]
        },
        {
            "x": 0,
            "y": 7,
            "z": 11,
            "elements": [
                "contenttweaker:extrememachineblock@0"
            ]
        },
        {
            "x": 7,
            "y": 7,
            "z": 14,
            "elements": [
                "modularmachinery:blockcasing@0"
            ]
        },
        {
            "x": 7,
            "y": 6,
            "z": 13,
            "elements": [
                "modularmachinery:blockcasing@0"
            ]
        },
        {
            "x": 0,
            "y": -7,
            "z": 10,
            "elements": [
                "contenttweaker:extrememachineblock@0"
            ]
        },
        {
            "x": 7,
            "y": -5,
            "z": 2,
            "elements": [
                "modularmachinery:blockcasing@0"
            ]
        },
        {
            "x": 0,
            "y": 6,
            "z": 14,
            "elements": [
                "contenttweaker:extrememachineblock@0"
            ]
        },
        {
            "x": 0,
            "y": 7,
            "z": 8,
            "elements": [
                "contenttweaker:extrememachineblock@0"
            ]
        },
        {
            "x": 7,
            "y": 0,
            "z": 12,
            "elements": [
                "contenttweaker:extrememachineblock@0"
            ]
        },
        {
            "x": -4,
            "y": 7,
            "z": 14,
            "elements": [
                "contenttweaker:extrememachineblock@0"
            ]
        },
        {
            "x": 0,
            "y": -6,
            "z": 8,
            "elements": [
                "modularmachinery:blockcasing@0"
            ]
        },
        {
            "x": 7,
            "y": -1,
            "z": 6,
            "elements": [
                "modularmachinery:blockcasing@0"
            ]
        },
        {
            "x": 0,
            "y": 5,
            "z": 9,
            "elements": [
                "modularmachinery:blockcasing@0"
            ]
        },
        {
            "x": 4,
            "y": 0,
            "z": 11,
            "elements": [
                "avaritia:block_resource@2"
            ]
        },
        {
            "x": 2,
            "y": 2,
            "z": 14,
            "elements": [
                "modularmachinery:blockcasing@0"
            ]
        },
        {
            "x": -1,
            "y": 7,
            "z": 6,
            "elements": [
                "modularmachinery:blockcasing@0"
            ]
        },
        {
            "x": 4,
            "y": -7,
            "z": 3,
            "elements": [
                "modularmachinery:blockcasing@0"
            ]
        },
        {
            "x": -7,
            "y": 1,
            "z": 7,
            "elements": [
                "contenttweaker:extrememachineblock@0"
            ]
        },
        {
            "x": 5,
            "y": -7,
            "z": 14,
            "elements": [
                "contenttweaker:extrememachineblock@0"
            ]
        },
        {
            "x": 7,
            "y": 0,
            "z": 4,
            "elements": [
                "contenttweaker:extrememachineblock@0"
            ]
        },
        {
            "x": -1,
            "y": 7,
            "z": 8,
            "elements": [
                "modularmachinery:blockcasing@0"
            ]
        },
        {
            "x": 0,
            "y": -7,
            "z": 8,
            "elements": [
                "contenttweaker:extrememachineblock@0"
            ]
        },
        {
            "x": 0,
            "y": 7,
            "z": 9,
            "elements": [
                "contenttweaker:extrememachineblock@0"
            ]
        },
        {
            "x": 4,
            "y": -7,
            "z": 7,
            "elements": [
                "contenttweaker:extrememachineblock@0"
            ]
        },
        {
            "x": 5,
            "y": 0,
            "z": 9,
            "elements": [
                "modularmachinery:blockcasing@0"
            ]
        },
        {
            "x": -4,
            "y": 0,
            "z": 3,
            "elements": [
                "avaritia:block_resource@2"
            ]
        },
        {
            "x": -7,
            "y": 0,
            "z": 7,
            "elements": [
                "modularmachinery:blockinputbus",
                "modularmachinery:blockmepatternprovider"
            ]
        },
        {
            "x": 5,
            "y": -7,
            "z": 2,
            "elements": [
                "modularmachinery:blockcasing@0"
            ]
        },
        {
            "x": 0,
            "y": 7,
            "z": 2,
            "elements": [
                "contenttweaker:extrememachineblock@0"
            ]
        },
        {
            "x": -7,
            "y": 0,
            "z": 4,
            "elements": [
                "contenttweaker:extrememachineblock@0"
            ]
        },
        {
            "x": 2,
            "y": -2,
            "z": 14,
            "elements": [
                "modularmachinery:blockcasing@0"
            ]
        },
        {
            "x": 7,
            "y": 7,
            "z": 10,
            "elements": [
                "contenttweaker:extrememachineblock@0"
            ]
        },
        {
            "x": 7,
            "y": 0,
            "z": 11,
            "elements": [
                "contenttweaker:extrememachineblock@0"
            ]
        },
        {
            "x": 2,
            "y": 0,
            "z": 14,
            "elements": [
                "contenttweaker:extrememachineblock@0"
            ]
        },
        {
            "x": 4,
            "y": -7,
            "z": 14,
            "elements": [
                "contenttweaker:extrememachineblock@0"
            ]
        },
        {
            "x": 7,
            "y": -7,
            "z": 4,
            "elements": [
                "contenttweaker:extrememachineblock@0"
            ]
        },
        {
            "x": -4,
            "y": 7,
            "z": 7,
            "elements": [
                "contenttweaker:extrememachineblock@0"
            ]
        },
        {
            "x": 1,
            "y": -1,
            "z": 14,
            "elements": [
                "modularmachinery:blockcasing@0"
            ]
        },
        {
            "x": 7,
            "y": -7,
            "z": 3,
            "elements": [
                "contenttweaker:extrememachineblock@0"
            ]
        },
        {
            "x": 7,
            "y": -1,
            "z": 7,
            "elements": [
                "contenttweaker:extrememachineblock@0"
            ]
        },
        {
            "x": 4,
            "y": 0,
            "z": 4,
            "elements": [
                "modularmachinery:blockcasing@0"
            ]
        },
        {
            "x": -7,
            "y": 0,
            "z": 3,
            "elements": [
                "contenttweaker:extrememachineblock@0"
            ]
        },
        {
            "x": 7,
            "y": 7,
            "z": 5,
            "elements": [
                "contenttweaker:extrememachineblock@0"
            ]
        },
        {
            "x": 4,
            "y": -3,
            "z": 7,
            "elements": [
                "modularmachinery:blockcasing@0"
            ]
        },
        {
            "x": -1,
            "y": 0,
            "z": 14,
            "elements": [
                "contenttweaker:extrememachineblock@0"
            ]
        },
        {
            "x": 1,
            "y": -6,
            "z": 7,
            "elements": [
                "modularmachinery:blockcasing@0"
            ]
        },
        {
            "x": -7,
            "y": -6,
            "z": 13,
            "elements": [
                "modularmachinery:blockcasing@0"
            ]
        },
        {
            "x": 4,
            "y": -4,
            "z": 14,
            "elements": [
                "modularmachinery:blockcasing@0"
            ]
        },
        {
            "x": 7,
            "y": -3,
            "z": 4,
            "elements": [
                "modularmachinery:blockcasing@0"
            ]
        },
        {
            "x": 7,
            "y": 0,
            "z": 1,
            "elements": [
                "contenttweaker:extrememachineblock@0"
            ]
        },
        {
            "x": -4,
            "y": 4,
            "z": 7,
            "elements": [
                "avaritia:block_resource@2"
            ]
        },
        {
            "x": 7,
            "y": -7,
            "z": 14,
            "elements": [
                "modularmachinery:blockcasing@0"
            ]
        },
        {
            "x": -7,
            "y": -7,
            "z": 13,
            "elements": [
                "contenttweaker:extrememachineblock@0"
            ]
        },
        {
            "x": 2,
            "y": 7,
            "z": 9,
            "elements": [
                "modularmachinery:blockcasing@0"
            ]
        },
        {
            "x": 7,
            "y": -6,
            "z": 14,
            "elements": [
                "contenttweaker:extrememachineblock@0"
            ]
        },
        {
            "x": -5,
            "y": -2,
            "z": 7,
            "elements": [
                "modularmachinery:blockcasing@0"
            ]
        },
        {
            "x": 4,
            "y": -4,
            "z": 7,
            "elements": [
                "avaritia:block_resource@2"
            ]
        },
        {
            "x": 2,
            "y": -7,
            "z": 14,
            "elements": [
                "contenttweaker:extrememachineblock@0"
            ]
        },
        {
            "x": -7,
            "y": 3,
            "z": 7,
            "elements": [
                "contenttweaker:extrememachineblock@0"
            ]
        },
        {
            "x": -7,
            "y": 4,
            "z": 7,
            "elements": [
                "contenttweaker:extrememachineblock@0"
            ]
        },
        {
            "x": 4,
            "y": 7,
            "z": 11,
            "elements": [
                "modularmachinery:blockcasing@0"
            ]
        },
        {
            "x": 7,
            "y": 3,
            "z": 10,
            "elements": [
                "modularmachinery:blockcasing@0"
            ]
        },
        {
            "x": -7,
            "y": 4,
            "z": 3,
            "elements": [
                "modularmachinery:blockcasing@0"
            ]
        },
        {
            "x": -7,
            "y": 2,
            "z": 7,
            "elements": [
                "contenttweaker:extrememachineblock@0"
            ]
        },
        {
            "x": 7,
            "y": -7,
            "z": 7,
            "elements": [
                "contenttweaker:extrememachineblock@0"
            ]
        },
        {
            "x": 0,
            "y": 2,
            "z": 12,
            "elements": [
                "modularmachinery:blockcasing@0"
            ]
        },
        {
            "x": -6,
            "y": -7,
            "z": 1,
            "elements": [
                "modularmachinery:blockcasing@0"
            ]
        },
        {
            "x": -1,
            "y": 1,
            "z": 14,
            "elements": [
                "modularmachinery:blockcasing@0"
            ]
        },
        {
            "x": -4,
            "y": 3,
            "z": 7,
            "elements": [
                "modularmachinery:blockcasing@0"
            ]
        },
        {
            "x": 0,
            "y": 2,
            "z": 2,
            "elements": [
                "modularmachinery:blockcasing@0"
            ]
        },
        {
            "x": -7,
            "y": 5,
            "z": 7,
            "elements": [
                "contenttweaker:extrememachineblock@0"
            ]
        },
        {
            "x": 0,
            "y": -2,
            "z": 2,
            "elements": [
                "modularmachinery:blockcasing@0"
            ]
        },
        {
            "x": 1,
            "y": 6,
            "z": 7,
            "elements": [
                "modularmachinery:blockcasing@0"
            ]
        },
        {
            "x": -2,
            "y": 0,
            "z": 2,
            "elements": [
                "modularmachinery:blockcasing@0"
            ]
        },
        {
            "x": 5,
            "y": -7,
            "z": 12,
            "elements": [
                "modularmachinery:blockcasing@0"
            ]
        },
        {
            "x": 7,
            "y": -2,
            "z": 14,
            "elements": [
                "contenttweaker:extrememachineblock@0"
            ]
        },
        {
            "x": 2,
            "y": -7,
            "z": 9,
            "elements": [
                "modularmachinery:blockcasing@0"
            ]
        },
        {
            "x": 5,
            "y": 0,
            "z": 14,
            "elements": [
                "contenttweaker:extrememachineblock@0"
            ]
        },
        {
            "x": 1,
            "y": 7,
            "z": 7,
            "elements": [
                "contenttweaker:extrememachineblock@0"
            ]
        },
        {
            "x": 7,
            "y": -5,
            "z": 7,
            "elements": [
                "contenttweaker:extrememachineblock@0"
            ]
        },
        {
            "x": 1,
            "y": 0,
            "z": 1,
            "elements": [
                "modularmachinery:blockcasing@0"
            ]
        },
        {
            "x": 7,
            "y": -3,
            "z": 14,
            "elements": [
                "contenttweaker:extrememachineblock@0"
            ]
        },
        {
            "x": 2,
            "y": 5,
            "z": 7,
            "elements": [
                "modularmachinery:blockcasing@0"
            ]
        },
        {
            "x": -7,
            "y": -6,
            "z": 14,
            "elements": [
                "contenttweaker:extrememachineblock@0"
            ]
        },
        {
            "x": 7,
            "y": -6,
            "z": 7,
            "elements": [
                "contenttweaker:extrememachineblock@0"
            ]
        },
        {
            "x": 7,
            "y": 7,
            "z": 4,
            "elements": [
                "contenttweaker:extrememachineblock@0"
            ]
        },
        {
            "x": 0,
            "y": 0,
            "z": 13,
            "elements": [
                "contenttweaker:fallenstarforcefieldcontrolblock@0"
            ]
        },
        {
            "x": 7,
            "y": -3,
            "z": 7,
            "elements": [
                "contenttweaker:extrememachineblock@0"
            ]
        },
        {
            "x": 7,
            "y": -7,
            "z": 6,
            "elements": [
                "contenttweaker:extrememachineblock@0"
            ]
        },
        {
            "x": 7,
            "y": -4,
            "z": 14,
            "elements": [
                "contenttweaker:extrememachineblock@0"
            ]
        },
        {
            "x": -7,
            "y": 7,
            "z": 14,
            "elements": [
                "modularmachinery:blockcasing@0"
            ]
        },
        {
            "x": 3,
            "y": 7,
            "z": 10,
            "elements": [
                "modularmachinery:blockcasing@0"
            ]
        },
        {
            "x": -7,
            "y": 1,
            "z": 8,
            "elements": [
                "modularmachinery:blockcasing@0"
            ]
        },
        {
            "x": -4,
            "y": 4,
            "z": 14,
            "elements": [
                "modularmachinery:blockcasing@0"
            ]
        },
        {
            "x": 4,
            "y": 7,
            "z": 3,
            "elements": [
                "modularmachinery:blockcasing@0"
            ]
        },
        {
            "x": 1,
            "y": -7,
            "z": 8,
            "elements": [
                "modularmachinery:blockcasing@0"
            ]
        },
        {
            "x": 7,
            "y": -4,
            "z": 7,
            "elements": [
                "contenttweaker:extrememachineblock@0"
            ]
        },
        {
            "x": 0,
            "y": 1,
            "z": 13,
            "elements": [
                "modularmachinery:blockcasing@0"
            ]
        },
        {
            "x": 7,
            "y": -5,
            "z": 14,
            "elements": [
                "contenttweaker:extrememachineblock@0"
            ]
        },
        {
            "x": 7,
            "y": 0,
            "z": 10,
            "elements": [
                "contenttweaker:extrememachineblock@0"
            ]
        },
        {
            "x": -5,
            "y": 7,
            "z": 2,
            "elements": [
                "modularmachinery:blockcasing@0"
            ]
        },
        {
            "x": -7,
            "y": -7,
            "z": 7,
            "elements": [
                "contenttweaker:extrememachineblock@0"
            ]
        },
        {
            "x": -7,
            "y": -7,
            "z": 14,
            "elements": [
                "modularmachinery:blockcasing@0"
            ]
        },
        {
            "x": 0,
            "y": 7,
            "z": 12,
            "elements": [
                "contenttweaker:extrememachineblock@0"
            ]
        },
        {
            "x": 7,
            "y": 7,
            "z": 11,
            "elements": [
                "contenttweaker:extrememachineblock@0"
            ]
        },
        {
            "x": 7,
            "y": 6,
            "z": 1,
            "elements": [
                "modularmachinery:blockcasing@0"
            ]
        },
        {
            "x": -1,
            "y": 6,
            "z": 7,
            "elements": [
                "modularmachinery:blockcasing@0"
            ]
        },
        {
            "x": -7,
            "y": -2,
            "z": 9,
            "elements": [
                "modularmachinery:blockcasing@0"
            ]
        },
        {
            "x": 5,
            "y": 5,
            "z": 14,
            "elements": [
                "modularmachinery:blockcasing@0"
            ]
        },
        {
            "x": 2,
            "y": 7,
            "z": 14,
            "elements": [
                "contenttweaker:extrememachineblock@0"
            ]
        },
        {
            "x": 5,
            "y": 2,
            "z": 7,
            "elements": [
                "modularmachinery:blockcasing@0"
            ]
        },
        {
            "x": -1,
            "y": 7,
            "z": 7,
            "elements": [
                "contenttweaker:extrememachineblock@0"
            ]
        },
        {
            "x": -7,
            "y": 7,
            "z": 8,
            "elements": [
                "contenttweaker:extrememachineblock@0"
            ]
        },
        {
            "x": 7,
            "y": -2,
            "z": 7,
            "elements": [
                "contenttweaker:extrememachineblock@0"
            ]
        },
        {
            "x": 7,
            "y": 7,
            "z": 1,
            "elements": [
                "contenttweaker:extrememachineblock@0"
            ]
        },
        {
            "x": 7,
            "y": 3,
            "z": 4,
            "elements": [
                "modularmachinery:blockcasing@0"
            ]
        },
        {
            "x": 7,
            "y": -4,
            "z": 3,
            "elements": [
                "modularmachinery:blockcasing@0"
            ]
        },
        {
            "x": -7,
            "y": -7,
            "z": 6,
            "elements": [
                "contenttweaker:extrememachineblock@0"
            ]
        },
        {
            "x": 7,
            "y": 4,
            "z": 11,
            "elements": [
                "modularmachinery:blockcasing@0"
            ]
        },
        {
            "x": -7,
            "y": -7,
            "z": 9,
            "elements": [
                "contenttweaker:extrememachineblock@0"
            ]
        },
        {
            "x": 6,
            "y": -7,
            "z": 1,
            "elements": [
                "modularmachinery:blockcasing@0"
            ]
        },
        {
            "x": -1,
            "y": 7,
            "z": 14,
            "elements": [
                "contenttweaker:extrememachineblock@0"
            ]
        },
        {
            "x": 2,
            "y": 7,
            "z": 7,
            "elements": [
                "contenttweaker:extrememachineblock@0"
            ]
        },
        {
            "x": -1,
            "y": -7,
            "z": 8,
            "elements": [
                "modularmachinery:blockcasing@0"
            ]
        },
        {
            "x": -5,
            "y": -7,
            "z": 7,
            "elements": [
                "contenttweaker:extrememachineblock@0"
            ]
        },
        {
            "x": 7,
            "y": -1,
            "z": 14,
            "elements": [
                "contenttweaker:extrememachineblock@0"
            ]
        },
        {
            "x": -7,
            "y": 0,
            "z": 14,
            "elements": [
                "contenttweaker:extrememachineblock@0"
            ]
        },
        {
            "x": 5,
            "y": 5,
            "z": 0,
            "elements": [
                "modularmachinery:blockcasing@0"
            ]
        },
        {
            "x": -6,
            "y": 7,
            "z": 1,
            "elements": [
                "modularmachinery:blockcasing@0"
            ]
        },
        {
            "x": -7,
            "y": -7,
            "z": 3,
            "elements": [
                "contenttweaker:extrememachineblock@0"
            ]
        },
        {
            "x": -3,
            "y": -7,
            "z": 14,
            "elements": [
                "contenttweaker:extrememachineblock@0"
            ]
        },
        {
            "x": -7,
            "y": -1,
            "z": 7,
            "elements": [
                "contenttweaker:extrememachineblock@0"
            ]
        },
        {
            "x": 7,
            "y": 0,
            "z": 3,
            "elements": [
                "contenttweaker:extrememachineblock@0"
            ]
        },
        {
            "x": -7,
            "y": 6,
            "z": 13,
            "elements": [
                "modularmachinery:blockcasing@0"
            ]
        },
        {
            "x": -2,
            "y": 0,
            "z": 12,
            "elements": [
                "modularmachinery:blockcasing@0"
            ]
        },
        {
            "x": -5,
            "y": 7,
            "z": 12,
            "elements": [
                "modularmachinery:blockcasing@0"
            ]
        },
        {
            "x": -7,
            "y": -4,
            "z": 0,
            "elements": [
                "contenttweaker:extrememachineblock@0"
            ]
        },
        {
            "x": -7,
            "y": -5,
            "z": 12,
            "elements": [
                "modularmachinery:blockcasing@0"
            ]
        },
        {
            "x": -7,
            "y": -7,
            "z": 12,
            "elements": [
                "contenttweaker:extrememachineblock@0"
            ]
        },
        {
            "x": -7,
            "y": 7,
            "z": 11,
            "elements": [
                "contenttweaker:extrememachineblock@0"
            ]
        },
        {
            "x": -6,
            "y": -6,
            "z": 0,
            "elements": [
                "modularmachinery:blockcasing@0"
            ]
        },
        {
            "x": 7,
            "y": 7,
            "z": 8,
            "elements": [
                "contenttweaker:extrememachineblock@0"
            ]
        },
        {
            "x": -2,
            "y": 5,
            "z": 7,
            "elements": [
                "modularmachinery:blockcasing@0"
            ]
        },
        {
            "x": -7,
            "y": 0,
            "z": 11,
            "elements": [
                "contenttweaker:extrememachineblock@0"
            ]
        },
        {
            "x": -7,
            "y": -2,
            "z": 7,
            "elements": [
                "contenttweaker:extrememachineblock@0"
            ]
        },
        {
            "x": 4,
            "y": -7,
            "z": 11,
            "elements": [
                "modularmachinery:blockcasing@0"
            ]
        },
        {
            "x": -4,
            "y": -7,
            "z": 7,
            "elements": [
                "contenttweaker:extrememachineblock@0"
            ]
        },
        {
            "x": -7,
            "y": -3,
            "z": 0,
            "elements": [
                "contenttweaker:extrememachineblock@0"
            ]
        },
        {
            "x": -6,
            "y": 1,
            "z": 7,
            "elements": [
                "modularmachinery:blockcasing@0"
            ]
        },
        {
            "x": -6,
            "y": 0,
            "z": 14,
            "elements": [
                "contenttweaker:extrememachineblock@0"
            ]
        },
        {
            "x": -5,
            "y": -5,
            "z": 14,
            "elements": [
                "modularmachinery:blockcasing@0"
            ]
        },
        {
            "x": 7,
            "y": -7,
            "z": 11,
            "elements": [
                "contenttweaker:extrememachineblock@0"
            ]
        },
        {
            "x": -4,
            "y": -7,
            "z": 14,
            "elements": [
                "contenttweaker:extrememachineblock@0"
            ]
        },
        {
            "x": -7,
            "y": 2,
            "z": 14,
            "elements": [
                "contenttweaker:extrememachineblock@0"
            ]
        },
        {
            "x": 5,
            "y": 7,
            "z": 0,
            "elements": [
                "contenttweaker:extrememachineblock@0"
            ]
        },
        {
            "x": 2,
            "y": -5,
            "z": 7,
            "elements": [
                "modularmachinery:blockcasing@0"
            ]
        },
        {
            "x": -6,
            "y": -7,
            "z": 0,
            "elements": [
                "contenttweaker:extrememachineblock@0"
            ]
        },
        {
            "x": -7,
            "y": -2,
            "z": 0,
            "elements": [
                "contenttweaker:extrememachineblock@0"
            ]
        },
        {
            "x": 0,
            "y": -7,
            "z": 1,
            "elements": [
                "contenttweaker:extrememachineblock@0"
            ]
        },
        {
            "x": 0,
            "y": 0,
            "z": 1,
            "elements": [
                "contenttweaker:fallenstarforcefieldcontrolblock@0"
            ]
        },
        {
            "x": -7,
            "y": -1,
            "z": 14,
            "elements": [
                "contenttweaker:extrememachineblock@0"
            ]
        },
        {
            "x": -7,
            "y": 4,
            "z": 11,
            "elements": [
                "modularmachinery:blockcasing@0"
            ]
        },
        {
            "x": -7,
            "y": 1,
            "z": 14,
            "elements": [
                "contenttweaker:extrememachineblock@0"
            ]
        },
        {
            "x": 7,
            "y": 7,
            "z": 9,
            "elements": [
                "contenttweaker:extrememachineblock@0"
            ]
        },
        {
            "x": -4,
            "y": 0,
            "z": 11,
            "elements": [
                "avaritia:block_resource@2"
            ]
        },
        {
            "x": 5,
            "y": -7,
            "z": 7,
            "elements": [
                "contenttweaker:extrememachineblock@0"
            ]
        },
        {
            "x": -7,
            "y": -1,
            "z": 0,
            "elements": [
                "contenttweaker:extrememachineblock@0"
            ]
        },
        {
            "x": -6,
            "y": 0,
            "z": 0,
            "elements": [
                "contenttweaker:extrememachineblock@0"
            ]
        },
        {
            "x": -6,
            "y": 0,
            "z": 7,
            "elements": [
                "contenttweaker:fallenstarforcefieldcontrolblock@0"
            ]
        },
        {
            "x": 0,
            "y": 1,
            "z": 1,
            "elements": [
                "modularmachinery:blockcasing@0"
            ]
        },
        {
            "x": -1,
            "y": 0,
            "z": 13,
            "elements": [
                "modularmachinery:blockcasing@0"
            ]
        },
        {
            "x": 3,
            "y": -4,
            "z": 7,
            "elements": [
                "modularmachinery:blockcasing@0"
            ]
        },
        {
            "x": 0,
            "y": -7,
            "z": 2,
            "elements": [
                "contenttweaker:extrememachineblock@0"
            ]
        },
        {
            "x": -1,
            "y": 0,
            "z": 1,
            "elements": [
                "modularmachinery:blockcasing@0"
            ]
        },
        {
            "x": -7,
            "y": -1,
            "z": 6,
            "elements": [
                "modularmachinery:blockcasing@0"
            ]
        },
        {
            "x": 7,
            "y": 4,
            "z": 3,
            "elements": [
                "modularmachinery:blockcasing@0"
            ]
        },
        {
            "x": -4,
            "y": -4,
            "z": 7,
            "elements": [
                "avaritia:block_resource@2"
            ]
        },
        {
            "x": -1,
            "y": -7,
            "z": 14,
            "elements": [
                "contenttweaker:extrememachineblock@0"
            ]
        },
        {
            "x": -7,
            "y": 1,
            "z": 6,
            "elements": [
                "modularmachinery:blockcasing@0"
            ]
        },
        {
            "x": 6,
            "y": 7,
            "z": 0,
            "elements": [
                "contenttweaker:extrememachineblock@0"
            ]
        },
        {
            "x": -7,
            "y": 4,
            "z": 14,
            "elements": [
                "contenttweaker:extrememachineblock@0"
            ]
        },
        {
            "x": -4,
            "y": -3,
            "z": 7,
            "elements": [
                "modularmachinery:blockcasing@0"
            ]
        },
        {
            "x": -7,
            "y": -7,
            "z": 0,
            "elements": [
                "modularmachinery:blockcasing@0"
            ]
        },
        {
            "x": -7,
            "y": -6,
            "z": 7,
            "elements": [
                "contenttweaker:extrememachineblock@0"
            ]
        },
        {
            "x": -7,
            "y": -3,
            "z": 14,
            "elements": [
                "contenttweaker:extrememachineblock@0"
            ]
        },
        {
            "x": 2,
            "y": -7,
            "z": 7,
            "elements": [
                "contenttweaker:extrememachineblock@0"
            ]
        },
        {
            "x": 0,
            "y": -2,
            "z": 12,
            "elements": [
                "modularmachinery:blockcasing@0"
            ]
        },
        {
            "x": -5,
            "y": 7,
            "z": 7,
            "elements": [
                "contenttweaker:extrememachineblock@0"
            ]
        },
        {
            "x": -7,
            "y": 6,
            "z": 14,
            "elements": [
                "contenttweaker:extrememachineblock@0"
            ]
        },
        {
            "x": -7,
            "y": 0,
            "z": 6,
            "elements": [
                "contenttweaker:extrememachineblock@0"
            ]
        },
        {
            "x": -6,
            "y": 7,
            "z": 13,
            "elements": [
                "modularmachinery:blockcasing@0"
            ]
        },
        {
            "x": -7,
            "y": 3,
            "z": 14,
            "elements": [
                "contenttweaker:extrememachineblock@0"
            ]
        },
        {
            "x": -7,
            "y": -2,
            "z": 14,
            "elements": [
                "contenttweaker:extrememachineblock@0"
            ]
        },
        {
            "x": -7,
            "y": -5,
            "z": 7,
            "elements": [
                "contenttweaker:extrememachineblock@0"
            ]
        },
        {
            "x": -4,
            "y": -4,
            "z": 14,
            "elements": [
                "modularmachinery:blockcasing@0"
            ]
        },
        {
            "x": 7,
            "y": -7,
            "z": 10,
            "elements": [
                "contenttweaker:extrememachineblock@0"
            ]
        },
        {
            "x": -4,
            "y": 0,
            "z": 14,
            "elements": [
                "contenttweaker:extrememachineblock@0"
            ]
        },
        {
            "x": -7,
            "y": -4,
            "z": 7,
            "elements": [
                "contenttweaker:extrememachineblock@0"
            ]
        },
        {
            "x": 3,
            "y": 7,
            "z": 0,
            "elements": [
                "contenttweaker:extrememachineblock@0"
            ]
        },
        {
            "x": -4,
            "y": -7,
            "z": 0,
            "elements": [
                "contenttweaker:extrememachineblock@0"
            ]
        },
        {
            "x": -7,
            "y": -5,
            "z": 14,
            "elements": [
                "contenttweaker:extrememachineblock@0"
            ]
        },
        {
            "x": -7,
            "y": -5,
            "z": 0,
            "elements": [
                "contenttweaker:extrememachineblock@0"
            ]
        },
        {
            "x": 7,
            "y": 1,
            "z": 8,
            "elements": [
                "modularmachinery:blockcasing@0"
            ]
        },
        {
            "x": -7,
            "y": -7,
            "z": 10,
            "elements": [
                "contenttweaker:extrememachineblock@0"
            ]
        },
        {
            "x": -7,
            "y": 0,
            "z": 8,
            "elements": [
                "contenttweaker:extrememachineblock@0"
            ]
        },
        {
            "x": 0,
            "y": -7,
            "z": 12,
            "elements": [
                "contenttweaker:extrememachineblock@0"
            ]
        },
        {
            "x": 0,
            "y": -1,
            "z": 1,
            "elements": [
                "modularmachinery:blockcasing@0"
            ]
        },
        {
            "x": -2,
            "y": 7,
            "z": 7,
            "elements": [
                "contenttweaker:extrememachineblock@0"
            ]
        },
        {
            "x": -6,
            "y": -6,
            "z": 14,
            "elements": [
                "modularmachinery:blockcasing@0"
            ]
        },
        {
            "x": -7,
            "y": -4,
            "z": 14,
            "elements": [
                "contenttweaker:extrememachineblock@0"
            ]
        },
        {
            "x": -7,
            "y": -3,
            "z": 7,
            "elements": [
                "contenttweaker:extrememachineblock@0"
            ]
        },
        {
            "x": -4,
            "y": 7,
            "z": 11,
            "elements": [
                "modularmachinery:blockcasing@0"
            ]
        },
        {
            "x": -6,
            "y": 0,
            "z": 6,
            "elements": [
                "modularmachinery:blockcasing@0"
            ]
        },
        {
            "x": -6,
            "y": -7,
            "z": 13,
            "elements": [
                "modularmachinery:blockcasing@0"
            ]
        },
        {
            "x": 6,
            "y": 6,
            "z": 0,
            "elements": [
                "modularmachinery:blockcasing@0"
            ]
        },
        {
            "x": -7,
            "y": -6,
            "z": 0,
            "elements": [
                "contenttweaker:extrememachineblock@0"
            ]
        },
        {
            "x": 7,
            "y": -4,
            "z": 11,
            "elements": [
                "modularmachinery:blockcasing@0"
            ]
        },
        {
            "x": -7,
            "y": 5,
            "z": 14,
            "elements": [
                "contenttweaker:extrememachineblock@0"
            ]
        },
        {
            "x": -1,
            "y": -7,
            "z": 7,
            "elements": [
                "contenttweaker:extrememachineblock@0"
            ]
        },
        {
            "x": 0,
            "y": 7,
            "z": 0,
            "elements": [
                "contenttweaker:extrememachineblock@0"
            ]
        },
        {
            "x": -7,
            "y": 7,
            "z": 13,
            "elements": [
                "contenttweaker:extrememachineblock@0"
            ]
        },
        {
            "x": -1,
            "y": -6,
            "z": 7,
            "elements": [
                "modularmachinery:blockcasing@0"
            ]
        },
        {
            "x": -1,
            "y": -7,
            "z": 0,
            "elements": [
                "contenttweaker:extrememachineblock@0"
            ]
        },
        {
            "x": 1,
            "y": -7,
            "z": 14,
            "elements": [
                "contenttweaker:extrememachineblock@0"
            ]
        },
        {
            "x": 7,
            "y": -3,
            "z": 10,
            "elements": [
                "modularmachinery:blockcasing@0"
            ]
        },
        {
            "x": -3,
            "y": 0,
            "z": 14,
            "elements": [
                "contenttweaker:extrememachineblock@0"
            ]
        },
        {
            "x": -7,
            "y": 0,
            "z": 1,
            "elements": [
                "contenttweaker:extrememachineblock@0"
            ]
        },
        {
            "x": 7,
            "y": -2,
            "z": 9,
            "elements": [
                "modularmachinery:blockcasing@0"
            ]
        },
        {
            "x": 7,
            "y": 7,
            "z": 3,
            "elements": [
                "contenttweaker:extrememachineblock@0"
            ]
        },
        {
            "x": -7,
            "y": 6,
            "z": 7,
            "elements": [
                "contenttweaker:extrememachineblock@0"
            ]
        },
        {
            "x": -2,
            "y": 7,
            "z": 5,
            "elements": [
                "modularmachinery:blockcasing@0"
            ]
        },
        {
            "x": 0,
            "y": -7,
            "z": 7,
            "elements": [
                "modularmachinery:blockenergyoutputhatch@7"
            ]
        },
        {
            "x": -7,
            "y": 7,
            "z": 7,
            "elements": [
                "contenttweaker:extrememachineblock@0"
            ]
        },
        {
            "x": -1,
            "y": -7,
            "z": 6,
            "elements": [
                "modularmachinery:blockcasing@0"
            ]
        },
        {
            "x": 7,
            "y": 0,
            "z": 8,
            "elements": [
                "contenttweaker:extrememachineblock@0"
            ]
        },
        {
            "x": -3,
            "y": 0,
            "z": 0,
            "elements": [
                "contenttweaker:extrememachineblock@0"
            ]
        },
        {
            "x": -2,
            "y": -2,
            "z": 14,
            "elements": [
                "modularmachinery:blockcasing@0"
            ]
        },
        {
            "x": 0,
            "y": 6,
            "z": 0,
            "elements": [
                "contenttweaker:extrememachineblock@0"
            ]
        },
        {
            "x": -4,
            "y": -4,
            "z": 0,
            "elements": [
                "modularmachinery:blockcasing@0"
            ]
        },
        {
            "x": -6,
            "y": 6,
            "z": 14,
            "elements": [
                "modularmachinery:blockcasing@0"
            ]
        },
        {
            "x": 1,
            "y": -7,
            "z": 7,
            "elements": [
                "contenttweaker:extrememachineblock@0"
            ]
        },
        {
            "x": -5,
            "y": 2,
            "z": 7,
            "elements": [
                "modularmachinery:blockcasing@0"
            ]
        },
        {
            "x": -2,
            "y": -5,
            "z": 7,
            "elements": [
                "modularmachinery:blockcasing@0"
            ]
        },
        {
            "x": 7,
            "y": 0,
            "z": 2,
            "elements": [
                "contenttweaker:extrememachineblock@0"
            ]
        },
        {
            "x": 3,
            "y": 3,
            "z": 0,
            "elements": [
                "modularmachinery:blockcasing@0"
            ]
        },
        {
            "x": 0,
            "y": -7,
            "z": 13,
            "elements": [
                "contenttweaker:extrememachineblock@0"
            ]
        },
        {
            "x": 0,
            "y": 5,
            "z": 0,
            "elements": [
                "contenttweaker:extrememachineblock@0"
            ]
        },
        {
            "x": 2,
            "y": -2,
            "z": 0,
            "elements": [
                "modularmachinery:blockcasing@0"
            ]
        },
        {
            "x": 7,
            "y": -7,
            "z": 1,
            "elements": [
                "contenttweaker:extrememachineblock@0"
            ]
        },
        {
            "x": 0,
            "y": -7,
            "z": 6,
            "elements": [
                "contenttweaker:extrememachineblock@0"
            ]
        },
        {
            "x": 6,
            "y": 0,
            "z": 0,
            "elements": [
                "contenttweaker:extrememachineblock@0"
            ]
        },
        {
            "x": -6,
            "y": 7,
            "z": 14,
            "elements": [
                "contenttweaker:extrememachineblock@0"
            ]
        },
        {
            "x": 0,
            "y": 7,
            "z": 1,
            "elements": [
                "contenttweaker:extrememachineblock@0"
            ]
        },
        {
            "x": 0,
            "y": 4,
            "z": 0,
            "elements": [
                "contenttweaker:extrememachineblock@0"
            ]
        },
        {
            "x": 7,
            "y": 2,
            "z": 5,
            "elements": [
                "modularmachinery:blockcasing@0"
            ]
        },
        {
            "x": -7,
            "y": 7,
            "z": 6,
            "elements": [
                "contenttweaker:extrememachineblock@0"
            ]
        },
        {
            "x": 0,
            "y": 2,
            "z": 14,
            "elements": [
                "contenttweaker:extrememachineblock@0"
            ]
        },
        {
            "x": -7,
            "y": 0,
            "z": 12,
            "elements": [
                "contenttweaker:extrememachineblock@0"
            ]
        },
        {
            "x": 7,
            "y": -7,
            "z": 9,
            "elements": [
                "contenttweaker:extrememachineblock@0"
            ]
        },
        {
            "x": 7,
            "y": 0,
            "z": 5,
            "elements": [
                "contenttweaker:extrememachineblock@0"
            ]
        },
        {
            "x": -7,
            "y": 7,
            "z": 12,
            "elements": [
                "contenttweaker:extrememachineblock@0"
            ]
        },
        {
            "x": 0,
            "y": 3,
            "z": 0,
            "elements": [
                "contenttweaker:extrememachineblock@0"
            ]
        },
        {
            "x": -2,
            "y": -7,
            "z": 7,
            "elements": [
                "contenttweaker:extrememachineblock@0"
            ]
        },
        {
            "x": 0,
            "y": 1,
            "z": 14,
            "elements": [
                "contenttweaker:extrememachineblock@0"
            ]
        },
        {
            "x": 1,
            "y": 7,
            "z": 8,
            "elements": [
                "modularmachinery:blockcasing@0"
            ]
        },
        {
            "x": -3,
            "y": 3,
            "z": 14,
            "elements": [
                "modularmachinery:blockcasing@0"
            ]
        },
        {
            "x": -6,
            "y": 7,
            "z": 0,
            "elements": [
                "contenttweaker:extrememachineblock@0"
            ]
        },
        {
            "x": 5,
            "y": -7,
            "z": 0,
            "elements": [
                "contenttweaker:extrememachineblock@0"
            ]
        },
        {
            "x": -7,
            "y": 7,
            "z": 1,
            "elements": [
                "contenttweaker:extrememachineblock@0"
            ]
        },
        {
            "x": 0,
            "y": -6,
            "z": 7,
            "elements": [
                "contenttweaker:fallenstarforcefieldcontrolblock@0"
            ]
        },
        {
            "x": 3,
            "y": 0,
            "z": 0,
            "elements": [
                "contenttweaker:extrememachineblock@0"
            ]
        },
        {
            "x": 0,
            "y": 2,
            "z": 0,
            "elements": [
                "contenttweaker:extrememachineblock@0"
            ]
        },
        {
            "x": -2,
            "y": -7,
            "z": 14,
            "elements": [
                "contenttweaker:extrememachineblock@0"
            ]
        },
        {
            "x": -3,
            "y": -4,
            "z": 7,
            "elements": [
                "modularmachinery:blockcasing@0"
            ]
        },
        {
            "x": 0,
            "y": 0,
            "z": 14,
            "elements": [
                "modularmachinery:blockfluidinputhatch",
                "modularmachinery:blockmepatternprovider"
            ]
        },
        {
            "x": 1,
            "y": -7,
            "z": 6,
            "elements": [
                "modularmachinery:blockcasing@0"
            ]
        },
        {
            "x": -6,
            "y": 6,
            "z": 0,
            "elements": [
                "modularmachinery:blockcasing@0"
            ]
        },
        {
            "x": -6,
            "y": -1,
            "z": 7,
            "elements": [
                "modularmachinery:blockcasing@0"
            ]
        },
        {
            "x": 0,
            "y": 1,
            "z": 0,
            "elements": [
                "contenttweaker:extrememachineblock@0"
            ]
        },
        {
            "x": -3,
            "y": 4,
            "z": 7,
            "elements": [
                "modularmachinery:blockcasing@0"
            ]
        },
        {
            "x": -7,
            "y": 6,
            "z": 1,
            "elements": [
                "modularmachinery:blockcasing@0"
            ]
        },
        {
            "x": -7,
            "y": 5,
            "z": 12,
            "elements": [
                "modularmachinery:blockcasing@0"
            ]
        },
        {
            "x": -1,
            "y": -1,
            "z": 0,
            "elements": [
                "modularmachinery:blockcasing@0"
            ]
        },
        {
            "x": 3,
            "y": -7,
            "z": 7,
            "elements": [
                "contenttweaker:extrememachineblock@0"
            ]
        },
        {
            "x": -7,
            "y": 0,
            "z": 13,
            "elements": [
                "contenttweaker:extrememachineblock@0"
            ]
        },
        {
            "x": 0,
            "y": 0,
            "z": 7,
            "elements": [
                "draconicadditions:chaos_stabilizer_core@0"
            ]
        },
        {
            "x": -1,
            "y": -1,
            "z": 14,
            "elements": [
                "modularmachinery:blockcasing@0"
            ]
        },
        {
            "x": -3,
            "y": 3,
            "z": 0,
            "elements": [
                "modularmachinery:blockcasing@0"
            ]
        },
        {
            "x": 7,
            "y": -6,
            "z": 1,
            "elements": [
                "modularmachinery:blockcasing@0"
            ]
        },
        {
            "x": -6,
            "y": 7,
            "z": 7,
            "elements": [
                "contenttweaker:extrememachineblock@0"
            ]
        },
        {
            "x": 5,
            "y": -5,
            "z": 0,
            "elements": [
                "modularmachinery:blockcasing@0"
            ]
        },
        {
            "x": -5,
            "y": -7,
            "z": 14,
            "elements": [
                "contenttweaker:extrememachineblock@0"
            ]
        },
        {
            "x": 7,
            "y": -7,
            "z": 8,
            "elements": [
                "contenttweaker:extrememachineblock@0"
            ]
        }
    ]}