{
    "registryname": "TruthSeek",
    "localizedname": "§c「§3求真§c」§e矩阵§9聚合§1之门§r",
    "parts": [
        {
            "x": -1,
            "y": 10,
            "z": 1,
            "elements": [
                "contenttweaker:arkmachineblock@0"
            ]
        },
        {
            "x": 0,
            "y": -11,
            "z": -1,
            "elements": [
                "contenttweaker:universalforcefieldcontrolblock@0"
            ]
        },
        {
            "x": -1,
            "y": 2,
            "z": 0,
            "elements": [
                "minecraft:concrete@11"
            ]
        },
        {
            "x": 0,
            "y": -2,
            "z": 0,
            "elements": [
                "minecraft:concrete@11"
            ]
        },
        {
            "x": 1,
            "y": -4,
            "z": 0,
            "elements": [
                "minecraft:concrete@11"
            ]
        },
        {
            "x": 4,
            "y": -9,
            "z": 0,
            "elements": [
                "minecraft:concrete@11"
            ]
        },
        {
            "x": 2,
            "y": -6,
            "z": 0,
            "elements": [
                "minecraft:concrete@11"
            ]
        },
        {
            "x": -2,
            "y": 4,
            "z": 0,
            "elements": [
                "minecraft:concrete@11"
            ]
        },
        {
            "x": 11,
            "y": -6,
            "z": 1,
            "elements": [
                "contenttweaker:arkmachineblock@0"
            ]
        },
        {
            "x": 5,
            "y": -11,
            "z": 0,
            "elements": [
                "contenttweaker:arkmachineblock@0"
            ]
        },
        {
            "x": -3,
            "y": -8,
            "z": -1,
            "elements": [
                "contenttweaker:arkmachineblock@0"
            ]
        },
        {
            "x": -1,
            "y": 1,
            "z": 0,
            "elements": [
                "minecraft:concrete@11"
            ]
        },
        {
            "x": -4,
            "y": 8,
            "z": 0,
            "elements": [
                "contenttweaker:arkmachineblock@0"
            ]
        },
        {
            "x": 11,
            "y": -11,
            "z": 1,
            "elements": [
                "contenttweaker:universalforcefieldcontrolblock@0"
            ]
        },
        {
            "x": -3,
            "y": 6,
            "z": 0,
            "elements": [
                "avaritia:block_resource@1"
            ]
        },
        {
            "x": 3,
            "y": -8,
            "z": 0,
            "elements": [
                "minecraft:concrete@11"
            ]
        },
        {
            "x": 0,
            "y": -1,
            "z": 0,
            "elements": [
                "minecraft:concrete@11"
            ]
        },
        {
            "x": -1,
            "y": 11,
            "z": 1,
            "elements": [
                "contenttweaker:universalforcefieldcontrolblock@0"
            ]
        },
        {
            "x": 1,
            "y": -2,
            "z": 0,
            "elements": [
                "minecraft:concrete@11"
            ]
        },
        {
            "x": 4,
            "y": -10,
            "z": 0,
            "elements": [
                "avaritia:block_resource@1"
            ]
        },
        {
            "x": 1,
            "y": -3,
            "z": 0,
            "elements": [
                "minecraft:concrete@11"
            ]
        },
        {
            "x": -2,
            "y": 3,
            "z": 0,
            "elements": [
                "minecraft:concrete@11"
            ]
        },
        {
            "x": 2,
            "y": -5,
            "z": 0,
            "elements": [
                "minecraft:concrete@11"
            ]
        },
        {
            "x": 2,
            "y": -7,
            "z": 0,
            "elements": [
                "minecraft:concrete@11"
            ]
        },
        {
            "x": 11,
            "y": -5,
            "z": 1,
            "elements": [
                "contenttweaker:arkmachineblock@0"
            ]
        },
        {
            "x": -3,
            "y": 5,
            "z": 0,
            "elements": [
                "avaritia:block_resource@1"
            ]
        },
        {
            "x": 11,
            "y": -11,
            "z": -1,
            "elements": [
                "contenttweaker:universalforcefieldcontrolblock@0"
            ]
        },
        {
            "x": -4,
            "y": 7,
            "z": 0,
            "elements": [
                "contenttweaker:arkmachineblock@0"
            ]
        },
        {
            "x": 3,
            "y": -7,
            "z": 0,
            "elements": [
                "minecraft:concrete@11"
            ]
        },
        {
            "x": -3,
            "y": -7,
            "z": -1,
            "elements": [
                "contenttweaker:arkmachineblock@0"
            ]
        },
        {
            "x": 1,
            "y": 0,
            "z": 0,
            "elements": [
                "minecraft:concrete@11"
            ]
        },
        {
            "x": -2,
            "y": 2,
            "z": 0,
            "elements": [
                "minecraft:concrete@11"
            ]
        },
        {
            "x": 5,
            "y": -9,
            "z": 0,
            "elements": [
                "minecraft:concrete@11"
            ]
        },
        {
            "x": -3,
            "y": 7,
            "z": 0,
            "elements": [
                "avaritia:block_resource@1"
            ]
        },
        {
            "x": 11,
            "y": -9,
            "z": 1,
            "elements": [
                "contenttweaker:arkmachineblock@0"
            ]
        },
        {
            "x": 11,
            "y": -10,
            "z": -1,
            "elements": [
                "contenttweaker:arkmachineblock@0"
            ]
        },
        {
            "x": 1,
            "y": -1,
            "z": 0,
            "elements": [
                "minecraft:concrete@11"
            ]
        },
        {
            "x": 2,
            "y": -8,
            "z": 0,
            "elements": [
                "minecraft:concrete@11"
            ]
        },
        {
            "x": -4,
            "y": 6,
            "z": 0,
            "elements": [
                "contenttweaker:arkmachineblock@0"
            ]
        },
        {
            "x": 4,
            "y": -11,
            "z": 0,
            "elements": [
                "contenttweaker:arkmachineblock@0"
            ]
        },
        {
            "x": -1,
            "y": 4,
            "z": 0,
            "elements": [
                "minecraft:concrete@11"
            ]
        },
        {
            "x": 0,
            "y": -4,
            "z": 0,
            "elements": [
                "minecraft:concrete@11"
            ]
        },
        {
            "x": 3,
            "y": -6,
            "z": 0,
            "elements": [
                "minecraft:concrete@11"
            ]
        },
        {
            "x": -3,
            "y": -6,
            "z": -1,
            "elements": [
                "contenttweaker:arkmachineblock@0"
            ]
        },
        {
            "x": -2,
            "y": 1,
            "z": 0,
            "elements": [
                "minecraft:concrete@11"
            ]
        },
        {
            "x": 11,
            "y": -9,
            "z": -1,
            "elements": [
                "contenttweaker:arkmachineblock@0"
            ]
        },
        {
            "x": -3,
            "y": 8,
            "z": 0,
            "elements": [
                "avaritia:block_resource@1"
            ]
        },
        {
            "x": -3,
            "y": -5,
            "z": -1,
            "elements": [
                "contenttweaker:arkmachineblock@0"
            ]
        },
        {
            "x": 7,
            "y": -11,
            "z": 0,
            "elements": [
                "contenttweaker:arkmachineblock@0"
            ]
        },
        {
            "x": 0,
            "y": -10,
            "z": -1,
            "elements": [
                "contenttweaker:arkmachineblock@0"
            ]
        },
        {
            "x": 11,
            "y": -8,
            "z": -1,
            "elements": [
                "contenttweaker:arkmachineblock@0"
            ]
        },
        {
            "x": 5,
            "y": -10,
            "z": 0,
            "elements": [
                "avaritia:block_resource@1"
            ]
        },
        {
            "x": -1,
            "y": 3,
            "z": 0,
            "elements": [
                "minecraft:concrete@11"
            ]
        },
        {
            "x": 0,
            "y": -3,
            "z": 0,
            "elements": [
                "minecraft:concrete@11"
            ]
        },
        {
            "x": 11,
            "y": -7,
            "z": 1,
            "elements": [
                "contenttweaker:arkmachineblock@0"
            ]
        },
        {
            "x": 1,
            "y": -7,
            "z": 0,
            "elements": [
                "minecraft:concrete@11"
            ]
        },
        {
            "x": 3,
            "y": -5,
            "z": 0,
            "elements": [
                "minecraft:concrete@11"
            ]
        },
        {
            "x": -4,
            "y": 5,
            "z": 0,
            "elements": [
                "contenttweaker:arkmachineblock@0"
            ]
        },
        {
            "x": 2,
            "y": -9,
            "z": 0,
            "elements": [
                "minecraft:concrete@11"
            ]
        },
        {
            "x": 1,
            "y": 2,
            "z": 0,
            "elements": [
                "minecraft:concrete@11"
            ]
        },
        {
            "x": 11,
            "y": -10,
            "z": 1,
            "elements": [
                "contenttweaker:arkmachineblock@0"
            ]
        },
        {
            "x": -2,
            "y": -2,
            "z": 0,
            "elements": [
                "minecraft:concrete@11"
            ]
        },
        {
            "x": -4,
            "y": -10,
            "z": 1,
            "elements": [
                "contenttweaker:universalforcefieldcontrolblock@0"
            ]
        },
        {
            "x": 2,
            "y": 0,
            "z": 0,
            "elements": [
                "minecraft:concrete@11"
            ]
        },
        {
            "x": -2,
            "y": 7,
            "z": 0,
            "elements": [
                "minecraft:concrete@11"
            ]
        },
        {
            "x": -3,
            "y": -9,
            "z": -1,
            "elements": [
                "contenttweaker:arkmachineblock@0"
            ]
        },
        {
            "x": -3,
            "y": 9,
            "z": 0,
            "elements": [
                "avaritia:block_resource@1"
            ]
        },
        {
            "x": -4,
            "y": 4,
            "z": 0,
            "elements": [
                "contenttweaker:arkmachineblock@0"
            ]
        },
        {
            "x": 3,
            "y": -4,
            "z": 0,
            "elements": [
                "minecraft:concrete@11"
            ]
        },
        {
            "x": 12,
            "y": -10,
            "z": -1,
            "elements": [
                "contenttweaker:universalforcefieldcontrolblock@0"
            ]
        },
        {
            "x": 11,
            "y": -7,
            "z": -1,
            "elements": [
                "contenttweaker:arkmachineblock@0"
            ]
        },
        {
            "x": 1,
            "y": 1,
            "z": 0,
            "elements": [
                "minecraft:concrete@11"
            ]
        },
        {
            "x": 4,
            "y": -6,
            "z": 0,
            "elements": [
                "minecraft:concrete@11"
            ]
        },
        {
            "x": 1,
            "y": -8,
            "z": 0,
            "elements": [
                "minecraft:concrete@11"
            ]
        },
        {
            "x": -2,
            "y": -1,
            "z": 0,
            "elements": [
                "minecraft:concrete@11"
            ]
        },
        {
            "x": 12,
            "y": -9,
            "z": -1,
            "elements": [
                "contenttweaker:universalforcefieldcontrolblock@0"
            ]
        },
        {
            "x": -3,
            "y": -10,
            "z": -1,
            "elements": [
                "contenttweaker:arkmachineblock@0"
            ]
        },
        {
            "x": 11,
            "y": -8,
            "z": 1,
            "elements": [
                "contenttweaker:arkmachineblock@0"
            ]
        },
        {
            "x": -4,
            "y": 3,
            "z": 0,
            "elements": [
                "contenttweaker:arkmachineblock@0"
            ]
        },
        {
            "x": 3,
            "y": -3,
            "z": 0,
            "elements": [
                "minecraft:concrete@11"
            ]
        },
        {
            "x": -4,
            "y": -9,
            "z": 1,
            "elements": [
                "contenttweaker:universalforcefieldcontrolblock@0"
            ]
        },
        {
            "x": -2,
            "y": 8,
            "z": 0,
            "elements": [
                "minecraft:concrete@11"
            ]
        },
        {
            "x": 4,
            "y": -5,
            "z": 0,
            "elements": [
                "minecraft:concrete@11"
            ]
        },
        {
            "x": 2,
            "y": -10,
            "z": 0,
            "elements": [
                "avaritia:block_resource@1"
            ]
        },
        {
            "x": -3,
            "y": 10,
            "z": 0,
            "elements": [
                "avaritia:block_resource@1"
            ]
        },
        {
            "x": -1,
            "y": 0,
            "z": 0,
            "elements": [
                "minecraft:concrete@11"
            ]
        },
        {
            "x": -4,
            "y": 2,
            "z": 0,
            "elements": [
                "contenttweaker:arkmachineblock@0"
            ]
        },
        {
            "x": 3,
            "y": -2,
            "z": 0,
            "elements": [
                "minecraft:concrete@11"
            ]
        },
        {
            "x": 7,
            "y": -9,
            "z": 0,
            "elements": [
                "minecraft:concrete@11"
            ]
        },
        {
            "x": -3,
            "y": -11,
            "z": -1,
            "elements": [
                "contenttweaker:universalforcefieldcontrolblock@0"
            ]
        },
        {
            "x": 2,
            "y": 10,
            "z": 1,
            "elements": [
                "contenttweaker:arkmachineblock@0"
            ]
        },
        {
            "x": 3,
            "y": 11,
            "z": -1,
            "elements": [
                "contenttweaker:universalforcefieldcontrolblock@0"
            ]
        },
        {
            "x": 1,
            "y": 4,
            "z": 0,
            "elements": [
                "minecraft:concrete@11"
            ]
        },
        {
            "x": 11,
            "y": -5,
            "z": -1,
            "elements": [
                "contenttweaker:arkmachineblock@0"
            ]
        },
        {
            "x": 2,
            "y": -11,
            "z": 0,
            "elements": [
                "contenttweaker:arkmachineblock@0"
            ]
        },
        {
            "x": 1,
            "y": -6,
            "z": 0,
            "elements": [
                "minecraft:concrete@11"
            ]
        },
        {
            "x": -2,
            "y": -4,
            "z": 0,
            "elements": [
                "minecraft:concrete@11"
            ]
        },
        {
            "x": -2,
            "y": 6,
            "z": 0,
            "elements": [
                "minecraft:concrete@11"
            ]
        },
        {
            "x": -3,
            "y": 11,
            "z": 0,
            "elements": [
                "contenttweaker:arkmachineblock@0"
            ]
        },
        {
            "x": 7,
            "y": -10,
            "z": 0,
            "elements": [
                "avaritia:block_resource@1"
            ]
        },
        {
            "x": 11,
            "y": 10,
            "z": 1,
            "elements": [
                "contenttweaker:arkmachineblock@0"
            ]
        },
        {
            "x": 7,
            "y": -8,
            "z": 0,
            "elements": [
                "minecraft:concrete@11"
            ]
        },
        {
            "x": 4,
            "y": -8,
            "z": 0,
            "elements": [
                "minecraft:concrete@11"
            ]
        },
        {
            "x": 11,
            "y": 11,
            "z": 1,
            "elements": [
                "contenttweaker:universalforcefieldcontrolblock@0"
            ]
        },
        {
            "x": 1,
            "y": 3,
            "z": 0,
            "elements": [
                "minecraft:concrete@11"
            ]
        },
        {
            "x": 1,
            "y": -5,
            "z": 0,
            "elements": [
                "minecraft:concrete@11"
            ]
        },
        {
            "x": 3,
            "y": 10,
            "z": -1,
            "elements": [
                "contenttweaker:arkmachineblock@0"
            ]
        },
        {
            "x": -2,
            "y": -3,
            "z": 0,
            "elements": [
                "minecraft:concrete@11"
            ]
        },
        {
            "x": -4,
            "y": -11,
            "z": 1,
            "elements": [
                "contenttweaker:universalforcefieldcontrolblock@0"
            ]
        },
        {
            "x": 12,
            "y": -11,
            "z": -1,
            "elements": [
                "contenttweaker:universalforcefieldcontrolblock@0"
            ]
        },
        {
            "x": 2,
            "y": 11,
            "z": 1,
            "elements": [
                "contenttweaker:universalforcefieldcontrolblock@0"
            ]
        },
        {
            "x": 4,
            "y": -7,
            "z": 0,
            "elements": [
                "minecraft:concrete@11"
            ]
        },
        {
            "x": -2,
            "y": 5,
            "z": 0,
            "elements": [
                "minecraft:concrete@11"
            ]
        },
        {
            "x": 11,
            "y": -6,
            "z": -1,
            "elements": [
                "contenttweaker:arkmachineblock@0"
            ]
        },
        {
            "x": 11,
            "y": -3,
            "z": -1,
            "elements": [
                "contenttweaker:arkmachineblock@0"
            ]
        },
        {
            "x": 4,
            "y": -2,
            "z": 0,
            "elements": [
                "minecraft:concrete@11"
            ]
        },
        {
            "x": -3,
            "y": 9,
            "z": -1,
            "elements": [
                "contenttweaker:arkmachineblock@0"
            ]
        },
        {
            "x": 12,
            "y": 2,
            "z": -1,
            "elements": [
                "contenttweaker:universalforcefieldcontrolblock@0"
            ]
        },
        {
            "x": 4,
            "y": 0,
            "z": 0,
            "elements": [
                "minecraft:concrete@11"
            ]
        },
        {
            "x": -3,
            "y": -4,
            "z": 0,
            "elements": [
                "avaritia:block_resource@1"
            ]
        },
        {
            "x": 9,
            "y": -11,
            "z": 0,
            "elements": [
                "contenttweaker:arkmachineblock@0"
            ]
        },
        {
            "x": 2,
            "y": -10,
            "z": 1,
            "elements": [
                "contenttweaker:arkmachineblock@0"
            ]
        },
        {
            "x": -3,
            "y": 8,
            "z": -1,
            "elements": [
                "contenttweaker:arkmachineblock@0"
            ]
        },
        {
            "x": 2,
            "y": 4,
            "z": 0,
            "elements": [
                "minecraft:concrete@11"
            ]
        },
        {
            "x": -1,
            "y": 9,
            "z": 0,
            "elements": [
                "minecraft:concrete@11"
            ]
        },
        {
            "x": 0,
            "y": -9,
            "z": 0,
            "elements": [
                "minecraft:concrete@11"
            ]
        },
        {
            "x": 6,
            "y": -6,
            "z": 0,
            "elements": [
                "minecraft:concrete@11"
            ]
        },
        {
            "x": 3,
            "y": -1,
            "z": 0,
            "elements": [
                "minecraft:concrete@11"
            ]
        },
        {
            "x": 0,
            "y": 11,
            "z": -1,
            "elements": [
                "contenttweaker:universalforcefieldcontrolblock@0"
            ]
        },
        {
            "x": -4,
            "y": 1,
            "z": 0,
            "elements": [
                "contenttweaker:arkmachineblock@0"
            ]
        },
        {
            "x": -4,
            "y": -5,
            "z": 1,
            "elements": [
                "contenttweaker:universalforcefieldcontrolblock@0"
            ]
        },
        {
            "x": 11,
            "y": -4,
            "z": -1,
            "elements": [
                "contenttweaker:arkmachineblock@0"
            ]
        },
        {
            "x": 0,
            "y": 10,
            "z": -1,
            "elements": [
                "contenttweaker:arkmachineblock@0"
            ]
        },
        {
            "x": -1,
            "y": -11,
            "z": 1,
            "elements": [
                "contenttweaker:universalforcefieldcontrolblock@0"
            ]
        },
        {
            "x": 0,
            "y": -10,
            "z": 0,
            "elements": [
                "avaritia:block_resource@1"
            ]
        },
        {
            "x": 6,
            "y": -5,
            "z": 0,
            "elements": [
                "minecraft:concrete@11"
            ]
        },
        {
            "x": 12,
            "y": 3,
            "z": -1,
            "elements": [
                "contenttweaker:universalforcefieldcontrolblock@0"
            ]
        },
        {
            "x": -1,
            "y": 10,
            "z": 0,
            "elements": [
                "avaritia:block_resource@1"
            ]
        },
        {
            "x": 2,
            "y": 3,
            "z": 0,
            "elements": [
                "minecraft:concrete@11"
            ]
        },
        {
            "x": -3,
            "y": -3,
            "z": 0,
            "elements": [
                "avaritia:block_resource@1"
            ]
        },
        {
            "x": 11,
            "y": 4,
            "z": 1,
            "elements": [
                "contenttweaker:arkmachineblock@0"
            ]
        },
        {
            "x": -4,
            "y": -6,
            "z": 1,
            "elements": [
                "contenttweaker:universalforcefieldcontrolblock@0"
            ]
        },
        {
            "x": 7,
            "y": -7,
            "z": 0,
            "elements": [
                "minecraft:concrete@11"
            ]
        },
        {
            "x": 7,
            "y": -6,
            "z": 0,
            "elements": [
                "minecraft:concrete@11"
            ]
        },
        {
            "x": -1,
            "y": -10,
            "z": 1,
            "elements": [
                "contenttweaker:arkmachineblock@0"
            ]
        },
        {
            "x": -3,
            "y": 11,
            "z": -1,
            "elements": [
                "contenttweaker:universalforcefieldcontrolblock@0"
            ]
        },
        {
            "x": 2,
            "y": 2,
            "z": 0,
            "elements": [
                "minecraft:concrete@11"
            ]
        },
        {
            "x": 5,
            "y": 0,
            "z": 0,
            "elements": [
                "minecraft:concrete@11"
            ]
        },
        {
            "x": -4,
            "y": -8,
            "z": 1,
            "elements": [
                "contenttweaker:universalforcefieldcontrolblock@0"
            ]
        },
        {
            "x": 4,
            "y": -4,
            "z": 0,
            "elements": [
                "minecraft:concrete@11"
            ]
        },
        {
            "x": -3,
            "y": -2,
            "z": 0,
            "elements": [
                "avaritia:block_resource@1"
            ]
        },
        {
            "x": 11,
            "y": 8,
            "z": 1,
            "elements": [
                "contenttweaker:arkmachineblock@0"
            ]
        },
        {
            "x": -4,
            "y": -7,
            "z": 1,
            "elements": [
                "contenttweaker:universalforcefieldcontrolblock@0"
            ]
        },
        {
            "x": 0,
            "y": -11,
            "z": 0,
            "elements": [
                "contenttweaker:arkmachineblock@0"
            ]
        },
        {
            "x": -1,
            "y": 11,
            "z": 0,
            "elements": [
                "contenttweaker:arkmachineblock@0"
            ]
        },
        {
            "x": 6,
            "y": -8,
            "z": 0,
            "elements": [
                "minecraft:concrete@11"
            ]
        },
        {
            "x": 4,
            "y": -1,
            "z": 0,
            "elements": [
                "minecraft:concrete@11"
            ]
        },
        {
            "x": 12,
            "y": 0,
            "z": -1,
            "elements": [
                "contenttweaker:universalforcefieldcontrolblock@0"
            ]
        },
        {
            "x": 8,
            "y": 10,
            "z": 1,
            "elements": [
                "contenttweaker:arkmachineblock@0"
            ]
        },
        {
            "x": 12,
            "y": 1,
            "z": -1,
            "elements": [
                "contenttweaker:universalforcefieldcontrolblock@0"
            ]
        },
        {
            "x": 9,
            "y": -10,
            "z": 0,
            "elements": [
                "avaritia:block_resource@1"
            ]
        },
        {
            "x": 2,
            "y": 1,
            "z": 0,
            "elements": [
                "minecraft:concrete@11"
            ]
        },
        {
            "x": 4,
            "y": -3,
            "z": 0,
            "elements": [
                "minecraft:concrete@11"
            ]
        },
        {
            "x": -3,
            "y": -1,
            "z": 0,
            "elements": [
                "avaritia:block_resource@1"
            ]
        },
        {
            "x": 7,
            "y": -5,
            "z": 0,
            "elements": [
                "minecraft:concrete@11"
            ]
        },
        {
            "x": 2,
            "y": -11,
            "z": 1,
            "elements": [
                "contenttweaker:universalforcefieldcontrolblock@0"
            ]
        },
        {
            "x": -3,
            "y": 10,
            "z": -1,
            "elements": [
                "contenttweaker:arkmachineblock@0"
            ]
        },
        {
            "x": 6,
            "y": -7,
            "z": 0,
            "elements": [
                "minecraft:concrete@11"
            ]
        },
        {
            "x": 11,
            "y": 9,
            "z": 1,
            "elements": [
                "contenttweaker:arkmachineblock@0"
            ]
        },
        {
            "x": 8,
            "y": 11,
            "z": 1,
            "elements": [
                "contenttweaker:universalforcefieldcontrolblock@0"
            ]
        },
        {
            "x": 9,
            "y": -9,
            "z": 0,
            "elements": [
                "minecraft:concrete@11"
            ]
        },
        {
            "x": -2,
            "y": 0,
            "z": 0,
            "elements": [
                "minecraft:concrete@11"
            ]
        },
        {
            "x": 11,
            "y": 1,
            "z": 1,
            "elements": [
                "contenttweaker:arkmachineblock@0"
            ]
        },
        {
            "x": 6,
            "y": -9,
            "z": 0,
            "elements": [
                "minecraft:concrete@11"
            ]
        },
        {
            "x": 7,
            "y": -4,
            "z": 0,
            "elements": [
                "minecraft:concrete@11"
            ]
        },
        {
            "x": 11,
            "y": -2,
            "z": -1,
            "elements": [
                "contenttweaker:arkmachineblock@0"
            ]
        },
        {
            "x": -3,
            "y": -7,
            "z": 0,
            "elements": [
                "avaritia:block_resource@1"
            ]
        },
        {
            "x": 2,
            "y": 7,
            "z": 0,
            "elements": [
                "minecraft:concrete@11"
            ]
        },
        {
            "x": 3,
            "y": -11,
            "z": 0,
            "elements": [
                "contenttweaker:arkmachineblock@0"
            ]
        },
        {
            "x": -4,
            "y": 11,
            "z": 0,
            "elements": [
                "contenttweaker:arkmachineblock@0"
            ]
        },
        {
            "x": 5,
            "y": 2,
            "z": 0,
            "elements": [
                "minecraft:concrete@11"
            ]
        },
        {
            "x": 5,
            "y": 10,
            "z": 1,
            "elements": [
                "contenttweaker:arkmachineblock@0"
            ]
        },
        {
            "x": 6,
            "y": 11,
            "z": -1,
            "elements": [
                "contenttweaker:universalforcefieldcontrolblock@0"
            ]
        },
        {
            "x": 7,
            "y": -3,
            "z": 0,
            "elements": [
                "minecraft:concrete@11"
            ]
        },
        {
            "x": 0,
            "y": -6,
            "z": 0,
            "elements": [
                "minecraft:concrete@11"
            ]
        },
        {
            "x": -1,
            "y": 6,
            "z": 0,
            "elements": [
                "minecraft:concrete@11"
            ]
        },
        {
            "x": 2,
            "y": 8,
            "z": 0,
            "elements": [
                "minecraft:concrete@11"
            ]
        },
        {
            "x": 11,
            "y": 0,
            "z": 1,
            "elements": [
                "contenttweaker:arkmachineblock@0"
            ]
        },
        {
            "x": 11,
            "y": -1,
            "z": -1,
            "elements": [
                "contenttweaker:arkmachineblock@0"
            ]
        },
        {
            "x": -4,
            "y": -2,
            "z": 1,
            "elements": [
                "contenttweaker:universalforcefieldcontrolblock@0"
            ]
        },
        {
            "x": 6,
            "y": -10,
            "z": 0,
            "elements": [
                "avaritia:block_resource@1"
            ]
        },
        {
            "x": 5,
            "y": 1,
            "z": 0,
            "elements": [
                "minecraft:concrete@11"
            ]
        },
        {
            "x": 6,
            "y": 10,
            "z": -1,
            "elements": [
                "contenttweaker:arkmachineblock@0"
            ]
        },
        {
            "x": 8,
            "y": -10,
            "z": 1,
            "elements": [
                "contenttweaker:arkmachineblock@0"
            ]
        },
        {
            "x": -3,
            "y": -8,
            "z": 0,
            "elements": [
                "avaritia:block_resource@1"
            ]
        },
        {
            "x": 0,
            "y": -5,
            "z": 0,
            "elements": [
                "minecraft:concrete@11"
            ]
        },
        {
            "x": -1,
            "y": 5,
            "z": 0,
            "elements": [
                "minecraft:concrete@11"
            ]
        },
        {
            "x": -3,
            "y": -5,
            "z": 0,
            "elements": [
                "avaritia:block_resource@1"
            ]
        },
        {
            "x": 5,
            "y": 11,
            "z": 1,
            "elements": [
                "contenttweaker:universalforcefieldcontrolblock@0"
            ]
        },
        {
            "x": 0,
            "y": -7,
            "z": 0,
            "elements": [
                "minecraft:concrete@11"
            ]
        },
        {
            "x": -1,
            "y": 7,
            "z": 0,
            "elements": [
                "minecraft:concrete@11"
            ]
        },
        {
            "x": 2,
            "y": 5,
            "z": 0,
            "elements": [
                "minecraft:concrete@11"
            ]
        },
        {
            "x": -4,
            "y": 9,
            "z": 0,
            "elements": [
                "contenttweaker:arkmachineblock@0"
            ]
        },
        {
            "x": 3,
            "y": -9,
            "z": 0,
            "elements": [
                "minecraft:concrete@11"
            ]
        },
        {
            "x": 8,
            "y": -11,
            "z": 1,
            "elements": [
                "contenttweaker:universalforcefieldcontrolblock@0"
            ]
        },
        {
            "x": -4,
            "y": -3,
            "z": 1,
            "elements": [
                "contenttweaker:universalforcefieldcontrolblock@0"
            ]
        },
        {
            "x": 6,
            "y": -11,
            "z": 0,
            "elements": [
                "contenttweaker:arkmachineblock@0"
            ]
        },
        {
            "x": 11,
            "y": 3,
            "z": 1,
            "elements": [
                "contenttweaker:arkmachineblock@0"
            ]
        },
        {
            "x": 5,
            "y": 4,
            "z": 0,
            "elements": [
                "minecraft:concrete@11"
            ]
        },
        {
            "x": -3,
            "y": -6,
            "z": 0,
            "elements": [
                "avaritia:block_resource@1"
            ]
        },
        {
            "x": 2,
            "y": 6,
            "z": 0,
            "elements": [
                "minecraft:concrete@11"
            ]
        },
        {
            "x": -4,
            "y": -1,
            "z": 1,
            "elements": [
                "contenttweaker:universalforcefieldcontrolblock@0"
            ]
        },
        {
            "x": -1,
            "y": 8,
            "z": 0,
            "elements": [
                "minecraft:concrete@11"
            ]
        },
        {
            "x": 0,
            "y": -8,
            "z": 0,
            "elements": [
                "minecraft:concrete@11"
            ]
        },
        {
            "x": 11,
            "y": 2,
            "z": 1,
            "elements": [
                "contenttweaker:arkmachineblock@0"
            ]
        },
        {
            "x": 3,
            "y": -10,
            "z": 0,
            "elements": [
                "avaritia:block_resource@1"
            ]
        },
        {
            "x": -4,
            "y": 10,
            "z": 0,
            "elements": [
                "contenttweaker:arkmachineblock@0"
            ]
        },
        {
            "x": -4,
            "y": -4,
            "z": 1,
            "elements": [
                "contenttweaker:universalforcefieldcontrolblock@0"
            ]
        },
        {
            "x": 5,
            "y": 3,
            "z": 0,
            "elements": [
                "minecraft:concrete@11"
            ]
        },
        {
            "x": 9,
            "y": -4,
            "z": 0,
            "elements": [
                "minecraft:concrete@11"
            ]
        },
        {
            "x": 4,
            "y": 7,
            "z": 0,
            "elements": [
                "minecraft:concrete@11"
            ]
        },
        {
            "x": 8,
            "y": 0,
            "z": 0,
            "elements": [
                "minecraft:concrete@11"
            ]
        },
        {
            "x": 10,
            "y": -6,
            "z": 0,
            "elements": [
                "minecraft:concrete@11"
            ]
        },
        {
            "x": 7,
            "y": 10,
            "z": 1,
            "elements": [
                "contenttweaker:arkmachineblock@0"
            ]
        },
        {
            "x": 12,
            "y": 8,
            "z": 1,
            "elements": [
                "contenttweaker:universalforcefieldcontrolblock@0"
            ]
        },
        {
            "x": 12,
            "y": -10,
            "z": 0,
            "elements": [
                "contenttweaker:arkmachineblock@0"
            ]
        },
        {
            "x": 7,
            "y": -1,
            "z": 0,
            "elements": [
                "minecraft:concrete@11"
            ]
        },
        {
            "x": 7,
            "y": 2,
            "z": 0,
            "elements": [
                "minecraft:concrete@11"
            ]
        },
        {
            "x": 1,
            "y": 11,
            "z": 0,
            "elements": [
                "contenttweaker:arkmachineblock@0"
            ]
        },
        {
            "x": 10,
            "y": -5,
            "z": 0,
            "elements": [
                "minecraft:concrete@11"
            ]
        },
        {
            "x": -2,
            "y": -11,
            "z": 0,
            "elements": [
                "contenttweaker:arkmachineblock@0"
            ]
        },
        {
            "x": 7,
            "y": 11,
            "z": -1,
            "elements": [
                "contenttweaker:universalforcefieldcontrolblock@0"
            ]
        },
        {
            "x": 4,
            "y": 8,
            "z": 0,
            "elements": [
                "minecraft:concrete@11"
            ]
        },
        {
            "x": 7,
            "y": 1,
            "z": 0,
            "elements": [
                "minecraft:concrete@11"
            ]
        },
        {
            "x": 12,
            "y": -9,
            "z": 0,
            "elements": [
                "contenttweaker:arkmachineblock@0"
            ]
        },
        {
            "x": 7,
            "y": 11,
            "z": 1,
            "elements": [
                "contenttweaker:universalforcefieldcontrolblock@0"
            ]
        },
        {
            "x": 7,
            "y": -2,
            "z": 0,
            "elements": [
                "minecraft:concrete@11"
            ]
        },
        {
            "x": 12,
            "y": 9,
            "z": 1,
            "elements": [
                "contenttweaker:universalforcefieldcontrolblock@0"
            ]
        },
        {
            "x": 12,
            "y": -11,
            "z": 0,
            "elements": [
                "contenttweaker:arkmachineblock@0"
            ]
        },
        {
            "x": 12,
            "y": 11,
            "z": 1,
            "elements": [
                "contenttweaker:universalforcefieldcontrolblock@0"
            ]
        },
        {
            "x": 4,
            "y": 5,
            "z": 0,
            "elements": [
                "minecraft:concrete@11"
            ]
        },
        {
            "x": 12,
            "y": 10,
            "z": -1,
            "elements": [
                "contenttweaker:universalforcefieldcontrolblock@0"
            ]
        },
        {
            "x": 12,
            "y": 9,
            "z": -1,
            "elements": [
                "contenttweaker:universalforcefieldcontrolblock@0"
            ]
        },
        {
            "x": 10,
            "y": -8,
            "z": 0,
            "elements": [
                "minecraft:concrete@11"
            ]
        },
        {
            "x": 12,
            "y": 11,
            "z": -1,
            "elements": [
                "contenttweaker:universalforcefieldcontrolblock@0"
            ]
        },
        {
            "x": 7,
            "y": 4,
            "z": 0,
            "elements": [
                "minecraft:concrete@11"
            ]
        },
        {
            "x": 12,
            "y": 10,
            "z": 1,
            "elements": [
                "contenttweaker:universalforcefieldcontrolblock@0"
            ]
        },
        {
            "x": 4,
            "y": 6,
            "z": 0,
            "elements": [
                "minecraft:concrete@11"
            ]
        },
        {
            "x": 10,
            "y": -7,
            "z": 0,
            "elements": [
                "minecraft:concrete@11"
            ]
        },
        {
            "x": 9,
            "y": 10,
            "z": -1,
            "elements": [
                "contenttweaker:arkmachineblock@0"
            ]
        },
        {
            "x": 12,
            "y": 8,
            "z": -1,
            "elements": [
                "contenttweaker:universalforcefieldcontrolblock@0"
            ]
        },
        {
            "x": 7,
            "y": 3,
            "z": 0,
            "elements": [
                "minecraft:concrete@11"
            ]
        },
        {
            "x": 11,
            "y": 6,
            "z": 1,
            "elements": [
                "contenttweaker:arkmachineblock@0"
            ]
        },
        {
            "x": 9,
            "y": 11,
            "z": 1,
            "elements": [
                "contenttweaker:universalforcefieldcontrolblock@0"
            ]
        },
        {
            "x": 12,
            "y": -6,
            "z": 0,
            "elements": [
                "contenttweaker:arkmachineblock@0"
            ]
        },
        {
            "x": 11,
            "y": 9,
            "z": -1,
            "elements": [
                "contenttweaker:arkmachineblock@0"
            ]
        },
        {
            "x": 10,
            "y": 0,
            "z": 0,
            "elements": [
                "minecraft:concrete@11"
            ]
        },
        {
            "x": 9,
            "y": -1,
            "z": 0,
            "elements": [
                "minecraft:concrete@11"
            ]
        },
        {
            "x": 9,
            "y": 10,
            "z": 1,
            "elements": [
                "contenttweaker:arkmachineblock@0"
            ]
        },
        {
            "x": 4,
            "y": 4,
            "z": 0,
            "elements": [
                "minecraft:concrete@11"
            ]
        },
        {
            "x": 12,
            "y": 7,
            "z": -1,
            "elements": [
                "contenttweaker:universalforcefieldcontrolblock@0"
            ]
        },
        {
            "x": 9,
            "y": -8,
            "z": 0,
            "elements": [
                "minecraft:concrete@11"
            ]
        },
        {
            "x": 12,
            "y": -5,
            "z": 0,
            "elements": [
                "contenttweaker:arkmachineblock@0"
            ]
        },
        {
            "x": 12,
            "y": 6,
            "z": -1,
            "elements": [
                "contenttweaker:universalforcefieldcontrolblock@0"
            ]
        },
        {
            "x": 10,
            "y": -10,
            "z": 0,
            "elements": [
                "avaritia:block_resource@1"
            ]
        },
        {
            "x": 11,
            "y": 7,
            "z": 1,
            "elements": [
                "contenttweaker:arkmachineblock@0"
            ]
        },
        {
            "x": 9,
            "y": 11,
            "z": -1,
            "elements": [
                "contenttweaker:universalforcefieldcontrolblock@0"
            ]
        },
        {
            "x": 12,
            "y": 5,
            "z": 1,
            "elements": [
                "contenttweaker:universalforcefieldcontrolblock@0"
            ]
        },
        {
            "x": 9,
            "y": -7,
            "z": 0,
            "elements": [
                "minecraft:concrete@11"
            ]
        },
        {
            "x": 11,
            "y": 8,
            "z": -1,
            "elements": [
                "contenttweaker:arkmachineblock@0"
            ]
        },
        {
            "x": 4,
            "y": 3,
            "z": 0,
            "elements": [
                "minecraft:concrete@11"
            ]
        },
        {
            "x": 9,
            "y": -2,
            "z": 0,
            "elements": [
                "minecraft:concrete@11"
            ]
        },
        {
            "x": 10,
            "y": -9,
            "z": 0,
            "elements": [
                "minecraft:concrete@11"
            ]
        },
        {
            "x": 10,
            "y": 11,
            "z": 1,
            "elements": [
                "contenttweaker:universalforcefieldcontrolblock@0"
            ]
        },
        {
            "x": 12,
            "y": 6,
            "z": 1,
            "elements": [
                "contenttweaker:universalforcefieldcontrolblock@0"
            ]
        },
        {
            "x": 12,
            "y": 5,
            "z": -1,
            "elements": [
                "contenttweaker:universalforcefieldcontrolblock@0"
            ]
        },
        {
            "x": 7,
            "y": 0,
            "z": 0,
            "elements": [
                "minecraft:concrete@11"
            ]
        },
        {
            "x": 10,
            "y": 10,
            "z": -1,
            "elements": [
                "contenttweaker:arkmachineblock@0"
            ]
        },
        {
            "x": 6,
            "y": -4,
            "z": 0,
            "elements": [
                "minecraft:concrete@11"
            ]
        },
        {
            "x": 9,
            "y": -6,
            "z": 0,
            "elements": [
                "minecraft:concrete@11"
            ]
        },
        {
            "x": 10,
            "y": -11,
            "z": 0,
            "elements": [
                "contenttweaker:arkmachineblock@0"
            ]
        },
        {
            "x": 4,
            "y": 2,
            "z": 0,
            "elements": [
                "minecraft:concrete@11"
            ]
        },
        {
            "x": 12,
            "y": -8,
            "z": 0,
            "elements": [
                "contenttweaker:arkmachineblock@0"
            ]
        },
        {
            "x": 6,
            "y": -1,
            "z": 0,
            "elements": [
                "minecraft:concrete@11"
            ]
        },
        {
            "x": 10,
            "y": 10,
            "z": 1,
            "elements": [
                "contenttweaker:arkmachineblock@0"
            ]
        },
        {
            "x": 9,
            "y": -3,
            "z": 0,
            "elements": [
                "minecraft:concrete@11"
            ]
        },
        {
            "x": 6,
            "y": -3,
            "z": 0,
            "elements": [
                "minecraft:concrete@11"
            ]
        },
        {
            "x": 11,
            "y": 5,
            "z": 1,
            "elements": [
                "contenttweaker:arkmachineblock@0"
            ]
        },
        {
            "x": 12,
            "y": -7,
            "z": 0,
            "elements": [
                "contenttweaker:arkmachineblock@0"
            ]
        },
        {
            "x": 10,
            "y": 11,
            "z": -1,
            "elements": [
                "contenttweaker:universalforcefieldcontrolblock@0"
            ]
        },
        {
            "x": 9,
            "y": -5,
            "z": 0,
            "elements": [
                "minecraft:concrete@11"
            ]
        },
        {
            "x": 4,
            "y": 1,
            "z": 0,
            "elements": [
                "minecraft:concrete@11"
            ]
        },
        {
            "x": 12,
            "y": 4,
            "z": -1,
            "elements": [
                "contenttweaker:universalforcefieldcontrolblock@0"
            ]
        },
        {
            "x": 12,
            "y": 4,
            "z": 1,
            "elements": [
                "contenttweaker:universalforcefieldcontrolblock@0"
            ]
        },
        {
            "x": 12,
            "y": 7,
            "z": 1,
            "elements": [
                "contenttweaker:universalforcefieldcontrolblock@0"
            ]
        },
        {
            "x": -4,
            "y": 0,
            "z": 0,
            "elements": [
                "contenttweaker:arkmachineblock@0"
            ]
        },
        {
            "x": 6,
            "y": -2,
            "z": 0,
            "elements": [
                "minecraft:concrete@11"
            ]
        },
        {
            "x": -4,
            "y": -11,
            "z": -1,
            "elements": [
                "contenttweaker:universalforcefieldcontrolblock@0"
            ]
        },
        {
            "x": 3,
            "y": 10,
            "z": 1,
            "elements": [
                "contenttweaker:arkmachineblock@0"
            ]
        },
        {
            "x": 10,
            "y": 3,
            "z": 0,
            "elements": [
                "minecraft:concrete@11"
            ]
        },
        {
            "x": 12,
            "y": -5,
            "z": -1,
            "elements": [
                "contenttweaker:universalforcefieldcontrolblock@0"
            ]
        },
        {
            "x": 11,
            "y": 10,
            "z": -1,
            "elements": [
                "contenttweaker:arkmachineblock@0"
            ]
        },
        {
            "x": 11,
            "y": 5,
            "z": -1,
            "elements": [
                "contenttweaker:arkmachineblock@0"
            ]
        },
        {
            "x": 12,
            "y": 3,
            "z": 1,
            "elements": [
                "contenttweaker:universalforcefieldcontrolblock@0"
            ]
        },
        {
            "x": 12,
            "y": -3,
            "z": 0,
            "elements": [
                "contenttweaker:arkmachineblock@0"
            ]
        },
        {
            "x": 1,
            "y": -11,
            "z": 0,
            "elements": [
                "contenttweaker:arkmachineblock@0"
            ]
        },
        {
            "x": 1,
            "y": 6,
            "z": 0,
            "elements": [
                "minecraft:concrete@11"
            ]
        },
        {
            "x": -2,
            "y": 11,
            "z": 0,
            "elements": [
                "contenttweaker:arkmachineblock@0"
            ]
        },
        {
            "x": 11,
            "y": 11,
            "z": -1,
            "elements": [
                "contenttweaker:universalforcefieldcontrolblock@0"
            ]
        },
        {
            "x": -2,
            "y": -6,
            "z": 0,
            "elements": [
                "minecraft:concrete@11"
            ]
        },
        {
            "x": 10,
            "y": 4,
            "z": 0,
            "elements": [
                "minecraft:concrete@11"
            ]
        },
        {
            "x": 11,
            "y": 4,
            "z": -1,
            "elements": [
                "contenttweaker:arkmachineblock@0"
            ]
        },
        {
            "x": 3,
            "y": 11,
            "z": 1,
            "elements": [
                "contenttweaker:universalforcefieldcontrolblock@0"
            ]
        },
        {
            "x": 8,
            "y": 10,
            "z": -1,
            "elements": [
                "contenttweaker:arkmachineblock@0"
            ]
        },
        {
            "x": 12,
            "y": 2,
            "z": 1,
            "elements": [
                "contenttweaker:universalforcefieldcontrolblock@0"
            ]
        },
        {
            "x": 12,
            "y": -6,
            "z": -1,
            "elements": [
                "contenttweaker:universalforcefieldcontrolblock@0"
            ]
        },
        {
            "x": 1,
            "y": 5,
            "z": 0,
            "elements": [
                "minecraft:concrete@11"
            ]
        },
        {
            "x": -2,
            "y": -5,
            "z": 0,
            "elements": [
                "minecraft:concrete@11"
            ]
        },
        {
            "x": 12,
            "y": -4,
            "z": 0,
            "elements": [
                "contenttweaker:arkmachineblock@0"
            ]
        },
        {
            "x": -4,
            "y": -9,
            "z": -1,
            "elements": [
                "contenttweaker:universalforcefieldcontrolblock@0"
            ]
        },
        {
            "x": 12,
            "y": 1,
            "z": 1,
            "elements": [
                "contenttweaker:universalforcefieldcontrolblock@0"
            ]
        },
        {
            "x": 1,
            "y": -9,
            "z": 0,
            "elements": [
                "minecraft:concrete@11"
            ]
        },
        {
            "x": 1,
            "y": 7,
            "z": 0,
            "elements": [
                "minecraft:concrete@11"
            ]
        },
        {
            "x": 12,
            "y": -1,
            "z": 0,
            "elements": [
                "contenttweaker:arkmachineblock@0"
            ]
        },
        {
            "x": -2,
            "y": 9,
            "z": 0,
            "elements": [
                "minecraft:concrete@11"
            ]
        },
        {
            "x": -2,
            "y": -7,
            "z": 0,
            "elements": [
                "minecraft:concrete@11"
            ]
        },
        {
            "x": 12,
            "y": -7,
            "z": -1,
            "elements": [
                "contenttweaker:universalforcefieldcontrolblock@0"
            ]
        },
        {
            "x": 5,
            "y": 11,
            "z": -1,
            "elements": [
                "contenttweaker:universalforcefieldcontrolblock@0"
            ]
        },
        {
            "x": 11,
            "y": 7,
            "z": -1,
            "elements": [
                "contenttweaker:arkmachineblock@0"
            ]
        },
        {
            "x": 10,
            "y": 2,
            "z": 0,
            "elements": [
                "minecraft:concrete@11"
            ]
        },
        {
            "x": 11,
            "y": 6,
            "z": -1,
            "elements": [
                "contenttweaker:arkmachineblock@0"
            ]
        },
        {
            "x": 12,
            "y": 0,
            "z": 1,
            "elements": [
                "contenttweaker:universalforcefieldcontrolblock@0"
            ]
        },
        {
            "x": 1,
            "y": 8,
            "z": 0,
            "elements": [
                "minecraft:concrete@11"
            ]
        },
        {
            "x": 8,
            "y": 11,
            "z": -1,
            "elements": [
                "contenttweaker:universalforcefieldcontrolblock@0"
            ]
        },
        {
            "x": -2,
            "y": -8,
            "z": 0,
            "elements": [
                "minecraft:concrete@11"
            ]
        },
        {
            "x": -4,
            "y": -10,
            "z": -1,
            "elements": [
                "contenttweaker:universalforcefieldcontrolblock@0"
            ]
        },
        {
            "x": 1,
            "y": -10,
            "z": 0,
            "elements": [
                "avaritia:block_resource@1"
            ]
        },
        {
            "x": 12,
            "y": -2,
            "z": 0,
            "elements": [
                "contenttweaker:arkmachineblock@0"
            ]
        },
        {
            "x": -2,
            "y": 10,
            "z": 0,
            "elements": [
                "avaritia:block_resource@1"
            ]
        },
        {
            "x": 12,
            "y": -8,
            "z": -1,
            "elements": [
                "contenttweaker:universalforcefieldcontrolblock@0"
            ]
        },
        {
            "x": 10,
            "y": 1,
            "z": 0,
            "elements": [
                "minecraft:concrete@11"
            ]
        },
        {
            "x": 5,
            "y": 10,
            "z": -1,
            "elements": [
                "contenttweaker:arkmachineblock@0"
            ]
        },
        {
            "x": 4,
            "y": 10,
            "z": 0,
            "elements": [
                "avaritia:block_resource@1"
            ]
        },
        {
            "x": 7,
            "y": 5,
            "z": 0,
            "elements": [
                "minecraft:concrete@11"
            ]
        },
        {
            "x": 1,
            "y": 9,
            "z": 0,
            "elements": [
                "minecraft:concrete@11"
            ]
        },
        {
            "x": 11,
            "y": -1,
            "z": 1,
            "elements": [
                "contenttweaker:arkmachineblock@0"
            ]
        },
        {
            "x": -2,
            "y": -9,
            "z": 0,
            "elements": [
                "minecraft:concrete@11"
            ]
        },
        {
            "x": 11,
            "y": -2,
            "z": 1,
            "elements": [
                "contenttweaker:arkmachineblock@0"
            ]
        },
        {
            "x": 11,
            "y": 0,
            "z": -1,
            "elements": [
                "contenttweaker:arkmachineblock@0"
            ]
        },
        {
            "x": 10,
            "y": 7,
            "z": 0,
            "elements": [
                "minecraft:concrete@11"
            ]
        },
        {
            "x": 7,
            "y": 11,
            "z": 0,
            "elements": [
                "contenttweaker:arkmachineblock@0"
            ]
        },
        {
            "x": 7,
            "y": 6,
            "z": 0,
            "elements": [
                "minecraft:concrete@11"
            ]
        },
        {
            "x": 1,
            "y": 10,
            "z": 0,
            "elements": [
                "avaritia:block_resource@1"
            ]
        },
        {
            "x": 11,
            "y": 1,
            "z": -1,
            "elements": [
                "contenttweaker:arkmachineblock@0"
            ]
        },
        {
            "x": -2,
            "y": -10,
            "z": 0,
            "elements": [
                "avaritia:block_resource@1"
            ]
        },
        {
            "x": 7,
            "y": 10,
            "z": 0,
            "elements": [
                "avaritia:block_resource@1"
            ]
        },
        {
            "x": 10,
            "y": 8,
            "z": 0,
            "elements": [
                "minecraft:concrete@11"
            ]
        },
        {
            "x": 11,
            "y": 2,
            "z": -1,
            "elements": [
                "contenttweaker:arkmachineblock@0"
            ]
        },
        {
            "x": 12,
            "y": -3,
            "z": -1,
            "elements": [
                "contenttweaker:universalforcefieldcontrolblock@0"
            ]
        },
        {
            "x": 10,
            "y": 5,
            "z": 0,
            "elements": [
                "minecraft:concrete@11"
            ]
        },
        {
            "x": 6,
            "y": 10,
            "z": 1,
            "elements": [
                "contenttweaker:arkmachineblock@0"
            ]
        },
        {
            "x": 7,
            "y": 7,
            "z": 0,
            "elements": [
                "minecraft:concrete@11"
            ]
        },
        {
            "x": 12,
            "y": -2,
            "z": -1,
            "elements": [
                "contenttweaker:universalforcefieldcontrolblock@0"
            ]
        },
        {
            "x": 12,
            "y": -4,
            "z": -1,
            "elements": [
                "contenttweaker:universalforcefieldcontrolblock@0"
            ]
        },
        {
            "x": 4,
            "y": 9,
            "z": 0,
            "elements": [
                "minecraft:concrete@11"
            ]
        },
        {
            "x": 11,
            "y": -4,
            "z": 1,
            "elements": [
                "contenttweaker:arkmachineblock@0"
            ]
        },
        {
            "x": 4,
            "y": 11,
            "z": 0,
            "elements": [
                "contenttweaker:arkmachineblock@0"
            ]
        },
        {
            "x": 7,
            "y": 9,
            "z": 0,
            "elements": [
                "minecraft:concrete@11"
            ]
        },
        {
            "x": 11,
            "y": 3,
            "z": -1,
            "elements": [
                "contenttweaker:arkmachineblock@0"
            ]
        },
        {
            "x": 12,
            "y": -1,
            "z": -1,
            "elements": [
                "contenttweaker:universalforcefieldcontrolblock@0"
            ]
        },
        {
            "x": 10,
            "y": 6,
            "z": 0,
            "elements": [
                "minecraft:concrete@11"
            ]
        },
        {
            "x": 11,
            "y": -3,
            "z": 1,
            "elements": [
                "contenttweaker:arkmachineblock@0"
            ]
        },
        {
            "x": 6,
            "y": 11,
            "z": 1,
            "elements": [
                "contenttweaker:universalforcefieldcontrolblock@0"
            ]
        },
        {
            "x": 7,
            "y": 8,
            "z": 0,
            "elements": [
                "minecraft:concrete@11"
            ]
        },
        {
            "x": -2,
            "y": -10,
            "z": 1,
            "elements": [
                "contenttweaker:arkmachineblock@0"
            ]
        },
        {
            "x": 11,
            "y": 8,
            "z": 0,
            "elements": [
                "avaritia:block_resource@1"
            ]
        },
        {
            "x": 10,
            "y": 10,
            "z": 0,
            "elements": [
                "avaritia:block_resource@1"
            ]
        },
        {
            "x": -3,
            "y": -8,
            "z": 1,
            "elements": [
                "contenttweaker:arkmachineblock@0"
            ]
        },
        {
            "x": 4,
            "y": 11,
            "z": -1,
            "elements": [
                "contenttweaker:universalforcefieldcontrolblock@0"
            ]
        },
        {
            "x": -3,
            "y": -7,
            "z": 1,
            "elements": [
                "contenttweaker:arkmachineblock@0"
            ]
        },
        {
            "x": 12,
            "y": 7,
            "z": 0,
            "elements": [
                "contenttweaker:arkmachineblock@0"
            ]
        },
        {
            "x": 10,
            "y": 9,
            "z": 0,
            "elements": [
                "minecraft:concrete@11"
            ]
        },
        {
            "x": 9,
            "y": 11,
            "z": 0,
            "elements": [
                "contenttweaker:arkmachineblock@0"
            ]
        },
        {
            "x": 4,
            "y": 10,
            "z": -1,
            "elements": [
                "contenttweaker:arkmachineblock@0"
            ]
        },
        {
            "x": 12,
            "y": 8,
            "z": 0,
            "elements": [
                "contenttweaker:arkmachineblock@0"
            ]
        },
        {
            "x": -3,
            "y": -5,
            "z": 1,
            "elements": [
                "contenttweaker:arkmachineblock@0"
            ]
        },
        {
            "x": 9,
            "y": 10,
            "z": 0,
            "elements": [
                "avaritia:block_resource@1"
            ]
        },
        {
            "x": 12,
            "y": 5,
            "z": 0,
            "elements": [
                "contenttweaker:arkmachineblock@0"
            ]
        },
        {
            "x": 4,
            "y": 10,
            "z": 1,
            "elements": [
                "contenttweaker:arkmachineblock@0"
            ]
        },
        {
            "x": 1,
            "y": 11,
            "z": -1,
            "elements": [
                "contenttweaker:universalforcefieldcontrolblock@0"
            ]
        },
        {
            "x": 9,
            "y": 9,
            "z": 0,
            "elements": [
                "minecraft:concrete@11"
            ]
        },
        {
            "x": -2,
            "y": -11,
            "z": 1,
            "elements": [
                "contenttweaker:universalforcefieldcontrolblock@0"
            ]
        },
        {
            "x": 1,
            "y": 10,
            "z": -1,
            "elements": [
                "contenttweaker:arkmachineblock@0"
            ]
        },
        {
            "x": 4,
            "y": 11,
            "z": 1,
            "elements": [
                "contenttweaker:universalforcefieldcontrolblock@0"
            ]
        },
        {
            "x": 10,
            "y": 11,
            "z": 0,
            "elements": [
                "contenttweaker:arkmachineblock@0"
            ]
        },
        {
            "x": 12,
            "y": 6,
            "z": 0,
            "elements": [
                "contenttweaker:arkmachineblock@0"
            ]
        },
        {
            "x": -3,
            "y": -6,
            "z": 1,
            "elements": [
                "contenttweaker:arkmachineblock@0"
            ]
        },
        {
            "x": 12,
            "y": -9,
            "z": 1,
            "elements": [
                "contenttweaker:universalforcefieldcontrolblock@0"
            ]
        },
        {
            "x": 12,
            "y": 3,
            "z": 0,
            "elements": [
                "contenttweaker:arkmachineblock@0"
            ]
        },
        {
            "x": 1,
            "y": 10,
            "z": 1,
            "elements": [
                "contenttweaker:arkmachineblock@0"
            ]
        },
        {
            "x": -2,
            "y": -11,
            "z": -1,
            "elements": [
                "contenttweaker:universalforcefieldcontrolblock@0"
            ]
        },
        {
            "x": 8,
            "y": 10,
            "z": 0,
            "elements": [
                "avaritia:block_resource@1"
            ]
        },
        {
            "x": 11,
            "y": 5,
            "z": 0,
            "elements": [
                "avaritia:block_resource@1"
            ]
        },
        {
            "x": 2,
            "y": 11,
            "z": -1,
            "elements": [
                "contenttweaker:universalforcefieldcontrolblock@0"
            ]
        },
        {
            "x": 12,
            "y": -10,
            "z": 1,
            "elements": [
                "contenttweaker:universalforcefieldcontrolblock@0"
            ]
        },
        {
            "x": 8,
            "y": 9,
            "z": 0,
            "elements": [
                "minecraft:concrete@11"
            ]
        },
        {
            "x": 12,
            "y": 4,
            "z": 0,
            "elements": [
                "contenttweaker:arkmachineblock@0"
            ]
        },
        {
            "x": 1,
            "y": 11,
            "z": 1,
            "elements": [
                "contenttweaker:universalforcefieldcontrolblock@0"
            ]
        },
        {
            "x": 11,
            "y": 11,
            "z": 0,
            "elements": [
                "contenttweaker:arkmachineblock@0"
            ]
        },
        {
            "x": 11,
            "y": 6,
            "z": 0,
            "elements": [
                "avaritia:block_resource@1"
            ]
        },
        {
            "x": 2,
            "y": 10,
            "z": -1,
            "elements": [
                "contenttweaker:arkmachineblock@0"
            ]
        },
        {
            "x": -3,
            "y": -11,
            "z": 1,
            "elements": [
                "contenttweaker:universalforcefieldcontrolblock@0"
            ]
        },
        {
            "x": -3,
            "y": -10,
            "z": 1,
            "elements": [
                "contenttweaker:arkmachineblock@0"
            ]
        },
        {
            "x": 11,
            "y": 10,
            "z": 0,
            "elements": [
                "avaritia:block_resource@1"
            ]
        },
        {
            "x": 12,
            "y": -11,
            "z": 1,
            "elements": [
                "contenttweaker:universalforcefieldcontrolblock@0"
            ]
        },
        {
            "x": 11,
            "y": 7,
            "z": 0,
            "elements": [
                "avaritia:block_resource@1"
            ]
        },
        {
            "x": 12,
            "y": 2,
            "z": 0,
            "elements": [
                "contenttweaker:arkmachineblock@0"
            ]
        },
        {
            "x": -2,
            "y": -10,
            "z": -1,
            "elements": [
                "contenttweaker:arkmachineblock@0"
            ]
        },
        {
            "x": -3,
            "y": -9,
            "z": 1,
            "elements": [
                "contenttweaker:arkmachineblock@0"
            ]
        },
        {
            "x": 8,
            "y": 11,
            "z": 0,
            "elements": [
                "contenttweaker:arkmachineblock@0"
            ]
        },
        {
            "x": 11,
            "y": 9,
            "z": 0,
            "elements": [
                "avaritia:block_resource@1"
            ]
        },
        {
            "x": 12,
            "y": 1,
            "z": 0,
            "elements": [
                "contenttweaker:arkmachineblock@0"
            ]
        },
        {
            "x": 6,
            "y": 10,
            "z": 0,
            "elements": [
                "avaritia:block_resource@1"
            ]
        },
        {
            "x": 10,
            "y": -10,
            "z": -1,
            "elements": [
                "contenttweaker:arkmachineblock@0"
            ]
        },
        {
            "x": 9,
            "y": 5,
            "z": 0,
            "elements": [
                "minecraft:concrete@11"
            ]
        },
        {
            "x": 8,
            "y": 7,
            "z": 0,
            "elements": [
                "minecraft:concrete@11"
            ]
        },
        {
            "x": 1,
            "y": 0,
            "z": 1,
            "elements": [
                "contenttweaker:arkmachineblock@0"
            ]
        },
        {
            "x": 11,
            "y": 2,
            "z": 0,
            "elements": [
                "avaritia:block_resource@1"
            ]
        },
        {
            "x": 5,
            "y": 11,
            "z": 0,
            "elements": [
                "contenttweaker:arkmachineblock@0"
            ]
        },
        {
            "x": 9,
            "y": 6,
            "z": 0,
            "elements": [
                "minecraft:concrete@11"
            ]
        },
        {
            "x": 12,
            "y": -7,
            "z": 1,
            "elements": [
                "contenttweaker:universalforcefieldcontrolblock@0"
            ]
        },
        {
            "x": 1,
            "y": 1,
            "z": 1,
            "elements": [
                "contenttweaker:arkmachineblock@0"
            ]
        },
        {
            "x": 8,
            "y": 8,
            "z": 0,
            "elements": [
                "minecraft:concrete@11"
            ]
        },
        {
            "x": 11,
            "y": 1,
            "z": 0,
            "elements": [
                "avaritia:block_resource@1"
            ]
        },
        {
            "x": 7,
            "y": -11,
            "z": -1,
            "elements": [
                "contenttweaker:universalforcefieldcontrolblock@0"
            ]
        },
        {
            "x": 5,
            "y": 10,
            "z": 0,
            "elements": [
                "avaritia:block_resource@1"
            ]
        },
        {
            "x": 11,
            "y": 3,
            "z": 0,
            "elements": [
                "avaritia:block_resource@1"
            ]
        },
        {
            "x": 8,
            "y": 5,
            "z": 0,
            "elements": [
                "minecraft:concrete@11"
            ]
        },
        {
            "x": 7,
            "y": -10,
            "z": -1,
            "elements": [
                "contenttweaker:arkmachineblock@0"
            ]
        },
        {
            "x": 12,
            "y": -6,
            "z": 1,
            "elements": [
                "contenttweaker:universalforcefieldcontrolblock@0"
            ]
        },
        {
            "x": 6,
            "y": 9,
            "z": 0,
            "elements": [
                "minecraft:concrete@11"
            ]
        },
        {
            "x": 9,
            "y": 7,
            "z": 0,
            "elements": [
                "minecraft:concrete@11"
            ]
        },
        {
            "x": 12,
            "y": -8,
            "z": 1,
            "elements": [
                "contenttweaker:universalforcefieldcontrolblock@0"
            ]
        },
        {
            "x": 6,
            "y": 11,
            "z": 0,
            "elements": [
                "contenttweaker:arkmachineblock@0"
            ]
        },
        {
            "x": 11,
            "y": 4,
            "z": 0,
            "elements": [
                "avaritia:block_resource@1"
            ]
        },
        {
            "x": 10,
            "y": -11,
            "z": -1,
            "elements": [
                "contenttweaker:universalforcefieldcontrolblock@0"
            ]
        },
        {
            "x": 8,
            "y": 6,
            "z": 0,
            "elements": [
                "minecraft:concrete@11"
            ]
        },
        {
            "x": 9,
            "y": 8,
            "z": 0,
            "elements": [
                "minecraft:concrete@11"
            ]
        },
        {
            "x": 12,
            "y": -5,
            "z": 1,
            "elements": [
                "contenttweaker:universalforcefieldcontrolblock@0"
            ]
        },
        {
            "x": -4,
            "y": 1,
            "z": -1,
            "elements": [
                "contenttweaker:universalforcefieldcontrolblock@0"
            ]
        },
        {
            "x": 8,
            "y": 3,
            "z": 0,
            "elements": [
                "minecraft:concrete@11"
            ]
        },
        {
            "x": 9,
            "y": -11,
            "z": 1,
            "elements": [
                "contenttweaker:universalforcefieldcontrolblock@0"
            ]
        },
        {
            "x": -3,
            "y": -3,
            "z": 1,
            "elements": [
                "contenttweaker:arkmachineblock@0"
            ]
        },
        {
            "x": 12,
            "y": 10,
            "z": 0,
            "elements": [
                "contenttweaker:arkmachineblock@0"
            ]
        },
        {
            "x": 10,
            "y": -3,
            "z": 0,
            "elements": [
                "minecraft:concrete@11"
            ]
        },
        {
            "x": 12,
            "y": -4,
            "z": 1,
            "elements": [
                "contenttweaker:universalforcefieldcontrolblock@0"
            ]
        },
        {
            "x": 1,
            "y": -10,
            "z": -1,
            "elements": [
                "contenttweaker:arkmachineblock@0"
            ]
        },
        {
            "x": 8,
            "y": 4,
            "z": 0,
            "elements": [
                "minecraft:concrete@11"
            ]
        },
        {
            "x": 12,
            "y": 9,
            "z": 0,
            "elements": [
                "contenttweaker:arkmachineblock@0"
            ]
        },
        {
            "x": 12,
            "y": -3,
            "z": 1,
            "elements": [
                "contenttweaker:universalforcefieldcontrolblock@0"
            ]
        },
        {
            "x": -3,
            "y": -4,
            "z": 1,
            "elements": [
                "contenttweaker:arkmachineblock@0"
            ]
        },
        {
            "x": -4,
            "y": 0,
            "z": -1,
            "elements": [
                "contenttweaker:universalforcefieldcontrolblock@0"
            ]
        },
        {
            "x": 1,
            "y": -11,
            "z": -1,
            "elements": [
                "contenttweaker:universalforcefieldcontrolblock@0"
            ]
        },
        {
            "x": -2,
            "y": 10,
            "z": 1,
            "elements": [
                "contenttweaker:arkmachineblock@0"
            ]
        },
        {
            "x": 10,
            "y": -4,
            "z": 0,
            "elements": [
                "minecraft:concrete@11"
            ]
        },
        {
            "x": 12,
            "y": -1,
            "z": 1,
            "elements": [
                "contenttweaker:universalforcefieldcontrolblock@0"
            ]
        },
        {
            "x": 12,
            "y": -2,
            "z": 1,
            "elements": [
                "contenttweaker:universalforcefieldcontrolblock@0"
            ]
        },
        {
            "x": -4,
            "y": 3,
            "z": -1,
            "elements": [
                "contenttweaker:universalforcefieldcontrolblock@0"
            ]
        },
        {
            "x": 10,
            "y": -1,
            "z": 0,
            "elements": [
                "minecraft:concrete@11"
            ]
        },
        {
            "x": 11,
            "y": 0,
            "z": 0,
            "elements": [
                "avaritia:block_resource@1"
            ]
        },
        {
            "x": 8,
            "y": 2,
            "z": 0,
            "elements": [
                "minecraft:concrete@11"
            ]
        },
        {
            "x": -4,
            "y": 2,
            "z": -1,
            "elements": [
                "contenttweaker:universalforcefieldcontrolblock@0"
            ]
        },
        {
            "x": -2,
            "y": 11,
            "z": 1,
            "elements": [
                "contenttweaker:universalforcefieldcontrolblock@0"
            ]
        },
        {
            "x": 7,
            "y": 10,
            "z": -1,
            "elements": [
                "contenttweaker:arkmachineblock@0"
            ]
        },
        {
            "x": 12,
            "y": 11,
            "z": 0,
            "elements": [
                "contenttweaker:arkmachineblock@0"
            ]
        },
        {
            "x": 8,
            "y": 1,
            "z": 0,
            "elements": [
                "minecraft:concrete@11"
            ]
        },
        {
            "x": 10,
            "y": -2,
            "z": 0,
            "elements": [
                "minecraft:concrete@11"
            ]
        },
        {
            "x": 9,
            "y": -10,
            "z": 1,
            "elements": [
                "contenttweaker:arkmachineblock@0"
            ]
        },
        {
            "x": -4,
            "y": 11,
            "z": -1,
            "elements": [
                "contenttweaker:universalforcefieldcontrolblock@0"
            ]
        },
        {
            "x": 5,
            "y": 5,
            "z": 0,
            "elements": [
                "minecraft:concrete@11"
            ]
        },
        {
            "x": -3,
            "y": 0,
            "z": 1,
            "elements": [
                "contenttweaker:arkmachineblock@0"
            ]
        },
        {
            "x": -3,
            "y": 3,
            "z": -1,
            "elements": [
                "contenttweaker:arkmachineblock@0"
            ]
        },
        {
            "x": -3,
            "y": -2,
            "z": 1,
            "elements": [
                "contenttweaker:arkmachineblock@0"
            ]
        },
        {
            "x": 11,
            "y": -8,
            "z": 0,
            "elements": [
                "avaritia:block_resource@1"
            ]
        },
        {
            "x": 6,
            "y": -10,
            "z": -1,
            "elements": [
                "contenttweaker:arkmachineblock@0"
            ]
        },
        {
            "x": 2,
            "y": 9,
            "z": 0,
            "elements": [
                "minecraft:concrete@11"
            ]
        },
        {
            "x": 3,
            "y": 9,
            "z": 0,
            "elements": [
                "minecraft:concrete@11"
            ]
        },
        {
            "x": -4,
            "y": -9,
            "z": 0,
            "elements": [
                "contenttweaker:arkmachineblock@0"
            ]
        },
        {
            "x": 8,
            "y": -3,
            "z": 0,
            "elements": [
                "minecraft:concrete@11"
            ]
        },
        {
            "x": 6,
            "y": 4,
            "z": 0,
            "elements": [
                "minecraft:concrete@11"
            ]
        },
        {
            "x": 2,
            "y": 11,
            "z": 0,
            "elements": [
                "contenttweaker:arkmachineblock@0"
            ]
        },
        {
            "x": 2,
            "y": 10,
            "z": 0,
            "elements": [
                "avaritia:block_resource@1"
            ]
        },
        {
            "x": -3,
            "y": 2,
            "z": -1,
            "elements": [
                "contenttweaker:arkmachineblock@0"
            ]
        },
        {
            "x": 5,
            "y": 6,
            "z": 0,
            "elements": [
                "minecraft:concrete@11"
            ]
        },
        {
            "x": -3,
            "y": -1,
            "z": 1,
            "elements": [
                "contenttweaker:arkmachineblock@0"
            ]
        },
        {
            "x": -4,
            "y": 10,
            "z": -1,
            "elements": [
                "contenttweaker:universalforcefieldcontrolblock@0"
            ]
        },
        {
            "x": 3,
            "y": -11,
            "z": 1,
            "elements": [
                "contenttweaker:universalforcefieldcontrolblock@0"
            ]
        },
        {
            "x": 6,
            "y": -10,
            "z": 1,
            "elements": [
                "contenttweaker:arkmachineblock@0"
            ]
        },
        {
            "x": -1,
            "y": 0,
            "z": 1,
            "elements": [
                "contenttweaker:arkmachineblock@0"
            ]
        },
        {
            "x": 11,
            "y": -7,
            "z": 0,
            "elements": [
                "avaritia:block_resource@1"
            ]
        },
        {
            "x": 3,
            "y": 10,
            "z": 0,
            "elements": [
                "avaritia:block_resource@1"
            ]
        },
        {
            "x": -4,
            "y": -10,
            "z": 0,
            "elements": [
                "contenttweaker:arkmachineblock@0"
            ]
        },
        {
            "x": 6,
            "y": 3,
            "z": 0,
            "elements": [
                "minecraft:concrete@11"
            ]
        },
        {
            "x": -3,
            "y": 1,
            "z": 1,
            "elements": [
                "contenttweaker:arkmachineblock@0"
            ]
        },
        {
            "x": 6,
            "y": 2,
            "z": 0,
            "elements": [
                "minecraft:concrete@11"
            ]
        },
        {
            "x": 3,
            "y": -11,
            "z": -1,
            "elements": [
                "contenttweaker:universalforcefieldcontrolblock@0"
            ]
        },
        {
            "x": 8,
            "y": -4,
            "z": 0,
            "elements": [
                "minecraft:concrete@11"
            ]
        },
        {
            "x": -3,
            "y": 1,
            "z": -1,
            "elements": [
                "contenttweaker:arkmachineblock@0"
            ]
        },
        {
            "x": -4,
            "y": 10,
            "z": 1,
            "elements": [
                "contenttweaker:universalforcefieldcontrolblock@0"
            ]
        },
        {
            "x": 11,
            "y": -6,
            "z": 0,
            "elements": [
                "avaritia:block_resource@1"
            ]
        },
        {
            "x": -4,
            "y": 8,
            "z": -1,
            "elements": [
                "contenttweaker:universalforcefieldcontrolblock@0"
            ]
        },
        {
            "x": 9,
            "y": 0,
            "z": 0,
            "elements": [
                "minecraft:concrete@11"
            ]
        },
        {
            "x": -3,
            "y": -9,
            "z": 0,
            "elements": [
                "avaritia:block_resource@1"
            ]
        },
        {
            "x": 6,
            "y": -11,
            "z": 1,
            "elements": [
                "contenttweaker:universalforcefieldcontrolblock@0"
            ]
        },
        {
            "x": 8,
            "y": -1,
            "z": 0,
            "elements": [
                "minecraft:concrete@11"
            ]
        },
        {
            "x": 5,
            "y": 7,
            "z": 0,
            "elements": [
                "minecraft:concrete@11"
            ]
        },
        {
            "x": 3,
            "y": -10,
            "z": -1,
            "elements": [
                "contenttweaker:arkmachineblock@0"
            ]
        },
        {
            "x": 0,
            "y": 0,
            "z": 1,
            "elements": [
                "modularmachinery:blockoutputbus",
                "modularmachinery:blockmeitemoutputbus"
            ]
        },
        {
            "x": -4,
            "y": 9,
            "z": 1,
            "elements": [
                "contenttweaker:universalforcefieldcontrolblock@0"
            ]
        },
        {
            "x": -3,
            "y": 2,
            "z": 1,
            "elements": [
                "contenttweaker:arkmachineblock@0"
            ]
        },
        {
            "x": -1,
            "y": -1,
            "z": -1,
            "elements": [
                "modularmachinery:blockinputbus",
                "modularmachinery:blockmeiteminputbus",
                "modularmachinery:blockmepatternprovider"
            ]
        },
        {
            "x": 6,
            "y": 1,
            "z": 0,
            "elements": [
                "minecraft:concrete@11"
            ]
        },
        {
            "x": -4,
            "y": 11,
            "z": 1,
            "elements": [
                "contenttweaker:universalforcefieldcontrolblock@0"
            ]
        },
        {
            "x": -3,
            "y": -11,
            "z": 0,
            "elements": [
                "contenttweaker:arkmachineblock@0"
            ]
        },
        {
            "x": 11,
            "y": -5,
            "z": 0,
            "elements": [
                "avaritia:block_resource@1"
            ]
        },
        {
            "x": 6,
            "y": -11,
            "z": -1,
            "elements": [
                "contenttweaker:universalforcefieldcontrolblock@0"
            ]
        },
        {
            "x": -3,
            "y": -10,
            "z": 0,
            "elements": [
                "avaritia:block_resource@1"
            ]
        },
        {
            "x": -4,
            "y": 9,
            "z": -1,
            "elements": [
                "contenttweaker:universalforcefieldcontrolblock@0"
            ]
        },
        {
            "x": 3,
            "y": -10,
            "z": 1,
            "elements": [
                "contenttweaker:arkmachineblock@0"
            ]
        },
        {
            "x": -4,
            "y": 8,
            "z": 1,
            "elements": [
                "contenttweaker:universalforcefieldcontrolblock@0"
            ]
        },
        {
            "x": 5,
            "y": 8,
            "z": 0,
            "elements": [
                "minecraft:concrete@11"
            ]
        },
        {
            "x": 8,
            "y": -2,
            "z": 0,
            "elements": [
                "minecraft:concrete@11"
            ]
        },
        {
            "x": -3,
            "y": 3,
            "z": 1,
            "elements": [
                "contenttweaker:arkmachineblock@0"
            ]
        },
        {
            "x": 0,
            "y": -1,
            "z": -1,
            "elements": [
                "modularmachinery:blockfluidinputhatch",
                "modularmachinery:blockmefluidinputbus"
            ]
        },
        {
            "x": 0,
            "y": 1,
            "z": 1,
            "elements": [
                "contenttweaker:arkmachineblock@0"
            ]
        },
        {
            "x": 3,
            "y": 5,
            "z": 0,
            "elements": [
                "minecraft:concrete@11"
            ]
        },
        {
            "x": -3,
            "y": 0,
            "z": -1,
            "elements": [
                "contenttweaker:arkmachineblock@0"
            ]
        },
        {
            "x": -4,
            "y": -5,
            "z": 0,
            "elements": [
                "contenttweaker:arkmachineblock@0"
            ]
        },
        {
            "x": -4,
            "y": 6,
            "z": -1,
            "elements": [
                "contenttweaker:universalforcefieldcontrolblock@0"
            ]
        },
        {
            "x": -3,
            "y": 4,
            "z": -1,
            "elements": [
                "contenttweaker:arkmachineblock@0"
            ]
        },
        {
            "x": 0,
            "y": 1,
            "z": -1,
            "elements": [
                "contenttweaker:arkmachineblock@0"
            ]
        },
        {
            "x": 0,
            "y": 11,
            "z": 0,
            "elements": [
                "contenttweaker:arkmachineblock@0"
            ]
        },
        {
            "x": -1,
            "y": -1,
            "z": 1,
            "elements": [
                "contenttweaker:arkmachineblock@0"
            ]
        },
        {
            "x": -3,
            "y": 5,
            "z": 1,
            "elements": [
                "contenttweaker:arkmachineblock@0"
            ]
        },
        {
            "x": 4,
            "y": -10,
            "z": -1,
            "elements": [
                "contenttweaker:arkmachineblock@0"
            ]
        },
        {
            "x": -1,
            "y": -11,
            "z": 0,
            "elements": [
                "contenttweaker:arkmachineblock@0"
            ]
        },
        {
            "x": 6,
            "y": 7,
            "z": 0,
            "elements": [
                "minecraft:concrete@11"
            ]
        },
        {
            "x": 5,
            "y": 9,
            "z": 0,
            "elements": [
                "minecraft:concrete@11"
            ]
        },
        {
            "x": -4,
            "y": 7,
            "z": 1,
            "elements": [
                "contenttweaker:universalforcefieldcontrolblock@0"
            ]
        },
        {
            "x": 9,
            "y": 2,
            "z": 0,
            "elements": [
                "minecraft:concrete@11"
            ]
        },
        {
            "x": 3,
            "y": 11,
            "z": 0,
            "elements": [
                "contenttweaker:arkmachineblock@0"
            ]
        },
        {
            "x": 3,
            "y": 6,
            "z": 0,
            "elements": [
                "minecraft:concrete@11"
            ]
        },
        {
            "x": -4,
            "y": 6,
            "z": 1,
            "elements": [
                "contenttweaker:universalforcefieldcontrolblock@0"
            ]
        },
        {
            "x": -4,
            "y": -11,
            "z": 0,
            "elements": [
                "contenttweaker:arkmachineblock@0"
            ]
        },
        {
            "x": -4,
            "y": -6,
            "z": 0,
            "elements": [
                "contenttweaker:arkmachineblock@0"
            ]
        },
        {
            "x": -3,
            "y": 5,
            "z": -1,
            "elements": [
                "contenttweaker:arkmachineblock@0"
            ]
        },
        {
            "x": -3,
            "y": 4,
            "z": 1,
            "elements": [
                "contenttweaker:arkmachineblock@0"
            ]
        },
        {
            "x": 5,
            "y": -11,
            "z": 1,
            "elements": [
                "contenttweaker:universalforcefieldcontrolblock@0"
            ]
        },
        {
            "x": 4,
            "y": -10,
            "z": 1,
            "elements": [
                "contenttweaker:arkmachineblock@0"
            ]
        },
        {
            "x": -1,
            "y": 1,
            "z": 1,
            "elements": [
                "contenttweaker:arkmachineblock@0"
            ]
        },
        {
            "x": 9,
            "y": 1,
            "z": 0,
            "elements": [
                "minecraft:concrete@11"
            ]
        },
        {
            "x": -4,
            "y": 7,
            "z": -1,
            "elements": [
                "contenttweaker:universalforcefieldcontrolblock@0"
            ]
        },
        {
            "x": 5,
            "y": -11,
            "z": -1,
            "elements": [
                "contenttweaker:universalforcefieldcontrolblock@0"
            ]
        },
        {
            "x": 6,
            "y": 8,
            "z": 0,
            "elements": [
                "minecraft:concrete@11"
            ]
        },
        {
            "x": 1,
            "y": -1,
            "z": -1,
            "elements": [
                "modularmachinery:blockinputbus",
                "modularmachinery:blockmeiteminputbus",
                "modularmachinery:blockmepatternprovider"
            ]
        },
        {
            "x": 9,
            "y": 3,
            "z": 0,
            "elements": [
                "minecraft:concrete@11"
            ]
        },
        {
            "x": -1,
            "y": 1,
            "z": -1,
            "elements": [
                "contenttweaker:arkmachineblock@0"
            ]
        },
        {
            "x": 3,
            "y": 7,
            "z": 0,
            "elements": [
                "minecraft:concrete@11"
            ]
        },
        {
            "x": -4,
            "y": -7,
            "z": 0,
            "elements": [
                "contenttweaker:arkmachineblock@0"
            ]
        },
        {
            "x": 6,
            "y": 5,
            "z": 0,
            "elements": [
                "minecraft:concrete@11"
            ]
        },
        {
            "x": -4,
            "y": 5,
            "z": 1,
            "elements": [
                "contenttweaker:universalforcefieldcontrolblock@0"
            ]
        },
        {
            "x": -4,
            "y": 4,
            "z": -1,
            "elements": [
                "contenttweaker:universalforcefieldcontrolblock@0"
            ]
        },
        {
            "x": 0,
            "y": 9,
            "z": 0,
            "elements": [
                "minecraft:concrete@11"
            ]
        },
        {
            "x": -4,
            "y": 4,
            "z": 1,
            "elements": [
                "contenttweaker:universalforcefieldcontrolblock@0"
            ]
        },
        {
            "x": -1,
            "y": -9,
            "z": 0,
            "elements": [
                "minecraft:concrete@11"
            ]
        },
        {
            "x": -3,
            "y": 6,
            "z": -1,
            "elements": [
                "contenttweaker:arkmachineblock@0"
            ]
        },
        {
            "x": -3,
            "y": 7,
            "z": 1,
            "elements": [
                "contenttweaker:arkmachineblock@0"
            ]
        },
        {
            "x": 5,
            "y": -10,
